Workbook

Sheet Page de garde
A1: 1. Expérimentateur 1 : copier et coller le n° de prestation et renseigner la date de réalisation de chaque réplica ainsi que le visa de l'expérimentateur.
A2: R1 | B2: Numéro d'expérience : | E2: Date de réalisation :
A3: R2 | B3: Numéro d'expérience : | E3: Date de réalisation :
A4: R3 | B4: Numéro d'expérience : | E4: Date de réalisation :
A5: 2. Expérimentateur 1 : copier et coller la dilution appliquée et le nom donné pour chaque des échantillons par le client. Conserver la mise en forme de l'exemple en italique. Ne pas remplir la colonne "nom sur graphique".
A6: Nom sur le graphique | B6: Code WF | C6: Concentration | D6: Unité | E6: Nom de l'échantillon donné par le client | F6: Dopage (+Testostérone / + EE2, ….)
A7: =IF(ISBLANK(liste_groupe[[#This Row],[Code WF]])," ",IF(ISBLANK(liste_groupe[[#This Row],[Unité]]),CONCATENATE(liste_groupe[[#This Row],[Nom de l''échantillon donné par le client]],liste_groupe[[#This Row],[Dopage (+Testostérone / + EE2, ….)]]),CONCATENATE(liste_groupe[[#This Row],[Nom de l''échantillon donné par le client]],"-",liste_groupe[[#This Row],[Concentration]],liste_groupe[[#This Row],[Unité]],liste_groupe[[#This Row],[Dopage (+Testostérone / + EE2, ….)]]))) -> Témoin solvant | B7: Témoin | E7: Témoin solvant
A8: =IF(ISBLANK(liste_groupe[[#This Row],[Code WF]])," ",IF(ISBLANK(liste_groupe[[#This Row],[Unité]]),CONCATENATE(liste_groupe[[#This Row],[Nom de l''échantillon donné par le client]],liste_groupe[[#This Row],[Dopage (+Testostérone / + EE2, ….)]]),CONCATENATE(liste_groupe[[#This Row],[Nom de l''échantillon donné par le client]],"-",liste_groupe[[#This Row],[Concentration]],liste_groupe[[#This Row],[Unité]],liste_groupe[[#This Row],[Dopage (+Testostérone / + EE2, ….)]]))) -> EE2-22.5ng/L | B8: Témoin | C8: 22.5 | D8: ng/L | E8: EE2
A9: =IF(ISBLANK(liste_groupe[[#This Row],[Code WF]])," ",IF(ISBLANK(liste_groupe[[#This Row],[Unité]]),CONCATENATE(liste_groupe[[#This Row],[Nom de l''échantillon donné par le client]],liste_groupe[[#This Row],[Dopage (+Testostérone / + EE2, ….)]]),CONCATENATE(liste_groupe[[#This Row],[Nom de l''échantillon donné par le client]],"-",liste_groupe[[#This Row],[Concentration]],liste_groupe[[#This Row],[Unité]],liste_groupe[[#This Row],[Dopage (+Testostérone / + EE2, ….)]]))) -> EE2-33.8ng/L | B9: Témoin | C9: 33.8 | D9: ng/L | E9: EE2
A10: =IF(ISBLANK(liste_groupe[[#This Row],[Code WF]])," ",IF(ISBLANK(liste_groupe[[#This Row],[Unité]]),CONCATENATE(liste_groupe[[#This Row],[Nom de l''échantillon donné par le client]],liste_groupe[[#This Row],[Dopage (+Testostérone / + EE2, ….)]]),CONCATENATE(liste_groupe[[#This Row],[Nom de l''échantillon donné par le client]],"-",liste_groupe[[#This Row],[Concentration]],liste_groupe[[#This Row],[Unité]],liste_groupe[[#This Row],[Dopage (+Testostérone / + EE2, ….)]]))) -> EE2-50.6ng/L | B10: Témoin | C10: 50.6 | D10: ng/L | E10: EE2
A11: =IF(ISBLANK(liste_groupe[[#This Row],[Code WF]])," ",IF(ISBLANK(liste_groupe[[#This Row],[Unité]]),CONCATENATE(liste_groupe[[#This Row],[Nom de l''échantillon donné par le client]],liste_groupe[[#This Row],[Dopage (+Testostérone / + EE2, ….)]]),CONCATENATE(liste_groupe[[#This Row],[Nom de l''échantillon donné par le client]],"-",liste_groupe[[#This Row],[Concentration]],liste_groupe[[#This Row],[Unité]],liste_groupe[[#This Row],[Dopage (+Testostérone / + EE2, ….)]]))) -> EE2-76ng/L | B11: Témoin | C11: 76 | D11: ng/L | E11: EE2
A12: =IF(ISBLANK(liste_groupe[[#This Row],[Code WF]])," ",IF(ISBLANK(liste_groupe[[#This Row],[Unité]]),CONCATENATE(liste_groupe[[#This Row],[Nom de l''échantillon donné par le client]],liste_groupe[[#This Row],[Dopage (+Testostérone / + EE2, ….)]]),CONCATENATE(liste_groupe[[#This Row],[Nom de l''échantillon donné par le client]],"-",liste_groupe[[#This Row],[Concentration]],liste_groupe[[#This Row],[Unité]],liste_groupe[[#This Row],[Dopage (+Testostérone / + EE2, ….)]]))) -> EE2-114ng/L | B12: Témoin | C12: 114 | D12: ng/L | E12: EE2
A13: =IF(ISBLANK(liste_groupe[[#This Row],[Code WF]])," ",IF(ISBLANK(liste_groupe[[#This Row],[Unité]]),CONCATENATE(liste_groupe[[#This Row],[Nom de l''échantillon donné par le client]],liste_groupe[[#This Row],[Dopage (+Testostérone / + EE2, ….)]]),CONCATENATE(liste_groupe[[#This Row],[Nom de l''échantillon donné par le client]],"-",liste_groupe[[#This Row],[Concentration]],liste_groupe[[#This Row],[Unité]],liste_groupe[[#This Row],[Dopage (+Testostérone / + EE2, ….)]]))) -> EE2-170.9ng/L | B13: Témoin | C13: 170.9 | D13: ng/L | E13: EE2
A14: =IF(ISBLANK(liste_groupe[[#This Row],[Code WF]])," ",IF(ISBLANK(liste_groupe[[#This Row],[Unité]]),CONCATENATE(liste_groupe[[#This Row],[Nom de l''échantillon donné par le client]],liste_groupe[[#This Row],[Dopage (+Testostérone / + EE2, ….)]]),CONCATENATE(liste_groupe[[#This Row],[Nom de l''échantillon donné par le client]],"-",liste_groupe[[#This Row],[Concentration]],liste_groupe[[#This Row],[Unité]],liste_groupe[[#This Row],[Dopage (+Testostérone / + EE2, ….)]]))) -> EE2-488ng/L | B14: Témoin | C14: 488 | D14: ng/L | E14: EE2
A15: =IF(ISBLANK(liste_groupe[[#This Row],[Code WF]])," ",IF(ISBLANK(liste_groupe[[#This Row],[Unité]]),CONCATENATE(liste_groupe[[#This Row],[Nom de l''échantillon donné par le client]],liste_groupe[[#This Row],[Dopage (+Testostérone / + EE2, ….)]]),CONCATENATE(liste_groupe[[#This Row],[Nom de l''échantillon donné par le client]],"-",liste_groupe[[#This Row],[Concentration]],liste_groupe[[#This Row],[Unité]],liste_groupe[[#This Row],[Dopage (+Testostérone / + EE2, ….)]]))) -> Fadrozole-0.016µg/L | B15: Test | C15: 0.016 | D15: µg/L | E15: Fadrozole
A16: =IF(ISBLANK(liste_groupe[[#This Row],[Code WF]])," ",IF(ISBLANK(liste_groupe[[#This Row],[Unité]]),CONCATENATE(liste_groupe[[#This Row],[Nom de l''échantillon donné par le client]],liste_groupe[[#This Row],[Dopage (+Testostérone / + EE2, ….)]]),CONCATENATE(liste_groupe[[#This Row],[Nom de l''échantillon donné par le client]],"-",liste_groupe[[#This Row],[Concentration]],liste_groupe[[#This Row],[Unité]],liste_groupe[[#This Row],[Dopage (+Testostérone / + EE2, ….)]]))) -> Fadrozole-0.08µg/L | B16: Test | C16: 0.08 | D16: µg/L | E16: Fadrozole
A17: =IF(ISBLANK(liste_groupe[[#This Row],[Code WF]])," ",IF(ISBLANK(liste_groupe[[#This Row],[Unité]]),CONCATENATE(liste_groupe[[#This Row],[Nom de l''échantillon donné par le client]],liste_groupe[[#This Row],[Dopage (+Testostérone / + EE2, ….)]]),CONCATENATE(liste_groupe[[#This Row],[Nom de l''échantillon donné par le client]],"-",liste_groupe[[#This Row],[Concentration]],liste_groupe[[#This Row],[Unité]],liste_groupe[[#This Row],[Dopage (+Testostérone / + EE2, ….)]]))) -> Fadrozole-0.4µg/L | B17: Test | C17: 0.4 | D17: µg/L | E17: Fadrozole
A18: =IF(ISBLANK(liste_groupe[[#This Row],[Code WF]])," ",IF(ISBLANK(liste_groupe[[#This Row],[Unité]]),CONCATENATE(liste_groupe[[#This Row],[Nom de l''échantillon donné par le client]],liste_groupe[[#This Row],[Dopage (+Testostérone / + EE2, ….)]]),CONCATENATE(liste_groupe[[#This Row],[Nom de l''échantillon donné par le client]],"-",liste_groupe[[#This Row],[Concentration]],liste_groupe[[#This Row],[Unité]],liste_groupe[[#This Row],[Dopage (+Testostérone / + EE2, ….)]]))) -> Fadrozole-2µg/L | B18: Test | C18: 2 | D18: µg/L | E18: Fadrozole
A19: =IF(ISBLANK(liste_groupe[[#This Row],[Code WF]])," ",IF(ISBLANK(liste_groupe[[#This Row],[Unité]]),CONCATENATE(liste_groupe[[#This Row],[Nom de l''échantillon donné par le client]],liste_groupe[[#This Row],[Dopage (+Testostérone / + EE2, ….)]]),CONCATENATE(liste_groupe[[#This Row],[Nom de l''échantillon donné par le client]],"-",liste_groupe[[#This Row],[Concentration]],liste_groupe[[#This Row],[Unité]],liste_groupe[[#This Row],[Dopage (+Testostérone / + EE2, ….)]]))) -> Fadrozole-10 µg/L | B19: Test | C19: 10 | D19: µg/L | E19: Fadrozole
A20: =IF(ISBLANK(liste_groupe[[#This Row],[Code WF]])," ",IF(ISBLANK(liste_groupe[[#This Row],[Unité]]),CONCATENATE(liste_groupe[[#This Row],[Nom de l''échantillon donné par le client]],liste_groupe[[#This Row],[Dopage (+Testostérone / + EE2, ….)]]),CONCATENATE(liste_groupe[[#This Row],[Nom de l''échantillon donné par le client]],"-",liste_groupe[[#This Row],[Concentration]],liste_groupe[[#This Row],[Unité]],liste_groupe[[#This Row],[Dopage (+Testostérone / + EE2, ….)]])))
A21: =IF(ISBLANK(liste_groupe[[#This Row],[Code WF]])," ",IF(ISBLANK(liste_groupe[[#This Row],[Unité]]),CONCATENATE(liste_groupe[[#This Row],[Nom de l''échantillon donné par le client]],liste_groupe[[#This Row],[Dopage (+Testostérone / + EE2, ….)]]),CONCATENATE(liste_groupe[[#This Row],[Nom de l''échantillon donné par le client]],"-",liste_groupe[[#This Row],[Concentration]],liste_groupe[[#This Row],[Unité]],liste_groupe[[#This Row],[Dopage (+Testostérone / + EE2, ….)]])))
A22: =IF(ISBLANK(liste_groupe[[#This Row],[Code WF]])," ",IF(ISBLANK(liste_groupe[[#This Row],[Unité]]),CONCATENATE(liste_groupe[[#This Row],[Nom de l''échantillon donné par le client]],liste_groupe[[#This Row],[Dopage (+Testostérone / + EE2, ….)]]),CONCATENATE(liste_groupe[[#This Row],[Nom de l''échantillon donné par le client]],"-",liste_groupe[[#This Row],[Concentration]],liste_groupe[[#This Row],[Unité]],liste_groupe[[#This Row],[Dopage (+Testostérone / + EE2, ….)]])))
A23: =IF(ISBLANK(liste_groupe[[#This Row],[Code WF]])," ",IF(ISBLANK(liste_groupe[[#This Row],[Unité]]),CONCATENATE(liste_groupe[[#This Row],[Nom de l''échantillon donné par le client]],liste_groupe[[#This Row],[Dopage (+Testostérone / + EE2, ….)]]),CONCATENATE(liste_groupe[[#This Row],[Nom de l''échantillon donné par le client]],"-",liste_groupe[[#This Row],[Concentration]],liste_groupe[[#This Row],[Unité]],liste_groupe[[#This Row],[Dopage (+Testostérone / + EE2, ….)]])))
A24: =IF(ISBLANK(liste_groupe[[#This Row],[Code WF]])," ",IF(ISBLANK(liste_groupe[[#This Row],[Unité]]),CONCATENATE(liste_groupe[[#This Row],[Nom de l''échantillon donné par le client]],liste_groupe[[#This Row],[Dopage (+Testostérone / + EE2, ….)]]),CONCATENATE(liste_groupe[[#This Row],[Nom de l''échantillon donné par le client]],"-",liste_groupe[[#This Row],[Concentration]],liste_groupe[[#This Row],[Unité]],liste_groupe[[#This Row],[Dopage (+Testostérone / + EE2, ….)]])))
A25: =IF(ISBLANK(liste_groupe[[#This Row],[Code WF]])," ",IF(ISBLANK(liste_groupe[[#This Row],[Unité]]),CONCATENATE(liste_groupe[[#This Row],[Nom de l''échantillon donné par le client]],liste_groupe[[#This Row],[Dopage (+Testostérone / + EE2, ….)]]),CONCATENATE(liste_groupe[[#This Row],[Nom de l''échantillon donné par le client]],"-",liste_groupe[[#This Row],[Concentration]],liste_groupe[[#This Row],[Unité]],liste_groupe[[#This Row],[Dopage (+Testostérone / + EE2, ….)]])))
A26: =IF(ISBLANK(liste_groupe[[#This Row],[Code WF]])," ",IF(ISBLANK(liste_groupe[[#This Row],[Unité]]),CONCATENATE(liste_groupe[[#This Row],[Nom de l''échantillon donné par le client]],liste_groupe[[#This Row],[Dopage (+Testostérone / + EE2, ….)]]),CONCATENATE(liste_groupe[[#This Row],[Nom de l''échantillon donné par le client]],"-",liste_groupe[[#This Row],[Concentration]],liste_groupe[[#This Row],[Unité]],liste_groupe[[#This Row],[Dopage (+Testostérone / + EE2, ….)]])))
A27: =IF(ISBLANK(liste_groupe[[#This Row],[Code WF]])," ",IF(ISBLANK(liste_groupe[[#This Row],[Unité]]),CONCATENATE(liste_groupe[[#This Row],[Nom de l''échantillon donné par le client]],liste_groupe[[#This Row],[Dopage (+Testostérone / + EE2, ….)]]),CONCATENATE(liste_groupe[[#This Row],[Nom de l''échantillon donné par le client]],"-",liste_groupe[[#This Row],[Concentration]],liste_groupe[[#This Row],[Unité]],liste_groupe[[#This Row],[Dopage (+Testostérone / + EE2, ….)]])))
A28: =IF(ISBLANK(liste_groupe[[#This Row],[Code WF]])," ",IF(ISBLANK(liste_groupe[[#This Row],[Unité]]),CONCATENATE(liste_groupe[[#This Row],[Nom de l''échantillon donné par le client]],liste_groupe[[#This Row],[Dopage (+Testostérone / + EE2, ….)]]),CONCATENATE(liste_groupe[[#This Row],[Nom de l''échantillon donné par le client]],"-",liste_groupe[[#This Row],[Concentration]],liste_groupe[[#This Row],[Unité]],liste_groupe[[#This Row],[Dopage (+Testostérone / + EE2, ….)]])))
A29: =IF(ISBLANK(liste_groupe[[#This Row],[Code WF]])," ",IF(ISBLANK(liste_groupe[[#This Row],[Unité]]),CONCATENATE(liste_groupe[[#This Row],[Nom de l''échantillon donné par le client]],liste_groupe[[#This Row],[Dopage (+Testostérone / + EE2, ….)]]),CONCATENATE(liste_groupe[[#This Row],[Nom de l''échantillon donné par le client]],"-",liste_groupe[[#This Row],[Concentration]],liste_groupe[[#This Row],[Unité]],liste_groupe[[#This Row],[Dopage (+Testostérone / + EE2, ….)]])))
A30: =IF(ISBLANK(liste_groupe[[#This Row],[Code WF]])," ",IF(ISBLANK(liste_groupe[[#This Row],[Unité]]),CONCATENATE(liste_groupe[[#This Row],[Nom de l''échantillon donné par le client]],liste_groupe[[#This Row],[Dopage (+Testostérone / + EE2, ….)]]),CONCATENATE(liste_groupe[[#This Row],[Nom de l''échantillon donné par le client]],"-",liste_groupe[[#This Row],[Concentration]],liste_groupe[[#This Row],[Unité]],liste_groupe[[#This Row],[Dopage (+Testostérone / + EE2, ….)]])))
A31: =IF(ISBLANK(liste_groupe[[#This Row],[Code WF]])," ",IF(ISBLANK(liste_groupe[[#This Row],[Unité]]),CONCATENATE(liste_groupe[[#This Row],[Nom de l''échantillon donné par le client]],liste_groupe[[#This Row],[Dopage (+Testostérone / + EE2, ….)]]),CONCATENATE(liste_groupe[[#This Row],[Nom de l''échantillon donné par le client]],"-",liste_groupe[[#This Row],[Concentration]],liste_groupe[[#This Row],[Unité]],liste_groupe[[#This Row],[Dopage (+Testostérone / + EE2, ….)]])))
... A35: =IF(ISBLANK(liste_groupe[[#This Row],[Code WF]])," ",IF(ISBLANK(liste_groupe[[#This Row],[Unité]]),CONCATENATE(liste_groupe[[#This Row],[Nom de l''échantillon donné par le client]],liste_groupe[[#This Row],[Dopage (+Testostérone / + EE2, ….)]]),CONCATENATE(liste_groupe[[#This Row],[Nom de l''échantillon donné par le client]],"-",liste_groupe[[#This Row],[Concentration]],liste_groupe[[#This Row],[Unité]],liste_groupe[[#This Row],[Dopage (+Testostérone / + EE2, ….)]])))
A36: =IF(ISBLANK(liste_groupe[[#This Row],[Code WF]])," ",IF(ISBLANK(liste_groupe[[#This Row],[Unité]]),CONCATENATE(liste_groupe[[#This Row],[Nom de l''échantillon donné par le client]],liste_groupe[[#This Row],[Dopage (+Testostérone / + EE2, ….)]]),CONCATENATE(liste_groupe[[#This Row],[Nom de l''échantillon donné par le client]],"-",liste_groupe[[#This Row],[Concentration]],liste_groupe[[#This Row],[Unité]],liste_groupe[[#This Row],[Dopage (+Testostérone / + EE2, ….)]]))) -> Testo -30µg/L | B36: Témoin | C36: 30 | D36: µg/L | E36: Testo
A37: =IF(ISBLANK(liste_groupe[[#This Row],[Code WF]])," ",IF(ISBLANK(liste_groupe[[#This Row],[Unité]]),CONCATENATE(liste_groupe[[#This Row],[Nom de l''échantillon donné par le client]],liste_groupe[[#This Row],[Dopage (+Testostérone / + EE2, ….)]]),CONCATENATE(liste_groupe[[#This Row],[Nom de l''échantillon donné par le client]],"-",liste_groupe[[#This Row],[Concentration]],liste_groupe[[#This Row],[Unité]],liste_groupe[[#This Row],[Dopage (+Testostérone / + EE2, ….)]]))) -> Testo 30µg/L + EE2 -64ng/L | B37: Témoin | C37: 64 | D37: ng/L | E37: Testo 30µg/L + EE2
A38: =IF(ISBLANK(liste_groupe[[#This Row],[Code WF]])," ",IF(ISBLANK(liste_groupe[[#This Row],[Unité]]),CONCATENATE(liste_groupe[[#This Row],[Nom de l''échantillon donné par le client]],liste_groupe[[#This Row],[Dopage (+Testostérone / + EE2, ….)]]),CONCATENATE(liste_groupe[[#This Row],[Nom de l''échantillon donné par le client]],"-",liste_groupe[[#This Row],[Concentration]],liste_groupe[[#This Row],[Unité]],liste_groupe[[#This Row],[Dopage (+Testostérone / + EE2, ….)]]))) -> Testo 30µg/L + FAD-10µg/L | B38: Témoin | C38: 10 | D38: µg/L | E38: Testo 30µg/L + FAD
A39: =IF(ISBLANK(liste_groupe[[#This Row],[Code WF]])," ",IF(ISBLANK(liste_groupe[[#This Row],[Unité]]),CONCATENATE(liste_groupe[[#This Row],[Nom de l''échantillon donné par le client]],liste_groupe[[#This Row],[Dopage (+Testostérone / + EE2, ….)]]),CONCATENATE(liste_groupe[[#This Row],[Nom de l''échantillon donné par le client]],"-",liste_groupe[[#This Row],[Concentration]],liste_groupe[[#This Row],[Unité]],liste_groupe[[#This Row],[Dopage (+Testostérone / + EE2, ….)]]))) -> Fadrozole-0.016µg/L + Testostérone | B39: =B15 -> Test | C39: =C15 -> 0.016 | D39: =D15 -> µg/L | E39: =E15 -> Fadrozole | F39: + Testostérone
A40: =IF(ISBLANK(liste_groupe[[#This Row],[Code WF]])," ",IF(ISBLANK(liste_groupe[[#This Row],[Unité]]),CONCATENATE(liste_groupe[[#This Row],[Nom de l''échantillon donné par le client]],liste_groupe[[#This Row],[Dopage (+Testostérone / + EE2, ….)]]),CONCATENATE(liste_groupe[[#This Row],[Nom de l''échantillon donné par le client]],"-",liste_groupe[[#This Row],[Concentration]],liste_groupe[[#This Row],[Unité]],liste_groupe[[#This Row],[Dopage (+Testostérone / + EE2, ….)]]))) -> Fadrozole-0.08µg/L + Testostérone | B40: =B16 -> Test | C40: =C16 -> 0.08 | D40: =D16 -> µg/L | E40: =E16 -> Fadrozole | F40: + Testostérone
A41: =IF(ISBLANK(liste_groupe[[#This Row],[Code WF]])," ",IF(ISBLANK(liste_groupe[[#This Row],[Unité]]),CONCATENATE(liste_groupe[[#This Row],[Nom de l''échantillon donné par le client]],liste_groupe[[#This Row],[Dopage (+Testostérone / + EE2, ….)]]),CONCATENATE(liste_groupe[[#This Row],[Nom de l''échantillon donné par le client]],"-",liste_groupe[[#This Row],[Concentration]],liste_groupe[[#This Row],[Unité]],liste_groupe[[#This Row],[Dopage (+Testostérone / + EE2, ….)]]))) -> Fadrozole-0.4µg/L + Testostérone | B41: =B17 -> Test | C41: =C17 -> 0.4 | D41: =D17 -> µg/L | E41: =E17 -> Fadrozole | F41: + Testostérone
A42: =IF(ISBLANK(liste_groupe[[#This Row],[Code WF]])," ",IF(ISBLANK(liste_groupe[[#This Row],[Unité]]),CONCATENATE(liste_groupe[[#This Row],[Nom de l''échantillon donné par le client]],liste_groupe[[#This Row],[Dopage (+Testostérone / + EE2, ….)]]),CONCATENATE(liste_groupe[[#This Row],[Nom de l''échantillon donné par le client]],"-",liste_groupe[[#This Row],[Concentration]],liste_groupe[[#This Row],[Unité]],liste_groupe[[#This Row],[Dopage (+Testostérone / + EE2, ….)]]))) -> Fadrozole-2µg/L + Testostérone | B42: =B18 -> Test | C42: =C18 -> 2 | D42: =D18 -> µg/L | E42: =E18 -> Fadrozole | F42: + Testostérone
A43: =IF(ISBLANK(liste_groupe[[#This Row],[Code WF]])," ",IF(ISBLANK(liste_groupe[[#This Row],[Unité]]),CONCATENATE(liste_groupe[[#This Row],[Nom de l''échantillon donné par le client]],liste_groupe[[#This Row],[Dopage (+Testostérone / + EE2, ….)]]),CONCATENATE(liste_groupe[[#This Row],[Nom de l''échantillon donné par le client]],"-",liste_groupe[[#This Row],[Concentration]],liste_groupe[[#This Row],[Unité]],liste_groupe[[#This Row],[Dopage (+Testostérone / + EE2, ….)]]))) -> Fadrozole-10 µg/L + Testostérone | B43: =B19 -> Test | C43: =C19 -> 10 | D43: =D19 -> µg/L | E43: =E19 -> Fadrozole | F43: + Testostérone
...

Sheet Feuil1
A1: Nom groupe | B1: N° de valeur | C1: file name | D1: total area | E1: mean intensity | G1: total fluorescence | I1: nbre de larves
A2: 01 EE2 0 | B2: A | C2: C:\Users\Olympus\Desktop\20190122\plaque1/@01 EE2 0/A1_1.tif | D2: 4931.616 | E2: 73.0526 | G2: 360268
A3: 01 EE2 0 | B3: A | C3: C:\Users\Olympus\Desktop\20190122\plaque1/@01 EE2 0/A1_2.tif | D3: 5234.4345 | E3: 71.1281 | G3: 372315
A4: 01 EE2 0 | B4: A | C4: C:\Users\Olympus\Desktop\20190122\plaque1/@01 EE2 0/A1_3.tif | D4: 3547.3027 | E4: 66.9878 | G4: 237626
A5: 01 EE2 0 | B5: A | C5: C:\Users\Olympus\Desktop\20190122\plaque3/@01 EE2 0/A1_3.tif | D5: 21456.8555 | E5: 67.0655 | G5: 1439015
A6: 01 EE2 0 | B6: A | C6: C:\Users\Olympus\Desktop\20190122\plaque3/@01 EE2 0/A1_2.tif | D6: 21586.6348 | E6: 66.4108 | G6: 1433586
A7: 01 EE2 0 | B7: A | C7: C:\Users\Olympus\Desktop\20190122\plaque3/@01 EE2 0/A1_1.tif | D7: 15984.4921 | E7: 69.7767 | G7: 1115346

Sheet Raw data R1
A1: Nom groupe | B1: N° de valeur | C1: file name | D1: total area | E1: mean intensity | G1: total fluorescence | I1: nbre de larves | L1: (Tous)
A2: =IFERROR(LEFT(RIGHT(C2,LEN(C2)-SEARCH("@",C2)),SEARCH("/",RIGHT(C2,LEN(C2)-SEARCH("@",C2)-1))),"") | B2: =LEFT(RIGHT(RIGHT(Tableau4[[#This Row],[file name]],LEN(Tableau4[[#This Row],[file name]])-SEARCH("@",Tableau4[[#This Row],[file name]])),LEN(RIGHT(Tableau4[[#This Row],[file name]],LEN(Tableau4[[#This Row],[file name]])-SEARCH("@",Tableau4[[#This Row],[file name]])))-SEARCH("/",RIGHT(Tableau4[[#This Row],[file name]],LEN(Tableau4[[#This Row],[file name]])-SEARCH("@",Tableau4[[#This Row],[file name]])))),1) -> #VALUE! | K2: Filtre lignes : Enlever (vide) et Néant | L2: Filtre colonnes : Enlever (vide) et " "
A3: =IFERROR(LEFT(RIGHT(C3,LEN(C3)-SEARCH("@",C3)),SEARCH("/",RIGHT(C3,LEN(C3)-SEARCH("@",C3)-1))),"") | B3: =LEFT(RIGHT(RIGHT(Tableau4[[#This Row],[file name]],LEN(Tableau4[[#This Row],[file name]])-SEARCH("@",Tableau4[[#This Row],[file name]])),LEN(RIGHT(Tableau4[[#This Row],[file name]],LEN(Tableau4[[#This Row],[file name]])-SEARCH("@",Tableau4[[#This Row],[file name]])))-SEARCH("/",RIGHT(Tableau4[[#This Row],[file name]],LEN(Tableau4[[#This Row],[file name]])-SEARCH("@",Tableau4[[#This Row],[file name]])))),1) -> #VALUE! | K3: Moyenne de total fluorescence | L3: Étiquettes de colonnes
A4: =IFERROR(LEFT(RIGHT(C4,LEN(C4)-SEARCH("@",C4)),SEARCH("/",RIGHT(C4,LEN(C4)-SEARCH("@",C4)-1))),"") | B4: =LEFT(RIGHT(RIGHT(Tableau4[[#This Row],[file name]],LEN(Tableau4[[#This Row],[file name]])-SEARCH("@",Tableau4[[#This Row],[file name]])),LEN(RIGHT(Tableau4[[#This Row],[file name]],LEN(Tableau4[[#This Row],[file name]])-SEARCH("@",Tableau4[[#This Row],[file name]])))-SEARCH("/",RIGHT(Tableau4[[#This Row],[file name]],LEN(Tableau4[[#This Row],[file name]])-SEARCH("@",Tableau4[[#This Row],[file name]])))),1) -> #VALUE! | K4: Étiquettes de lignes
A5: =IFERROR(LEFT(RIGHT(C5,LEN(C5)-SEARCH("@",C5)),SEARCH("/",RIGHT(C5,LEN(C5)-SEARCH("@",C5)-1))),"") | B5: =LEFT(RIGHT(RIGHT(Tableau4[[#This Row],[file name]],LEN(Tableau4[[#This Row],[file name]])-SEARCH("@",Tableau4[[#This Row],[file name]])),LEN(RIGHT(Tableau4[[#This Row],[file name]],LEN(Tableau4[[#This Row],[file name]])-SEARCH("@",Tableau4[[#This Row],[file name]])))-SEARCH("/",RIGHT(Tableau4[[#This Row],[file name]],LEN(Tableau4[[#This Row],[file name]])-SEARCH("@",Tableau4[[#This Row],[file name]])))),1) -> #VALUE! | K5: #VALEUR!
A6: =IFERROR(LEFT(RIGHT(C6,LEN(C6)-SEARCH("@",C6)),SEARCH("/",RIGHT(C6,LEN(C6)-SEARCH("@",C6)-1))),"") | B6: =LEFT(RIGHT(RIGHT(Tableau4[[#This Row],[file name]],LEN(Tableau4[[#This Row],[file name]])-SEARCH("@",Tableau4[[#This Row],[file name]])),LEN(RIGHT(Tableau4[[#This Row],[file name]],LEN(Tableau4[[#This Row],[file name]])-SEARCH("@",Tableau4[[#This Row],[file name]])))-SEARCH("/",RIGHT(Tableau4[[#This Row],[file name]],LEN(Tableau4[[#This Row],[file name]])-SEARCH("@",Tableau4[[#This Row],[file name]])))),1) -> #VALUE!
A7: =IFERROR(LEFT(RIGHT(C7,LEN(C7)-SEARCH("@",C7)),SEARCH("/",RIGHT(C7,LEN(C7)-SEARCH("@",C7)-1))),"") | B7: =LEFT(RIGHT(RIGHT(Tableau4[[#This Row],[file name]],LEN(Tableau4[[#This Row],[file name]])-SEARCH("@",Tableau4[[#This Row],[file name]])),LEN(RIGHT(Tableau4[[#This Row],[file name]],LEN(Tableau4[[#This Row],[file name]])-SEARCH("@",Tableau4[[#This Row],[file name]])))-SEARCH("/",RIGHT(Tableau4[[#This Row],[file name]],LEN(Tableau4[[#This Row],[file name]])-SEARCH("@",Tableau4[[#This Row],[file name]])))),1) -> #VALUE!
A8: =IFERROR(LEFT(RIGHT(C8,LEN(C8)-SEARCH("@",C8)),SEARCH("/",RIGHT(C8,LEN(C8)-SEARCH("@",C8)-1))),"") | B8: =LEFT(RIGHT(RIGHT(Tableau4[[#This Row],[file name]],LEN(Tableau4[[#This Row],[file name]])-SEARCH("@",Tableau4[[#This Row],[file name]])),LEN(RIGHT(Tableau4[[#This Row],[file name]],LEN(Tableau4[[#This Row],[file name]])-SEARCH("@",Tableau4[[#This Row],[file name]])))-SEARCH("/",RIGHT(Tableau4[[#This Row],[file name]],LEN(Tableau4[[#This Row],[file name]])-SEARCH("@",Tableau4[[#This Row],[file name]])))),1) -> #VALUE!
A9: =IFERROR(LEFT(RIGHT(C9,LEN(C9)-SEARCH("@",C9)),SEARCH("/",RIGHT(C9,LEN(C9)-SEARCH("@",C9)-1))),"") | B9: =LEFT(RIGHT(RIGHT(Tableau4[[#This Row],[file name]],LEN(Tableau4[[#This Row],[file name]])-SEARCH("@",Tableau4[[#This Row],[file name]])),LEN(RIGHT(Tableau4[[#This Row],[file name]],LEN(Tableau4[[#This Row],[file name]])-SEARCH("@",Tableau4[[#This Row],[file name]])))-SEARCH("/",RIGHT(Tableau4[[#This Row],[file name]],LEN(Tableau4[[#This Row],[file name]])-SEARCH("@",Tableau4[[#This Row],[file name]])))),1) -> #VALUE!
A10: =IFERROR(LEFT(RIGHT(C10,LEN(C10)-SEARCH("@",C10)),SEARCH("/",RIGHT(C10,LEN(C10)-SEARCH("@",C10)-1))),"") | B10: =LEFT(RIGHT(RIGHT(Tableau4[[#This Row],[file name]],LEN(Tableau4[[#This Row],[file name]])-SEARCH("@",Tableau4[[#This Row],[file name]])),LEN(RIGHT(Tableau4[[#This Row],[file name]],LEN(Tableau4[[#This Row],[file name]])-SEARCH("@",Tableau4[[#This Row],[file name]])))-SEARCH("/",RIGHT(Tableau4[[#This Row],[file name]],LEN(Tableau4[[#This Row],[file name]])-SEARCH("@",Tableau4[[#This Row],[file name]])))),1) -> #VALUE!
A11: =IFERROR(LEFT(RIGHT(C11,LEN(C11)-SEARCH("@",C11)),SEARCH("/",RIGHT(C11,LEN(C11)-SEARCH("@",C11)-1))),"") | B11: =LEFT(RIGHT(RIGHT(Tableau4[[#This Row],[file name]],LEN(Tableau4[[#This Row],[file name]])-SEARCH("@",Tableau4[[#This Row],[file name]])),LEN(RIGHT(Tableau4[[#This Row],[file name]],LEN(Tableau4[[#This Row],[file name]])-SEARCH("@",Tableau4[[#This Row],[file name]])))-SEARCH("/",RIGHT(Tableau4[[#This Row],[file name]],LEN(Tableau4[[#This Row],[file name]])-SEARCH("@",Tableau4[[#This Row],[file name]])))),1) -> #VALUE!
A12: =IFERROR(LEFT(RIGHT(C12,LEN(C12)-SEARCH("@",C12)),SEARCH("/",RIGHT(C12,LEN(C12)-SEARCH("@",C12)-1))),"") | B12: =LEFT(RIGHT(RIGHT(Tableau4[[#This Row],[file name]],LEN(Tableau4[[#This Row],[file name]])-SEARCH("@",Tableau4[[#This Row],[file name]])),LEN(RIGHT(Tableau4[[#This Row],[file name]],LEN(Tableau4[[#This Row],[file name]])-SEARCH("@",Tableau4[[#This Row],[file name]])))-SEARCH("/",RIGHT(Tableau4[[#This Row],[file name]],LEN(Tableau4[[#This Row],[file name]])-SEARCH("@",Tableau4[[#This Row],[file name]])))),1) -> #VALUE!
A13: =IFERROR(LEFT(RIGHT(C13,LEN(C13)-SEARCH("@",C13)),SEARCH("/",RIGHT(C13,LEN(C13)-SEARCH("@",C13)-1))),"") | B13: =LEFT(RIGHT(RIGHT(Tableau4[[#This Row],[file name]],LEN(Tableau4[[#This Row],[file name]])-SEARCH("@",Tableau4[[#This Row],[file name]])),LEN(RIGHT(Tableau4[[#This Row],[file name]],LEN(Tableau4[[#This Row],[file name]])-SEARCH("@",Tableau4[[#This Row],[file name]])))-SEARCH("/",RIGHT(Tableau4[[#This Row],[file name]],LEN(Tableau4[[#This Row],[file name]])-SEARCH("@",Tableau4[[#This Row],[file name]])))),1) -> #VALUE!
A14: =IFERROR(LEFT(RIGHT(C14,LEN(C14)-SEARCH("@",C14)),SEARCH("/",RIGHT(C14,LEN(C14)-SEARCH("@",C14)-1))),"") | B14: =LEFT(RIGHT(RIGHT(Tableau4[[#This Row],[file name]],LEN(Tableau4[[#This Row],[file name]])-SEARCH("@",Tableau4[[#This Row],[file name]])),LEN(RIGHT(Tableau4[[#This Row],[file name]],LEN(Tableau4[[#This Row],[file name]])-SEARCH("@",Tableau4[[#This Row],[file name]])))-SEARCH("/",RIGHT(Tableau4[[#This Row],[file name]],LEN(Tableau4[[#This Row],[file name]])-SEARCH("@",Tableau4[[#This Row],[file name]])))),1) -> #VALUE!
A15: =IFERROR(LEFT(RIGHT(C15,LEN(C15)-SEARCH("@",C15)),SEARCH("/",RIGHT(C15,LEN(C15)-SEARCH("@",C15)-1))),"") | B15: =LEFT(RIGHT(RIGHT(Tableau4[[#This Row],[file name]],LEN(Tableau4[[#This Row],[file name]])-SEARCH("@",Tableau4[[#This Row],[file name]])),LEN(RIGHT(Tableau4[[#This Row],[file name]],LEN(Tableau4[[#This Row],[file name]])-SEARCH("@",Tableau4[[#This Row],[file name]])))-SEARCH("/",RIGHT(Tableau4[[#This Row],[file name]],LEN(Tableau4[[#This Row],[file name]])-SEARCH("@",Tableau4[[#This Row],[file name]])))),1) -> #VALUE!
A16: =IFERROR(LEFT(RIGHT(C16,LEN(C16)-SEARCH("@",C16)),SEARCH("/",RIGHT(C16,LEN(C16)-SEARCH("@",C16)-1))),"") | B16: =LEFT(RIGHT(RIGHT(Tableau4[[#This Row],[file name]],LEN(Tableau4[[#This Row],[file name]])-SEARCH("@",Tableau4[[#This Row],[file name]])),LEN(RIGHT(Tableau4[[#This Row],[file name]],LEN(Tableau4[[#This Row],[file name]])-SEARCH("@",Tableau4[[#This Row],[file name]])))-SEARCH("/",RIGHT(Tableau4[[#This Row],[file name]],LEN(Tableau4[[#This Row],[file name]])-SEARCH("@",Tableau4[[#This Row],[file name]])))),1) -> #VALUE!
A17: =IFERROR(LEFT(RIGHT(C17,LEN(C17)-SEARCH("@",C17)),SEARCH("/",RIGHT(C17,LEN(C17)-SEARCH("@",C17)-1))),"") | B17: =LEFT(RIGHT(RIGHT(Tableau4[[#This Row],[file name]],LEN(Tableau4[[#This Row],[file name]])-SEARCH("@",Tableau4[[#This Row],[file name]])),LEN(RIGHT(Tableau4[[#This Row],[file name]],LEN(Tableau4[[#This Row],[file name]])-SEARCH("@",Tableau4[[#This Row],[file name]])))-SEARCH("/",RIGHT(Tableau4[[#This Row],[file name]],LEN(Tableau4[[#This Row],[file name]])-SEARCH("@",Tableau4[[#This Row],[file name]])))),1) -> #VALUE!
... A1557: =IFERROR(LEFT(RIGHT(C1557,LEN(C1557)-SEARCH("@",C1557)),SEARCH("/",RIGHT(C1557,LEN(C1557)-SEARCH("@",C1557)-1))),"") | B1557: =LEFT(RIGHT(RIGHT(Tableau4[[#This Row],[file name]],LEN(Tableau4[[#This Row],[file name]])-SEARCH("@",Tableau4[[#This Row],[file name]])),LEN(RIGHT(Tableau4[[#This Row],[file name]],LEN(Tableau4[[#This Row],[file name]])-SEARCH("@",Tableau4[[#This Row],[file name]])))-SEARCH("/",RIGHT(Tableau4[[#This Row],[file name]],LEN(Tableau4[[#This Row],[file name]])-SEARCH("@",Tableau4[[#This Row],[file name]])))),1) -> #VALUE!

Sheet R1
A1: 3. Expérimentateur 1 : copier et coller les valeurs des intensités totales de fluorescences obtenues dans le fichier raw data lors du traitement des images.
A3: R1 | B3: Non dopé | O3: avec testo
A4: Noms des groupes | B4: ='Page de garde'!A7 -> Témoin solvant | C4: ='Page de garde'!A9 -> EE2-33.8ng/L | D4: ='Page de garde'!A10 -> EE2-50.6ng/L | E4: ='Page de garde'!A11 -> EE2-76ng/L | F4: ='Page de garde'!A12 -> EE2-114ng/L | G4: ='Page de garde'!A13 -> EE2-170.9ng/L | H4: ='Page de garde'!A14 -> EE2-488ng/L | I4: ='Page de garde'!A15 -> Fadrozole-0.016µg/L | J4: ='Page de garde'!A16 -> Fadrozole-0.08µg/L | K4: ='Page de garde'!A17 -> Fadrozole-0.4µg/L | L4: ='Page de garde'!A18 -> Fadrozole-2µg/L | M4: ='Page de garde'!A19 -> Fadrozole-10 µg/L | O4: ='Page de garde'!A36 -> Testo -30µg/L | P4: ='Page de garde'!A37 -> Testo 30µg/L + EE2 -64ng/L | Q4: ='Page de garde'!A38 -> Testo 30µg/L + FAD-10µg/L | R4: ='Page de garde'!A39 -> Fadrozole-0.016µg/L + Testostérone | S4: ='Page de garde'!A40 -> Fadrozole-0.08µg/L + Testostérone | T4: ='Page de garde'!A41 -> Fadrozole-0.4µg/L + Testostérone | U4: ='Page de garde'!A42 -> Fadrozole-2µg/L + Testostérone | V4: ='Page de garde'!A43 -> Fadrozole-10 µg/L + Testostérone
A5: Données brutes | B5: 158766 | C5: 57136 | D5: 186916 | E5: 1223699 | F5: 2276002 | G5: 5426030 | H5: 14275997 | I5: 305488 | J5: 100730 | K5: 460106 | L5: 95067 | M5: 135736 | O5: 819719 | P5: 3016064 | Q5: 168672 | R5: 704190 | S5: 331980 | T5: 396011 | U5: 279614 | V5: 246421
B6: 261710 | C6: 436459 | D6: 4102877 | E6: 637027 | F6: 6327600 | G6: 12479308 | H6: 5166605 | J6: 28464 | K6: 206076 | L6: 222536 | M6: 293601 | O6: 380926 | P6: 6364434 | Q6: 140088 | R6: 762324 | S6: 1216717 | T6: 3486935 | U6: 252554 | V6: 97877
B7: 101318 | C7: 309636 | D7: 163681 | E7: 1644129 | F7: 5805732 | G7: 6832013 | H7: 13720090 | I7: 77093 | J7: 268593 | K7: 80537 | L7: 45186 | M7: 262847 | O7: 46897 | P7: 5294147 | Q7: 189563 | R7: 63918 | S7: 66285 | T7: 587766 | U7: 285975 | V7: 375150
B8: 86576 | C8: 340614 | D8: 41827 | E8: 229004 | F8: 6172423 | G8: 10358241 | H8: 9790582 | I8: 78821 | J8: 47629 | K8: 338230 | L8: 310877 | M8: 56167 | O8: 6736051 | P8: 4331760 | Q8: 35504 | R8: 740718 | S8: 301847 | T8: 220674 | U8: 6326925 | V8: 107794
B9: 112558 | C9: 102767 | D9: 184680 | E9: 56960 | F9: 3221587 | G9: 1245206 | H9: 14734883 | I9: 10921 | J9: 94381 | K9: 248839 | L9: 116135 | M9: 69572 | O9: 28732 | P9: 4275985 | Q9: 45650 | R9: 2799406 | S9: 3367912 | T9: 1000867 | U9: 798422 | V9: 162300
B10: 7589 | C10: 854529 | D10: 168508 | E10: 183911 | F10: 3427207 | G10: 8430899 | H10: 11851558 | I10: 98396 | J10: 214045 | K10: 134101 | L10: 46784 | M10: 48565 | O10: 1319588 | P10: 6080033 | Q10: 58464 | R10: 323828 | S10: 4872627 | T10: 653321 | U10: 587834 | V10: 3059019
B11: 47764 | C11: 26914 | D11: 68208 | E11: 909449 | F11: 4703796 | G11: 8972192 | H11: 14321736 | I11: 19959 | J11: 590542 | K11: 21507 | L11: 103763 | M11: 42573 | O11: 2132397 | P11: 7760937 | Q11: 287830 | R11: 2090821 | S11: 615157 | T11: 408620 | U11: 200305 | V11: 68296
B12: 123468 | C12: 44440 | E12: 71596 | F12: 5762709 | G12: 7213127 | H12: 18016628 | I12: 265729 | J12: 34192 | K12: 387269 | L12: 12177 | M12: 17355 | O12: 4916 | Q12: 84801 | R12: 666750 | S12: 1324940 | T12: 348858 | U12: 309587 | V12: 220464
O13: 1283555
O14: 1050960
O15: 156410
O16: 4685186
O17: 534144
O18: 488837
O19: 78980
O20: 498265
A22: =A4 -> Noms des groupes | B22: =B4 -> Témoin solvant | C22: =C4 -> EE2-33.8ng/L | D22: =D4 -> EE2-50.6ng/L | E22: =E4 -> EE2-76ng/L | F22: =F4 -> EE2-114ng/L | G22: =G4 -> EE2-170.9ng/L | H22: =H4 -> EE2-488ng/L | ... M22: =M4 -> Fadrozole-10 µg/L | N22: Nom des groupes | O22: =O4 -> Testo -30µg/L | P22: =P4 -> Testo 30µg/L + EE2 -64ng/L | Q22: =Q4 -> Testo 30µg/L + FAD-10µg/L | R22: =R4 -> Fadrozole-0.016µg/L + Testostérone | S22: =S4 -> Fadrozole-0.08µg/L + Testostérone | T22: =T4 -> Fadrozole-0.4µg/L + Testostérone | U22: =U4 -> Fadrozole-2µg/L + Testostérone | V22: =V4 -> Fadrozole-10 µg/L + Testostérone
A23: mean | B23: =AVERAGE(B5:B20) -> 112468.62 | C23: =AVERAGE(C5:C20) -> 271561.88 | D23: =AVERAGE(D5:D20) -> 702385.29 | E23: =AVERAGE(E5:E20) -> 619471.88 | F23: =AVERAGE(F5:F20) -> 4712132 | G23: =AVERAGE(G5:G20) -> 7619627 | H23: =AVERAGE(H5:H20) -> 12734760 | I23: =AVERAGE(I5:I20) -> 122343.86 | ... M23: =AVERAGE(M5:M20) -> 115802 | N23: mean | O23: =AVERAGE(O5:O20) -> 1265347.7 | P23: =AVERAGE(P5:P20) -> 5303337.1 | Q23: =AVERAGE(Q5:Q20) -> 126321.5 | R23: =AVERAGE(R5:R20) -> 1018994.4 | S23: =AVERAGE(S5:S20) -> 1512183.1 | T23: =AVERAGE(T5:T20) -> 887881.5 | U23: =AVERAGE(U5:U20) -> 1130152 | V23: =AVERAGE(V5:V20) -> 542165.12
A24: SD | B24: =STDEV(B5:B20) -> 76081.364 | C24: =STDEV(C5:C20) -> 282632.18 | D24: =STDEV(D5:D20) -> 1500600.8 | E24: =STDEV(E5:E20) -> 592594 | F24: =STDEV(F5:F20) -> 1551470 | G24: =STDEV(G5:G20) -> 3377124.5 | H24: =STDEV(H5:H20) -> 3863540.2 | I24: =STDEV(I5:I20) -> 116557.69 | ... M24: =STDEV(M5:M20) -> 106167.48 | N24: SD | O24: =STDEV(O5:O20) -> 1868537.2 | P24: =STDEV(P5:P20) -> 1581144 | Q24: =STDEV(Q5:Q20) -> 87138.532 | R24: =STDEV(R5:R20) -> 932017.81 | S24: =STDEV(S5:S20) -> 1715964.7 | T24: =STDEV(T5:T20) -> 1077051.1 | U24: =STDEV(U5:U20) -> 2109663.9 | V24: =STDEV(V5:V20) -> 1021785.8
B26: Non dopé | O26: avec testo
A27: Noms des groupes | B27: =B4 -> Témoin solvant | C27: =C4 -> EE2-33.8ng/L | D27: =D4 -> EE2-50.6ng/L | E27: =E4 -> EE2-76ng/L | F27: =F4 -> EE2-114ng/L | G27: =G4 -> EE2-170.9ng/L | H27: =H4 -> EE2-488ng/L | I27: =I4 -> Fadrozole-0.016µg/L | ... M27: =M4 -> Fadrozole-10 µg/L | O27: =O4 -> Testo -30µg/L | P27: =P4 -> Testo 30µg/L + EE2 -64ng/L | Q27: =Q4 -> Testo 30µg/L + FAD-10µg/L | R27: =R4 -> Fadrozole-0.016µg/L + Testostérone | S27: =S4 -> Fadrozole-0.08µg/L + Testostérone | T27: =T4 -> Fadrozole-0.4µg/L + Testostérone | U27: =U4 -> Fadrozole-2µg/L + Testostérone | V27: =V4 -> Fadrozole-10 µg/L + Testostérone
A28: Données normalisées sur la moyenne du groupe "Testo" | B28: =IF(B5="","",(B5/$O$23)) -> 0.12547223 | C28: =IF(C5="","",(C5/$O$23)) -> 0.045154388 | D28: =IF(D5="","",(D5/$O$23)) -> 0.14771908 | E28: =IF(E5="","",(E5/$O$23)) -> 0.96708518 | F28: =IF(F5="","",(F5/$O$23)) -> 1.7987167 | G28: =IF(G5="","",(G5/$O$23)) -> 4.2881732 | H28: =IF(H5="","",(H5/$O$23)) -> 11.282272 | I28: =IF(I5="","",(I5/$O$23)) -> 0.24142613 | ... M28: =IF(M5="","",(M5/$O$23)) -> 0.1072717 | O28: =IF(O5="","",(O5/$O$23)) -> 0.64782115 | P28: =IF(P5="","",(P5/$O$23)) -> 2.3835852 | Q28: =IF(Q5="","",(Q5/$O$23)) -> 0.13330091 | R28: =IF(R5="","",(R5/$O$23)) -> 0.55651898 | S28: =IF(S5="","",(S5/$O$23)) -> 0.26236267 | T28: =IF(T5="","",(T5/$O$23)) -> 0.31296615 | U28: =IF(U5="","",(U5/$O$23)) -> 0.220978 | V28: =IF(V5="","",(V5/$O$23)) -> 0.19474568
B29: =IF(B6="","",(B6/$O$23)) -> 0.20682853 | C29: =IF(C6="","",(C6/$O$23)) -> 0.34493207 | D29: =IF(D6="","",(D6/$O$23)) -> 3.2424898 | E29: =IF(E6="","",(E6/$O$23)) -> 0.50344028 | F29: =IF(F6="","",(F6/$O$23)) -> 5.0006809 | G29: =IF(G6="","",(G6/$O$23)) -> 9.8623549 | H29: =IF(H6="","",(H6/$O$23)) -> 4.0831505 | I29: =IF(I6="","",(I6/$O$23)) | ... M29: =IF(M6="","",(M6/$O$23)) -> 0.23203188 | O29: =IF(O6="","",(O6/$O$23)) -> 0.30104453 | P29: =IF(P6="","",(P6/$O$23)) -> 5.0297907 | Q29: =IF(Q6="","",(Q6/$O$23)) -> 0.11071107 | R29: =IF(R6="","",(R6/$O$23)) -> 0.60246208 | S29: =IF(S6="","",(S6/$O$23)) -> 0.96156733 | T29: =IF(T6="","",(T6/$O$23)) -> 2.7557129 | U29: =IF(U6="","",(U6/$O$23)) -> 0.19959257 | V29: =IF(V6="","",(V6/$O$23)) -> 0.077351862
B30: =IF(B7="","",(B7/$O$23)) -> 0.080071273 | C30: =IF(C7="","",(C7/$O$23)) -> 0.24470428 | D30: =IF(D7="","",(D7/$O$23)) -> 0.12935654 | E30: =IF(E7="","",(E7/$O$23)) -> 1.2993496 | F30: =IF(F7="","",(F7/$O$23)) -> 4.5882504 | G30: =IF(G7="","",(G7/$O$23)) -> 5.3993168 | H30: =IF(H7="","",(H7/$O$23)) -> 10.842941 | I30: =IF(I7="","",(I7/$O$23)) -> 0.060926337 | ... M30: =IF(M7="","",(M7/$O$23)) -> 0.2077271 | O30: =IF(O7="","",(O7/$O$23)) -> 0.037062541 | P30: =IF(P7="","",(P7/$O$23)) -> 4.1839465 | Q30: =IF(Q7="","",(Q7/$O$23)) -> 0.149811 | R30: =IF(R7="","",(R7/$O$23)) -> 0.050514179 | S30: =IF(S7="","",(S7/$O$23)) -> 0.052384811 | T30: =IF(T7="","",(T7/$O$23)) -> 0.46450948 | U30: =IF(U7="","",(U7/$O$23)) -> 0.22600508 | V30: =IF(V7="","",(V7/$O$23)) -> 0.29647978
B31: =IF(B8="","",(B8/$O$23)) -> 0.06842072 | C31: =IF(C8="","",(C8/$O$23)) -> 0.26918609 | D31: =IF(D8="","",(D8/$O$23)) -> 0.033055737 | E31: =IF(E8="","",(E8/$O$23)) -> 0.18098109 | F31: =IF(F8="","",(F8/$O$23)) -> 4.878045 | G31: =IF(G8="","",(G8/$O$23)) -> 8.1860828 | H31: =IF(H8="","",(H8/$O$23)) -> 7.7374639 | I31: =IF(I8="","",(I8/$O$23)) -> 0.06229197 | ... M31: =IF(M8="","",(M8/$O$23)) -> 0.04438859 | O31: =IF(O8="","",(O8/$O$23)) -> 5.3234783 | P31: =IF(P8="","",(P8/$O$23)) -> 3.4233753 | Q31: =IF(Q8="","",(Q8/$O$23)) -> 0.028058691 | R31: =IF(R8="","",(R8/$O$23)) -> 0.58538693 | S31: =IF(S8="","",(S8/$O$23)) -> 0.23854866 | T31: =IF(T8="","",(T8/$O$23)) -> 0.17439792 | U31: =IF(U8="","",(U8/$O$23)) -> 5.0001474 | V31: =IF(V8="","",(V8/$O$23)) -> 0.085189234
B32: =IF(B9="","",(B9/$O$23)) -> 0.088954207 | C32: =IF(C9="","",(C9/$O$23)) -> 0.081216413 | D32: =IF(D9="","",(D9/$O$23)) -> 0.14595198 | E32: =IF(E9="","",(E9/$O$23)) -> 0.045015295 | F32: =IF(F9="","",(F9/$O$23)) -> 2.5460093 | G32: =IF(G9="","",(G9/$O$23)) -> 0.98408209 | H32: =IF(H9="","",(H9/$O$23)) -> 11.644928 | I32: =IF(I9="","",(I9/$O$23)) -> 0.0086308294 | ... M32: =IF(M9="","",(M9/$O$23)) -> 0.054982516 | O32: =IF(O9="","",(O9/$O$23)) -> 0.022706802 | P32: =IF(P9="","",(P9/$O$23)) -> 3.3792965 | Q32: =IF(Q9="","",(Q9/$O$23)) -> 0.036077041 | R32: =IF(R9="","",(R9/$O$23)) -> 2.2123611 | S32: =IF(S9="","",(S9/$O$23)) -> 2.6616495 | T32: =IF(T9="","",(T9/$O$23)) -> 0.79098181 | U32: =IF(U9="","",(U9/$O$23)) -> 0.63099021 | V32: =IF(V9="","",(V9/$O$23)) -> 0.12826514
B33: =IF(B10="","",(B10/$O$23)) -> 0.005997561 | C33: =IF(C10="","",(C10/$O$23)) -> 0.67533138 | D33: =IF(D10="","",(D10/$O$23)) -> 0.1331713 | E33: =IF(E10="","",(E10/$O$23)) -> 0.14534424 | F33: =IF(F10="","",(F10/$O$23)) -> 2.7085101 | G33: =IF(G10="","",(G10/$O$23)) -> 6.662911 | H33: =IF(H10="","",(H10/$O$23)) -> 9.3662462 | I33: =IF(I10="","",(I10/$O$23)) -> 0.077762026 | ... M33: =IF(M10="","",(M10/$O$23)) -> 0.038380755 | O33: =IF(O10="","",(O10/$O$23)) -> 1.0428659 | P33: =IF(P10="","",(P10/$O$23)) -> 4.8050295 | Q33: =IF(Q10="","",(Q10/$O$23)) -> 0.046203902 | R33: =IF(R10="","",(R10/$O$23)) -> 0.25592017 | S33: =IF(S10="","",(S10/$O$23)) -> 3.8508206 | T33: =IF(T10="","",(T10/$O$23)) -> 0.51631738 | U33: =IF(U10="","",(U10/$O$23)) -> 0.46456322 | V33: =IF(V10="","",(V10/$O$23)) -> 2.4175324
B34: =IF(B11="","",(B11/$O$23)) -> 0.037747728 | C34: =IF(C11="","",(C11/$O$23)) -> 0.021270043 | D34: =IF(D11="","",(D11/$O$23)) -> 0.053904552 | E34: =IF(E11="","",(E11/$O$23)) -> 0.71873447 | F34: =IF(F11="","",(F11/$O$23)) -> 3.7173941 | G34: =IF(G11="","",(G11/$O$23)) -> 7.090693 | H34: =IF(H11="","",(H11/$O$23)) -> 11.31842 | I34: =IF(I11="","",(I11/$O$23)) -> 0.01577353 | ... M34: =IF(M11="","",(M11/$O$23)) -> 0.033645298 | O34: =IF(O11="","",(O11/$O$23)) -> 1.6852261 | P34: =IF(P11="","",(P11/$O$23)) -> 6.1334423 | Q34: =IF(Q11="","",(Q11/$O$23)) -> 0.22747108 | R34: =IF(R11="","",(R11/$O$23)) -> 1.6523688 | S34: =IF(S11="","",(S11/$O$23)) -> 0.4861565 | T34: =IF(T11="","",(T11/$O$23)) -> 0.322931 | U34: =IF(U11="","",(U11/$O$23)) -> 0.15830036 | V34: =IF(V11="","",(V11/$O$23)) -> 0.053974098
B35: =IF(B12="","",(B12/$O$23)) -> 0.097576343 | C35: =IF(C12="","",(C12/$O$23)) -> 0.035120782 | D35: =IF(D12="","",(D12/$O$23)) | E35: =IF(E12="","",(E12/$O$23)) -> 0.056582077 | F35: =IF(F12="","",(F12/$O$23)) -> 4.5542494 | G35: =IF(G12="","",(G12/$O$23)) -> 5.7005099 | H35: =IF(H12="","",(H12/$O$23)) -> 14.23848 | I35: =IF(I12="","",(I12/$O$23)) -> 0.21000473 | ... M35: =IF(M12="","",(M12/$O$23)) -> 0.013715598 | O35: =IF(O12="","",(O12/$O$23)) -> 0.0038850982 | P35: =IF(P12="","",(P12/$O$23)) | Q35: =IF(Q12="","",(Q12/$O$23)) -> 0.067017944 | R35: =IF(R12="","",(R12/$O$23)) -> 0.52693027 | S35: =IF(S12="","",(S12/$O$23)) -> 1.0470956 | T35: =IF(T12="","",(T12/$O$23)) -> 0.2757013 | U35: =IF(U12="","",(U12/$O$23)) -> 0.24466556 | V35: =IF(V12="","",(V12/$O$23)) -> 0.17423195
B36: =IF(B13="","",(B13/$O$23)) | C36: =IF(C13="","",(C13/$O$23)) | D36: =IF(D13="","",(D13/$O$23)) | E36: =IF(E13="","",(E13/$O$23)) | F36: =IF(F13="","",(F13/$O$23)) | G36: =IF(G13="","",(G13/$O$23)) | H36: =IF(H13="","",(H13/$O$23)) | I36: =IF(I13="","",(I13/$O$23)) | ... M36: =IF(M13="","",(M13/$O$23)) | O36: =IF(O13="","",(O13/$O$23)) -> 1.0143892 | P36: =IF(P13="","",(P13/$O$23)) | Q36: =IF(Q13="","",(Q13/$O$23)) | R36: =IF(R13="","",(R13/$O$23)) | S36: =IF(S13="","",(S13/$O$23)) | T36: =IF(T13="","",(T13/$O$23)) | U36: =IF(U13="","",(U13/$O$23)) | V36: =IF(V13="","",(V13/$O$23))
B37: =IF(B14="","",(B14/$O$23)) | C37: =IF(C14="","",(C14/$O$23)) | D37: =IF(D14="","",(D14/$O$23)) | E37: =IF(E14="","",(E14/$O$23)) | F37: =IF(F14="","",(F14/$O$23)) | G37: =IF(G14="","",(G14/$O$23)) | H37: =IF(H14="","",(H14/$O$23)) | I37: =IF(I14="","",(I14/$O$23)) | ... M37: =IF(M14="","",(M14/$O$23)) | O37: =IF(O14="","",(O14/$O$23)) -> 0.83057014 | P37: =IF(P14="","",(P14/$O$23)) | Q37: =IF(Q14="","",(Q14/$O$23)) | R37: =IF(R14="","",(R14/$O$23)) | S37: =IF(S14="","",(S14/$O$23)) | T37: =IF(T14="","",(T14/$O$23)) | U37: =IF(U14="","",(U14/$O$23)) | V37: =IF(V14="","",(V14/$O$23))
B38: =IF(B15="","",(B15/$O$23)) | C38: =IF(C15="","",(C15/$O$23)) | D38: =IF(D15="","",(D15/$O$23)) | E38: =IF(E15="","",(E15/$O$23)) | F38: =IF(F15="","",(F15/$O$23)) | G38: =IF(G15="","",(G15/$O$23)) | H38: =IF(H15="","",(H15/$O$23)) | I38: =IF(I15="","",(I15/$O$23)) | ... M38: =IF(M15="","",(M15/$O$23)) | O38: =IF(O15="","",(O15/$O$23)) -> 0.12361029 | P38: =IF(P15="","",(P15/$O$23)) | Q38: =IF(Q15="","",(Q15/$O$23)) | R38: =IF(R15="","",(R15/$O$23)) | S38: =IF(S15="","",(S15/$O$23)) | T38: =IF(T15="","",(T15/$O$23)) | U38: =IF(U15="","",(U15/$O$23)) | V38: =IF(V15="","",(V15/$O$23))
B39: =IF(B16="","",(B16/$O$23)) | C39: =IF(C16="","",(C16/$O$23)) | D39: =IF(D16="","",(D16/$O$23)) | E39: =IF(E16="","",(E16/$O$23)) | F39: =IF(F16="","",(F16/$O$23)) | G39: =IF(G16="","",(G16/$O$23)) | H39: =IF(H16="","",(H16/$O$23)) | I39: =IF(I16="","",(I16/$O$23)) | ... M39: =IF(M16="","",(M16/$O$23)) | O39: =IF(O16="","",(O16/$O$23)) -> 3.7026867 | P39: =IF(P16="","",(P16/$O$23)) | Q39: =IF(Q16="","",(Q16/$O$23)) | R39: =IF(R16="","",(R16/$O$23)) | S39: =IF(S16="","",(S16/$O$23)) | T39: =IF(T16="","",(T16/$O$23)) | U39: =IF(U16="","",(U16/$O$23)) | V39: =IF(V16="","",(V16/$O$23))
B40: =IF(B17="","",(B17/$O$23)) | C40: =IF(C17="","",(C17/$O$23)) | D40: =IF(D17="","",(D17/$O$23)) | E40: =IF(E17="","",(E17/$O$23)) | F40: =IF(F17="","",(F17/$O$23)) | G40: =IF(G17="","",(G17/$O$23)) | H40: =IF(H17="","",(H17/$O$23)) | I40: =IF(I17="","",(I17/$O$23)) | ... M40: =IF(M17="","",(M17/$O$23)) | O40: =IF(O17="","",(O17/$O$23)) -> 0.4221322 | P40: =IF(P17="","",(P17/$O$23)) | Q40: =IF(Q17="","",(Q17/$O$23)) | R40: =IF(R17="","",(R17/$O$23)) | S40: =IF(S17="","",(S17/$O$23)) | T40: =IF(T17="","",(T17/$O$23)) | U40: =IF(U17="","",(U17/$O$23)) | V40: =IF(V17="","",(V17/$O$23))
... B43: =IF(B20="","",(B20/$O$23)) | C43: =IF(C20="","",(C20/$O$23)) | D43: =IF(D20="","",(D20/$O$23)) | E43: =IF(E20="","",(E20/$O$23)) | F43: =IF(F20="","",(F20/$O$23)) | G43: =IF(G20="","",(G20/$O$23)) | H43: =IF(H20="","",(H20/$O$23)) | I43: =IF(I20="","",(I20/$O$23)) | ... M43: =IF(M20="","",(M20/$O$23)) | O43: =IF(O20="","",(O20/$O$23)) -> 0.39377715 | P43: =IF(P20="","",(P20/$O$23)) | Q43: =IF(Q20="","",(Q20/$O$23)) | R43: =IF(R20="","",(R20/$O$23)) | S43: =IF(S20="","",(S20/$O$23)) | T43: =IF(T20="","",(T20/$O$23)) | U43: =IF(U20="","",(U20/$O$23)) | V43: =IF(V20="","",(V20/$O$23))
A45: =A4 -> Noms des groupes | B45: =B4 -> Témoin solvant | C45: =C4 -> EE2-33.8ng/L | D45: =D4 -> EE2-50.6ng/L | E45: =E4 -> EE2-76ng/L | F45: =F4 -> EE2-114ng/L | G45: =G4 -> EE2-170.9ng/L | H45: =H4 -> EE2-488ng/L | ... M45: =M4 -> Fadrozole-10 µg/L | N45: =N22 -> Nom des groupes | O45: =O4 -> Testo -30µg/L | P45: =P4 -> Testo 30µg/L + EE2 -64ng/L | Q45: =Q4 -> Testo 30µg/L + FAD-10µg/L | R45: =R4 -> Fadrozole-0.016µg/L + Testostérone | S45: =S4 -> Fadrozole-0.08µg/L + Testostérone | T45: =T4 -> Fadrozole-0.4µg/L + Testostérone | U45: =U4 -> Fadrozole-2µg/L + Testostérone | V45: =V4 -> Fadrozole-10 µg/L + Testostérone
A46: mean | B46: =AVERAGE(B28:B43) -> 0.088883574 | C46: =AVERAGE(C28:C43) -> 0.21461443 | D46: =AVERAGE(D28:D43) -> 0.55509272 | E46: =AVERAGE(E28:E43) -> 0.48956653 | F46: =AVERAGE(F28:F43) -> 3.723982 | G46: =AVERAGE(G28:G43) -> 6.0217655 | H46: =AVERAGE(H28:H43) -> 10.064238 | I46: =AVERAGE(I28:I43) -> 0.096687937 | ... M46: =AVERAGE(M28:M43) -> 0.091517929 | N46: mean | O46: =AVERAGE(O28:O43) -> 1 | P46: =AVERAGE(P28:P43) -> 4.1912094 | Q46: =AVERAGE(Q28:Q43) -> 0.099831454 | R46: =AVERAGE(R28:R43) -> 0.80530781 | S46: =AVERAGE(S28:S43) -> 1.1950732 | T46: =AVERAGE(T28:T43) -> 0.70168975 | U46: =AVERAGE(U28:U43) -> 0.89315531 | V46: =AVERAGE(V28:V43) -> 0.42847127
...

Sheet Raw data R2
A1: Nom groupe | B1: N° de valeur | C1: file name | D1: total area | E1: mean intensity | G1: total fluorescence | I1: nbre de larves | L1: (Tous)
A2: =IFERROR(LEFT(RIGHT(C2,LEN(C2)-SEARCH("@",C2)),SEARCH("/",RIGHT(C2,LEN(C2)-SEARCH("@",C2)-1))),"") | B2: =LEFT(RIGHT(RIGHT(Tableau46[[#This Row],[file name]],LEN(Tableau46[[#This Row],[file name]])-SEARCH("@",Tableau46[[#This Row],[file name]])),LEN(RIGHT(Tableau46[[#This Row],[file name]],LEN(Tableau46[[#This Row],[file name]])-SEARCH("@",Tableau46[[#This Row],[file name]])))-SEARCH("/",RIGHT(Tableau46[[#This Row],[file name]],LEN(Tableau46[[#This Row],[file name]])-SEARCH("@",Tableau46[[#This Row],[file name]])))),1) -> #VALUE! | K2: Filtre lignes : Enlever (vide) et Néant | L2: Filtre colonnes : Enlever (vide) et " "
A3: =IFERROR(LEFT(RIGHT(C3,LEN(C3)-SEARCH("@",C3)),SEARCH("/",RIGHT(C3,LEN(C3)-SEARCH("@",C3)-1))),"") | B3: =LEFT(RIGHT(RIGHT(Tableau46[[#This Row],[file name]],LEN(Tableau46[[#This Row],[file name]])-SEARCH("@",Tableau46[[#This Row],[file name]])),LEN(RIGHT(Tableau46[[#This Row],[file name]],LEN(Tableau46[[#This Row],[file name]])-SEARCH("@",Tableau46[[#This Row],[file name]])))-SEARCH("/",RIGHT(Tableau46[[#This Row],[file name]],LEN(Tableau46[[#This Row],[file name]])-SEARCH("@",Tableau46[[#This Row],[file name]])))),1) -> #VALUE! | K3: Moyenne de total fluorescence | L3: Étiquettes de colonnes
A4: =IFERROR(LEFT(RIGHT(C4,LEN(C4)-SEARCH("@",C4)),SEARCH("/",RIGHT(C4,LEN(C4)-SEARCH("@",C4)-1))),"") | B4: =LEFT(RIGHT(RIGHT(Tableau46[[#This Row],[file name]],LEN(Tableau46[[#This Row],[file name]])-SEARCH("@",Tableau46[[#This Row],[file name]])),LEN(RIGHT(Tableau46[[#This Row],[file name]],LEN(Tableau46[[#This Row],[file name]])-SEARCH("@",Tableau46[[#This Row],[file name]])))-SEARCH("/",RIGHT(Tableau46[[#This Row],[file name]],LEN(Tableau46[[#This Row],[file name]])-SEARCH("@",Tableau46[[#This Row],[file name]])))),1) -> #VALUE! | K4: Étiquettes de lignes
A5: =IFERROR(LEFT(RIGHT(C5,LEN(C5)-SEARCH("@",C5)),SEARCH("/",RIGHT(C5,LEN(C5)-SEARCH("@",C5)-1))),"") | B5: =LEFT(RIGHT(RIGHT(Tableau46[[#This Row],[file name]],LEN(Tableau46[[#This Row],[file name]])-SEARCH("@",Tableau46[[#This Row],[file name]])),LEN(RIGHT(Tableau46[[#This Row],[file name]],LEN(Tableau46[[#This Row],[file name]])-SEARCH("@",Tableau46[[#This Row],[file name]])))-SEARCH("/",RIGHT(Tableau46[[#This Row],[file name]],LEN(Tableau46[[#This Row],[file name]])-SEARCH("@",Tableau46[[#This Row],[file name]])))),1) -> #VALUE! | K5: #VALEUR!
A6: =IFERROR(LEFT(RIGHT(C6,LEN(C6)-SEARCH("@",C6)),SEARCH("/",RIGHT(C6,LEN(C6)-SEARCH("@",C6)-1))),"") | B6: =LEFT(RIGHT(RIGHT(Tableau46[[#This Row],[file name]],LEN(Tableau46[[#This Row],[file name]])-SEARCH("@",Tableau46[[#This Row],[file name]])),LEN(RIGHT(Tableau46[[#This Row],[file name]],LEN(Tableau46[[#This Row],[file name]])-SEARCH("@",Tableau46[[#This Row],[file name]])))-SEARCH("/",RIGHT(Tableau46[[#This Row],[file name]],LEN(Tableau46[[#This Row],[file name]])-SEARCH("@",Tableau46[[#This Row],[file name]])))),1) -> #VALUE!
A7: =IFERROR(LEFT(RIGHT(C7,LEN(C7)-SEARCH("@",C7)),SEARCH("/",RIGHT(C7,LEN(C7)-SEARCH("@",C7)-1))),"") | B7: =LEFT(RIGHT(RIGHT(Tableau46[[#This Row],[file name]],LEN(Tableau46[[#This Row],[file name]])-SEARCH("@",Tableau46[[#This Row],[file name]])),LEN(RIGHT(Tableau46[[#This Row],[file name]],LEN(Tableau46[[#This Row],[file name]])-SEARCH("@",Tableau46[[#This Row],[file name]])))-SEARCH("/",RIGHT(Tableau46[[#This Row],[file name]],LEN(Tableau46[[#This Row],[file name]])-SEARCH("@",Tableau46[[#This Row],[file name]])))),1) -> #VALUE!
A8: =IFERROR(LEFT(RIGHT(C8,LEN(C8)-SEARCH("@",C8)),SEARCH("/",RIGHT(C8,LEN(C8)-SEARCH("@",C8)-1))),"") | B8: =LEFT(RIGHT(RIGHT(Tableau46[[#This Row],[file name]],LEN(Tableau46[[#This Row],[file name]])-SEARCH("@",Tableau46[[#This Row],[file name]])),LEN(RIGHT(Tableau46[[#This Row],[file name]],LEN(Tableau46[[#This Row],[file name]])-SEARCH("@",Tableau46[[#This Row],[file name]])))-SEARCH("/",RIGHT(Tableau46[[#This Row],[file name]],LEN(Tableau46[[#This Row],[file name]])-SEARCH("@",Tableau46[[#This Row],[file name]])))),1) -> #VALUE!
A9: =IFERROR(LEFT(RIGHT(C9,LEN(C9)-SEARCH("@",C9)),SEARCH("/",RIGHT(C9,LEN(C9)-SEARCH("@",C9)-1))),"") | B9: =LEFT(RIGHT(RIGHT(Tableau46[[#This Row],[file name]],LEN(Tableau46[[#This Row],[file name]])-SEARCH("@",Tableau46[[#This Row],[file name]])),LEN(RIGHT(Tableau46[[#This Row],[file name]],LEN(Tableau46[[#This Row],[file name]])-SEARCH("@",Tableau46[[#This Row],[file name]])))-SEARCH("/",RIGHT(Tableau46[[#This Row],[file name]],LEN(Tableau46[[#This Row],[file name]])-SEARCH("@",Tableau46[[#This Row],[file name]])))),1) -> #VALUE!
A10: =IFERROR(LEFT(RIGHT(C10,LEN(C10)-SEARCH("@",C10)),SEARCH("/",RIGHT(C10,LEN(C10)-SEARCH("@",C10)-1))),"") | B10: =LEFT(RIGHT(RIGHT(Tableau46[[#This Row],[file name]],LEN(Tableau46[[#This Row],[file name]])-SEARCH("@",Tableau46[[#This Row],[file name]])),LEN(RIGHT(Tableau46[[#This Row],[file name]],LEN(Tableau46[[#This Row],[file name]])-SEARCH("@",Tableau46[[#This Row],[file name]])))-SEARCH("/",RIGHT(Tableau46[[#This Row],[file name]],LEN(Tableau46[[#This Row],[file name]])-SEARCH("@",Tableau46[[#This Row],[file name]])))),1) -> #VALUE!
A11: =IFERROR(LEFT(RIGHT(C11,LEN(C11)-SEARCH("@",C11)),SEARCH("/",RIGHT(C11,LEN(C11)-SEARCH("@",C11)-1))),"") | B11: =LEFT(RIGHT(RIGHT(Tableau46[[#This Row],[file name]],LEN(Tableau46[[#This Row],[file name]])-SEARCH("@",Tableau46[[#This Row],[file name]])),LEN(RIGHT(Tableau46[[#This Row],[file name]],LEN(Tableau46[[#This Row],[file name]])-SEARCH("@",Tableau46[[#This Row],[file name]])))-SEARCH("/",RIGHT(Tableau46[[#This Row],[file name]],LEN(Tableau46[[#This Row],[file name]])-SEARCH("@",Tableau46[[#This Row],[file name]])))),1) -> #VALUE!
A12: =IFERROR(LEFT(RIGHT(C12,LEN(C12)-SEARCH("@",C12)),SEARCH("/",RIGHT(C12,LEN(C12)-SEARCH("@",C12)-1))),"") | B12: =LEFT(RIGHT(RIGHT(Tableau46[[#This Row],[file name]],LEN(Tableau46[[#This Row],[file name]])-SEARCH("@",Tableau46[[#This Row],[file name]])),LEN(RIGHT(Tableau46[[#This Row],[file name]],LEN(Tableau46[[#This Row],[file name]])-SEARCH("@",Tableau46[[#This Row],[file name]])))-SEARCH("/",RIGHT(Tableau46[[#This Row],[file name]],LEN(Tableau46[[#This Row],[file name]])-SEARCH("@",Tableau46[[#This Row],[file name]])))),1) -> #VALUE!
A13: =IFERROR(LEFT(RIGHT(C13,LEN(C13)-SEARCH("@",C13)),SEARCH("/",RIGHT(C13,LEN(C13)-SEARCH("@",C13)-1))),"") | B13: =LEFT(RIGHT(RIGHT(Tableau46[[#This Row],[file name]],LEN(Tableau46[[#This Row],[file name]])-SEARCH("@",Tableau46[[#This Row],[file name]])),LEN(RIGHT(Tableau46[[#This Row],[file name]],LEN(Tableau46[[#This Row],[file name]])-SEARCH("@",Tableau46[[#This Row],[file name]])))-SEARCH("/",RIGHT(Tableau46[[#This Row],[file name]],LEN(Tableau46[[#This Row],[file name]])-SEARCH("@",Tableau46[[#This Row],[file name]])))),1) -> #VALUE!
A14: =IFERROR(LEFT(RIGHT(C14,LEN(C14)-SEARCH("@",C14)),SEARCH("/",RIGHT(C14,LEN(C14)-SEARCH("@",C14)-1))),"") | B14: =LEFT(RIGHT(RIGHT(Tableau46[[#This Row],[file name]],LEN(Tableau46[[#This Row],[file name]])-SEARCH("@",Tableau46[[#This Row],[file name]])),LEN(RIGHT(Tableau46[[#This Row],[file name]],LEN(Tableau46[[#This Row],[file name]])-SEARCH("@",Tableau46[[#This Row],[file name]])))-SEARCH("/",RIGHT(Tableau46[[#This Row],[file name]],LEN(Tableau46[[#This Row],[file name]])-SEARCH("@",Tableau46[[#This Row],[file name]])))),1) -> #VALUE!
A15: =IFERROR(LEFT(RIGHT(C15,LEN(C15)-SEARCH("@",C15)),SEARCH("/",RIGHT(C15,LEN(C15)-SEARCH("@",C15)-1))),"") | B15: =LEFT(RIGHT(RIGHT(Tableau46[[#This Row],[file name]],LEN(Tableau46[[#This Row],[file name]])-SEARCH("@",Tableau46[[#This Row],[file name]])),LEN(RIGHT(Tableau46[[#This Row],[file name]],LEN(Tableau46[[#This Row],[file name]])-SEARCH("@",Tableau46[[#This Row],[file name]])))-SEARCH("/",RIGHT(Tableau46[[#This Row],[file name]],LEN(Tableau46[[#This Row],[file name]])-SEARCH("@",Tableau46[[#This Row],[file name]])))),1) -> #VALUE!
A16: =IFERROR(LEFT(RIGHT(C16,LEN(C16)-SEARCH("@",C16)),SEARCH("/",RIGHT(C16,LEN(C16)-SEARCH("@",C16)-1))),"") | B16: =LEFT(RIGHT(RIGHT(Tableau46[[#This Row],[file name]],LEN(Tableau46[[#This Row],[file name]])-SEARCH("@",Tableau46[[#This Row],[file name]])),LEN(RIGHT(Tableau46[[#This Row],[file name]],LEN(Tableau46[[#This Row],[file name]])-SEARCH("@",Tableau46[[#This Row],[file name]])))-SEARCH("/",RIGHT(Tableau46[[#This Row],[file name]],LEN(Tableau46[[#This Row],[file name]])-SEARCH("@",Tableau46[[#This Row],[file name]])))),1) -> #VALUE!
A17: =IFERROR(LEFT(RIGHT(C17,LEN(C17)-SEARCH("@",C17)),SEARCH("/",RIGHT(C17,LEN(C17)-SEARCH("@",C17)-1))),"") | B17: =LEFT(RIGHT(RIGHT(Tableau46[[#This Row],[file name]],LEN(Tableau46[[#This Row],[file name]])-SEARCH("@",Tableau46[[#This Row],[file name]])),LEN(RIGHT(Tableau46[[#This Row],[file name]],LEN(Tableau46[[#This Row],[file name]])-SEARCH("@",Tableau46[[#This Row],[file name]])))-SEARCH("/",RIGHT(Tableau46[[#This Row],[file name]],LEN(Tableau46[[#This Row],[file name]])-SEARCH("@",Tableau46[[#This Row],[file name]])))),1) -> #VALUE!
... A1531: =IFERROR(LEFT(RIGHT(C1531,LEN(C1531)-SEARCH("@",C1531)),SEARCH("/",RIGHT(C1531,LEN(C1531)-SEARCH("@",C1531)-1))),"") | B1531: =LEFT(RIGHT(RIGHT(Tableau46[[#This Row],[file name]],LEN(Tableau46[[#This Row],[file name]])-SEARCH("@",Tableau46[[#This Row],[file name]])),LEN(RIGHT(Tableau46[[#This Row],[file name]],LEN(Tableau46[[#This Row],[file name]])-SEARCH("@",Tableau46[[#This Row],[file name]])))-SEARCH("/",RIGHT(Tableau46[[#This Row],[file name]],LEN(Tableau46[[#This Row],[file name]])-SEARCH("@",Tableau46[[#This Row],[file name]])))),1) -> #VALUE!

Sheet R2
A1: 6. Expérimentateur 2 : copier et coller les valeurs des intensités totales de fluorescences obtenues dans le fichier raw data lors du traitement des images. Ne pas supprimer les colonnes correspondant aux concentrations non lues.
A3: R2 | B3: Non dopé | O3: avec testo
A4: Noms des groupes | B4: ='Page de garde'!A7 -> Témoin solvant | C4: ='Page de garde'!A9 -> EE2-33.8ng/L | D4: ='Page de garde'!A10 -> EE2-50.6ng/L | E4: ='Page de garde'!A11 -> EE2-76ng/L | F4: ='Page de garde'!A12 -> EE2-114ng/L | G4: ='Page de garde'!A13 -> EE2-170.9ng/L | H4: ='Page de garde'!A14 -> EE2-488ng/L | I4: ='Page de garde'!A15 -> Fadrozole-0.016µg/L | J4: ='Page de garde'!A16 -> Fadrozole-0.08µg/L | K4: ='Page de garde'!A17 -> Fadrozole-0.4µg/L | L4: ='Page de garde'!A18 -> Fadrozole-2µg/L | M4: ='Page de garde'!A19 -> Fadrozole-10 µg/L | O4: ='Page de garde'!A36 -> Testo -30µg/L | P4: ='Page de garde'!A37 -> Testo 30µg/L + EE2 -64ng/L | Q4: ='Page de garde'!A38 -> Testo 30µg/L + FAD-10µg/L | R4: ='Page de garde'!A39 -> Fadrozole-0.016µg/L + Testostérone | S4: ='Page de garde'!A40 -> Fadrozole-0.08µg/L + Testostérone | T4: ='Page de garde'!A41 -> Fadrozole-0.4µg/L + Testostérone | U4: ='Page de garde'!A42 -> Fadrozole-2µg/L + Testostérone | V4: ='Page de garde'!A43 -> Fadrozole-10 µg/L + Testostérone
A5: Données brutes | B5: 16004 | C5: 44275 | D5: 84335 | E5: 56759 | F5: 635672 | G5: 5320367 | H5: 5752161 | I5: 11180 | J5: 13007 | K5: 2215 | L5: 6396 | M5: 212 | O5: 1533268 | P5: 12366433 | Q5: 26932 | R5: 643584 | S5: 1657930 | T5: 761042 | U5: 1177412 | V5: 183364
B6: 25 | C6: 135239 | D6: 54395 | E6: 689836 | F6: 5342877 | G6: 5151762 | H6: 9697788 | I6: 19351 | J6: 2952 | K6: 1813 | L6: 35036 | M6: 11470 | O6: 756579 | P6: 10283725 | Q6: 20399 | R6: 175366 | S6: 65511 | T6: 109 | U6: 1379903 | V6: 15526
B7: 12686 | C7: 30927 | D7: 2549196 | E7: 1314250 | F7: 11727 | G7: 2502303 | H7: 4621560 | I7: 21926 | J7: 3527 | K7: 30457 | L7: 6572 | M7: 11113 | O7: 2158852 | P7: 12335567 | Q7: 43427 | R7: 80106 | S7: 119675 | T7: 29206 | U7: 13593 | V7: 65958
B8: 11008 | C8: 112012 | D8: 59409 | E8: 750221 | F8: 3851055 | G8: 1961183 | H8: 4771477 | I8: 7435 | J8: 68440 | K8: 4225 | L8: 20374 | M8: 16891 | O8: 351834 | P8: 6964463 | Q8: 11442 | R8: 2029755 | S8: 2425342 | T8: 226134 | U8: 95500 | V8: 18948
B9: 36506 | C9: 26878 | D9: 27310 | E9: 3691988 | F9: 2899183 | G9: 3538908 | H9: 5071291 | I9: 2756 | J9: 49809 | K9: 30484 | L9: 21835 | M9: 15639 | O9: 7281 | P9: 8365911 | Q9: 92326 | R9: 1971882 | S9: 472131 | T9: 67576 | U9: 328509 | V9: 9644
B10: 17717 | C10: 48285 | D10: 160966 | E10: 2161546 | F10: 2467623 | G10: 4181222 | H10: 4191230 | I10: 1080 | J10: 7901 | K10: 34908 | L10: 309686 | M10: 2963 | O10: 214038 | P10: 6548075 | Q10: 32774 | R10: 12158 | S10: 492964 | T10: 628674 | U10: 101094 | V10: 4054
B11: 4179 | C11: 0 | D11: 62196 | E11: 161971 | F11: 3637237 | G11: 3017964 | H11: 5437701 | I11: 28440 | J11: 79 | K11: 654 | L11: 2569 | M11: 22172 | O11: 582344 | P11: 8099428 | Q11: 17635 | R11: 267222 | S11: 1997791 | T11: 670014 | U11: 2231 | V11: 51287
C12: 702 | D12: 6050 | E12: 1253702 | F12: 725198 | G12: 4942591 | H12: 8192981 | I12: 1448 | K12: 65027 | L12: 24816 | M12: 22296 | O12: 1436365 | S12: 3179701 | T12: 18370 | U12: 625 | V12: 23351
O13: 255348
O14: 186050
O15: 666483
O16: 1457314
O17: 2540184
