Workbook

Sheet Page de garde
A1: 1. Expérimentateur 1 : copier et coller le n° de prestation et renseigner la date de réalisation de chaque réplica ainsi que le visa de l'expérimentateur.
A2: R1 | B2: Numéro d'expérience : | E2: Date de réalisation :
A3: R2 | B3: Numéro d'expérience : | E3: Date de réalisation :
A4: R3 | B4: Numéro d'expérience : | E4: Date de réalisation :
A5: 2. Expérimentateur 1 : copier et coller la dilution appliquée et le nom donné pour chaque des échantillons par le client. Conserver la mise en forme de l'exemple en italique. Ne pas remplir la colonne "nom sur graphique".
A6: Nom sur le graphique | B6: Code WF | C6: Concentration | D6: Unité | E6: Nom de l'échantillon donné par le client | F6: Dopage (+Testostérone / + EE2, ….)
A7: =IF(ISBLANK(liste_groupe[[#This Row],[Code WF]])," ",IF(ISBLANK(liste_groupe[[#This Row],[Unité]]),CONCATENATE(liste_groupe[[#This Row],[Nom de l''échantillon donné par le client]],liste_groupe[[#This Row],[Dopage (+Testostérone / + EE2, ….)]]),CONCATENATE(liste_groupe[[#This Row],[Nom de l''échantillon donné par le client]],"-",liste_groupe[[#This Row],[Concentration]],liste_groupe[[#This Row],[Unité]],liste_groupe[[#This Row],[Dopage (+Testostérone / + EE2, ….)]]))) -> Témoin solvant | B7: Témoin | E7: Témoin solvant
A8: =IF(ISBLANK(liste_groupe[[#This Row],[Code WF]])," ",IF(ISBLANK(liste_groupe[[#This Row],[Unité]]),CONCATENATE(liste_groupe[[#This Row],[Nom de l''échantillon donné par le client]],liste_groupe[[#This Row],[Dopage (+Testostérone / + EE2, ….)]]),CONCATENATE(liste_groupe[[#This Row],[Nom de l''échantillon donné par le client]],"-",liste_groupe[[#This Row],[Concentration]],liste_groupe[[#This Row],[Unité]],liste_groupe[[#This Row],[Dopage (+Testostérone / + EE2, ….)]]))) -> EE2-22.5ng/L | B8: Témoin | C8: 22.5 | D8: ng/L | E8: EE2
A9: =IF(ISBLANK(liste_groupe[[#This Row],[Code WF]])," ",IF(ISBLANK(liste_groupe[[#This Row],[Unité]]),CONCATENATE(liste_groupe[[#This Row],[Nom de l''échantillon donné par le client]],liste_groupe[[#This Row],[Dopage (+Testostérone / + EE2, ….)]]),CONCATENATE(liste_groupe[[#This Row],[Nom de l''échantillon donné par le client]],"-",liste_groupe[[#This Row],[Concentration]],liste_groupe[[#This Row],[Unité]],liste_groupe[[#This Row],[Dopage (+Testostérone / + EE2, ….)]]))) -> EE2-33.8ng/L | B9: Témoin | C9: 33.8 | D9: ng/L | E9: EE2
A10: =IF(ISBLANK(liste_groupe[[#This Row],[Code WF]])," ",IF(ISBLANK(liste_groupe[[#This Row],[Unité]]),CONCATENATE(liste_groupe[[#This Row],[Nom de l''échantillon donné par le client]],liste_groupe[[#This Row],[Dopage (+Testostérone / + EE2, ….)]]),CONCATENATE(liste_groupe[[#This Row],[Nom de l''échantillon donné par le client]],"-",liste_groupe[[#This Row],[Concentration]],liste_groupe[[#This Row],[Unité]],liste_groupe[[#This Row],[Dopage (+Testostérone / + EE2, ….)]]))) -> EE2-50.6ng/L | B10: Témoin | C10: 50.6 | D10: ng/L | E10: EE2
A11: =IF(ISBLANK(liste_groupe[[#This Row],[Code WF]])," ",IF(ISBLANK(liste_groupe[[#This Row],[Unité]]),CONCATENATE(liste_groupe[[#This Row],[Nom de l''échantillon donné par le client]],liste_groupe[[#This Row],[Dopage (+Testostérone / + EE2, ….)]]),CONCATENATE(liste_groupe[[#This Row],[Nom de l''échantillon donné par le client]],"-",liste_groupe[[#This Row],[Concentration]],liste_groupe[[#This Row],[Unité]],liste_groupe[[#This Row],[Dopage (+Testostérone / + EE2, ….)]]))) -> EE2-76ng/L | B11: Témoin | C11: 76 | D11: ng/L | E11: EE2
A12: =IF(ISBLANK(liste_groupe[[#This Row],[Code WF]])," ",IF(ISBLANK(liste_groupe[[#This Row],[Unité]]),CONCATENATE(liste_groupe[[#This Row],[Nom de l''échantillon donné par le client]],liste_groupe[[#This Row],[Dopage (+Testostérone / + EE2, ….)]]),CONCATENATE(liste_groupe[[#This Row],[Nom de l''échantillon donné par le client]],"-",liste_groupe[[#This Row],[Concentration]],liste_groupe[[#This Row],[Unité]],liste_groupe[[#This Row],[Dopage (+Testostérone / + EE2, ….)]]))) -> EE2-114ng/L | B12: Témoin | C12: 114 | D12: ng/L | E12: EE2
A13: =IF(ISBLANK(liste_groupe[[#This Row],[Code WF]])," ",IF(ISBLANK(liste_groupe[[#This Row],[Unité]]),CONCATENATE(liste_groupe[[#This Row],[Nom de l''échantillon donné par le client]],liste_groupe[[#This Row],[Dopage (+Testostérone / + EE2, ….)]]),CONCATENATE(liste_groupe[[#This Row],[Nom de l''échantillon donné par le client]],"-",liste_groupe[[#This Row],[Concentration]],liste_groupe[[#This Row],[Unité]],liste_groupe[[#This Row],[Dopage (+Testostérone / + EE2, ….)]]))) -> EE2-170.9ng/L | B13: Témoin | C13: 170.9 | D13: ng/L | E13: EE2
A14: =IF(ISBLANK(liste_groupe[[#This Row],[Code WF]])," ",IF(ISBLANK(liste_groupe[[#This Row],[Unité]]),CONCATENATE(liste_groupe[[#This Row],[Nom de l''échantillon donné par le client]],liste_groupe[[#This Row],[Dopage (+Testostérone / + EE2, ….)]]),CONCATENATE(liste_groupe[[#This Row],[Nom de l''échantillon donné par le client]],"-",liste_groupe[[#This Row],[Concentration]],liste_groupe[[#This Row],[Unité]],liste_groupe[[#This Row],[Dopage (+Testostérone / + EE2, ….)]]))) -> EE2-488ng/L | B14: Témoin | C14: 488 | D14: ng/L | E14: EE2
A15: =IF(ISBLANK(liste_groupe[[#This Row],[Code WF]])," ",IF(ISBLANK(liste_groupe[[#This Row],[Unité]]),CONCATENATE(liste_groupe[[#This Row],[Nom de l''échantillon donné par le client]],liste_groupe[[#This Row],[Dopage (+Testostérone / + EE2, ….)]]),CONCATENATE(liste_groupe[[#This Row],[Nom de l''échantillon donné par le client]],"-",liste_groupe[[#This Row],[Concentration]],liste_groupe[[#This Row],[Unité]],liste_groupe[[#This Row],[Dopage (+Testostérone / + EE2, ….)]]))) -> BPA-1mg/L | B15: Test | C15: 1 | D15: mg/L | E15: BPA
A16: =IF(ISBLANK(liste_groupe[[#This Row],[Code WF]])," ",IF(ISBLANK(liste_groupe[[#This Row],[Unité]]),CONCATENATE(liste_groupe[[#This Row],[Nom de l''échantillon donné par le client]],liste_groupe[[#This Row],[Dopage (+Testostérone / + EE2, ….)]]),CONCATENATE(liste_groupe[[#This Row],[Nom de l''échantillon donné par le client]],"-",liste_groupe[[#This Row],[Concentration]],liste_groupe[[#This Row],[Unité]],liste_groupe[[#This Row],[Dopage (+Testostérone / + EE2, ….)]]))) -> BPA-2mg/L | B16: Test | C16: 2 | D16: mg/L | E16: BPA
A17: =IF(ISBLANK(liste_groupe[[#This Row],[Code WF]])," ",IF(ISBLANK(liste_groupe[[#This Row],[Unité]]),CONCATENATE(liste_groupe[[#This Row],[Nom de l''échantillon donné par le client]],liste_groupe[[#This Row],[Dopage (+Testostérone / + EE2, ….)]]),CONCATENATE(liste_groupe[[#This Row],[Nom de l''échantillon donné par le client]],"-",liste_groupe[[#This Row],[Concentration]],liste_groupe[[#This Row],[Unité]],liste_groupe[[#This Row],[Dopage (+Testostérone / + EE2, ….)]]))) -> BPA-3mg/L | B17: Test | C17: 3 | D17: mg/L | E17: BPA
A18: =IF(ISBLANK(liste_groupe[[#This Row],[Code WF]])," ",IF(ISBLANK(liste_groupe[[#This Row],[Unité]]),CONCATENATE(liste_groupe[[#This Row],[Nom de l''échantillon donné par le client]],liste_groupe[[#This Row],[Dopage (+Testostérone / + EE2, ….)]]),CONCATENATE(liste_groupe[[#This Row],[Nom de l''échantillon donné par le client]],"-",liste_groupe[[#This Row],[Concentration]],liste_groupe[[#This Row],[Unité]],liste_groupe[[#This Row],[Dopage (+Testostérone / + EE2, ….)]]))) -> BPA-4mg/L | B18: Test | C18: 4 | D18: mg/L | E18: BPA
A19: =IF(ISBLANK(liste_groupe[[#This Row],[Code WF]])," ",IF(ISBLANK(liste_groupe[[#This Row],[Unité]]),CONCATENATE(liste_groupe[[#This Row],[Nom de l''échantillon donné par le client]],liste_groupe[[#This Row],[Dopage (+Testostérone / + EE2, ….)]]),CONCATENATE(liste_groupe[[#This Row],[Nom de l''échantillon donné par le client]],"-",liste_groupe[[#This Row],[Concentration]],liste_groupe[[#This Row],[Unité]],liste_groupe[[#This Row],[Dopage (+Testostérone / + EE2, ….)]]))) -> BPA-5mg/L | B19: Test | C19: 5 | D19: mg/L | E19: BPA
A20: =IF(ISBLANK(liste_groupe[[#This Row],[Code WF]])," ",IF(ISBLANK(liste_groupe[[#This Row],[Unité]]),CONCATENATE(liste_groupe[[#This Row],[Nom de l''échantillon donné par le client]],liste_groupe[[#This Row],[Dopage (+Testostérone / + EE2, ….)]]),CONCATENATE(liste_groupe[[#This Row],[Nom de l''échantillon donné par le client]],"-",liste_groupe[[#This Row],[Concentration]],liste_groupe[[#This Row],[Unité]],liste_groupe[[#This Row],[Dopage (+Testostérone / + EE2, ….)]])))
A21: =IF(ISBLANK(liste_groupe[[#This Row],[Code WF]])," ",IF(ISBLANK(liste_groupe[[#This Row],[Unité]]),CONCATENATE(liste_groupe[[#This Row],[Nom de l''échantillon donné par le client]],liste_groupe[[#This Row],[Dopage (+Testostérone / + EE2, ….)]]),CONCATENATE(liste_groupe[[#This Row],[Nom de l''échantillon donné par le client]],"-",liste_groupe[[#This Row],[Concentration]],liste_groupe[[#This Row],[Unité]],liste_groupe[[#This Row],[Dopage (+Testostérone / + EE2, ….)]])))
A22: =IF(ISBLANK(liste_groupe[[#This Row],[Code WF]])," ",IF(ISBLANK(liste_groupe[[#This Row],[Unité]]),CONCATENATE(liste_groupe[[#This Row],[Nom de l''échantillon donné par le client]],liste_groupe[[#This Row],[Dopage (+Testostérone / + EE2, ….)]]),CONCATENATE(liste_groupe[[#This Row],[Nom de l''échantillon donné par le client]],"-",liste_groupe[[#This Row],[Concentration]],liste_groupe[[#This Row],[Unité]],liste_groupe[[#This Row],[Dopage (+Testostérone / + EE2, ….)]])))
A23: =IF(ISBLANK(liste_groupe[[#This Row],[Code WF]])," ",IF(ISBLANK(liste_groupe[[#This Row],[Unité]]),CONCATENATE(liste_groupe[[#This Row],[Nom de l''échantillon donné par le client]],liste_groupe[[#This Row],[Dopage (+Testostérone / + EE2, ….)]]),CONCATENATE(liste_groupe[[#This Row],[Nom de l''échantillon donné par le client]],"-",liste_groupe[[#This Row],[Concentration]],liste_groupe[[#This Row],[Unité]],liste_groupe[[#This Row],[Dopage (+Testostérone / + EE2, ….)]])))
A24: =IF(ISBLANK(liste_groupe[[#This Row],[Code WF]])," ",IF(ISBLANK(liste_groupe[[#This Row],[Unité]]),CONCATENATE(liste_groupe[[#This Row],[Nom de l''échantillon donné par le client]],liste_groupe[[#This Row],[Dopage (+Testostérone / + EE2, ….)]]),CONCATENATE(liste_groupe[[#This Row],[Nom de l''échantillon donné par le client]],"-",liste_groupe[[#This Row],[Concentration]],liste_groupe[[#This Row],[Unité]],liste_groupe[[#This Row],[Dopage (+Testostérone / + EE2, ….)]])))
A25: =IF(ISBLANK(liste_groupe[[#This Row],[Code WF]])," ",IF(ISBLANK(liste_groupe[[#This Row],[Unité]]),CONCATENATE(liste_groupe[[#This Row],[Nom de l''échantillon donné par le client]],liste_groupe[[#This Row],[Dopage (+Testostérone / + EE2, ….)]]),CONCATENATE(liste_groupe[[#This Row],[Nom de l''échantillon donné par le client]],"-",liste_groupe[[#This Row],[Concentration]],liste_groupe[[#This Row],[Unité]],liste_groupe[[#This Row],[Dopage (+Testostérone / + EE2, ….)]])))
A26: =IF(ISBLANK(liste_groupe[[#This Row],[Code WF]])," ",IF(ISBLANK(liste_groupe[[#This Row],[Unité]]),CONCATENATE(liste_groupe[[#This Row],[Nom de l''échantillon donné par le client]],liste_groupe[[#This Row],[Dopage (+Testostérone / + EE2, ….)]]),CONCATENATE(liste_groupe[[#This Row],[Nom de l''échantillon donné par le client]],"-",liste_groupe[[#This Row],[Concentration]],liste_groupe[[#This Row],[Unité]],liste_groupe[[#This Row],[Dopage (+Testostérone / + EE2, ….)]])))
A27: =IF(ISBLANK(liste_groupe[[#This Row],[Code WF]])," ",IF(ISBLANK(liste_groupe[[#This Row],[Unité]]),CONCATENATE(liste_groupe[[#This Row],[Nom de l''échantillon donné par le client]],liste_groupe[[#This Row],[Dopage (+Testostérone / + EE2, ….)]]),CONCATENATE(liste_groupe[[#This Row],[Nom de l''échantillon donné par le client]],"-",liste_groupe[[#This Row],[Concentration]],liste_groupe[[#This Row],[Unité]],liste_groupe[[#This Row],[Dopage (+Testostérone / + EE2, ….)]])))
A28: =IF(ISBLANK(liste_groupe[[#This Row],[Code WF]])," ",IF(ISBLANK(liste_groupe[[#This Row],[Unité]]),CONCATENATE(liste_groupe[[#This Row],[Nom de l''échantillon donné par le client]],liste_groupe[[#This Row],[Dopage (+Testostérone / + EE2, ….)]]),CONCATENATE(liste_groupe[[#This Row],[Nom de l''échantillon donné par le client]],"-",liste_groupe[[#This Row],[Concentration]],liste_groupe[[#This Row],[Unité]],liste_groupe[[#This Row],[Dopage (+Testostérone / + EE2, ….)]])))
A29: =IF(ISBLANK(liste_groupe[[#This Row],[Code WF]])," ",IF(ISBLANK(liste_groupe[[#This Row],[Unité]]),CONCATENATE(liste_groupe[[#This Row],[Nom de l''échantillon donné par le client]],liste_groupe[[#This Row],[Dopage (+Testostérone / + EE2, ….)]]),CONCATENATE(liste_groupe[[#This Row],[Nom de l''échantillon donné par le client]],"-",liste_groupe[[#This Row],[Concentration]],liste_groupe[[#This Row],[Unité]],liste_groupe[[#This Row],[Dopage (+Testostérone / + EE2, ….)]])))
A30: =IF(ISBLANK(liste_groupe[[#This Row],[Code WF]])," ",IF(ISBLANK(liste_groupe[[#This Row],[Unité]]),CONCATENATE(liste_groupe[[#This Row],[Nom de l''échantillon donné par le client]],liste_groupe[[#This Row],[Dopage (+Testostérone / + EE2, ….)]]),CONCATENATE(liste_groupe[[#This Row],[Nom de l''échantillon donné par le client]],"-",liste_groupe[[#This Row],[Concentration]],liste_groupe[[#This Row],[Unité]],liste_groupe[[#This Row],[Dopage (+Testostérone / + EE2, ….)]])))
A31: =IF(ISBLANK(liste_groupe[[#This Row],[Code WF]])," ",IF(ISBLANK(liste_groupe[[#This Row],[Unité]]),CONCATENATE(liste_groupe[[#This Row],[Nom de l''échantillon donné par le client]],liste_groupe[[#This Row],[Dopage (+Testostérone / + EE2, ….)]]),CONCATENATE(liste_groupe[[#This Row],[Nom de l''échantillon donné par le client]],"-",liste_groupe[[#This Row],[Concentration]],liste_groupe[[#This Row],[Unité]],liste_groupe[[#This Row],[Dopage (+Testostérone / + EE2, ….)]])))
... A35: =IF(ISBLANK(liste_groupe[[#This Row],[Code WF]])," ",IF(ISBLANK(liste_groupe[[#This Row],[Unité]]),CONCATENATE(liste_groupe[[#This Row],[Nom de l''échantillon donné par le client]],liste_groupe[[#This Row],[Dopage (+Testostérone / + EE2, ….)]]),CONCATENATE(liste_groupe[[#This Row],[Nom de l''échantillon donné par le client]],"-",liste_groupe[[#This Row],[Concentration]],liste_groupe[[#This Row],[Unité]],liste_groupe[[#This Row],[Dopage (+Testostérone / + EE2, ….)]])))
A36: =IF(ISBLANK(liste_groupe[[#This Row],[Code WF]])," ",IF(ISBLANK(liste_groupe[[#This Row],[Unité]]),CONCATENATE(liste_groupe[[#This Row],[Nom de l''échantillon donné par le client]],liste_groupe[[#This Row],[Dopage (+Testostérone / + EE2, ….)]]),CONCATENATE(liste_groupe[[#This Row],[Nom de l''échantillon donné par le client]],"-",liste_groupe[[#This Row],[Concentration]],liste_groupe[[#This Row],[Unité]],liste_groupe[[#This Row],[Dopage (+Testostérone / + EE2, ….)]]))) -> Testo -30µg/L | B36: Témoin | C36: 30 | D36: µg/L | E36: Testo
A37: =IF(ISBLANK(liste_groupe[[#This Row],[Code WF]])," ",IF(ISBLANK(liste_groupe[[#This Row],[Unité]]),CONCATENATE(liste_groupe[[#This Row],[Nom de l''échantillon donné par le client]],liste_groupe[[#This Row],[Dopage (+Testostérone / + EE2, ….)]]),CONCATENATE(liste_groupe[[#This Row],[Nom de l''échantillon donné par le client]],"-",liste_groupe[[#This Row],[Concentration]],liste_groupe[[#This Row],[Unité]],liste_groupe[[#This Row],[Dopage (+Testostérone / + EE2, ….)]]))) -> Testo 30µg/L + EE2 -64ng/L | B37: Témoin | C37: 64 | D37: ng/L | E37: Testo 30µg/L + EE2
A38: =IF(ISBLANK(liste_groupe[[#This Row],[Code WF]])," ",IF(ISBLANK(liste_groupe[[#This Row],[Unité]]),CONCATENATE(liste_groupe[[#This Row],[Nom de l''échantillon donné par le client]],liste_groupe[[#This Row],[Dopage (+Testostérone / + EE2, ….)]]),CONCATENATE(liste_groupe[[#This Row],[Nom de l''échantillon donné par le client]],"-",liste_groupe[[#This Row],[Concentration]],liste_groupe[[#This Row],[Unité]],liste_groupe[[#This Row],[Dopage (+Testostérone / + EE2, ….)]]))) -> Testo 30µg/L + FAD-10µg/L | B38: Témoin | C38: 10 | D38: µg/L | E38: Testo 30µg/L + FAD
A39: =IF(ISBLANK(liste_groupe[[#This Row],[Code WF]])," ",IF(ISBLANK(liste_groupe[[#This Row],[Unité]]),CONCATENATE(liste_groupe[[#This Row],[Nom de l''échantillon donné par le client]],liste_groupe[[#This Row],[Dopage (+Testostérone / + EE2, ….)]]),CONCATENATE(liste_groupe[[#This Row],[Nom de l''échantillon donné par le client]],"-",liste_groupe[[#This Row],[Concentration]],liste_groupe[[#This Row],[Unité]],liste_groupe[[#This Row],[Dopage (+Testostérone / + EE2, ….)]]))) -> BPA-1mg/L + Testostérone | B39: =B15 -> Test | C39: =C15 -> 1 | D39: =D15 -> mg/L | E39: =E15 -> BPA | F39: + Testostérone
A40: =IF(ISBLANK(liste_groupe[[#This Row],[Code WF]])," ",IF(ISBLANK(liste_groupe[[#This Row],[Unité]]),CONCATENATE(liste_groupe[[#This Row],[Nom de l''échantillon donné par le client]],liste_groupe[[#This Row],[Dopage (+Testostérone / + EE2, ….)]]),CONCATENATE(liste_groupe[[#This Row],[Nom de l''échantillon donné par le client]],"-",liste_groupe[[#This Row],[Concentration]],liste_groupe[[#This Row],[Unité]],liste_groupe[[#This Row],[Dopage (+Testostérone / + EE2, ….)]]))) -> BPA-2mg/L + Testostérone | B40: =B16 -> Test | C40: =C16 -> 2 | D40: =D16 -> mg/L | E40: =E16 -> BPA | F40: + Testostérone
A41: =IF(ISBLANK(liste_groupe[[#This Row],[Code WF]])," ",IF(ISBLANK(liste_groupe[[#This Row],[Unité]]),CONCATENATE(liste_groupe[[#This Row],[Nom de l''échantillon donné par le client]],liste_groupe[[#This Row],[Dopage (+Testostérone / + EE2, ….)]]),CONCATENATE(liste_groupe[[#This Row],[Nom de l''échantillon donné par le client]],"-",liste_groupe[[#This Row],[Concentration]],liste_groupe[[#This Row],[Unité]],liste_groupe[[#This Row],[Dopage (+Testostérone / + EE2, ….)]]))) -> BPA-3mg/L + Testostérone | B41: =B17 -> Test | C41: =C17 -> 3 | D41: =D17 -> mg/L | E41: =E17 -> BPA | F41: + Testostérone
A42: =IF(ISBLANK(liste_groupe[[#This Row],[Code WF]])," ",IF(ISBLANK(liste_groupe[[#This Row],[Unité]]),CONCATENATE(liste_groupe[[#This Row],[Nom de l''échantillon donné par le client]],liste_groupe[[#This Row],[Dopage (+Testostérone / + EE2, ….)]]),CONCATENATE(liste_groupe[[#This Row],[Nom de l''échantillon donné par le client]],"-",liste_groupe[[#This Row],[Concentration]],liste_groupe[[#This Row],[Unité]],liste_groupe[[#This Row],[Dopage (+Testostérone / + EE2, ….)]]))) -> BPA-4mg/L + Testostérone | B42: =B18 -> Test | C42: =C18 -> 4 | D42: =D18 -> mg/L | E42: =E18 -> BPA | F42: + Testostérone
A43: =IF(ISBLANK(liste_groupe[[#This Row],[Code WF]])," ",IF(ISBLANK(liste_groupe[[#This Row],[Unité]]),CONCATENATE(liste_groupe[[#This Row],[Nom de l''échantillon donné par le client]],liste_groupe[[#This Row],[Dopage (+Testostérone / + EE2, ….)]]),CONCATENATE(liste_groupe[[#This Row],[Nom de l''échantillon donné par le client]],"-",liste_groupe[[#This Row],[Concentration]],liste_groupe[[#This Row],[Unité]],liste_groupe[[#This Row],[Dopage (+Testostérone / + EE2, ….)]]))) -> BPA-5mg/L + Testostérone | B43: =B19 -> Test | C43: =C19 -> 5 | D43: =D19 -> mg/L | E43: =E19 -> BPA | F43: + Testostérone
...

Sheet Feuil1
A1: Nom groupe | B1: N° de valeur | C1: file name | D1: total area | E1: mean intensity | G1: total fluorescence | I1: nbre de larves
A2: 01 EE2 0 | B2: A | C2: C:\Users\Olympus\Desktop\20190122\plaque1/@01 EE2 0/A1_1.tif | D2: 4931.616 | E2: 73.0526 | G2: 360268
A3: 01 EE2 0 | B3: A | C3: C:\Users\Olympus\Desktop\20190122\plaque1/@01 EE2 0/A1_2.tif | D3: 5234.4345 | E3: 71.1281 | G3: 372315
A4: 01 EE2 0 | B4: A | C4: C:\Users\Olympus\Desktop\20190122\plaque1/@01 EE2 0/A1_3.tif | D4: 3547.3027 | E4: 66.9878 | G4: 237626
A5: 01 EE2 0 | B5: A | C5: C:\Users\Olympus\Desktop\20190122\plaque3/@01 EE2 0/A1_3.tif | D5: 21456.8555 | E5: 67.0655 | G5: 1439015
A6: 01 EE2 0 | B6: A | C6: C:\Users\Olympus\Desktop\20190122\plaque3/@01 EE2 0/A1_2.tif | D6: 21586.6348 | E6: 66.4108 | G6: 1433586
A7: 01 EE2 0 | B7: A | C7: C:\Users\Olympus\Desktop\20190122\plaque3/@01 EE2 0/A1_1.tif | D7: 15984.4921 | E7: 69.7767 | G7: 1115346

Sheet Raw data R1
A1: Nom groupe | B1: N° de valeur | C1: file name | D1: total area | E1: mean intensity | G1: total fluorescence | I1: nbre de larves | L1: (Tous)
A2: =IFERROR(LEFT(RIGHT(C2,LEN(C2)-SEARCH("@",C2)),SEARCH("/",RIGHT(C2,LEN(C2)-SEARCH("@",C2)-1))),"") | B2: =LEFT(RIGHT(RIGHT(Tableau4[[#This Row],[file name]],LEN(Tableau4[[#This Row],[file name]])-SEARCH("@",Tableau4[[#This Row],[file name]])),LEN(RIGHT(Tableau4[[#This Row],[file name]],LEN(Tableau4[[#This Row],[file name]])-SEARCH("@",Tableau4[[#This Row],[file name]])))-SEARCH("/",RIGHT(Tableau4[[#This Row],[file name]],LEN(Tableau4[[#This Row],[file name]])-SEARCH("@",Tableau4[[#This Row],[file name]])))),1) -> #VALUE! | K2: Filtre lignes : Enlever (vide) et Néant | L2: Filtre colonnes : Enlever (vide) et " "
A3: =IFERROR(LEFT(RIGHT(C3,LEN(C3)-SEARCH("@",C3)),SEARCH("/",RIGHT(C3,LEN(C3)-SEARCH("@",C3)-1))),"") | B3: =LEFT(RIGHT(RIGHT(Tableau4[[#This Row],[file name]],LEN(Tableau4[[#This Row],[file name]])-SEARCH("@",Tableau4[[#This Row],[file name]])),LEN(RIGHT(Tableau4[[#This Row],[file name]],LEN(Tableau4[[#This Row],[file name]])-SEARCH("@",Tableau4[[#This Row],[file name]])))-SEARCH("/",RIGHT(Tableau4[[#This Row],[file name]],LEN(Tableau4[[#This Row],[file name]])-SEARCH("@",Tableau4[[#This Row],[file name]])))),1) -> #VALUE! | K3: Moyenne de total fluorescence | L3: Étiquettes de colonnes
A4: =IFERROR(LEFT(RIGHT(C4,LEN(C4)-SEARCH("@",C4)),SEARCH("/",RIGHT(C4,LEN(C4)-SEARCH("@",C4)-1))),"") | B4: =LEFT(RIGHT(RIGHT(Tableau4[[#This Row],[file name]],LEN(Tableau4[[#This Row],[file name]])-SEARCH("@",Tableau4[[#This Row],[file name]])),LEN(RIGHT(Tableau4[[#This Row],[file name]],LEN(Tableau4[[#This Row],[file name]])-SEARCH("@",Tableau4[[#This Row],[file name]])))-SEARCH("/",RIGHT(Tableau4[[#This Row],[file name]],LEN(Tableau4[[#This Row],[file name]])-SEARCH("@",Tableau4[[#This Row],[file name]])))),1) -> #VALUE! | K4: Étiquettes de lignes
A5: =IFERROR(LEFT(RIGHT(C5,LEN(C5)-SEARCH("@",C5)),SEARCH("/",RIGHT(C5,LEN(C5)-SEARCH("@",C5)-1))),"") | B5: =LEFT(RIGHT(RIGHT(Tableau4[[#This Row],[file name]],LEN(Tableau4[[#This Row],[file name]])-SEARCH("@",Tableau4[[#This Row],[file name]])),LEN(RIGHT(Tableau4[[#This Row],[file name]],LEN(Tableau4[[#This Row],[file name]])-SEARCH("@",Tableau4[[#This Row],[file name]])))-SEARCH("/",RIGHT(Tableau4[[#This Row],[file name]],LEN(Tableau4[[#This Row],[file name]])-SEARCH("@",Tableau4[[#This Row],[file name]])))),1) -> #VALUE! | K5: #VALEUR!
A6: =IFERROR(LEFT(RIGHT(C6,LEN(C6)-SEARCH("@",C6)),SEARCH("/",RIGHT(C6,LEN(C6)-SEARCH("@",C6)-1))),"") | B6: =LEFT(RIGHT(RIGHT(Tableau4[[#This Row],[file name]],LEN(Tableau4[[#This Row],[file name]])-SEARCH("@",Tableau4[[#This Row],[file name]])),LEN(RIGHT(Tableau4[[#This Row],[file name]],LEN(Tableau4[[#This Row],[file name]])-SEARCH("@",Tableau4[[#This Row],[file name]])))-SEARCH("/",RIGHT(Tableau4[[#This Row],[file name]],LEN(Tableau4[[#This Row],[file name]])-SEARCH("@",Tableau4[[#This Row],[file name]])))),1) -> #VALUE!
A7: =IFERROR(LEFT(RIGHT(C7,LEN(C7)-SEARCH("@",C7)),SEARCH("/",RIGHT(C7,LEN(C7)-SEARCH("@",C7)-1))),"") | B7: =LEFT(RIGHT(RIGHT(Tableau4[[#This Row],[file name]],LEN(Tableau4[[#This Row],[file name]])-SEARCH("@",Tableau4[[#This Row],[file name]])),LEN(RIGHT(Tableau4[[#This Row],[file name]],LEN(Tableau4[[#This Row],[file name]])-SEARCH("@",Tableau4[[#This Row],[file name]])))-SEARCH("/",RIGHT(Tableau4[[#This Row],[file name]],LEN(Tableau4[[#This Row],[file name]])-SEARCH("@",Tableau4[[#This Row],[file name]])))),1) -> #VALUE!
A8: =IFERROR(LEFT(RIGHT(C8,LEN(C8)-SEARCH("@",C8)),SEARCH("/",RIGHT(C8,LEN(C8)-SEARCH("@",C8)-1))),"") | B8: =LEFT(RIGHT(RIGHT(Tableau4[[#This Row],[file name]],LEN(Tableau4[[#This Row],[file name]])-SEARCH("@",Tableau4[[#This Row],[file name]])),LEN(RIGHT(Tableau4[[#This Row],[file name]],LEN(Tableau4[[#This Row],[file name]])-SEARCH("@",Tableau4[[#This Row],[file name]])))-SEARCH("/",RIGHT(Tableau4[[#This Row],[file name]],LEN(Tableau4[[#This Row],[file name]])-SEARCH("@",Tableau4[[#This Row],[file name]])))),1) -> #VALUE!
A9: =IFERROR(LEFT(RIGHT(C9,LEN(C9)-SEARCH("@",C9)),SEARCH("/",RIGHT(C9,LEN(C9)-SEARCH("@",C9)-1))),"") | B9: =LEFT(RIGHT(RIGHT(Tableau4[[#This Row],[file name]],LEN(Tableau4[[#This Row],[file name]])-SEARCH("@",Tableau4[[#This Row],[file name]])),LEN(RIGHT(Tableau4[[#This Row],[file name]],LEN(Tableau4[[#This Row],[file name]])-SEARCH("@",Tableau4[[#This Row],[file name]])))-SEARCH("/",RIGHT(Tableau4[[#This Row],[file name]],LEN(Tableau4[[#This Row],[file name]])-SEARCH("@",Tableau4[[#This Row],[file name]])))),1) -> #VALUE!
A10: =IFERROR(LEFT(RIGHT(C10,LEN(C10)-SEARCH("@",C10)),SEARCH("/",RIGHT(C10,LEN(C10)-SEARCH("@",C10)-1))),"") | B10: =LEFT(RIGHT(RIGHT(Tableau4[[#This Row],[file name]],LEN(Tableau4[[#This Row],[file name]])-SEARCH("@",Tableau4[[#This Row],[file name]])),LEN(RIGHT(Tableau4[[#This Row],[file name]],LEN(Tableau4[[#This Row],[file name]])-SEARCH("@",Tableau4[[#This Row],[file name]])))-SEARCH("/",RIGHT(Tableau4[[#This Row],[file name]],LEN(Tableau4[[#This Row],[file name]])-SEARCH("@",Tableau4[[#This Row],[file name]])))),1) -> #VALUE!
A11: =IFERROR(LEFT(RIGHT(C11,LEN(C11)-SEARCH("@",C11)),SEARCH("/",RIGHT(C11,LEN(C11)-SEARCH("@",C11)-1))),"") | B11: =LEFT(RIGHT(RIGHT(Tableau4[[#This Row],[file name]],LEN(Tableau4[[#This Row],[file name]])-SEARCH("@",Tableau4[[#This Row],[file name]])),LEN(RIGHT(Tableau4[[#This Row],[file name]],LEN(Tableau4[[#This Row],[file name]])-SEARCH("@",Tableau4[[#This Row],[file name]])))-SEARCH("/",RIGHT(Tableau4[[#This Row],[file name]],LEN(Tableau4[[#This Row],[file name]])-SEARCH("@",Tableau4[[#This Row],[file name]])))),1) -> #VALUE!
A12: =IFERROR(LEFT(RIGHT(C12,LEN(C12)-SEARCH("@",C12)),SEARCH("/",RIGHT(C12,LEN(C12)-SEARCH("@",C12)-1))),"") | B12: =LEFT(RIGHT(RIGHT(Tableau4[[#This Row],[file name]],LEN(Tableau4[[#This Row],[file name]])-SEARCH("@",Tableau4[[#This Row],[file name]])),LEN(RIGHT(Tableau4[[#This Row],[file name]],LEN(Tableau4[[#This Row],[file name]])-SEARCH("@",Tableau4[[#This Row],[file name]])))-SEARCH("/",RIGHT(Tableau4[[#This Row],[file name]],LEN(Tableau4[[#This Row],[file name]])-SEARCH("@",Tableau4[[#This Row],[file name]])))),1) -> #VALUE!
A13: =IFERROR(LEFT(RIGHT(C13,LEN(C13)-SEARCH("@",C13)),SEARCH("/",RIGHT(C13,LEN(C13)-SEARCH("@",C13)-1))),"") | B13: =LEFT(RIGHT(RIGHT(Tableau4[[#This Row],[file name]],LEN(Tableau4[[#This Row],[file name]])-SEARCH("@",Tableau4[[#This Row],[file name]])),LEN(RIGHT(Tableau4[[#This Row],[file name]],LEN(Tableau4[[#This Row],[file name]])-SEARCH("@",Tableau4[[#This Row],[file name]])))-SEARCH("/",RIGHT(Tableau4[[#This Row],[file name]],LEN(Tableau4[[#This Row],[file name]])-SEARCH("@",Tableau4[[#This Row],[file name]])))),1) -> #VALUE!
A14: =IFERROR(LEFT(RIGHT(C14,LEN(C14)-SEARCH("@",C14)),SEARCH("/",RIGHT(C14,LEN(C14)-SEARCH("@",C14)-1))),"") | B14: =LEFT(RIGHT(RIGHT(Tableau4[[#This Row],[file name]],LEN(Tableau4[[#This Row],[file name]])-SEARCH("@",Tableau4[[#This Row],[file name]])),LEN(RIGHT(Tableau4[[#This Row],[file name]],LEN(Tableau4[[#This Row],[file name]])-SEARCH("@",Tableau4[[#This Row],[file name]])))-SEARCH("/",RIGHT(Tableau4[[#This Row],[file name]],LEN(Tableau4[[#This Row],[file name]])-SEARCH("@",Tableau4[[#This Row],[file name]])))),1) -> #VALUE!
A15: =IFERROR(LEFT(RIGHT(C15,LEN(C15)-SEARCH("@",C15)),SEARCH("/",RIGHT(C15,LEN(C15)-SEARCH("@",C15)-1))),"") | B15: =LEFT(RIGHT(RIGHT(Tableau4[[#This Row],[file name]],LEN(Tableau4[[#This Row],[file name]])-SEARCH("@",Tableau4[[#This Row],[file name]])),LEN(RIGHT(Tableau4[[#This Row],[file name]],LEN(Tableau4[[#This Row],[file name]])-SEARCH("@",Tableau4[[#This Row],[file name]])))-SEARCH("/",RIGHT(Tableau4[[#This Row],[file name]],LEN(Tableau4[[#This Row],[file name]])-SEARCH("@",Tableau4[[#This Row],[file name]])))),1) -> #VALUE!
A16: =IFERROR(LEFT(RIGHT(C16,LEN(C16)-SEARCH("@",C16)),SEARCH("/",RIGHT(C16,LEN(C16)-SEARCH("@",C16)-1))),"") | B16: =LEFT(RIGHT(RIGHT(Tableau4[[#This Row],[file name]],LEN(Tableau4[[#This Row],[file name]])-SEARCH("@",Tableau4[[#This Row],[file name]])),LEN(RIGHT(Tableau4[[#This Row],[file name]],LEN(Tableau4[[#This Row],[file name]])-SEARCH("@",Tableau4[[#This Row],[file name]])))-SEARCH("/",RIGHT(Tableau4[[#This Row],[file name]],LEN(Tableau4[[#This Row],[file name]])-SEARCH("@",Tableau4[[#This Row],[file name]])))),1) -> #VALUE!
A17: =IFERROR(LEFT(RIGHT(C17,LEN(C17)-SEARCH("@",C17)),SEARCH("/",RIGHT(C17,LEN(C17)-SEARCH("@",C17)-1))),"") | B17: =LEFT(RIGHT(RIGHT(Tableau4[[#This Row],[file name]],LEN(Tableau4[[#This Row],[file name]])-SEARCH("@",Tableau4[[#This Row],[file name]])),LEN(RIGHT(Tableau4[[#This Row],[file name]],LEN(Tableau4[[#This Row],[file name]])-SEARCH("@",Tableau4[[#This Row],[file name]])))-SEARCH("/",RIGHT(Tableau4[[#This Row],[file name]],LEN(Tableau4[[#This Row],[file name]])-SEARCH("@",Tableau4[[#This Row],[file name]])))),1) -> #VALUE!
... A1557: =IFERROR(LEFT(RIGHT(C1557,LEN(C1557)-SEARCH("@",C1557)),SEARCH("/",RIGHT(C1557,LEN(C1557)-SEARCH("@",C1557)-1))),"") | B1557: =LEFT(RIGHT(RIGHT(Tableau4[[#This Row],[file name]],LEN(Tableau4[[#This Row],[file name]])-SEARCH("@",Tableau4[[#This Row],[file name]])),LEN(RIGHT(Tableau4[[#This Row],[file name]],LEN(Tableau4[[#This Row],[file name]])-SEARCH("@",Tableau4[[#This Row],[file name]])))-SEARCH("/",RIGHT(Tableau4[[#This Row],[file name]],LEN(Tableau4[[#This Row],[file name]])-SEARCH("@",Tableau4[[#This Row],[file name]])))),1) -> #VALUE!

Sheet R1
A1: 3. Expérimentateur 1 : copier et coller les valeurs des intensités totales de fluorescences obtenues dans le fichier raw data lors du traitement des images.
A3: R1 | B3: Non dopé | O3: avec testo
A4: Noms des groupes | B4: ='Page de garde'!A7 -> Témoin solvant | C4: ='Page de garde'!A9 -> EE2-33.8ng/L | D4: ='Page de garde'!A10 -> EE2-50.6ng/L | E4: ='Page de garde'!A11 -> EE2-76ng/L | F4: ='Page de garde'!A12 -> EE2-114ng/L | G4: ='Page de garde'!A13 -> EE2-170.9ng/L | H4: ='Page de garde'!A14 -> EE2-488ng/L | I4: ='Page de garde'!A15 -> BPA-1mg/L | J4: ='Page de garde'!A16 -> BPA-2mg/L | K4: ='Page de garde'!A17 -> BPA-3mg/L | L4: ='Page de garde'!A18 -> BPA-4mg/L | M4: ='Page de garde'!A19 -> BPA-5mg/L | O4: ='Page de garde'!A36 -> Testo -30µg/L | P4: ='Page de garde'!A37 -> Testo 30µg/L + EE2 -64ng/L | Q4: ='Page de garde'!A38 -> Testo 30µg/L + FAD-10µg/L | R4: ='Page de garde'!A39 -> BPA-1mg/L + Testostérone | S4: ='Page de garde'!A40 -> BPA-2mg/L + Testostérone | T4: ='Page de garde'!A41 -> BPA-3mg/L + Testostérone | U4: ='Page de garde'!A42 -> BPA-4mg/L + Testostérone | V4: ='Page de garde'!A43 -> BPA-5mg/L + Testostérone
A5: Données brutes | B5: 20425 | C5: 5266 | D5: 20553 | E5: 128302 | F5: 2580598 | G5: 3454849 | H5: 11408250 | I5: 26958 | J5: 46257 | K5: 12973 | L5: 69342 | M5: 3444338 | O5: 194963 | P5: 6070749 | Q5: 75076 | R5: 931513 | S5: 3187706 | T5: 5106170 | U5: 6402154 | V5: 8723974
B6: 32635 | C6: 5201 | D6: 96829 | E6: 66856 | F6: 885196 | G6: 3028557 | H6: 5936158 | I6: 17952 | J6: 8558 | K6: 4153 | L6: 918180 | M6: 787290 | O6: 1134466 | P6: 8310940 | Q6: 157 | R6: 772285 | S6: 3260 | T6: 3380758 | U6: 6265154 | V6: 2122346
B7: 1139 | C7: 28796 | D7: 28299 | E7: 179643 | F7: 871190 | G7: 1398458 | H7: 8722663 | I7: 6724 | J7: 3409 | K7: 1105 | L7: 804 | M7: 1446680 | O7: 243058 | P7: 11367047 | Q7: 2464 | R7: 232067 | S7: 2701432 | T7: 5168766 | U7: 6316551 | V7: 2430089
B8: 30470 | C8: 370 | D8: 2034472 | E8: 30966 | F8: 2085460 | G8: 2681815 | H8: 3792581 | I8: 544 | J8: 6017 | K8: 46339 | L8: 327993 | M8: 515668 | O8: 15329 | P8: 2918381 | Q8: 7204 | R8: 1155997 | S8: 5004744 | T8: 2402939 | U8: 2872481 | V8: 4992345
B9: 6298 | C9: 1971 | D9: 39163 | E9: 3075288 | F9: 1300276 | G9: 2910091 | H9: 4361678 | I9: 14958 | J9: 7121 | K9: 69212 | L9: 41371 | M9: 1449356 | O9: 670341 | P9: 3507096 | Q9: 17771 | R9: 4838257 | S9: 5596532 | T9: 4595815 | U9: 1985492 | V9: 8326641
B10: 21291 | C10: 28 | D10: 10345 | E10: 16916 | F10: 1004811 | G10: 1903433 | H10: 6052165 | I10: 24264 | J10: 42515 | K10: 1341 | L10: 861104 | M10: 152 | O10: 1195331 | P10: 4729680 | Q10: 29626 | R10: 693829 | S10: 248994 | T10: 2297774 | U10: 6644573 | V10: 7258536
B11: 2065 | C11: 130 | D11: 53999 | E11: 349294 | F11: 150975 | G11: 3809116 | I11: 3809 | J11: 397 | K11: 481 | L11: 583912 | M11: 315017 | O11: 30683 | P11: 10342504 | Q11: 11046 | R11: 1218101 | S11: 4083461 | T11: 6432400 | U11: 6464218 | V11: 6566624
C12: 580662 | D12: 52353 | I12: 1728 | J12: 1421 | K12: 20595 | L12: 12287 | O12: 642339 | P12: 10194498 | Q12: 24173 | R12: 273401 | S12: 2387692 | T12: 5087643 | U12: 3117086
O13: 5320920
O14: 6723
O15: 125073
O16: 1072115
O17: 2237625
O18: 695941
O19: 2663838
A22: =A4 -> Noms des groupes | B22: =B4 -> Témoin solvant | C22: =C4 -> EE2-33.8ng/L | D22: =D4 -> EE2-50.6ng/L | E22: =E4 -> EE2-76ng/L | F22: =F4 -> EE2-114ng/L | G22: =G4 -> EE2-170.9ng/L | H22: =H4 -> EE2-488ng/L | ... M22: =M4 -> BPA-5mg/L | N22: Nom des groupes | O22: =O4 -> Testo -30µg/L | P22: =P4 -> Testo 30µg/L + EE2 -64ng/L | Q22: =Q4 -> Testo 30µg/L + FAD-10µg/L | R22: =R4 -> BPA-1mg/L + Testostérone | S22: =S4 -> BPA-2mg/L + Testostérone | T22: =T4 -> BPA-3mg/L + Testostérone | U22: =U4 -> BPA-4mg/L + Testostérone | V22: =V4 -> BPA-5mg/L + Testostérone
A23: mean | B23: =AVERAGE(B5:B20) -> 16331.857 | C23: =AVERAGE(C5:C20) -> 77803 | D23: =AVERAGE(D5:D20) -> 292001.62 | E23: =AVERAGE(E5:E20) -> 549609.29 | F23: =AVERAGE(F5:F20) -> 1268358 | G23: =AVERAGE(G5:G20) -> 2740902.7 | H23: =AVERAGE(H5:H20) -> 6712249.2 | I23: =AVERAGE(I5:I20) -> 12117.125 | ... M23: =AVERAGE(M5:M20) -> 1136928.7 | N23: mean | O23: =AVERAGE(O5:O20) -> 1083249.7 | P23: =AVERAGE(P5:P20) -> 7180111.9 | Q23: =AVERAGE(Q5:Q20) -> 20939.625 | R23: =AVERAGE(R5:R20) -> 1264431.2 | S23: =AVERAGE(S5:S20) -> 2901727.6 | T23: =AVERAGE(T5:T20) -> 4309033.1 | U23: =AVERAGE(U5:U20) -> 5008463.6 | V23: =AVERAGE(V5:V20) -> 5774365
A24: SD | B24: =STDEV(B5:B20) -> 13178.713 | C24: =STDEV(C5:C20) -> 203410.19 | D24: =STDEV(D5:D20) -> 704562 | E24: =STDEV(E5:E20) -> 1119475.9 | F24: =STDEV(F5:F20) -> 817843.26 | G24: =STDEV(G5:G20) -> 843521.71 | H24: =STDEV(H5:H20) -> 2869908.1 | I24: =STDEV(I5:I20) -> 10350.268 | ... M24: =STDEV(M5:M20) -> 1154246.3 | N24: SD | O24: =STDEV(O5:O20) -> 1417725.6 | P24: =STDEV(P5:P20) -> 3311994.3 | Q24: =STDEV(Q5:Q20) -> 24161.695 | R24: =STDEV(R5:R20) -> 1488656.2 | S24: =STDEV(S5:S20) -> 2032078 | T24: =STDEV(T5:T20) -> 1469294.5 | U24: =STDEV(U5:U20) -> 1975091.3 | V24: =STDEV(V5:V20) -> 2682589.7
B26: Non dopé | O26: avec testo
A27: Noms des groupes | B27: =B4 -> Témoin solvant | C27: =C4 -> EE2-33.8ng/L | D27: =D4 -> EE2-50.6ng/L | E27: =E4 -> EE2-76ng/L | F27: =F4 -> EE2-114ng/L | G27: =G4 -> EE2-170.9ng/L | H27: =H4 -> EE2-488ng/L | I27: =I4 -> BPA-1mg/L | ... M27: =M4 -> BPA-5mg/L | O27: =O4 -> Testo -30µg/L | P27: =P4 -> Testo 30µg/L + EE2 -64ng/L | Q27: =Q4 -> Testo 30µg/L + FAD-10µg/L | R27: =R4 -> BPA-1mg/L + Testostérone | S27: =S4 -> BPA-2mg/L + Testostérone | T27: =T4 -> BPA-3mg/L + Testostérone | U27: =U4 -> BPA-4mg/L + Testostérone | V27: =V4 -> BPA-5mg/L + Testostérone
A28: Données normalisées sur la moyenne du groupe "Testo" | B28: =IF(B5="","",(B5/$O$23)) -> 0.018855302 | C28: =IF(C5="","",(C5/$O$23)) -> 0.0048612985 | D28: =IF(D5="","",(D5/$O$23)) -> 0.018973465 | E28: =IF(E5="","",(E5/$O$23)) -> 0.11844176 | F28: =IF(F5="","",(F5/$O$23)) -> 2.3822744 | G28: =IF(G5="","",(G5/$O$23)) -> 3.1893377 | H28: =IF(H5="","",(H5/$O$23)) -> 10.531506 | I28: =IF(I5="","",(I5/$O$23)) -> 0.02488623 | ... M28: =IF(M5="","",(M5/$O$23)) -> 3.1796345 | O28: =IF(O5="","",(O5/$O$23)) -> 0.17997975 | P28: =IF(P5="","",(P5/$O$23)) -> 5.6042011 | Q28: =IF(Q5="","",(Q5/$O$23)) -> 0.069306276 | R28: =IF(R5="","",(R5/$O$23)) -> 0.85992457 | S28: =IF(S5="","",(S5/$O$23)) -> 2.9427251 | T28: =IF(T5="","",(T5/$O$23)) -> 4.7137517 | U28: =IF(U5="","",(U5/$O$23)) -> 5.9101371 | V28: =IF(V5="","",(V5/$O$23)) -> 8.0535211
B29: =IF(B6="","",(B6/$O$23)) -> 0.030126942 | C29: =IF(C6="","",(C6/$O$23)) -> 0.0048012939 | D29: =IF(D6="","",(D6/$O$23)) -> 0.089387519 | E29: =IF(E6="","",(E6/$O$23)) -> 0.061717997 | F29: =IF(F6="","",(F6/$O$23)) -> 0.81716711 | G29: =IF(G6="","",(G6/$O$23)) -> 2.795807 | H29: =IF(H6="","",(H6/$O$23)) -> 5.4799537 | I29: =IF(I6="","",(I6/$O$23)) -> 0.016572357 | ... M29: =IF(M6="","",(M6/$O$23)) -> 0.72678536 | O29: =IF(O6="","",(O6/$O$23)) -> 1.0472803 | P29: =IF(P6="","",(P6/$O$23)) -> 7.6722295 | Q29: =IF(Q6="","",(Q6/$O$23)) -> 0.00014493427 | R29: =IF(R6="","",(R6/$O$23)) -> 0.71293352 | S29: =IF(S6="","",(S6/$O$23)) -> 0.0030094632 | T29: =IF(T6="","",(T6/$O$23)) -> 3.1209407 | U29: =IF(U6="","",(U6/$O$23)) -> 5.7836658 | V29: =IF(V6="","",(V6/$O$23)) -> 1.9592399
B30: =IF(B7="","",(B7/$O$23)) -> 0.0010514658 | C30: =IF(C7="","",(C7/$O$23)) -> 0.026582976 | D30: =IF(D7="","",(D7/$O$23)) -> 0.026124171 | E30: =IF(E7="","",(E7/$O$23)) -> 0.16583712 | F30: =IF(F7="","",(F7/$O$23)) -> 0.8042375 | G30: =IF(G7="","",(G7/$O$23)) -> 1.290984 | H30: =IF(H7="","",(H7/$O$23)) -> 8.0523108 | I30: =IF(I7="","",(I7/$O$23)) -> 0.0062072486 | ... M30: =IF(M7="","",(M7/$O$23)) -> 1.3355001 | O30: =IF(O7="","",(O7/$O$23)) -> 0.22437856 | P30: =IF(P7="","",(P7/$O$23)) -> 10.493469 | Q30: =IF(Q7="","",(Q7/$O$23)) -> 0.0022746372 | R30: =IF(R7="","",(R7/$O$23)) -> 0.21423224 | S30: =IF(S7="","",(S7/$O$23)) -> 2.4938221 | T30: =IF(T7="","",(T7/$O$23)) -> 4.7715371 | U30: =IF(U7="","",(U7/$O$23)) -> 5.8311128 | V30: =IF(V7="","",(V7/$O$23)) -> 2.2433323
B31: =IF(B8="","",(B8/$O$23)) -> 0.028128326 | C31: =IF(C8="","",(C8/$O$23)) -> 0.00034156484 | D31: =IF(D8="","",(D8/$O$23)) -> 1.8781192 | E31: =IF(E8="","",(E8/$O$23)) -> 0.028586208 | F31: =IF(F8="","",(F8/$O$23)) -> 1.9251887 | G31: =IF(G8="","",(G8/$O$23)) -> 2.4757127 | H31: =IF(H8="","",(H8/$O$23)) -> 3.5011144 | I31: =IF(I8="","",(I8/$O$23)) -> 0.00050219263 | ... M31: =IF(M8="","",(M8/$O$23)) -> 0.476038 | O31: =IF(O8="","",(O8/$O$23)) -> 0.014150939 | P31: =IF(P8="","",(P8/$O$23)) -> 2.6940982 | Q31: =IF(Q8="","",(Q8/$O$23)) -> 0.0066503598 | R31: =IF(R8="","",(R8/$O$23)) -> 1.0671566 | S31: =IF(S8="","",(S8/$O$23)) -> 4.6201205 | T31: =IF(T8="","",(T8/$O$23)) -> 2.2182689 | U31: =IF(U8="","",(U8/$O$23)) -> 2.6517257 | V31: =IF(V8="","",(V8/$O$23)) -> 4.6086744
B32: =IF(B9="","",(B9/$O$23)) -> 0.0058139875 | C32: =IF(C9="","",(C9/$O$23)) -> 0.0018195251 | D32: =IF(D9="","",(D9/$O$23)) -> 0.036153254 | E32: =IF(E9="","",(E9/$O$23)) -> 2.8389466 | F32: =IF(F9="","",(F9/$O$23)) -> 1.2003475 | G32: =IF(G9="","",(G9/$O$23)) -> 2.6864453 | H32: =IF(H9="","",(H9/$O$23)) -> 4.0264753 | I32: =IF(I9="","",(I9/$O$23)) -> 0.013808451 | ... M32: =IF(M9="","",(M9/$O$23)) -> 1.3379704 | O32: =IF(O9="","",(O9/$O$23)) -> 0.6188241 | P32: =IF(P9="","",(P9/$O$23)) -> 3.2375694 | Q32: =IF(Q9="","",(Q9/$O$23)) -> 0.016405267 | R32: =IF(R9="","",(R9/$O$23)) -> 4.4664283 | S32: =IF(S9="","",(S9/$O$23)) -> 5.1664285 | T32: =IF(T9="","",(T9/$O$23)) -> 4.2426184 | U32: =IF(U9="","",(U9/$O$23)) -> 1.8329034 | V32: =IF(V9="","",(V9/$O$23)) -> 7.6867238
B33: =IF(B10="","",(B10/$O$23)) -> 0.019654749 | C33: =IF(C10="","",(C10/$O$23)) -> 2.584815e-05 | D33: =IF(D10="","",(D10/$O$23)) -> 0.0095499683 | E33: =IF(E10="","",(E10/$O$23)) -> 0.015615975 | F33: =IF(F10="","",(F10/$O$23)) -> 0.92758948 | G33: =IF(G10="","",(G10/$O$23)) -> 1.7571508 | H33: =IF(H10="","",(H10/$O$23)) -> 5.5870453 | I33: =IF(I10="","",(I10/$O$23)) -> 0.022399268 | ... M33: =IF(M10="","",(M10/$O$23)) -> 0.00014031853 | O33: =IF(O10="","",(O10/$O$23)) -> 1.1034677 | P33: =IF(P10="","",(P10/$O$23)) -> 4.3661957 | Q33: =IF(Q10="","",(Q10/$O$23)) -> 0.027349189 | R33: =IF(R10="","",(R10/$O$23)) -> 0.64050701 | S33: =IF(S10="","",(S10/$O$23)) -> 0.22985837 | T33: =IF(T10="","",(T10/$O$23)) -> 2.121186 | U33: =IF(U10="","",(U10/$O$23)) -> 6.1339257 | V33: =IF(V10="","",(V10/$O$23)) -> 6.7007046
B34: =IF(B11="","",(B11/$O$23)) -> 0.0019063011 | C34: =IF(C11="","",(C11/$O$23)) -> 0.00012000927 | D34: =IF(D11="","",(D11/$O$23)) -> 0.049849081 | E34: =IF(E11="","",(E11/$O$23)) -> 0.32245013 | F34: =IF(F11="","",(F11/$O$23)) -> 0.1393723 | G34: =IF(G11="","",(G11/$O$23)) -> 3.5163786 | H34: =IF(H11="","",(H11/$O$23)) | I34: =IF(I11="","",(I11/$O$23)) -> 0.0035162716 | ... M34: =IF(M11="","",(M11/$O$23)) -> 0.29080738 | O34: =IF(O11="","",(O11/$O$23)) -> 0.028324957 | P34: =IF(P11="","",(P11/$O$23)) -> 9.5476641 | Q34: =IF(Q11="","",(Q11/$O$23)) -> 0.010197095 | R34: =IF(R11="","",(R11/$O$23)) -> 1.1244878 | S34: =IF(S11="","",(S11/$O$23)) -> 3.7696397 | T34: =IF(T11="","",(T11/$O$23)) -> 5.9380586 | U34: =IF(U11="","",(U11/$O$23)) -> 5.9674313 | V34: =IF(V11="","",(V11/$O$23)) -> 6.0619672
B35: =IF(B12="","",(B12/$O$23)) | C35: =IF(C12="","",(C12/$O$23)) -> 0.53603709 | D35: =IF(D12="","",(D12/$O$23)) -> 0.048329579 | E35: =IF(E12="","",(E12/$O$23)) | F35: =IF(F12="","",(F12/$O$23)) | G35: =IF(G12="","",(G12/$O$23)) | H35: =IF(H12="","",(H12/$O$23)) | I35: =IF(I12="","",(I12/$O$23)) -> 0.0015952001 | ... M35: =IF(M12="","",(M12/$O$23)) | O35: =IF(O12="","",(O12/$O$23)) -> 0.5929741 | P35: =IF(P12="","",(P12/$O$23)) -> 9.4110327 | Q35: =IF(Q12="","",(Q12/$O$23)) -> 0.022315262 | R35: =IF(R12="","",(R12/$O$23)) -> 0.25238965 | S35: =IF(S12="","",(S12/$O$23)) -> 2.2041936 | T35: =IF(T12="","",(T12/$O$23)) -> 4.6966486 | U35: =IF(U12="","",(U12/$O$23)) -> 2.8775324 | V35: =IF(V12="","",(V12/$O$23))
B36: =IF(B13="","",(B13/$O$23)) | C36: =IF(C13="","",(C13/$O$23)) | D36: =IF(D13="","",(D13/$O$23)) | E36: =IF(E13="","",(E13/$O$23)) | F36: =IF(F13="","",(F13/$O$23)) | G36: =IF(G13="","",(G13/$O$23)) | H36: =IF(H13="","",(H13/$O$23)) | I36: =IF(I13="","",(I13/$O$23)) | ... M36: =IF(M13="","",(M13/$O$23)) | O36: =IF(O13="","",(O13/$O$23)) -> 4.9119978 | P36: =IF(P13="","",(P13/$O$23)) | Q36: =IF(Q13="","",(Q13/$O$23)) | R36: =IF(R13="","",(R13/$O$23)) | S36: =IF(S13="","",(S13/$O$23)) | T36: =IF(T13="","",(T13/$O$23)) | U36: =IF(U13="","",(U13/$O$23)) | V36: =IF(V13="","",(V13/$O$23))
B37: =IF(B14="","",(B14/$O$23)) | C37: =IF(C14="","",(C14/$O$23)) | D37: =IF(D14="","",(D14/$O$23)) | E37: =IF(E14="","",(E14/$O$23)) | F37: =IF(F14="","",(F14/$O$23)) | G37: =IF(G14="","",(G14/$O$23)) | H37: =IF(H14="","",(H14/$O$23)) | I37: =IF(I14="","",(I14/$O$23)) | ... M37: =IF(M14="","",(M14/$O$23)) | O37: =IF(O14="","",(O14/$O$23)) -> 0.0062063255 | P37: =IF(P14="","",(P14/$O$23)) | Q37: =IF(Q14="","",(Q14/$O$23)) | R37: =IF(R14="","",(R14/$O$23)) | S37: =IF(S14="","",(S14/$O$23)) | T37: =IF(T14="","",(T14/$O$23)) | U37: =IF(U14="","",(U14/$O$23)) | V37: =IF(V14="","",(V14/$O$23))
B38: =IF(B15="","",(B15/$O$23)) | C38: =IF(C15="","",(C15/$O$23)) | D38: =IF(D15="","",(D15/$O$23)) | E38: =IF(E15="","",(E15/$O$23)) | F38: =IF(F15="","",(F15/$O$23)) | G38: =IF(G15="","",(G15/$O$23)) | H38: =IF(H15="","",(H15/$O$23)) | I38: =IF(I15="","",(I15/$O$23)) | ... M38: =IF(M15="","",(M15/$O$23)) | O38: =IF(O15="","",(O15/$O$23)) -> 0.11546092 | P38: =IF(P15="","",(P15/$O$23)) | Q38: =IF(Q15="","",(Q15/$O$23)) | R38: =IF(R15="","",(R15/$O$23)) | S38: =IF(S15="","",(S15/$O$23)) | T38: =IF(T15="","",(T15/$O$23)) | U38: =IF(U15="","",(U15/$O$23)) | V38: =IF(V15="","",(V15/$O$23))
B39: =IF(B16="","",(B16/$O$23)) | C39: =IF(C16="","",(C16/$O$23)) | D39: =IF(D16="","",(D16/$O$23)) | E39: =IF(E16="","",(E16/$O$23)) | F39: =IF(F16="","",(F16/$O$23)) | G39: =IF(G16="","",(G16/$O$23)) | H39: =IF(H16="","",(H16/$O$23)) | I39: =IF(I16="","",(I16/$O$23)) | ... M39: =IF(M16="","",(M16/$O$23)) | O39: =IF(O16="","",(O16/$O$23)) -> 0.98972105 | P39: =IF(P16="","",(P16/$O$23)) | Q39: =IF(Q16="","",(Q16/$O$23)) | R39: =IF(R16="","",(R16/$O$23)) | S39: =IF(S16="","",(S16/$O$23)) | T39: =IF(T16="","",(T16/$O$23)) | U39: =IF(U16="","",(U16/$O$23)) | V39: =IF(V16="","",(V16/$O$23))
B40: =IF(B17="","",(B17/$O$23)) | C40: =IF(C17="","",(C17/$O$23)) | D40: =IF(D17="","",(D17/$O$23)) | E40: =IF(E17="","",(E17/$O$23)) | F40: =IF(F17="","",(F17/$O$23)) | G40: =IF(G17="","",(G17/$O$23)) | H40: =IF(H17="","",(H17/$O$23)) | I40: =IF(I17="","",(I17/$O$23)) | ... M40: =IF(M17="","",(M17/$O$23)) | O40: =IF(O17="","",(O17/$O$23)) -> 2.0656595 | P40: =IF(P17="","",(P17/$O$23)) | Q40: =IF(Q17="","",(Q17/$O$23)) | R40: =IF(R17="","",(R17/$O$23)) | S40: =IF(S17="","",(S17/$O$23)) | T40: =IF(T17="","",(T17/$O$23)) | U40: =IF(U17="","",(U17/$O$23)) | V40: =IF(V17="","",(V17/$O$23))
... B43: =IF(B20="","",(B20/$O$23)) | C43: =IF(C20="","",(C20/$O$23)) | D43: =IF(D20="","",(D20/$O$23)) | E43: =IF(E20="","",(E20/$O$23)) | F43: =IF(F20="","",(F20/$O$23)) | G43: =IF(G20="","",(G20/$O$23)) | H43: =IF(H20="","",(H20/$O$23)) | I43: =IF(I20="","",(I20/$O$23)) | ... M43: =IF(M20="","",(M20/$O$23)) | O43: =IF(O20="","",(O20/$O$23)) | P43: =IF(P20="","",(P20/$O$23)) | Q43: =IF(Q20="","",(Q20/$O$23)) | R43: =IF(R20="","",(R20/$O$23)) | S43: =IF(S20="","",(S20/$O$23)) | T43: =IF(T20="","",(T20/$O$23)) | U43: =IF(U20="","",(U20/$O$23)) | V43: =IF(V20="","",(V20/$O$23))
A45: =A4 -> Noms des groupes | B45: =B4 -> Témoin solvant | C45: =C4 -> EE2-33.8ng/L | D45: =D4 -> EE2-50.6ng/L | E45: =E4 -> EE2-76ng/L | F45: =F4 -> EE2-114ng/L | G45: =G4 -> EE2-170.9ng/L | H45: =H4 -> EE2-488ng/L | ... M45: =M4 -> BPA-5mg/L | N45: =N22 -> Nom des groupes | O45: =O4 -> Testo -30µg/L | P45: =P4 -> Testo 30µg/L + EE2 -64ng/L | Q45: =Q4 -> Testo 30µg/L + FAD-10µg/L | R45: =R4 -> BPA-1mg/L + Testostérone | S45: =S4 -> BPA-2mg/L + Testostérone | T45: =T4 -> BPA-3mg/L + Testostérone | U45: =U4 -> BPA-4mg/L + Testostérone | V45: =V4 -> BPA-5mg/L + Testostérone
A46: mean | B46: =AVERAGE(B28:B43) -> 0.015076725 | C46: =AVERAGE(C28:C43) -> 0.071823701 | D46: =AVERAGE(D28:D43) -> 0.26956078 | E46: =AVERAGE(E28:E43) -> 0.50737083 | F46: =AVERAGE(F28:F43) -> 1.1708824 | G46: =AVERAGE(G28:G43) -> 2.5302595 | H46: =AVERAGE(H28:H43) -> 6.1964009 | I46: =AVERAGE(I28:I43) -> 0.011185902 | ... M46: =AVERAGE(M28:M43) -> 1.0495537 | N46: mean | O46: =AVERAGE(O28:O43) -> 1 | P46: =AVERAGE(P28:P43) -> 6.6283075 | Q46: =AVERAGE(Q28:Q43) -> 0.019330378 | R46: =AVERAGE(R28:R43) -> 1.1672575 | S46: =AVERAGE(S28:S43) -> 2.6787247 | T46: =AVERAGE(T28:T43) -> 3.9778763 | U46: =AVERAGE(U28:U43) -> 4.6235543 | V46: =AVERAGE(V28:V43) -> 5.3305948
A47: SD | B47: =STDEV(B28:B43) -> 0.012165906 | C47: =STDEV(C28:C43) -> 0.18777775 | D47: =STDEV(D28:D43) -> 0.65041516 | E47: =STDEV(E28:E43) -> 1.0334422 | F47: =STDEV(F28:F43) -> 0.75499055 | G47: =STDEV(G28:G43) -> 0.77869557 | H47: =STDEV(H28:H43) -> 2.6493506 | I47: =STDEV(I28:I43) -> 0.0095548316 | ... M47: =STDEV(M28:M43) -> 1.0655404 | N47: SD | O47: =STDEV(O28:O43) -> 1.3087709 | P47: =STDEV(P28:P43) -> 3.0574616 | Q47: =STDEV(Q28:Q43) -> 0.022304826 | R47: =STDEV(R28:R43) -> 1.3742503 | S47: =STDEV(S28:S43) -> 1.8759092 | T47: =STDEV(T28:T43) -> 1.3563766 | U47: =STDEV(U28:U43) -> 1.823302 | V47: =STDEV(V28:V43) -> 2.4764279
...

Sheet Raw data R2
A1: Nom groupe | B1: N° de valeur | C1: file name | D1: total area | E1: mean intensity | G1: total fluorescence | I1: nbre de larves | L1: (Tous)
A2: =IFERROR(LEFT(RIGHT(C2,LEN(C2)-SEARCH("@",C2)),SEARCH("/",RIGHT(C2,LEN(C2)-SEARCH("@",C2)-1))),"") | B2: =LEFT(RIGHT(RIGHT(Tableau46[[#This Row],[file name]],LEN(Tableau46[[#This Row],[file name]])-SEARCH("@",Tableau46[[#This Row],[file name]])),LEN(RIGHT(Tableau46[[#This Row],[file name]],LEN(Tableau46[[#This Row],[file name]])-SEARCH("@",Tableau46[[#This Row],[file name]])))-SEARCH("/",RIGHT(Tableau46[[#This Row],[file name]],LEN(Tableau46[[#This Row],[file name]])-SEARCH("@",Tableau46[[#This Row],[file name]])))),1) -> #VALUE! | K2: Filtre lignes : Enlever (vide) et Néant | L2: Filtre colonnes : Enlever (vide) et " "
A3: =IFERROR(LEFT(RIGHT(C3,LEN(C3)-SEARCH("@",C3)),SEARCH("/",RIGHT(C3,LEN(C3)-SEARCH("@",C3)-1))),"") | B3: =LEFT(RIGHT(RIGHT(Tableau46[[#This Row],[file name]],LEN(Tableau46[[#This Row],[file name]])-SEARCH("@",Tableau46[[#This Row],[file name]])),LEN(RIGHT(Tableau46[[#This Row],[file name]],LEN(Tableau46[[#This Row],[file name]])-SEARCH("@",Tableau46[[#This Row],[file name]])))-SEARCH("/",RIGHT(Tableau46[[#This Row],[file name]],LEN(Tableau46[[#This Row],[file name]])-SEARCH("@",Tableau46[[#This Row],[file name]])))),1) -> #VALUE! | K3: Moyenne de total fluorescence | L3: Étiquettes de colonnes
A4: =IFERROR(LEFT(RIGHT(C4,LEN(C4)-SEARCH("@",C4)),SEARCH("/",RIGHT(C4,LEN(C4)-SEARCH("@",C4)-1))),"") | B4: =LEFT(RIGHT(RIGHT(Tableau46[[#This Row],[file name]],LEN(Tableau46[[#This Row],[file name]])-SEARCH("@",Tableau46[[#This Row],[file name]])),LEN(RIGHT(Tableau46[[#This Row],[file name]],LEN(Tableau46[[#This Row],[file name]])-SEARCH("@",Tableau46[[#This Row],[file name]])))-SEARCH("/",RIGHT(Tableau46[[#This Row],[file name]],LEN(Tableau46[[#This Row],[file name]])-SEARCH("@",Tableau46[[#This Row],[file name]])))),1) -> #VALUE! | K4: Étiquettes de lignes
A5: =IFERROR(LEFT(RIGHT(C5,LEN(C5)-SEARCH("@",C5)),SEARCH("/",RIGHT(C5,LEN(C5)-SEARCH("@",C5)-1))),"") | B5: =LEFT(RIGHT(RIGHT(Tableau46[[#This Row],[file name]],LEN(Tableau46[[#This Row],[file name]])-SEARCH("@",Tableau46[[#This Row],[file name]])),LEN(RIGHT(Tableau46[[#This Row],[file name]],LEN(Tableau46[[#This Row],[file name]])-SEARCH("@",Tableau46[[#This Row],[file name]])))-SEARCH("/",RIGHT(Tableau46[[#This Row],[file name]],LEN(Tableau46[[#This Row],[file name]])-SEARCH("@",Tableau46[[#This Row],[file name]])))),1) -> #VALUE! | K5: #VALEUR!
A6: =IFERROR(LEFT(RIGHT(C6,LEN(C6)-SEARCH("@",C6)),SEARCH("/",RIGHT(C6,LEN(C6)-SEARCH("@",C6)-1))),"") | B6: =LEFT(RIGHT(RIGHT(Tableau46[[#This Row],[file name]],LEN(Tableau46[[#This Row],[file name]])-SEARCH("@",Tableau46[[#This Row],[file name]])),LEN(RIGHT(Tableau46[[#This Row],[file name]],LEN(Tableau46[[#This Row],[file name]])-SEARCH("@",Tableau46[[#This Row],[file name]])))-SEARCH("/",RIGHT(Tableau46[[#This Row],[file name]],LEN(Tableau46[[#This Row],[file name]])-SEARCH("@",Tableau46[[#This Row],[file name]])))),1) -> #VALUE!
A7: =IFERROR(LEFT(RIGHT(C7,LEN(C7)-SEARCH("@",C7)),SEARCH("/",RIGHT(C7,LEN(C7)-SEARCH("@",C7)-1))),"") | B7: =LEFT(RIGHT(RIGHT(Tableau46[[#This Row],[file name]],LEN(Tableau46[[#This Row],[file name]])-SEARCH("@",Tableau46[[#This Row],[file name]])),LEN(RIGHT(Tableau46[[#This Row],[file name]],LEN(Tableau46[[#This Row],[file name]])-SEARCH("@",Tableau46[[#This Row],[file name]])))-SEARCH("/",RIGHT(Tableau46[[#This Row],[file name]],LEN(Tableau46[[#This Row],[file name]])-SEARCH("@",Tableau46[[#This Row],[file name]])))),1) -> #VALUE!
A8: =IFERROR(LEFT(RIGHT(C8,LEN(C8)-SEARCH("@",C8)),SEARCH("/",RIGHT(C8,LEN(C8)-SEARCH("@",C8)-1))),"") | B8: =LEFT(RIGHT(RIGHT(Tableau46[[#This Row],[file name]],LEN(Tableau46[[#This Row],[file name]])-SEARCH("@",Tableau46[[#This Row],[file name]])),LEN(RIGHT(Tableau46[[#This Row],[file name]],LEN(Tableau46[[#This Row],[file name]])-SEARCH("@",Tableau46[[#This Row],[file name]])))-SEARCH("/",RIGHT(Tableau46[[#This Row],[file name]],LEN(Tableau46[[#This Row],[file name]])-SEARCH("@",Tableau46[[#This Row],[file name]])))),1) -> #VALUE!
A9: =IFERROR(LEFT(RIGHT(C9,LEN(C9)-SEARCH("@",C9)),SEARCH("/",RIGHT(C9,LEN(C9)-SEARCH("@",C9)-1))),"") | B9: =LEFT(RIGHT(RIGHT(Tableau46[[#This Row],[file name]],LEN(Tableau46[[#This Row],[file name]])-SEARCH("@",Tableau46[[#This Row],[file name]])),LEN(RIGHT(Tableau46[[#This Row],[file name]],LEN(Tableau46[[#This Row],[file name]])-SEARCH("@",Tableau46[[#This Row],[file name]])))-SEARCH("/",RIGHT(Tableau46[[#This Row],[file name]],LEN(Tableau46[[#This Row],[file name]])-SEARCH("@",Tableau46[[#This Row],[file name]])))),1) -> #VALUE!
A10: =IFERROR(LEFT(RIGHT(C10,LEN(C10)-SEARCH("@",C10)),SEARCH("/",RIGHT(C10,LEN(C10)-SEARCH("@",C10)-1))),"") | B10: =LEFT(RIGHT(RIGHT(Tableau46[[#This Row],[file name]],LEN(Tableau46[[#This Row],[file name]])-SEARCH("@",Tableau46[[#This Row],[file name]])),LEN(RIGHT(Tableau46[[#This Row],[file name]],LEN(Tableau46[[#This Row],[file name]])-SEARCH("@",Tableau46[[#This Row],[file name]])))-SEARCH("/",RIGHT(Tableau46[[#This Row],[file name]],LEN(Tableau46[[#This Row],[file name]])-SEARCH("@",Tableau46[[#This Row],[file name]])))),1) -> #VALUE!
A11: =IFERROR(LEFT(RIGHT(C11,LEN(C11)-SEARCH("@",C11)),SEARCH("/",RIGHT(C11,LEN(C11)-SEARCH("@",C11)-1))),"") | B11: =LEFT(RIGHT(RIGHT(Tableau46[[#This Row],[file name]],LEN(Tableau46[[#This Row],[file name]])-SEARCH("@",Tableau46[[#This Row],[file name]])),LEN(RIGHT(Tableau46[[#This Row],[file name]],LEN(Tableau46[[#This Row],[file name]])-SEARCH("@",Tableau46[[#This Row],[file name]])))-SEARCH("/",RIGHT(Tableau46[[#This Row],[file name]],LEN(Tableau46[[#This Row],[file name]])-SEARCH("@",Tableau46[[#This Row],[file name]])))),1) -> #VALUE!
A12: =IFERROR(LEFT(RIGHT(C12,LEN(C12)-SEARCH("@",C12)),SEARCH("/",RIGHT(C12,LEN(C12)-SEARCH("@",C12)-1))),"") | B12: =LEFT(RIGHT(RIGHT(Tableau46[[#This Row],[file name]],LEN(Tableau46[[#This Row],[file name]])-SEARCH("@",Tableau46[[#This Row],[file name]])),LEN(RIGHT(Tableau46[[#This Row],[file name]],LEN(Tableau46[[#This Row],[file name]])-SEARCH("@",Tableau46[[#This Row],[file name]])))-SEARCH("/",RIGHT(Tableau46[[#This Row],[file name]],LEN(Tableau46[[#This Row],[file name]])-SEARCH("@",Tableau46[[#This Row],[file name]])))),1) -> #VALUE!
A13: =IFERROR(LEFT(RIGHT(C13,LEN(C13)-SEARCH("@",C13)),SEARCH("/",RIGHT(C13,LEN(C13)-SEARCH("@",C13)-1))),"") | B13: =LEFT(RIGHT(RIGHT(Tableau46[[#This Row],[file name]],LEN(Tableau46[[#This Row],[file name]])-SEARCH("@",Tableau46[[#This Row],[file name]])),LEN(RIGHT(Tableau46[[#This Row],[file name]],LEN(Tableau46[[#This Row],[file name]])-SEARCH("@",Tableau46[[#This Row],[file name]])))-SEARCH("/",RIGHT(Tableau46[[#This Row],[file name]],LEN(Tableau46[[#This Row],[file name]])-SEARCH("@",Tableau46[[#This Row],[file name]])))),1) -> #VALUE!
A14: =IFERROR(LEFT(RIGHT(C14,LEN(C14)-SEARCH("@",C14)),SEARCH("/",RIGHT(C14,LEN(C14)-SEARCH("@",C14)-1))),"") | B14: =LEFT(RIGHT(RIGHT(Tableau46[[#This Row],[file name]],LEN(Tableau46[[#This Row],[file name]])-SEARCH("@",Tableau46[[#This Row],[file name]])),LEN(RIGHT(Tableau46[[#This Row],[file name]],LEN(Tableau46[[#This Row],[file name]])-SEARCH("@",Tableau46[[#This Row],[file name]])))-SEARCH("/",RIGHT(Tableau46[[#This Row],[file name]],LEN(Tableau46[[#This Row],[file name]])-SEARCH("@",Tableau46[[#This Row],[file name]])))),1) -> #VALUE!
A15: =IFERROR(LEFT(RIGHT(C15,LEN(C15)-SEARCH("@",C15)),SEARCH("/",RIGHT(C15,LEN(C15)-SEARCH("@",C15)-1))),"") | B15: =LEFT(RIGHT(RIGHT(Tableau46[[#This Row],[file name]],LEN(Tableau46[[#This Row],[file name]])-SEARCH("@",Tableau46[[#This Row],[file name]])),LEN(RIGHT(Tableau46[[#This Row],[file name]],LEN(Tableau46[[#This Row],[file name]])-SEARCH("@",Tableau46[[#This Row],[file name]])))-SEARCH("/",RIGHT(Tableau46[[#This Row],[file name]],LEN(Tableau46[[#This Row],[file name]])-SEARCH("@",Tableau46[[#This Row],[file name]])))),1) -> #VALUE!
A16: =IFERROR(LEFT(RIGHT(C16,LEN(C16)-SEARCH("@",C16)),SEARCH("/",RIGHT(C16,LEN(C16)-SEARCH("@",C16)-1))),"") | B16: =LEFT(RIGHT(RIGHT(Tableau46[[#This Row],[file name]],LEN(Tableau46[[#This Row],[file name]])-SEARCH("@",Tableau46[[#This Row],[file name]])),LEN(RIGHT(Tableau46[[#This Row],[file name]],LEN(Tableau46[[#This Row],[file name]])-SEARCH("@",Tableau46[[#This Row],[file name]])))-SEARCH("/",RIGHT(Tableau46[[#This Row],[file name]],LEN(Tableau46[[#This Row],[file name]])-SEARCH("@",Tableau46[[#This Row],[file name]])))),1) -> #VALUE!
A17: =IFERROR(LEFT(RIGHT(C17,LEN(C17)-SEARCH("@",C17)),SEARCH("/",RIGHT(C17,LEN(C17)-SEARCH("@",C17)-1))),"") | B17: =LEFT(RIGHT(RIGHT(Tableau46[[#This Row],[file name]],LEN(Tableau46[[#This Row],[file name]])-SEARCH("@",Tableau46[[#This Row],[file name]])),LEN(RIGHT(Tableau46[[#This Row],[file name]],LEN(Tableau46[[#This Row],[file name]])-SEARCH("@",Tableau46[[#This Row],[file name]])))-SEARCH("/",RIGHT(Tableau46[[#This Row],[file name]],LEN(Tableau46[[#This Row],[file name]])-SEARCH("@",Tableau46[[#This Row],[file name]])))),1) -> #VALUE!
... A1531: =IFERROR(LEFT(RIGHT(C1531,LEN(C1531)-SEARCH("@",C1531)),SEARCH("/",RIGHT(C1531,LEN(C1531)-SEARCH("@",C1531)-1))),"") | B1531: =LEFT(RIGHT(RIGHT(Tableau46[[#This Row],[file name]],LEN(Tableau46[[#This Row],[file name]])-SEARCH("@",Tableau46[[#This Row],[file name]])),LEN(RIGHT(Tableau46[[#This Row],[file name]],LEN(Tableau46[[#This Row],[file name]])-SEARCH("@",Tableau46[[#This Row],[file name]])))-SEARCH("/",RIGHT(Tableau46[[#This Row],[file name]],LEN(Tableau46[[#This Row],[file name]])-SEARCH("@",Tableau46[[#This Row],[file name]])))),1) -> #VALUE!

Sheet R2
A1: 6. Expérimentateur 2 : copier et coller les valeurs des intensités totales de fluorescences obtenues dans le fichier raw data lors du traitement des images. Ne pas supprimer les colonnes correspondant aux concentrations non lues.
A3: R2 | B3: Non dopé | O3: avec testo
A4: Noms des groupes | B4: ='Page de garde'!A7 -> Témoin solvant | C4: ='Page de garde'!A9 -> EE2-33.8ng/L | D4: ='Page de garde'!A10 -> EE2-50.6ng/L | E4: ='Page de garde'!A11 -> EE2-76ng/L | F4: ='Page de garde'!A12 -> EE2-114ng/L | G4: ='Page de garde'!A13 -> EE2-170.9ng/L | H4: ='Page de garde'!A14 -> EE2-488ng/L | I4: ='Page de garde'!A15 -> BPA-1mg/L | J4: ='Page de garde'!A16 -> BPA-2mg/L | K4: ='Page de garde'!A17 -> BPA-3mg/L | L4: ='Page de garde'!A18 -> BPA-4mg/L | M4: ='Page de garde'!A19 -> BPA-5mg/L | O4: ='Page de garde'!A36 -> Testo -30µg/L | P4: ='Page de garde'!A37 -> Testo 30µg/L + EE2 -64ng/L | Q4: ='Page de garde'!A38 -> Testo 30µg/L + FAD-10µg/L | R4: ='Page de garde'!A39 -> BPA-1mg/L + Testostérone | S4: ='Page de garde'!A40 -> BPA-2mg/L + Testostérone | T4: ='Page de garde'!A41 -> BPA-3mg/L + Testostérone | U4: ='Page de garde'!A42 -> BPA-4mg/L + Testostérone | V4: ='Page de garde'!A43 -> BPA-5mg/L + Testostérone
A5: Données brutes | B5: 341346 | C5: 49962 | D5: 46002 | E5: 859704 | F5: 2582836 | G5: 5162975 | H5: 9612003 | I5: 89289 | J5: 43930 | K5: 53287 | L5: 113970 | M5: 3350107 | O5: 139897 | P5: 6654239 | Q5: 486365 | R5: 5823564 | S5: 660827 | T5: 2500405 | U5: 2824785 | V5: 2806386
B6: 85962 | C6: 50766 | D6: 198878 | E6: 3492845 | F6: 1023201 | G6: 6215654 | H6: 9051795 | I6: 23573 | J6: 846429 | K6: 123069 | L6: 149786 | M6: 494877 | O6: 217163 | P6: 6248328 | Q6: 55985 | R6: 125320 | S6: 1450280 | T6: 1778733 | U6: 7407366 | V6: 3307501
B7: 58616 | C7: 202708 | D7: 142140 | E7: 2056087 | F7: 1901571 | G7: 5698899 | H7: 8528732 | I7: 164825 | J7: 150643 | K7: 78864 | L7: 920894 | M7: 180068 | O7: 110923 | P7: 8850646 | Q7: 181854 | R7: 305069 | S7: 1932572 | T7: 3375797 | U7: 6969120 | V7: 7404935
B8: 77241 | C8: 32261 | D8: 84557 | E8: 1696581 | F8: 3053297 | G8: 6080086 | H8: 19764273 | I8: 332263 | J8: 14139 | K8: 157159 | L8: 146712 | M8: 1978513 | O8: 120070 | P8: 6435481 | Q8: 35208 | R8: 14010 | S8: 3297498 | T8: 241509 | U8: 4409046 | V8: 4009701
B9: 155715 | C9: 34456 | D9: 86266 | E9: 3760830 | F9: 5746894 | G9: 8378617 | H9: 11624024 | I9: 133770 | J9: 81458 | K9: 113369 | L9: 773415 | M9: 6366489 | O9: 1228892 | P9: 7287235 | Q9: 263194 | R9: 3134116 | S9: 418966 | T9: 2639225 | U9: 4873243 | V9: 2418238
B10: 148514 | C10: 96871 | D10: 43949 | E10: 668770 | F10: 9227517 | G10: 2631251 | H10: 8905748 | I10: 378477 | J10: 4446 | K10: 76702 | L10: 10964 | M10: 48912 | O10: 450016 | P10: 4463677 | Q10: 390024 | R10: 185294 | S10: 952931 | T10: 4588873 | U10: 10642563 | V10: 2258995
B11: 7253 | C11: 54971 | D11: 48908 | E11: 2967954 | F11: 6165683 | G11: 3948149 | H11: 14310533 | I11: 73674 | J11: 34310 | K11: 100845 | L11: 225691 | M11: 295160 | O11: 81341 | P11: 5810268 | Q11: 105669 | R11: 1083991 | S11: 633322 | T11: 1120718 | U11: 4773935 | V11: 2185283
B12: 87950 | C12: 44256 | E12: 357171 | F12: 4988230 | G12: 8204967 | H12: 14371213 | I12: 238119 | J12: 148157 | K12: 73620 | L12: 2698199 | M12: 6944491 | O12: 1335327 | Q12: 262441 | R12: 483685 | S12: 179130 | T12: 895643 | U12: 1070572 | V12: 3656079
O13: 52306
O14: 218248
O15: 449155
O16: 1439472
O17: 26769
O18: 16708
O19: 53538
O20: 6596512
