Workbook

Sheet Page de garde
A1: 1. Expérimentateur 1 : copier et coller le n° de prestation et renseigner la date de réalisation de chaque réplica ainsi que le visa de l'expérimentateur.
A2: R1 | B2: Numéro d'expérience : | E2: Date de réalisation :
A3: R2 | B3: Numéro d'expérience : | E3: Date de réalisation :
A4: R3 | B4: Numéro d'expérience : | E4: Date de réalisation :
A5: 2. Expérimentateur 1 : copier et coller la dilution appliquée et le nom donné pour chaque des échantillons par le client. Conserver la mise en forme de l'exemple en italique. Ne pas remplir la colonne "nom sur graphique".
A6: Nom sur le graphique | B6: Code WF | C6: Concentration | D6: Unité | E6: Nom de l'échantillon donné par le client | F6: Dopage (+Testostérone / + EE2, ….)
A7: =IF(ISBLANK(liste_groupe[[#This Row],[Code WF]])," ",IF(ISBLANK(liste_groupe[[#This Row],[Unité]]),CONCATENATE(liste_groupe[[#This Row],[Nom de l''échantillon donné par le client]],liste_groupe[[#This Row],[Dopage (+Testostérone / + EE2, ….)]]),CONCATENATE(liste_groupe[[#This Row],[Nom de l''échantillon donné par le client]],"-",liste_groupe[[#This Row],[Concentration]],liste_groupe[[#This Row],[Unité]],liste_groupe[[#This Row],[Dopage (+Testostérone / + EE2, ….)]]))) -> Témoin solvant | B7: Témoin | E7: Témoin solvant
A8: =IF(ISBLANK(liste_groupe[[#This Row],[Code WF]])," ",IF(ISBLANK(liste_groupe[[#This Row],[Unité]]),CONCATENATE(liste_groupe[[#This Row],[Nom de l''échantillon donné par le client]],liste_groupe[[#This Row],[Dopage (+Testostérone / + EE2, ….)]]),CONCATENATE(liste_groupe[[#This Row],[Nom de l''échantillon donné par le client]],"-",liste_groupe[[#This Row],[Concentration]],liste_groupe[[#This Row],[Unité]],liste_groupe[[#This Row],[Dopage (+Testostérone / + EE2, ….)]]))) -> EE2-22.5ng/L | B8: Témoin | C8: 22.5 | D8: ng/L | E8: EE2
A9: =IF(ISBLANK(liste_groupe[[#This Row],[Code WF]])," ",IF(ISBLANK(liste_groupe[[#This Row],[Unité]]),CONCATENATE(liste_groupe[[#This Row],[Nom de l''échantillon donné par le client]],liste_groupe[[#This Row],[Dopage (+Testostérone / + EE2, ….)]]),CONCATENATE(liste_groupe[[#This Row],[Nom de l''échantillon donné par le client]],"-",liste_groupe[[#This Row],[Concentration]],liste_groupe[[#This Row],[Unité]],liste_groupe[[#This Row],[Dopage (+Testostérone / + EE2, ….)]]))) -> EE2-33.8ng/L | B9: Témoin | C9: 33.8 | D9: ng/L | E9: EE2
A10: =IF(ISBLANK(liste_groupe[[#This Row],[Code WF]])," ",IF(ISBLANK(liste_groupe[[#This Row],[Unité]]),CONCATENATE(liste_groupe[[#This Row],[Nom de l''échantillon donné par le client]],liste_groupe[[#This Row],[Dopage (+Testostérone / + EE2, ….)]]),CONCATENATE(liste_groupe[[#This Row],[Nom de l''échantillon donné par le client]],"-",liste_groupe[[#This Row],[Concentration]],liste_groupe[[#This Row],[Unité]],liste_groupe[[#This Row],[Dopage (+Testostérone / + EE2, ….)]]))) -> EE2-50.6ng/L | B10: Témoin | C10: 50.6 | D10: ng/L | E10: EE2
A11: =IF(ISBLANK(liste_groupe[[#This Row],[Code WF]])," ",IF(ISBLANK(liste_groupe[[#This Row],[Unité]]),CONCATENATE(liste_groupe[[#This Row],[Nom de l''échantillon donné par le client]],liste_groupe[[#This Row],[Dopage (+Testostérone / + EE2, ….)]]),CONCATENATE(liste_groupe[[#This Row],[Nom de l''échantillon donné par le client]],"-",liste_groupe[[#This Row],[Concentration]],liste_groupe[[#This Row],[Unité]],liste_groupe[[#This Row],[Dopage (+Testostérone / + EE2, ….)]]))) -> EE2-76ng/L | B11: Témoin | C11: 76 | D11: ng/L | E11: EE2
A12: =IF(ISBLANK(liste_groupe[[#This Row],[Code WF]])," ",IF(ISBLANK(liste_groupe[[#This Row],[Unité]]),CONCATENATE(liste_groupe[[#This Row],[Nom de l''échantillon donné par le client]],liste_groupe[[#This Row],[Dopage (+Testostérone / + EE2, ….)]]),CONCATENATE(liste_groupe[[#This Row],[Nom de l''échantillon donné par le client]],"-",liste_groupe[[#This Row],[Concentration]],liste_groupe[[#This Row],[Unité]],liste_groupe[[#This Row],[Dopage (+Testostérone / + EE2, ….)]]))) -> EE2-114ng/L | B12: Témoin | C12: 114 | D12: ng/L | E12: EE2
A13: =IF(ISBLANK(liste_groupe[[#This Row],[Code WF]])," ",IF(ISBLANK(liste_groupe[[#This Row],[Unité]]),CONCATENATE(liste_groupe[[#This Row],[Nom de l''échantillon donné par le client]],liste_groupe[[#This Row],[Dopage (+Testostérone / + EE2, ….)]]),CONCATENATE(liste_groupe[[#This Row],[Nom de l''échantillon donné par le client]],"-",liste_groupe[[#This Row],[Concentration]],liste_groupe[[#This Row],[Unité]],liste_groupe[[#This Row],[Dopage (+Testostérone / + EE2, ….)]]))) -> EE2-170.9ng/L | B13: Témoin | C13: 170.9 | D13: ng/L | E13: EE2
A14: =IF(ISBLANK(liste_groupe[[#This Row],[Code WF]])," ",IF(ISBLANK(liste_groupe[[#This Row],[Unité]]),CONCATENATE(liste_groupe[[#This Row],[Nom de l''échantillon donné par le client]],liste_groupe[[#This Row],[Dopage (+Testostérone / + EE2, ….)]]),CONCATENATE(liste_groupe[[#This Row],[Nom de l''échantillon donné par le client]],"-",liste_groupe[[#This Row],[Concentration]],liste_groupe[[#This Row],[Unité]],liste_groupe[[#This Row],[Dopage (+Testostérone / + EE2, ….)]]))) -> EE2-488ng/L | B14: Témoin | C14: 488 | D14: ng/L | E14: EE2
A15: =IF(ISBLANK(liste_groupe[[#This Row],[Code WF]])," ",IF(ISBLANK(liste_groupe[[#This Row],[Unité]]),CONCATENATE(liste_groupe[[#This Row],[Nom de l''échantillon donné par le client]],liste_groupe[[#This Row],[Dopage (+Testostérone / + EE2, ….)]]),CONCATENATE(liste_groupe[[#This Row],[Nom de l''échantillon donné par le client]],"-",liste_groupe[[#This Row],[Concentration]],liste_groupe[[#This Row],[Unité]],liste_groupe[[#This Row],[Dopage (+Testostérone / + EE2, ….)]]))) -> Prochloraz-0.063mg/L | B15: Test | C15: 0.063 | D15: mg/L | E15: Prochloraz
A16: =IF(ISBLANK(liste_groupe[[#This Row],[Code WF]])," ",IF(ISBLANK(liste_groupe[[#This Row],[Unité]]),CONCATENATE(liste_groupe[[#This Row],[Nom de l''échantillon donné par le client]],liste_groupe[[#This Row],[Dopage (+Testostérone / + EE2, ….)]]),CONCATENATE(liste_groupe[[#This Row],[Nom de l''échantillon donné par le client]],"-",liste_groupe[[#This Row],[Concentration]],liste_groupe[[#This Row],[Unité]],liste_groupe[[#This Row],[Dopage (+Testostérone / + EE2, ….)]]))) -> Prochloraz-0.13mg/L | B16: Test | C16: 0.13 | D16: mg/L | E16: Prochloraz
A17: =IF(ISBLANK(liste_groupe[[#This Row],[Code WF]])," ",IF(ISBLANK(liste_groupe[[#This Row],[Unité]]),CONCATENATE(liste_groupe[[#This Row],[Nom de l''échantillon donné par le client]],liste_groupe[[#This Row],[Dopage (+Testostérone / + EE2, ….)]]),CONCATENATE(liste_groupe[[#This Row],[Nom de l''échantillon donné par le client]],"-",liste_groupe[[#This Row],[Concentration]],liste_groupe[[#This Row],[Unité]],liste_groupe[[#This Row],[Dopage (+Testostérone / + EE2, ….)]]))) -> Prochloraz-0.25mg/L | B17: Test | C17: 0.25 | D17: mg/L | E17: Prochloraz
A18: =IF(ISBLANK(liste_groupe[[#This Row],[Code WF]])," ",IF(ISBLANK(liste_groupe[[#This Row],[Unité]]),CONCATENATE(liste_groupe[[#This Row],[Nom de l''échantillon donné par le client]],liste_groupe[[#This Row],[Dopage (+Testostérone / + EE2, ….)]]),CONCATENATE(liste_groupe[[#This Row],[Nom de l''échantillon donné par le client]],"-",liste_groupe[[#This Row],[Concentration]],liste_groupe[[#This Row],[Unité]],liste_groupe[[#This Row],[Dopage (+Testostérone / + EE2, ….)]]))) -> Prochloraz-0.5mg/L | B18: Test | C18: 0.5 | D18: mg/L | E18: Prochloraz
A19: =IF(ISBLANK(liste_groupe[[#This Row],[Code WF]])," ",IF(ISBLANK(liste_groupe[[#This Row],[Unité]]),CONCATENATE(liste_groupe[[#This Row],[Nom de l''échantillon donné par le client]],liste_groupe[[#This Row],[Dopage (+Testostérone / + EE2, ….)]]),CONCATENATE(liste_groupe[[#This Row],[Nom de l''échantillon donné par le client]],"-",liste_groupe[[#This Row],[Concentration]],liste_groupe[[#This Row],[Unité]],liste_groupe[[#This Row],[Dopage (+Testostérone / + EE2, ….)]]))) -> Prochloraz-1mg/L | B19: Test | C19: 1 | D19: mg/L | E19: Prochloraz
A20: =IF(ISBLANK(liste_groupe[[#This Row],[Code WF]])," ",IF(ISBLANK(liste_groupe[[#This Row],[Unité]]),CONCATENATE(liste_groupe[[#This Row],[Nom de l''échantillon donné par le client]],liste_groupe[[#This Row],[Dopage (+Testostérone / + EE2, ….)]]),CONCATENATE(liste_groupe[[#This Row],[Nom de l''échantillon donné par le client]],"-",liste_groupe[[#This Row],[Concentration]],liste_groupe[[#This Row],[Unité]],liste_groupe[[#This Row],[Dopage (+Testostérone / + EE2, ….)]])))
A21: =IF(ISBLANK(liste_groupe[[#This Row],[Code WF]])," ",IF(ISBLANK(liste_groupe[[#This Row],[Unité]]),CONCATENATE(liste_groupe[[#This Row],[Nom de l''échantillon donné par le client]],liste_groupe[[#This Row],[Dopage (+Testostérone / + EE2, ….)]]),CONCATENATE(liste_groupe[[#This Row],[Nom de l''échantillon donné par le client]],"-",liste_groupe[[#This Row],[Concentration]],liste_groupe[[#This Row],[Unité]],liste_groupe[[#This Row],[Dopage (+Testostérone / + EE2, ….)]])))
A22: =IF(ISBLANK(liste_groupe[[#This Row],[Code WF]])," ",IF(ISBLANK(liste_groupe[[#This Row],[Unité]]),CONCATENATE(liste_groupe[[#This Row],[Nom de l''échantillon donné par le client]],liste_groupe[[#This Row],[Dopage (+Testostérone / + EE2, ….)]]),CONCATENATE(liste_groupe[[#This Row],[Nom de l''échantillon donné par le client]],"-",liste_groupe[[#This Row],[Concentration]],liste_groupe[[#This Row],[Unité]],liste_groupe[[#This Row],[Dopage (+Testostérone / + EE2, ….)]])))
A23: =IF(ISBLANK(liste_groupe[[#This Row],[Code WF]])," ",IF(ISBLANK(liste_groupe[[#This Row],[Unité]]),CONCATENATE(liste_groupe[[#This Row],[Nom de l''échantillon donné par le client]],liste_groupe[[#This Row],[Dopage (+Testostérone / + EE2, ….)]]),CONCATENATE(liste_groupe[[#This Row],[Nom de l''échantillon donné par le client]],"-",liste_groupe[[#This Row],[Concentration]],liste_groupe[[#This Row],[Unité]],liste_groupe[[#This Row],[Dopage (+Testostérone / + EE2, ….)]])))
A24: =IF(ISBLANK(liste_groupe[[#This Row],[Code WF]])," ",IF(ISBLANK(liste_groupe[[#This Row],[Unité]]),CONCATENATE(liste_groupe[[#This Row],[Nom de l''échantillon donné par le client]],liste_groupe[[#This Row],[Dopage (+Testostérone / + EE2, ….)]]),CONCATENATE(liste_groupe[[#This Row],[Nom de l''échantillon donné par le client]],"-",liste_groupe[[#This Row],[Concentration]],liste_groupe[[#This Row],[Unité]],liste_groupe[[#This Row],[Dopage (+Testostérone / + EE2, ….)]])))
A25: =IF(ISBLANK(liste_groupe[[#This Row],[Code WF]])," ",IF(ISBLANK(liste_groupe[[#This Row],[Unité]]),CONCATENATE(liste_groupe[[#This Row],[Nom de l''échantillon donné par le client]],liste_groupe[[#This Row],[Dopage (+Testostérone / + EE2, ….)]]),CONCATENATE(liste_groupe[[#This Row],[Nom de l''échantillon donné par le client]],"-",liste_groupe[[#This Row],[Concentration]],liste_groupe[[#This Row],[Unité]],liste_groupe[[#This Row],[Dopage (+Testostérone / + EE2, ….)]])))
A26: =IF(ISBLANK(liste_groupe[[#This Row],[Code WF]])," ",IF(ISBLANK(liste_groupe[[#This Row],[Unité]]),CONCATENATE(liste_groupe[[#This Row],[Nom de l''échantillon donné par le client]],liste_groupe[[#This Row],[Dopage (+Testostérone / + EE2, ….)]]),CONCATENATE(liste_groupe[[#This Row],[Nom de l''échantillon donné par le client]],"-",liste_groupe[[#This Row],[Concentration]],liste_groupe[[#This Row],[Unité]],liste_groupe[[#This Row],[Dopage (+Testostérone / + EE2, ….)]])))
A27: =IF(ISBLANK(liste_groupe[[#This Row],[Code WF]])," ",IF(ISBLANK(liste_groupe[[#This Row],[Unité]]),CONCATENATE(liste_groupe[[#This Row],[Nom de l''échantillon donné par le client]],liste_groupe[[#This Row],[Dopage (+Testostérone / + EE2, ….)]]),CONCATENATE(liste_groupe[[#This Row],[Nom de l''échantillon donné par le client]],"-",liste_groupe[[#This Row],[Concentration]],liste_groupe[[#This Row],[Unité]],liste_groupe[[#This Row],[Dopage (+Testostérone / + EE2, ….)]])))
A28: =IF(ISBLANK(liste_groupe[[#This Row],[Code WF]])," ",IF(ISBLANK(liste_groupe[[#This Row],[Unité]]),CONCATENATE(liste_groupe[[#This Row],[Nom de l''échantillon donné par le client]],liste_groupe[[#This Row],[Dopage (+Testostérone / + EE2, ….)]]),CONCATENATE(liste_groupe[[#This Row],[Nom de l''échantillon donné par le client]],"-",liste_groupe[[#This Row],[Concentration]],liste_groupe[[#This Row],[Unité]],liste_groupe[[#This Row],[Dopage (+Testostérone / + EE2, ….)]])))
A29: =IF(ISBLANK(liste_groupe[[#This Row],[Code WF]])," ",IF(ISBLANK(liste_groupe[[#This Row],[Unité]]),CONCATENATE(liste_groupe[[#This Row],[Nom de l''échantillon donné par le client]],liste_groupe[[#This Row],[Dopage (+Testostérone / + EE2, ….)]]),CONCATENATE(liste_groupe[[#This Row],[Nom de l''échantillon donné par le client]],"-",liste_groupe[[#This Row],[Concentration]],liste_groupe[[#This Row],[Unité]],liste_groupe[[#This Row],[Dopage (+Testostérone / + EE2, ….)]])))
A30: =IF(ISBLANK(liste_groupe[[#This Row],[Code WF]])," ",IF(ISBLANK(liste_groupe[[#This Row],[Unité]]),CONCATENATE(liste_groupe[[#This Row],[Nom de l''échantillon donné par le client]],liste_groupe[[#This Row],[Dopage (+Testostérone / + EE2, ….)]]),CONCATENATE(liste_groupe[[#This Row],[Nom de l''échantillon donné par le client]],"-",liste_groupe[[#This Row],[Concentration]],liste_groupe[[#This Row],[Unité]],liste_groupe[[#This Row],[Dopage (+Testostérone / + EE2, ….)]])))
A31: =IF(ISBLANK(liste_groupe[[#This Row],[Code WF]])," ",IF(ISBLANK(liste_groupe[[#This Row],[Unité]]),CONCATENATE(liste_groupe[[#This Row],[Nom de l''échantillon donné par le client]],liste_groupe[[#This Row],[Dopage (+Testostérone / + EE2, ….)]]),CONCATENATE(liste_groupe[[#This Row],[Nom de l''échantillon donné par le client]],"-",liste_groupe[[#This Row],[Concentration]],liste_groupe[[#This Row],[Unité]],liste_groupe[[#This Row],[Dopage (+Testostérone / + EE2, ….)]])))
... A35: =IF(ISBLANK(liste_groupe[[#This Row],[Code WF]])," ",IF(ISBLANK(liste_groupe[[#This Row],[Unité]]),CONCATENATE(liste_groupe[[#This Row],[Nom de l''échantillon donné par le client]],liste_groupe[[#This Row],[Dopage (+Testostérone / + EE2, ….)]]),CONCATENATE(liste_groupe[[#This Row],[Nom de l''échantillon donné par le client]],"-",liste_groupe[[#This Row],[Concentration]],liste_groupe[[#This Row],[Unité]],liste_groupe[[#This Row],[Dopage (+Testostérone / + EE2, ….)]])))
A36: =IF(ISBLANK(liste_groupe[[#This Row],[Code WF]])," ",IF(ISBLANK(liste_groupe[[#This Row],[Unité]]),CONCATENATE(liste_groupe[[#This Row],[Nom de l''échantillon donné par le client]],liste_groupe[[#This Row],[Dopage (+Testostérone / + EE2, ….)]]),CONCATENATE(liste_groupe[[#This Row],[Nom de l''échantillon donné par le client]],"-",liste_groupe[[#This Row],[Concentration]],liste_groupe[[#This Row],[Unité]],liste_groupe[[#This Row],[Dopage (+Testostérone / + EE2, ….)]]))) -> Testo -30µg/L | B36: Témoin | C36: 30 | D36: µg/L | E36: Testo
A37: =IF(ISBLANK(liste_groupe[[#This Row],[Code WF]])," ",IF(ISBLANK(liste_groupe[[#This Row],[Unité]]),CONCATENATE(liste_groupe[[#This Row],[Nom de l''échantillon donné par le client]],liste_groupe[[#This Row],[Dopage (+Testostérone / + EE2, ….)]]),CONCATENATE(liste_groupe[[#This Row],[Nom de l''échantillon donné par le client]],"-",liste_groupe[[#This Row],[Concentration]],liste_groupe[[#This Row],[Unité]],liste_groupe[[#This Row],[Dopage (+Testostérone / + EE2, ….)]]))) -> Testo 30µg/L + EE2 -64ng/L | B37: Témoin | C37: 64 | D37: ng/L | E37: Testo 30µg/L + EE2
A38: =IF(ISBLANK(liste_groupe[[#This Row],[Code WF]])," ",IF(ISBLANK(liste_groupe[[#This Row],[Unité]]),CONCATENATE(liste_groupe[[#This Row],[Nom de l''échantillon donné par le client]],liste_groupe[[#This Row],[Dopage (+Testostérone / + EE2, ….)]]),CONCATENATE(liste_groupe[[#This Row],[Nom de l''échantillon donné par le client]],"-",liste_groupe[[#This Row],[Concentration]],liste_groupe[[#This Row],[Unité]],liste_groupe[[#This Row],[Dopage (+Testostérone / + EE2, ….)]]))) -> Testo 30µg/L + FAD-10µg/L | B38: Témoin | C38: 10 | D38: µg/L | E38: Testo 30µg/L + FAD
A39: =IF(ISBLANK(liste_groupe[[#This Row],[Code WF]])," ",IF(ISBLANK(liste_groupe[[#This Row],[Unité]]),CONCATENATE(liste_groupe[[#This Row],[Nom de l''échantillon donné par le client]],liste_groupe[[#This Row],[Dopage (+Testostérone / + EE2, ….)]]),CONCATENATE(liste_groupe[[#This Row],[Nom de l''échantillon donné par le client]],"-",liste_groupe[[#This Row],[Concentration]],liste_groupe[[#This Row],[Unité]],liste_groupe[[#This Row],[Dopage (+Testostérone / + EE2, ….)]]))) -> Prochloraz-0.063mg/L + Testostérone | B39: =B15 -> Test | C39: =C15 -> 0.063 | D39: =D15 -> mg/L | E39: =E15 -> Prochloraz | F39: + Testostérone
A40: =IF(ISBLANK(liste_groupe[[#This Row],[Code WF]])," ",IF(ISBLANK(liste_groupe[[#This Row],[Unité]]),CONCATENATE(liste_groupe[[#This Row],[Nom de l''échantillon donné par le client]],liste_groupe[[#This Row],[Dopage (+Testostérone / + EE2, ….)]]),CONCATENATE(liste_groupe[[#This Row],[Nom de l''échantillon donné par le client]],"-",liste_groupe[[#This Row],[Concentration]],liste_groupe[[#This Row],[Unité]],liste_groupe[[#This Row],[Dopage (+Testostérone / + EE2, ….)]]))) -> Prochloraz-0.13mg/L + Testostérone | B40: =B16 -> Test | C40: =C16 -> 0.13 | D40: =D16 -> mg/L | E40: =E16 -> Prochloraz | F40: + Testostérone
A41: =IF(ISBLANK(liste_groupe[[#This Row],[Code WF]])," ",IF(ISBLANK(liste_groupe[[#This Row],[Unité]]),CONCATENATE(liste_groupe[[#This Row],[Nom de l''échantillon donné par le client]],liste_groupe[[#This Row],[Dopage (+Testostérone / + EE2, ….)]]),CONCATENATE(liste_groupe[[#This Row],[Nom de l''échantillon donné par le client]],"-",liste_groupe[[#This Row],[Concentration]],liste_groupe[[#This Row],[Unité]],liste_groupe[[#This Row],[Dopage (+Testostérone / + EE2, ….)]]))) -> Prochloraz-0.25mg/L + Testostérone | B41: =B17 -> Test | C41: =C17 -> 0.25 | D41: =D17 -> mg/L | E41: =E17 -> Prochloraz | F41: + Testostérone
A42: =IF(ISBLANK(liste_groupe[[#This Row],[Code WF]])," ",IF(ISBLANK(liste_groupe[[#This Row],[Unité]]),CONCATENATE(liste_groupe[[#This Row],[Nom de l''échantillon donné par le client]],liste_groupe[[#This Row],[Dopage (+Testostérone / + EE2, ….)]]),CONCATENATE(liste_groupe[[#This Row],[Nom de l''échantillon donné par le client]],"-",liste_groupe[[#This Row],[Concentration]],liste_groupe[[#This Row],[Unité]],liste_groupe[[#This Row],[Dopage (+Testostérone / + EE2, ….)]]))) -> Prochloraz-0.5mg/L + Testostérone | B42: =B18 -> Test | C42: =C18 -> 0.5 | D42: =D18 -> mg/L | E42: =E18 -> Prochloraz | F42: + Testostérone
A43: =IF(ISBLANK(liste_groupe[[#This Row],[Code WF]])," ",IF(ISBLANK(liste_groupe[[#This Row],[Unité]]),CONCATENATE(liste_groupe[[#This Row],[Nom de l''échantillon donné par le client]],liste_groupe[[#This Row],[Dopage (+Testostérone / + EE2, ….)]]),CONCATENATE(liste_groupe[[#This Row],[Nom de l''échantillon donné par le client]],"-",liste_groupe[[#This Row],[Concentration]],liste_groupe[[#This Row],[Unité]],liste_groupe[[#This Row],[Dopage (+Testostérone / + EE2, ….)]]))) -> Prochloraz-1mg/L + Testostérone | B43: =B19 -> Test | C43: =C19 -> 1 | D43: =D19 -> mg/L | E43: =E19 -> Prochloraz | F43: + Testostérone
...

Sheet Feuil1
A1: Nom groupe | B1: N° de valeur | C1: file name | D1: total area | E1: mean intensity | G1: total fluorescence | I1: nbre de larves
A2: 01 EE2 0 | B2: A | C2: C:\Users\Olympus\Desktop\20190122\plaque1/@01 EE2 0/A1_1.tif | D2: 4931.616 | E2: 73.0526 | G2: 360268
A3: 01 EE2 0 | B3: A | C3: C:\Users\Olympus\Desktop\20190122\plaque1/@01 EE2 0/A1_2.tif | D3: 5234.4345 | E3: 71.1281 | G3: 372315
A4: 01 EE2 0 | B4: A | C4: C:\Users\Olympus\Desktop\20190122\plaque1/@01 EE2 0/A1_3.tif | D4: 3547.3027 | E4: 66.9878 | G4: 237626
A5: 01 EE2 0 | B5: A | C5: C:\Users\Olympus\Desktop\20190122\plaque3/@01 EE2 0/A1_3.tif | D5: 21456.8555 | E5: 67.0655 | G5: 1439015
A6: 01 EE2 0 | B6: A | C6: C:\Users\Olympus\Desktop\20190122\plaque3/@01 EE2 0/A1_2.tif | D6: 21586.6348 | E6: 66.4108 | G6: 1433586
A7: 01 EE2 0 | B7: A | C7: C:\Users\Olympus\Desktop\20190122\plaque3/@01 EE2 0/A1_1.tif | D7: 15984.4921 | E7: 69.7767 | G7: 1115346

Sheet Raw data R1
A1: Nom groupe | B1: N° de valeur | C1: file name | D1: total area | E1: mean intensity | G1: total fluorescence | I1: nbre de larves | L1: (Tous)
A2: =IFERROR(LEFT(RIGHT(C2,LEN(C2)-SEARCH("@",C2)),SEARCH("/",RIGHT(C2,LEN(C2)-SEARCH("@",C2)-1))),"") | B2: =LEFT(RIGHT(RIGHT(Tableau4[[#This Row],[file name]],LEN(Tableau4[[#This Row],[file name]])-SEARCH("@",Tableau4[[#This Row],[file name]])),LEN(RIGHT(Tableau4[[#This Row],[file name]],LEN(Tableau4[[#This Row],[file name]])-SEARCH("@",Tableau4[[#This Row],[file name]])))-SEARCH("/",RIGHT(Tableau4[[#This Row],[file name]],LEN(Tableau4[[#This Row],[file name]])-SEARCH("@",Tableau4[[#This Row],[file name]])))),1) -> #VALUE! | K2: Filtre lignes : Enlever (vide) et Néant | L2: Filtre colonnes : Enlever (vide) et " "
A3: =IFERROR(LEFT(RIGHT(C3,LEN(C3)-SEARCH("@",C3)),SEARCH("/",RIGHT(C3,LEN(C3)-SEARCH("@",C3)-1))),"") | B3: =LEFT(RIGHT(RIGHT(Tableau4[[#This Row],[file name]],LEN(Tableau4[[#This Row],[file name]])-SEARCH("@",Tableau4[[#This Row],[file name]])),LEN(RIGHT(Tableau4[[#This Row],[file name]],LEN(Tableau4[[#This Row],[file name]])-SEARCH("@",Tableau4[[#This Row],[file name]])))-SEARCH("/",RIGHT(Tableau4[[#This Row],[file name]],LEN(Tableau4[[#This Row],[file name]])-SEARCH("@",Tableau4[[#This Row],[file name]])))),1) -> #VALUE! | K3: Moyenne de total fluorescence | L3: Étiquettes de colonnes
A4: =IFERROR(LEFT(RIGHT(C4,LEN(C4)-SEARCH("@",C4)),SEARCH("/",RIGHT(C4,LEN(C4)-SEARCH("@",C4)-1))),"") | B4: =LEFT(RIGHT(RIGHT(Tableau4[[#This Row],[file name]],LEN(Tableau4[[#This Row],[file name]])-SEARCH("@",Tableau4[[#This Row],[file name]])),LEN(RIGHT(Tableau4[[#This Row],[file name]],LEN(Tableau4[[#This Row],[file name]])-SEARCH("@",Tableau4[[#This Row],[file name]])))-SEARCH("/",RIGHT(Tableau4[[#This Row],[file name]],LEN(Tableau4[[#This Row],[file name]])-SEARCH("@",Tableau4[[#This Row],[file name]])))),1) -> #VALUE! | K4: Étiquettes de lignes
A5: =IFERROR(LEFT(RIGHT(C5,LEN(C5)-SEARCH("@",C5)),SEARCH("/",RIGHT(C5,LEN(C5)-SEARCH("@",C5)-1))),"") | B5: =LEFT(RIGHT(RIGHT(Tableau4[[#This Row],[file name]],LEN(Tableau4[[#This Row],[file name]])-SEARCH("@",Tableau4[[#This Row],[file name]])),LEN(RIGHT(Tableau4[[#This Row],[file name]],LEN(Tableau4[[#This Row],[file name]])-SEARCH("@",Tableau4[[#This Row],[file name]])))-SEARCH("/",RIGHT(Tableau4[[#This Row],[file name]],LEN(Tableau4[[#This Row],[file name]])-SEARCH("@",Tableau4[[#This Row],[file name]])))),1) -> #VALUE! | K5: #VALEUR!
A6: =IFERROR(LEFT(RIGHT(C6,LEN(C6)-SEARCH("@",C6)),SEARCH("/",RIGHT(C6,LEN(C6)-SEARCH("@",C6)-1))),"") | B6: =LEFT(RIGHT(RIGHT(Tableau4[[#This Row],[file name]],LEN(Tableau4[[#This Row],[file name]])-SEARCH("@",Tableau4[[#This Row],[file name]])),LEN(RIGHT(Tableau4[[#This Row],[file name]],LEN(Tableau4[[#This Row],[file name]])-SEARCH("@",Tableau4[[#This Row],[file name]])))-SEARCH("/",RIGHT(Tableau4[[#This Row],[file name]],LEN(Tableau4[[#This Row],[file name]])-SEARCH("@",Tableau4[[#This Row],[file name]])))),1) -> #VALUE!
A7: =IFERROR(LEFT(RIGHT(C7,LEN(C7)-SEARCH("@",C7)),SEARCH("/",RIGHT(C7,LEN(C7)-SEARCH("@",C7)-1))),"") | B7: =LEFT(RIGHT(RIGHT(Tableau4[[#This Row],[file name]],LEN(Tableau4[[#This Row],[file name]])-SEARCH("@",Tableau4[[#This Row],[file name]])),LEN(RIGHT(Tableau4[[#This Row],[file name]],LEN(Tableau4[[#This Row],[file name]])-SEARCH("@",Tableau4[[#This Row],[file name]])))-SEARCH("/",RIGHT(Tableau4[[#This Row],[file name]],LEN(Tableau4[[#This Row],[file name]])-SEARCH("@",Tableau4[[#This Row],[file name]])))),1) -> #VALUE!
A8: =IFERROR(LEFT(RIGHT(C8,LEN(C8)-SEARCH("@",C8)),SEARCH("/",RIGHT(C8,LEN(C8)-SEARCH("@",C8)-1))),"") | B8: =LEFT(RIGHT(RIGHT(Tableau4[[#This Row],[file name]],LEN(Tableau4[[#This Row],[file name]])-SEARCH("@",Tableau4[[#This Row],[file name]])),LEN(RIGHT(Tableau4[[#This Row],[file name]],LEN(Tableau4[[#This Row],[file name]])-SEARCH("@",Tableau4[[#This Row],[file name]])))-SEARCH("/",RIGHT(Tableau4[[#This Row],[file name]],LEN(Tableau4[[#This Row],[file name]])-SEARCH("@",Tableau4[[#This Row],[file name]])))),1) -> #VALUE!
A9: =IFERROR(LEFT(RIGHT(C9,LEN(C9)-SEARCH("@",C9)),SEARCH("/",RIGHT(C9,LEN(C9)-SEARCH("@",C9)-1))),"") | B9: =LEFT(RIGHT(RIGHT(Tableau4[[#This Row],[file name]],LEN(Tableau4[[#This Row],[file name]])-SEARCH("@",Tableau4[[#This Row],[file name]])),LEN(RIGHT(Tableau4[[#This Row],[file name]],LEN(Tableau4[[#This Row],[file name]])-SEARCH("@",Tableau4[[#This Row],[file name]])))-SEARCH("/",RIGHT(Tableau4[[#This Row],[file name]],LEN(Tableau4[[#This Row],[file name]])-SEARCH("@",Tableau4[[#This Row],[file name]])))),1) -> #VALUE!
A10: =IFERROR(LEFT(RIGHT(C10,LEN(C10)-SEARCH("@",C10)),SEARCH("/",RIGHT(C10,LEN(C10)-SEARCH("@",C10)-1))),"") | B10: =LEFT(RIGHT(RIGHT(Tableau4[[#This Row],[file name]],LEN(Tableau4[[#This Row],[file name]])-SEARCH("@",Tableau4[[#This Row],[file name]])),LEN(RIGHT(Tableau4[[#This Row],[file name]],LEN(Tableau4[[#This Row],[file name]])-SEARCH("@",Tableau4[[#This Row],[file name]])))-SEARCH("/",RIGHT(Tableau4[[#This Row],[file name]],LEN(Tableau4[[#This Row],[file name]])-SEARCH("@",Tableau4[[#This Row],[file name]])))),1) -> #VALUE!
A11: =IFERROR(LEFT(RIGHT(C11,LEN(C11)-SEARCH("@",C11)),SEARCH("/",RIGHT(C11,LEN(C11)-SEARCH("@",C11)-1))),"") | B11: =LEFT(RIGHT(RIGHT(Tableau4[[#This Row],[file name]],LEN(Tableau4[[#This Row],[file name]])-SEARCH("@",Tableau4[[#This Row],[file name]])),LEN(RIGHT(Tableau4[[#This Row],[file name]],LEN(Tableau4[[#This Row],[file name]])-SEARCH("@",Tableau4[[#This Row],[file name]])))-SEARCH("/",RIGHT(Tableau4[[#This Row],[file name]],LEN(Tableau4[[#This Row],[file name]])-SEARCH("@",Tableau4[[#This Row],[file name]])))),1) -> #VALUE!
A12: =IFERROR(LEFT(RIGHT(C12,LEN(C12)-SEARCH("@",C12)),SEARCH("/",RIGHT(C12,LEN(C12)-SEARCH("@",C12)-1))),"") | B12: =LEFT(RIGHT(RIGHT(Tableau4[[#This Row],[file name]],LEN(Tableau4[[#This Row],[file name]])-SEARCH("@",Tableau4[[#This Row],[file name]])),LEN(RIGHT(Tableau4[[#This Row],[file name]],LEN(Tableau4[[#This Row],[file name]])-SEARCH("@",Tableau4[[#This Row],[file name]])))-SEARCH("/",RIGHT(Tableau4[[#This Row],[file name]],LEN(Tableau4[[#This Row],[file name]])-SEARCH("@",Tableau4[[#This Row],[file name]])))),1) -> #VALUE!
A13: =IFERROR(LEFT(RIGHT(C13,LEN(C13)-SEARCH("@",C13)),SEARCH("/",RIGHT(C13,LEN(C13)-SEARCH("@",C13)-1))),"") | B13: =LEFT(RIGHT(RIGHT(Tableau4[[#This Row],[file name]],LEN(Tableau4[[#This Row],[file name]])-SEARCH("@",Tableau4[[#This Row],[file name]])),LEN(RIGHT(Tableau4[[#This Row],[file name]],LEN(Tableau4[[#This Row],[file name]])-SEARCH("@",Tableau4[[#This Row],[file name]])))-SEARCH("/",RIGHT(Tableau4[[#This Row],[file name]],LEN(Tableau4[[#This Row],[file name]])-SEARCH("@",Tableau4[[#This Row],[file name]])))),1) -> #VALUE!
A14: =IFERROR(LEFT(RIGHT(C14,LEN(C14)-SEARCH("@",C14)),SEARCH("/",RIGHT(C14,LEN(C14)-SEARCH("@",C14)-1))),"") | B14: =LEFT(RIGHT(RIGHT(Tableau4[[#This Row],[file name]],LEN(Tableau4[[#This Row],[file name]])-SEARCH("@",Tableau4[[#This Row],[file name]])),LEN(RIGHT(Tableau4[[#This Row],[file name]],LEN(Tableau4[[#This Row],[file name]])-SEARCH("@",Tableau4[[#This Row],[file name]])))-SEARCH("/",RIGHT(Tableau4[[#This Row],[file name]],LEN(Tableau4[[#This Row],[file name]])-SEARCH("@",Tableau4[[#This Row],[file name]])))),1) -> #VALUE!
A15: =IFERROR(LEFT(RIGHT(C15,LEN(C15)-SEARCH("@",C15)),SEARCH("/",RIGHT(C15,LEN(C15)-SEARCH("@",C15)-1))),"") | B15: =LEFT(RIGHT(RIGHT(Tableau4[[#This Row],[file name]],LEN(Tableau4[[#This Row],[file name]])-SEARCH("@",Tableau4[[#This Row],[file name]])),LEN(RIGHT(Tableau4[[#This Row],[file name]],LEN(Tableau4[[#This Row],[file name]])-SEARCH("@",Tableau4[[#This Row],[file name]])))-SEARCH("/",RIGHT(Tableau4[[#This Row],[file name]],LEN(Tableau4[[#This Row],[file name]])-SEARCH("@",Tableau4[[#This Row],[file name]])))),1) -> #VALUE!
A16: =IFERROR(LEFT(RIGHT(C16,LEN(C16)-SEARCH("@",C16)),SEARCH("/",RIGHT(C16,LEN(C16)-SEARCH("@",C16)-1))),"") | B16: =LEFT(RIGHT(RIGHT(Tableau4[[#This Row],[file name]],LEN(Tableau4[[#This Row],[file name]])-SEARCH("@",Tableau4[[#This Row],[file name]])),LEN(RIGHT(Tableau4[[#This Row],[file name]],LEN(Tableau4[[#This Row],[file name]])-SEARCH("@",Tableau4[[#This Row],[file name]])))-SEARCH("/",RIGHT(Tableau4[[#This Row],[file name]],LEN(Tableau4[[#This Row],[file name]])-SEARCH("@",Tableau4[[#This Row],[file name]])))),1) -> #VALUE!
A17: =IFERROR(LEFT(RIGHT(C17,LEN(C17)-SEARCH("@",C17)),SEARCH("/",RIGHT(C17,LEN(C17)-SEARCH("@",C17)-1))),"") | B17: =LEFT(RIGHT(RIGHT(Tableau4[[#This Row],[file name]],LEN(Tableau4[[#This Row],[file name]])-SEARCH("@",Tableau4[[#This Row],[file name]])),LEN(RIGHT(Tableau4[[#This Row],[file name]],LEN(Tableau4[[#This Row],[file name]])-SEARCH("@",Tableau4[[#This Row],[file name]])))-SEARCH("/",RIGHT(Tableau4[[#This Row],[file name]],LEN(Tableau4[[#This Row],[file name]])-SEARCH("@",Tableau4[[#This Row],[file name]])))),1) -> #VALUE!
... A1557: =IFERROR(LEFT(RIGHT(C1557,LEN(C1557)-SEARCH("@",C1557)),SEARCH("/",RIGHT(C1557,LEN(C1557)-SEARCH("@",C1557)-1))),"") | B1557: =LEFT(RIGHT(RIGHT(Tableau4[[#This Row],[file name]],LEN(Tableau4[[#This Row],[file name]])-SEARCH("@",Tableau4[[#This Row],[file name]])),LEN(RIGHT(Tableau4[[#This Row],[file name]],LEN(Tableau4[[#This Row],[file name]])-SEARCH("@",Tableau4[[#This Row],[file name]])))-SEARCH("/",RIGHT(Tableau4[[#This Row],[file name]],LEN(Tableau4[[#This Row],[file name]])-SEARCH("@",Tableau4[[#This Row],[file name]])))),1) -> #VALUE!

Sheet R1
A1: 3. Expérimentateur 1 : copier et coller les valeurs des intensités totales de fluorescences obtenues dans le fichier raw data lors du traitement des images.
A3: R1 | B3: Non dopé | O3: avec testo
A4: Noms des groupes | B4: ='Page de garde'!A7 -> Témoin solvant | C4: ='Page de garde'!A9 -> EE2-33.8ng/L | D4: ='Page de garde'!A10 -> EE2-50.6ng/L | E4: ='Page de garde'!A11 -> EE2-76ng/L | F4: ='Page de garde'!A12 -> EE2-114ng/L | G4: ='Page de garde'!A13 -> EE2-170.9ng/L | H4: ='Page de garde'!A14 -> EE2-488ng/L | I4: ='Page de garde'!A15 -> Prochloraz-0.063mg/L | J4: ='Page de garde'!A16 -> Prochloraz-0.13mg/L | K4: ='Page de garde'!A17 -> Prochloraz-0.25mg/L | L4: ='Page de garde'!A18 -> Prochloraz-0.5mg/L | M4: ='Page de garde'!A19 -> Prochloraz-1mg/L | O4: ='Page de garde'!A36 -> Testo -30µg/L | P4: ='Page de garde'!A37 -> Testo 30µg/L + EE2 -64ng/L | Q4: ='Page de garde'!A38 -> Testo 30µg/L + FAD-10µg/L | R4: ='Page de garde'!A39 -> Prochloraz-0.063mg/L + Testostérone | S4: ='Page de garde'!A40 -> Prochloraz-0.13mg/L + Testostérone | T4: ='Page de garde'!A41 -> Prochloraz-0.25mg/L + Testostérone | U4: ='Page de garde'!A42 -> Prochloraz-0.5mg/L + Testostérone | V4: ='Page de garde'!A43 -> Prochloraz-1mg/L + Testostérone
A5: Données brutes | B5: 504 | C5: 8644 | D5: 50874 | E5: 1767694 | F5: 4433384 | G5: 6312574 | H5: 5058215 | I5: 104521 | J5: 95335 | K5: 14697 | L5: 154980 | M5: 191824 | O5: 5617947 | P5: 9118163 | Q5: 109228 | R5: 33216 | S5: 106690 | T5: 14254 | U5: 41337 | V5: 2186
B6: 62050 | C6: 245025 | D6: 19952 | E6: 2079692 | F6: 3192578 | G6: 4338734 | H6: 11154097 | I6: 14686 | J6: 39078 | K6: 27894 | L6: 38475 | M6: 169084 | O6: 322836 | P6: 4992926 | Q6: 30755 | R6: 166012 | S6: 1403295 | T6: 20573 | U6: 126129 | V6: 37307
B7: 7437 | C7: 1063913 | D7: 2497975 | E7: 3024330 | F7: 4218063 | G7: 6230528 | H7: 4981766 | I7: 197474 | J7: 24789 | K7: 303617 | L7: 57311 | M7: 78588 | O7: 107235 | P7: 5400444 | Q7: 40538 | R7: 250543 | S7: 495557 | T7: 458226 | U7: 40023 | V7: 29656
B8: 9104 | C8: 84919 | D8: 153518 | E8: 227901 | F8: 3836567 | G8: 7925413 | H8: 8796791 | I8: 31902 | J8: 48100 | K8: 136702 | L8: 231817 | M8: 163780 | O8: 1711306 | P8: 7183840 | Q8: 5613 | R8: 75042 | S8: 5651 | T8: 252495 | U8: 212071 | V8: 2204
B9: 147320 | C9: 794685 | D9: 2397417 | E9: 741029 | F9: 4667684 | G9: 10983199 | H9: 4776605 | I9: 5599 | J9: 24650 | K9: 28533 | L9: 732107 | M9: 35420 | O9: 94720 | P9: 2600841 | Q9: 1378 | R9: 81619 | S9: 37045 | T9: 1061569 | U9: 14604 | V9: 32099
B10: 68496 | C10: 221936 | D10: 394828 | E10: 840778 | F10: 6373155 | G10: 4355737 | H10: 8354584 | I10: 51439 | J10: 182 | K10: 55132 | L10: 82915 | M10: 143064 | O10: 109070 | P10: 4391312 | Q10: 32381 | R10: 4310762 | S10: 108488 | T10: 1202404 | U10: 4324 | V10: 173599
B11: 3288 | C11: 39545 | D11: 612539 | E11: 2397266 | F11: 2089369 | G11: 11523934 | H11: 7739948 | I11: 100872 | J11: 58586 | K11: 60891 | L11: 18242 | M11: 83298 | O11: 778570 | P11: 6251883 | Q11: 246824 | R11: 1700645 | S11: 32497 | T11: 1596164 | U11: 2018 | V11: 2059175
B12: 47121 | C12: 87806 | D12: 169961 | E12: 50356 | F12: 6637201 | H12: 6023951 | J12: 56758 | K12: 31803 | L12: 88741 | M12: 202435 | O12: 1662317 | P12: 6556297 | Q12: 21215 | R12: 191074 | S12: 361651 | T12: 142882 | U12: 534030
O13: 1305817
O14: 1570350
O15: 635804
O16: 125671
O17: 509366
O18: 3094321
O19: 603071
O20: 1202713
A22: =A4 -> Noms des groupes | B22: =B4 -> Témoin solvant | C22: =C4 -> EE2-33.8ng/L | D22: =D4 -> EE2-50.6ng/L | E22: =E4 -> EE2-76ng/L | F22: =F4 -> EE2-114ng/L | G22: =G4 -> EE2-170.9ng/L | H22: =H4 -> EE2-488ng/L | ... M22: =M4 -> Prochloraz-1mg/L | N22: Nom des groupes | O22: =O4 -> Testo -30µg/L | P22: =P4 -> Testo 30µg/L + EE2 -64ng/L | Q22: =Q4 -> Testo 30µg/L + FAD-10µg/L | R22: =R4 -> Prochloraz-0.063mg/L + Testostérone | S22: =S4 -> Prochloraz-0.13mg/L + Testostérone | T22: =T4 -> Prochloraz-0.25mg/L + Testostérone | U22: =U4 -> Prochloraz-0.5mg/L + Testostérone | V22: =V4 -> Prochloraz-1mg/L + Testostérone
A23: mean | B23: =AVERAGE(B5:B20) -> 43165 | C23: =AVERAGE(C5:C20) -> 318309.12 | D23: =AVERAGE(D5:D20) -> 787133 | E23: =AVERAGE(E5:E20) -> 1391130.8 | F23: =AVERAGE(F5:F20) -> 4431000.1 | G23: =AVERAGE(G5:G20) -> 7381445.6 | H23: =AVERAGE(H5:H20) -> 7110744.6 | I23: =AVERAGE(I5:I20) -> 72356.143 | ... M23: =AVERAGE(M5:M20) -> 133436.62 | N23: mean | O23: =AVERAGE(O5:O20) -> 1215694.6 | P23: =AVERAGE(P5:P20) -> 5811963.2 | Q23: =AVERAGE(Q5:Q20) -> 60991.5 | R23: =AVERAGE(R5:R20) -> 851114.12 | S23: =AVERAGE(S5:S20) -> 318859.25 | T23: =AVERAGE(T5:T20) -> 593570.88 | U23: =AVERAGE(U5:U20) -> 121817 | V23: =AVERAGE(V5:V20) -> 333746.57
A24: SD | B24: =STDEV(B5:B20) -> 50297.677 | C24: =STDEV(C5:C20) -> 392559.74 | D24: =STDEV(D5:D20) -> 1043167.9 | E24: =STDEV(E5:E20) -> 1080467.2 | F24: =STDEV(F5:F20) -> 1517089.9 | G24: =STDEV(G5:G20) -> 2924290.3 | H24: =STDEV(H5:H20) -> 2283770.1 | I24: =STDEV(I5:I20) -> 67526.089 | ... M24: =STDEV(M5:M20) -> 60454.842 | N24: SD | O24: =STDEV(O5:O20) -> 1427936.2 | P24: =STDEV(P5:P20) -> 1954127.2 | Q24: =STDEV(Q5:Q20) -> 82127.382 | R24: =STDEV(R5:R20) -> 1503326.7 | S24: =STDEV(S5:S20) -> 471751.75 | T24: =STDEV(T5:T20) -> 609050.67 | U24: =STDEV(U5:U20) -> 181620.58 | V24: =STDEV(V5:V20) -> 763101.36
B26: Non dopé | O26: avec testo
A27: Noms des groupes | B27: =B4 -> Témoin solvant | C27: =C4 -> EE2-33.8ng/L | D27: =D4 -> EE2-50.6ng/L | E27: =E4 -> EE2-76ng/L | F27: =F4 -> EE2-114ng/L | G27: =G4 -> EE2-170.9ng/L | H27: =H4 -> EE2-488ng/L | I27: =I4 -> Prochloraz-0.063mg/L | ... M27: =M4 -> Prochloraz-1mg/L | O27: =O4 -> Testo -30µg/L | P27: =P4 -> Testo 30µg/L + EE2 -64ng/L | Q27: =Q4 -> Testo 30µg/L + FAD-10µg/L | R27: =R4 -> Prochloraz-0.063mg/L + Testostérone | S27: =S4 -> Prochloraz-0.13mg/L + Testostérone | T27: =T4 -> Prochloraz-0.25mg/L + Testostérone | U27: =U4 -> Prochloraz-0.5mg/L + Testostérone | V27: =V4 -> Prochloraz-1mg/L + Testostérone
A28: Données normalisées sur la moyenne du groupe "Testo" | B28: =IF(B5="","",(B5/$O$23)) -> 0.0004145778 | C28: =IF(C5="","",(C5/$O$23)) -> 0.0071103383 | D28: =IF(D5="","",(D5/$O$23)) -> 0.04184768 | E28: =IF(E5="","",(E5/$O$23)) -> 1.4540609 | F28: =IF(F5="","",(F5/$O$23)) -> 3.6467908 | G28: =IF(G5="","",(G5/$O$23)) -> 5.1925655 | H28: =IF(H5="","",(H5/$O$23)) -> 4.1607612 | I28: =IF(I5="","",(I5/$O$23)) -> 0.085976361 | ... M28: =IF(M5="","",(M5/$O$23)) -> 0.15778963 | O28: =IF(O5="","",(O5/$O$23)) -> 4.6211827 | P28: =IF(P5="","",(P5/$O$23)) -> 7.5003729 | Q28: =IF(Q5="","",(Q5/$O$23)) -> 0.089848222 | R28: =IF(R5="","",(R5/$O$23)) -> 0.027322651 | S28: =IF(S5="","",(S5/$O$23)) -> 0.087760526 | T28: =IF(T5="","",(T5/$O$23)) -> 0.011724984 | U28: =IF(U5="","",(U5/$O$23)) -> 0.034002783 | V28: =IF(V5="","",(V5/$O$23)) -> 0.0017981489
B29: =IF(B6="","",(B6/$O$23)) -> 0.051040778 | C29: =IF(C6="","",(C6/$O$23)) -> 0.20155144 | D29: =IF(D6="","",(D6/$O$23)) -> 0.016412016 | E29: =IF(E6="","",(E6/$O$23)) -> 1.7107026 | F29: =IF(F6="","",(F6/$O$23)) -> 2.6261348 | G29: =IF(G6="","",(G6/$O$23)) -> 3.5689341 | H29: =IF(H6="","",(H6/$O$23)) -> 9.1750813 | I29: =IF(I6="","",(I6/$O$23)) -> 0.012080336 | ... M29: =IF(M6="","",(M6/$O$23)) -> 0.13908427 | O29: =IF(O6="","",(O6/$O$23)) -> 0.26555682 | P29: =IF(P6="","",(P6/$O$23)) -> 4.1070561 | Q29: =IF(Q6="","",(Q6/$O$23)) -> 0.025298294 | R29: =IF(R6="","",(R6/$O$23)) -> 0.13655732 | S29: =IF(S6="","",(S6/$O$23)) -> 1.1543154 | T29: =IF(T6="","",(T6/$O$23)) -> 0.016922835 | U29: =IF(U6="","",(U6/$O$23)) -> 0.10375056 | V29: =IF(V6="","",(V6/$O$23)) -> 0.030687805
B30: =IF(B7="","",(B7/$O$23)) -> 0.0061174902 | C30: =IF(C7="","",(C7/$O$23)) -> 0.87514823 | D30: =IF(D7="","",(D7/$O$23)) -> 2.0547718 | E30: =IF(E7="","",(E7/$O$23)) -> 2.4877382 | F30: =IF(F7="","",(F7/$O$23)) -> 3.4696732 | G30: =IF(G7="","",(G7/$O$23)) -> 5.1250765 | H30: =IF(H7="","",(H7/$O$23)) -> 4.0978761 | I30: =IF(I7="","",(I7/$O$23)) -> 0.16243717 | ... M30: =IF(M7="","",(M7/$O$23)) -> 0.064644524 | O30: =IF(O7="","",(O7/$O$23)) -> 0.08820883 | P30: =IF(P7="","",(P7/$O$23)) -> 4.4422702 | Q30: =IF(Q7="","",(Q7/$O$23)) -> 0.033345545 | R30: =IF(R7="","",(R7/$O$23)) -> 0.20609041 | S30: =IF(S7="","",(S7/$O$23)) -> 0.4076328 | T30: =IF(T7="","",(T7/$O$23)) -> 0.37692525 | U30: =IF(U7="","",(U7/$O$23)) -> 0.032921919 | V30: =IF(V7="","",(V7/$O$23)) -> 0.024394284
B31: =IF(B8="","",(B8/$O$23)) -> 0.0074887228 | C31: =IF(C8="","",(C8/$O$23)) -> 0.069852246 | D31: =IF(D8="","",(D8/$O$23)) -> 0.12628007 | E31: =IF(E8="","",(E8/$O$23)) -> 0.18746566 | F31: =IF(F8="","",(F8/$O$23)) -> 3.1558641 | G31: =IF(G8="","",(G8/$O$23)) -> 6.5192466 | H31: =IF(H8="","",(H8/$O$23)) -> 7.2360203 | I31: =IF(I8="","",(I8/$O$23)) -> 0.026241787 | ... M31: =IF(M8="","",(M8/$O$23)) -> 0.13472133 | O31: =IF(O8="","",(O8/$O$23)) -> 1.4076775 | P31: =IF(P8="","",(P8/$O$23)) -> 5.9092472 | Q31: =IF(Q8="","",(Q8/$O$23)) -> 0.0046171134 | R31: =IF(R8="","",(R8/$O$23)) -> 0.061727673 | S31: =IF(S8="","",(S8/$O$23)) -> 0.0046483713 | T31: =IF(T8="","",(T8/$O$23)) -> 0.20769607 | U31: =IF(U8="","",(U8/$O$23)) -> 0.1744443 | V31: =IF(V8="","",(V8/$O$23)) -> 0.0018129553
B32: =IF(B9="","",(B9/$O$23)) -> 0.12118175 | C32: =IF(C9="","",(C9/$O$23)) -> 0.65368801 | D32: =IF(D9="","",(D9/$O$23)) -> 1.9720553 | E32: =IF(E9="","",(E9/$O$23)) -> 0.60955193 | F32: =IF(F9="","",(F9/$O$23)) -> 3.8395201 | G32: =IF(G9="","",(G9/$O$23)) -> 9.0345049 | H32: =IF(H9="","",(H9/$O$23)) -> 3.9291158 | I32: =IF(I9="","",(I9/$O$23)) -> 0.0046055974 | ... M32: =IF(M9="","",(M9/$O$23)) -> 0.029135606 | O32: =IF(O9="","",(O9/$O$23)) -> 0.077914304 | P32: =IF(P9="","",(P9/$O$23)) -> 2.1393868 | Q32: =IF(Q9="","",(Q9/$O$23)) -> 0.0011335083 | R32: =IF(R9="","",(R9/$O$23)) -> 0.067137749 | S32: =IF(S9="","",(S9/$O$23)) -> 0.030472291 | T32: =IF(T9="","",(T9/$O$23)) -> 0.87322011 | U32: =IF(U9="","",(U9/$O$23)) -> 0.012012885 | V32: =IF(V9="","",(V9/$O$23)) -> 0.026403835
B33: =IF(B10="","",(B10/$O$23)) -> 0.056343097 | C33: =IF(C10="","",(C10/$O$23)) -> 0.182559 | D33: =IF(D10="","",(D10/$O$23)) -> 0.32477564 | E33: =IF(E10="","",(E10/$O$23)) -> 0.69160296 | F33: =IF(F10="","",(F10/$O$23)) -> 5.2423979 | G33: =IF(G10="","",(G10/$O$23)) -> 3.5829203 | H33: =IF(H10="","",(H10/$O$23)) -> 6.8722719 | I33: =IF(I10="","",(I10/$O$23)) -> 0.042312435 | ... M33: =IF(M10="","",(M10/$O$23)) -> 0.11768087 | O33: =IF(O10="","",(O10/$O$23)) -> 0.089718255 | P33: =IF(P10="","",(P10/$O$23)) -> 3.6121834 | Q33: =IF(Q10="","",(Q10/$O$23)) -> 0.026635801 | R33: =IF(R10="","",(R10/$O$23)) -> 3.545925 | S33: =IF(S10="","",(S10/$O$23)) -> 0.089239516 | T33: =IF(T10="","",(T10/$O$23)) -> 0.98906746 | U33: =IF(U10="","",(U10/$O$23)) -> 0.0035568143 | V33: =IF(V10="","",(V10/$O$23)) -> 0.1427982
B34: =IF(B11="","",(B11/$O$23)) -> 0.0027046266 | C34: =IF(C11="","",(C11/$O$23)) -> 0.032528728 | D34: =IF(D11="","",(D11/$O$23)) -> 0.50385926 | E34: =IF(E11="","",(E11/$O$23)) -> 1.9719311 | F34: =IF(F11="","",(F11/$O$23)) -> 1.7186627 | G34: =IF(G11="","",(G11/$O$23)) -> 9.4793 | H34: =IF(H11="","",(H11/$O$23)) -> 6.3666877 | I34: =IF(I11="","",(I11/$O$23)) -> 0.082974785 | ... M34: =IF(M11="","",(M11/$O$23)) -> 0.068518852 | O34: =IF(O11="","",(O11/$O$23)) -> 0.64043221 | P34: =IF(P11="","",(P11/$O$23)) -> 5.1426426 | Q34: =IF(Q11="","",(Q11/$O$23)) -> 0.20303125 | R34: =IF(R11="","",(R11/$O$23)) -> 1.3989081 | S34: =IF(S11="","",(S11/$O$23)) -> 0.02673122 | T34: =IF(T11="","",(T11/$O$23)) -> 1.3129646 | U34: =IF(U11="","",(U11/$O$23)) -> 0.0016599563 | V34: =IF(V11="","",(V11/$O$23)) -> 1.6938259
B35: =IF(B12="","",(B12/$O$23)) -> 0.038760556 | C35: =IF(C12="","",(C12/$O$23)) -> 0.07222702 | D35: =IF(D12="","",(D12/$O$23)) -> 0.13980567 | E35: =IF(E12="","",(E12/$O$23)) -> 0.041421586 | F35: =IF(F12="","",(F12/$O$23)) -> 5.4595956 | G35: =IF(G12="","",(G12/$O$23)) | H35: =IF(H12="","",(H12/$O$23)) -> 4.9551515 | I35: =IF(I12="","",(I12/$O$23)) | ... M35: =IF(M12="","",(M12/$O$23)) -> 0.16651797 | O35: =IF(O12="","",(O12/$O$23)) -> 1.3673804 | P35: =IF(P12="","",(P12/$O$23)) -> 5.393046 | Q35: =IF(Q12="","",(Q12/$O$23)) -> 0.017450929 | R35: =IF(R12="","",(R12/$O$23)) -> 0.15717269 | S35: =IF(S12="","",(S12/$O$23)) -> 0.29748507 | T35: =IF(T12="","",(T12/$O$23)) -> 0.11753116 | U35: =IF(U12="","",(U12/$O$23)) -> 0.43927972 | V35: =IF(V12="","",(V12/$O$23))
B36: =IF(B13="","",(B13/$O$23)) | C36: =IF(C13="","",(C13/$O$23)) | D36: =IF(D13="","",(D13/$O$23)) | E36: =IF(E13="","",(E13/$O$23)) | F36: =IF(F13="","",(F13/$O$23)) | G36: =IF(G13="","",(G13/$O$23)) | H36: =IF(H13="","",(H13/$O$23)) | I36: =IF(I13="","",(I13/$O$23)) | ... M36: =IF(M13="","",(M13/$O$23)) | O36: =IF(O13="","",(O13/$O$23)) -> 1.0741324 | P36: =IF(P13="","",(P13/$O$23)) | Q36: =IF(Q13="","",(Q13/$O$23)) | R36: =IF(R13="","",(R13/$O$23)) | S36: =IF(S13="","",(S13/$O$23)) | T36: =IF(T13="","",(T13/$O$23)) | U36: =IF(U13="","",(U13/$O$23)) | V36: =IF(V13="","",(V13/$O$23))
B37: =IF(B14="","",(B14/$O$23)) | C37: =IF(C14="","",(C14/$O$23)) | D37: =IF(D14="","",(D14/$O$23)) | E37: =IF(E14="","",(E14/$O$23)) | F37: =IF(F14="","",(F14/$O$23)) | G37: =IF(G14="","",(G14/$O$23)) | H37: =IF(H14="","",(H14/$O$23)) | I37: =IF(I14="","",(I14/$O$23)) | ... M37: =IF(M14="","",(M14/$O$23)) | O37: =IF(O14="","",(O14/$O$23)) -> 1.2917306 | P37: =IF(P14="","",(P14/$O$23)) | Q37: =IF(Q14="","",(Q14/$O$23)) | R37: =IF(R14="","",(R14/$O$23)) | S37: =IF(S14="","",(S14/$O$23)) | T37: =IF(T14="","",(T14/$O$23)) | U37: =IF(U14="","",(U14/$O$23)) | V37: =IF(V14="","",(V14/$O$23))
B38: =IF(B15="","",(B15/$O$23)) | C38: =IF(C15="","",(C15/$O$23)) | D38: =IF(D15="","",(D15/$O$23)) | E38: =IF(E15="","",(E15/$O$23)) | F38: =IF(F15="","",(F15/$O$23)) | G38: =IF(G15="","",(G15/$O$23)) | H38: =IF(H15="","",(H15/$O$23)) | I38: =IF(I15="","",(I15/$O$23)) | ... M38: =IF(M15="","",(M15/$O$23)) | O38: =IF(O15="","",(O15/$O$23)) -> 0.52299647 | P38: =IF(P15="","",(P15/$O$23)) | Q38: =IF(Q15="","",(Q15/$O$23)) | R38: =IF(R15="","",(R15/$O$23)) | S38: =IF(S15="","",(S15/$O$23)) | T38: =IF(T15="","",(T15/$O$23)) | U38: =IF(U15="","",(U15/$O$23)) | V38: =IF(V15="","",(V15/$O$23))
B39: =IF(B16="","",(B16/$O$23)) | C39: =IF(C16="","",(C16/$O$23)) | D39: =IF(D16="","",(D16/$O$23)) | E39: =IF(E16="","",(E16/$O$23)) | F39: =IF(F16="","",(F16/$O$23)) | G39: =IF(G16="","",(G16/$O$23)) | H39: =IF(H16="","",(H16/$O$23)) | I39: =IF(I16="","",(I16/$O$23)) | ... M39: =IF(M16="","",(M16/$O$23)) | O39: =IF(O16="","",(O16/$O$23)) -> 0.10337382 | P39: =IF(P16="","",(P16/$O$23)) | Q39: =IF(Q16="","",(Q16/$O$23)) | R39: =IF(R16="","",(R16/$O$23)) | S39: =IF(S16="","",(S16/$O$23)) | T39: =IF(T16="","",(T16/$O$23)) | U39: =IF(U16="","",(U16/$O$23)) | V39: =IF(V16="","",(V16/$O$23))
B40: =IF(B17="","",(B17/$O$23)) | C40: =IF(C17="","",(C17/$O$23)) | D40: =IF(D17="","",(D17/$O$23)) | E40: =IF(E17="","",(E17/$O$23)) | F40: =IF(F17="","",(F17/$O$23)) | G40: =IF(G17="","",(G17/$O$23)) | H40: =IF(H17="","",(H17/$O$23)) | I40: =IF(I17="","",(I17/$O$23)) | ... M40: =IF(M17="","",(M17/$O$23)) | O40: =IF(O17="","",(O17/$O$23)) -> 0.41899173 | P40: =IF(P17="","",(P17/$O$23)) | Q40: =IF(Q17="","",(Q17/$O$23)) | R40: =IF(R17="","",(R17/$O$23)) | S40: =IF(S17="","",(S17/$O$23)) | T40: =IF(T17="","",(T17/$O$23)) | U40: =IF(U17="","",(U17/$O$23)) | V40: =IF(V17="","",(V17/$O$23))
... B43: =IF(B20="","",(B20/$O$23)) | C43: =IF(C20="","",(C20/$O$23)) | D43: =IF(D20="","",(D20/$O$23)) | E43: =IF(E20="","",(E20/$O$23)) | F43: =IF(F20="","",(F20/$O$23)) | G43: =IF(G20="","",(G20/$O$23)) | H43: =IF(H20="","",(H20/$O$23)) | I43: =IF(I20="","",(I20/$O$23)) | ... M43: =IF(M20="","",(M20/$O$23)) | O43: =IF(O20="","",(O20/$O$23)) -> 0.98932164 | P43: =IF(P20="","",(P20/$O$23)) | Q43: =IF(Q20="","",(Q20/$O$23)) | R43: =IF(R20="","",(R20/$O$23)) | S43: =IF(S20="","",(S20/$O$23)) | T43: =IF(T20="","",(T20/$O$23)) | U43: =IF(U20="","",(U20/$O$23)) | V43: =IF(V20="","",(V20/$O$23))
A45: =A4 -> Noms des groupes | B45: =B4 -> Témoin solvant | C45: =C4 -> EE2-33.8ng/L | D45: =D4 -> EE2-50.6ng/L | E45: =E4 -> EE2-76ng/L | F45: =F4 -> EE2-114ng/L | G45: =G4 -> EE2-170.9ng/L | H45: =H4 -> EE2-488ng/L | ... M45: =M4 -> Prochloraz-1mg/L | N45: =N22 -> Nom des groupes | O45: =O4 -> Testo -30µg/L | P45: =P4 -> Testo 30µg/L + EE2 -64ng/L | Q45: =Q4 -> Testo 30µg/L + FAD-10µg/L | R45: =R4 -> Prochloraz-0.063mg/L + Testostérone | S45: =S4 -> Prochloraz-0.13mg/L + Testostérone | T45: =T4 -> Prochloraz-0.25mg/L + Testostérone | U45: =U4 -> Prochloraz-0.5mg/L + Testostérone | V45: =V4 -> Prochloraz-1mg/L + Testostérone
A46: mean | B46: =AVERAGE(B28:B43) -> 0.03550645 | C46: =AVERAGE(C28:C43) -> 0.26183313 | D46: =AVERAGE(D28:D43) -> 0.64747592 | E46: =AVERAGE(E28:E43) -> 1.1443094 | F46: =AVERAGE(F28:F43) -> 3.6448299 | G46: =AVERAGE(G28:G43) -> 6.0717926 | H46: =AVERAGE(H28:H43) -> 5.8491207 | I46: =AVERAGE(I28:I43) -> 0.059518354 | ... M46: =AVERAGE(M28:M43) -> 0.10976163 | N46: mean | O46: =AVERAGE(O28:O43) -> 1 | P46: =AVERAGE(P28:P43) -> 4.7807756 | Q46: =AVERAGE(Q28:Q43) -> 0.050170083 | R46: =AVERAGE(R28:R43) -> 0.7001052 | S46: =AVERAGE(S28:S43) -> 0.26228565 | T46: =AVERAGE(T28:T43) -> 0.48825656 | U46: =AVERAGE(U28:U43) -> 0.10020362 | V46: =AVERAGE(V28:V43) -> 0.27453158
...

Sheet Raw data R2
A1: Nom groupe | B1: N° de valeur | C1: file name | D1: total area | E1: mean intensity | G1: total fluorescence | I1: nbre de larves | L1: (Tous)
A2: =IFERROR(LEFT(RIGHT(C2,LEN(C2)-SEARCH("@",C2)),SEARCH("/",RIGHT(C2,LEN(C2)-SEARCH("@",C2)-1))),"") | B2: =LEFT(RIGHT(RIGHT(Tableau46[[#This Row],[file name]],LEN(Tableau46[[#This Row],[file name]])-SEARCH("@",Tableau46[[#This Row],[file name]])),LEN(RIGHT(Tableau46[[#This Row],[file name]],LEN(Tableau46[[#This Row],[file name]])-SEARCH("@",Tableau46[[#This Row],[file name]])))-SEARCH("/",RIGHT(Tableau46[[#This Row],[file name]],LEN(Tableau46[[#This Row],[file name]])-SEARCH("@",Tableau46[[#This Row],[file name]])))),1) -> #VALUE! | K2: Filtre lignes : Enlever (vide) et Néant | L2: Filtre colonnes : Enlever (vide) et " "
A3: =IFERROR(LEFT(RIGHT(C3,LEN(C3)-SEARCH("@",C3)),SEARCH("/",RIGHT(C3,LEN(C3)-SEARCH("@",C3)-1))),"") | B3: =LEFT(RIGHT(RIGHT(Tableau46[[#This Row],[file name]],LEN(Tableau46[[#This Row],[file name]])-SEARCH("@",Tableau46[[#This Row],[file name]])),LEN(RIGHT(Tableau46[[#This Row],[file name]],LEN(Tableau46[[#This Row],[file name]])-SEARCH("@",Tableau46[[#This Row],[file name]])))-SEARCH("/",RIGHT(Tableau46[[#This Row],[file name]],LEN(Tableau46[[#This Row],[file name]])-SEARCH("@",Tableau46[[#This Row],[file name]])))),1) -> #VALUE! | K3: Moyenne de total fluorescence | L3: Étiquettes de colonnes
A4: =IFERROR(LEFT(RIGHT(C4,LEN(C4)-SEARCH("@",C4)),SEARCH("/",RIGHT(C4,LEN(C4)-SEARCH("@",C4)-1))),"") | B4: =LEFT(RIGHT(RIGHT(Tableau46[[#This Row],[file name]],LEN(Tableau46[[#This Row],[file name]])-SEARCH("@",Tableau46[[#This Row],[file name]])),LEN(RIGHT(Tableau46[[#This Row],[file name]],LEN(Tableau46[[#This Row],[file name]])-SEARCH("@",Tableau46[[#This Row],[file name]])))-SEARCH("/",RIGHT(Tableau46[[#This Row],[file name]],LEN(Tableau46[[#This Row],[file name]])-SEARCH("@",Tableau46[[#This Row],[file name]])))),1) -> #VALUE! | K4: Étiquettes de lignes
A5: =IFERROR(LEFT(RIGHT(C5,LEN(C5)-SEARCH("@",C5)),SEARCH("/",RIGHT(C5,LEN(C5)-SEARCH("@",C5)-1))),"") | B5: =LEFT(RIGHT(RIGHT(Tableau46[[#This Row],[file name]],LEN(Tableau46[[#This Row],[file name]])-SEARCH("@",Tableau46[[#This Row],[file name]])),LEN(RIGHT(Tableau46[[#This Row],[file name]],LEN(Tableau46[[#This Row],[file name]])-SEARCH("@",Tableau46[[#This Row],[file name]])))-SEARCH("/",RIGHT(Tableau46[[#This Row],[file name]],LEN(Tableau46[[#This Row],[file name]])-SEARCH("@",Tableau46[[#This Row],[file name]])))),1) -> #VALUE! | K5: #VALEUR!
A6: =IFERROR(LEFT(RIGHT(C6,LEN(C6)-SEARCH("@",C6)),SEARCH("/",RIGHT(C6,LEN(C6)-SEARCH("@",C6)-1))),"") | B6: =LEFT(RIGHT(RIGHT(Tableau46[[#This Row],[file name]],LEN(Tableau46[[#This Row],[file name]])-SEARCH("@",Tableau46[[#This Row],[file name]])),LEN(RIGHT(Tableau46[[#This Row],[file name]],LEN(Tableau46[[#This Row],[file name]])-SEARCH("@",Tableau46[[#This Row],[file name]])))-SEARCH("/",RIGHT(Tableau46[[#This Row],[file name]],LEN(Tableau46[[#This Row],[file name]])-SEARCH("@",Tableau46[[#This Row],[file name]])))),1) -> #VALUE!
A7: =IFERROR(LEFT(RIGHT(C7,LEN(C7)-SEARCH("@",C7)),SEARCH("/",RIGHT(C7,LEN(C7)-SEARCH("@",C7)-1))),"") | B7: =LEFT(RIGHT(RIGHT(Tableau46[[#This Row],[file name]],LEN(Tableau46[[#This Row],[file name]])-SEARCH("@",Tableau46[[#This Row],[file name]])),LEN(RIGHT(Tableau46[[#This Row],[file name]],LEN(Tableau46[[#This Row],[file name]])-SEARCH("@",Tableau46[[#This Row],[file name]])))-SEARCH("/",RIGHT(Tableau46[[#This Row],[file name]],LEN(Tableau46[[#This Row],[file name]])-SEARCH("@",Tableau46[[#This Row],[file name]])))),1) -> #VALUE!
A8: =IFERROR(LEFT(RIGHT(C8,LEN(C8)-SEARCH("@",C8)),SEARCH("/",RIGHT(C8,LEN(C8)-SEARCH("@",C8)-1))),"") | B8: =LEFT(RIGHT(RIGHT(Tableau46[[#This Row],[file name]],LEN(Tableau46[[#This Row],[file name]])-SEARCH("@",Tableau46[[#This Row],[file name]])),LEN(RIGHT(Tableau46[[#This Row],[file name]],LEN(Tableau46[[#This Row],[file name]])-SEARCH("@",Tableau46[[#This Row],[file name]])))-SEARCH("/",RIGHT(Tableau46[[#This Row],[file name]],LEN(Tableau46[[#This Row],[file name]])-SEARCH("@",Tableau46[[#This Row],[file name]])))),1) -> #VALUE!
A9: =IFERROR(LEFT(RIGHT(C9,LEN(C9)-SEARCH("@",C9)),SEARCH("/",RIGHT(C9,LEN(C9)-SEARCH("@",C9)-1))),"") | B9: =LEFT(RIGHT(RIGHT(Tableau46[[#This Row],[file name]],LEN(Tableau46[[#This Row],[file name]])-SEARCH("@",Tableau46[[#This Row],[file name]])),LEN(RIGHT(Tableau46[[#This Row],[file name]],LEN(Tableau46[[#This Row],[file name]])-SEARCH("@",Tableau46[[#This Row],[file name]])))-SEARCH("/",RIGHT(Tableau46[[#This Row],[file name]],LEN(Tableau46[[#This Row],[file name]])-SEARCH("@",Tableau46[[#This Row],[file name]])))),1) -> #VALUE!
A10: =IFERROR(LEFT(RIGHT(C10,LEN(C10)-SEARCH("@",C10)),SEARCH("/",RIGHT(C10,LEN(C10)-SEARCH("@",C10)-1))),"") | B10: =LEFT(RIGHT(RIGHT(Tableau46[[#This Row],[file name]],LEN(Tableau46[[#This Row],[file name]])-SEARCH("@",Tableau46[[#This Row],[file name]])),LEN(RIGHT(Tableau46[[#This Row],[file name]],LEN(Tableau46[[#This Row],[file name]])-SEARCH("@",Tableau46[[#This Row],[file name]])))-SEARCH("/",RIGHT(Tableau46[[#This Row],[file name]],LEN(Tableau46[[#This Row],[file name]])-SEARCH("@",Tableau46[[#This Row],[file name]])))),1) -> #VALUE!
A11: =IFERROR(LEFT(RIGHT(C11,LEN(C11)-SEARCH("@",C11)),SEARCH("/",RIGHT(C11,LEN(C11)-SEARCH("@",C11)-1))),"") | B11: =LEFT(RIGHT(RIGHT(Tableau46[[#This Row],[file name]],LEN(Tableau46[[#This Row],[file name]])-SEARCH("@",Tableau46[[#This Row],[file name]])),LEN(RIGHT(Tableau46[[#This Row],[file name]],LEN(Tableau46[[#This Row],[file name]])-SEARCH("@",Tableau46[[#This Row],[file name]])))-SEARCH("/",RIGHT(Tableau46[[#This Row],[file name]],LEN(Tableau46[[#This Row],[file name]])-SEARCH("@",Tableau46[[#This Row],[file name]])))),1) -> #VALUE!
A12: =IFERROR(LEFT(RIGHT(C12,LEN(C12)-SEARCH("@",C12)),SEARCH("/",RIGHT(C12,LEN(C12)-SEARCH("@",C12)-1))),"") | B12: =LEFT(RIGHT(RIGHT(Tableau46[[#This Row],[file name]],LEN(Tableau46[[#This Row],[file name]])-SEARCH("@",Tableau46[[#This Row],[file name]])),LEN(RIGHT(Tableau46[[#This Row],[file name]],LEN(Tableau46[[#This Row],[file name]])-SEARCH("@",Tableau46[[#This Row],[file name]])))-SEARCH("/",RIGHT(Tableau46[[#This Row],[file name]],LEN(Tableau46[[#This Row],[file name]])-SEARCH("@",Tableau46[[#This Row],[file name]])))),1) -> #VALUE!
A13: =IFERROR(LEFT(RIGHT(C13,LEN(C13)-SEARCH("@",C13)),SEARCH("/",RIGHT(C13,LEN(C13)-SEARCH("@",C13)-1))),"") | B13: =LEFT(RIGHT(RIGHT(Tableau46[[#This Row],[file name]],LEN(Tableau46[[#This Row],[file name]])-SEARCH("@",Tableau46[[#This Row],[file name]])),LEN(RIGHT(Tableau46[[#This Row],[file name]],LEN(Tableau46[[#This Row],[file name]])-SEARCH("@",Tableau46[[#This Row],[file name]])))-SEARCH("/",RIGHT(Tableau46[[#This Row],[file name]],LEN(Tableau46[[#This Row],[file name]])-SEARCH("@",Tableau46[[#This Row],[file name]])))),1) -> #VALUE!
A14: =IFERROR(LEFT(RIGHT(C14,LEN(C14)-SEARCH("@",C14)),SEARCH("/",RIGHT(C14,LEN(C14)-SEARCH("@",C14)-1))),"") | B14: =LEFT(RIGHT(RIGHT(Tableau46[[#This Row],[file name]],LEN(Tableau46[[#This Row],[file name]])-SEARCH("@",Tableau46[[#This Row],[file name]])),LEN(RIGHT(Tableau46[[#This Row],[file name]],LEN(Tableau46[[#This Row],[file name]])-SEARCH("@",Tableau46[[#This Row],[file name]])))-SEARCH("/",RIGHT(Tableau46[[#This Row],[file name]],LEN(Tableau46[[#This Row],[file name]])-SEARCH("@",Tableau46[[#This Row],[file name]])))),1) -> #VALUE!
A15: =IFERROR(LEFT(RIGHT(C15,LEN(C15)-SEARCH("@",C15)),SEARCH("/",RIGHT(C15,LEN(C15)-SEARCH("@",C15)-1))),"") | B15: =LEFT(RIGHT(RIGHT(Tableau46[[#This Row],[file name]],LEN(Tableau46[[#This Row],[file name]])-SEARCH("@",Tableau46[[#This Row],[file name]])),LEN(RIGHT(Tableau46[[#This Row],[file name]],LEN(Tableau46[[#This Row],[file name]])-SEARCH("@",Tableau46[[#This Row],[file name]])))-SEARCH("/",RIGHT(Tableau46[[#This Row],[file name]],LEN(Tableau46[[#This Row],[file name]])-SEARCH("@",Tableau46[[#This Row],[file name]])))),1) -> #VALUE!
A16: =IFERROR(LEFT(RIGHT(C16,LEN(C16)-SEARCH("@",C16)),SEARCH("/",RIGHT(C16,LEN(C16)-SEARCH("@",C16)-1))),"") | B16: =LEFT(RIGHT(RIGHT(Tableau46[[#This Row],[file name]],LEN(Tableau46[[#This Row],[file name]])-SEARCH("@",Tableau46[[#This Row],[file name]])),LEN(RIGHT(Tableau46[[#This Row],[file name]],LEN(Tableau46[[#This Row],[file name]])-SEARCH("@",Tableau46[[#This Row],[file name]])))-SEARCH("/",RIGHT(Tableau46[[#This Row],[file name]],LEN(Tableau46[[#This Row],[file name]])-SEARCH("@",Tableau46[[#This Row],[file name]])))),1) -> #VALUE!
A17: =IFERROR(LEFT(RIGHT(C17,LEN(C17)-SEARCH("@",C17)),SEARCH("/",RIGHT(C17,LEN(C17)-SEARCH("@",C17)-1))),"") | B17: =LEFT(RIGHT(RIGHT(Tableau46[[#This Row],[file name]],LEN(Tableau46[[#This Row],[file name]])-SEARCH("@",Tableau46[[#This Row],[file name]])),LEN(RIGHT(Tableau46[[#This Row],[file name]],LEN(Tableau46[[#This Row],[file name]])-SEARCH("@",Tableau46[[#This Row],[file name]])))-SEARCH("/",RIGHT(Tableau46[[#This Row],[file name]],LEN(Tableau46[[#This Row],[file name]])-SEARCH("@",Tableau46[[#This Row],[file name]])))),1) -> #VALUE!
... A1531: =IFERROR(LEFT(RIGHT(C1531,LEN(C1531)-SEARCH("@",C1531)),SEARCH("/",RIGHT(C1531,LEN(C1531)-SEARCH("@",C1531)-1))),"") | B1531: =LEFT(RIGHT(RIGHT(Tableau46[[#This Row],[file name]],LEN(Tableau46[[#This Row],[file name]])-SEARCH("@",Tableau46[[#This Row],[file name]])),LEN(RIGHT(Tableau46[[#This Row],[file name]],LEN(Tableau46[[#This Row],[file name]])-SEARCH("@",Tableau46[[#This Row],[file name]])))-SEARCH("/",RIGHT(Tableau46[[#This Row],[file name]],LEN(Tableau46[[#This Row],[file name]])-SEARCH("@",Tableau46[[#This Row],[file name]])))),1) -> #VALUE!

Sheet R2
A1: 6. Expérimentateur 2 : copier et coller les valeurs des intensités totales de fluorescences obtenues dans le fichier raw data lors du traitement des images. Ne pas supprimer les colonnes correspondant aux concentrations non lues.
A3: R2 | B3: Non dopé | O3: avec testo
A4: Noms des groupes | B4: ='Page de garde'!A7 -> Témoin solvant | C4: ='Page de garde'!A9 -> EE2-33.8ng/L | D4: ='Page de garde'!A10 -> EE2-50.6ng/L | E4: ='Page de garde'!A11 -> EE2-76ng/L | F4: ='Page de garde'!A12 -> EE2-114ng/L | G4: ='Page de garde'!A13 -> EE2-170.9ng/L | H4: ='Page de garde'!A14 -> EE2-488ng/L | I4: ='Page de garde'!A15 -> Prochloraz-0.063mg/L | J4: ='Page de garde'!A16 -> Prochloraz-0.13mg/L | K4: ='Page de garde'!A17 -> Prochloraz-0.25mg/L | L4: ='Page de garde'!A18 -> Prochloraz-0.5mg/L | M4: ='Page de garde'!A19 -> Prochloraz-1mg/L | O4: ='Page de garde'!A36 -> Testo -30µg/L | P4: ='Page de garde'!A37 -> Testo 30µg/L + EE2 -64ng/L | Q4: ='Page de garde'!A38 -> Testo 30µg/L + FAD-10µg/L | R4: ='Page de garde'!A39 -> Prochloraz-0.063mg/L + Testostérone | S4: ='Page de garde'!A40 -> Prochloraz-0.13mg/L + Testostérone | T4: ='Page de garde'!A41 -> Prochloraz-0.25mg/L + Testostérone | U4: ='Page de garde'!A42 -> Prochloraz-0.5mg/L + Testostérone | V4: ='Page de garde'!A43 -> Prochloraz-1mg/L + Testostérone
A5: Données brutes | B5: 149372 | C5: 33844 | D5: 456092 | E5: 2899117 | F5: 5759557 | G5: 5422705 | H5: 13022906 | I5: 271568 | J5: 18941 | K5: 11090 | L5: 47166 | M5: 1216 | O5: 5134886 | P5: 2277303 | Q5: 104077 | R5: 140274 | S5: 2302835 | T5: 1581973 | U5: 121694 | V5: 36062
B6: 135517 | C6: 155757 | D6: 41239 | E6: 1547180 | F6: 8237697 | G6: 9780730 | H6: 12561495 | I6: 284544 | J6: 436246 | K6: 150941 | L6: 65801 | M6: 81150 | O6: 3805757 | P6: 8253862 | Q6: 245377 | R6: 53826 | S6: 120296 | T6: 154690 | U6: 28101 | V6: 38139
B7: 33126 | C7: 51183 | D7: 148387 | E7: 145232 | F7: 5127448 | G7: 11425175 | H7: 3256763 | I7: 356258 | J7: 71435 | K7: 90099 | L7: 128719 | M7: 96936 | O7: 4831043 | P7: 5909894 | Q7: 130351 | R7: 494013 | S7: 1696310 | T7: 75509 | U7: 37486 | V7: 140099
B8: 44916 | C8: 452890 | D8: 116127 | E8: 1886784 | F8: 13014237 | G8: 10848075 | H8: 14622003 | I8: 113271 | J8: 291509 | K8: 178685 | L8: 95556 | M8: 43070 | O8: 4116104 | P8: 4996432 | Q8: 24708 | R8: 438026 | S8: 531368 | T8: 33952 | U8: 123807 | V8: 43047
B9: 16167 | C9: 171180 | D9: 348811 | E9: 1647783 | F9: 4424599 | G9: 12509888 | H9: 21270490 | I9: 149674 | J9: 270182 | K9: 5885 | L9: 55637 | M9: 93318 | O9: 3322818 | P9: 4236178 | Q9: 24531 | R9: 1890596 | S9: 169203 | T9: 63374 | U9: 229876 | V9: 736109
B10: 156525 | C10: 66860 | D10: 220815 | E10: 2683844 | F10: 4865092 | G10: 7409035 | H10: 17156783 | I10: 376141 | J10: 932194 | K10: 61799 | L10: 79307 | M10: 136264 | O10: 804720 | P10: 1606612 | Q10: 141707 | R10: 1148 | S10: 364856 | T10: 31036 | U10: 10880 | V10: 184916
B11: 7719 | C11: 639303 | D11: 903592 | E11: 836476 | F11: 3078611 | G11: 2426504 | H11: 10284233 | I11: 78302 | J11: 31272 | K11: 174879 | L11: 193731 | M11: 46016 | O11: 777545 | P11: 2030500 | Q11: 27910 | R11: 192639 | S11: 206243 | T11: 69706 | U11: 53607 | V11: 173797
B12: 28375 | C12: 66869 | D12: 377278 | E12: 6906235 | F12: 5866782 | G12: 5555755 | H12: 11608714 | I12: 184347 | J12: 357066 | K12: 115549 | L12: 263021 | O12: 1591366 | P12: 3380577 | Q12: 12222 | R12: 698727 | S12: 244571 | T12: 351147 | U12: 198945 | V12: 47413
O13: 85467
O14: 1806021
O15: 2813577
O16: 1070165
O17: 830157
O18: 5574603
O19: 1779738
O20: 3824389
