Workbook

Sheet Page de garde
A1: 1. Expérimentateur 1 : copier et coller le n° de prestation et renseigner la date de réalisation de chaque réplica ainsi que le visa de l'expérimentateur.
A2: R1 | B2: Numéro d'expérience : | E2: Date de réalisation :
A3: R2 | B3: Numéro d'expérience : | E3: Date de réalisation :
A4: R3 | B4: Numéro d'expérience : | E4: Date de réalisation :
A5: 2. Expérimentateur 1 : copier et coller la dilution appliquée et le nom donné pour chaque des échantillons par le client. Conserver la mise en forme de l'exemple en italique. Ne pas remplir la colonne "nom sur graphique".
A6: Nom sur le graphique | B6: Code WF | C6: Concentration | D6: Unité | E6: Nom de l'échantillon donné par le client | F6: Dopage (+Testostérone / + EE2, ….)
A7: =IF(ISBLANK(liste_groupe[[#This Row],[Code WF]])," ",IF(ISBLANK(liste_groupe[[#This Row],[Unité]]),CONCATENATE(liste_groupe[[#This Row],[Nom de l''échantillon donné par le client]],liste_groupe[[#This Row],[Dopage (+Testostérone / + EE2, ….)]]),CONCATENATE(liste_groupe[[#This Row],[Nom de l''échantillon donné par le client]],"-",liste_groupe[[#This Row],[Concentration]],liste_groupe[[#This Row],[Unité]],liste_groupe[[#This Row],[Dopage (+Testostérone / + EE2, ….)]]))) -> Témoin solvant | B7: Témoin | E7: Témoin solvant
A8: =IF(ISBLANK(liste_groupe[[#This Row],[Code WF]])," ",IF(ISBLANK(liste_groupe[[#This Row],[Unité]]),CONCATENATE(liste_groupe[[#This Row],[Nom de l''échantillon donné par le client]],liste_groupe[[#This Row],[Dopage (+Testostérone / + EE2, ….)]]),CONCATENATE(liste_groupe[[#This Row],[Nom de l''échantillon donné par le client]],"-",liste_groupe[[#This Row],[Concentration]],liste_groupe[[#This Row],[Unité]],liste_groupe[[#This Row],[Dopage (+Testostérone / + EE2, ….)]]))) -> EE2-22.5ng/L | B8: Témoin | C8: 22.5 | D8: ng/L | E8: EE2
A9: =IF(ISBLANK(liste_groupe[[#This Row],[Code WF]])," ",IF(ISBLANK(liste_groupe[[#This Row],[Unité]]),CONCATENATE(liste_groupe[[#This Row],[Nom de l''échantillon donné par le client]],liste_groupe[[#This Row],[Dopage (+Testostérone / + EE2, ….)]]),CONCATENATE(liste_groupe[[#This Row],[Nom de l''échantillon donné par le client]],"-",liste_groupe[[#This Row],[Concentration]],liste_groupe[[#This Row],[Unité]],liste_groupe[[#This Row],[Dopage (+Testostérone / + EE2, ….)]]))) -> EE2-33.8ng/L | B9: Témoin | C9: 33.8 | D9: ng/L | E9: EE2
A10: =IF(ISBLANK(liste_groupe[[#This Row],[Code WF]])," ",IF(ISBLANK(liste_groupe[[#This Row],[Unité]]),CONCATENATE(liste_groupe[[#This Row],[Nom de l''échantillon donné par le client]],liste_groupe[[#This Row],[Dopage (+Testostérone / + EE2, ….)]]),CONCATENATE(liste_groupe[[#This Row],[Nom de l''échantillon donné par le client]],"-",liste_groupe[[#This Row],[Concentration]],liste_groupe[[#This Row],[Unité]],liste_groupe[[#This Row],[Dopage (+Testostérone / + EE2, ….)]]))) -> EE2-50.6ng/L | B10: Témoin | C10: 50.6 | D10: ng/L | E10: EE2
A11: =IF(ISBLANK(liste_groupe[[#This Row],[Code WF]])," ",IF(ISBLANK(liste_groupe[[#This Row],[Unité]]),CONCATENATE(liste_groupe[[#This Row],[Nom de l''échantillon donné par le client]],liste_groupe[[#This Row],[Dopage (+Testostérone / + EE2, ….)]]),CONCATENATE(liste_groupe[[#This Row],[Nom de l''échantillon donné par le client]],"-",liste_groupe[[#This Row],[Concentration]],liste_groupe[[#This Row],[Unité]],liste_groupe[[#This Row],[Dopage (+Testostérone / + EE2, ….)]]))) -> EE2-76ng/L | B11: Témoin | C11: 76 | D11: ng/L | E11: EE2
A12: =IF(ISBLANK(liste_groupe[[#This Row],[Code WF]])," ",IF(ISBLANK(liste_groupe[[#This Row],[Unité]]),CONCATENATE(liste_groupe[[#This Row],[Nom de l''échantillon donné par le client]],liste_groupe[[#This Row],[Dopage (+Testostérone / + EE2, ….)]]),CONCATENATE(liste_groupe[[#This Row],[Nom de l''échantillon donné par le client]],"-",liste_groupe[[#This Row],[Concentration]],liste_groupe[[#This Row],[Unité]],liste_groupe[[#This Row],[Dopage (+Testostérone / + EE2, ….)]]))) -> EE2-114ng/L | B12: Témoin | C12: 114 | D12: ng/L | E12: EE2
A13: =IF(ISBLANK(liste_groupe[[#This Row],[Code WF]])," ",IF(ISBLANK(liste_groupe[[#This Row],[Unité]]),CONCATENATE(liste_groupe[[#This Row],[Nom de l''échantillon donné par le client]],liste_groupe[[#This Row],[Dopage (+Testostérone / + EE2, ….)]]),CONCATENATE(liste_groupe[[#This Row],[Nom de l''échantillon donné par le client]],"-",liste_groupe[[#This Row],[Concentration]],liste_groupe[[#This Row],[Unité]],liste_groupe[[#This Row],[Dopage (+Testostérone / + EE2, ….)]]))) -> EE2-170.9ng/L | B13: Témoin | C13: 170.9 | D13: ng/L | E13: EE2
A14: =IF(ISBLANK(liste_groupe[[#This Row],[Code WF]])," ",IF(ISBLANK(liste_groupe[[#This Row],[Unité]]),CONCATENATE(liste_groupe[[#This Row],[Nom de l''échantillon donné par le client]],liste_groupe[[#This Row],[Dopage (+Testostérone / + EE2, ….)]]),CONCATENATE(liste_groupe[[#This Row],[Nom de l''échantillon donné par le client]],"-",liste_groupe[[#This Row],[Concentration]],liste_groupe[[#This Row],[Unité]],liste_groupe[[#This Row],[Dopage (+Testostérone / + EE2, ….)]]))) -> EE2-488ng/L | B14: Témoin | C14: 488 | D14: ng/L | E14: EE2
A15: =IF(ISBLANK(liste_groupe[[#This Row],[Code WF]])," ",IF(ISBLANK(liste_groupe[[#This Row],[Unité]]),CONCATENATE(liste_groupe[[#This Row],[Nom de l''échantillon donné par le client]],liste_groupe[[#This Row],[Dopage (+Testostérone / + EE2, ….)]]),CONCATENATE(liste_groupe[[#This Row],[Nom de l''échantillon donné par le client]],"-",liste_groupe[[#This Row],[Concentration]],liste_groupe[[#This Row],[Unité]],liste_groupe[[#This Row],[Dopage (+Testostérone / + EE2, ….)]]))) -> Testosterone-3.7µg/L | B15: Test | C15: 3.7 | D15: µg/L | E15: Testosterone
A16: =IF(ISBLANK(liste_groupe[[#This Row],[Code WF]])," ",IF(ISBLANK(liste_groupe[[#This Row],[Unité]]),CONCATENATE(liste_groupe[[#This Row],[Nom de l''échantillon donné par le client]],liste_groupe[[#This Row],[Dopage (+Testostérone / + EE2, ….)]]),CONCATENATE(liste_groupe[[#This Row],[Nom de l''échantillon donné par le client]],"-",liste_groupe[[#This Row],[Concentration]],liste_groupe[[#This Row],[Unité]],liste_groupe[[#This Row],[Dopage (+Testostérone / + EE2, ….)]]))) -> Testosterone-11µg/L | B16: Test | C16: 11 | D16: µg/L | E16: Testosterone
A17: =IF(ISBLANK(liste_groupe[[#This Row],[Code WF]])," ",IF(ISBLANK(liste_groupe[[#This Row],[Unité]]),CONCATENATE(liste_groupe[[#This Row],[Nom de l''échantillon donné par le client]],liste_groupe[[#This Row],[Dopage (+Testostérone / + EE2, ….)]]),CONCATENATE(liste_groupe[[#This Row],[Nom de l''échantillon donné par le client]],"-",liste_groupe[[#This Row],[Concentration]],liste_groupe[[#This Row],[Unité]],liste_groupe[[#This Row],[Dopage (+Testostérone / + EE2, ….)]]))) -> Testosterone-33µg/L | B17: Test | C17: 33 | D17: µg/L | E17: Testosterone
A18: =IF(ISBLANK(liste_groupe[[#This Row],[Code WF]])," ",IF(ISBLANK(liste_groupe[[#This Row],[Unité]]),CONCATENATE(liste_groupe[[#This Row],[Nom de l''échantillon donné par le client]],liste_groupe[[#This Row],[Dopage (+Testostérone / + EE2, ….)]]),CONCATENATE(liste_groupe[[#This Row],[Nom de l''échantillon donné par le client]],"-",liste_groupe[[#This Row],[Concentration]],liste_groupe[[#This Row],[Unité]],liste_groupe[[#This Row],[Dopage (+Testostérone / + EE2, ….)]]))) -> Testosterone-100µg/L | B18: Test | C18: 100 | D18: µg/L | E18: Testosterone
A19: =IF(ISBLANK(liste_groupe[[#This Row],[Code WF]])," ",IF(ISBLANK(liste_groupe[[#This Row],[Unité]]),CONCATENATE(liste_groupe[[#This Row],[Nom de l''échantillon donné par le client]],liste_groupe[[#This Row],[Dopage (+Testostérone / + EE2, ….)]]),CONCATENATE(liste_groupe[[#This Row],[Nom de l''échantillon donné par le client]],"-",liste_groupe[[#This Row],[Concentration]],liste_groupe[[#This Row],[Unité]],liste_groupe[[#This Row],[Dopage (+Testostérone / + EE2, ….)]]))) -> Testosterone-300µg/L | B19: Test | C19: 300 | D19: µg/L | E19: Testosterone
A20: =IF(ISBLANK(liste_groupe[[#This Row],[Code WF]])," ",IF(ISBLANK(liste_groupe[[#This Row],[Unité]]),CONCATENATE(liste_groupe[[#This Row],[Nom de l''échantillon donné par le client]],liste_groupe[[#This Row],[Dopage (+Testostérone / + EE2, ….)]]),CONCATENATE(liste_groupe[[#This Row],[Nom de l''échantillon donné par le client]],"-",liste_groupe[[#This Row],[Concentration]],liste_groupe[[#This Row],[Unité]],liste_groupe[[#This Row],[Dopage (+Testostérone / + EE2, ….)]])))
A21: =IF(ISBLANK(liste_groupe[[#This Row],[Code WF]])," ",IF(ISBLANK(liste_groupe[[#This Row],[Unité]]),CONCATENATE(liste_groupe[[#This Row],[Nom de l''échantillon donné par le client]],liste_groupe[[#This Row],[Dopage (+Testostérone / + EE2, ….)]]),CONCATENATE(liste_groupe[[#This Row],[Nom de l''échantillon donné par le client]],"-",liste_groupe[[#This Row],[Concentration]],liste_groupe[[#This Row],[Unité]],liste_groupe[[#This Row],[Dopage (+Testostérone / + EE2, ….)]])))
A22: =IF(ISBLANK(liste_groupe[[#This Row],[Code WF]])," ",IF(ISBLANK(liste_groupe[[#This Row],[Unité]]),CONCATENATE(liste_groupe[[#This Row],[Nom de l''échantillon donné par le client]],liste_groupe[[#This Row],[Dopage (+Testostérone / + EE2, ….)]]),CONCATENATE(liste_groupe[[#This Row],[Nom de l''échantillon donné par le client]],"-",liste_groupe[[#This Row],[Concentration]],liste_groupe[[#This Row],[Unité]],liste_groupe[[#This Row],[Dopage (+Testostérone / + EE2, ….)]])))
A23: =IF(ISBLANK(liste_groupe[[#This Row],[Code WF]])," ",IF(ISBLANK(liste_groupe[[#This Row],[Unité]]),CONCATENATE(liste_groupe[[#This Row],[Nom de l''échantillon donné par le client]],liste_groupe[[#This Row],[Dopage (+Testostérone / + EE2, ….)]]),CONCATENATE(liste_groupe[[#This Row],[Nom de l''échantillon donné par le client]],"-",liste_groupe[[#This Row],[Concentration]],liste_groupe[[#This Row],[Unité]],liste_groupe[[#This Row],[Dopage (+Testostérone / + EE2, ….)]])))
A24: =IF(ISBLANK(liste_groupe[[#This Row],[Code WF]])," ",IF(ISBLANK(liste_groupe[[#This Row],[Unité]]),CONCATENATE(liste_groupe[[#This Row],[Nom de l''échantillon donné par le client]],liste_groupe[[#This Row],[Dopage (+Testostérone / + EE2, ….)]]),CONCATENATE(liste_groupe[[#This Row],[Nom de l''échantillon donné par le client]],"-",liste_groupe[[#This Row],[Concentration]],liste_groupe[[#This Row],[Unité]],liste_groupe[[#This Row],[Dopage (+Testostérone / + EE2, ….)]])))
A25: =IF(ISBLANK(liste_groupe[[#This Row],[Code WF]])," ",IF(ISBLANK(liste_groupe[[#This Row],[Unité]]),CONCATENATE(liste_groupe[[#This Row],[Nom de l''échantillon donné par le client]],liste_groupe[[#This Row],[Dopage (+Testostérone / + EE2, ….)]]),CONCATENATE(liste_groupe[[#This Row],[Nom de l''échantillon donné par le client]],"-",liste_groupe[[#This Row],[Concentration]],liste_groupe[[#This Row],[Unité]],liste_groupe[[#This Row],[Dopage (+Testostérone / + EE2, ….)]])))
A26: =IF(ISBLANK(liste_groupe[[#This Row],[Code WF]])," ",IF(ISBLANK(liste_groupe[[#This Row],[Unité]]),CONCATENATE(liste_groupe[[#This Row],[Nom de l''échantillon donné par le client]],liste_groupe[[#This Row],[Dopage (+Testostérone / + EE2, ….)]]),CONCATENATE(liste_groupe[[#This Row],[Nom de l''échantillon donné par le client]],"-",liste_groupe[[#This Row],[Concentration]],liste_groupe[[#This Row],[Unité]],liste_groupe[[#This Row],[Dopage (+Testostérone / + EE2, ….)]])))
A27: =IF(ISBLANK(liste_groupe[[#This Row],[Code WF]])," ",IF(ISBLANK(liste_groupe[[#This Row],[Unité]]),CONCATENATE(liste_groupe[[#This Row],[Nom de l''échantillon donné par le client]],liste_groupe[[#This Row],[Dopage (+Testostérone / + EE2, ….)]]),CONCATENATE(liste_groupe[[#This Row],[Nom de l''échantillon donné par le client]],"-",liste_groupe[[#This Row],[Concentration]],liste_groupe[[#This Row],[Unité]],liste_groupe[[#This Row],[Dopage (+Testostérone / + EE2, ….)]])))
A28: =IF(ISBLANK(liste_groupe[[#This Row],[Code WF]])," ",IF(ISBLANK(liste_groupe[[#This Row],[Unité]]),CONCATENATE(liste_groupe[[#This Row],[Nom de l''échantillon donné par le client]],liste_groupe[[#This Row],[Dopage (+Testostérone / + EE2, ….)]]),CONCATENATE(liste_groupe[[#This Row],[Nom de l''échantillon donné par le client]],"-",liste_groupe[[#This Row],[Concentration]],liste_groupe[[#This Row],[Unité]],liste_groupe[[#This Row],[Dopage (+Testostérone / + EE2, ….)]])))
A29: =IF(ISBLANK(liste_groupe[[#This Row],[Code WF]])," ",IF(ISBLANK(liste_groupe[[#This Row],[Unité]]),CONCATENATE(liste_groupe[[#This Row],[Nom de l''échantillon donné par le client]],liste_groupe[[#This Row],[Dopage (+Testostérone / + EE2, ….)]]),CONCATENATE(liste_groupe[[#This Row],[Nom de l''échantillon donné par le client]],"-",liste_groupe[[#This Row],[Concentration]],liste_groupe[[#This Row],[Unité]],liste_groupe[[#This Row],[Dopage (+Testostérone / + EE2, ….)]])))
A30: =IF(ISBLANK(liste_groupe[[#This Row],[Code WF]])," ",IF(ISBLANK(liste_groupe[[#This Row],[Unité]]),CONCATENATE(liste_groupe[[#This Row],[Nom de l''échantillon donné par le client]],liste_groupe[[#This Row],[Dopage (+Testostérone / + EE2, ….)]]),CONCATENATE(liste_groupe[[#This Row],[Nom de l''échantillon donné par le client]],"-",liste_groupe[[#This Row],[Concentration]],liste_groupe[[#This Row],[Unité]],liste_groupe[[#This Row],[Dopage (+Testostérone / + EE2, ….)]])))
A31: =IF(ISBLANK(liste_groupe[[#This Row],[Code WF]])," ",IF(ISBLANK(liste_groupe[[#This Row],[Unité]]),CONCATENATE(liste_groupe[[#This Row],[Nom de l''échantillon donné par le client]],liste_groupe[[#This Row],[Dopage (+Testostérone / + EE2, ….)]]),CONCATENATE(liste_groupe[[#This Row],[Nom de l''échantillon donné par le client]],"-",liste_groupe[[#This Row],[Concentration]],liste_groupe[[#This Row],[Unité]],liste_groupe[[#This Row],[Dopage (+Testostérone / + EE2, ….)]])))
... A35: =IF(ISBLANK(liste_groupe[[#This Row],[Code WF]])," ",IF(ISBLANK(liste_groupe[[#This Row],[Unité]]),CONCATENATE(liste_groupe[[#This Row],[Nom de l''échantillon donné par le client]],liste_groupe[[#This Row],[Dopage (+Testostérone / + EE2, ….)]]),CONCATENATE(liste_groupe[[#This Row],[Nom de l''échantillon donné par le client]],"-",liste_groupe[[#This Row],[Concentration]],liste_groupe[[#This Row],[Unité]],liste_groupe[[#This Row],[Dopage (+Testostérone / + EE2, ….)]])))
A36: =IF(ISBLANK(liste_groupe[[#This Row],[Code WF]])," ",IF(ISBLANK(liste_groupe[[#This Row],[Unité]]),CONCATENATE(liste_groupe[[#This Row],[Nom de l''échantillon donné par le client]],liste_groupe[[#This Row],[Dopage (+Testostérone / + EE2, ….)]]),CONCATENATE(liste_groupe[[#This Row],[Nom de l''échantillon donné par le client]],"-",liste_groupe[[#This Row],[Concentration]],liste_groupe[[#This Row],[Unité]],liste_groupe[[#This Row],[Dopage (+Testostérone / + EE2, ….)]]))) -> Testo -30µg/L | B36: Témoin | C36: 30 | D36: µg/L | E36: Testo
A37: =IF(ISBLANK(liste_groupe[[#This Row],[Code WF]])," ",IF(ISBLANK(liste_groupe[[#This Row],[Unité]]),CONCATENATE(liste_groupe[[#This Row],[Nom de l''échantillon donné par le client]],liste_groupe[[#This Row],[Dopage (+Testostérone / + EE2, ….)]]),CONCATENATE(liste_groupe[[#This Row],[Nom de l''échantillon donné par le client]],"-",liste_groupe[[#This Row],[Concentration]],liste_groupe[[#This Row],[Unité]],liste_groupe[[#This Row],[Dopage (+Testostérone / + EE2, ….)]]))) -> Testo 30µg/L + EE2 -64ng/L | B37: Témoin | C37: 64 | D37: ng/L | E37: Testo 30µg/L + EE2
A38: =IF(ISBLANK(liste_groupe[[#This Row],[Code WF]])," ",IF(ISBLANK(liste_groupe[[#This Row],[Unité]]),CONCATENATE(liste_groupe[[#This Row],[Nom de l''échantillon donné par le client]],liste_groupe[[#This Row],[Dopage (+Testostérone / + EE2, ….)]]),CONCATENATE(liste_groupe[[#This Row],[Nom de l''échantillon donné par le client]],"-",liste_groupe[[#This Row],[Concentration]],liste_groupe[[#This Row],[Unité]],liste_groupe[[#This Row],[Dopage (+Testostérone / + EE2, ….)]]))) -> Testo 30µg/L + FAD-10µg/L | B38: Témoin | C38: 10 | D38: µg/L | E38: Testo 30µg/L + FAD
A39: =IF(ISBLANK(liste_groupe[[#This Row],[Code WF]])," ",IF(ISBLANK(liste_groupe[[#This Row],[Unité]]),CONCATENATE(liste_groupe[[#This Row],[Nom de l''échantillon donné par le client]],liste_groupe[[#This Row],[Dopage (+Testostérone / + EE2, ….)]]),CONCATENATE(liste_groupe[[#This Row],[Nom de l''échantillon donné par le client]],"-",liste_groupe[[#This Row],[Concentration]],liste_groupe[[#This Row],[Unité]],liste_groupe[[#This Row],[Dopage (+Testostérone / + EE2, ….)]]))) -> Testosterone-3.7µg/L + Testostérone | B39: =B15 -> Test | C39: =C15 -> 3.7 | D39: =D15 -> µg/L | E39: =E15 -> Testosterone | F39: + Testostérone
A40: =IF(ISBLANK(liste_groupe[[#This Row],[Code WF]])," ",IF(ISBLANK(liste_groupe[[#This Row],[Unité]]),CONCATENATE(liste_groupe[[#This Row],[Nom de l''échantillon donné par le client]],liste_groupe[[#This Row],[Dopage (+Testostérone / + EE2, ….)]]),CONCATENATE(liste_groupe[[#This Row],[Nom de l''échantillon donné par le client]],"-",liste_groupe[[#This Row],[Concentration]],liste_groupe[[#This Row],[Unité]],liste_groupe[[#This Row],[Dopage (+Testostérone / + EE2, ….)]]))) -> Testosterone-11µg/L + Testostérone | B40: =B16 -> Test | C40: =C16 -> 11 | D40: =D16 -> µg/L | E40: =E16 -> Testosterone | F40: + Testostérone
A41: =IF(ISBLANK(liste_groupe[[#This Row],[Code WF]])," ",IF(ISBLANK(liste_groupe[[#This Row],[Unité]]),CONCATENATE(liste_groupe[[#This Row],[Nom de l''échantillon donné par le client]],liste_groupe[[#This Row],[Dopage (+Testostérone / + EE2, ….)]]),CONCATENATE(liste_groupe[[#This Row],[Nom de l''échantillon donné par le client]],"-",liste_groupe[[#This Row],[Concentration]],liste_groupe[[#This Row],[Unité]],liste_groupe[[#This Row],[Dopage (+Testostérone / + EE2, ….)]]))) -> Testosterone-33µg/L + Testostérone | B41: =B17 -> Test | C41: =C17 -> 33 | D41: =D17 -> µg/L | E41: =E17 -> Testosterone | F41: + Testostérone
A42: =IF(ISBLANK(liste_groupe[[#This Row],[Code WF]])," ",IF(ISBLANK(liste_groupe[[#This Row],[Unité]]),CONCATENATE(liste_groupe[[#This Row],[Nom de l''échantillon donné par le client]],liste_groupe[[#This Row],[Dopage (+Testostérone / + EE2, ….)]]),CONCATENATE(liste_groupe[[#This Row],[Nom de l''échantillon donné par le client]],"-",liste_groupe[[#This Row],[Concentration]],liste_groupe[[#This Row],[Unité]],liste_groupe[[#This Row],[Dopage (+Testostérone / + EE2, ….)]]))) -> Testosterone-100µg/L + Testostérone | B42: =B18 -> Test | C42: =C18 -> 100 | D42: =D18 -> µg/L | E42: =E18 -> Testosterone | F42: + Testostérone
A43: =IF(ISBLANK(liste_groupe[[#This Row],[Code WF]])," ",IF(ISBLANK(liste_groupe[[#This Row],[Unité]]),CONCATENATE(liste_groupe[[#This Row],[Nom de l''échantillon donné par le client]],liste_groupe[[#This Row],[Dopage (+Testostérone / + EE2, ….)]]),CONCATENATE(liste_groupe[[#This Row],[Nom de l''échantillon donné par le client]],"-",liste_groupe[[#This Row],[Concentration]],liste_groupe[[#This Row],[Unité]],liste_groupe[[#This Row],[Dopage (+Testostérone / + EE2, ….)]]))) -> Testosterone-300µg/L + Testostérone | B43: =B19 -> Test | C43: =C19 -> 300 | D43: =D19 -> µg/L | E43: =E19 -> Testosterone | F43: + Testostérone
...

Sheet Feuil1
A1: Nom groupe | B1: N° de valeur | C1: file name | D1: total area | E1: mean intensity | G1: total fluorescence | I1: nbre de larves
A2: 01 EE2 0 | B2: A | C2: C:\Users\Olympus\Desktop\20190122\plaque1/@01 EE2 0/A1_1.tif | D2: 4931.616 | E2: 73.0526 | G2: 360268
A3: 01 EE2 0 | B3: A | C3: C:\Users\Olympus\Desktop\20190122\plaque1/@01 EE2 0/A1_2.tif | D3: 5234.4345 | E3: 71.1281 | G3: 372315
A4: 01 EE2 0 | B4: A | C4: C:\Users\Olympus\Desktop\20190122\plaque1/@01 EE2 0/A1_3.tif | D4: 3547.3027 | E4: 66.9878 | G4: 237626
A5: 01 EE2 0 | B5: A | C5: C:\Users\Olympus\Desktop\20190122\plaque3/@01 EE2 0/A1_3.tif | D5: 21456.8555 | E5: 67.0655 | G5: 1439015
A6: 01 EE2 0 | B6: A | C6: C:\Users\Olympus\Desktop\20190122\plaque3/@01 EE2 0/A1_2.tif | D6: 21586.6348 | E6: 66.4108 | G6: 1433586
A7: 01 EE2 0 | B7: A | C7: C:\Users\Olympus\Desktop\20190122\plaque3/@01 EE2 0/A1_1.tif | D7: 15984.4921 | E7: 69.7767 | G7: 1115346

Sheet Raw data R1
A1: Nom groupe | B1: N° de valeur | C1: file name | D1: total area | E1: mean intensity | G1: total fluorescence | I1: nbre de larves | L1: (Tous)
A2: =IFERROR(LEFT(RIGHT(C2,LEN(C2)-SEARCH("@",C2)),SEARCH("/",RIGHT(C2,LEN(C2)-SEARCH("@",C2)-1))),"") | B2: =LEFT(RIGHT(RIGHT(Tableau4[[#This Row],[file name]],LEN(Tableau4[[#This Row],[file name]])-SEARCH("@",Tableau4[[#This Row],[file name]])),LEN(RIGHT(Tableau4[[#This Row],[file name]],LEN(Tableau4[[#This Row],[file name]])-SEARCH("@",Tableau4[[#This Row],[file name]])))-SEARCH("/",RIGHT(Tableau4[[#This Row],[file name]],LEN(Tableau4[[#This Row],[file name]])-SEARCH("@",Tableau4[[#This Row],[file name]])))),1) -> #VALUE! | K2: Filtre lignes : Enlever (vide) et Néant | L2: Filtre colonnes : Enlever (vide) et " "
A3: =IFERROR(LEFT(RIGHT(C3,LEN(C3)-SEARCH("@",C3)),SEARCH("/",RIGHT(C3,LEN(C3)-SEARCH("@",C3)-1))),"") | B3: =LEFT(RIGHT(RIGHT(Tableau4[[#This Row],[file name]],LEN(Tableau4[[#This Row],[file name]])-SEARCH("@",Tableau4[[#This Row],[file name]])),LEN(RIGHT(Tableau4[[#This Row],[file name]],LEN(Tableau4[[#This Row],[file name]])-SEARCH("@",Tableau4[[#This Row],[file name]])))-SEARCH("/",RIGHT(Tableau4[[#This Row],[file name]],LEN(Tableau4[[#This Row],[file name]])-SEARCH("@",Tableau4[[#This Row],[file name]])))),1) -> #VALUE! | K3: Moyenne de total fluorescence | L3: Étiquettes de colonnes
A4: =IFERROR(LEFT(RIGHT(C4,LEN(C4)-SEARCH("@",C4)),SEARCH("/",RIGHT(C4,LEN(C4)-SEARCH("@",C4)-1))),"") | B4: =LEFT(RIGHT(RIGHT(Tableau4[[#This Row],[file name]],LEN(Tableau4[[#This Row],[file name]])-SEARCH("@",Tableau4[[#This Row],[file name]])),LEN(RIGHT(Tableau4[[#This Row],[file name]],LEN(Tableau4[[#This Row],[file name]])-SEARCH("@",Tableau4[[#This Row],[file name]])))-SEARCH("/",RIGHT(Tableau4[[#This Row],[file name]],LEN(Tableau4[[#This Row],[file name]])-SEARCH("@",Tableau4[[#This Row],[file name]])))),1) -> #VALUE! | K4: Étiquettes de lignes
A5: =IFERROR(LEFT(RIGHT(C5,LEN(C5)-SEARCH("@",C5)),SEARCH("/",RIGHT(C5,LEN(C5)-SEARCH("@",C5)-1))),"") | B5: =LEFT(RIGHT(RIGHT(Tableau4[[#This Row],[file name]],LEN(Tableau4[[#This Row],[file name]])-SEARCH("@",Tableau4[[#This Row],[file name]])),LEN(RIGHT(Tableau4[[#This Row],[file name]],LEN(Tableau4[[#This Row],[file name]])-SEARCH("@",Tableau4[[#This Row],[file name]])))-SEARCH("/",RIGHT(Tableau4[[#This Row],[file name]],LEN(Tableau4[[#This Row],[file name]])-SEARCH("@",Tableau4[[#This Row],[file name]])))),1) -> #VALUE! | K5: #VALEUR!
A6: =IFERROR(LEFT(RIGHT(C6,LEN(C6)-SEARCH("@",C6)),SEARCH("/",RIGHT(C6,LEN(C6)-SEARCH("@",C6)-1))),"") | B6: =LEFT(RIGHT(RIGHT(Tableau4[[#This Row],[file name]],LEN(Tableau4[[#This Row],[file name]])-SEARCH("@",Tableau4[[#This Row],[file name]])),LEN(RIGHT(Tableau4[[#This Row],[file name]],LEN(Tableau4[[#This Row],[file name]])-SEARCH("@",Tableau4[[#This Row],[file name]])))-SEARCH("/",RIGHT(Tableau4[[#This Row],[file name]],LEN(Tableau4[[#This Row],[file name]])-SEARCH("@",Tableau4[[#This Row],[file name]])))),1) -> #VALUE!
A7: =IFERROR(LEFT(RIGHT(C7,LEN(C7)-SEARCH("@",C7)),SEARCH("/",RIGHT(C7,LEN(C7)-SEARCH("@",C7)-1))),"") | B7: =LEFT(RIGHT(RIGHT(Tableau4[[#This Row],[file name]],LEN(Tableau4[[#This Row],[file name]])-SEARCH("@",Tableau4[[#This Row],[file name]])),LEN(RIGHT(Tableau4[[#This Row],[file name]],LEN(Tableau4[[#This Row],[file name]])-SEARCH("@",Tableau4[[#This Row],[file name]])))-SEARCH("/",RIGHT(Tableau4[[#This Row],[file name]],LEN(Tableau4[[#This Row],[file name]])-SEARCH("@",Tableau4[[#This Row],[file name]])))),1) -> #VALUE!
A8: =IFERROR(LEFT(RIGHT(C8,LEN(C8)-SEARCH("@",C8)),SEARCH("/",RIGHT(C8,LEN(C8)-SEARCH("@",C8)-1))),"") | B8: =LEFT(RIGHT(RIGHT(Tableau4[[#This Row],[file name]],LEN(Tableau4[[#This Row],[file name]])-SEARCH("@",Tableau4[[#This Row],[file name]])),LEN(RIGHT(Tableau4[[#This Row],[file name]],LEN(Tableau4[[#This Row],[file name]])-SEARCH("@",Tableau4[[#This Row],[file name]])))-SEARCH("/",RIGHT(Tableau4[[#This Row],[file name]],LEN(Tableau4[[#This Row],[file name]])-SEARCH("@",Tableau4[[#This Row],[file name]])))),1) -> #VALUE!
A9: =IFERROR(LEFT(RIGHT(C9,LEN(C9)-SEARCH("@",C9)),SEARCH("/",RIGHT(C9,LEN(C9)-SEARCH("@",C9)-1))),"") | B9: =LEFT(RIGHT(RIGHT(Tableau4[[#This Row],[file name]],LEN(Tableau4[[#This Row],[file name]])-SEARCH("@",Tableau4[[#This Row],[file name]])),LEN(RIGHT(Tableau4[[#This Row],[file name]],LEN(Tableau4[[#This Row],[file name]])-SEARCH("@",Tableau4[[#This Row],[file name]])))-SEARCH("/",RIGHT(Tableau4[[#This Row],[file name]],LEN(Tableau4[[#This Row],[file name]])-SEARCH("@",Tableau4[[#This Row],[file name]])))),1) -> #VALUE!
A10: =IFERROR(LEFT(RIGHT(C10,LEN(C10)-SEARCH("@",C10)),SEARCH("/",RIGHT(C10,LEN(C10)-SEARCH("@",C10)-1))),"") | B10: =LEFT(RIGHT(RIGHT(Tableau4[[#This Row],[file name]],LEN(Tableau4[[#This Row],[file name]])-SEARCH("@",Tableau4[[#This Row],[file name]])),LEN(RIGHT(Tableau4[[#This Row],[file name]],LEN(Tableau4[[#This Row],[file name]])-SEARCH("@",Tableau4[[#This Row],[file name]])))-SEARCH("/",RIGHT(Tableau4[[#This Row],[file name]],LEN(Tableau4[[#This Row],[file name]])-SEARCH("@",Tableau4[[#This Row],[file name]])))),1) -> #VALUE!
A11: =IFERROR(LEFT(RIGHT(C11,LEN(C11)-SEARCH("@",C11)),SEARCH("/",RIGHT(C11,LEN(C11)-SEARCH("@",C11)-1))),"") | B11: =LEFT(RIGHT(RIGHT(Tableau4[[#This Row],[file name]],LEN(Tableau4[[#This Row],[file name]])-SEARCH("@",Tableau4[[#This Row],[file name]])),LEN(RIGHT(Tableau4[[#This Row],[file name]],LEN(Tableau4[[#This Row],[file name]])-SEARCH("@",Tableau4[[#This Row],[file name]])))-SEARCH("/",RIGHT(Tableau4[[#This Row],[file name]],LEN(Tableau4[[#This Row],[file name]])-SEARCH("@",Tableau4[[#This Row],[file name]])))),1) -> #VALUE!
A12: =IFERROR(LEFT(RIGHT(C12,LEN(C12)-SEARCH("@",C12)),SEARCH("/",RIGHT(C12,LEN(C12)-SEARCH("@",C12)-1))),"") | B12: =LEFT(RIGHT(RIGHT(Tableau4[[#This Row],[file name]],LEN(Tableau4[[#This Row],[file name]])-SEARCH("@",Tableau4[[#This Row],[file name]])),LEN(RIGHT(Tableau4[[#This Row],[file name]],LEN(Tableau4[[#This Row],[file name]])-SEARCH("@",Tableau4[[#This Row],[file name]])))-SEARCH("/",RIGHT(Tableau4[[#This Row],[file name]],LEN(Tableau4[[#This Row],[file name]])-SEARCH("@",Tableau4[[#This Row],[file name]])))),1) -> #VALUE!
A13: =IFERROR(LEFT(RIGHT(C13,LEN(C13)-SEARCH("@",C13)),SEARCH("/",RIGHT(C13,LEN(C13)-SEARCH("@",C13)-1))),"") | B13: =LEFT(RIGHT(RIGHT(Tableau4[[#This Row],[file name]],LEN(Tableau4[[#This Row],[file name]])-SEARCH("@",Tableau4[[#This Row],[file name]])),LEN(RIGHT(Tableau4[[#This Row],[file name]],LEN(Tableau4[[#This Row],[file name]])-SEARCH("@",Tableau4[[#This Row],[file name]])))-SEARCH("/",RIGHT(Tableau4[[#This Row],[file name]],LEN(Tableau4[[#This Row],[file name]])-SEARCH("@",Tableau4[[#This Row],[file name]])))),1) -> #VALUE!
A14: =IFERROR(LEFT(RIGHT(C14,LEN(C14)-SEARCH("@",C14)),SEARCH("/",RIGHT(C14,LEN(C14)-SEARCH("@",C14)-1))),"") | B14: =LEFT(RIGHT(RIGHT(Tableau4[[#This Row],[file name]],LEN(Tableau4[[#This Row],[file name]])-SEARCH("@",Tableau4[[#This Row],[file name]])),LEN(RIGHT(Tableau4[[#This Row],[file name]],LEN(Tableau4[[#This Row],[file name]])-SEARCH("@",Tableau4[[#This Row],[file name]])))-SEARCH("/",RIGHT(Tableau4[[#This Row],[file name]],LEN(Tableau4[[#This Row],[file name]])-SEARCH("@",Tableau4[[#This Row],[file name]])))),1) -> #VALUE!
A15: =IFERROR(LEFT(RIGHT(C15,LEN(C15)-SEARCH("@",C15)),SEARCH("/",RIGHT(C15,LEN(C15)-SEARCH("@",C15)-1))),"") | B15: =LEFT(RIGHT(RIGHT(Tableau4[[#This Row],[file name]],LEN(Tableau4[[#This Row],[file name]])-SEARCH("@",Tableau4[[#This Row],[file name]])),LEN(RIGHT(Tableau4[[#This Row],[file name]],LEN(Tableau4[[#This Row],[file name]])-SEARCH("@",Tableau4[[#This Row],[file name]])))-SEARCH("/",RIGHT(Tableau4[[#This Row],[file name]],LEN(Tableau4[[#This Row],[file name]])-SEARCH("@",Tableau4[[#This Row],[file name]])))),1) -> #VALUE!
A16: =IFERROR(LEFT(RIGHT(C16,LEN(C16)-SEARCH("@",C16)),SEARCH("/",RIGHT(C16,LEN(C16)-SEARCH("@",C16)-1))),"") | B16: =LEFT(RIGHT(RIGHT(Tableau4[[#This Row],[file name]],LEN(Tableau4[[#This Row],[file name]])-SEARCH("@",Tableau4[[#This Row],[file name]])),LEN(RIGHT(Tableau4[[#This Row],[file name]],LEN(Tableau4[[#This Row],[file name]])-SEARCH("@",Tableau4[[#This Row],[file name]])))-SEARCH("/",RIGHT(Tableau4[[#This Row],[file name]],LEN(Tableau4[[#This Row],[file name]])-SEARCH("@",Tableau4[[#This Row],[file name]])))),1) -> #VALUE!
A17: =IFERROR(LEFT(RIGHT(C17,LEN(C17)-SEARCH("@",C17)),SEARCH("/",RIGHT(C17,LEN(C17)-SEARCH("@",C17)-1))),"") | B17: =LEFT(RIGHT(RIGHT(Tableau4[[#This Row],[file name]],LEN(Tableau4[[#This Row],[file name]])-SEARCH("@",Tableau4[[#This Row],[file name]])),LEN(RIGHT(Tableau4[[#This Row],[file name]],LEN(Tableau4[[#This Row],[file name]])-SEARCH("@",Tableau4[[#This Row],[file name]])))-SEARCH("/",RIGHT(Tableau4[[#This Row],[file name]],LEN(Tableau4[[#This Row],[file name]])-SEARCH("@",Tableau4[[#This Row],[file name]])))),1) -> #VALUE!
... A1557: =IFERROR(LEFT(RIGHT(C1557,LEN(C1557)-SEARCH("@",C1557)),SEARCH("/",RIGHT(C1557,LEN(C1557)-SEARCH("@",C1557)-1))),"") | B1557: =LEFT(RIGHT(RIGHT(Tableau4[[#This Row],[file name]],LEN(Tableau4[[#This Row],[file name]])-SEARCH("@",Tableau4[[#This Row],[file name]])),LEN(RIGHT(Tableau4[[#This Row],[file name]],LEN(Tableau4[[#This Row],[file name]])-SEARCH("@",Tableau4[[#This Row],[file name]])))-SEARCH("/",RIGHT(Tableau4[[#This Row],[file name]],LEN(Tableau4[[#This Row],[file name]])-SEARCH("@",Tableau4[[#This Row],[file name]])))),1) -> #VALUE!

Sheet R1
A1: 3. Expérimentateur 1 : copier et coller les valeurs des intensités totales de fluorescences obtenues dans le fichier raw data lors du traitement des images.
A3: R1 | B3: Non dopé | O3: avec testo
A4: Noms des groupes | B4: ='Page de garde'!A7 -> Témoin solvant | C4: ='Page de garde'!A9 -> EE2-33.8ng/L | D4: ='Page de garde'!A10 -> EE2-50.6ng/L | E4: ='Page de garde'!A11 -> EE2-76ng/L | F4: ='Page de garde'!A12 -> EE2-114ng/L | G4: ='Page de garde'!A13 -> EE2-170.9ng/L | H4: ='Page de garde'!A14 -> EE2-488ng/L | I4: ='Page de garde'!A15 -> Testosterone-3.7µg/L | J4: ='Page de garde'!A16 -> Testosterone-11µg/L | K4: ='Page de garde'!A17 -> Testosterone-33µg/L | L4: ='Page de garde'!A18 -> Testosterone-100µg/L | M4: ='Page de garde'!A19 -> Testosterone-300µg/L | O4: ='Page de garde'!A36 -> Testo -30µg/L | P4: ='Page de garde'!A37 -> Testo 30µg/L + EE2 -64ng/L | Q4: ='Page de garde'!A38 -> Testo 30µg/L + FAD-10µg/L | R4: ='Page de garde'!A39 -> Testosterone-3.7µg/L + Testostérone | S4: ='Page de garde'!A40 -> Testosterone-11µg/L + Testostérone | T4: ='Page de garde'!A41 -> Testosterone-33µg/L + Testostérone | U4: ='Page de garde'!A42 -> Testosterone-100µg/L + Testostérone | V4: ='Page de garde'!A43 -> Testosterone-300µg/L + Testostérone
A5: Données brutes | B5: 17374 | C5: 189468 | D5: 176613 | E5: 1286129 | F5: 864092 | G5: 6792474 | H5: 10942530 | I5: 40199 | J5: 444208 | K5: 5327003 | L5: 5349343 | M5: 10312573 | O5: 773933 | P5: 8825798 | Q5: 31019 | R5: 2489673 | S5: 1350543 | T5: 4896033 | U5: 1132463 | V5: 4894270
B6: 20947 | C6: 84617 | D6: 2742777 | E6: 1751175 | F6: 1650416 | G6: 4154047 | H6: 13853079 | I6: 1025236 | J6: 98601 | K6: 3082026 | L6: 6955081 | M6: 7295619 | O6: 406614 | P6: 5374976 | Q6: 13952 | R6: 3106291 | S6: 1073230 | T6: 3698377 | U6: 187598 | V6: 5870799
B7: 30810 | C7: 234889 | D7: 300649 | E7: 2425512 | F7: 8198043 | G7: 133239 | H7: 8380928 | I7: 159231 | J7: 205920 | K7: 281778 | L7: 3024790 | M7: 6139778 | O7: 129203 | P7: 10375356 | Q7: 92407 | R7: 1786438 | S7: 12604 | T7: 4891481 | U7: 2778292 | V7: 5475924
B8: 22392 | C8: 63231 | D8: 306782 | E8: 1031228 | F8: 4418159 | G8: 3734949 | H8: 10250432 | I8: 170298 | J8: 398472 | K8: 2351056 | L8: 5744424 | M8: 4811739 | O8: 635652 | P8: 2403596 | Q8: 72694 | R8: 322540 | S8: 1170923 | T8: 2168116 | U8: 5010261 | V8: 5172007
B9: 1511 | C9: 437352 | D9: 412966 | E9: 2719942 | F9: 2135639 | G9: 8110171 | H9: 8541636 | I9: 55990 | J9: 71952 | K9: 330504 | L9: 4023424 | M9: 4304565 | O9: 1651235 | P9: 8572502 | Q9: 60618 | R9: 2485145 | S9: 734722 | T9: 1455097 | U9: 4212149 | V9: 2338200
B10: 13818 | C10: 100682 | D10: 239493 | E10: 131404 | F10: 15382011 | G10: 16294656 | H10: 16067774 | I10: 684146 | J10: 51304 | K10: 477304 | L10: 7157800 | M10: 3615546 | O10: 124184 | P10: 2167242 | Q10: 35268 | R10: 495774 | S10: 247023 | T10: 2612 | U10: 3318559 | V10: 7072356
B11: 289405 | C11: 25908 | D11: 3381637 | E11: 660693 | F11: 5689978 | G11: 1071942 | H11: 3424252 | I11: 911960 | J11: 127971 | K11: 507455 | L11: 2436494 | M11: 1811868 | O11: 1546961 | P11: 6124968 | Q11: 61325 | R11: 3397081 | S11: 1473565 | T11: 1146256 | U11: 4736679 | V11: 5264680
B12: 157177 | C12: 80744 | D12: 3915144 | E12: 2137158 | G12: 6463121 | H12: 11916667 | I12: 47242 | J12: 273332 | K12: 2545975 | L12: 3483109 | M12: 4515192 | O12: 47156 | P12: 5974837 | Q12: 127730 | R12: 1492479 | S12: 999544 | T12: 2223078 | U12: 5898725 | V12: 6292551
O13: 423047
O14: 19608
O15: 478755
O16: 409158
O17: 2143140
O18: 9659
O19: 173567
O20: 833028
A22: =A4 -> Noms des groupes | B22: =B4 -> Témoin solvant | C22: =C4 -> EE2-33.8ng/L | D22: =D4 -> EE2-50.6ng/L | E22: =E4 -> EE2-76ng/L | F22: =F4 -> EE2-114ng/L | G22: =G4 -> EE2-170.9ng/L | H22: =H4 -> EE2-488ng/L | ... M22: =M4 -> Testosterone-300µg/L | N22: Nom des groupes | O22: =O4 -> Testo -30µg/L | P22: =P4 -> Testo 30µg/L + EE2 -64ng/L | Q22: =Q4 -> Testo 30µg/L + FAD-10µg/L | R22: =R4 -> Testosterone-3.7µg/L + Testostérone | S22: =S4 -> Testosterone-11µg/L + Testostérone | T22: =T4 -> Testosterone-33µg/L + Testostérone | U22: =U4 -> Testosterone-100µg/L + Testostérone | V22: =V4 -> Testosterone-300µg/L + Testostérone
A23: mean | B23: =AVERAGE(B5:B20) -> 69179.25 | C23: =AVERAGE(C5:C20) -> 152111.38 | D23: =AVERAGE(D5:D20) -> 1434507.6 | E23: =AVERAGE(E5:E20) -> 1517905.1 | F23: =AVERAGE(F5:F20) -> 5476905.4 | G23: =AVERAGE(G5:G20) -> 5844324.9 | H23: =AVERAGE(H5:H20) -> 10422162 | I23: =AVERAGE(I5:I20) -> 386787.75 | ... M23: =AVERAGE(M5:M20) -> 5350860 | N23: mean | O23: =AVERAGE(O5:O20) -> 612806.25 | P23: =AVERAGE(P5:P20) -> 6227409.4 | Q23: =AVERAGE(Q5:Q20) -> 61876.625 | R23: =AVERAGE(R5:R20) -> 1946927.6 | S23: =AVERAGE(S5:S20) -> 882769.25 | T23: =AVERAGE(T5:T20) -> 2560131.2 | U23: =AVERAGE(U5:U20) -> 3409340.8 | V23: =AVERAGE(V5:V20) -> 5297598.4
A24: SD | B24: =STDEV(B5:B20) -> 101810.91 | C24: =STDEV(C5:C20) -> 134020.6 | D24: =STDEV(D5:D20) -> 1615449.7 | E24: =STDEV(E5:E20) -> 898753.47 | F24: =STDEV(F5:F20) -> 5062380.5 | G24: =STDEV(G5:G20) -> 5047262.6 | H24: =STDEV(H5:H20) -> 3833158 | I24: =STDEV(I5:I20) -> 416676.67 | ... M24: =STDEV(M5:M20) -> 2581322.5 | N24: SD | O24: =STDEV(O5:O20) -> 643274.65 | P24: =STDEV(P5:P20) -> 2960791 | Q24: =STDEV(Q5:Q20) -> 36536.98 | R24: =STDEV(R5:R20) -> 1134402.4 | S24: =STDEV(S5:S20) -> 518800.12 | T24: =STDEV(T5:T20) -> 1781474.6 | U24: =STDEV(U5:U20) -> 1968921.7 | V24: =STDEV(V5:V20) -> 1385518.1
B26: Non dopé | O26: avec testo
A27: Noms des groupes | B27: =B4 -> Témoin solvant | C27: =C4 -> EE2-33.8ng/L | D27: =D4 -> EE2-50.6ng/L | E27: =E4 -> EE2-76ng/L | F27: =F4 -> EE2-114ng/L | G27: =G4 -> EE2-170.9ng/L | H27: =H4 -> EE2-488ng/L | I27: =I4 -> Testosterone-3.7µg/L | ... M27: =M4 -> Testosterone-300µg/L | O27: =O4 -> Testo -30µg/L | P27: =P4 -> Testo 30µg/L + EE2 -64ng/L | Q27: =Q4 -> Testo 30µg/L + FAD-10µg/L | R27: =R4 -> Testosterone-3.7µg/L + Testostérone | S27: =S4 -> Testosterone-11µg/L + Testostérone | T27: =T4 -> Testosterone-33µg/L + Testostérone | U27: =U4 -> Testosterone-100µg/L + Testostérone | V27: =V4 -> Testosterone-300µg/L + Testostérone
A28: Données normalisées sur la moyenne du groupe "Testo" | B28: =IF(B5="","",(B5/$O$23)) -> 0.028351539 | C28: =IF(C5="","",(C5/$O$23)) -> 0.30918092 | D28: =IF(D5="","",(D5/$O$23)) -> 0.28820365 | E28: =IF(E5="","",(E5/$O$23)) -> 2.0987531 | F28: =IF(F5="","",(F5/$O$23)) -> 1.4100574 | G28: =IF(G5="","",(G5/$O$23)) -> 11.084211 | H28: =IF(H5="","",(H5/$O$23)) -> 17.856427 | I28: =IF(I5="","",(I5/$O$23)) -> 0.065598221 | ... M28: =IF(M5="","",(M5/$O$23)) -> 16.82844 | O28: =IF(O5="","",(O5/$O$23)) -> 1.2629326 | P28: =IF(P5="","",(P5/$O$23)) -> 14.402265 | Q28: =IF(Q5="","",(Q5/$O$23)) -> 0.050617956 | R28: =IF(R5="","",(R5/$O$23)) -> 4.0627409 | S28: =IF(S5="","",(S5/$O$23)) -> 2.2038662 | T28: =IF(T5="","",(T5/$O$23)) -> 7.9895285 | U28: =IF(U5="","",(U5/$O$23)) -> 1.8479952 | V28: =IF(V5="","",(V5/$O$23)) -> 7.9866516
B29: =IF(B6="","",(B6/$O$23)) -> 0.034182093 | C29: =IF(C6="","",(C6/$O$23)) -> 0.13808116 | D29: =IF(D6="","",(D6/$O$23)) -> 4.4757654 | E29: =IF(E6="","",(E6/$O$23)) -> 2.8576324 | F29: =IF(F6="","",(F6/$O$23)) -> 2.6932101 | G29: =IF(G6="","",(G6/$O$23)) -> 6.7787282 | H29: =IF(H6="","",(H6/$O$23)) -> 22.605969 | I29: =IF(I6="","",(I6/$O$23)) -> 1.6730182 | ... M29: =IF(M6="","",(M6/$O$23)) -> 11.905262 | O29: =IF(O6="","",(O6/$O$23)) -> 0.66352783 | P29: =IF(P6="","",(P6/$O$23)) -> 8.7710855 | Q29: =IF(Q6="","",(Q6/$O$23)) -> 0.022767392 | R29: =IF(R6="","",(R6/$O$23)) -> 5.068961 | S29: =IF(S6="","",(S6/$O$23)) -> 1.7513366 | T29: =IF(T6="","",(T6/$O$23)) -> 6.035149 | U29: =IF(U6="","",(U6/$O$23)) -> 0.30612938 | V29: =IF(V6="","",(V6/$O$23)) -> 9.5801879
B30: =IF(B7="","",(B7/$O$23)) -> 0.050276902 | C30: =IF(C7="","",(C7/$O$23)) -> 0.38330059 | D30: =IF(D7="","",(D7/$O$23)) -> 0.49061021 | E30: =IF(E7="","",(E7/$O$23)) -> 3.9580406 | F30: =IF(F7="","",(F7/$O$23)) -> 13.377871 | G30: =IF(G7="","",(G7/$O$23)) -> 0.21742435 | H30: =IF(H7="","",(H7/$O$23)) -> 13.67631 | I30: =IF(I7="","",(I7/$O$23)) -> 0.25983906 | ... M30: =IF(M7="","",(M7/$O$23)) -> 10.019118 | O30: =IF(O7="","",(O7/$O$23)) -> 0.21083825 | P30: =IF(P7="","",(P7/$O$23)) -> 16.930891 | Q30: =IF(Q7="","",(Q7/$O$23)) -> 0.15079317 | R30: =IF(R7="","",(R7/$O$23)) -> 2.9151759 | S30: =IF(S7="","",(S7/$O$23)) -> 0.020567675 | T30: =IF(T7="","",(T7/$O$23)) -> 7.9821004 | U30: =IF(U7="","",(U7/$O$23)) -> 4.5337201 | V30: =IF(V7="","",(V7/$O$23)) -> 8.9358162
B31: =IF(B8="","",(B8/$O$23)) -> 0.036540097 | C31: =IF(C8="","",(C8/$O$23)) -> 0.10318269 | D31: =IF(D8="","",(D8/$O$23)) -> 0.50061826 | E31: =IF(E8="","",(E8/$O$23)) -> 1.6827962 | F31: =IF(F8="","",(F8/$O$23)) -> 7.209716 | G31: =IF(G8="","",(G8/$O$23)) -> 6.0948285 | H31: =IF(H8="","",(H8/$O$23)) -> 16.727036 | I31: =IF(I8="","",(I8/$O$23)) -> 0.2778986 | ... M31: =IF(M8="","",(M8/$O$23)) -> 7.8519744 | O31: =IF(O8="","",(O8/$O$23)) -> 1.0372805 | P31: =IF(P8="","",(P8/$O$23)) -> 3.9222772 | Q31: =IF(Q8="","",(Q8/$O$23)) -> 0.11862477 | R31: =IF(R8="","",(R8/$O$23)) -> 0.52633275 | S31: =IF(S8="","",(S8/$O$23)) -> 1.9107556 | T31: =IF(T8="","",(T8/$O$23)) -> 3.5380122 | U31: =IF(U8="","",(U8/$O$23)) -> 8.17593 | V31: =IF(V8="","",(V8/$O$23)) -> 8.4398731
B32: =IF(B9="","",(B9/$O$23)) -> 0.0024657059 | C32: =IF(C9="","",(C9/$O$23)) -> 0.71368724 | D32: =IF(D9="","",(D9/$O$23)) -> 0.67389326 | E32: =IF(E9="","",(E9/$O$23)) -> 4.4385024 | F32: =IF(F9="","",(F9/$O$23)) -> 3.485015 | G32: =IF(G9="","",(G9/$O$23)) -> 13.234478 | H32: =IF(H9="","",(H9/$O$23)) -> 13.938559 | I32: =IF(I9="","",(I9/$O$23)) -> 0.091366562 | ... M32: =IF(M9="","",(M9/$O$23)) -> 7.024349 | O32: =IF(O9="","",(O9/$O$23)) -> 2.6945466 | P32: =IF(P9="","",(P9/$O$23)) -> 13.988927 | Q32: =IF(Q9="","",(Q9/$O$23)) -> 0.098918704 | R32: =IF(R9="","",(R9/$O$23)) -> 4.0553519 | S32: =IF(S9="","",(S9/$O$23)) -> 1.1989466 | T32: =IF(T9="","",(T9/$O$23)) -> 2.3744813 | U32: =IF(U9="","",(U9/$O$23)) -> 6.8735412 | V32: =IF(V9="","",(V9/$O$23)) -> 3.8155616
B33: =IF(B10="","",(B10/$O$23)) -> 0.022548726 | C33: =IF(C10="","",(C10/$O$23)) -> 0.16429663 | D33: =IF(D10="","",(D10/$O$23)) -> 0.39081357 | E33: =IF(E10="","",(E10/$O$23)) -> 0.21442993 | F33: =IF(F10="","",(F10/$O$23)) -> 25.100937 | G33: =IF(G10="","",(G10/$O$23)) -> 26.590225 | H33: =IF(H10="","",(H10/$O$23)) -> 26.21999 | I33: =IF(I10="","",(I10/$O$23)) -> 1.1164149 | ... M33: =IF(M10="","",(M10/$O$23)) -> 5.8999823 | O33: =IF(O10="","",(O10/$O$23)) -> 0.20264806 | P33: =IF(P10="","",(P10/$O$23)) -> 3.536586 | Q33: =IF(Q10="","",(Q10/$O$23)) -> 0.057551632 | R33: =IF(R10="","",(R10/$O$23)) -> 0.80902243 | S33: =IF(S10="","",(S10/$O$23)) -> 0.40310131 | T33: =IF(T10="","",(T10/$O$23)) -> 0.0042623586 | U33: =IF(U10="","",(U10/$O$23)) -> 5.4153478 | V33: =IF(V10="","",(V10/$O$23)) -> 11.540933
B34: =IF(B11="","",(B11/$O$23)) -> 0.47226183 | C34: =IF(C11="","",(C11/$O$23)) -> 0.042277637 | D34: =IF(D11="","",(D11/$O$23)) -> 5.5182809 | E34: =IF(E11="","",(E11/$O$23)) -> 1.0781434 | F34: =IF(F11="","",(F11/$O$23)) -> 9.2851174 | G34: =IF(G11="","",(G11/$O$23)) -> 1.7492348 | H34: =IF(H11="","",(H11/$O$23)) -> 5.5878216 | I34: =IF(I11="","",(I11/$O$23)) -> 1.4881702 | ... M34: =IF(M11="","",(M11/$O$23)) -> 2.9566735 | O34: =IF(O11="","",(O11/$O$23)) -> 2.5243884 | P34: =IF(P11="","",(P11/$O$23)) -> 9.9949503 | Q34: =IF(Q11="","",(Q11/$O$23)) -> 0.10007241 | R34: =IF(R11="","",(R11/$O$23)) -> 5.543483 | S34: =IF(S11="","",(S11/$O$23)) -> 2.4046181 | T34: =IF(T11="","",(T11/$O$23)) -> 1.8705031 | U34: =IF(U11="","",(U11/$O$23)) -> 7.7294887 | V34: =IF(V11="","",(V11/$O$23)) -> 8.5911004
B35: =IF(B12="","",(B12/$O$23)) -> 0.25648727 | C35: =IF(C12="","",(C12/$O$23)) -> 0.13176106 | D35: =IF(D12="","",(D12/$O$23)) -> 6.3888774 | E35: =IF(E12="","",(E12/$O$23)) -> 3.4874938 | F35: =IF(F12="","",(F12/$O$23)) | G35: =IF(G12="","",(G12/$O$23)) -> 10.546761 | H35: =IF(H12="","",(H12/$O$23)) -> 19.44606 | I35: =IF(I12="","",(I12/$O$23)) -> 0.07709125 | ... M35: =IF(M12="","",(M12/$O$23)) -> 7.368058 | O35: =IF(O12="","",(O12/$O$23)) -> 0.076950912 | P35: =IF(P12="","",(P12/$O$23)) -> 9.7499609 | Q35: =IF(Q12="","",(Q12/$O$23)) -> 0.20843456 | R35: =IF(R12="","",(R12/$O$23)) -> 2.4354827 | S35: =IF(S12="","",(S12/$O$23)) -> 1.631093 | T35: =IF(T12="","",(T12/$O$23)) -> 3.6277013 | U35: =IF(U12="","",(U12/$O$23)) -> 9.6257585 | V35: =IF(V12="","",(V12/$O$23)) -> 10.268418
B36: =IF(B13="","",(B13/$O$23)) | C36: =IF(C13="","",(C13/$O$23)) | D36: =IF(D13="","",(D13/$O$23)) | E36: =IF(E13="","",(E13/$O$23)) | F36: =IF(F13="","",(F13/$O$23)) | G36: =IF(G13="","",(G13/$O$23)) | H36: =IF(H13="","",(H13/$O$23)) | I36: =IF(I13="","",(I13/$O$23)) | ... M36: =IF(M13="","",(M13/$O$23)) | O36: =IF(O13="","",(O13/$O$23)) -> 0.69034381 | P36: =IF(P13="","",(P13/$O$23)) | Q36: =IF(Q13="","",(Q13/$O$23)) | R36: =IF(R13="","",(R13/$O$23)) | S36: =IF(S13="","",(S13/$O$23)) | T36: =IF(T13="","",(T13/$O$23)) | U36: =IF(U13="","",(U13/$O$23)) | V36: =IF(V13="","",(V13/$O$23))
B37: =IF(B14="","",(B14/$O$23)) | C37: =IF(C14="","",(C14/$O$23)) | D37: =IF(D14="","",(D14/$O$23)) | E37: =IF(E14="","",(E14/$O$23)) | F37: =IF(F14="","",(F14/$O$23)) | G37: =IF(G14="","",(G14/$O$23)) | H37: =IF(H14="","",(H14/$O$23)) | I37: =IF(I14="","",(I14/$O$23)) | ... M37: =IF(M14="","",(M14/$O$23)) | O37: =IF(O14="","",(O14/$O$23)) -> 0.031997063 | P37: =IF(P14="","",(P14/$O$23)) | Q37: =IF(Q14="","",(Q14/$O$23)) | R37: =IF(R14="","",(R14/$O$23)) | S37: =IF(S14="","",(S14/$O$23)) | T37: =IF(T14="","",(T14/$O$23)) | U37: =IF(U14="","",(U14/$O$23)) | V37: =IF(V14="","",(V14/$O$23))
B38: =IF(B15="","",(B15/$O$23)) | C38: =IF(C15="","",(C15/$O$23)) | D38: =IF(D15="","",(D15/$O$23)) | E38: =IF(E15="","",(E15/$O$23)) | F38: =IF(F15="","",(F15/$O$23)) | G38: =IF(G15="","",(G15/$O$23)) | H38: =IF(H15="","",(H15/$O$23)) | I38: =IF(I15="","",(I15/$O$23)) | ... M38: =IF(M15="","",(M15/$O$23)) | O38: =IF(O15="","",(O15/$O$23)) -> 0.78125019 | P38: =IF(P15="","",(P15/$O$23)) | Q38: =IF(Q15="","",(Q15/$O$23)) | R38: =IF(R15="","",(R15/$O$23)) | S38: =IF(S15="","",(S15/$O$23)) | T38: =IF(T15="","",(T15/$O$23)) | U38: =IF(U15="","",(U15/$O$23)) | V38: =IF(V15="","",(V15/$O$23))
B39: =IF(B16="","",(B16/$O$23)) | C39: =IF(C16="","",(C16/$O$23)) | D39: =IF(D16="","",(D16/$O$23)) | E39: =IF(E16="","",(E16/$O$23)) | F39: =IF(F16="","",(F16/$O$23)) | G39: =IF(G16="","",(G16/$O$23)) | H39: =IF(H16="","",(H16/$O$23)) | I39: =IF(I16="","",(I16/$O$23)) | ... M39: =IF(M16="","",(M16/$O$23)) | O39: =IF(O16="","",(O16/$O$23)) -> 0.66767922 | P39: =IF(P16="","",(P16/$O$23)) | Q39: =IF(Q16="","",(Q16/$O$23)) | R39: =IF(R16="","",(R16/$O$23)) | S39: =IF(S16="","",(S16/$O$23)) | T39: =IF(T16="","",(T16/$O$23)) | U39: =IF(U16="","",(U16/$O$23)) | V39: =IF(V16="","",(V16/$O$23))
B40: =IF(B17="","",(B17/$O$23)) | C40: =IF(C17="","",(C17/$O$23)) | D40: =IF(D17="","",(D17/$O$23)) | E40: =IF(E17="","",(E17/$O$23)) | F40: =IF(F17="","",(F17/$O$23)) | G40: =IF(G17="","",(G17/$O$23)) | H40: =IF(H17="","",(H17/$O$23)) | I40: =IF(I17="","",(I17/$O$23)) | ... M40: =IF(M17="","",(M17/$O$23)) | O40: =IF(O17="","",(O17/$O$23)) -> 3.4972555 | P40: =IF(P17="","",(P17/$O$23)) | Q40: =IF(Q17="","",(Q17/$O$23)) | R40: =IF(R17="","",(R17/$O$23)) | S40: =IF(S17="","",(S17/$O$23)) | T40: =IF(T17="","",(T17/$O$23)) | U40: =IF(U17="","",(U17/$O$23)) | V40: =IF(V17="","",(V17/$O$23))
... B43: =IF(B20="","",(B20/$O$23)) | C43: =IF(C20="","",(C20/$O$23)) | D43: =IF(D20="","",(D20/$O$23)) | E43: =IF(E20="","",(E20/$O$23)) | F43: =IF(F20="","",(F20/$O$23)) | G43: =IF(G20="","",(G20/$O$23)) | H43: =IF(H20="","",(H20/$O$23)) | I43: =IF(I20="","",(I20/$O$23)) | ... M43: =IF(M20="","",(M20/$O$23)) | O43: =IF(O20="","",(O20/$O$23)) -> 1.359366 | P43: =IF(P20="","",(P20/$O$23)) | Q43: =IF(Q20="","",(Q20/$O$23)) | R43: =IF(R20="","",(R20/$O$23)) | S43: =IF(S20="","",(S20/$O$23)) | T43: =IF(T20="","",(T20/$O$23)) | U43: =IF(U20="","",(U20/$O$23)) | V43: =IF(V20="","",(V20/$O$23))
A45: =A4 -> Noms des groupes | B45: =B4 -> Témoin solvant | C45: =C4 -> EE2-33.8ng/L | D45: =D4 -> EE2-50.6ng/L | E45: =E4 -> EE2-76ng/L | F45: =F4 -> EE2-114ng/L | G45: =G4 -> EE2-170.9ng/L | H45: =H4 -> EE2-488ng/L | ... M45: =M4 -> Testosterone-300µg/L | N45: =N22 -> Nom des groupes | O45: =O4 -> Testo -30µg/L | P45: =P4 -> Testo 30µg/L + EE2 -64ng/L | Q45: =Q4 -> Testo 30µg/L + FAD-10µg/L | R45: =R4 -> Testosterone-3.7µg/L + Testostérone | S45: =S4 -> Testosterone-11µg/L + Testostérone | T45: =T4 -> Testosterone-33µg/L + Testostérone | U45: =U4 -> Testosterone-100µg/L + Testostérone | V45: =V4 -> Testosterone-300µg/L + Testostérone
A46: mean | B46: =AVERAGE(B28:B43) -> 0.11288927 | C46: =AVERAGE(C28:C43) -> 0.24822099 | D46: =AVERAGE(D28:D43) -> 2.3408828 | E46: =AVERAGE(E28:E43) -> 2.476974 | F46: =AVERAGE(F28:F43) -> 8.9374177 | G46: =AVERAGE(G28:G43) -> 9.5369864 | H46: =AVERAGE(H28:H43) -> 17.007271 | I46: =AVERAGE(I28:I43) -> 0.63117462 | ... M46: =AVERAGE(M28:M43) -> 8.7317321 | N46: mean | O46: =AVERAGE(O28:O43) -> 1 | P46: =AVERAGE(P28:P43) -> 10.162118 | Q46: =AVERAGE(Q28:Q43) -> 0.10097257 | R46: =AVERAGE(R28:R43) -> 3.1770688 | S46: =AVERAGE(S28:S43) -> 1.4405357 | T46: =AVERAGE(T28:T43) -> 4.1777173 | U46: =AVERAGE(U28:U43) -> 5.5634889 | V46: =AVERAGE(V28:V43) -> 8.6448178
...

Sheet Raw data R2
A1: Nom groupe | B1: N° de valeur | C1: file name | D1: total area | E1: mean intensity | G1: total fluorescence | I1: nbre de larves | L1: (Tous)
A2: =IFERROR(LEFT(RIGHT(C2,LEN(C2)-SEARCH("@",C2)),SEARCH("/",RIGHT(C2,LEN(C2)-SEARCH("@",C2)-1))),"") | B2: =LEFT(RIGHT(RIGHT(Tableau46[[#This Row],[file name]],LEN(Tableau46[[#This Row],[file name]])-SEARCH("@",Tableau46[[#This Row],[file name]])),LEN(RIGHT(Tableau46[[#This Row],[file name]],LEN(Tableau46[[#This Row],[file name]])-SEARCH("@",Tableau46[[#This Row],[file name]])))-SEARCH("/",RIGHT(Tableau46[[#This Row],[file name]],LEN(Tableau46[[#This Row],[file name]])-SEARCH("@",Tableau46[[#This Row],[file name]])))),1) -> #VALUE! | K2: Filtre lignes : Enlever (vide) et Néant | L2: Filtre colonnes : Enlever (vide) et " "
A3: =IFERROR(LEFT(RIGHT(C3,LEN(C3)-SEARCH("@",C3)),SEARCH("/",RIGHT(C3,LEN(C3)-SEARCH("@",C3)-1))),"") | B3: =LEFT(RIGHT(RIGHT(Tableau46[[#This Row],[file name]],LEN(Tableau46[[#This Row],[file name]])-SEARCH("@",Tableau46[[#This Row],[file name]])),LEN(RIGHT(Tableau46[[#This Row],[file name]],LEN(Tableau46[[#This Row],[file name]])-SEARCH("@",Tableau46[[#This Row],[file name]])))-SEARCH("/",RIGHT(Tableau46[[#This Row],[file name]],LEN(Tableau46[[#This Row],[file name]])-SEARCH("@",Tableau46[[#This Row],[file name]])))),1) -> #VALUE! | K3: Moyenne de total fluorescence | L3: Étiquettes de colonnes
A4: =IFERROR(LEFT(RIGHT(C4,LEN(C4)-SEARCH("@",C4)),SEARCH("/",RIGHT(C4,LEN(C4)-SEARCH("@",C4)-1))),"") | B4: =LEFT(RIGHT(RIGHT(Tableau46[[#This Row],[file name]],LEN(Tableau46[[#This Row],[file name]])-SEARCH("@",Tableau46[[#This Row],[file name]])),LEN(RIGHT(Tableau46[[#This Row],[file name]],LEN(Tableau46[[#This Row],[file name]])-SEARCH("@",Tableau46[[#This Row],[file name]])))-SEARCH("/",RIGHT(Tableau46[[#This Row],[file name]],LEN(Tableau46[[#This Row],[file name]])-SEARCH("@",Tableau46[[#This Row],[file name]])))),1) -> #VALUE! | K4: Étiquettes de lignes
A5: =IFERROR(LEFT(RIGHT(C5,LEN(C5)-SEARCH("@",C5)),SEARCH("/",RIGHT(C5,LEN(C5)-SEARCH("@",C5)-1))),"") | B5: =LEFT(RIGHT(RIGHT(Tableau46[[#This Row],[file name]],LEN(Tableau46[[#This Row],[file name]])-SEARCH("@",Tableau46[[#This Row],[file name]])),LEN(RIGHT(Tableau46[[#This Row],[file name]],LEN(Tableau46[[#This Row],[file name]])-SEARCH("@",Tableau46[[#This Row],[file name]])))-SEARCH("/",RIGHT(Tableau46[[#This Row],[file name]],LEN(Tableau46[[#This Row],[file name]])-SEARCH("@",Tableau46[[#This Row],[file name]])))),1) -> #VALUE! | K5: #VALEUR!
A6: =IFERROR(LEFT(RIGHT(C6,LEN(C6)-SEARCH("@",C6)),SEARCH("/",RIGHT(C6,LEN(C6)-SEARCH("@",C6)-1))),"") | B6: =LEFT(RIGHT(RIGHT(Tableau46[[#This Row],[file name]],LEN(Tableau46[[#This Row],[file name]])-SEARCH("@",Tableau46[[#This Row],[file name]])),LEN(RIGHT(Tableau46[[#This Row],[file name]],LEN(Tableau46[[#This Row],[file name]])-SEARCH("@",Tableau46[[#This Row],[file name]])))-SEARCH("/",RIGHT(Tableau46[[#This Row],[file name]],LEN(Tableau46[[#This Row],[file name]])-SEARCH("@",Tableau46[[#This Row],[file name]])))),1) -> #VALUE!
A7: =IFERROR(LEFT(RIGHT(C7,LEN(C7)-SEARCH("@",C7)),SEARCH("/",RIGHT(C7,LEN(C7)-SEARCH("@",C7)-1))),"") | B7: =LEFT(RIGHT(RIGHT(Tableau46[[#This Row],[file name]],LEN(Tableau46[[#This Row],[file name]])-SEARCH("@",Tableau46[[#This Row],[file name]])),LEN(RIGHT(Tableau46[[#This Row],[file name]],LEN(Tableau46[[#This Row],[file name]])-SEARCH("@",Tableau46[[#This Row],[file name]])))-SEARCH("/",RIGHT(Tableau46[[#This Row],[file name]],LEN(Tableau46[[#This Row],[file name]])-SEARCH("@",Tableau46[[#This Row],[file name]])))),1) -> #VALUE!
A8: =IFERROR(LEFT(RIGHT(C8,LEN(C8)-SEARCH("@",C8)),SEARCH("/",RIGHT(C8,LEN(C8)-SEARCH("@",C8)-1))),"") | B8: =LEFT(RIGHT(RIGHT(Tableau46[[#This Row],[file name]],LEN(Tableau46[[#This Row],[file name]])-SEARCH("@",Tableau46[[#This Row],[file name]])),LEN(RIGHT(Tableau46[[#This Row],[file name]],LEN(Tableau46[[#This Row],[file name]])-SEARCH("@",Tableau46[[#This Row],[file name]])))-SEARCH("/",RIGHT(Tableau46[[#This Row],[file name]],LEN(Tableau46[[#This Row],[file name]])-SEARCH("@",Tableau46[[#This Row],[file name]])))),1) -> #VALUE!
A9: =IFERROR(LEFT(RIGHT(C9,LEN(C9)-SEARCH("@",C9)),SEARCH("/",RIGHT(C9,LEN(C9)-SEARCH("@",C9)-1))),"") | B9: =LEFT(RIGHT(RIGHT(Tableau46[[#This Row],[file name]],LEN(Tableau46[[#This Row],[file name]])-SEARCH("@",Tableau46[[#This Row],[file name]])),LEN(RIGHT(Tableau46[[#This Row],[file name]],LEN(Tableau46[[#This Row],[file name]])-SEARCH("@",Tableau46[[#This Row],[file name]])))-SEARCH("/",RIGHT(Tableau46[[#This Row],[file name]],LEN(Tableau46[[#This Row],[file name]])-SEARCH("@",Tableau46[[#This Row],[file name]])))),1) -> #VALUE!
A10: =IFERROR(LEFT(RIGHT(C10,LEN(C10)-SEARCH("@",C10)),SEARCH("/",RIGHT(C10,LEN(C10)-SEARCH("@",C10)-1))),"") | B10: =LEFT(RIGHT(RIGHT(Tableau46[[#This Row],[file name]],LEN(Tableau46[[#This Row],[file name]])-SEARCH("@",Tableau46[[#This Row],[file name]])),LEN(RIGHT(Tableau46[[#This Row],[file name]],LEN(Tableau46[[#This Row],[file name]])-SEARCH("@",Tableau46[[#This Row],[file name]])))-SEARCH("/",RIGHT(Tableau46[[#This Row],[file name]],LEN(Tableau46[[#This Row],[file name]])-SEARCH("@",Tableau46[[#This Row],[file name]])))),1) -> #VALUE!
A11: =IFERROR(LEFT(RIGHT(C11,LEN(C11)-SEARCH("@",C11)),SEARCH("/",RIGHT(C11,LEN(C11)-SEARCH("@",C11)-1))),"") | B11: =LEFT(RIGHT(RIGHT(Tableau46[[#This Row],[file name]],LEN(Tableau46[[#This Row],[file name]])-SEARCH("@",Tableau46[[#This Row],[file name]])),LEN(RIGHT(Tableau46[[#This Row],[file name]],LEN(Tableau46[[#This Row],[file name]])-SEARCH("@",Tableau46[[#This Row],[file name]])))-SEARCH("/",RIGHT(Tableau46[[#This Row],[file name]],LEN(Tableau46[[#This Row],[file name]])-SEARCH("@",Tableau46[[#This Row],[file name]])))),1) -> #VALUE!
A12: =IFERROR(LEFT(RIGHT(C12,LEN(C12)-SEARCH("@",C12)),SEARCH("/",RIGHT(C12,LEN(C12)-SEARCH("@",C12)-1))),"") | B12: =LEFT(RIGHT(RIGHT(Tableau46[[#This Row],[file name]],LEN(Tableau46[[#This Row],[file name]])-SEARCH("@",Tableau46[[#This Row],[file name]])),LEN(RIGHT(Tableau46[[#This Row],[file name]],LEN(Tableau46[[#This Row],[file name]])-SEARCH("@",Tableau46[[#This Row],[file name]])))-SEARCH("/",RIGHT(Tableau46[[#This Row],[file name]],LEN(Tableau46[[#This Row],[file name]])-SEARCH("@",Tableau46[[#This Row],[file name]])))),1) -> #VALUE!
A13: =IFERROR(LEFT(RIGHT(C13,LEN(C13)-SEARCH("@",C13)),SEARCH("/",RIGHT(C13,LEN(C13)-SEARCH("@",C13)-1))),"") | B13: =LEFT(RIGHT(RIGHT(Tableau46[[#This Row],[file name]],LEN(Tableau46[[#This Row],[file name]])-SEARCH("@",Tableau46[[#This Row],[file name]])),LEN(RIGHT(Tableau46[[#This Row],[file name]],LEN(Tableau46[[#This Row],[file name]])-SEARCH("@",Tableau46[[#This Row],[file name]])))-SEARCH("/",RIGHT(Tableau46[[#This Row],[file name]],LEN(Tableau46[[#This Row],[file name]])-SEARCH("@",Tableau46[[#This Row],[file name]])))),1) -> #VALUE!
A14: =IFERROR(LEFT(RIGHT(C14,LEN(C14)-SEARCH("@",C14)),SEARCH("/",RIGHT(C14,LEN(C14)-SEARCH("@",C14)-1))),"") | B14: =LEFT(RIGHT(RIGHT(Tableau46[[#This Row],[file name]],LEN(Tableau46[[#This Row],[file name]])-SEARCH("@",Tableau46[[#This Row],[file name]])),LEN(RIGHT(Tableau46[[#This Row],[file name]],LEN(Tableau46[[#This Row],[file name]])-SEARCH("@",Tableau46[[#This Row],[file name]])))-SEARCH("/",RIGHT(Tableau46[[#This Row],[file name]],LEN(Tableau46[[#This Row],[file name]])-SEARCH("@",Tableau46[[#This Row],[file name]])))),1) -> #VALUE!
A15: =IFERROR(LEFT(RIGHT(C15,LEN(C15)-SEARCH("@",C15)),SEARCH("/",RIGHT(C15,LEN(C15)-SEARCH("@",C15)-1))),"") | B15: =LEFT(RIGHT(RIGHT(Tableau46[[#This Row],[file name]],LEN(Tableau46[[#This Row],[file name]])-SEARCH("@",Tableau46[[#This Row],[file name]])),LEN(RIGHT(Tableau46[[#This Row],[file name]],LEN(Tableau46[[#This Row],[file name]])-SEARCH("@",Tableau46[[#This Row],[file name]])))-SEARCH("/",RIGHT(Tableau46[[#This Row],[file name]],LEN(Tableau46[[#This Row],[file name]])-SEARCH("@",Tableau46[[#This Row],[file name]])))),1) -> #VALUE!
A16: =IFERROR(LEFT(RIGHT(C16,LEN(C16)-SEARCH("@",C16)),SEARCH("/",RIGHT(C16,LEN(C16)-SEARCH("@",C16)-1))),"") | B16: =LEFT(RIGHT(RIGHT(Tableau46[[#This Row],[file name]],LEN(Tableau46[[#This Row],[file name]])-SEARCH("@",Tableau46[[#This Row],[file name]])),LEN(RIGHT(Tableau46[[#This Row],[file name]],LEN(Tableau46[[#This Row],[file name]])-SEARCH("@",Tableau46[[#This Row],[file name]])))-SEARCH("/",RIGHT(Tableau46[[#This Row],[file name]],LEN(Tableau46[[#This Row],[file name]])-SEARCH("@",Tableau46[[#This Row],[file name]])))),1) -> #VALUE!
A17: =IFERROR(LEFT(RIGHT(C17,LEN(C17)-SEARCH("@",C17)),SEARCH("/",RIGHT(C17,LEN(C17)-SEARCH("@",C17)-1))),"") | B17: =LEFT(RIGHT(RIGHT(Tableau46[[#This Row],[file name]],LEN(Tableau46[[#This Row],[file name]])-SEARCH("@",Tableau46[[#This Row],[file name]])),LEN(RIGHT(Tableau46[[#This Row],[file name]],LEN(Tableau46[[#This Row],[file name]])-SEARCH("@",Tableau46[[#This Row],[file name]])))-SEARCH("/",RIGHT(Tableau46[[#This Row],[file name]],LEN(Tableau46[[#This Row],[file name]])-SEARCH("@",Tableau46[[#This Row],[file name]])))),1) -> #VALUE!
... A1531: =IFERROR(LEFT(RIGHT(C1531,LEN(C1531)-SEARCH("@",C1531)),SEARCH("/",RIGHT(C1531,LEN(C1531)-SEARCH("@",C1531)-1))),"") | B1531: =LEFT(RIGHT(RIGHT(Tableau46[[#This Row],[file name]],LEN(Tableau46[[#This Row],[file name]])-SEARCH("@",Tableau46[[#This Row],[file name]])),LEN(RIGHT(Tableau46[[#This Row],[file name]],LEN(Tableau46[[#This Row],[file name]])-SEARCH("@",Tableau46[[#This Row],[file name]])))-SEARCH("/",RIGHT(Tableau46[[#This Row],[file name]],LEN(Tableau46[[#This Row],[file name]])-SEARCH("@",Tableau46[[#This Row],[file name]])))),1) -> #VALUE!

Sheet R2
A1: 6. Expérimentateur 2 : copier et coller les valeurs des intensités totales de fluorescences obtenues dans le fichier raw data lors du traitement des images. Ne pas supprimer les colonnes correspondant aux concentrations non lues.
A3: R2 | B3: Non dopé | O3: avec testo
A4: Noms des groupes | B4: ='Page de garde'!A7 -> Témoin solvant | C4: ='Page de garde'!A9 -> EE2-33.8ng/L | D4: ='Page de garde'!A10 -> EE2-50.6ng/L | E4: ='Page de garde'!A11 -> EE2-76ng/L | F4: ='Page de garde'!A12 -> EE2-114ng/L | G4: ='Page de garde'!A13 -> EE2-170.9ng/L | H4: ='Page de garde'!A14 -> EE2-488ng/L | I4: ='Page de garde'!A15 -> Testosterone-3.7µg/L | J4: ='Page de garde'!A16 -> Testosterone-11µg/L | K4: ='Page de garde'!A17 -> Testosterone-33µg/L | L4: ='Page de garde'!A18 -> Testosterone-100µg/L | M4: ='Page de garde'!A19 -> Testosterone-300µg/L | O4: ='Page de garde'!A36 -> Testo -30µg/L | P4: ='Page de garde'!A37 -> Testo 30µg/L + EE2 -64ng/L | Q4: ='Page de garde'!A38 -> Testo 30µg/L + FAD-10µg/L | R4: ='Page de garde'!A39 -> Testosterone-3.7µg/L + Testostérone | S4: ='Page de garde'!A40 -> Testosterone-11µg/L + Testostérone | T4: ='Page de garde'!A41 -> Testosterone-33µg/L + Testostérone | U4: ='Page de garde'!A42 -> Testosterone-100µg/L + Testostérone | V4: ='Page de garde'!A43 -> Testosterone-300µg/L + Testostérone
A5: Données brutes | B5: 20425 | C5: 5266 | D5: 20553 | E5: 128302 | F5: 2580598 | G5: 3454849 | H5: 11408250 | I5: 12678 | J5: 3178 | K5: 64726 | L5: 9528 | M5: 1187973 | O5: 194963 | P5: 6070749 | Q5: 75076 | R5: 25337 | S5: 20568 | T5: 2725958 | U5: 2290105 | V5: 64940
B6: 32635 | C6: 5201 | D6: 96829 | E6: 66856 | F6: 885196 | G6: 3028557 | H6: 5936158 | I6: 25 | J6: 4517 | K6: 8635 | L6: 776466 | M6: 49833 | O6: 1134466 | P6: 8310940 | Q6: 157 | R6: 1226701 | S6: 9067 | T6: 3131689 | U6: 103088 | V6: 2777103
B7: 1139 | C7: 28796 | D7: 28299 | E7: 179643 | F7: 871190 | G7: 1398458 | H7: 8722663 | I7: 14830 | J7: 36612 | K7: 0 | L7: 816367 | M7: 739531 | O7: 243058 | P7: 11367047 | Q7: 2464 | R7: 1531 | S7: 508711 | T7: 1663880 | U7: 139923 | V7: 499625
B8: 30470 | C8: 370 | D8: 2034472 | E8: 30966 | F8: 2085460 | G8: 2681815 | H8: 3792581 | I8: 3553 | J8: 64338 | K8: 493625 | L8: 429 | M8: 2222638 | O8: 15329 | P8: 2918381 | Q8: 7204 | R8: 18764 | S8: 2264719 | T8: 746616 | U8: 824251 | V8: 132650
B9: 6298 | C9: 1971 | D9: 39163 | E9: 3075288 | F9: 1300276 | G9: 2910091 | H9: 4361678 | I9: 12271 | J9: 9136 | K9: 781836 | M9: 1605 | O9: 670341 | P9: 3507096 | Q9: 17771 | R9: 219783 | S9: 28577 | T9: 2773585 | U9: 1301583 | V9: 1888787
B10: 21291 | C10: 28 | D10: 10345 | E10: 16916 | F10: 1004811 | G10: 1903433 | H10: 6052165 | I10: 86029 | J10: 7114 | K10: 498720 | M10: 0 | O10: 1195331 | P10: 4729680 | Q10: 29626 | R10: 150548 | S10: 3249586 | T10: 1564504 | U10: 3088702 | V10: 895730
B11: 2065 | C11: 130 | D11: 53999 | E11: 349294 | F11: 150975 | G11: 3809116 | I11: 4470 | J11: 31923 | K11: 746 | M11: 1682282 | O11: 30683 | P11: 10342504 | Q11: 11046 | R11: 16306 | S11: 10449 | T11: 2227353 | U11: 291 | V11: 809248
C12: 580662 | D12: 52353 | I12: 9746 | J12: 54756 | K12: 5836 | M12: 397016 | O12: 642339 | P12: 10194498 | Q12: 24173 | R12: 48699 | S12: 8543 | T12: 1727947 | U12: 1915141
O13: 5320920
O14: 6723
O15: 125073
O16: 1072115
O17: 2237625
O18: 695941
O19: 2663838
