Workbook

Sheet Page de garde
A1: 1. Expérimentateur 1 : copier et coller le n° de prestation et renseigner la date de réalisation de chaque réplica ainsi que le visa de l'expérimentateur.
A2: R1 | B2: Numéro d'expérience : | E2: Date de réalisation :
A3: R2 | B3: Numéro d'expérience : | E3: Date de réalisation :
A4: R3 | B4: Numéro d'expérience : | E4: Date de réalisation :
A5: 2. Expérimentateur 1 : copier et coller la dilution appliquée et le nom donné pour chaque des échantillons par le client. Conserver la mise en forme de l'exemple en italique. Ne pas remplir la colonne "nom sur graphique".
A6: Nom sur le graphique | B6: Code WF | C6: Concentration | D6: Unité | E6: Nom de l'échantillon donné par le client | F6: Dopage (+Testostérone / + EE2, ….)
A7: =IF(ISBLANK(liste_groupe[[#This Row],[Code WF]])," ",IF(ISBLANK(liste_groupe[[#This Row],[Unité]]),CONCATENATE(liste_groupe[[#This Row],[Nom de l''échantillon donné par le client]],liste_groupe[[#This Row],[Dopage (+Testostérone / + EE2, ….)]]),CONCATENATE(liste_groupe[[#This Row],[Nom de l''échantillon donné par le client]],"-",liste_groupe[[#This Row],[Concentration]],liste_groupe[[#This Row],[Unité]],liste_groupe[[#This Row],[Dopage (+Testostérone / + EE2, ….)]]))) -> Témoin solvant | B7: Témoin | E7: Témoin solvant
A8: =IF(ISBLANK(liste_groupe[[#This Row],[Code WF]])," ",IF(ISBLANK(liste_groupe[[#This Row],[Unité]]),CONCATENATE(liste_groupe[[#This Row],[Nom de l''échantillon donné par le client]],liste_groupe[[#This Row],[Dopage (+Testostérone / + EE2, ….)]]),CONCATENATE(liste_groupe[[#This Row],[Nom de l''échantillon donné par le client]],"-",liste_groupe[[#This Row],[Concentration]],liste_groupe[[#This Row],[Unité]],liste_groupe[[#This Row],[Dopage (+Testostérone / + EE2, ….)]]))) -> EE2-22,5ng/L | B8: Témoin | C8: 22.5 | D8: ng/L | E8: EE2
A9: =IF(ISBLANK(liste_groupe[[#This Row],[Code WF]])," ",IF(ISBLANK(liste_groupe[[#This Row],[Unité]]),CONCATENATE(liste_groupe[[#This Row],[Nom de l''échantillon donné par le client]],liste_groupe[[#This Row],[Dopage (+Testostérone / + EE2, ….)]]),CONCATENATE(liste_groupe[[#This Row],[Nom de l''échantillon donné par le client]],"-",liste_groupe[[#This Row],[Concentration]],liste_groupe[[#This Row],[Unité]],liste_groupe[[#This Row],[Dopage (+Testostérone / + EE2, ….)]]))) -> EE2-33,8ng/L | B9: Témoin | C9: 33.8 | D9: ng/L | E9: EE2
A10: =IF(ISBLANK(liste_groupe[[#This Row],[Code WF]])," ",IF(ISBLANK(liste_groupe[[#This Row],[Unité]]),CONCATENATE(liste_groupe[[#This Row],[Nom de l''échantillon donné par le client]],liste_groupe[[#This Row],[Dopage (+Testostérone / + EE2, ….)]]),CONCATENATE(liste_groupe[[#This Row],[Nom de l''échantillon donné par le client]],"-",liste_groupe[[#This Row],[Concentration]],liste_groupe[[#This Row],[Unité]],liste_groupe[[#This Row],[Dopage (+Testostérone / + EE2, ….)]]))) -> EE2-50,6ng/L | B10: Témoin | C10: 50.6 | D10: ng/L | E10: EE2
A11: =IF(ISBLANK(liste_groupe[[#This Row],[Code WF]])," ",IF(ISBLANK(liste_groupe[[#This Row],[Unité]]),CONCATENATE(liste_groupe[[#This Row],[Nom de l''échantillon donné par le client]],liste_groupe[[#This Row],[Dopage (+Testostérone / + EE2, ….)]]),CONCATENATE(liste_groupe[[#This Row],[Nom de l''échantillon donné par le client]],"-",liste_groupe[[#This Row],[Concentration]],liste_groupe[[#This Row],[Unité]],liste_groupe[[#This Row],[Dopage (+Testostérone / + EE2, ….)]]))) -> EE2-76ng/L | B11: Témoin | C11: 76 | D11: ng/L | E11: EE2
A12: =IF(ISBLANK(liste_groupe[[#This Row],[Code WF]])," ",IF(ISBLANK(liste_groupe[[#This Row],[Unité]]),CONCATENATE(liste_groupe[[#This Row],[Nom de l''échantillon donné par le client]],liste_groupe[[#This Row],[Dopage (+Testostérone / + EE2, ….)]]),CONCATENATE(liste_groupe[[#This Row],[Nom de l''échantillon donné par le client]],"-",liste_groupe[[#This Row],[Concentration]],liste_groupe[[#This Row],[Unité]],liste_groupe[[#This Row],[Dopage (+Testostérone / + EE2, ….)]]))) -> EE2-114ng/L | B12: Témoin | C12: 114 | D12: ng/L | E12: EE2
A13: =IF(ISBLANK(liste_groupe[[#This Row],[Code WF]])," ",IF(ISBLANK(liste_groupe[[#This Row],[Unité]]),CONCATENATE(liste_groupe[[#This Row],[Nom de l''échantillon donné par le client]],liste_groupe[[#This Row],[Dopage (+Testostérone / + EE2, ….)]]),CONCATENATE(liste_groupe[[#This Row],[Nom de l''échantillon donné par le client]],"-",liste_groupe[[#This Row],[Concentration]],liste_groupe[[#This Row],[Unité]],liste_groupe[[#This Row],[Dopage (+Testostérone / + EE2, ….)]]))) -> EE2-170,9ng/L | B13: Témoin | C13: 170.9 | D13: ng/L | E13: EE2
A14: =IF(ISBLANK(liste_groupe[[#This Row],[Code WF]])," ",IF(ISBLANK(liste_groupe[[#This Row],[Unité]]),CONCATENATE(liste_groupe[[#This Row],[Nom de l''échantillon donné par le client]],liste_groupe[[#This Row],[Dopage (+Testostérone / + EE2, ….)]]),CONCATENATE(liste_groupe[[#This Row],[Nom de l''échantillon donné par le client]],"-",liste_groupe[[#This Row],[Concentration]],liste_groupe[[#This Row],[Unité]],liste_groupe[[#This Row],[Dopage (+Testostérone / + EE2, ….)]]))) -> EE2-488ng/L | B14: Témoin | C14: 488 | D14: ng/L | E14: EE2
A15: CRO-0.1µg/L | B15: Chemical | C15: 0.1 | D15: µg/L | E15: CRO
A16: CRO-1µg/L | B16: Chemical | C16: 1 | D16: µg/L | E16: CRO
A17: CRO-10µg/L | B17: Chemical | C17: 10 | D17: µg/L | E17: CRO
A18: CRO-100µg/L | B18: Chemical | C18: 100 | D18: µg/L | E18: CRO
A19: CRO-1000µg/L | B19: Chemical | C19: 1000 | D19: µg/L | E19: CRO
A20: =IF(ISBLANK(liste_groupe[[#This Row],[Code WF]])," ",IF(ISBLANK(liste_groupe[[#This Row],[Unité]]),CONCATENATE(liste_groupe[[#This Row],[Nom de l''échantillon donné par le client]],liste_groupe[[#This Row],[Dopage (+Testostérone / + EE2, ….)]]),CONCATENATE(liste_groupe[[#This Row],[Nom de l''échantillon donné par le client]],"-",liste_groupe[[#This Row],[Concentration]],liste_groupe[[#This Row],[Unité]],liste_groupe[[#This Row],[Dopage (+Testostérone / + EE2, ….)]])))
A21: =IF(ISBLANK(liste_groupe[[#This Row],[Code WF]])," ",IF(ISBLANK(liste_groupe[[#This Row],[Unité]]),CONCATENATE(liste_groupe[[#This Row],[Nom de l''échantillon donné par le client]],liste_groupe[[#This Row],[Dopage (+Testostérone / + EE2, ….)]]),CONCATENATE(liste_groupe[[#This Row],[Nom de l''échantillon donné par le client]],"-",liste_groupe[[#This Row],[Concentration]],liste_groupe[[#This Row],[Unité]],liste_groupe[[#This Row],[Dopage (+Testostérone / + EE2, ….)]])))
A22: =IF(ISBLANK(liste_groupe[[#This Row],[Code WF]])," ",IF(ISBLANK(liste_groupe[[#This Row],[Unité]]),CONCATENATE(liste_groupe[[#This Row],[Nom de l''échantillon donné par le client]],liste_groupe[[#This Row],[Dopage (+Testostérone / + EE2, ….)]]),CONCATENATE(liste_groupe[[#This Row],[Nom de l''échantillon donné par le client]],"-",liste_groupe[[#This Row],[Concentration]],liste_groupe[[#This Row],[Unité]],liste_groupe[[#This Row],[Dopage (+Testostérone / + EE2, ….)]])))
A23: =IF(ISBLANK(liste_groupe[[#This Row],[Code WF]])," ",IF(ISBLANK(liste_groupe[[#This Row],[Unité]]),CONCATENATE(liste_groupe[[#This Row],[Nom de l''échantillon donné par le client]],liste_groupe[[#This Row],[Dopage (+Testostérone / + EE2, ….)]]),CONCATENATE(liste_groupe[[#This Row],[Nom de l''échantillon donné par le client]],"-",liste_groupe[[#This Row],[Concentration]],liste_groupe[[#This Row],[Unité]],liste_groupe[[#This Row],[Dopage (+Testostérone / + EE2, ….)]])))
A24: =IF(ISBLANK(liste_groupe[[#This Row],[Code WF]])," ",IF(ISBLANK(liste_groupe[[#This Row],[Unité]]),CONCATENATE(liste_groupe[[#This Row],[Nom de l''échantillon donné par le client]],liste_groupe[[#This Row],[Dopage (+Testostérone / + EE2, ….)]]),CONCATENATE(liste_groupe[[#This Row],[Nom de l''échantillon donné par le client]],"-",liste_groupe[[#This Row],[Concentration]],liste_groupe[[#This Row],[Unité]],liste_groupe[[#This Row],[Dopage (+Testostérone / + EE2, ….)]])))
A25: =IF(ISBLANK(liste_groupe[[#This Row],[Code WF]])," ",IF(ISBLANK(liste_groupe[[#This Row],[Unité]]),CONCATENATE(liste_groupe[[#This Row],[Nom de l''échantillon donné par le client]],liste_groupe[[#This Row],[Dopage (+Testostérone / + EE2, ….)]]),CONCATENATE(liste_groupe[[#This Row],[Nom de l''échantillon donné par le client]],"-",liste_groupe[[#This Row],[Concentration]],liste_groupe[[#This Row],[Unité]],liste_groupe[[#This Row],[Dopage (+Testostérone / + EE2, ….)]])))
A26: =IF(ISBLANK(liste_groupe[[#This Row],[Code WF]])," ",IF(ISBLANK(liste_groupe[[#This Row],[Unité]]),CONCATENATE(liste_groupe[[#This Row],[Nom de l''échantillon donné par le client]],liste_groupe[[#This Row],[Dopage (+Testostérone / + EE2, ….)]]),CONCATENATE(liste_groupe[[#This Row],[Nom de l''échantillon donné par le client]],"-",liste_groupe[[#This Row],[Concentration]],liste_groupe[[#This Row],[Unité]],liste_groupe[[#This Row],[Dopage (+Testostérone / + EE2, ….)]])))
A27: =IF(ISBLANK(liste_groupe[[#This Row],[Code WF]])," ",IF(ISBLANK(liste_groupe[[#This Row],[Unité]]),CONCATENATE(liste_groupe[[#This Row],[Nom de l''échantillon donné par le client]],liste_groupe[[#This Row],[Dopage (+Testostérone / + EE2, ….)]]),CONCATENATE(liste_groupe[[#This Row],[Nom de l''échantillon donné par le client]],"-",liste_groupe[[#This Row],[Concentration]],liste_groupe[[#This Row],[Unité]],liste_groupe[[#This Row],[Dopage (+Testostérone / + EE2, ….)]])))
A28: =IF(ISBLANK(liste_groupe[[#This Row],[Code WF]])," ",IF(ISBLANK(liste_groupe[[#This Row],[Unité]]),CONCATENATE(liste_groupe[[#This Row],[Nom de l''échantillon donné par le client]],liste_groupe[[#This Row],[Dopage (+Testostérone / + EE2, ….)]]),CONCATENATE(liste_groupe[[#This Row],[Nom de l''échantillon donné par le client]],"-",liste_groupe[[#This Row],[Concentration]],liste_groupe[[#This Row],[Unité]],liste_groupe[[#This Row],[Dopage (+Testostérone / + EE2, ….)]])))
A29: =IF(ISBLANK(liste_groupe[[#This Row],[Code WF]])," ",IF(ISBLANK(liste_groupe[[#This Row],[Unité]]),CONCATENATE(liste_groupe[[#This Row],[Nom de l''échantillon donné par le client]],liste_groupe[[#This Row],[Dopage (+Testostérone / + EE2, ….)]]),CONCATENATE(liste_groupe[[#This Row],[Nom de l''échantillon donné par le client]],"-",liste_groupe[[#This Row],[Concentration]],liste_groupe[[#This Row],[Unité]],liste_groupe[[#This Row],[Dopage (+Testostérone / + EE2, ….)]])))
A30: =IF(ISBLANK(liste_groupe[[#This Row],[Code WF]])," ",IF(ISBLANK(liste_groupe[[#This Row],[Unité]]),CONCATENATE(liste_groupe[[#This Row],[Nom de l''échantillon donné par le client]],liste_groupe[[#This Row],[Dopage (+Testostérone / + EE2, ….)]]),CONCATENATE(liste_groupe[[#This Row],[Nom de l''échantillon donné par le client]],"-",liste_groupe[[#This Row],[Concentration]],liste_groupe[[#This Row],[Unité]],liste_groupe[[#This Row],[Dopage (+Testostérone / + EE2, ….)]])))
A31: =IF(ISBLANK(liste_groupe[[#This Row],[Code WF]])," ",IF(ISBLANK(liste_groupe[[#This Row],[Unité]]),CONCATENATE(liste_groupe[[#This Row],[Nom de l''échantillon donné par le client]],liste_groupe[[#This Row],[Dopage (+Testostérone / + EE2, ….)]]),CONCATENATE(liste_groupe[[#This Row],[Nom de l''échantillon donné par le client]],"-",liste_groupe[[#This Row],[Concentration]],liste_groupe[[#This Row],[Unité]],liste_groupe[[#This Row],[Dopage (+Testostérone / + EE2, ….)]])))
... A35: =IF(ISBLANK(liste_groupe[[#This Row],[Code WF]])," ",IF(ISBLANK(liste_groupe[[#This Row],[Unité]]),CONCATENATE(liste_groupe[[#This Row],[Nom de l''échantillon donné par le client]],liste_groupe[[#This Row],[Dopage (+Testostérone / + EE2, ….)]]),CONCATENATE(liste_groupe[[#This Row],[Nom de l''échantillon donné par le client]],"-",liste_groupe[[#This Row],[Concentration]],liste_groupe[[#This Row],[Unité]],liste_groupe[[#This Row],[Dopage (+Testostérone / + EE2, ….)]])))
A36: =IF(ISBLANK(liste_groupe[[#This Row],[Code WF]])," ",IF(ISBLANK(liste_groupe[[#This Row],[Unité]]),CONCATENATE(liste_groupe[[#This Row],[Nom de l''échantillon donné par le client]],liste_groupe[[#This Row],[Dopage (+Testostérone / + EE2, ….)]]),CONCATENATE(liste_groupe[[#This Row],[Nom de l''échantillon donné par le client]],"-",liste_groupe[[#This Row],[Concentration]],liste_groupe[[#This Row],[Unité]],liste_groupe[[#This Row],[Dopage (+Testostérone / + EE2, ….)]]))) -> Testo -30µg/L | B36: Témoin | C36: 30 | D36: µg/L | E36: Testo
A37: =IF(ISBLANK(liste_groupe[[#This Row],[Code WF]])," ",IF(ISBLANK(liste_groupe[[#This Row],[Unité]]),CONCATENATE(liste_groupe[[#This Row],[Nom de l''échantillon donné par le client]],liste_groupe[[#This Row],[Dopage (+Testostérone / + EE2, ….)]]),CONCATENATE(liste_groupe[[#This Row],[Nom de l''échantillon donné par le client]],"-",liste_groupe[[#This Row],[Concentration]],liste_groupe[[#This Row],[Unité]],liste_groupe[[#This Row],[Dopage (+Testostérone / + EE2, ….)]]))) -> Testo 30µg/L + EE2 -64ng/L | B37: Témoin | C37: 64 | D37: ng/L | E37: Testo 30µg/L + EE2
A38: =IF(ISBLANK(liste_groupe[[#This Row],[Code WF]])," ",IF(ISBLANK(liste_groupe[[#This Row],[Unité]]),CONCATENATE(liste_groupe[[#This Row],[Nom de l''échantillon donné par le client]],liste_groupe[[#This Row],[Dopage (+Testostérone / + EE2, ….)]]),CONCATENATE(liste_groupe[[#This Row],[Nom de l''échantillon donné par le client]],"-",liste_groupe[[#This Row],[Concentration]],liste_groupe[[#This Row],[Unité]],liste_groupe[[#This Row],[Dopage (+Testostérone / + EE2, ….)]]))) -> Testo 30µg/L + FAD-10mg/L | B38: Témoin | C38: 10 | D38: mg/L | E38: Testo 30µg/L + FAD
A39: =IF(ISBLANK(liste_groupe[[#This Row],[Code WF]])," ",IF(ISBLANK(liste_groupe[[#This Row],[Unité]]),CONCATENATE(liste_groupe[[#This Row],[Nom de l''échantillon donné par le client]],liste_groupe[[#This Row],[Dopage (+Testostérone / + EE2, ….)]]),CONCATENATE(liste_groupe[[#This Row],[Nom de l''échantillon donné par le client]],"-",liste_groupe[[#This Row],[Concentration]],liste_groupe[[#This Row],[Unité]],liste_groupe[[#This Row],[Dopage (+Testostérone / + EE2, ….)]]))) -> CRO-0,1µg/L + Testostérone | B39: =B15 -> Chemical | C39: =C15 -> 0.1 | D39: =D15 -> µg/L | E39: =E15 -> CRO | F39: + Testostérone
A40: =IF(ISBLANK(liste_groupe[[#This Row],[Code WF]])," ",IF(ISBLANK(liste_groupe[[#This Row],[Unité]]),CONCATENATE(liste_groupe[[#This Row],[Nom de l''échantillon donné par le client]],liste_groupe[[#This Row],[Dopage (+Testostérone / + EE2, ….)]]),CONCATENATE(liste_groupe[[#This Row],[Nom de l''échantillon donné par le client]],"-",liste_groupe[[#This Row],[Concentration]],liste_groupe[[#This Row],[Unité]],liste_groupe[[#This Row],[Dopage (+Testostérone / + EE2, ….)]]))) -> CRO-1µg/L + Testostérone | B40: =B16 -> Chemical | C40: =C16 -> 1 | D40: =D16 -> µg/L | E40: =E16 -> CRO | F40: + Testostérone
A41: =IF(ISBLANK(liste_groupe[[#This Row],[Code WF]])," ",IF(ISBLANK(liste_groupe[[#This Row],[Unité]]),CONCATENATE(liste_groupe[[#This Row],[Nom de l''échantillon donné par le client]],liste_groupe[[#This Row],[Dopage (+Testostérone / + EE2, ….)]]),CONCATENATE(liste_groupe[[#This Row],[Nom de l''échantillon donné par le client]],"-",liste_groupe[[#This Row],[Concentration]],liste_groupe[[#This Row],[Unité]],liste_groupe[[#This Row],[Dopage (+Testostérone / + EE2, ….)]]))) -> CRO-10µg/L + Testostérone | B41: =B17 -> Chemical | C41: =C17 -> 10 | D41: =D17 -> µg/L | E41: =E17 -> CRO | F41: + Testostérone
A42: =IF(ISBLANK(liste_groupe[[#This Row],[Code WF]])," ",IF(ISBLANK(liste_groupe[[#This Row],[Unité]]),CONCATENATE(liste_groupe[[#This Row],[Nom de l''échantillon donné par le client]],liste_groupe[[#This Row],[Dopage (+Testostérone / + EE2, ….)]]),CONCATENATE(liste_groupe[[#This Row],[Nom de l''échantillon donné par le client]],"-",liste_groupe[[#This Row],[Concentration]],liste_groupe[[#This Row],[Unité]],liste_groupe[[#This Row],[Dopage (+Testostérone / + EE2, ….)]]))) -> CRO-100µg/L + Testostérone | B42: =B18 -> Chemical | C42: =C18 -> 100 | D42: =D18 -> µg/L | E42: =E18 -> CRO | F42: + Testostérone
A43: =IF(ISBLANK(liste_groupe[[#This Row],[Code WF]])," ",IF(ISBLANK(liste_groupe[[#This Row],[Unité]]),CONCATENATE(liste_groupe[[#This Row],[Nom de l''échantillon donné par le client]],liste_groupe[[#This Row],[Dopage (+Testostérone / + EE2, ….)]]),CONCATENATE(liste_groupe[[#This Row],[Nom de l''échantillon donné par le client]],"-",liste_groupe[[#This Row],[Concentration]],liste_groupe[[#This Row],[Unité]],liste_groupe[[#This Row],[Dopage (+Testostérone / + EE2, ….)]]))) -> CRO-1000µg/L + Testostérone | B43: =B19 -> Chemical | C43: =C19 -> 1000 | D43: =D19 -> µg/L | E43: =E19 -> CRO | F43: + Testostérone
...

Sheet Feuil1
A1: Nom groupe | B1: N° de valeur | C1: file name | D1: total area | E1: mean intensity | G1: total fluorescence | I1: nbre de larves
A2: 01 EE2 0 | B2: A | C2: C:\Users\Olympus\Desktop\20190122\plaque1/@01 EE2 0/A1_1.tif | D2: 4931.616 | E2: 73.0526 | G2: 360268
A3: 01 EE2 0 | B3: A | C3: C:\Users\Olympus\Desktop\20190122\plaque1/@01 EE2 0/A1_2.tif | D3: 5234.4345 | E3: 71.1281 | G3: 372315
A4: 01 EE2 0 | B4: A | C4: C:\Users\Olympus\Desktop\20190122\plaque1/@01 EE2 0/A1_3.tif | D4: 3547.3027 | E4: 66.9878 | G4: 237626
A5: 01 EE2 0 | B5: A | C5: C:\Users\Olympus\Desktop\20190122\plaque3/@01 EE2 0/A1_3.tif | D5: 21456.8555 | E5: 67.0655 | G5: 1439015
A6: 01 EE2 0 | B6: A | C6: C:\Users\Olympus\Desktop\20190122\plaque3/@01 EE2 0/A1_2.tif | D6: 21586.6348 | E6: 66.4108 | G6: 1433586
A7: 01 EE2 0 | B7: A | C7: C:\Users\Olympus\Desktop\20190122\plaque3/@01 EE2 0/A1_1.tif | D7: 15984.4921 | E7: 69.7767 | G7: 1115346

Sheet Raw data R1
A1: Nom groupe | B1: N° de valeur | C1: file name | D1: total area | E1: mean intensity | G1: total fluorescence | I1: nbre de larves | L1: (Tous)
A2: =IFERROR(LEFT(RIGHT(C2,LEN(C2)-SEARCH("@",C2)),SEARCH("/",RIGHT(C2,LEN(C2)-SEARCH("@",C2)-1))),"") | B2: =LEFT(RIGHT(RIGHT(Tableau4[[#This Row],[file name]],LEN(Tableau4[[#This Row],[file name]])-SEARCH("@",Tableau4[[#This Row],[file name]])),LEN(RIGHT(Tableau4[[#This Row],[file name]],LEN(Tableau4[[#This Row],[file name]])-SEARCH("@",Tableau4[[#This Row],[file name]])))-SEARCH("/",RIGHT(Tableau4[[#This Row],[file name]],LEN(Tableau4[[#This Row],[file name]])-SEARCH("@",Tableau4[[#This Row],[file name]])))),1) -> #VALUE! | C2: file name | D2: total area | E2: mean intensity | G2: total fluorescence | K2: Filtre lignes : Enlever (vide) et Néant | L2: Filtre colonnes : Enlever (vide) et " "
A3: =IFERROR(LEFT(RIGHT(C3,LEN(C3)-SEARCH("@",C3)),SEARCH("/",RIGHT(C3,LEN(C3)-SEARCH("@",C3)-1))),"") -> 1 | B3: =LEFT(RIGHT(RIGHT(Tableau4[[#This Row],[file name]],LEN(Tableau4[[#This Row],[file name]])-SEARCH("@",Tableau4[[#This Row],[file name]])),LEN(RIGHT(Tableau4[[#This Row],[file name]],LEN(Tableau4[[#This Row],[file name]])-SEARCH("@",Tableau4[[#This Row],[file name]])))-SEARCH("/",RIGHT(Tableau4[[#This Row],[file name]],LEN(Tableau4[[#This Row],[file name]])-SEARCH("@",Tableau4[[#This Row],[file name]])))),1) -> A | C3: C:\Users\andre\Desktop\REACTIV CEFAS\Cromolyn\Cromolyn/20201217_Cefas_Test10_Run1/Plate 1/@1/A10_01.tif | D3: 9625.3031 | E3: 39.5348 | G3: 380535 | K3: Moyenne de total fluorescence | L3: Étiquettes de colonnes
A4: =IFERROR(LEFT(RIGHT(C4,LEN(C4)-SEARCH("@",C4)),SEARCH("/",RIGHT(C4,LEN(C4)-SEARCH("@",C4)-1))),"") -> 1 | B4: =LEFT(RIGHT(RIGHT(Tableau4[[#This Row],[file name]],LEN(Tableau4[[#This Row],[file name]])-SEARCH("@",Tableau4[[#This Row],[file name]])),LEN(RIGHT(Tableau4[[#This Row],[file name]],LEN(Tableau4[[#This Row],[file name]])-SEARCH("@",Tableau4[[#This Row],[file name]])))-SEARCH("/",RIGHT(Tableau4[[#This Row],[file name]],LEN(Tableau4[[#This Row],[file name]])-SEARCH("@",Tableau4[[#This Row],[file name]])))),1) -> A | C4: C:\Users\andre\Desktop\REACTIV CEFAS\Cromolyn\Cromolyn/20201217_Cefas_Test10_Run1/Plate 1/@1/A10_02- exclu.tif | K4: Étiquettes de lignes | L4: 1 | M4: 13 | N4: 14 | O4: 15 | P4: 16 | Q4: 2 | R4: 3 | S4: 4 | T4: 5 | U4: 6 | V4: 7 | W4: 10 | X4: 11 | Y4: 12 | Z4: 17 | AA4: 18 | AB4: 19 | AC4: 20 | AD4: 21 | AE4: 8 | AF4: 9
A5: =IFERROR(LEFT(RIGHT(C5,LEN(C5)-SEARCH("@",C5)),SEARCH("/",RIGHT(C5,LEN(C5)-SEARCH("@",C5)-1))),"") -> 1 | B5: =LEFT(RIGHT(RIGHT(Tableau4[[#This Row],[file name]],LEN(Tableau4[[#This Row],[file name]])-SEARCH("@",Tableau4[[#This Row],[file name]])),LEN(RIGHT(Tableau4[[#This Row],[file name]],LEN(Tableau4[[#This Row],[file name]])-SEARCH("@",Tableau4[[#This Row],[file name]])))-SEARCH("/",RIGHT(Tableau4[[#This Row],[file name]],LEN(Tableau4[[#This Row],[file name]])-SEARCH("@",Tableau4[[#This Row],[file name]])))),1) -> A | C5: C:\Users\andre\Desktop\REACTIV CEFAS\Cromolyn\Cromolyn/20201217_Cefas_Test10_Run1/Plate 1/@1/A10_03.tif | D5: 2682.1069 | E5: 37.2823 | G5: 99995 | K5: A | L5: 276639.33 | M5: 224334.25 | N5: 696807.5 | O5: 2147113.3 | P5: 132672.25 | Q5: 348706.5 | R5: 472078 | S5: 617944 | T5: 1923734 | U5: 2825048.2 | V5: 5966260 | W5: 134271 | X5: 63575.5 | Y5: 542039.75 | Z5: 585824 | AA5: 85648.75 | AB5: 1868174.3 | AC5: 1133395.5 | AD5: 1032351.7 | AE5: 194371.75 | AF5: 147375
A6: =IFERROR(LEFT(RIGHT(C6,LEN(C6)-SEARCH("@",C6)),SEARCH("/",RIGHT(C6,LEN(C6)-SEARCH("@",C6)-1))),"") -> 1 | B6: =LEFT(RIGHT(RIGHT(Tableau4[[#This Row],[file name]],LEN(Tableau4[[#This Row],[file name]])-SEARCH("@",Tableau4[[#This Row],[file name]])),LEN(RIGHT(Tableau4[[#This Row],[file name]],LEN(Tableau4[[#This Row],[file name]])-SEARCH("@",Tableau4[[#This Row],[file name]])))-SEARCH("/",RIGHT(Tableau4[[#This Row],[file name]],LEN(Tableau4[[#This Row],[file name]])-SEARCH("@",Tableau4[[#This Row],[file name]])))),1) -> A | C6: C:\Users\andre\Desktop\REACTIV CEFAS\Cromolyn\Cromolyn/20201217_Cefas_Test10_Run1/Plate 1/@1/A10_04.tif | D6: 9365.7444 | E6: 37.3048 | G6: 349388 | K6: B | L6: 148175.5 | M6: 2383625.2 | N6: 393037 | O6: 3481558.5 | P6: 284384.5 | Q6: 236166.25 | R6: 437286 | S6: 682798 | T6: 2626334.2 | U6: 2580084 | V6: 5184188.5 | W6: 40224.333 | X6: 102158 | Y6: 143260.25 | Z6: 1938509 | AA6: 1396368.3 | AB6: 1597908.5 | AC6: 2317027 | AD6: 2226359.8 | AE6: 83743.667 | AF6: 43568
A7: =IFERROR(LEFT(RIGHT(C7,LEN(C7)-SEARCH("@",C7)),SEARCH("/",RIGHT(C7,LEN(C7)-SEARCH("@",C7)-1))),"") -> 1 | B7: =LEFT(RIGHT(RIGHT(Tableau4[[#This Row],[file name]],LEN(Tableau4[[#This Row],[file name]])-SEARCH("@",Tableau4[[#This Row],[file name]])),LEN(RIGHT(Tableau4[[#This Row],[file name]],LEN(Tableau4[[#This Row],[file name]])-SEARCH("@",Tableau4[[#This Row],[file name]])))-SEARCH("/",RIGHT(Tableau4[[#This Row],[file name]],LEN(Tableau4[[#This Row],[file name]])-SEARCH("@",Tableau4[[#This Row],[file name]])))),1) -> B | C7: C:\Users\andre\Desktop\REACTIV CEFAS\Cromolyn\Cromolyn/20201217_Cefas_Test10_Run1/Plate 1/@1/B10_01.tif | D7: 5385.8438 | E7: 34.9157 | G7: 188050 | K7: C | L7: 98891.75 | M7: 1803982.2 | N7: 2433074.7 | O7: 3323087.2 | P7: 169421.5 | Q7: 494041 | R7: 196713 | S7: 3041119.7 | T7: 3128991.5 | U7: 3289528.5 | V7: 4711640 | W7: 412595.5 | X7: 125837.25 | Y7: 98913.75 | Z7: 1128291 | AA7: 2544400.2 | AB7: 2025401.8 | AC7: 667114.75 | AD7: 3054811.8 | AE7: 252383 | AF7: 95177.25
A8: =IFERROR(LEFT(RIGHT(C8,LEN(C8)-SEARCH("@",C8)),SEARCH("/",RIGHT(C8,LEN(C8)-SEARCH("@",C8)-1))),"") -> 1 | B8: =LEFT(RIGHT(RIGHT(Tableau4[[#This Row],[file name]],LEN(Tableau4[[#This Row],[file name]])-SEARCH("@",Tableau4[[#This Row],[file name]])),LEN(RIGHT(Tableau4[[#This Row],[file name]],LEN(Tableau4[[#This Row],[file name]])-SEARCH("@",Tableau4[[#This Row],[file name]])))-SEARCH("/",RIGHT(Tableau4[[#This Row],[file name]],LEN(Tableau4[[#This Row],[file name]])-SEARCH("@",Tableau4[[#This Row],[file name]])))),1) -> B | C8: C:\Users\andre\Desktop\REACTIV CEFAS\Cromolyn\Cromolyn/20201217_Cefas_Test10_Run1/Plate 1/@1/B10_02.tif | D8: 4585.5377 | E8: 34.0377 | G8: 156081 | K8: D | L8: 346446 | M8: 2453299 | N8: 1107436.3 | O8: 3442078.5 | P8: 237615.5 | Q8: 456099 | R8: 183805.5 | S8: 1098874.5 | T8: 2428815.5 | U8: 3001110.2 | V8: 4374019 | W8: 19921.25 | X8: 305695 | Y8: 202877.75 | Z8: 2220099.3 | AA8: 1279132.5 | AB8: 3646230.7 | AC8: 243671.75 | AD8: 2840875.5 | AE8: 134808.25 | AF8: 137501
A9: =IFERROR(LEFT(RIGHT(C9,LEN(C9)-SEARCH("@",C9)),SEARCH("/",RIGHT(C9,LEN(C9)-SEARCH("@",C9)-1))),"") -> 1 | B9: =LEFT(RIGHT(RIGHT(Tableau4[[#This Row],[file name]],LEN(Tableau4[[#This Row],[file name]])-SEARCH("@",Tableau4[[#This Row],[file name]])),LEN(RIGHT(Tableau4[[#This Row],[file name]],LEN(Tableau4[[#This Row],[file name]])-SEARCH("@",Tableau4[[#This Row],[file name]])))-SEARCH("/",RIGHT(Tableau4[[#This Row],[file name]],LEN(Tableau4[[#This Row],[file name]])-SEARCH("@",Tableau4[[#This Row],[file name]])))),1) -> B | C9: C:\Users\andre\Desktop\REACTIV CEFAS\Cromolyn\Cromolyn/20201217_Cefas_Test10_Run1/Plate 1/@1/B10_03.tif | D9: 5234.4345 | E9: 36.0537 | G9: 188721 | K9: E | L9: 264349.75 | M9: 637750.33 | N9: 2085300.2 | O9: 4822331 | P9: 413942 | Q9: 236681.67 | R9: 389197.5 | S9: 1033881.8 | T9: 2112563 | U9: 2341003.5 | V9: 4643738 | W9: 30860.25 | X9: 251577.33 | Y9: 136273.75 | Z9: 495908.67 | AA9: 728878.75 | AB9: 1205866.5 | AC9: 1500628 | AD9: 636421.75 | AE9: 261975.75 | AF9: 32401.5
A10: =IFERROR(LEFT(RIGHT(C10,LEN(C10)-SEARCH("@",C10)),SEARCH("/",RIGHT(C10,LEN(C10)-SEARCH("@",C10)-1))),"") -> 1 | B10: =LEFT(RIGHT(RIGHT(Tableau4[[#This Row],[file name]],LEN(Tableau4[[#This Row],[file name]])-SEARCH("@",Tableau4[[#This Row],[file name]])),LEN(RIGHT(Tableau4[[#This Row],[file name]],LEN(Tableau4[[#This Row],[file name]])-SEARCH("@",Tableau4[[#This Row],[file name]])))-SEARCH("/",RIGHT(Tableau4[[#This Row],[file name]],LEN(Tableau4[[#This Row],[file name]])-SEARCH("@",Tableau4[[#This Row],[file name]])))),1) -> B | C10: C:\Users\andre\Desktop\REACTIV CEFAS\Cromolyn\Cromolyn/20201217_Cefas_Test10_Run1/Plate 1/@1/B10_04.tif | D10: 1752.0215 | E10: 34.1605 | G10: 59850 | K10: F | L10: 317667.75 | M10: 3376023 | N10: 2051422.2 | O10: 3322741 | P10: 528953.75 | Q10: 850146.75 | R10: 352648.5 | S10: 95561 | T10: 3638786.2 | U10: 3538888.5 | V10: 6543416.2 | W10: 410994.75 | X10: 225421.25 | Y10: 98416 | Z10: 1096662.8 | AA10: 1005162.7 | AB10: 2062113 | AC10: 1695913.2 | AD10: 2108395.2 | AE10: 164387 | AF10: 294361.25
A11: =IFERROR(LEFT(RIGHT(C11,LEN(C11)-SEARCH("@",C11)),SEARCH("/",RIGHT(C11,LEN(C11)-SEARCH("@",C11)-1))),"") -> 1 | B11: =LEFT(RIGHT(RIGHT(Tableau4[[#This Row],[file name]],LEN(Tableau4[[#This Row],[file name]])-SEARCH("@",Tableau4[[#This Row],[file name]])),LEN(RIGHT(Tableau4[[#This Row],[file name]],LEN(Tableau4[[#This Row],[file name]])-SEARCH("@",Tableau4[[#This Row],[file name]])))-SEARCH("/",RIGHT(Tableau4[[#This Row],[file name]],LEN(Tableau4[[#This Row],[file name]])-SEARCH("@",Tableau4[[#This Row],[file name]])))),1) -> C | C11: C:\Users\andre\Desktop\REACTIV CEFAS\Cromolyn\Cromolyn/20201217_Cefas_Test10_Run1/Plate 1/@1/C10_01.tif | D11: 108.1495 | E11: 30.2 | G11: 3266 | K11: G | L11: 298157.25 | M11: 2218340.2 | N11: 2543243 | O11: 2581312 | P11: 226775 | Q11: 300109.25 | R11: 109501.25 | S11: 234549 | T11: 851217.25 | U11: 2891284.2 | V11: 4575566.2 | W11: 234821.33 | X11: 199660.5 | Y11: 308339.5 | Z11: 2599345.5 | AA11: 4532360.5 | AB11: 664713.75 | AC11: 2781912.8 | AD11: 322345.25 | AE11: 189321.25 | AF11: 175791.5
A12: =IFERROR(LEFT(RIGHT(C12,LEN(C12)-SEARCH("@",C12)),SEARCH("/",RIGHT(C12,LEN(C12)-SEARCH("@",C12)-1))),"") -> 1 | B12: =LEFT(RIGHT(RIGHT(Tableau4[[#This Row],[file name]],LEN(Tableau4[[#This Row],[file name]])-SEARCH("@",Tableau4[[#This Row],[file name]])),LEN(RIGHT(Tableau4[[#This Row],[file name]],LEN(Tableau4[[#This Row],[file name]])-SEARCH("@",Tableau4[[#This Row],[file name]])))-SEARCH("/",RIGHT(Tableau4[[#This Row],[file name]],LEN(Tableau4[[#This Row],[file name]])-SEARCH("@",Tableau4[[#This Row],[file name]])))),1) -> C | C12: C:\Users\andre\Desktop\REACTIV CEFAS\Cromolyn\Cromolyn/20201217_Cefas_Test10_Run1/Plate 1/@1/C10_02.tif | D12: 8500.5486 | E12: 45.5267 | G12: 387002 | K12: H | L12: 184454.5 | M12: 3870334.5 | N12: 2277946.8 | O12: 4275689.5 | P12: 126767.25 | Q12: 414428.5 | R12: 325070.25 | S12: 258012.25 | T12: 30520 | U12: 2631238.8 | V12: 5965557.2 | W12: 119261.75 | X12: 356433.75 | Y12: 162779.33 | Z12: 3355719.7 | AA12: 373543 | AB12: 2361855 | AC12: 2218129.8 | AD12: 1685304 | AE12: 270583 | AF12: 151793
A13: =IFERROR(LEFT(RIGHT(C13,LEN(C13)-SEARCH("@",C13)),SEARCH("/",RIGHT(C13,LEN(C13)-SEARCH("@",C13)-1))),"") -> 1 | B13: =LEFT(RIGHT(RIGHT(Tableau4[[#This Row],[file name]],LEN(Tableau4[[#This Row],[file name]])-SEARCH("@",Tableau4[[#This Row],[file name]])),LEN(RIGHT(Tableau4[[#This Row],[file name]],LEN(Tableau4[[#This Row],[file name]])-SEARCH("@",Tableau4[[#This Row],[file name]])))-SEARCH("/",RIGHT(Tableau4[[#This Row],[file name]],LEN(Tableau4[[#This Row],[file name]])-SEARCH("@",Tableau4[[#This Row],[file name]])))),1) -> C | C13: C:\Users\andre\Desktop\REACTIV CEFAS\Cromolyn\Cromolyn/20201217_Cefas_Test10_Run1/Plate 1/@1/C10_03.tif | D13: 151.4093 | E13: 30.7143 | G13: 4650
A14: =IFERROR(LEFT(RIGHT(C14,LEN(C14)-SEARCH("@",C14)),SEARCH("/",RIGHT(C14,LEN(C14)-SEARCH("@",C14)-1))),"") -> 1 | B14: =LEFT(RIGHT(RIGHT(Tableau4[[#This Row],[file name]],LEN(Tableau4[[#This Row],[file name]])-SEARCH("@",Tableau4[[#This Row],[file name]])),LEN(RIGHT(Tableau4[[#This Row],[file name]],LEN(Tableau4[[#This Row],[file name]])-SEARCH("@",Tableau4[[#This Row],[file name]])))-SEARCH("/",RIGHT(Tableau4[[#This Row],[file name]],LEN(Tableau4[[#This Row],[file name]])-SEARCH("@",Tableau4[[#This Row],[file name]])))),1) -> C | C14: C:\Users\andre\Desktop\REACTIV CEFAS\Cromolyn\Cromolyn/20201217_Cefas_Test10_Run1/Plate 1/@1/C10_04.tif | D14: 21.6299 | E14: 30 | G14: 649
A15: =IFERROR(LEFT(RIGHT(C15,LEN(C15)-SEARCH("@",C15)),SEARCH("/",RIGHT(C15,LEN(C15)-SEARCH("@",C15)-1))),"") -> 1 | B15: =LEFT(RIGHT(RIGHT(Tableau4[[#This Row],[file name]],LEN(Tableau4[[#This Row],[file name]])-SEARCH("@",Tableau4[[#This Row],[file name]])),LEN(RIGHT(Tableau4[[#This Row],[file name]],LEN(Tableau4[[#This Row],[file name]])-SEARCH("@",Tableau4[[#This Row],[file name]])))-SEARCH("/",RIGHT(Tableau4[[#This Row],[file name]],LEN(Tableau4[[#This Row],[file name]])-SEARCH("@",Tableau4[[#This Row],[file name]])))),1) -> D | C15: C:\Users\andre\Desktop\REACTIV CEFAS\Cromolyn\Cromolyn/20201217_Cefas_Test10_Run1/Plate 1/@1/D10_01.tif | D15: 10490.4989 | E15: 36.7835 | G15: 385877
A16: =IFERROR(LEFT(RIGHT(C16,LEN(C16)-SEARCH("@",C16)),SEARCH("/",RIGHT(C16,LEN(C16)-SEARCH("@",C16)-1))),"") -> 1 | B16: =LEFT(RIGHT(RIGHT(Tableau4[[#This Row],[file name]],LEN(Tableau4[[#This Row],[file name]])-SEARCH("@",Tableau4[[#This Row],[file name]])),LEN(RIGHT(Tableau4[[#This Row],[file name]],LEN(Tableau4[[#This Row],[file name]])-SEARCH("@",Tableau4[[#This Row],[file name]])))-SEARCH("/",RIGHT(Tableau4[[#This Row],[file name]],LEN(Tableau4[[#This Row],[file name]])-SEARCH("@",Tableau4[[#This Row],[file name]])))),1) -> D | C16: C:\Users\andre\Desktop\REACTIV CEFAS\Cromolyn\Cromolyn/20201217_Cefas_Test10_Run1/Plate 1/@1/D10_02.tif | D16: 7743.5023 | E16: 38.7709 | G16: 300223
A17: =IFERROR(LEFT(RIGHT(C17,LEN(C17)-SEARCH("@",C17)),SEARCH("/",RIGHT(C17,LEN(C17)-SEARCH("@",C17)-1))),"") -> 1 | B17: =LEFT(RIGHT(RIGHT(Tableau4[[#This Row],[file name]],LEN(Tableau4[[#This Row],[file name]])-SEARCH("@",Tableau4[[#This Row],[file name]])),LEN(RIGHT(Tableau4[[#This Row],[file name]],LEN(Tableau4[[#This Row],[file name]])-SEARCH("@",Tableau4[[#This Row],[file name]])))-SEARCH("/",RIGHT(Tableau4[[#This Row],[file name]],LEN(Tableau4[[#This Row],[file name]])-SEARCH("@",Tableau4[[#This Row],[file name]])))),1) -> D | C17: C:\Users\andre\Desktop\REACTIV CEFAS\Cromolyn\Cromolyn/20201217_Cefas_Test10_Run1/Plate 1/@1/D10_03.tif | D17: 10901.4669 | E17: 39.9901 | G17: 435951
A18: =IFERROR(LEFT(RIGHT(C18,LEN(C18)-SEARCH("@",C18)),SEARCH("/",RIGHT(C18,LEN(C18)-SEARCH("@",C18)-1))),"") -> 1 | B18: =LEFT(RIGHT(RIGHT(Tableau4[[#This Row],[file name]],LEN(Tableau4[[#This Row],[file name]])-SEARCH("@",Tableau4[[#This Row],[file name]])),LEN(RIGHT(Tableau4[[#This Row],[file name]],LEN(Tableau4[[#This Row],[file name]])-SEARCH("@",Tableau4[[#This Row],[file name]])))-SEARCH("/",RIGHT(Tableau4[[#This Row],[file name]],LEN(Tableau4[[#This Row],[file name]])-SEARCH("@",Tableau4[[#This Row],[file name]])))),1) -> D | C18: C:\Users\andre\Desktop\REACTIV CEFAS\Cromolyn\Cromolyn/20201217_Cefas_Test10_Run1/Plate 1/@1/D10_04.tif | D18: 6835.0467 | E18: 38.5854 | G18: 263733
A19: =IFERROR(LEFT(RIGHT(C19,LEN(C19)-SEARCH("@",C19)),SEARCH("/",RIGHT(C19,LEN(C19)-SEARCH("@",C19)-1))),"") -> 1 | B19: =LEFT(RIGHT(RIGHT(Tableau4[[#This Row],[file name]],LEN(Tableau4[[#This Row],[file name]])-SEARCH("@",Tableau4[[#This Row],[file name]])),LEN(RIGHT(Tableau4[[#This Row],[file name]],LEN(Tableau4[[#This Row],[file name]])-SEARCH("@",Tableau4[[#This Row],[file name]])))-SEARCH("/",RIGHT(Tableau4[[#This Row],[file name]],LEN(Tableau4[[#This Row],[file name]])-SEARCH("@",Tableau4[[#This Row],[file name]])))),1) -> E | C19: C:\Users\andre\Desktop\REACTIV CEFAS\Cromolyn\Cromolyn/20201217_Cefas_Test10_Run1/Plate 1/@1/E10_01.tif | D19: 6294.2993 | E19: 43.4192 | G19: 273294
A20: =IFERROR(LEFT(RIGHT(C20,LEN(C20)-SEARCH("@",C20)),SEARCH("/",RIGHT(C20,LEN(C20)-SEARCH("@",C20)-1))),"") -> 1 | B20: =LEFT(RIGHT(RIGHT(Tableau4[[#This Row],[file name]],LEN(Tableau4[[#This Row],[file name]])-SEARCH("@",Tableau4[[#This Row],[file name]])),LEN(RIGHT(Tableau4[[#This Row],[file name]],LEN(Tableau4[[#This Row],[file name]])-SEARCH("@",Tableau4[[#This Row],[file name]])))-SEARCH("/",RIGHT(Tableau4[[#This Row],[file name]],LEN(Tableau4[[#This Row],[file name]])-SEARCH("@",Tableau4[[#This Row],[file name]])))),1) -> E | C20: C:\Users\andre\Desktop\REACTIV CEFAS\Cromolyn\Cromolyn/20201217_Cefas_Test10_Run1/Plate 1/@1/E10_02.tif | D20: 6575.488 | E20: 45.7599 | G20: 300893
A21: =IFERROR(LEFT(RIGHT(C21,LEN(C21)-SEARCH("@",C21)),SEARCH("/",RIGHT(C21,LEN(C21)-SEARCH("@",C21)-1))),"") -> 1 | B21: =LEFT(RIGHT(RIGHT(Tableau4[[#This Row],[file name]],LEN(Tableau4[[#This Row],[file name]])-SEARCH("@",Tableau4[[#This Row],[file name]])),LEN(RIGHT(Tableau4[[#This Row],[file name]],LEN(Tableau4[[#This Row],[file name]])-SEARCH("@",Tableau4[[#This Row],[file name]])))-SEARCH("/",RIGHT(Tableau4[[#This Row],[file name]],LEN(Tableau4[[#This Row],[file name]])-SEARCH("@",Tableau4[[#This Row],[file name]])))),1) -> E | C21: C:\Users\andre\Desktop\REACTIV CEFAS\Cromolyn\Cromolyn/20201217_Cefas_Test10_Run1/Plate 1/@1/E10_03.tif | D21: 5450.7334 | E21: 39.4246 | G21: 214893
A22: =IFERROR(LEFT(RIGHT(C22,LEN(C22)-SEARCH("@",C22)),SEARCH("/",RIGHT(C22,LEN(C22)-SEARCH("@",C22)-1))),"") -> 1 | B22: =LEFT(RIGHT(RIGHT(Tableau4[[#This Row],[file name]],LEN(Tableau4[[#This Row],[file name]])-SEARCH("@",Tableau4[[#This Row],[file name]])),LEN(RIGHT(Tableau4[[#This Row],[file name]],LEN(Tableau4[[#This Row],[file name]])-SEARCH("@",Tableau4[[#This Row],[file name]])))-SEARCH("/",RIGHT(Tableau4[[#This Row],[file name]],LEN(Tableau4[[#This Row],[file name]])-SEARCH("@",Tableau4[[#This Row],[file name]])))),1) -> E | C22: C:\Users\andre\Desktop\REACTIV CEFAS\Cromolyn\Cromolyn/20201217_Cefas_Test10_Run1/Plate 1/@1/E10_04.tif | D22: 6337.5591 | E22: 42.3379 | G22: 268319
A23: =IFERROR(LEFT(RIGHT(C23,LEN(C23)-SEARCH("@",C23)),SEARCH("/",RIGHT(C23,LEN(C23)-SEARCH("@",C23)-1))),"") -> 1 | B23: =LEFT(RIGHT(RIGHT(Tableau4[[#This Row],[file name]],LEN(Tableau4[[#This Row],[file name]])-SEARCH("@",Tableau4[[#This Row],[file name]])),LEN(RIGHT(Tableau4[[#This Row],[file name]],LEN(Tableau4[[#This Row],[file name]])-SEARCH("@",Tableau4[[#This Row],[file name]])))-SEARCH("/",RIGHT(Tableau4[[#This Row],[file name]],LEN(Tableau4[[#This Row],[file name]])-SEARCH("@",Tableau4[[#This Row],[file name]])))),1) -> F | C23: C:\Users\andre\Desktop\REACTIV CEFAS\Cromolyn\Cromolyn/20201217_Cefas_Test10_Run1/Plate 1/@1/F10_01.tif | D23: 6359.189 | E23: 38.2789 | G23: 243423
A24: =IFERROR(LEFT(RIGHT(C24,LEN(C24)-SEARCH("@",C24)),SEARCH("/",RIGHT(C24,LEN(C24)-SEARCH("@",C24)-1))),"") -> 1 | B24: =LEFT(RIGHT(RIGHT(Tableau4[[#This Row],[file name]],LEN(Tableau4[[#This Row],[file name]])-SEARCH("@",Tableau4[[#This Row],[file name]])),LEN(RIGHT(Tableau4[[#This Row],[file name]],LEN(Tableau4[[#This Row],[file name]])-SEARCH("@",Tableau4[[#This Row],[file name]])))-SEARCH("/",RIGHT(Tableau4[[#This Row],[file name]],LEN(Tableau4[[#This Row],[file name]])-SEARCH("@",Tableau4[[#This Row],[file name]])))),1) -> F | C24: C:\Users\andre\Desktop\REACTIV CEFAS\Cromolyn\Cromolyn/20201217_Cefas_Test10_Run1/Plate 1/@1/F10_02.tif | D24: 9646.933 | E24: 44.0022 | G24: 424487
A25: =IFERROR(LEFT(RIGHT(C25,LEN(C25)-SEARCH("@",C25)),SEARCH("/",RIGHT(C25,LEN(C25)-SEARCH("@",C25)-1))),"") -> 1 | B25: =LEFT(RIGHT(RIGHT(Tableau4[[#This Row],[file name]],LEN(Tableau4[[#This Row],[file name]])-SEARCH("@",Tableau4[[#This Row],[file name]])),LEN(RIGHT(Tableau4[[#This Row],[file name]],LEN(Tableau4[[#This Row],[file name]])-SEARCH("@",Tableau4[[#This Row],[file name]])))-SEARCH("/",RIGHT(Tableau4[[#This Row],[file name]],LEN(Tableau4[[#This Row],[file name]])-SEARCH("@",Tableau4[[#This Row],[file name]])))),1) -> F | C25: C:\Users\andre\Desktop\REACTIV CEFAS\Cromolyn\Cromolyn/20201217_Cefas_Test10_Run1/Plate 1/@1/F10_03.tif | D25: 8803.3671 | E25: 41.0885 | G25: 361717
A26: =IFERROR(LEFT(RIGHT(C26,LEN(C26)-SEARCH("@",C26)),SEARCH("/",RIGHT(C26,LEN(C26)-SEARCH("@",C26)-1))),"") -> 1 | B26: =LEFT(RIGHT(RIGHT(Tableau4[[#This Row],[file name]],LEN(Tableau4[[#This Row],[file name]])-SEARCH("@",Tableau4[[#This Row],[file name]])),LEN(RIGHT(Tableau4[[#This Row],[file name]],LEN(Tableau4[[#This Row],[file name]])-SEARCH("@",Tableau4[[#This Row],[file name]])))-SEARCH("/",RIGHT(Tableau4[[#This Row],[file name]],LEN(Tableau4[[#This Row],[file name]])-SEARCH("@",Tableau4[[#This Row],[file name]])))),1) -> F | C26: C:\Users\andre\Desktop\REACTIV CEFAS\Cromolyn\Cromolyn/20201217_Cefas_Test10_Run1/Plate 1/@1/F10_04.tif | D26: 6380.8189 | E26: 37.7763 | G26: 241044
... A34: =IFERROR(LEFT(RIGHT(C34,LEN(C34)-SEARCH("@",C34)),SEARCH("/",RIGHT(C34,LEN(C34)-SEARCH("@",C34)-1))),"") -> 1 | B34: =LEFT(RIGHT(RIGHT(Tableau4[[#This Row],[file name]],LEN(Tableau4[[#This Row],[file name]])-SEARCH("@",Tableau4[[#This Row],[file name]])),LEN(RIGHT(Tableau4[[#This Row],[file name]],LEN(Tableau4[[#This Row],[file name]])-SEARCH("@",Tableau4[[#This Row],[file name]])))-SEARCH("/",RIGHT(Tableau4[[#This Row],[file name]],LEN(Tableau4[[#This Row],[file name]])-SEARCH("@",Tableau4[[#This Row],[file name]])))),1) -> H | C34: C:\Users\andre\Desktop\REACTIV CEFAS\Cromolyn\Cromolyn/20201217_Cefas_Test10_Run1/Plate 1/@1/H10_04.tif | D34: 7419.0539 | E34: 39.1603 | G34: 290533
A35: =IFERROR(LEFT(RIGHT(C35,LEN(C35)-SEARCH("@",C35)),SEARCH("/",RIGHT(C35,LEN(C35)-SEARCH("@",C35)-1))),"") | B35: =LEFT(RIGHT(RIGHT(Tableau4[[#This Row],[file name]],LEN(Tableau4[[#This Row],[file name]])-SEARCH("@",Tableau4[[#This Row],[file name]])),LEN(RIGHT(Tableau4[[#This Row],[file name]],LEN(Tableau4[[#This Row],[file name]])-SEARCH("@",Tableau4[[#This Row],[file name]])))-SEARCH("/",RIGHT(Tableau4[[#This Row],[file name]],LEN(Tableau4[[#This Row],[file name]])-SEARCH("@",Tableau4[[#This Row],[file name]])))),1) -> #VALUE!
A36: =IFERROR(LEFT(RIGHT(C36,LEN(C36)-SEARCH("@",C36)),SEARCH("/",RIGHT(C36,LEN(C36)-SEARCH("@",C36)-1))),"") | B36: =LEFT(RIGHT(RIGHT(Tableau4[[#This Row],[file name]],LEN(Tableau4[[#This Row],[file name]])-SEARCH("@",Tableau4[[#This Row],[file name]])),LEN(RIGHT(Tableau4[[#This Row],[file name]],LEN(Tableau4[[#This Row],[file name]])-SEARCH("@",Tableau4[[#This Row],[file name]])))-SEARCH("/",RIGHT(Tableau4[[#This Row],[file name]],LEN(Tableau4[[#This Row],[file name]])-SEARCH("@",Tableau4[[#This Row],[file name]])))),1) -> #VALUE! | C36: group | E36: mean of mean fluo | F36: SD mean fluo | G36: mean of total fluo | H36: SD total fluo
A37: =IFERROR(LEFT(RIGHT(C37,LEN(C37)-SEARCH("@",C37)),SEARCH("/",RIGHT(C37,LEN(C37)-SEARCH("@",C37)-1))),"") -> 1 | B37: =LEFT(RIGHT(RIGHT(Tableau4[[#This Row],[file name]],LEN(Tableau4[[#This Row],[file name]])-SEARCH("@",Tableau4[[#This Row],[file name]])),LEN(RIGHT(Tableau4[[#This Row],[file name]],LEN(Tableau4[[#This Row],[file name]])-SEARCH("@",Tableau4[[#This Row],[file name]])))-SEARCH("/",RIGHT(Tableau4[[#This Row],[file name]],LEN(Tableau4[[#This Row],[file name]])-SEARCH("@",Tableau4[[#This Row],[file name]])))),1) | C37: C:\Users\andre\Desktop\REACTIV CEFAS\Cromolyn\Cromolyn/20201217_Cefas_Test10_Run1/Plate 1/@1/ | E37: 36.8441 | F37: 7.8914 | G37: 233202.75 | H37: 137729.762
A38: =IFERROR(LEFT(RIGHT(C38,LEN(C38)-SEARCH("@",C38)),SEARCH("/",RIGHT(C38,LEN(C38)-SEARCH("@",C38)-1))),"") | B38: =LEFT(RIGHT(RIGHT(Tableau4[[#This Row],[file name]],LEN(Tableau4[[#This Row],[file name]])-SEARCH("@",Tableau4[[#This Row],[file name]])),LEN(RIGHT(Tableau4[[#This Row],[file name]],LEN(Tableau4[[#This Row],[file name]])-SEARCH("@",Tableau4[[#This Row],[file name]])))-SEARCH("/",RIGHT(Tableau4[[#This Row],[file name]],LEN(Tableau4[[#This Row],[file name]])-SEARCH("@",Tableau4[[#This Row],[file name]])))),1) -> #VALUE!
A39: =IFERROR(LEFT(RIGHT(C39,LEN(C39)-SEARCH("@",C39)),SEARCH("/",RIGHT(C39,LEN(C39)-SEARCH("@",C39)-1))),"") | B39: =LEFT(RIGHT(RIGHT(Tableau4[[#This Row],[file name]],LEN(Tableau4[[#This Row],[file name]])-SEARCH("@",Tableau4[[#This Row],[file name]])),LEN(RIGHT(Tableau4[[#This Row],[file name]],LEN(Tableau4[[#This Row],[file name]])-SEARCH("@",Tableau4[[#This Row],[file name]])))-SEARCH("/",RIGHT(Tableau4[[#This Row],[file name]],LEN(Tableau4[[#This Row],[file name]])-SEARCH("@",Tableau4[[#This Row],[file name]])))),1) -> #VALUE!
A40: =IFERROR(LEFT(RIGHT(C40,LEN(C40)-SEARCH("@",C40)),SEARCH("/",RIGHT(C40,LEN(C40)-SEARCH("@",C40)-1))),"") | B40: =LEFT(RIGHT(RIGHT(Tableau4[[#This Row],[file name]],LEN(Tableau4[[#This Row],[file name]])-SEARCH("@",Tableau4[[#This Row],[file name]])),LEN(RIGHT(Tableau4[[#This Row],[file name]],LEN(Tableau4[[#This Row],[file name]])-SEARCH("@",Tableau4[[#This Row],[file name]])))-SEARCH("/",RIGHT(Tableau4[[#This Row],[file name]],LEN(Tableau4[[#This Row],[file name]])-SEARCH("@",Tableau4[[#This Row],[file name]])))),1) -> #VALUE!
A41: =IFERROR(LEFT(RIGHT(C41,LEN(C41)-SEARCH("@",C41)),SEARCH("/",RIGHT(C41,LEN(C41)-SEARCH("@",C41)-1))),"") | B41: =LEFT(RIGHT(RIGHT(Tableau4[[#This Row],[file name]],LEN(Tableau4[[#This Row],[file name]])-SEARCH("@",Tableau4[[#This Row],[file name]])),LEN(RIGHT(Tableau4[[#This Row],[file name]],LEN(Tableau4[[#This Row],[file name]])-SEARCH("@",Tableau4[[#This Row],[file name]])))-SEARCH("/",RIGHT(Tableau4[[#This Row],[file name]],LEN(Tableau4[[#This Row],[file name]])-SEARCH("@",Tableau4[[#This Row],[file name]])))),1) -> #VALUE!
A42: =IFERROR(LEFT(RIGHT(C42,LEN(C42)-SEARCH("@",C42)),SEARCH("/",RIGHT(C42,LEN(C42)-SEARCH("@",C42)-1))),"") | B42: =LEFT(RIGHT(RIGHT(Tableau4[[#This Row],[file name]],LEN(Tableau4[[#This Row],[file name]])-SEARCH("@",Tableau4[[#This Row],[file name]])),LEN(RIGHT(Tableau4[[#This Row],[file name]],LEN(Tableau4[[#This Row],[file name]])-SEARCH("@",Tableau4[[#This Row],[file name]])))-SEARCH("/",RIGHT(Tableau4[[#This Row],[file name]],LEN(Tableau4[[#This Row],[file name]])-SEARCH("@",Tableau4[[#This Row],[file name]])))),1) -> #VALUE!
A43: =IFERROR(LEFT(RIGHT(C43,LEN(C43)-SEARCH("@",C43)),SEARCH("/",RIGHT(C43,LEN(C43)-SEARCH("@",C43)-1))),"") | B43: =LEFT(RIGHT(RIGHT(Tableau4[[#This Row],[file name]],LEN(Tableau4[[#This Row],[file name]])-SEARCH("@",Tableau4[[#This Row],[file name]])),LEN(RIGHT(Tableau4[[#This Row],[file name]],LEN(Tableau4[[#This Row],[file name]])-SEARCH("@",Tableau4[[#This Row],[file name]])))-SEARCH("/",RIGHT(Tableau4[[#This Row],[file name]],LEN(Tableau4[[#This Row],[file name]])-SEARCH("@",Tableau4[[#This Row],[file name]])))),1) -> #VALUE! | C43: file name | D43: total area | E43: mean intensity | G43: total fluorescence
A44: =IFERROR(LEFT(RIGHT(C44,LEN(C44)-SEARCH("@",C44)),SEARCH("/",RIGHT(C44,LEN(C44)-SEARCH("@",C44)-1))),"") -> 13 | B44: =LEFT(RIGHT(RIGHT(Tableau4[[#This Row],[file name]],LEN(Tableau4[[#This Row],[file name]])-SEARCH("@",Tableau4[[#This Row],[file name]])),LEN(RIGHT(Tableau4[[#This Row],[file name]],LEN(Tableau4[[#This Row],[file name]])-SEARCH("@",Tableau4[[#This Row],[file name]])))-SEARCH("/",RIGHT(Tableau4[[#This Row],[file name]],LEN(Tableau4[[#This Row],[file name]])-SEARCH("@",Tableau4[[#This Row],[file name]])))),1) -> A | C44: C:\Users\andre\Desktop\REACTIV CEFAS\Cromolyn\Cromolyn/20201217_Cefas_Test10_Run1/Plate 1/@13/A8_01.tif | D44: 7830.0219 | E44: 41.1685 | G44: 322350
A45: =IFERROR(LEFT(RIGHT(C45,LEN(C45)-SEARCH("@",C45)),SEARCH("/",RIGHT(C45,LEN(C45)-SEARCH("@",C45)-1))),"") -> 13 | B45: =LEFT(RIGHT(RIGHT(Tableau4[[#This Row],[file name]],LEN(Tableau4[[#This Row],[file name]])-SEARCH("@",Tableau4[[#This Row],[file name]])),LEN(RIGHT(Tableau4[[#This Row],[file name]],LEN(Tableau4[[#This Row],[file name]])-SEARCH("@",Tableau4[[#This Row],[file name]])))-SEARCH("/",RIGHT(Tableau4[[#This Row],[file name]],LEN(Tableau4[[#This Row],[file name]])-SEARCH("@",Tableau4[[#This Row],[file name]])))),1) -> A | C45: C:\Users\andre\Desktop\REACTIV CEFAS\Cromolyn\Cromolyn/20201217_Cefas_Test10_Run1/Plate 1/@13/A8_02.tif | D45: 2725.3667 | E45: 33.6587 | G45: 91732
A46: =IFERROR(LEFT(RIGHT(C46,LEN(C46)-SEARCH("@",C46)),SEARCH("/",RIGHT(C46,LEN(C46)-SEARCH("@",C46)-1))),"") -> 13 | B46: =LEFT(RIGHT(RIGHT(Tableau4[[#This Row],[file name]],LEN(Tableau4[[#This Row],[file name]])-SEARCH("@",Tableau4[[#This Row],[file name]])),LEN(RIGHT(Tableau4[[#This Row],[file name]],LEN(Tableau4[[#This Row],[file name]])-SEARCH("@",Tableau4[[#This Row],[file name]])))-SEARCH("/",RIGHT(Tableau4[[#This Row],[file name]],LEN(Tableau4[[#This Row],[file name]])-SEARCH("@",Tableau4[[#This Row],[file name]])))),1) -> A | C46: C:\Users\andre\Desktop\REACTIV CEFAS\Cromolyn\Cromolyn/20201217_Cefas_Test10_Run1/Plate 1/@13/A8_03.tif | D46: 7613.7229 | E46: 40.0199 | G46: 304700
A47: =IFERROR(LEFT(RIGHT(C47,LEN(C47)-SEARCH("@",C47)),SEARCH("/",RIGHT(C47,LEN(C47)-SEARCH("@",C47)-1))),"") -> 13 | B47: =LEFT(RIGHT(RIGHT(Tableau4[[#This Row],[file name]],LEN(Tableau4[[#This Row],[file name]])-SEARCH("@",Tableau4[[#This Row],[file name]])),LEN(RIGHT(Tableau4[[#This Row],[file name]],LEN(Tableau4[[#This Row],[file name]])-SEARCH("@",Tableau4[[#This Row],[file name]])))-SEARCH("/",RIGHT(Tableau4[[#This Row],[file name]],LEN(Tableau4[[#This Row],[file name]])-SEARCH("@",Tableau4[[#This Row],[file name]])))),1) -> A | C47: C:\Users\andre\Desktop\REACTIV CEFAS\Cromolyn\Cromolyn/20201217_Cefas_Test10_Run1/Plate 1/@13/A8_04.tif | D47: 5039.7654 | E47: 35.4292 | G47: 178555
...

Sheet R1
A1: 3. Expérimentateur 1 : copier et coller les valeurs des intensités totales de fluorescences obtenues dans le fichier raw data lors du traitement des images.
A3: R1 | B3: Non dopé | O3: avec testo
A4: Noms des groupes | B4: ='Page de garde'!A7 -> Témoin solvant | C4: ='Page de garde'!A9 -> EE2-33,8ng/L | D4: ='Page de garde'!A10 -> EE2-50,6ng/L | E4: ='Page de garde'!A11 -> EE2-76ng/L | F4: ='Page de garde'!A12 -> EE2-114ng/L | G4: ='Page de garde'!A13 -> EE2-170,9ng/L | H4: ='Page de garde'!A14 -> EE2-488ng/L | I4: ='Page de garde'!A15 -> CRO-0.1µg/L | J4: ='Page de garde'!A16 -> CRO-1µg/L | K4: ='Page de garde'!A17 -> CRO-10µg/L | L4: ='Page de garde'!A18 -> CRO-100µg/L | M4: ='Page de garde'!A19 -> CRO-1000µg/L | O4: ='Page de garde'!A36 -> Testo -30µg/L | P4: ='Page de garde'!A37 -> Testo 30µg/L + EE2 -64ng/L | Q4: ='Page de garde'!A38 -> Testo 30µg/L + FAD-10mg/L | R4: ='Page de garde'!A39 -> CRO-0,1µg/L + Testostérone | S4: ='Page de garde'!A40 -> CRO-1µg/L + Testostérone | T4: ='Page de garde'!A41 -> CRO-10µg/L + Testostérone | U4: ='Page de garde'!A42 -> CRO-100µg/L + Testostérone | V4: ='Page de garde'!A43 -> CRO-1000µg/L + Testostérone
A5: Données brutes | B5: 276639.33 | C5: 348706.5 | D5: 472078 | E5: 617944 | F5: 1923734 | G5: 2825048.2 | H5: 5966260 | I5: 194371.75 | J5: 147375 | K5: 134271 | L5: 63575.5 | M5: 542039.75 | O5: 224334.25 | P5: 2147113.3 | Q5: 132672.25 | R5: 585824 | S5: 85648.75 | T5: 1868174.3 | U5: 1133395.5 | V5: 1032351.7
B6: 148175.5 | C6: 236166.25 | D6: 437286 | E6: 682798 | F6: 2626334.2 | G6: 2580084 | H6: 5184188.5 | I6: 83743.667 | J6: 43568 | K6: 40224.333 | L6: 102158 | M6: 143260.25 | O6: 2383625.2 | P6: 3481558.5 | Q6: 284384.5 | R6: 1938509 | S6: 1396368.3 | T6: 1597908.5 | U6: 2317027 | V6: 2226359.8
B7: 98891.75 | C7: 494041 | D7: 196713 | E7: 3041119.7 | F7: 3128991.5 | G7: 3289528.5 | H7: 4711640 | I7: 252383 | J7: 95177.25 | K7: 412595.5 | L7: 125837.25 | M7: 98913.75 | O7: 1803982.2 | P7: 3323087.2 | Q7: 169421.5 | R7: 1128291 | S7: 2544400.2 | T7: 2025401.8 | U7: 667114.75 | V7: 3054811.8
B8: 346446 | C8: 456099 | D8: 183805.5 | E8: 1098874.5 | F8: 2428815.5 | G8: 3001110.2 | H8: 4374019 | I8: 134808.25 | J8: 137501 | K8: 19921.25 | L8: 305695 | M8: 202877.75 | O8: 2453299 | P8: 3442078.5 | Q8: 237615.5 | R8: 2220099.3 | S8: 1279132.5 | T8: 3646230.7 | U8: 243671.75 | V8: 2840875.5
B9: 264349.75 | C9: 236681.67 | D9: 389197.5 | E9: 1033881.8 | F9: 2112563 | G9: 2341003.5 | H9: 4643738 | I9: 261975.75 | J9: 32401.5 | K9: 30860.25 | L9: 251577.33 | M9: 136273.75 | O9: 637750.33 | P9: 4822331 | Q9: 413942 | R9: 495908.67 | S9: 728878.75 | T9: 1205866.5 | U9: 1500628 | V9: 636421.75
B10: 317667.75 | C10: 850146.75 | D10: 352648.5 | E10: 95561 | F10: 3638786.2 | G10: 3538888.5 | H10: 6543416.2 | I10: 164387 | J10: 294361.25 | K10: 410994.75 | L10: 225421.25 | M10: 98416 | O10: 3376023 | P10: 3322741 | Q10: 528953.75 | R10: 1096662.8 | S10: 1005162.7 | T10: 2062113 | U10: 1695913.2 | V10: 2108395.2
B11: 298157.25 | C11: 300109.25 | D11: 109501.25 | E11: 234549 | F11: 851217.25 | G11: 2891284.2 | H11: 4575566.2 | I11: 189321.25 | J11: 175791.5 | K11: 234821.33 | L11: 199660.5 | M11: 308339.5 | O11: 2218340.2 | P11: 2581312 | Q11: 226775 | R11: 2599345.5 | S11: 4532360.5 | T11: 664713.75 | U11: 2781912.8 | V11: 322345.25
B12: 184454.5 | C12: 414428.5 | D12: 325070.25 | E12: 258012.25 | F12: 30520 | G12: 2631238.8 | H12: 5965557.2 | I12: 270583 | J12: 151793 | K12: 119261.75 | L12: 356433.75 | M12: 162779.33 | O12: 3870334.5 | P12: 4275689.5 | Q12: 126767.25 | R12: 3355719.7 | S12: 373543 | T12: 2361855 | U12: 2218129.8 | V12: 1685304
O13: 696807.5
O14: 393037
O15: 2433074.7
O16: 1107436.3
O17: 2085300.2
O18: 2051422.2
O19: 2543243
O20: 2277946.8
A22: =A4 -> Noms des groupes | B22: =B4 -> Témoin solvant | C22: =C4 -> EE2-33,8ng/L | D22: =D4 -> EE2-50,6ng/L | E22: =E4 -> EE2-76ng/L | F22: =F4 -> EE2-114ng/L | G22: =G4 -> EE2-170,9ng/L | H22: =H4 -> EE2-488ng/L | ... M22: =M4 -> CRO-1000µg/L | N22: Nom des groupes | O22: =O4 -> Testo -30µg/L | P22: =P4 -> Testo 30µg/L + EE2 -64ng/L | Q22: =Q4 -> Testo 30µg/L + FAD-10mg/L | R22: =R4 -> CRO-0,1µg/L + Testostérone | S22: =S4 -> CRO-1µg/L + Testostérone | T22: =T4 -> CRO-10µg/L + Testostérone | U22: =U4 -> CRO-100µg/L + Testostérone | V22: =V4 -> CRO-1000µg/L + Testostérone
A23: mean | B23: =AVERAGE(B5:B20) -> 241847.73 | C23: =AVERAGE(C5:C20) -> 417047.36 | D23: =AVERAGE(D5:D20) -> 308287.5 | E23: =AVERAGE(E5:E20) -> 882842.52 | F23: =AVERAGE(F5:F20) -> 2092620.2 | G23: =AVERAGE(G5:G20) -> 2887273.2 | H23: =AVERAGE(H5:H20) -> 5245548.2 | I23: =AVERAGE(I5:I20) -> 193946.71 | ... M23: =AVERAGE(M5:M20) -> 211612.51 | N23: mean | O23: =AVERAGE(O5:O20) -> 1909747.3 | P23: =AVERAGE(P5:P20) -> 3424488.9 | Q23: =AVERAGE(Q5:Q20) -> 265066.47 | R23: =AVERAGE(R5:R20) -> 1677545 | S23: =AVERAGE(S5:S20) -> 1493186.8 | T23: =AVERAGE(T5:T20) -> 1929032.9 | U23: =AVERAGE(U5:U20) -> 1569724.1 | V23: =AVERAGE(V5:V20) -> 1738358.1
A24: SD | B24: =STDEV(B5:B20) -> 87897.598 | C24: =STDEV(C5:C20) -> 199510.02 | D24: =STDEV(D5:D20) -> 130780.37 | E24: =STDEV(E5:E20) -> 946296.65 | F24: =STDEV(F5:F20) -> 1176242.9 | G24: =STDEV(G5:G20) -> 389429.65 | H24: =STDEV(H5:H20) -> 809032.71 | I24: =STDEV(I5:I20) -> 65958.094 | ... M24: =STDEV(M5:M20) -> 149695.72 | N24: SD | O24: =STDEV(O5:O20) -> 1044218.1 | P24: =STDEV(P5:P20) -> 848977.69 | Q24: =STDEV(Q5:Q20) -> 141520.45 | R24: =STDEV(R5:R20) -> 1018098.9 | S24: =STDEV(S5:S20) -> 1436957.1 | T24: =STDEV(T5:T20) -> 878140.9 | U24: =STDEV(U5:U20) -> 864580.16 | V24: =STDEV(V5:V20) -> 1003158.1
B26: Non dopé | O26: avec testo
A27: Noms des groupes | B27: =B4 -> Témoin solvant | C27: =C4 -> EE2-33,8ng/L | D27: =D4 -> EE2-50,6ng/L | E27: =E4 -> EE2-76ng/L | F27: =F4 -> EE2-114ng/L | G27: =G4 -> EE2-170,9ng/L | H27: =H4 -> EE2-488ng/L | I27: =I4 -> CRO-0.1µg/L | ... M27: =M4 -> CRO-1000µg/L | O27: =O4 -> Testo -30µg/L | P27: =P4 -> Testo 30µg/L + EE2 -64ng/L | Q27: =Q4 -> Testo 30µg/L + FAD-10mg/L | R27: =R4 -> CRO-0,1µg/L + Testostérone | S27: =S4 -> CRO-1µg/L + Testostérone | T27: =T4 -> CRO-10µg/L + Testostérone | U27: =U4 -> CRO-100µg/L + Testostérone | V27: =V4 -> CRO-1000µg/L + Testostérone
A28: Données normalisées sur la moyenne du groupe "Testo" | B28: =IF(B5="","",(B5/$O$23)) -> 0.14485651 | C28: =IF(C5="","",(C5/$O$23)) -> 0.18259301 | D28: =IF(D5="","",(D5/$O$23)) -> 0.24719396 | E28: =IF(E5="","",(E5/$O$23)) -> 0.3235737 | F28: =IF(F5="","",(F5/$O$23)) -> 1.0073239 | G28: =IF(G5="","",(G5/$O$23)) -> 1.4792786 | H28: =IF(H5="","",(H5/$O$23)) -> 3.1241097 | I28: =IF(I5="","",(I5/$O$23)) -> 0.10177878 | ... M28: =IF(M5="","",(M5/$O$23)) -> 0.283828 | O28: =IF(O5="","",(O5/$O$23)) -> 0.11746803 | P28: =IF(P5="","",(P5/$O$23)) -> 1.1242919 | Q28: =IF(Q5="","",(Q5/$O$23)) -> 0.069471103 | R28: =IF(R5="","",(R5/$O$23)) -> 0.30675472 | S28: =IF(S5="","",(S5/$O$23)) -> 0.044848211 | T28: =IF(T5="","",(T5/$O$23)) -> 0.97823118 | U28: =IF(U5="","",(U5/$O$23)) -> 0.59347931 | V28: =IF(V5="","",(V5/$O$23)) -> 0.54056978
B29: =IF(B6="","",(B6/$O$23)) -> 0.077589062 | C29: =IF(C6="","",(C6/$O$23)) -> 0.12366361 | D29: =IF(D6="","",(D6/$O$23)) -> 0.22897585 | E29: =IF(E6="","",(E6/$O$23)) -> 0.35753317 | F29: =IF(F6="","",(F6/$O$23)) -> 1.3752261 | G29: =IF(G6="","",(G6/$O$23)) -> 1.3510081 | H29: =IF(H6="","",(H6/$O$23)) -> 2.714594 | I29: =IF(I6="","",(I6/$O$23)) -> 0.043850654 | ... M29: =IF(M6="","",(M6/$O$23)) -> 0.075015292 | O29: =IF(O6="","",(O6/$O$23)) -> 1.2481365 | P29: =IF(P6="","",(P6/$O$23)) -> 1.8230467 | Q29: =IF(Q6="","",(Q6/$O$23)) -> 0.14891211 | R29: =IF(R6="","",(R6/$O$23)) -> 1.0150605 | S29: =IF(S6="","",(S6/$O$23)) -> 0.73117964 | T29: =IF(T6="","",(T6/$O$23)) -> 0.83671201 | U29: =IF(U6="","",(U6/$O$23)) -> 1.2132637 | V29: =IF(V6="","",(V6/$O$23)) -> 1.1657876
B30: =IF(B7="","",(B7/$O$23)) -> 0.051782637 | C30: =IF(C7="","",(C7/$O$23)) -> 0.25869444 | D30: =IF(D7="","",(D7/$O$23)) -> 0.10300473 | E30: =IF(E7="","",(E7/$O$23)) -> 1.5924199 | F30: =IF(F7="","",(F7/$O$23)) -> 1.6384322 | G30: =IF(G7="","",(G7/$O$23)) -> 1.7224941 | H30: =IF(H7="","",(H7/$O$23)) -> 2.4671537 | I30: =IF(I7="","",(I7/$O$23)) -> 0.13215518 | ... M30: =IF(M7="","",(M7/$O$23)) -> 0.051794157 | O30: =IF(O7="","",(O7/$O$23)) -> 0.94461831 | P30: =IF(P7="","",(P7/$O$23)) -> 1.7400665 | Q30: =IF(Q7="","",(Q7/$O$23)) -> 0.088714094 | R30: =IF(R7="","",(R7/$O$23)) -> 0.59080644 | S30: =IF(S7="","",(S7/$O$23)) -> 1.332323 | T30: =IF(T7="","",(T7/$O$23)) -> 1.0605601 | U30: =IF(U7="","",(U7/$O$23)) -> 0.34932096 | V30: =IF(V7="","",(V7/$O$23)) -> 1.5995895
B31: =IF(B8="","",(B8/$O$23)) -> 0.18140934 | C31: =IF(C8="","",(C8/$O$23)) -> 0.23882689 | D31: =IF(D8="","",(D8/$O$23)) -> 0.09624598 | E31: =IF(E8="","",(E8/$O$23)) -> 0.5754031 | F31: =IF(F8="","",(F8/$O$23)) -> 1.2717994 | G31: =IF(G8="","",(G8/$O$23)) -> 1.5714698 | H31: =IF(H8="","",(H8/$O$23)) -> 2.2903653 | I31: =IF(I8="","",(I8/$O$23)) -> 0.070589575 | ... M31: =IF(M8="","",(M8/$O$23)) -> 0.10623277 | O31: =IF(O8="","",(O8/$O$23)) -> 1.2846197 | P31: =IF(P8="","",(P8/$O$23)) -> 1.8023738 | Q31: =IF(Q8="","",(Q8/$O$23)) -> 0.12442248 | R31: =IF(R8="","",(R8/$O$23)) -> 1.1625095 | S31: =IF(S8="","",(S8/$O$23)) -> 0.6697915 | T31: =IF(T8="","",(T8/$O$23)) -> 1.9092739 | U31: =IF(U8="","",(U8/$O$23)) -> 0.12759371 | V31: =IF(V8="","",(V8/$O$23)) -> 1.4875662
B32: =IF(B9="","",(B9/$O$23)) -> 0.13842133 | C32: =IF(C9="","",(C9/$O$23)) -> 0.1239335 | D32: =IF(D9="","",(D9/$O$23)) -> 0.20379529 | E32: =IF(E9="","",(E9/$O$23)) -> 0.54137097 | F32: =IF(F9="","",(F9/$O$23)) -> 1.1062003 | G32: =IF(G9="","",(G9/$O$23)) -> 1.2258185 | H32: =IF(H9="","",(H9/$O$23)) -> 2.4315982 | I32: =IF(I9="","",(I9/$O$23)) -> 0.13717823 | ... M32: =IF(M9="","",(M9/$O$23)) -> 0.071356954 | O32: =IF(O9="","",(O9/$O$23)) -> 0.33394488 | P32: =IF(P9="","",(P9/$O$23)) -> 2.5251147 | Q32: =IF(Q9="","",(Q9/$O$23)) -> 0.21675224 | R32: =IF(R9="","",(R9/$O$23)) -> 0.2596724 | S32: =IF(S9="","",(S9/$O$23)) -> 0.38166241 | T32: =IF(T9="","",(T9/$O$23)) -> 0.63142726 | U32: =IF(U9="","",(U9/$O$23)) -> 0.78577308 | V32: =IF(V9="","",(V9/$O$23)) -> 0.3332492
B33: =IF(B10="","",(B10/$O$23)) -> 0.1663402 | C33: =IF(C10="","",(C10/$O$23)) -> 0.44516191 | D33: =IF(D10="","",(D10/$O$23)) -> 0.18465715 | E33: =IF(E10="","",(E10/$O$23)) -> 0.050038558 | F33: =IF(F10="","",(F10/$O$23)) -> 1.9053758 | G33: =IF(G10="","",(G10/$O$23)) -> 1.8530664 | H33: =IF(H10="","",(H10/$O$23)) -> 3.4263257 | I33: =IF(I10="","",(I10/$O$23)) -> 0.086077881 | ... M33: =IF(M10="","",(M10/$O$23)) -> 0.05153352 | O33: =IF(O10="","",(O10/$O$23)) -> 1.7677852 | P33: =IF(P10="","",(P10/$O$23)) -> 1.7398852 | Q33: =IF(Q10="","",(Q10/$O$23)) -> 0.27697578 | R33: =IF(R10="","",(R10/$O$23)) -> 0.57424496 | S33: =IF(S10="","",(S10/$O$23)) -> 0.52633282 | T33: =IF(T10="","",(T10/$O$23)) -> 1.0797832 | U33: =IF(U10="","",(U10/$O$23)) -> 0.88803019 | V33: =IF(V10="","",(V10/$O$23)) -> 1.1040179
B34: =IF(B11="","",(B11/$O$23)) -> 0.15612393 | C34: =IF(C11="","",(C11/$O$23)) -> 0.15714605 | D34: =IF(D11="","",(D11/$O$23)) -> 0.057338084 | E34: =IF(E11="","",(E11/$O$23)) -> 0.12281677 | F34: =IF(F11="","",(F11/$O$23)) -> 0.44572246 | G34: =IF(G11="","",(G11/$O$23)) -> 1.5139617 | H34: =IF(H11="","",(H11/$O$23)) -> 2.3959014 | I34: =IF(I11="","",(I11/$O$23)) -> 0.09913419 | ... M34: =IF(M11="","",(M11/$O$23)) -> 0.16145566 | O34: =IF(O11="","",(O11/$O$23)) -> 1.1615884 | P34: =IF(P11="","",(P11/$O$23)) -> 1.3516511 | Q34: =IF(Q11="","",(Q11/$O$23)) -> 0.11874608 | R34: =IF(R11="","",(R11/$O$23)) -> 1.361094 | S34: =IF(S11="","",(S11/$O$23)) -> 2.3732776 | T34: =IF(T11="","",(T11/$O$23)) -> 0.34806372 | U34: =IF(U11="","",(U11/$O$23)) -> 1.4566916 | V34: =IF(V11="","",(V11/$O$23)) -> 0.16878948
B35: =IF(B12="","",(B12/$O$23)) -> 0.096585816 | C35: =IF(C12="","",(C12/$O$23)) -> 0.21700698 | D35: =IF(D12="","",(D12/$O$23)) -> 0.17021637 | E35: =IF(E12="","",(E12/$O$23)) -> 0.13510282 | F35: =IF(F12="","",(F12/$O$23)) -> 0.015981172 | G35: =IF(G12="","",(G12/$O$23)) -> 1.3777942 | H35: =IF(H12="","",(H12/$O$23)) -> 3.1237417 | I35: =IF(I12="","",(I12/$O$23)) -> 0.14168524 | ... M35: =IF(M12="","",(M12/$O$23)) -> 0.085236059 | O35: =IF(O12="","",(O12/$O$23)) -> 2.0266213 | P35: =IF(P12="","",(P12/$O$23)) -> 2.2388771 | Q35: =IF(Q12="","",(Q12/$O$23)) -> 0.066379071 | R35: =IF(R12="","",(R12/$O$23)) -> 1.7571538 | S35: =IF(S12="","",(S12/$O$23)) -> 0.19559813 | T35: =IF(T12="","",(T12/$O$23)) -> 1.2367369 | U35: =IF(U12="","",(U12/$O$23)) -> 1.1614782 | V35: =IF(V12="","",(V12/$O$23)) -> 0.88247488
B36: =IF(B13="","",(B13/$O$23)) | C36: =IF(C13="","",(C13/$O$23)) | D36: =IF(D13="","",(D13/$O$23)) | E36: =IF(E13="","",(E13/$O$23)) | F36: =IF(F13="","",(F13/$O$23)) | G36: =IF(G13="","",(G13/$O$23)) | H36: =IF(H13="","",(H13/$O$23)) | I36: =IF(I13="","",(I13/$O$23)) | ... M36: =IF(M13="","",(M13/$O$23)) | O36: =IF(O13="","",(O13/$O$23)) -> 0.36486896 | P36: =IF(P13="","",(P13/$O$23)) | Q36: =IF(Q13="","",(Q13/$O$23)) | R36: =IF(R13="","",(R13/$O$23)) | S36: =IF(S13="","",(S13/$O$23)) | T36: =IF(T13="","",(T13/$O$23)) | U36: =IF(U13="","",(U13/$O$23)) | V36: =IF(V13="","",(V13/$O$23))
