Workbook

Sheet Page de garde
A1: 1. Expérimentateur 1 : copier et coller le n° de prestation et renseigner la date de réalisation de chaque réplica ainsi que le visa de l'expérimentateur.
A2: R1 | B2: Numéro d'expérience : | E2: Date de réalisation :
A3: R2 | B3: Numéro d'expérience : | E3: Date de réalisation :
A4: R3 | B4: Numéro d'expérience : | E4: Date de réalisation :
A5: 2. Expérimentateur 1 : copier et coller la dilution appliquée et le nom donné pour chaque des échantillons par le client. Conserver la mise en forme de l'exemple en italique. Ne pas remplir la colonne "nom sur graphique".
A6: Nom sur le graphique | B6: Code WF | C6: Concentration | D6: Unité | E6: Nom de l'échantillon donné par le client | F6: Dopage (+Testostérone / + EE2, ….)
A7: =IF(ISBLANK(liste_groupe[[#This Row],[Code WF]])," ",IF(ISBLANK(liste_groupe[[#This Row],[Unité]]),CONCATENATE(liste_groupe[[#This Row],[Nom de l''échantillon donné par le client]],liste_groupe[[#This Row],[Dopage (+Testostérone / + EE2, ….)]]),CONCATENATE(liste_groupe[[#This Row],[Nom de l''échantillon donné par le client]],"-",liste_groupe[[#This Row],[Concentration]],liste_groupe[[#This Row],[Unité]],liste_groupe[[#This Row],[Dopage (+Testostérone / + EE2, ….)]]))) -> Témoin solvant | B7: Témoin | E7: Témoin solvant
A8: =IF(ISBLANK(liste_groupe[[#This Row],[Code WF]])," ",IF(ISBLANK(liste_groupe[[#This Row],[Unité]]),CONCATENATE(liste_groupe[[#This Row],[Nom de l''échantillon donné par le client]],liste_groupe[[#This Row],[Dopage (+Testostérone / + EE2, ….)]]),CONCATENATE(liste_groupe[[#This Row],[Nom de l''échantillon donné par le client]],"-",liste_groupe[[#This Row],[Concentration]],liste_groupe[[#This Row],[Unité]],liste_groupe[[#This Row],[Dopage (+Testostérone / + EE2, ….)]]))) -> EE2-22.5ng/L | B8: Témoin | C8: 22.5 | D8: ng/L | E8: EE2
A9: =IF(ISBLANK(liste_groupe[[#This Row],[Code WF]])," ",IF(ISBLANK(liste_groupe[[#This Row],[Unité]]),CONCATENATE(liste_groupe[[#This Row],[Nom de l''échantillon donné par le client]],liste_groupe[[#This Row],[Dopage (+Testostérone / + EE2, ….)]]),CONCATENATE(liste_groupe[[#This Row],[Nom de l''échantillon donné par le client]],"-",liste_groupe[[#This Row],[Concentration]],liste_groupe[[#This Row],[Unité]],liste_groupe[[#This Row],[Dopage (+Testostérone / + EE2, ….)]]))) -> EE2-33.8ng/L | B9: Témoin | C9: 33.8 | D9: ng/L | E9: EE2
A10: =IF(ISBLANK(liste_groupe[[#This Row],[Code WF]])," ",IF(ISBLANK(liste_groupe[[#This Row],[Unité]]),CONCATENATE(liste_groupe[[#This Row],[Nom de l''échantillon donné par le client]],liste_groupe[[#This Row],[Dopage (+Testostérone / + EE2, ….)]]),CONCATENATE(liste_groupe[[#This Row],[Nom de l''échantillon donné par le client]],"-",liste_groupe[[#This Row],[Concentration]],liste_groupe[[#This Row],[Unité]],liste_groupe[[#This Row],[Dopage (+Testostérone / + EE2, ….)]]))) -> EE2-50.6ng/L | B10: Témoin | C10: 50.6 | D10: ng/L | E10: EE2
A11: =IF(ISBLANK(liste_groupe[[#This Row],[Code WF]])," ",IF(ISBLANK(liste_groupe[[#This Row],[Unité]]),CONCATENATE(liste_groupe[[#This Row],[Nom de l''échantillon donné par le client]],liste_groupe[[#This Row],[Dopage (+Testostérone / + EE2, ….)]]),CONCATENATE(liste_groupe[[#This Row],[Nom de l''échantillon donné par le client]],"-",liste_groupe[[#This Row],[Concentration]],liste_groupe[[#This Row],[Unité]],liste_groupe[[#This Row],[Dopage (+Testostérone / + EE2, ….)]]))) -> EE2-76ng/L | B11: Témoin | C11: 76 | D11: ng/L | E11: EE2
A12: =IF(ISBLANK(liste_groupe[[#This Row],[Code WF]])," ",IF(ISBLANK(liste_groupe[[#This Row],[Unité]]),CONCATENATE(liste_groupe[[#This Row],[Nom de l''échantillon donné par le client]],liste_groupe[[#This Row],[Dopage (+Testostérone / + EE2, ….)]]),CONCATENATE(liste_groupe[[#This Row],[Nom de l''échantillon donné par le client]],"-",liste_groupe[[#This Row],[Concentration]],liste_groupe[[#This Row],[Unité]],liste_groupe[[#This Row],[Dopage (+Testostérone / + EE2, ….)]]))) -> EE2-114ng/L | B12: Témoin | C12: 114 | D12: ng/L | E12: EE2
A13: =IF(ISBLANK(liste_groupe[[#This Row],[Code WF]])," ",IF(ISBLANK(liste_groupe[[#This Row],[Unité]]),CONCATENATE(liste_groupe[[#This Row],[Nom de l''échantillon donné par le client]],liste_groupe[[#This Row],[Dopage (+Testostérone / + EE2, ….)]]),CONCATENATE(liste_groupe[[#This Row],[Nom de l''échantillon donné par le client]],"-",liste_groupe[[#This Row],[Concentration]],liste_groupe[[#This Row],[Unité]],liste_groupe[[#This Row],[Dopage (+Testostérone / + EE2, ….)]]))) -> EE2-170.9ng/L | B13: Témoin | C13: 170.9 | D13: ng/L | E13: EE2
A14: =IF(ISBLANK(liste_groupe[[#This Row],[Code WF]])," ",IF(ISBLANK(liste_groupe[[#This Row],[Unité]]),CONCATENATE(liste_groupe[[#This Row],[Nom de l''échantillon donné par le client]],liste_groupe[[#This Row],[Dopage (+Testostérone / + EE2, ….)]]),CONCATENATE(liste_groupe[[#This Row],[Nom de l''échantillon donné par le client]],"-",liste_groupe[[#This Row],[Concentration]],liste_groupe[[#This Row],[Unité]],liste_groupe[[#This Row],[Dopage (+Testostérone / + EE2, ….)]]))) -> EE2-488ng/L | B14: Témoin | C14: 488 | D14: ng/L | E14: EE2
A15: DUS-10µg/L | B15: Chemical | C15: 10 | D15: µg/L | E15: DUS
A16: DUS-100µg/L | B16: Chemical | C16: 100 | D16: µg/L | E16: DUS
A17: DUS-250µg/L | B17: Chemical | C17: 250 | D17: µg/L | E17: DUS
A18: DUS-500µg/L | B18: Chemical | C18: 500 | D18: µg/L | E18: DUS
A19: DUS-1000µg/L | B19: Chemical | C19: 1000 | D19: µg/L | E19: DUS
A20: =IF(ISBLANK(liste_groupe[[#This Row],[Code WF]])," ",IF(ISBLANK(liste_groupe[[#This Row],[Unité]]),CONCATENATE(liste_groupe[[#This Row],[Nom de l''échantillon donné par le client]],liste_groupe[[#This Row],[Dopage (+Testostérone / + EE2, ….)]]),CONCATENATE(liste_groupe[[#This Row],[Nom de l''échantillon donné par le client]],"-",liste_groupe[[#This Row],[Concentration]],liste_groupe[[#This Row],[Unité]],liste_groupe[[#This Row],[Dopage (+Testostérone / + EE2, ….)]])))
A21: =IF(ISBLANK(liste_groupe[[#This Row],[Code WF]])," ",IF(ISBLANK(liste_groupe[[#This Row],[Unité]]),CONCATENATE(liste_groupe[[#This Row],[Nom de l''échantillon donné par le client]],liste_groupe[[#This Row],[Dopage (+Testostérone / + EE2, ….)]]),CONCATENATE(liste_groupe[[#This Row],[Nom de l''échantillon donné par le client]],"-",liste_groupe[[#This Row],[Concentration]],liste_groupe[[#This Row],[Unité]],liste_groupe[[#This Row],[Dopage (+Testostérone / + EE2, ….)]])))
A22: =IF(ISBLANK(liste_groupe[[#This Row],[Code WF]])," ",IF(ISBLANK(liste_groupe[[#This Row],[Unité]]),CONCATENATE(liste_groupe[[#This Row],[Nom de l''échantillon donné par le client]],liste_groupe[[#This Row],[Dopage (+Testostérone / + EE2, ….)]]),CONCATENATE(liste_groupe[[#This Row],[Nom de l''échantillon donné par le client]],"-",liste_groupe[[#This Row],[Concentration]],liste_groupe[[#This Row],[Unité]],liste_groupe[[#This Row],[Dopage (+Testostérone / + EE2, ….)]])))
A23: =IF(ISBLANK(liste_groupe[[#This Row],[Code WF]])," ",IF(ISBLANK(liste_groupe[[#This Row],[Unité]]),CONCATENATE(liste_groupe[[#This Row],[Nom de l''échantillon donné par le client]],liste_groupe[[#This Row],[Dopage (+Testostérone / + EE2, ….)]]),CONCATENATE(liste_groupe[[#This Row],[Nom de l''échantillon donné par le client]],"-",liste_groupe[[#This Row],[Concentration]],liste_groupe[[#This Row],[Unité]],liste_groupe[[#This Row],[Dopage (+Testostérone / + EE2, ….)]])))
A24: =IF(ISBLANK(liste_groupe[[#This Row],[Code WF]])," ",IF(ISBLANK(liste_groupe[[#This Row],[Unité]]),CONCATENATE(liste_groupe[[#This Row],[Nom de l''échantillon donné par le client]],liste_groupe[[#This Row],[Dopage (+Testostérone / + EE2, ….)]]),CONCATENATE(liste_groupe[[#This Row],[Nom de l''échantillon donné par le client]],"-",liste_groupe[[#This Row],[Concentration]],liste_groupe[[#This Row],[Unité]],liste_groupe[[#This Row],[Dopage (+Testostérone / + EE2, ….)]])))
A25: =IF(ISBLANK(liste_groupe[[#This Row],[Code WF]])," ",IF(ISBLANK(liste_groupe[[#This Row],[Unité]]),CONCATENATE(liste_groupe[[#This Row],[Nom de l''échantillon donné par le client]],liste_groupe[[#This Row],[Dopage (+Testostérone / + EE2, ….)]]),CONCATENATE(liste_groupe[[#This Row],[Nom de l''échantillon donné par le client]],"-",liste_groupe[[#This Row],[Concentration]],liste_groupe[[#This Row],[Unité]],liste_groupe[[#This Row],[Dopage (+Testostérone / + EE2, ….)]])))
A26: =IF(ISBLANK(liste_groupe[[#This Row],[Code WF]])," ",IF(ISBLANK(liste_groupe[[#This Row],[Unité]]),CONCATENATE(liste_groupe[[#This Row],[Nom de l''échantillon donné par le client]],liste_groupe[[#This Row],[Dopage (+Testostérone / + EE2, ….)]]),CONCATENATE(liste_groupe[[#This Row],[Nom de l''échantillon donné par le client]],"-",liste_groupe[[#This Row],[Concentration]],liste_groupe[[#This Row],[Unité]],liste_groupe[[#This Row],[Dopage (+Testostérone / + EE2, ….)]])))
A27: =IF(ISBLANK(liste_groupe[[#This Row],[Code WF]])," ",IF(ISBLANK(liste_groupe[[#This Row],[Unité]]),CONCATENATE(liste_groupe[[#This Row],[Nom de l''échantillon donné par le client]],liste_groupe[[#This Row],[Dopage (+Testostérone / + EE2, ….)]]),CONCATENATE(liste_groupe[[#This Row],[Nom de l''échantillon donné par le client]],"-",liste_groupe[[#This Row],[Concentration]],liste_groupe[[#This Row],[Unité]],liste_groupe[[#This Row],[Dopage (+Testostérone / + EE2, ….)]])))
A28: =IF(ISBLANK(liste_groupe[[#This Row],[Code WF]])," ",IF(ISBLANK(liste_groupe[[#This Row],[Unité]]),CONCATENATE(liste_groupe[[#This Row],[Nom de l''échantillon donné par le client]],liste_groupe[[#This Row],[Dopage (+Testostérone / + EE2, ….)]]),CONCATENATE(liste_groupe[[#This Row],[Nom de l''échantillon donné par le client]],"-",liste_groupe[[#This Row],[Concentration]],liste_groupe[[#This Row],[Unité]],liste_groupe[[#This Row],[Dopage (+Testostérone / + EE2, ….)]])))
A29: =IF(ISBLANK(liste_groupe[[#This Row],[Code WF]])," ",IF(ISBLANK(liste_groupe[[#This Row],[Unité]]),CONCATENATE(liste_groupe[[#This Row],[Nom de l''échantillon donné par le client]],liste_groupe[[#This Row],[Dopage (+Testostérone / + EE2, ….)]]),CONCATENATE(liste_groupe[[#This Row],[Nom de l''échantillon donné par le client]],"-",liste_groupe[[#This Row],[Concentration]],liste_groupe[[#This Row],[Unité]],liste_groupe[[#This Row],[Dopage (+Testostérone / + EE2, ….)]])))
A30: =IF(ISBLANK(liste_groupe[[#This Row],[Code WF]])," ",IF(ISBLANK(liste_groupe[[#This Row],[Unité]]),CONCATENATE(liste_groupe[[#This Row],[Nom de l''échantillon donné par le client]],liste_groupe[[#This Row],[Dopage (+Testostérone / + EE2, ….)]]),CONCATENATE(liste_groupe[[#This Row],[Nom de l''échantillon donné par le client]],"-",liste_groupe[[#This Row],[Concentration]],liste_groupe[[#This Row],[Unité]],liste_groupe[[#This Row],[Dopage (+Testostérone / + EE2, ….)]])))
A31: =IF(ISBLANK(liste_groupe[[#This Row],[Code WF]])," ",IF(ISBLANK(liste_groupe[[#This Row],[Unité]]),CONCATENATE(liste_groupe[[#This Row],[Nom de l''échantillon donné par le client]],liste_groupe[[#This Row],[Dopage (+Testostérone / + EE2, ….)]]),CONCATENATE(liste_groupe[[#This Row],[Nom de l''échantillon donné par le client]],"-",liste_groupe[[#This Row],[Concentration]],liste_groupe[[#This Row],[Unité]],liste_groupe[[#This Row],[Dopage (+Testostérone / + EE2, ….)]])))
... A35: =IF(ISBLANK(liste_groupe[[#This Row],[Code WF]])," ",IF(ISBLANK(liste_groupe[[#This Row],[Unité]]),CONCATENATE(liste_groupe[[#This Row],[Nom de l''échantillon donné par le client]],liste_groupe[[#This Row],[Dopage (+Testostérone / + EE2, ….)]]),CONCATENATE(liste_groupe[[#This Row],[Nom de l''échantillon donné par le client]],"-",liste_groupe[[#This Row],[Concentration]],liste_groupe[[#This Row],[Unité]],liste_groupe[[#This Row],[Dopage (+Testostérone / + EE2, ….)]])))
A36: =IF(ISBLANK(liste_groupe[[#This Row],[Code WF]])," ",IF(ISBLANK(liste_groupe[[#This Row],[Unité]]),CONCATENATE(liste_groupe[[#This Row],[Nom de l''échantillon donné par le client]],liste_groupe[[#This Row],[Dopage (+Testostérone / + EE2, ….)]]),CONCATENATE(liste_groupe[[#This Row],[Nom de l''échantillon donné par le client]],"-",liste_groupe[[#This Row],[Concentration]],liste_groupe[[#This Row],[Unité]],liste_groupe[[#This Row],[Dopage (+Testostérone / + EE2, ….)]]))) -> Testo -30µg/L | B36: Témoin | C36: 30 | D36: µg/L | E36: Testo
A37: =IF(ISBLANK(liste_groupe[[#This Row],[Code WF]])," ",IF(ISBLANK(liste_groupe[[#This Row],[Unité]]),CONCATENATE(liste_groupe[[#This Row],[Nom de l''échantillon donné par le client]],liste_groupe[[#This Row],[Dopage (+Testostérone / + EE2, ….)]]),CONCATENATE(liste_groupe[[#This Row],[Nom de l''échantillon donné par le client]],"-",liste_groupe[[#This Row],[Concentration]],liste_groupe[[#This Row],[Unité]],liste_groupe[[#This Row],[Dopage (+Testostérone / + EE2, ….)]]))) -> Testo 30µg/L + EE2 -64ng/L | B37: Témoin | C37: 64 | D37: ng/L | E37: Testo 30µg/L + EE2
A38: =IF(ISBLANK(liste_groupe[[#This Row],[Code WF]])," ",IF(ISBLANK(liste_groupe[[#This Row],[Unité]]),CONCATENATE(liste_groupe[[#This Row],[Nom de l''échantillon donné par le client]],liste_groupe[[#This Row],[Dopage (+Testostérone / + EE2, ….)]]),CONCATENATE(liste_groupe[[#This Row],[Nom de l''échantillon donné par le client]],"-",liste_groupe[[#This Row],[Concentration]],liste_groupe[[#This Row],[Unité]],liste_groupe[[#This Row],[Dopage (+Testostérone / + EE2, ….)]]))) -> Testo 30µg/L + FAD-10mg/L | B38: Témoin | C38: 10 | D38: mg/L | E38: Testo 30µg/L + FAD
A39: =IF(ISBLANK(liste_groupe[[#This Row],[Code WF]])," ",IF(ISBLANK(liste_groupe[[#This Row],[Unité]]),CONCATENATE(liste_groupe[[#This Row],[Nom de l''échantillon donné par le client]],liste_groupe[[#This Row],[Dopage (+Testostérone / + EE2, ….)]]),CONCATENATE(liste_groupe[[#This Row],[Nom de l''échantillon donné par le client]],"-",liste_groupe[[#This Row],[Concentration]],liste_groupe[[#This Row],[Unité]],liste_groupe[[#This Row],[Dopage (+Testostérone / + EE2, ….)]]))) -> DUS-10µg/L + Testostérone | B39: =B15 -> Chemical | C39: =C15 -> 10 | D39: =D15 -> µg/L | E39: =E15 -> DUS | F39: + Testostérone
A40: =IF(ISBLANK(liste_groupe[[#This Row],[Code WF]])," ",IF(ISBLANK(liste_groupe[[#This Row],[Unité]]),CONCATENATE(liste_groupe[[#This Row],[Nom de l''échantillon donné par le client]],liste_groupe[[#This Row],[Dopage (+Testostérone / + EE2, ….)]]),CONCATENATE(liste_groupe[[#This Row],[Nom de l''échantillon donné par le client]],"-",liste_groupe[[#This Row],[Concentration]],liste_groupe[[#This Row],[Unité]],liste_groupe[[#This Row],[Dopage (+Testostérone / + EE2, ….)]]))) -> DUS-100µg/L + Testostérone | B40: =B16 -> Chemical | C40: =C16 -> 100 | D40: =D16 -> µg/L | E40: =E16 -> DUS | F40: + Testostérone
A41: =IF(ISBLANK(liste_groupe[[#This Row],[Code WF]])," ",IF(ISBLANK(liste_groupe[[#This Row],[Unité]]),CONCATENATE(liste_groupe[[#This Row],[Nom de l''échantillon donné par le client]],liste_groupe[[#This Row],[Dopage (+Testostérone / + EE2, ….)]]),CONCATENATE(liste_groupe[[#This Row],[Nom de l''échantillon donné par le client]],"-",liste_groupe[[#This Row],[Concentration]],liste_groupe[[#This Row],[Unité]],liste_groupe[[#This Row],[Dopage (+Testostérone / + EE2, ….)]]))) -> DUS-250µg/L + Testostérone | B41: =B17 -> Chemical | C41: =C17 -> 250 | D41: =D17 -> µg/L | E41: =E17 -> DUS | F41: + Testostérone
A42: =IF(ISBLANK(liste_groupe[[#This Row],[Code WF]])," ",IF(ISBLANK(liste_groupe[[#This Row],[Unité]]),CONCATENATE(liste_groupe[[#This Row],[Nom de l''échantillon donné par le client]],liste_groupe[[#This Row],[Dopage (+Testostérone / + EE2, ….)]]),CONCATENATE(liste_groupe[[#This Row],[Nom de l''échantillon donné par le client]],"-",liste_groupe[[#This Row],[Concentration]],liste_groupe[[#This Row],[Unité]],liste_groupe[[#This Row],[Dopage (+Testostérone / + EE2, ….)]]))) -> DUS-500µg/L + Testostérone | B42: =B18 -> Chemical | C42: =C18 -> 500 | D42: =D18 -> µg/L | E42: =E18 -> DUS | F42: + Testostérone
A43: =IF(ISBLANK(liste_groupe[[#This Row],[Code WF]])," ",IF(ISBLANK(liste_groupe[[#This Row],[Unité]]),CONCATENATE(liste_groupe[[#This Row],[Nom de l''échantillon donné par le client]],liste_groupe[[#This Row],[Dopage (+Testostérone / + EE2, ….)]]),CONCATENATE(liste_groupe[[#This Row],[Nom de l''échantillon donné par le client]],"-",liste_groupe[[#This Row],[Concentration]],liste_groupe[[#This Row],[Unité]],liste_groupe[[#This Row],[Dopage (+Testostérone / + EE2, ….)]]))) -> DUS-1000µg/L + Testostérone | B43: =B19 -> Chemical | C43: =C19 -> 1000 | D43: =D19 -> µg/L | E43: =E19 -> DUS | F43: + Testostérone
...

Sheet Feuil1
A1: Nom groupe | B1: N° de valeur | C1: file name | D1: total area | E1: mean intensity | G1: total fluorescence | I1: nbre de larves
A2: 01 EE2 0 | B2: A | C2: C:\Users\Olympus\Desktop\20190122\plaque1/@01 EE2 0/A1_1.tif | D2: 4931.616 | E2: 73.0526 | G2: 360268
A3: 01 EE2 0 | B3: A | C3: C:\Users\Olympus\Desktop\20190122\plaque1/@01 EE2 0/A1_2.tif | D3: 5234.4345 | E3: 71.1281 | G3: 372315
A4: 01 EE2 0 | B4: A | C4: C:\Users\Olympus\Desktop\20190122\plaque1/@01 EE2 0/A1_3.tif | D4: 3547.3027 | E4: 66.9878 | G4: 237626
A5: 01 EE2 0 | B5: A | C5: C:\Users\Olympus\Desktop\20190122\plaque3/@01 EE2 0/A1_3.tif | D5: 21456.8555 | E5: 67.0655 | G5: 1439015
A6: 01 EE2 0 | B6: A | C6: C:\Users\Olympus\Desktop\20190122\plaque3/@01 EE2 0/A1_2.tif | D6: 21586.6348 | E6: 66.4108 | G6: 1433586
A7: 01 EE2 0 | B7: A | C7: C:\Users\Olympus\Desktop\20190122\plaque3/@01 EE2 0/A1_1.tif | D7: 15984.4921 | E7: 69.7767 | G7: 1115346

Sheet Feuil2
A1: Nom groupe | B1: N° de valeur | C1: file name | D1: total area | E1: mean intensity | G1: total fluorescence | I1: nbre de larves | J1: Colonne1
A2: 13 | B2: A | C2: C:\Users\andre\Desktop\REACTIV CEFAS\Dutasteride\Dutasteride/20201201_Cefas_Test8_Run1/Plate 1/@13/A8_03.tif | D2: 21911.0833 | E2: 35.157 | G2: 770327
A3: 13 | B3: A | C3: C:\Users\andre\Desktop\REACTIV CEFAS\Dutasteride\Dutasteride/20201201_Cefas_Test8_Run1/Plate 1/@13/A8_02.tif | D3: 15140.9262 | E3: 35.39 | G3: 535837
A4: 13 | B4: A | C4: C:\Users\andre\Desktop\REACTIV CEFAS\Dutasteride\Dutasteride/20201201_Cefas_Test8_Run1/Plate 1/@13/A8_01.tif | D4: 24312.0016 | E4: 35.6423 | G4: 866537

Sheet Raw data R1
A1: Nom groupe | B1: N° de valeur | C1: file name | D1: total area | E1: mean intensity | G1: total fluorescence | I1: nbre de larves | J1: Colonne1 | L1: (Tous)
A2: =IFERROR(LEFT(RIGHT(C2,LEN(C2)-SEARCH("@",C2)),SEARCH("/",RIGHT(C2,LEN(C2)-SEARCH("@",C2)-1))),"") -> 1 | B2: =LEFT(RIGHT(RIGHT(Tableau4[[#This Row],[file name]],LEN(Tableau4[[#This Row],[file name]])-SEARCH("@",Tableau4[[#This Row],[file name]])),LEN(RIGHT(Tableau4[[#This Row],[file name]],LEN(Tableau4[[#This Row],[file name]])-SEARCH("@",Tableau4[[#This Row],[file name]])))-SEARCH("/",RIGHT(Tableau4[[#This Row],[file name]],LEN(Tableau4[[#This Row],[file name]])-SEARCH("@",Tableau4[[#This Row],[file name]])))),1) -> A | C2: C:\Users\andre\Desktop\REACTIV CEFAS\Dutasteride\Dutasteride/20201201_Cefas_Test8_Run1/Plate 1/@1/A10_01- exclu.tif | K2: Filtre lignes : Enlever (vide) et Néant | L2: Filtre colonnes : Enlever (vide) et " "
A3: =IFERROR(LEFT(RIGHT(C3,LEN(C3)-SEARCH("@",C3)),SEARCH("/",RIGHT(C3,LEN(C3)-SEARCH("@",C3)-1))),"") -> 1 | B3: =LEFT(RIGHT(RIGHT(Tableau4[[#This Row],[file name]],LEN(Tableau4[[#This Row],[file name]])-SEARCH("@",Tableau4[[#This Row],[file name]])),LEN(RIGHT(Tableau4[[#This Row],[file name]],LEN(Tableau4[[#This Row],[file name]])-SEARCH("@",Tableau4[[#This Row],[file name]])))-SEARCH("/",RIGHT(Tableau4[[#This Row],[file name]],LEN(Tableau4[[#This Row],[file name]])-SEARCH("@",Tableau4[[#This Row],[file name]])))),1) -> A | C3: C:\Users\andre\Desktop\REACTIV CEFAS\Dutasteride\Dutasteride/20201201_Cefas_Test8_Run1/Plate 1/@1/A10_02- exclu.tif | K3: Moyenne de total fluorescence | L3: Étiquettes de colonnes
A4: =IFERROR(LEFT(RIGHT(C4,LEN(C4)-SEARCH("@",C4)),SEARCH("/",RIGHT(C4,LEN(C4)-SEARCH("@",C4)-1))),"") -> 1 | B4: =LEFT(RIGHT(RIGHT(Tableau4[[#This Row],[file name]],LEN(Tableau4[[#This Row],[file name]])-SEARCH("@",Tableau4[[#This Row],[file name]])),LEN(RIGHT(Tableau4[[#This Row],[file name]],LEN(Tableau4[[#This Row],[file name]])-SEARCH("@",Tableau4[[#This Row],[file name]])))-SEARCH("/",RIGHT(Tableau4[[#This Row],[file name]],LEN(Tableau4[[#This Row],[file name]])-SEARCH("@",Tableau4[[#This Row],[file name]])))),1) -> A | C4: C:\Users\andre\Desktop\REACTIV CEFAS\Dutasteride\Dutasteride/20201201_Cefas_Test8_Run1/Plate 1/@1/A10_03- exclu.tif | K4: Étiquettes de lignes | L4: 1 | M4: 13 | N4: 14 | O4: 15 | P4: 16 | Q4: 2 | R4: 3 | S4: 4 | T4: 5 | U4: 6 | V4: 7 | W4: 10 | X4: 11 | Y4: 12 | Z4: 17 | AA4: 18 | AB4: 19 | AC4: 20 | AD4: 21 | AE4: 8 | AF4: 9
A5: =IFERROR(LEFT(RIGHT(C5,LEN(C5)-SEARCH("@",C5)),SEARCH("/",RIGHT(C5,LEN(C5)-SEARCH("@",C5)-1))),"") -> 1 | B5: =LEFT(RIGHT(RIGHT(Tableau4[[#This Row],[file name]],LEN(Tableau4[[#This Row],[file name]])-SEARCH("@",Tableau4[[#This Row],[file name]])),LEN(RIGHT(Tableau4[[#This Row],[file name]],LEN(Tableau4[[#This Row],[file name]])-SEARCH("@",Tableau4[[#This Row],[file name]])))-SEARCH("/",RIGHT(Tableau4[[#This Row],[file name]],LEN(Tableau4[[#This Row],[file name]])-SEARCH("@",Tableau4[[#This Row],[file name]])))),1) -> B | C5: C:\Users\andre\Desktop\REACTIV CEFAS\Dutasteride\Dutasteride/20201201_Cefas_Test8_Run1/Plate 1/@1/B10_01- exclu.tif | K5: A | M5: 724233.67 | N5: 2719721.3 | O5: 3923338.3 | P5: 59684.333 | Q5: 94573.333 | R5: 187142 | S5: 280237 | T5: 853451 | U5: 2129117 | V5: 4171570.3 | W5: 295723.67 | X5: 69345.333 | Y5: 185310.33 | Z5: 1418171.3 | AA5: 771704.33 | AB5: 2543344 | AC5: 2526313.7 | AD5: 2702194 | AE5: 319257.5 | AF5: 300439.33
A6: =IFERROR(LEFT(RIGHT(C6,LEN(C6)-SEARCH("@",C6)),SEARCH("/",RIGHT(C6,LEN(C6)-SEARCH("@",C6)-1))),"") -> 1 | B6: =LEFT(RIGHT(RIGHT(Tableau4[[#This Row],[file name]],LEN(Tableau4[[#This Row],[file name]])-SEARCH("@",Tableau4[[#This Row],[file name]])),LEN(RIGHT(Tableau4[[#This Row],[file name]],LEN(Tableau4[[#This Row],[file name]])-SEARCH("@",Tableau4[[#This Row],[file name]])))-SEARCH("/",RIGHT(Tableau4[[#This Row],[file name]],LEN(Tableau4[[#This Row],[file name]])-SEARCH("@",Tableau4[[#This Row],[file name]])))),1) -> B | C6: C:\Users\andre\Desktop\REACTIV CEFAS\Dutasteride\Dutasteride/20201201_Cefas_Test8_Run1/Plate 1/@1/B10_02- exclu.tif | K6: B | L6: 274743 | M6: 1986799.7 | N6: 2314600.3 | O6: 3912985 | P6: 94493.667 | Q6: 218368.33 | R6: 1344831.7 | S6: 411458 | T6: 2262696 | U6: 2429058.3 | V6: 3502579.3 | W6: 122829.33 | X6: 228282 | Y6: 175692.67 | Z6: 634650 | AA6: 3489089.3 | AB6: 1960468.7 | AC6: 2321407 | AD6: 5145521.3 | AE6: 310706.33 | AF6: 47838
A7: =IFERROR(LEFT(RIGHT(C7,LEN(C7)-SEARCH("@",C7)),SEARCH("/",RIGHT(C7,LEN(C7)-SEARCH("@",C7)-1))),"") -> 1 | B7: =LEFT(RIGHT(RIGHT(Tableau4[[#This Row],[file name]],LEN(Tableau4[[#This Row],[file name]])-SEARCH("@",Tableau4[[#This Row],[file name]])),LEN(RIGHT(Tableau4[[#This Row],[file name]],LEN(Tableau4[[#This Row],[file name]])-SEARCH("@",Tableau4[[#This Row],[file name]])))-SEARCH("/",RIGHT(Tableau4[[#This Row],[file name]],LEN(Tableau4[[#This Row],[file name]])-SEARCH("@",Tableau4[[#This Row],[file name]])))),1) -> B | C7: C:\Users\andre\Desktop\REACTIV CEFAS\Dutasteride\Dutasteride/20201201_Cefas_Test8_Run1/Plate 1/@1/B10_03.tif | D7: 7267.6446 | E7: 37.8036 | G7: 274743 | K7: C | L7: 249731.67 | M7: 3366073 | N7: 2557252 | O7: 4483711.3 | P7: 59223 | Q7: 138229.67 | R7: 78826.667 | S7: 1014521.7 | T7: 999503.33 | U7: 3440083 | V7: 3891142.5 | W7: 487184.67 | X7: 4340.3333 | Y7: 0 | Z7: 2875435 | AA7: 57672.333 | AB7: 3560280.7 | AC7: 3770818.7 | AD7: 2972200 | AE7: 181770.33 | AF7: 216998.33
A8: =IFERROR(LEFT(RIGHT(C8,LEN(C8)-SEARCH("@",C8)),SEARCH("/",RIGHT(C8,LEN(C8)-SEARCH("@",C8)-1))),"") -> 1 | B8: =LEFT(RIGHT(RIGHT(Tableau4[[#This Row],[file name]],LEN(Tableau4[[#This Row],[file name]])-SEARCH("@",Tableau4[[#This Row],[file name]])),LEN(RIGHT(Tableau4[[#This Row],[file name]],LEN(Tableau4[[#This Row],[file name]])-SEARCH("@",Tableau4[[#This Row],[file name]])))-SEARCH("/",RIGHT(Tableau4[[#This Row],[file name]],LEN(Tableau4[[#This Row],[file name]])-SEARCH("@",Tableau4[[#This Row],[file name]])))),1) -> C | C8: C:\Users\andre\Desktop\REACTIV CEFAS\Dutasteride\Dutasteride/20201201_Cefas_Test8_Run1/Plate 1/@1/C10_01.tif | D8: 6986.456 | E8: 39.4241 | G8: 275435 | K8: D | L8: 145771 | M8: 1698523.7 | N8: 2630339.3 | O8: 2204854 | P8: 178872 | Q8: 171705.33 | R8: 191792.33 | S8: 696836 | T8: 3496688.7 | U8: 3562422 | V8: 3758107.7 | W8: 174877.33 | X8: 213112 | Y8: 237993.67 | Z8: 375639 | AA8: 3671826 | AB8: 2135130.3 | AC8: 116679 | AD8: 1710759 | AE8: 148193.67 | AF8: 248297
A9: =IFERROR(LEFT(RIGHT(C9,LEN(C9)-SEARCH("@",C9)),SEARCH("/",RIGHT(C9,LEN(C9)-SEARCH("@",C9)-1))),"") -> 1 | B9: =LEFT(RIGHT(RIGHT(Tableau4[[#This Row],[file name]],LEN(Tableau4[[#This Row],[file name]])-SEARCH("@",Tableau4[[#This Row],[file name]])),LEN(RIGHT(Tableau4[[#This Row],[file name]],LEN(Tableau4[[#This Row],[file name]])-SEARCH("@",Tableau4[[#This Row],[file name]])))-SEARCH("/",RIGHT(Tableau4[[#This Row],[file name]],LEN(Tableau4[[#This Row],[file name]])-SEARCH("@",Tableau4[[#This Row],[file name]])))),1) -> C | C9: C:\Users\andre\Desktop\REACTIV CEFAS\Dutasteride\Dutasteride/20201201_Cefas_Test8_Run1/Plate 1/@1/C10_02.tif | D9: 6186.1499 | E9: 39.8147 | G9: 246300 | K9: E | L9: 23857.667 | M9: 192722.33 | N9: 2193357.5 | O9: 4702836.7 | P9: 152707 | Q9: 260272.67 | R9: 56980.333 | S9: 799556.67 | T9: 1513725 | U9: 2736780 | V9: 4961775 | W9: 206082.33 | X9: 192390.67 | Y9: 398524 | Z9: 2025200 | AA9: 3040341.3 | AB9: 2964456.3 | AC9: 1720110.3 | AD9: 1520415.7 | AE9: 110225.67 | AF9: 86570
A10: =IFERROR(LEFT(RIGHT(C10,LEN(C10)-SEARCH("@",C10)),SEARCH("/",RIGHT(C10,LEN(C10)-SEARCH("@",C10)-1))),"") -> 1 | B10: =LEFT(RIGHT(RIGHT(Tableau4[[#This Row],[file name]],LEN(Tableau4[[#This Row],[file name]])-SEARCH("@",Tableau4[[#This Row],[file name]])),LEN(RIGHT(Tableau4[[#This Row],[file name]],LEN(Tableau4[[#This Row],[file name]])-SEARCH("@",Tableau4[[#This Row],[file name]])))-SEARCH("/",RIGHT(Tableau4[[#This Row],[file name]],LEN(Tableau4[[#This Row],[file name]])-SEARCH("@",Tableau4[[#This Row],[file name]])))),1) -> C | C10: C:\Users\andre\Desktop\REACTIV CEFAS\Dutasteride\Dutasteride/20201201_Cefas_Test8_Run1/Plate 1/@1/C10_03.tif | D10: 5991.4808 | E10: 37.9639 | G10: 227460 | K10: F | L10: 61155 | M10: 1376382.3 | N10: 1415006 | O10: 3265714 | P10: 266372.33 | Q10: 215109.33 | S10: 163067.67 | T10: 2032301.7 | U10: 4106169 | V10: 4917830.7 | W10: 185836.67 | X10: 75048.667 | Y10: 155317 | Z10: 1039915 | AA10: 2102757.7 | AB10: 2015264.3 | AC10: 56958.667 | AD10: 3058344.7 | AE10: 24420 | AF10: 8385
A11: =IFERROR(LEFT(RIGHT(C11,LEN(C11)-SEARCH("@",C11)),SEARCH("/",RIGHT(C11,LEN(C11)-SEARCH("@",C11)-1))),"") -> 1 | B11: =LEFT(RIGHT(RIGHT(Tableau4[[#This Row],[file name]],LEN(Tableau4[[#This Row],[file name]])-SEARCH("@",Tableau4[[#This Row],[file name]])),LEN(RIGHT(Tableau4[[#This Row],[file name]],LEN(Tableau4[[#This Row],[file name]])-SEARCH("@",Tableau4[[#This Row],[file name]])))-SEARCH("/",RIGHT(Tableau4[[#This Row],[file name]],LEN(Tableau4[[#This Row],[file name]])-SEARCH("@",Tableau4[[#This Row],[file name]])))),1) -> D | C11: C:\Users\andre\Desktop\REACTIV CEFAS\Dutasteride\Dutasteride/20201201_Cefas_Test8_Run1/Plate 1/@1/D10_01.tif | D11: 3655.4522 | E11: 34.5503 | G11: 126297 | K11: G | L11: 440 | M11: 1717795.7 | N11: 311802.33 | O11: 4801562.7 | P11: 70946 | Q11: 85568.333 | R11: 144509 | S11: 994283.33 | T11: 2373686.3 | U11: 3742541.7 | V11: 4126154.7 | W11: 441156 | X11: 220935 | Y11: 223.66667 | Z11: 872564.33 | AB11: 1812931 | AD11: 2030044.7 | AE11: 310439.33 | AF11: 230027
A12: =IFERROR(LEFT(RIGHT(C12,LEN(C12)-SEARCH("@",C12)),SEARCH("/",RIGHT(C12,LEN(C12)-SEARCH("@",C12)-1))),"") -> 1 | B12: =LEFT(RIGHT(RIGHT(Tableau4[[#This Row],[file name]],LEN(Tableau4[[#This Row],[file name]])-SEARCH("@",Tableau4[[#This Row],[file name]])),LEN(RIGHT(Tableau4[[#This Row],[file name]],LEN(Tableau4[[#This Row],[file name]])-SEARCH("@",Tableau4[[#This Row],[file name]])))-SEARCH("/",RIGHT(Tableau4[[#This Row],[file name]],LEN(Tableau4[[#This Row],[file name]])-SEARCH("@",Tableau4[[#This Row],[file name]])))),1) -> D | C12: C:\Users\andre\Desktop\REACTIV CEFAS\Dutasteride\Dutasteride/20201201_Cefas_Test8_Run1/Plate 1/@1/D10_02.tif | D12: 7592.093 | E12: 32.9202 | G12: 249933 | K12: H | L12: 189593.33 | N12: 1213422.7 | O12: 2435663.3 | P12: 137674.67 | Q12: 202506 | R12: 61155 | S12: 74785.5 | T12: 2684284.7 | V12: 2066065.7 | W12: 97190.333 | X12: 195166.67 | Y12: 264656.33 | Z12: 1787422.3 | AA12: 2478216.7 | AB12: 3257743.3 | AC12: 225167.33 | AD12: 1462498 | AE12: 242240.33 | AF12: 342141.67
A13: =IFERROR(LEFT(RIGHT(C13,LEN(C13)-SEARCH("@",C13)),SEARCH("/",RIGHT(C13,LEN(C13)-SEARCH("@",C13)-1))),"") -> 1 | B13: =LEFT(RIGHT(RIGHT(Tableau4[[#This Row],[file name]],LEN(Tableau4[[#This Row],[file name]])-SEARCH("@",Tableau4[[#This Row],[file name]])),LEN(RIGHT(Tableau4[[#This Row],[file name]],LEN(Tableau4[[#This Row],[file name]])-SEARCH("@",Tableau4[[#This Row],[file name]])))-SEARCH("/",RIGHT(Tableau4[[#This Row],[file name]],LEN(Tableau4[[#This Row],[file name]])-SEARCH("@",Tableau4[[#This Row],[file name]])))),1) -> D | C13: C:\Users\andre\Desktop\REACTIV CEFAS\Dutasteride\Dutasteride/20201201_Cefas_Test8_Run1/Plate 1/@1/D10_03.tif | D13: 1838.541 | E13: 33.2235 | G13: 61083
A14: =IFERROR(LEFT(RIGHT(C14,LEN(C14)-SEARCH("@",C14)),SEARCH("/",RIGHT(C14,LEN(C14)-SEARCH("@",C14)-1))),"") -> 1 | B14: =LEFT(RIGHT(RIGHT(Tableau4[[#This Row],[file name]],LEN(Tableau4[[#This Row],[file name]])-SEARCH("@",Tableau4[[#This Row],[file name]])),LEN(RIGHT(Tableau4[[#This Row],[file name]],LEN(Tableau4[[#This Row],[file name]])-SEARCH("@",Tableau4[[#This Row],[file name]])))-SEARCH("/",RIGHT(Tableau4[[#This Row],[file name]],LEN(Tableau4[[#This Row],[file name]])-SEARCH("@",Tableau4[[#This Row],[file name]])))),1) -> E | C14: C:\Users\andre\Desktop\REACTIV CEFAS\Dutasteride\Dutasteride/20201201_Cefas_Test8_Run1/Plate 1/@1/E10_01.tif | D14: 1752.0215 | E14: 37.358 | G14: 65452
A15: =IFERROR(LEFT(RIGHT(C15,LEN(C15)-SEARCH("@",C15)),SEARCH("/",RIGHT(C15,LEN(C15)-SEARCH("@",C15)-1))),"") -> 1 | B15: =LEFT(RIGHT(RIGHT(Tableau4[[#This Row],[file name]],LEN(Tableau4[[#This Row],[file name]])-SEARCH("@",Tableau4[[#This Row],[file name]])),LEN(RIGHT(Tableau4[[#This Row],[file name]],LEN(Tableau4[[#This Row],[file name]])-SEARCH("@",Tableau4[[#This Row],[file name]])))-SEARCH("/",RIGHT(Tableau4[[#This Row],[file name]],LEN(Tableau4[[#This Row],[file name]])-SEARCH("@",Tableau4[[#This Row],[file name]])))),1) -> E | C15: C:\Users\andre\Desktop\REACTIV CEFAS\Dutasteride\Dutasteride/20201201_Cefas_Test8_Run1/Plate 1/@1/E10_02.tif | D15: 194.6691 | E15: 31.4444 | G15: 6121
A16: =IFERROR(LEFT(RIGHT(C16,LEN(C16)-SEARCH("@",C16)),SEARCH("/",RIGHT(C16,LEN(C16)-SEARCH("@",C16)-1))),"") -> 1 | B16: =LEFT(RIGHT(RIGHT(Tableau4[[#This Row],[file name]],LEN(Tableau4[[#This Row],[file name]])-SEARCH("@",Tableau4[[#This Row],[file name]])),LEN(RIGHT(Tableau4[[#This Row],[file name]],LEN(Tableau4[[#This Row],[file name]])-SEARCH("@",Tableau4[[#This Row],[file name]])))-SEARCH("/",RIGHT(Tableau4[[#This Row],[file name]],LEN(Tableau4[[#This Row],[file name]])-SEARCH("@",Tableau4[[#This Row],[file name]])))),1) -> E | C16: C:\Users\andre\Desktop\REACTIV CEFAS\Dutasteride\Dutasteride/20201201_Cefas_Test8_Run1/Plate 1/@1/E10_03.tif | D16: 0 | E16: 0 | G16: 0
A17: =IFERROR(LEFT(RIGHT(C17,LEN(C17)-SEARCH("@",C17)),SEARCH("/",RIGHT(C17,LEN(C17)-SEARCH("@",C17)-1))),"") -> 1 | B17: =LEFT(RIGHT(RIGHT(Tableau4[[#This Row],[file name]],LEN(Tableau4[[#This Row],[file name]])-SEARCH("@",Tableau4[[#This Row],[file name]])),LEN(RIGHT(Tableau4[[#This Row],[file name]],LEN(Tableau4[[#This Row],[file name]])-SEARCH("@",Tableau4[[#This Row],[file name]])))-SEARCH("/",RIGHT(Tableau4[[#This Row],[file name]],LEN(Tableau4[[#This Row],[file name]])-SEARCH("@",Tableau4[[#This Row],[file name]])))),1) -> F | C17: C:\Users\andre\Desktop\REACTIV CEFAS\Dutasteride\Dutasteride/20201201_Cefas_Test8_Run1/Plate 1/@1/F10_01.tif | D17: 4412.4985 | E17: 35.7255 | G17: 157639
A18: =IFERROR(LEFT(RIGHT(C18,LEN(C18)-SEARCH("@",C18)),SEARCH("/",RIGHT(C18,LEN(C18)-SEARCH("@",C18)-1))),"") -> 1 | B18: =LEFT(RIGHT(RIGHT(Tableau4[[#This Row],[file name]],LEN(Tableau4[[#This Row],[file name]])-SEARCH("@",Tableau4[[#This Row],[file name]])),LEN(RIGHT(Tableau4[[#This Row],[file name]],LEN(Tableau4[[#This Row],[file name]])-SEARCH("@",Tableau4[[#This Row],[file name]])))-SEARCH("/",RIGHT(Tableau4[[#This Row],[file name]],LEN(Tableau4[[#This Row],[file name]])-SEARCH("@",Tableau4[[#This Row],[file name]])))),1) -> F | C18: C:\Users\andre\Desktop\REACTIV CEFAS\Dutasteride\Dutasteride/20201201_Cefas_Test8_Run1/Plate 1/@1/F10_02.tif | D18: 800.3061 | E18: 32.2703 | G18: 25826
A19: =IFERROR(LEFT(RIGHT(C19,LEN(C19)-SEARCH("@",C19)),SEARCH("/",RIGHT(C19,LEN(C19)-SEARCH("@",C19)-1))),"") -> 1 | B19: =LEFT(RIGHT(RIGHT(Tableau4[[#This Row],[file name]],LEN(Tableau4[[#This Row],[file name]])-SEARCH("@",Tableau4[[#This Row],[file name]])),LEN(RIGHT(Tableau4[[#This Row],[file name]],LEN(Tableau4[[#This Row],[file name]])-SEARCH("@",Tableau4[[#This Row],[file name]])))-SEARCH("/",RIGHT(Tableau4[[#This Row],[file name]],LEN(Tableau4[[#This Row],[file name]])-SEARCH("@",Tableau4[[#This Row],[file name]])))),1) -> F | C19: C:\Users\andre\Desktop\REACTIV CEFAS\Dutasteride\Dutasteride/20201201_Cefas_Test8_Run1/Plate 1/@1/F10_03.tif | D19: 0 | E19: 0 | G19: 0
A20: =IFERROR(LEFT(RIGHT(C20,LEN(C20)-SEARCH("@",C20)),SEARCH("/",RIGHT(C20,LEN(C20)-SEARCH("@",C20)-1))),"") -> 1 | B20: =LEFT(RIGHT(RIGHT(Tableau4[[#This Row],[file name]],LEN(Tableau4[[#This Row],[file name]])-SEARCH("@",Tableau4[[#This Row],[file name]])),LEN(RIGHT(Tableau4[[#This Row],[file name]],LEN(Tableau4[[#This Row],[file name]])-SEARCH("@",Tableau4[[#This Row],[file name]])))-SEARCH("/",RIGHT(Tableau4[[#This Row],[file name]],LEN(Tableau4[[#This Row],[file name]])-SEARCH("@",Tableau4[[#This Row],[file name]])))),1) -> G | C20: C:\Users\andre\Desktop\REACTIV CEFAS\Dutasteride\Dutasteride/20201201_Cefas_Test8_Run1/Plate 1/@1/G10_01.tif | D20: 0 | E20: 0 | G20: 0
A21: =IFERROR(LEFT(RIGHT(C21,LEN(C21)-SEARCH("@",C21)),SEARCH("/",RIGHT(C21,LEN(C21)-SEARCH("@",C21)-1))),"") -> 1 | B21: =LEFT(RIGHT(RIGHT(Tableau4[[#This Row],[file name]],LEN(Tableau4[[#This Row],[file name]])-SEARCH("@",Tableau4[[#This Row],[file name]])),LEN(RIGHT(Tableau4[[#This Row],[file name]],LEN(Tableau4[[#This Row],[file name]])-SEARCH("@",Tableau4[[#This Row],[file name]])))-SEARCH("/",RIGHT(Tableau4[[#This Row],[file name]],LEN(Tableau4[[#This Row],[file name]])-SEARCH("@",Tableau4[[#This Row],[file name]])))),1) -> G | C21: C:\Users\andre\Desktop\REACTIV CEFAS\Dutasteride\Dutasteride/20201201_Cefas_Test8_Run1/Plate 1/@1/G10_02.tif | D21: 21.6299 | E21: 31 | G21: 671
A22: =IFERROR(LEFT(RIGHT(C22,LEN(C22)-SEARCH("@",C22)),SEARCH("/",RIGHT(C22,LEN(C22)-SEARCH("@",C22)-1))),"") -> 1 | B22: =LEFT(RIGHT(RIGHT(Tableau4[[#This Row],[file name]],LEN(Tableau4[[#This Row],[file name]])-SEARCH("@",Tableau4[[#This Row],[file name]])),LEN(RIGHT(Tableau4[[#This Row],[file name]],LEN(Tableau4[[#This Row],[file name]])-SEARCH("@",Tableau4[[#This Row],[file name]])))-SEARCH("/",RIGHT(Tableau4[[#This Row],[file name]],LEN(Tableau4[[#This Row],[file name]])-SEARCH("@",Tableau4[[#This Row],[file name]])))),1) -> G | C22: C:\Users\andre\Desktop\REACTIV CEFAS\Dutasteride\Dutasteride/20201201_Cefas_Test8_Run1/Plate 1/@1/G10_03.tif | D22: 21.6299 | E22: 30 | G22: 649
A23: =IFERROR(LEFT(RIGHT(C23,LEN(C23)-SEARCH("@",C23)),SEARCH("/",RIGHT(C23,LEN(C23)-SEARCH("@",C23)-1))),"") -> 1 | B23: =LEFT(RIGHT(RIGHT(Tableau4[[#This Row],[file name]],LEN(Tableau4[[#This Row],[file name]])-SEARCH("@",Tableau4[[#This Row],[file name]])),LEN(RIGHT(Tableau4[[#This Row],[file name]],LEN(Tableau4[[#This Row],[file name]])-SEARCH("@",Tableau4[[#This Row],[file name]])))-SEARCH("/",RIGHT(Tableau4[[#This Row],[file name]],LEN(Tableau4[[#This Row],[file name]])-SEARCH("@",Tableau4[[#This Row],[file name]])))),1) -> H | C23: C:\Users\andre\Desktop\REACTIV CEFAS\Dutasteride\Dutasteride/20201201_Cefas_Test8_Run1/Plate 1/@1/H10_01.tif | D23: 562.3773 | E23: 31.4231 | G23: 17672
A24: =IFERROR(LEFT(RIGHT(C24,LEN(C24)-SEARCH("@",C24)),SEARCH("/",RIGHT(C24,LEN(C24)-SEARCH("@",C24)-1))),"") -> 1 | B24: =LEFT(RIGHT(RIGHT(Tableau4[[#This Row],[file name]],LEN(Tableau4[[#This Row],[file name]])-SEARCH("@",Tableau4[[#This Row],[file name]])),LEN(RIGHT(Tableau4[[#This Row],[file name]],LEN(Tableau4[[#This Row],[file name]])-SEARCH("@",Tableau4[[#This Row],[file name]])))-SEARCH("/",RIGHT(Tableau4[[#This Row],[file name]],LEN(Tableau4[[#This Row],[file name]])-SEARCH("@",Tableau4[[#This Row],[file name]])))),1) -> H | C24: C:\Users\andre\Desktop\REACTIV CEFAS\Dutasteride\Dutasteride/20201201_Cefas_Test8_Run1/Plate 1/@1/H10_02.tif | D24: 6467.3385 | E24: 37.4582 | G24: 242255
A25: =IFERROR(LEFT(RIGHT(C25,LEN(C25)-SEARCH("@",C25)),SEARCH("/",RIGHT(C25,LEN(C25)-SEARCH("@",C25)-1))),"") -> 1 | B25: =LEFT(RIGHT(RIGHT(Tableau4[[#This Row],[file name]],LEN(Tableau4[[#This Row],[file name]])-SEARCH("@",Tableau4[[#This Row],[file name]])),LEN(RIGHT(Tableau4[[#This Row],[file name]],LEN(Tableau4[[#This Row],[file name]])-SEARCH("@",Tableau4[[#This Row],[file name]])))-SEARCH("/",RIGHT(Tableau4[[#This Row],[file name]],LEN(Tableau4[[#This Row],[file name]])-SEARCH("@",Tableau4[[#This Row],[file name]])))),1) -> H | C25: C:\Users\andre\Desktop\REACTIV CEFAS\Dutasteride\Dutasteride/20201201_Cefas_Test8_Run1/Plate 1/@1/H10_03.tif | D25: 7786.7621 | E25: 39.6639 | G25: 308853
A26: =IFERROR(LEFT(RIGHT(C26,LEN(C26)-SEARCH("@",C26)),SEARCH("/",RIGHT(C26,LEN(C26)-SEARCH("@",C26)-1))),"") | B26: =LEFT(RIGHT(RIGHT(Tableau4[[#This Row],[file name]],LEN(Tableau4[[#This Row],[file name]])-SEARCH("@",Tableau4[[#This Row],[file name]])),LEN(RIGHT(Tableau4[[#This Row],[file name]],LEN(Tableau4[[#This Row],[file name]])-SEARCH("@",Tableau4[[#This Row],[file name]])))-SEARCH("/",RIGHT(Tableau4[[#This Row],[file name]],LEN(Tableau4[[#This Row],[file name]])-SEARCH("@",Tableau4[[#This Row],[file name]])))),1) -> #VALUE!
A27: =IFERROR(LEFT(RIGHT(C27,LEN(C27)-SEARCH("@",C27)),SEARCH("/",RIGHT(C27,LEN(C27)-SEARCH("@",C27)-1))),"") | B27: =LEFT(RIGHT(RIGHT(Tableau4[[#This Row],[file name]],LEN(Tableau4[[#This Row],[file name]])-SEARCH("@",Tableau4[[#This Row],[file name]])),LEN(RIGHT(Tableau4[[#This Row],[file name]],LEN(Tableau4[[#This Row],[file name]])-SEARCH("@",Tableau4[[#This Row],[file name]])))-SEARCH("/",RIGHT(Tableau4[[#This Row],[file name]],LEN(Tableau4[[#This Row],[file name]])-SEARCH("@",Tableau4[[#This Row],[file name]])))),1) -> #VALUE! | C27: group | E27: mean of mean fluo | F27: SD mean fluo | G27: mean of total fluo | H27: SD total fluo | I27: n fluorescent | J27: n total
A28: =IFERROR(LEFT(RIGHT(C28,LEN(C28)-SEARCH("@",C28)),SEARCH("/",RIGHT(C28,LEN(C28)-SEARCH("@",C28)-1))),"") -> 1 | B28: =LEFT(RIGHT(RIGHT(Tableau4[[#This Row],[file name]],LEN(Tableau4[[#This Row],[file name]])-SEARCH("@",Tableau4[[#This Row],[file name]])),LEN(RIGHT(Tableau4[[#This Row],[file name]],LEN(Tableau4[[#This Row],[file name]])-SEARCH("@",Tableau4[[#This Row],[file name]])))-SEARCH("/",RIGHT(Tableau4[[#This Row],[file name]],LEN(Tableau4[[#This Row],[file name]])-SEARCH("@",Tableau4[[#This Row],[file name]])))),1) | C28: C:\Users\andre\Desktop\REACTIV CEFAS\Dutasteride\Dutasteride/20201201_Cefas_Test8_Run1/Plate 1/@1/ | E28: 29.8795 | F28: 14.2068 | G28: 140170.792 | H28: 147850.892 | I28: 20 | J28: 24
A29: =IFERROR(LEFT(RIGHT(C29,LEN(C29)-SEARCH("@",C29)),SEARCH("/",RIGHT(C29,LEN(C29)-SEARCH("@",C29)-1))),"") | B29: =LEFT(RIGHT(RIGHT(Tableau4[[#This Row],[file name]],LEN(Tableau4[[#This Row],[file name]])-SEARCH("@",Tableau4[[#This Row],[file name]])),LEN(RIGHT(Tableau4[[#This Row],[file name]],LEN(Tableau4[[#This Row],[file name]])-SEARCH("@",Tableau4[[#This Row],[file name]])))-SEARCH("/",RIGHT(Tableau4[[#This Row],[file name]],LEN(Tableau4[[#This Row],[file name]])-SEARCH("@",Tableau4[[#This Row],[file name]])))),1) -> #VALUE!
A30: =IFERROR(LEFT(RIGHT(C30,LEN(C30)-SEARCH("@",C30)),SEARCH("/",RIGHT(C30,LEN(C30)-SEARCH("@",C30)-1))),"") | B30: =LEFT(RIGHT(RIGHT(Tableau4[[#This Row],[file name]],LEN(Tableau4[[#This Row],[file name]])-SEARCH("@",Tableau4[[#This Row],[file name]])),LEN(RIGHT(Tableau4[[#This Row],[file name]],LEN(Tableau4[[#This Row],[file name]])-SEARCH("@",Tableau4[[#This Row],[file name]])))-SEARCH("/",RIGHT(Tableau4[[#This Row],[file name]],LEN(Tableau4[[#This Row],[file name]])-SEARCH("@",Tableau4[[#This Row],[file name]])))),1) -> #VALUE!
A31: =IFERROR(LEFT(RIGHT(C31,LEN(C31)-SEARCH("@",C31)),SEARCH("/",RIGHT(C31,LEN(C31)-SEARCH("@",C31)-1))),"") | B31: =LEFT(RIGHT(RIGHT(Tableau4[[#This Row],[file name]],LEN(Tableau4[[#This Row],[file name]])-SEARCH("@",Tableau4[[#This Row],[file name]])),LEN(RIGHT(Tableau4[[#This Row],[file name]],LEN(Tableau4[[#This Row],[file name]])-SEARCH("@",Tableau4[[#This Row],[file name]])))-SEARCH("/",RIGHT(Tableau4[[#This Row],[file name]],LEN(Tableau4[[#This Row],[file name]])-SEARCH("@",Tableau4[[#This Row],[file name]])))),1) -> #VALUE!
A32: =IFERROR(LEFT(RIGHT(C32,LEN(C32)-SEARCH("@",C32)),SEARCH("/",RIGHT(C32,LEN(C32)-SEARCH("@",C32)-1))),"") | B32: =LEFT(RIGHT(RIGHT(Tableau4[[#This Row],[file name]],LEN(Tableau4[[#This Row],[file name]])-SEARCH("@",Tableau4[[#This Row],[file name]])),LEN(RIGHT(Tableau4[[#This Row],[file name]],LEN(Tableau4[[#This Row],[file name]])-SEARCH("@",Tableau4[[#This Row],[file name]])))-SEARCH("/",RIGHT(Tableau4[[#This Row],[file name]],LEN(Tableau4[[#This Row],[file name]])-SEARCH("@",Tableau4[[#This Row],[file name]])))),1) -> #VALUE!
A33: =IFERROR(LEFT(RIGHT(C33,LEN(C33)-SEARCH("@",C33)),SEARCH("/",RIGHT(C33,LEN(C33)-SEARCH("@",C33)-1))),"") | B33: =LEFT(RIGHT(RIGHT(Tableau4[[#This Row],[file name]],LEN(Tableau4[[#This Row],[file name]])-SEARCH("@",Tableau4[[#This Row],[file name]])),LEN(RIGHT(Tableau4[[#This Row],[file name]],LEN(Tableau4[[#This Row],[file name]])-SEARCH("@",Tableau4[[#This Row],[file name]])))-SEARCH("/",RIGHT(Tableau4[[#This Row],[file name]],LEN(Tableau4[[#This Row],[file name]])-SEARCH("@",Tableau4[[#This Row],[file name]])))),1) -> #VALUE!
A34: =IFERROR(LEFT(RIGHT(C34,LEN(C34)-SEARCH("@",C34)),SEARCH("/",RIGHT(C34,LEN(C34)-SEARCH("@",C34)-1))),"") | B34: =LEFT(RIGHT(RIGHT(Tableau4[[#This Row],[file name]],LEN(Tableau4[[#This Row],[file name]])-SEARCH("@",Tableau4[[#This Row],[file name]])),LEN(RIGHT(Tableau4[[#This Row],[file name]],LEN(Tableau4[[#This Row],[file name]])-SEARCH("@",Tableau4[[#This Row],[file name]])))-SEARCH("/",RIGHT(Tableau4[[#This Row],[file name]],LEN(Tableau4[[#This Row],[file name]])-SEARCH("@",Tableau4[[#This Row],[file name]])))),1) -> #VALUE! | C34: file name | D34: total area | E34: mean intensity | G34: total fluorescence
A35: =IFERROR(LEFT(RIGHT(C35,LEN(C35)-SEARCH("@",C35)),SEARCH("/",RIGHT(C35,LEN(C35)-SEARCH("@",C35)-1))),"") -> 13 | B35: =LEFT(RIGHT(RIGHT(Tableau4[[#This Row],[file name]],LEN(Tableau4[[#This Row],[file name]])-SEARCH("@",Tableau4[[#This Row],[file name]])),LEN(RIGHT(Tableau4[[#This Row],[file name]],LEN(Tableau4[[#This Row],[file name]])-SEARCH("@",Tableau4[[#This Row],[file name]])))-SEARCH("/",RIGHT(Tableau4[[#This Row],[file name]],LEN(Tableau4[[#This Row],[file name]])-SEARCH("@",Tableau4[[#This Row],[file name]])))),1) -> A | C35: C:\Users\andre\Desktop\REACTIV CEFAS\Dutasteride\Dutasteride/20201201_Cefas_Test8_Run1/Plate 1/@13/A8_01.tif | D35: 24312.0016 | E35: 35.6423 | G35: 866537
A36: =IFERROR(LEFT(RIGHT(C36,LEN(C36)-SEARCH("@",C36)),SEARCH("/",RIGHT(C36,LEN(C36)-SEARCH("@",C36)-1))),"") -> 13 | B36: =LEFT(RIGHT(RIGHT(Tableau4[[#This Row],[file name]],LEN(Tableau4[[#This Row],[file name]])-SEARCH("@",Tableau4[[#This Row],[file name]])),LEN(RIGHT(Tableau4[[#This Row],[file name]],LEN(Tableau4[[#This Row],[file name]])-SEARCH("@",Tableau4[[#This Row],[file name]])))-SEARCH("/",RIGHT(Tableau4[[#This Row],[file name]],LEN(Tableau4[[#This Row],[file name]])-SEARCH("@",Tableau4[[#This Row],[file name]])))),1) -> A | C36: C:\Users\andre\Desktop\REACTIV CEFAS\Dutasteride\Dutasteride/20201201_Cefas_Test8_Run1/Plate 1/@13/A8_02.tif | D36: 15140.9262 | E36: 35.39 | G36: 535837
A37: =IFERROR(LEFT(RIGHT(C37,LEN(C37)-SEARCH("@",C37)),SEARCH("/",RIGHT(C37,LEN(C37)-SEARCH("@",C37)-1))),"") -> 13 | B37: =LEFT(RIGHT(RIGHT(Tableau4[[#This Row],[file name]],LEN(Tableau4[[#This Row],[file name]])-SEARCH("@",Tableau4[[#This Row],[file name]])),LEN(RIGHT(Tableau4[[#This Row],[file name]],LEN(Tableau4[[#This Row],[file name]])-SEARCH("@",Tableau4[[#This Row],[file name]])))-SEARCH("/",RIGHT(Tableau4[[#This Row],[file name]],LEN(Tableau4[[#This Row],[file name]])-SEARCH("@",Tableau4[[#This Row],[file name]])))),1) -> A | C37: C:\Users\andre\Desktop\REACTIV CEFAS\Dutasteride\Dutasteride/20201201_Cefas_Test8_Run1/Plate 1/@13/A8_03.tif | D37: 21911.0833 | E37: 35.157 | G37: 770327
A38: =IFERROR(LEFT(RIGHT(C38,LEN(C38)-SEARCH("@",C38)),SEARCH("/",RIGHT(C38,LEN(C38)-SEARCH("@",C38)-1))),"") -> 13 | B38: =LEFT(RIGHT(RIGHT(Tableau4[[#This Row],[file name]],LEN(Tableau4[[#This Row],[file name]])-SEARCH("@",Tableau4[[#This Row],[file name]])),LEN(RIGHT(Tableau4[[#This Row],[file name]],LEN(Tableau4[[#This Row],[file name]])-SEARCH("@",Tableau4[[#This Row],[file name]])))-SEARCH("/",RIGHT(Tableau4[[#This Row],[file name]],LEN(Tableau4[[#This Row],[file name]])-SEARCH("@",Tableau4[[#This Row],[file name]])))),1) -> B | C38: C:\Users\andre\Desktop\REACTIV CEFAS\Dutasteride\Dutasteride/20201201_Cefas_Test8_Run1/Plate 1/@13/B8_01.tif | D38: 47239.6899 | E38: 36.8214 | G38: 1739433
A39: =IFERROR(LEFT(RIGHT(C39,LEN(C39)-SEARCH("@",C39)),SEARCH("/",RIGHT(C39,LEN(C39)-SEARCH("@",C39)-1))),"") -> 13 | B39: =LEFT(RIGHT(RIGHT(Tableau4[[#This Row],[file name]],LEN(Tableau4[[#This Row],[file name]])-SEARCH("@",Tableau4[[#This Row],[file name]])),LEN(RIGHT(Tableau4[[#This Row],[file name]],LEN(Tableau4[[#This Row],[file name]])-SEARCH("@",Tableau4[[#This Row],[file name]])))-SEARCH("/",RIGHT(Tableau4[[#This Row],[file name]],LEN(Tableau4[[#This Row],[file name]])-SEARCH("@",Tableau4[[#This Row],[file name]])))),1) -> B | C39: C:\Users\andre\Desktop\REACTIV CEFAS\Dutasteride\Dutasteride/20201201_Cefas_Test8_Run1/Plate 1/@13/B8_02.tif | D39: 60217.6266 | E39: 38.5862 | G39: 2323570
A40: =IFERROR(LEFT(RIGHT(C40,LEN(C40)-SEARCH("@",C40)),SEARCH("/",RIGHT(C40,LEN(C40)-SEARCH("@",C40)-1))),"") -> 13 | B40: =LEFT(RIGHT(RIGHT(Tableau4[[#This Row],[file name]],LEN(Tableau4[[#This Row],[file name]])-SEARCH("@",Tableau4[[#This Row],[file name]])),LEN(RIGHT(Tableau4[[#This Row],[file name]],LEN(Tableau4[[#This Row],[file name]])-SEARCH("@",Tableau4[[#This Row],[file name]])))-SEARCH("/",RIGHT(Tableau4[[#This Row],[file name]],LEN(Tableau4[[#This Row],[file name]])-SEARCH("@",Tableau4[[#This Row],[file name]])))),1) -> B | C40: C:\Users\andre\Desktop\REACTIV CEFAS\Dutasteride\Dutasteride/20201201_Cefas_Test8_Run1/Plate 1/@13/B8_03.tif | D40: 51046.5513 | E40: 37.1699 | G40: 1897396
...

Sheet R1
A1: 3. Expérimentateur 1 : copier et coller les valeurs des intensités totales de fluorescences obtenues dans le fichier raw data lors du traitement des images.
A3: R1 | B3: Non dopé | O3: avec testo
A4: Noms des groupes | B4: ='Page de garde'!A7 -> Témoin solvant | C4: ='Page de garde'!A9 -> EE2-33.8ng/L | D4: ='Page de garde'!A10 -> EE2-50.6ng/L | E4: ='Page de garde'!A11 -> EE2-76ng/L | F4: ='Page de garde'!A12 -> EE2-114ng/L | G4: ='Page de garde'!A13 -> EE2-170.9ng/L | H4: ='Page de garde'!A14 -> EE2-488ng/L | I4: ='Page de garde'!A15 -> DUS-10µg/L | J4: ='Page de garde'!A16 -> DUS-100µg/L | K4: ='Page de garde'!A17 -> DUS-250µg/L | L4: ='Page de garde'!A18 -> DUS-500µg/L | M4: ='Page de garde'!A19 -> DUS-1000µg/L | O4: ='Page de garde'!A36 -> Testo -30µg/L | P4: ='Page de garde'!A37 -> Testo 30µg/L + EE2 -64ng/L | Q4: ='Page de garde'!A38 -> Testo 30µg/L + FAD-10mg/L | R4: ='Page de garde'!A39 -> DUS-10µg/L + Testostérone | S4: ='Page de garde'!A40 -> DUS-100µg/L + Testostérone | T4: ='Page de garde'!A41 -> DUS-250µg/L + Testostérone | U4: ='Page de garde'!A42 -> DUS-500µg/L + Testostérone | V4: ='Page de garde'!A43 -> DUS-1000µg/L + Testostérone | W4: ='Page de garde'!A44 -> 0-00 + Testostérone | X4: ='Page de garde'!A45 -> 0-00 + Testostérone | Y4: ='Page de garde'!A46 -> 0-00 + Testostérone | Z4: ='Page de garde'!A47 -> 0-00 + Testostérone | AA4: ='Page de garde'!A48 -> 0-00 + Testostérone | AB4: ='Page de garde'!A49 -> 0-00 + Testostérone | AC4: ='Page de garde'!A50 -> 0-00 + Testostérone | AD4: ='Page de garde'!A51 -> 0-00 + Testostérone | AE4: ='Page de garde'!A52 -> 0-00 + Testostérone | AF4: ='Page de garde'!A53 -> 0-00 + Testostérone | AG4: ='Page de garde'!A54 -> 0-00 + Testostérone | AH4: ='Page de garde'!A55 -> 0-00 + Testostérone | AI4: ='Page de garde'!A56 -> 0-00 + Testostérone | AJ4: ='Page de garde'!A57 -> 0-00 + Testostérone | AK4: ='Page de garde'!A58 -> 0-00 + Testostérone
A5: Données brutes | C5: 94573.333 | D5: 187142 | E5: 280237 | F5: 853451 | G5: 2129117 | H5: 4171570.3 | I5: 319257.5 | J5: 300439.33 | K5: 295723.67 | L5: 69345.333 | M5: 185310.33 | O5: 724233.67 | P5: 3923338.3 | Q5: 59684.333 | R5: 1418171.3 | S5: 771704.33 | T5: 2543344 | U5: 2526313.7 | V5: 2702194
B6: 274743 | C6: 218368.33 | D6: 1344831.7 | E6: 411458 | F6: 2262696 | G6: 2429058.3 | H6: 3502579.3 | I6: 310706.33 | J6: 47838 | K6: 122829.33 | L6: 228282 | M6: 175692.67 | O6: 1986799.7 | P6: 3912985 | Q6: 94493.667 | R6: 634650 | S6: 3489089.3 | T6: 1960468.7 | U6: 2321407 | V6: 5145521.3
B7: 249731.67 | C7: 138229.67 | D7: 78826.667 | E7: 1014521.7 | F7: 999503.33 | G7: 3440083 | H7: 3891142.5 | I7: 181770.33 | J7: 216998.33 | K7: 487184.67 | L7: 4340.3333 | M7: 0 | O7: 3366073 | P7: 4483711.3 | Q7: 59223 | R7: 2875435 | S7: 57672.333 | T7: 3560280.7 | U7: 3770818.7 | V7: 2972200
B8: 145771 | C8: 171705.33 | D8: 191792.33 | E8: 696836 | F8: 3496688.7 | G8: 3562422 | H8: 3758107.7 | I8: 148193.67 | J8: 248297 | K8: 174877.33 | L8: 213112 | M8: 237993.67 | O8: 1698523.7 | P8: 2204854 | Q8: 178872 | R8: 375639 | S8: 3671826 | T8: 2135130.3 | U8: 116679 | V8: 1710759
B9: 23857.667 | C9: 260272.67 | D9: 56980.333 | E9: 799556.67 | F9: 1513725 | G9: 2736780 | H9: 4961775 | I9: 110225.67 | J9: 86570 | K9: 206082.33 | L9: 192390.67 | M9: 398524 | O9: 192722.33 | P9: 4702836.7 | Q9: 152707 | R9: 2025200 | S9: 3040341.3 | T9: 2964456.3 | U9: 1720110.3 | V9: 1520415.7
B10: 61155 | C10: 215109.33 | E10: 163067.67 | F10: 2032301.7 | G10: 4106169 | H10: 4917830.7 | I10: 24420 | J10: 8385 | K10: 185836.67 | L10: 75048.667 | M10: 155317 | O10: 1376382.3 | P10: 3265714 | Q10: 266372.33 | R10: 1039915 | S10: 2102757.7 | T10: 2015264.3 | U10: 56958.667 | V10: 3058344.7
B11: 440 | C11: 85568.333 | D11: 144509 | E11: 994283.33 | F11: 2373686.3 | G11: 3742541.7 | H11: 4126154.7 | I11: 310439.33 | J11: 230027 | K11: 441156 | L11: 220935 | M11: 223.66667 | O11: 1717795.7 | P11: 4801562.7 | Q11: 70946 | R11: 872564.33 | T11: 1812931 | V11: 2030044.7
B12: 189593.33 | C12: 202506 | D12: 61155 | E12: 74785.5 | F12: 2684284.7 | H12: 2066065.7 | I12: 242240.33 | J12: 342141.67 | K12: 97190.333 | L12: 195166.67 | M12: 264656.33 | P12: 2435663.3 | Q12: 137674.67 | R12: 1787422.3 | S12: 2478216.7 | T12: 3257743.3 | U12: 225167.33 | V12: 1462498
O13: 2719721.3
O14: 2314600.3
O15: 2557252
O16: 2630339.3
O17: 2193357.5
O18: 1415006
O19: 311802.33
O20: 1213422.7
A22: =A4 -> Noms des groupes | B22: =B4 -> Témoin solvant | C22: =C4 -> EE2-33.8ng/L | D22: =D4 -> EE2-50.6ng/L | E22: =E4 -> EE2-76ng/L | F22: =F4 -> EE2-114ng/L | G22: =G4 -> EE2-170.9ng/L | H22: =H4 -> EE2-488ng/L | ... M22: =M4 -> DUS-1000µg/L | N22: Nom des groupes | O22: =O4 -> Testo -30µg/L | P22: =P4 -> Testo 30µg/L + EE2 -64ng/L | Q22: =Q4 -> Testo 30µg/L + FAD-10mg/L | R22: =R4 -> DUS-10µg/L + Testostérone | S22: =S4 -> DUS-100µg/L + Testostérone | T22: =T4 -> DUS-250µg/L + Testostérone | U22: =U4 -> DUS-500µg/L + Testostérone | V22: =V4 -> DUS-1000µg/L + Testostérone | ... AK22: =AK4 -> 0-00 + Testostérone
A23: mean | B23: =AVERAGE(B5:B20) -> 135041.67 | C23: =AVERAGE(C5:C20) -> 173291.62 | D23: =AVERAGE(D5:D20) -> 295033.86 | E23: =AVERAGE(E5:E20) -> 554343.23 | F23: =AVERAGE(F5:F20) -> 2027042.1 | G23: =AVERAGE(G5:G20) -> 3163738.7 | H23: =AVERAGE(H5:H20) -> 3924403.2 | I23: =AVERAGE(I5:I20) -> 205906.65 | ... M23: =AVERAGE(M5:M20) -> 177214.71 | N23: mean | O23: =AVERAGE(O5:O20) -> 1761202.1 | P23: =AVERAGE(P5:P20) -> 3716333.2 | Q23: =AVERAGE(Q5:Q20) -> 127496.62 | R23: =AVERAGE(R5:R20) -> 1378624.6 | S23: =AVERAGE(S5:S20) -> 2230229.7 | T23: =AVERAGE(T5:T20) -> 2531202.3 | U23: =AVERAGE(U5:U20) -> 1533922.1 | V23: =AVERAGE(V5:V20) -> 2575247.2 | ... AK23: =AVERAGE(AK5:AK20) -> #DIV/0!
A24: SD | B24: =STDEV(B5:B20) -> 109316.05 | C24: =STDEV(C5:C20) -> 62476.983 | D24: =STDEV(D5:D20) -> 466395.22 | E24: =STDEV(E5:E20) -> 371169.56 | F24: =STDEV(F5:F20) -> 883515.53 | G24: =STDEV(G5:G20) -> 736092.54 | H24: =STDEV(H5:H20) -> 912214.56 | I24: =STDEV(I5:I20) -> 108288.12 | ... M24: =STDEV(M5:M20) -> 132878.12 | N24: SD | O24: =STDEV(O5:O20) -> 911724.11 | P24: =STDEV(P5:P20) -> 996353.83 | Q24: =STDEV(Q5:Q20) -> 71924.574 | R24: =STDEV(R5:R20) -> 824402.83 | S24: =STDEV(S5:S20) -> 1368956.8 | T24: =STDEV(T5:T20) -> 658942.46 | U24: =STDEV(U5:U20) -> 1446039.6 | V24: =STDEV(V5:V20) -> 1219417 | ... AK24: =STDEV(AK5:AK20) -> #DIV/0!
B26: Non dopé | O26: avec testo
A27: Noms des groupes | B27: =B4 -> Témoin solvant | C27: =C4 -> EE2-33.8ng/L | D27: =D4 -> EE2-50.6ng/L | E27: =E4 -> EE2-76ng/L | F27: =F4 -> EE2-114ng/L | G27: =G4 -> EE2-170.9ng/L | H27: =H4 -> EE2-488ng/L | I27: =I4 -> DUS-10µg/L | ... M27: =M4 -> DUS-1000µg/L | O27: =O4 -> Testo -30µg/L | P27: =P4 -> Testo 30µg/L + EE2 -64ng/L | Q27: =Q4 -> Testo 30µg/L + FAD-10mg/L | R27: =R4 -> DUS-10µg/L + Testostérone | S27: =S4 -> DUS-100µg/L + Testostérone | T27: =T4 -> DUS-250µg/L + Testostérone | U27: =U4 -> DUS-500µg/L + Testostérone | V27: =V4 -> DUS-1000µg/L + Testostérone | ... AK27: =AK4 -> 0-00 + Testostérone
A28: Données normalisées sur la moyenne du groupe "Testo" | B28: =IF(B5="","",(B5/$O$23)) | C28: =IF(C5="","",(C5/$O$23)) -> 0.053698171 | D28: =IF(D5="","",(D5/$O$23)) -> 0.1062581 | E28: =IF(E5="","",(E5/$O$23)) -> 0.15911689 | F28: =IF(F5="","",(F5/$O$23)) -> 0.48458436 | G28: =IF(G5="","",(G5/$O$23)) -> 1.2088999 | H28: =IF(H5="","",(H5/$O$23)) -> 2.3685926 | I28: =IF(I5="","",(I5/$O$23)) -> 0.18127249 | ... M28: =IF(M5="","",(M5/$O$23)) -> 0.1052181 | O28: =IF(O5="","",(O5/$O$23)) -> 0.41121553 | P28: =IF(P5="","",(P5/$O$23)) -> 2.227648 | Q28: =IF(Q5="","",(Q5/$O$23)) -> 0.033888406 | R28: =IF(R5="","",(R5/$O$23)) -> 0.80522918 | S28: =IF(S5="","",(S5/$O$23)) -> 0.43816909 | T28: =IF(T5="","",(T5/$O$23)) -> 1.4440955 | U28: =IF(U5="","",(U5/$O$23)) -> 1.4344257 | V28: =IF(V5="","",(V5/$O$23)) -> 1.5342895 | ... AK28: =IF(AK5="","",(AK5/$O$23))
B29: =IF(B6="","",(B6/$O$23)) -> 0.15599743 | C29: =IF(C6="","",(C6/$O$23)) -> 0.12398823 | D29: =IF(D6="","",(D6/$O$23)) -> 0.76358735 | E29: =IF(E6="","",(E6/$O$23)) -> 0.23362338 | F29: =IF(F6="","",(F6/$O$23)) -> 1.2847452 | G29: =IF(G6="","",(G6/$O$23)) -> 1.3792048 | H29: =IF(H6="","",(H6/$O$23)) -> 1.9887435 | I29: =IF(I6="","",(I6/$O$23)) -> 0.17641719 | ... M29: =IF(M6="","",(M6/$O$23)) -> 0.099757242 | O29: =IF(O6="","",(O6/$O$23)) -> 1.1280929 | P29: =IF(P6="","",(P6/$O$23)) -> 2.2217694 | Q29: =IF(Q6="","",(Q6/$O$23)) -> 0.053652937 | R29: =IF(R6="","",(R6/$O$23)) -> 0.36035046 | S29: =IF(S6="","",(S6/$O$23)) -> 1.981084 | T29: =IF(T6="","",(T6/$O$23)) -> 1.1131423 | U29: =IF(U6="","",(U6/$O$23)) -> 1.318081 | V29: =IF(V6="","",(V6/$O$23)) -> 2.9215961 | ... AK29: =IF(AK6="","",(AK6/$O$23))
B30: =IF(B7="","",(B7/$O$23)) -> 0.14179614 | C30: =IF(C7="","",(C7/$O$23)) -> 0.078485976 | D30: =IF(D7="","",(D7/$O$23)) -> 0.044757308 | E30: =IF(E7="","",(E7/$O$23)) -> 0.57603932 | F30: =IF(F7="","",(F7/$O$23)) -> 0.567512 | G30: =IF(G7="","",(G7/$O$23)) -> 1.9532585 | H30: =IF(H7="","",(H7/$O$23)) -> 2.2093674 | I30: =IF(I7="","",(I7/$O$23)) -> 0.1032081 | ... M30: =IF(M7="","",(M7/$O$23)) -> 0 | O30: =IF(O7="","",(O7/$O$23)) -> 1.9112361 | P30: =IF(P7="","",(P7/$O$23)) -> 2.5458244 | Q30: =IF(Q7="","",(Q7/$O$23)) -> 0.033626464 | R30: =IF(R7="","",(R7/$O$23)) -> 1.6326547 | S30: =IF(S7="","",(S7/$O$23)) -> 0.032746005 | T30: =IF(T7="","",(T7/$O$23)) -> 2.021506 | U30: =IF(U7="","",(U7/$O$23)) -> 2.1410482 | V30: =IF(V7="","",(V7/$O$23)) -> 1.6875973 | ... AK30: =IF(AK7="","",(AK7/$O$23))
B31: =IF(B8="","",(B8/$O$23)) -> 0.082767899 | C31: =IF(C8="","",(C8/$O$23)) -> 0.097493258 | D31: =IF(D8="","",(D8/$O$23)) -> 0.10889854 | E31: =IF(E8="","",(E8/$O$23)) -> 0.3956593 | F31: =IF(F8="","",(F8/$O$23)) -> 1.9853988 | G31: =IF(G8="","",(G8/$O$23)) -> 2.0227218 | H31: =IF(H8="","",(H8/$O$23)) -> 2.133831 | I31: =IF(I8="","",(I8/$O$23)) -> 0.084143475 | ... M31: =IF(M8="","",(M8/$O$23)) -> 0.13513138 | O31: =IF(O8="","",(O8/$O$23)) -> 0.96441155 | P31: =IF(P8="","",(P8/$O$23)) -> 1.2519029 | Q31: =IF(Q8="","",(Q8/$O$23)) -> 0.10156245 | R31: =IF(R8="","",(R8/$O$23)) -> 0.21328557 | S31: =IF(S8="","",(S8/$O$23)) -> 2.0848408 | T31: =IF(T8="","",(T8/$O$23)) -> 1.2123142 | U31: =IF(U8="","",(U8/$O$23)) -> 0.066249636 | V31: =IF(V8="","",(V8/$O$23)) -> 0.9713587 | ... AK31: =IF(AK8="","",(AK8/$O$23))
B32: =IF(B9="","",(B9/$O$23)) -> 0.01354624 | C32: =IF(C9="","",(C9/$O$23)) -> 0.14778126 | D32: =IF(D9="","",(D9/$O$23)) -> 0.032353091 | E32: =IF(E9="","",(E9/$O$23)) -> 0.45398348 | F32: =IF(F9="","",(F9/$O$23)) -> 0.85948397 | G32: =IF(G9="","",(G9/$O$23)) -> 1.5539273 | H32: =IF(H9="","",(H9/$O$23)) -> 2.8172661 | I32: =IF(I9="","",(I9/$O$23)) -> 0.062585472 | ... M32: =IF(M9="","",(M9/$O$23)) -> 0.22627954 | O32: =IF(O9="","",(O9/$O$23)) -> 0.10942658 | P32: =IF(P9="","",(P9/$O$23)) -> 2.6702424 | Q32: =IF(Q9="","",(Q9/$O$23)) -> 0.086706119 | R32: =IF(R9="","",(R9/$O$23)) -> 1.1498964 | S32: =IF(S9="","",(S9/$O$23)) -> 1.7262876 | T32: =IF(T9="","",(T9/$O$23)) -> 1.6832005 | U32: =IF(U9="","",(U9/$O$23)) -> 0.97666833 | V32: =IF(V9="","",(V9/$O$23)) -> 0.86328289 | ... AK32: =IF(AK9="","",(AK9/$O$23))
B33: =IF(B10="","",(B10/$O$23)) -> 0.034723442 | C33: =IF(C10="","",(C10/$O$23)) -> 0.12213779 | D33: =IF(D10="","",(D10/$O$23)) | E33: =IF(E10="","",(E10/$O$23)) -> 0.092588843 | F33: =IF(F10="","",(F10/$O$23)) -> 1.1539287 | G33: =IF(G10="","",(G10/$O$23)) -> 2.3314581 | H33: =IF(H10="","",(H10/$O$23)) -> 2.7923148 | I33: =IF(I10="","",(I10/$O$23)) -> 0.01386553 | ... M33: =IF(M10="","",(M10/$O$23)) -> 0.088188061 | O33: =IF(O10="","",(O10/$O$23)) -> 0.78150163 | P33: =IF(P10="","",(P10/$O$23)) -> 1.8542528 | Q33: =IF(Q10="","",(Q10/$O$23)) -> 0.15124461 | R33: =IF(R10="","",(R10/$O$23)) -> 0.5904575 | S33: =IF(S10="","",(S10/$O$23)) -> 1.1939332 | T33: =IF(T10="","",(T10/$O$23)) -> 1.144255 | U33: =IF(U10="","",(U10/$O$23)) -> 0.032340789 | V33: =IF(V10="","",(V10/$O$23)) -> 1.7365098 | ... AK33: =IF(AK10="","",(AK10/$O$23))
B34: =IF(B11="","",(B11/$O$23)) -> 0.00024982936 | C34: =IF(C11="","",(C11/$O$23)) -> 0.048585186 | D34: =IF(D11="","",(D11/$O$23)) -> 0.082051343 | E34: =IF(E11="","",(E11/$O$23)) -> 0.56454811 | F34: =IF(F11="","",(F11/$O$23)) -> 1.3477649 | G34: =IF(G11="","",(G11/$O$23)) -> 2.1249927 | H34: =IF(H11="","",(H11/$O$23)) -> 2.3428059 | I34: =IF(I11="","",(I11/$O$23)) -> 0.17626559 | ... M34: =IF(M11="","",(M11/$O$23)) -> 0.00012699659 | O34: =IF(O11="","",(O11/$O$23)) -> 0.97535407 | P34: =IF(P11="","",(P11/$O$23)) -> 2.7262985 | Q34: =IF(Q11="","",(Q11/$O$23)) -> 0.040282713 | R34: =IF(R11="","",(R11/$O$23)) -> 0.49543679 | S34: =IF(S11="","",(S11/$O$23)) | T34: =IF(T11="","",(T11/$O$23)) -> 1.0293713 | U34: =IF(U11="","",(U11/$O$23)) | V34: =IF(V11="","",(V11/$O$23)) -> 1.1526472 | ... AK34: =IF(AK11="","",(AK11/$O$23))
