Workbook

Sheet Page de garde
A1: 1. Expérimentateur 1 : copier et coller le n° de prestation et renseigner la date de réalisation de chaque réplica ainsi que le visa de l'expérimentateur.
A2: R1 | B2: Numéro d'expérience : | E2: Date de réalisation :
A3: R2 | B3: Numéro d'expérience : | E3: Date de réalisation :
A4: R3 | B4: Numéro d'expérience : | E4: Date de réalisation :
A5: 2. Expérimentateur 1 : copier et coller la dilution appliquée et le nom donné pour chaque des échantillons par le client. Conserver la mise en forme de l'exemple en italique. Ne pas remplir la colonne "nom sur graphique".
A6: Nom sur le graphique | B6: Code WF | C6: Concentration | D6: Unité | E6: Nom de l'échantillon donné par le client | F6: Dopage (+Testostérone / + EE2, ….)
A7: =IF(ISBLANK(liste_groupe[[#This Row],[Code WF]])," ",IF(ISBLANK(liste_groupe[[#This Row],[Unité]]),CONCATENATE(liste_groupe[[#This Row],[Nom de l''échantillon donné par le client]],liste_groupe[[#This Row],[Dopage (+Testostérone / + EE2, ….)]]),CONCATENATE(liste_groupe[[#This Row],[Nom de l''échantillon donné par le client]],"-",liste_groupe[[#This Row],[Concentration]],liste_groupe[[#This Row],[Unité]],liste_groupe[[#This Row],[Dopage (+Testostérone / + EE2, ….)]]))) -> Témoin solvant | B7: Témoin | E7: Témoin solvant
A8: =IF(ISBLANK(liste_groupe[[#This Row],[Code WF]])," ",IF(ISBLANK(liste_groupe[[#This Row],[Unité]]),CONCATENATE(liste_groupe[[#This Row],[Nom de l''échantillon donné par le client]],liste_groupe[[#This Row],[Dopage (+Testostérone / + EE2, ….)]]),CONCATENATE(liste_groupe[[#This Row],[Nom de l''échantillon donné par le client]],"-",liste_groupe[[#This Row],[Concentration]],liste_groupe[[#This Row],[Unité]],liste_groupe[[#This Row],[Dopage (+Testostérone / + EE2, ….)]]))) -> EE2-22,5ng/L | B8: Témoin | C8: 22.5 | D8: ng/L | E8: EE2
A9: =IF(ISBLANK(liste_groupe[[#This Row],[Code WF]])," ",IF(ISBLANK(liste_groupe[[#This Row],[Unité]]),CONCATENATE(liste_groupe[[#This Row],[Nom de l''échantillon donné par le client]],liste_groupe[[#This Row],[Dopage (+Testostérone / + EE2, ….)]]),CONCATENATE(liste_groupe[[#This Row],[Nom de l''échantillon donné par le client]],"-",liste_groupe[[#This Row],[Concentration]],liste_groupe[[#This Row],[Unité]],liste_groupe[[#This Row],[Dopage (+Testostérone / + EE2, ….)]]))) -> EE2-33,8ng/L | B9: Témoin | C9: 33.8 | D9: ng/L | E9: EE2
A10: =IF(ISBLANK(liste_groupe[[#This Row],[Code WF]])," ",IF(ISBLANK(liste_groupe[[#This Row],[Unité]]),CONCATENATE(liste_groupe[[#This Row],[Nom de l''échantillon donné par le client]],liste_groupe[[#This Row],[Dopage (+Testostérone / + EE2, ….)]]),CONCATENATE(liste_groupe[[#This Row],[Nom de l''échantillon donné par le client]],"-",liste_groupe[[#This Row],[Concentration]],liste_groupe[[#This Row],[Unité]],liste_groupe[[#This Row],[Dopage (+Testostérone / + EE2, ….)]]))) -> EE2-50,6ng/L | B10: Témoin | C10: 50.6 | D10: ng/L | E10: EE2
A11: =IF(ISBLANK(liste_groupe[[#This Row],[Code WF]])," ",IF(ISBLANK(liste_groupe[[#This Row],[Unité]]),CONCATENATE(liste_groupe[[#This Row],[Nom de l''échantillon donné par le client]],liste_groupe[[#This Row],[Dopage (+Testostérone / + EE2, ….)]]),CONCATENATE(liste_groupe[[#This Row],[Nom de l''échantillon donné par le client]],"-",liste_groupe[[#This Row],[Concentration]],liste_groupe[[#This Row],[Unité]],liste_groupe[[#This Row],[Dopage (+Testostérone / + EE2, ….)]]))) -> EE2-76ng/L | B11: Témoin | C11: 76 | D11: ng/L | E11: EE2
A12: =IF(ISBLANK(liste_groupe[[#This Row],[Code WF]])," ",IF(ISBLANK(liste_groupe[[#This Row],[Unité]]),CONCATENATE(liste_groupe[[#This Row],[Nom de l''échantillon donné par le client]],liste_groupe[[#This Row],[Dopage (+Testostérone / + EE2, ….)]]),CONCATENATE(liste_groupe[[#This Row],[Nom de l''échantillon donné par le client]],"-",liste_groupe[[#This Row],[Concentration]],liste_groupe[[#This Row],[Unité]],liste_groupe[[#This Row],[Dopage (+Testostérone / + EE2, ….)]]))) -> EE2-114ng/L | B12: Témoin | C12: 114 | D12: ng/L | E12: EE2
A13: =IF(ISBLANK(liste_groupe[[#This Row],[Code WF]])," ",IF(ISBLANK(liste_groupe[[#This Row],[Unité]]),CONCATENATE(liste_groupe[[#This Row],[Nom de l''échantillon donné par le client]],liste_groupe[[#This Row],[Dopage (+Testostérone / + EE2, ….)]]),CONCATENATE(liste_groupe[[#This Row],[Nom de l''échantillon donné par le client]],"-",liste_groupe[[#This Row],[Concentration]],liste_groupe[[#This Row],[Unité]],liste_groupe[[#This Row],[Dopage (+Testostérone / + EE2, ….)]]))) -> EE2-170,9ng/L | B13: Témoin | C13: 170.9 | D13: ng/L | E13: EE2
A14: =IF(ISBLANK(liste_groupe[[#This Row],[Code WF]])," ",IF(ISBLANK(liste_groupe[[#This Row],[Unité]]),CONCATENATE(liste_groupe[[#This Row],[Nom de l''échantillon donné par le client]],liste_groupe[[#This Row],[Dopage (+Testostérone / + EE2, ….)]]),CONCATENATE(liste_groupe[[#This Row],[Nom de l''échantillon donné par le client]],"-",liste_groupe[[#This Row],[Concentration]],liste_groupe[[#This Row],[Unité]],liste_groupe[[#This Row],[Dopage (+Testostérone / + EE2, ….)]]))) -> EE2-488ng/L | B14: Témoin | C14: 488 | D14: ng/L | E14: EE2
A15: Testo-3.7µg/L | C15: 3.7 | D15: µg/L | E15: Testo
A16: Testo-11µg/L | C16: 11 | D16: µg/L | E16: Testo
A17: Testo-33µg/L | C17: 33 | D17: µg/L | E17: Testo
A18: Testo-100µg/L | C18: 100 | D18: µg/L | E18: Testo
A19: Testo-300µg/L | C19: 300 | D19: µg/L | E19: Testo
A20: =IF(ISBLANK(liste_groupe[[#This Row],[Code WF]])," ",IF(ISBLANK(liste_groupe[[#This Row],[Unité]]),CONCATENATE(liste_groupe[[#This Row],[Nom de l''échantillon donné par le client]],liste_groupe[[#This Row],[Dopage (+Testostérone / + EE2, ….)]]),CONCATENATE(liste_groupe[[#This Row],[Nom de l''échantillon donné par le client]],"-",liste_groupe[[#This Row],[Concentration]],liste_groupe[[#This Row],[Unité]],liste_groupe[[#This Row],[Dopage (+Testostérone / + EE2, ….)]])))
A21: =IF(ISBLANK(liste_groupe[[#This Row],[Code WF]])," ",IF(ISBLANK(liste_groupe[[#This Row],[Unité]]),CONCATENATE(liste_groupe[[#This Row],[Nom de l''échantillon donné par le client]],liste_groupe[[#This Row],[Dopage (+Testostérone / + EE2, ….)]]),CONCATENATE(liste_groupe[[#This Row],[Nom de l''échantillon donné par le client]],"-",liste_groupe[[#This Row],[Concentration]],liste_groupe[[#This Row],[Unité]],liste_groupe[[#This Row],[Dopage (+Testostérone / + EE2, ….)]])))
A22: =IF(ISBLANK(liste_groupe[[#This Row],[Code WF]])," ",IF(ISBLANK(liste_groupe[[#This Row],[Unité]]),CONCATENATE(liste_groupe[[#This Row],[Nom de l''échantillon donné par le client]],liste_groupe[[#This Row],[Dopage (+Testostérone / + EE2, ….)]]),CONCATENATE(liste_groupe[[#This Row],[Nom de l''échantillon donné par le client]],"-",liste_groupe[[#This Row],[Concentration]],liste_groupe[[#This Row],[Unité]],liste_groupe[[#This Row],[Dopage (+Testostérone / + EE2, ….)]])))
A23: =IF(ISBLANK(liste_groupe[[#This Row],[Code WF]])," ",IF(ISBLANK(liste_groupe[[#This Row],[Unité]]),CONCATENATE(liste_groupe[[#This Row],[Nom de l''échantillon donné par le client]],liste_groupe[[#This Row],[Dopage (+Testostérone / + EE2, ….)]]),CONCATENATE(liste_groupe[[#This Row],[Nom de l''échantillon donné par le client]],"-",liste_groupe[[#This Row],[Concentration]],liste_groupe[[#This Row],[Unité]],liste_groupe[[#This Row],[Dopage (+Testostérone / + EE2, ….)]])))
A24: =IF(ISBLANK(liste_groupe[[#This Row],[Code WF]])," ",IF(ISBLANK(liste_groupe[[#This Row],[Unité]]),CONCATENATE(liste_groupe[[#This Row],[Nom de l''échantillon donné par le client]],liste_groupe[[#This Row],[Dopage (+Testostérone / + EE2, ….)]]),CONCATENATE(liste_groupe[[#This Row],[Nom de l''échantillon donné par le client]],"-",liste_groupe[[#This Row],[Concentration]],liste_groupe[[#This Row],[Unité]],liste_groupe[[#This Row],[Dopage (+Testostérone / + EE2, ….)]])))
A25: =IF(ISBLANK(liste_groupe[[#This Row],[Code WF]])," ",IF(ISBLANK(liste_groupe[[#This Row],[Unité]]),CONCATENATE(liste_groupe[[#This Row],[Nom de l''échantillon donné par le client]],liste_groupe[[#This Row],[Dopage (+Testostérone / + EE2, ….)]]),CONCATENATE(liste_groupe[[#This Row],[Nom de l''échantillon donné par le client]],"-",liste_groupe[[#This Row],[Concentration]],liste_groupe[[#This Row],[Unité]],liste_groupe[[#This Row],[Dopage (+Testostérone / + EE2, ….)]])))
A26: =IF(ISBLANK(liste_groupe[[#This Row],[Code WF]])," ",IF(ISBLANK(liste_groupe[[#This Row],[Unité]]),CONCATENATE(liste_groupe[[#This Row],[Nom de l''échantillon donné par le client]],liste_groupe[[#This Row],[Dopage (+Testostérone / + EE2, ….)]]),CONCATENATE(liste_groupe[[#This Row],[Nom de l''échantillon donné par le client]],"-",liste_groupe[[#This Row],[Concentration]],liste_groupe[[#This Row],[Unité]],liste_groupe[[#This Row],[Dopage (+Testostérone / + EE2, ….)]])))
A27: =IF(ISBLANK(liste_groupe[[#This Row],[Code WF]])," ",IF(ISBLANK(liste_groupe[[#This Row],[Unité]]),CONCATENATE(liste_groupe[[#This Row],[Nom de l''échantillon donné par le client]],liste_groupe[[#This Row],[Dopage (+Testostérone / + EE2, ….)]]),CONCATENATE(liste_groupe[[#This Row],[Nom de l''échantillon donné par le client]],"-",liste_groupe[[#This Row],[Concentration]],liste_groupe[[#This Row],[Unité]],liste_groupe[[#This Row],[Dopage (+Testostérone / + EE2, ….)]])))
A28: =IF(ISBLANK(liste_groupe[[#This Row],[Code WF]])," ",IF(ISBLANK(liste_groupe[[#This Row],[Unité]]),CONCATENATE(liste_groupe[[#This Row],[Nom de l''échantillon donné par le client]],liste_groupe[[#This Row],[Dopage (+Testostérone / + EE2, ….)]]),CONCATENATE(liste_groupe[[#This Row],[Nom de l''échantillon donné par le client]],"-",liste_groupe[[#This Row],[Concentration]],liste_groupe[[#This Row],[Unité]],liste_groupe[[#This Row],[Dopage (+Testostérone / + EE2, ….)]])))
A29: =IF(ISBLANK(liste_groupe[[#This Row],[Code WF]])," ",IF(ISBLANK(liste_groupe[[#This Row],[Unité]]),CONCATENATE(liste_groupe[[#This Row],[Nom de l''échantillon donné par le client]],liste_groupe[[#This Row],[Dopage (+Testostérone / + EE2, ….)]]),CONCATENATE(liste_groupe[[#This Row],[Nom de l''échantillon donné par le client]],"-",liste_groupe[[#This Row],[Concentration]],liste_groupe[[#This Row],[Unité]],liste_groupe[[#This Row],[Dopage (+Testostérone / + EE2, ….)]])))
A30: =IF(ISBLANK(liste_groupe[[#This Row],[Code WF]])," ",IF(ISBLANK(liste_groupe[[#This Row],[Unité]]),CONCATENATE(liste_groupe[[#This Row],[Nom de l''échantillon donné par le client]],liste_groupe[[#This Row],[Dopage (+Testostérone / + EE2, ….)]]),CONCATENATE(liste_groupe[[#This Row],[Nom de l''échantillon donné par le client]],"-",liste_groupe[[#This Row],[Concentration]],liste_groupe[[#This Row],[Unité]],liste_groupe[[#This Row],[Dopage (+Testostérone / + EE2, ….)]])))
A31: =IF(ISBLANK(liste_groupe[[#This Row],[Code WF]])," ",IF(ISBLANK(liste_groupe[[#This Row],[Unité]]),CONCATENATE(liste_groupe[[#This Row],[Nom de l''échantillon donné par le client]],liste_groupe[[#This Row],[Dopage (+Testostérone / + EE2, ….)]]),CONCATENATE(liste_groupe[[#This Row],[Nom de l''échantillon donné par le client]],"-",liste_groupe[[#This Row],[Concentration]],liste_groupe[[#This Row],[Unité]],liste_groupe[[#This Row],[Dopage (+Testostérone / + EE2, ….)]])))
... A35: =IF(ISBLANK(liste_groupe[[#This Row],[Code WF]])," ",IF(ISBLANK(liste_groupe[[#This Row],[Unité]]),CONCATENATE(liste_groupe[[#This Row],[Nom de l''échantillon donné par le client]],liste_groupe[[#This Row],[Dopage (+Testostérone / + EE2, ….)]]),CONCATENATE(liste_groupe[[#This Row],[Nom de l''échantillon donné par le client]],"-",liste_groupe[[#This Row],[Concentration]],liste_groupe[[#This Row],[Unité]],liste_groupe[[#This Row],[Dopage (+Testostérone / + EE2, ….)]])))
A36: =IF(ISBLANK(liste_groupe[[#This Row],[Code WF]])," ",IF(ISBLANK(liste_groupe[[#This Row],[Unité]]),CONCATENATE(liste_groupe[[#This Row],[Nom de l''échantillon donné par le client]],liste_groupe[[#This Row],[Dopage (+Testostérone / + EE2, ….)]]),CONCATENATE(liste_groupe[[#This Row],[Nom de l''échantillon donné par le client]],"-",liste_groupe[[#This Row],[Concentration]],liste_groupe[[#This Row],[Unité]],liste_groupe[[#This Row],[Dopage (+Testostérone / + EE2, ….)]]))) -> Testo -30µg/L | B36: Témoin | C36: 30 | D36: µg/L | E36: Testo
A37: =IF(ISBLANK(liste_groupe[[#This Row],[Code WF]])," ",IF(ISBLANK(liste_groupe[[#This Row],[Unité]]),CONCATENATE(liste_groupe[[#This Row],[Nom de l''échantillon donné par le client]],liste_groupe[[#This Row],[Dopage (+Testostérone / + EE2, ….)]]),CONCATENATE(liste_groupe[[#This Row],[Nom de l''échantillon donné par le client]],"-",liste_groupe[[#This Row],[Concentration]],liste_groupe[[#This Row],[Unité]],liste_groupe[[#This Row],[Dopage (+Testostérone / + EE2, ….)]]))) -> Testo 30µg/L + EE2 -64ng/L | B37: Témoin | C37: 64 | D37: ng/L | E37: Testo 30µg/L + EE2
A38: =IF(ISBLANK(liste_groupe[[#This Row],[Code WF]])," ",IF(ISBLANK(liste_groupe[[#This Row],[Unité]]),CONCATENATE(liste_groupe[[#This Row],[Nom de l''échantillon donné par le client]],liste_groupe[[#This Row],[Dopage (+Testostérone / + EE2, ….)]]),CONCATENATE(liste_groupe[[#This Row],[Nom de l''échantillon donné par le client]],"-",liste_groupe[[#This Row],[Concentration]],liste_groupe[[#This Row],[Unité]],liste_groupe[[#This Row],[Dopage (+Testostérone / + EE2, ….)]]))) -> Testo 30µg/L + FAD-10mg/L | B38: Témoin | C38: 10 | D38: mg/L | E38: Testo 30µg/L + FAD
A39: =IF(ISBLANK(liste_groupe[[#This Row],[Code WF]])," ",IF(ISBLANK(liste_groupe[[#This Row],[Unité]]),CONCATENATE(liste_groupe[[#This Row],[Nom de l''échantillon donné par le client]],liste_groupe[[#This Row],[Dopage (+Testostérone / + EE2, ….)]]),CONCATENATE(liste_groupe[[#This Row],[Nom de l''échantillon donné par le client]],"-",liste_groupe[[#This Row],[Concentration]],liste_groupe[[#This Row],[Unité]],liste_groupe[[#This Row],[Dopage (+Testostérone / + EE2, ….)]]))) -> Testo-3,7µg/L + Testostérone | B39: =B15 -> 0 | C39: =C15 -> 3.7 | D39: =D15 -> µg/L | E39: =E15 -> Testo | F39: + Testostérone
A40: =IF(ISBLANK(liste_groupe[[#This Row],[Code WF]])," ",IF(ISBLANK(liste_groupe[[#This Row],[Unité]]),CONCATENATE(liste_groupe[[#This Row],[Nom de l''échantillon donné par le client]],liste_groupe[[#This Row],[Dopage (+Testostérone / + EE2, ….)]]),CONCATENATE(liste_groupe[[#This Row],[Nom de l''échantillon donné par le client]],"-",liste_groupe[[#This Row],[Concentration]],liste_groupe[[#This Row],[Unité]],liste_groupe[[#This Row],[Dopage (+Testostérone / + EE2, ….)]]))) -> Testo-11µg/L + Testostérone | B40: =B16 -> 0 | C40: =C16 -> 11 | D40: =D16 -> µg/L | E40: =E16 -> Testo | F40: + Testostérone
A41: =IF(ISBLANK(liste_groupe[[#This Row],[Code WF]])," ",IF(ISBLANK(liste_groupe[[#This Row],[Unité]]),CONCATENATE(liste_groupe[[#This Row],[Nom de l''échantillon donné par le client]],liste_groupe[[#This Row],[Dopage (+Testostérone / + EE2, ….)]]),CONCATENATE(liste_groupe[[#This Row],[Nom de l''échantillon donné par le client]],"-",liste_groupe[[#This Row],[Concentration]],liste_groupe[[#This Row],[Unité]],liste_groupe[[#This Row],[Dopage (+Testostérone / + EE2, ….)]]))) -> Testo-33µg/L + Testostérone | B41: =B17 -> 0 | C41: =C17 -> 33 | D41: =D17 -> µg/L | E41: =E17 -> Testo | F41: + Testostérone
A42: =IF(ISBLANK(liste_groupe[[#This Row],[Code WF]])," ",IF(ISBLANK(liste_groupe[[#This Row],[Unité]]),CONCATENATE(liste_groupe[[#This Row],[Nom de l''échantillon donné par le client]],liste_groupe[[#This Row],[Dopage (+Testostérone / + EE2, ….)]]),CONCATENATE(liste_groupe[[#This Row],[Nom de l''échantillon donné par le client]],"-",liste_groupe[[#This Row],[Concentration]],liste_groupe[[#This Row],[Unité]],liste_groupe[[#This Row],[Dopage (+Testostérone / + EE2, ….)]]))) -> Testo-100µg/L + Testostérone | B42: =B18 -> 0 | C42: =C18 -> 100 | D42: =D18 -> µg/L | E42: =E18 -> Testo | F42: + Testostérone
A43: =IF(ISBLANK(liste_groupe[[#This Row],[Code WF]])," ",IF(ISBLANK(liste_groupe[[#This Row],[Unité]]),CONCATENATE(liste_groupe[[#This Row],[Nom de l''échantillon donné par le client]],liste_groupe[[#This Row],[Dopage (+Testostérone / + EE2, ….)]]),CONCATENATE(liste_groupe[[#This Row],[Nom de l''échantillon donné par le client]],"-",liste_groupe[[#This Row],[Concentration]],liste_groupe[[#This Row],[Unité]],liste_groupe[[#This Row],[Dopage (+Testostérone / + EE2, ….)]]))) -> Testo-300µg/L + Testostérone | B43: =B19 -> 0 | C43: =C19 -> 300 | D43: =D19 -> µg/L | E43: =E19 -> Testo | F43: + Testostérone
...

Sheet Feuil1
A1: Nom groupe | B1: N° de valeur | C1: file name | D1: total area | E1: mean intensity | G1: total fluorescence | I1: nbre de larves
A2: 01 EE2 0 | B2: A | C2: C:\Users\Olympus\Desktop\20190122\plaque1/@01 EE2 0/A1_1.tif | D2: 4931.616 | E2: 73.0526 | G2: 360268
A3: 01 EE2 0 | B3: A | C3: C:\Users\Olympus\Desktop\20190122\plaque1/@01 EE2 0/A1_2.tif | D3: 5234.4345 | E3: 71.1281 | G3: 372315
A4: 01 EE2 0 | B4: A | C4: C:\Users\Olympus\Desktop\20190122\plaque1/@01 EE2 0/A1_3.tif | D4: 3547.3027 | E4: 66.9878 | G4: 237626
A5: 01 EE2 0 | B5: A | C5: C:\Users\Olympus\Desktop\20190122\plaque3/@01 EE2 0/A1_3.tif | D5: 21456.8555 | E5: 67.0655 | G5: 1439015
A6: 01 EE2 0 | B6: A | C6: C:\Users\Olympus\Desktop\20190122\plaque3/@01 EE2 0/A1_2.tif | D6: 21586.6348 | E6: 66.4108 | G6: 1433586
A7: 01 EE2 0 | B7: A | C7: C:\Users\Olympus\Desktop\20190122\plaque3/@01 EE2 0/A1_1.tif | D7: 15984.4921 | E7: 69.7767 | G7: 1115346

Sheet Raw data R1
A1: Nom groupe | B1: N° de valeur | C1: file name | D1: total area | E1: mean intensity | G1: total fluorescence | I1: nbre de larves | J1: Colonne1 | L1: (Tous)
A2: =IFERROR(LEFT(RIGHT(C2,LEN(C2)-SEARCH("@",C2)),SEARCH("/",RIGHT(C2,LEN(C2)-SEARCH("@",C2)-1))),"") -> 1 | B2: =LEFT(RIGHT(RIGHT(Tableau4[[#This Row],[file name]],LEN(Tableau4[[#This Row],[file name]])-SEARCH("@",Tableau4[[#This Row],[file name]])),LEN(RIGHT(Tableau4[[#This Row],[file name]],LEN(Tableau4[[#This Row],[file name]])-SEARCH("@",Tableau4[[#This Row],[file name]])))-SEARCH("/",RIGHT(Tableau4[[#This Row],[file name]],LEN(Tableau4[[#This Row],[file name]])-SEARCH("@",Tableau4[[#This Row],[file name]])))),1) -> A | C2: C:\Users\andre\Desktop\REACTIV CEFAS\Testosterone\Testosterone/20201116_Cefas_Test6-Run1/Plate 1/@1/A10_01.tif | D2: 9473.8938 | E2: 38.9132 | G2: 368660 | K2: Filtre lignes : Enlever (vide) et Néant | L2: Filtre colonnes : Enlever (vide) et " "
A3: =IFERROR(LEFT(RIGHT(C3,LEN(C3)-SEARCH("@",C3)),SEARCH("/",RIGHT(C3,LEN(C3)-SEARCH("@",C3)-1))),"") -> 1 | B3: =LEFT(RIGHT(RIGHT(Tableau4[[#This Row],[file name]],LEN(Tableau4[[#This Row],[file name]])-SEARCH("@",Tableau4[[#This Row],[file name]])),LEN(RIGHT(Tableau4[[#This Row],[file name]],LEN(Tableau4[[#This Row],[file name]])-SEARCH("@",Tableau4[[#This Row],[file name]])))-SEARCH("/",RIGHT(Tableau4[[#This Row],[file name]],LEN(Tableau4[[#This Row],[file name]])-SEARCH("@",Tableau4[[#This Row],[file name]])))),1) -> A | C3: C:\Users\andre\Desktop\REACTIV CEFAS\Testosterone\Testosterone/20201116_Cefas_Test6-Run1/Plate 1/@1/A10_02.tif | D3: 2746.9966 | E3: 38.8819 | G3: 106808 | K3: Moyenne de total fluorescence | L3: Étiquettes de colonnes
A4: =IFERROR(LEFT(RIGHT(C4,LEN(C4)-SEARCH("@",C4)),SEARCH("/",RIGHT(C4,LEN(C4)-SEARCH("@",C4)-1))),"") -> 1 | B4: =LEFT(RIGHT(RIGHT(Tableau4[[#This Row],[file name]],LEN(Tableau4[[#This Row],[file name]])-SEARCH("@",Tableau4[[#This Row],[file name]])),LEN(RIGHT(Tableau4[[#This Row],[file name]],LEN(Tableau4[[#This Row],[file name]])-SEARCH("@",Tableau4[[#This Row],[file name]])))-SEARCH("/",RIGHT(Tableau4[[#This Row],[file name]],LEN(Tableau4[[#This Row],[file name]])-SEARCH("@",Tableau4[[#This Row],[file name]])))),1) -> A | C4: C:\Users\andre\Desktop\REACTIV CEFAS\Testosterone\Testosterone/20201116_Cefas_Test6-Run1/Plate 1/@1/A10_03.tif | D4: 4563.9078 | E4: 33.7488 | G4: 154026 | K4: Étiquettes de lignes | L4: 1 | M4: 13 | N4: 14 | O4: 15 | P4: 16 | Q4: 2 | R4: 3 | S4: 4 | T4: 5 | U4: 6 | V4: 7 | W4: 10 | X4: 11 | Y4: 12 | Z4: 17 | AA4: 18 | AB4: 19 | AC4: 20 | AD4: 21 | AE4: 8 | AF4: 9
A5: =IFERROR(LEFT(RIGHT(C5,LEN(C5)-SEARCH("@",C5)),SEARCH("/",RIGHT(C5,LEN(C5)-SEARCH("@",C5)-1))),"") -> 1 | B5: =LEFT(RIGHT(RIGHT(Tableau4[[#This Row],[file name]],LEN(Tableau4[[#This Row],[file name]])-SEARCH("@",Tableau4[[#This Row],[file name]])),LEN(RIGHT(Tableau4[[#This Row],[file name]],LEN(Tableau4[[#This Row],[file name]])-SEARCH("@",Tableau4[[#This Row],[file name]])))-SEARCH("/",RIGHT(Tableau4[[#This Row],[file name]],LEN(Tableau4[[#This Row],[file name]])-SEARCH("@",Tableau4[[#This Row],[file name]])))),1) -> B | C5: C:\Users\andre\Desktop\REACTIV CEFAS\Testosterone\Testosterone/20201116_Cefas_Test6-Run1/Plate 1/@1/B10_01.tif | D5: 3741.9718 | E5: 39.4566 | G5: 147646 | K5: A | L5: 209831.33 | M5: 1690989 | N5: 69677 | O5: 5102852.3 | P5: 50181.333 | Q5: 249277.33 | R5: 151596.67 | S5: 575607.33 | T5: 2841245.7 | U5: 3057292 | V5: 4148181 | W5: 653835.33 | X5: 2189414 | Y5: 1447905 | Z5: 2533415.7 | AA5: 2262148.3 | AB5: 1298795.7 | AC5: 2427724.7 | AD5: 3812312 | AE5: 73339.667 | AF5: 1012502.3
A6: =IFERROR(LEFT(RIGHT(C6,LEN(C6)-SEARCH("@",C6)),SEARCH("/",RIGHT(C6,LEN(C6)-SEARCH("@",C6)-1))),"") -> 1 | B6: =LEFT(RIGHT(RIGHT(Tableau4[[#This Row],[file name]],LEN(Tableau4[[#This Row],[file name]])-SEARCH("@",Tableau4[[#This Row],[file name]])),LEN(RIGHT(Tableau4[[#This Row],[file name]],LEN(Tableau4[[#This Row],[file name]])-SEARCH("@",Tableau4[[#This Row],[file name]])))-SEARCH("/",RIGHT(Tableau4[[#This Row],[file name]],LEN(Tableau4[[#This Row],[file name]])-SEARCH("@",Tableau4[[#This Row],[file name]])))),1) -> B | C6: C:\Users\andre\Desktop\REACTIV CEFAS\Testosterone\Testosterone/20201116_Cefas_Test6-Run1/Plate 1/@1/B10_02.tif | D6: 5818.4417 | E6: 39.7286 | G6: 231159 | K6: B | L6: 216753.33 | M6: 72424 | N6: 67434.667 | O6: 4121381.3 | P6: 133059.67 | Q6: 39035 | R6: 98070 | S6: 1837502.5 | T6: 1625371 | U6: 458013.33 | V6: 3753572.7 | W6: 802743 | X6: 420218.67 | Y6: 2740551 | Z6: 2744538.3 | AA6: 1332639.7 | AB6: 2069130 | AC6: 88070 | AE6: 466621.5 | AF6: 247900.33
A7: =IFERROR(LEFT(RIGHT(C7,LEN(C7)-SEARCH("@",C7)),SEARCH("/",RIGHT(C7,LEN(C7)-SEARCH("@",C7)-1))),"") -> 1 | B7: =LEFT(RIGHT(RIGHT(Tableau4[[#This Row],[file name]],LEN(Tableau4[[#This Row],[file name]])-SEARCH("@",Tableau4[[#This Row],[file name]])),LEN(RIGHT(Tableau4[[#This Row],[file name]],LEN(Tableau4[[#This Row],[file name]])-SEARCH("@",Tableau4[[#This Row],[file name]])))-SEARCH("/",RIGHT(Tableau4[[#This Row],[file name]],LEN(Tableau4[[#This Row],[file name]])-SEARCH("@",Tableau4[[#This Row],[file name]])))),1) -> B | C7: C:\Users\andre\Desktop\REACTIV CEFAS\Testosterone\Testosterone/20201116_Cefas_Test6-Run1/Plate 1/@1/B10_03.tif | D7: 7246.0147 | E7: 37.4627 | G7: 271455 | K7: C | L7: 419093.67 | M7: 1480696 | N7: 1772274.3 | O7: 3965228.7 | P7: 87741.5 | Q7: 158482.33 | R7: 200970.67 | S7: 283315.67 | T7: 2885074.7 | U7: 3176144.5 | V7: 5196171.3 | W7: 1108928.7 | X7: 2273792.3 | Z7: 582688 | AA7: 1975480 | AB7: 78235 | AC7: 2548211 | AD7: 3468173.3 | AE7: 248621.33 | AF7: 265312.33
A8: =IFERROR(LEFT(RIGHT(C8,LEN(C8)-SEARCH("@",C8)),SEARCH("/",RIGHT(C8,LEN(C8)-SEARCH("@",C8)-1))),"") -> 1 | B8: =LEFT(RIGHT(RIGHT(Tableau4[[#This Row],[file name]],LEN(Tableau4[[#This Row],[file name]])-SEARCH("@",Tableau4[[#This Row],[file name]])),LEN(RIGHT(Tableau4[[#This Row],[file name]],LEN(Tableau4[[#This Row],[file name]])-SEARCH("@",Tableau4[[#This Row],[file name]])))-SEARCH("/",RIGHT(Tableau4[[#This Row],[file name]],LEN(Tableau4[[#This Row],[file name]])-SEARCH("@",Tableau4[[#This Row],[file name]])))),1) -> C | C8: C:\Users\andre\Desktop\REACTIV CEFAS\Testosterone\Testosterone/20201116_Cefas_Test6-Run1/Plate 1/@1/C10_01.tif | D8: 14297.3603 | E8: 43.6263 | G8: 623741 | K8: D | L8: 213660.33 | M8: 1059713.5 | O8: 3489421.3 | P8: 55019.333 | Q8: 170876 | R8: 196478.67 | S8: 2692467.3 | T8: 2233452.3 | U8: 3915479.7 | V8: 4267585.3 | W8: 1739930.7 | X8: 3698322.7 | Y8: 3041877 | Z8: 1989135.7 | AA8: 2921074 | AB8: 375999.67 | AC8: 454696.67 | AD8: 2352049 | AE8: 693368 | AF8: 462879.67
A9: =IFERROR(LEFT(RIGHT(C9,LEN(C9)-SEARCH("@",C9)),SEARCH("/",RIGHT(C9,LEN(C9)-SEARCH("@",C9)-1))),"") -> 1 | B9: =LEFT(RIGHT(RIGHT(Tableau4[[#This Row],[file name]],LEN(Tableau4[[#This Row],[file name]])-SEARCH("@",Tableau4[[#This Row],[file name]])),LEN(RIGHT(Tableau4[[#This Row],[file name]],LEN(Tableau4[[#This Row],[file name]])-SEARCH("@",Tableau4[[#This Row],[file name]])))-SEARCH("/",RIGHT(Tableau4[[#This Row],[file name]],LEN(Tableau4[[#This Row],[file name]])-SEARCH("@",Tableau4[[#This Row],[file name]])))),1) -> C | C9: C:\Users\andre\Desktop\REACTIV CEFAS\Testosterone\Testosterone/20201116_Cefas_Test6-Run1/Plate 1/@1/C10_02.tif | D9: 11398.9545 | E9: 42.8577 | G9: 488533 | K9: E | L9: 297079.33 | M9: 337325.33 | N9: 378660.33 | O9: 1875780.7 | P9: 277677 | R9: 122757 | S9: 217106.33 | T9: 3019374.7 | U9: 4671148.7 | V9: 4224059 | W9: 1908427 | X9: 1352654.3 | Y9: 1577627 | Z9: 120781.33 | AA9: 2636504 | AB9: 1832268 | AC9: 195880.67 | AD9: 1029958 | AE9: 482866 | AF9: 383260
A10: =IFERROR(LEFT(RIGHT(C10,LEN(C10)-SEARCH("@",C10)),SEARCH("/",RIGHT(C10,LEN(C10)-SEARCH("@",C10)-1))),"") -> 1 | B10: =LEFT(RIGHT(RIGHT(Tableau4[[#This Row],[file name]],LEN(Tableau4[[#This Row],[file name]])-SEARCH("@",Tableau4[[#This Row],[file name]])),LEN(RIGHT(Tableau4[[#This Row],[file name]],LEN(Tableau4[[#This Row],[file name]])-SEARCH("@",Tableau4[[#This Row],[file name]])))-SEARCH("/",RIGHT(Tableau4[[#This Row],[file name]],LEN(Tableau4[[#This Row],[file name]])-SEARCH("@",Tableau4[[#This Row],[file name]])))),1) -> C | C10: C:\Users\andre\Desktop\REACTIV CEFAS\Testosterone\Testosterone/20201116_Cefas_Test6-Run1/Plate 1/@1/C10_03.tif | D10: 3893.381 | E10: 37.2444 | G10: 145007 | K10: F | L10: 125057 | M10: 2049014 | N10: 530365 | O10: 2992027.3 | P10: 32127.667 | Q10: 548231.33 | R10: 128229.33 | S10: 129245.67 | T10: 1470371.3 | U10: 3020247 | V10: 4025316.3 | W10: 272053.67 | X10: 3893013.3 | Y10: 3377832.3 | Z10: 410160.67 | AA10: 2718863 | AB10: 39453 | AC10: 338443 | AD10: 1568275.3 | AE10: 348306 | AF10: 1379154.5
A11: =IFERROR(LEFT(RIGHT(C11,LEN(C11)-SEARCH("@",C11)),SEARCH("/",RIGHT(C11,LEN(C11)-SEARCH("@",C11)-1))),"") -> 1 | B11: =LEFT(RIGHT(RIGHT(Tableau4[[#This Row],[file name]],LEN(Tableau4[[#This Row],[file name]])-SEARCH("@",Tableau4[[#This Row],[file name]])),LEN(RIGHT(Tableau4[[#This Row],[file name]],LEN(Tableau4[[#This Row],[file name]])-SEARCH("@",Tableau4[[#This Row],[file name]])))-SEARCH("/",RIGHT(Tableau4[[#This Row],[file name]],LEN(Tableau4[[#This Row],[file name]])-SEARCH("@",Tableau4[[#This Row],[file name]])))),1) -> D | C11: C:\Users\andre\Desktop\REACTIV CEFAS\Testosterone\Testosterone/20201116_Cefas_Test6-Run1/Plate 1/@1/D10_01.tif | D11: 10166.0505 | E11: 41.4787 | G11: 421675 | K11: G | L11: 104083.33 | M11: 24824 | N11: 185483.67 | O11: 3668877 | P11: 85200 | Q11: 184849.33 | R11: 666510.67 | S11: 1235312.3 | T11: 2724429.7 | V11: 5225458 | W11: 171618.67 | X11: 182470 | Y11: 2412468.3 | Z11: 442944.33 | AA11: 1241029.3 | AB11: 3218398.7 | AC11: 919097.67 | AD11: 1886696.3 | AE11: 139447.67 | AF11: 180631
A12: =IFERROR(LEFT(RIGHT(C12,LEN(C12)-SEARCH("@",C12)),SEARCH("/",RIGHT(C12,LEN(C12)-SEARCH("@",C12)-1))),"") -> 1 | B12: =LEFT(RIGHT(RIGHT(Tableau4[[#This Row],[file name]],LEN(Tableau4[[#This Row],[file name]])-SEARCH("@",Tableau4[[#This Row],[file name]])),LEN(RIGHT(Tableau4[[#This Row],[file name]],LEN(Tableau4[[#This Row],[file name]])-SEARCH("@",Tableau4[[#This Row],[file name]])))-SEARCH("/",RIGHT(Tableau4[[#This Row],[file name]],LEN(Tableau4[[#This Row],[file name]])-SEARCH("@",Tableau4[[#This Row],[file name]])))),1) -> D | C12: C:\Users\andre\Desktop\REACTIV CEFAS\Testosterone\Testosterone/20201116_Cefas_Test6-Run1/Plate 1/@1/D10_02.tif | D12: 5083.0252 | E12: 40.0809 | G12: 203732 | K12: H | L12: 83080.333 | M12: 484726 | N12: 693533.33 | O12: 3375410 | P12: 197726 | Q12: 67319.333 | R12: 154502.33 | S12: 2268053 | T12: 2656165.7 | U12: 1460508.3 | V12: 3912307.3 | W12: 2017788.3 | X12: 1695300.3 | Y12: 3572350.3 | Z12: 961787.67 | AA12: 296481 | AB12: 488208.33 | AC12: 2417097.5 | AD12: 102417.67 | AE12: 48797 | AF12: 346136
A13: =IFERROR(LEFT(RIGHT(C13,LEN(C13)-SEARCH("@",C13)),SEARCH("/",RIGHT(C13,LEN(C13)-SEARCH("@",C13)-1))),"") -> 1 | B13: =LEFT(RIGHT(RIGHT(Tableau4[[#This Row],[file name]],LEN(Tableau4[[#This Row],[file name]])-SEARCH("@",Tableau4[[#This Row],[file name]])),LEN(RIGHT(Tableau4[[#This Row],[file name]],LEN(Tableau4[[#This Row],[file name]])-SEARCH("@",Tableau4[[#This Row],[file name]])))-SEARCH("/",RIGHT(Tableau4[[#This Row],[file name]],LEN(Tableau4[[#This Row],[file name]])-SEARCH("@",Tableau4[[#This Row],[file name]])))),1) -> D | C13: C:\Users\andre\Desktop\REACTIV CEFAS\Testosterone\Testosterone/20201116_Cefas_Test6-Run1/Plate 1/@1/D10_03.tif | D13: 497.4876 | E13: 31.3043 | G13: 15574
A14: =IFERROR(LEFT(RIGHT(C14,LEN(C14)-SEARCH("@",C14)),SEARCH("/",RIGHT(C14,LEN(C14)-SEARCH("@",C14)-1))),"") -> 1 | B14: =LEFT(RIGHT(RIGHT(Tableau4[[#This Row],[file name]],LEN(Tableau4[[#This Row],[file name]])-SEARCH("@",Tableau4[[#This Row],[file name]])),LEN(RIGHT(Tableau4[[#This Row],[file name]],LEN(Tableau4[[#This Row],[file name]])-SEARCH("@",Tableau4[[#This Row],[file name]])))-SEARCH("/",RIGHT(Tableau4[[#This Row],[file name]],LEN(Tableau4[[#This Row],[file name]])-SEARCH("@",Tableau4[[#This Row],[file name]])))),1) -> E | C14: C:\Users\andre\Desktop\REACTIV CEFAS\Testosterone\Testosterone/20201116_Cefas_Test6-Run1/Plate 1/@1/E10_01.tif | D14: 7332.5343 | E14: 37.8643 | G14: 277641
A15: =IFERROR(LEFT(RIGHT(C15,LEN(C15)-SEARCH("@",C15)),SEARCH("/",RIGHT(C15,LEN(C15)-SEARCH("@",C15)-1))),"") -> 1 | B15: =LEFT(RIGHT(RIGHT(Tableau4[[#This Row],[file name]],LEN(Tableau4[[#This Row],[file name]])-SEARCH("@",Tableau4[[#This Row],[file name]])),LEN(RIGHT(Tableau4[[#This Row],[file name]],LEN(Tableau4[[#This Row],[file name]])-SEARCH("@",Tableau4[[#This Row],[file name]])))-SEARCH("/",RIGHT(Tableau4[[#This Row],[file name]],LEN(Tableau4[[#This Row],[file name]])-SEARCH("@",Tableau4[[#This Row],[file name]])))),1) -> E | C15: C:\Users\andre\Desktop\REACTIV CEFAS\Testosterone\Testosterone/20201116_Cefas_Test6-Run1/Plate 1/@1/E10_02.tif | D15: 7072.9755 | E15: 34.7034 | G15: 245456
A16: =IFERROR(LEFT(RIGHT(C16,LEN(C16)-SEARCH("@",C16)),SEARCH("/",RIGHT(C16,LEN(C16)-SEARCH("@",C16)-1))),"") -> 1 | B16: =LEFT(RIGHT(RIGHT(Tableau4[[#This Row],[file name]],LEN(Tableau4[[#This Row],[file name]])-SEARCH("@",Tableau4[[#This Row],[file name]])),LEN(RIGHT(Tableau4[[#This Row],[file name]],LEN(Tableau4[[#This Row],[file name]])-SEARCH("@",Tableau4[[#This Row],[file name]])))-SEARCH("/",RIGHT(Tableau4[[#This Row],[file name]],LEN(Tableau4[[#This Row],[file name]])-SEARCH("@",Tableau4[[#This Row],[file name]])))),1) -> E | C16: C:\Users\andre\Desktop\REACTIV CEFAS\Testosterone\Testosterone/20201116_Cefas_Test6-Run1/Plate 1/@1/E10_03.tif | D16: 10295.8298 | E16: 35.7563 | G16: 368141
A17: =IFERROR(LEFT(RIGHT(C17,LEN(C17)-SEARCH("@",C17)),SEARCH("/",RIGHT(C17,LEN(C17)-SEARCH("@",C17)-1))),"") -> 1 | B17: =LEFT(RIGHT(RIGHT(Tableau4[[#This Row],[file name]],LEN(Tableau4[[#This Row],[file name]])-SEARCH("@",Tableau4[[#This Row],[file name]])),LEN(RIGHT(Tableau4[[#This Row],[file name]],LEN(Tableau4[[#This Row],[file name]])-SEARCH("@",Tableau4[[#This Row],[file name]])))-SEARCH("/",RIGHT(Tableau4[[#This Row],[file name]],LEN(Tableau4[[#This Row],[file name]])-SEARCH("@",Tableau4[[#This Row],[file name]])))),1) -> F | C17: C:\Users\andre\Desktop\REACTIV CEFAS\Testosterone\Testosterone/20201116_Cefas_Test6-Run1/Plate 1/@1/F10_01.tif | D17: 4996.5057 | E17: 36.4719 | G17: 182232
A18: =IFERROR(LEFT(RIGHT(C18,LEN(C18)-SEARCH("@",C18)),SEARCH("/",RIGHT(C18,LEN(C18)-SEARCH("@",C18)-1))),"") -> 1 | B18: =LEFT(RIGHT(RIGHT(Tableau4[[#This Row],[file name]],LEN(Tableau4[[#This Row],[file name]])-SEARCH("@",Tableau4[[#This Row],[file name]])),LEN(RIGHT(Tableau4[[#This Row],[file name]],LEN(Tableau4[[#This Row],[file name]])-SEARCH("@",Tableau4[[#This Row],[file name]])))-SEARCH("/",RIGHT(Tableau4[[#This Row],[file name]],LEN(Tableau4[[#This Row],[file name]])-SEARCH("@",Tableau4[[#This Row],[file name]])))),1) -> F | C18: C:\Users\andre\Desktop\REACTIV CEFAS\Testosterone\Testosterone/20201116_Cefas_Test6-Run1/Plate 1/@1/F10_02.tif | D18: 2898.4059 | E18: 35.7388 | G18: 103586
A19: =IFERROR(LEFT(RIGHT(C19,LEN(C19)-SEARCH("@",C19)),SEARCH("/",RIGHT(C19,LEN(C19)-SEARCH("@",C19)-1))),"") -> 1 | B19: =LEFT(RIGHT(RIGHT(Tableau4[[#This Row],[file name]],LEN(Tableau4[[#This Row],[file name]])-SEARCH("@",Tableau4[[#This Row],[file name]])),LEN(RIGHT(Tableau4[[#This Row],[file name]],LEN(Tableau4[[#This Row],[file name]])-SEARCH("@",Tableau4[[#This Row],[file name]])))-SEARCH("/",RIGHT(Tableau4[[#This Row],[file name]],LEN(Tableau4[[#This Row],[file name]])-SEARCH("@",Tableau4[[#This Row],[file name]])))),1) -> F | C19: C:\Users\andre\Desktop\REACTIV CEFAS\Testosterone\Testosterone/20201116_Cefas_Test6-Run1/Plate 1/@1/F10_03.tif | D19: 2660.477 | E19: 33.5854 | G19: 89353
A20: =IFERROR(LEFT(RIGHT(C20,LEN(C20)-SEARCH("@",C20)),SEARCH("/",RIGHT(C20,LEN(C20)-SEARCH("@",C20)-1))),"") -> 1 | B20: =LEFT(RIGHT(RIGHT(Tableau4[[#This Row],[file name]],LEN(Tableau4[[#This Row],[file name]])-SEARCH("@",Tableau4[[#This Row],[file name]])),LEN(RIGHT(Tableau4[[#This Row],[file name]],LEN(Tableau4[[#This Row],[file name]])-SEARCH("@",Tableau4[[#This Row],[file name]])))-SEARCH("/",RIGHT(Tableau4[[#This Row],[file name]],LEN(Tableau4[[#This Row],[file name]])-SEARCH("@",Tableau4[[#This Row],[file name]])))),1) -> G | C20: C:\Users\andre\Desktop\REACTIV CEFAS\Testosterone\Testosterone/20201116_Cefas_Test6-Run1/Plate 1/@1/G10_01.tif | D20: 4412.4985 | E20: 37.0343 | G20: 163414
A21: =IFERROR(LEFT(RIGHT(C21,LEN(C21)-SEARCH("@",C21)),SEARCH("/",RIGHT(C21,LEN(C21)-SEARCH("@",C21)-1))),"") -> 1 | B21: =LEFT(RIGHT(RIGHT(Tableau4[[#This Row],[file name]],LEN(Tableau4[[#This Row],[file name]])-SEARCH("@",Tableau4[[#This Row],[file name]])),LEN(RIGHT(Tableau4[[#This Row],[file name]],LEN(Tableau4[[#This Row],[file name]])-SEARCH("@",Tableau4[[#This Row],[file name]])))-SEARCH("/",RIGHT(Tableau4[[#This Row],[file name]],LEN(Tableau4[[#This Row],[file name]])-SEARCH("@",Tableau4[[#This Row],[file name]])))),1) -> G | C21: C:\Users\andre\Desktop\REACTIV CEFAS\Testosterone\Testosterone/20201116_Cefas_Test6-Run1/Plate 1/@1/G10_02.tif | D21: 3655.4522 | E21: 40.3609 | G21: 147538
A22: =IFERROR(LEFT(RIGHT(C22,LEN(C22)-SEARCH("@",C22)),SEARCH("/",RIGHT(C22,LEN(C22)-SEARCH("@",C22)-1))),"") -> 1 | B22: =LEFT(RIGHT(RIGHT(Tableau4[[#This Row],[file name]],LEN(Tableau4[[#This Row],[file name]])-SEARCH("@",Tableau4[[#This Row],[file name]])),LEN(RIGHT(Tableau4[[#This Row],[file name]],LEN(Tableau4[[#This Row],[file name]])-SEARCH("@",Tableau4[[#This Row],[file name]])))-SEARCH("/",RIGHT(Tableau4[[#This Row],[file name]],LEN(Tableau4[[#This Row],[file name]])-SEARCH("@",Tableau4[[#This Row],[file name]])))),1) -> G | C22: C:\Users\andre\Desktop\REACTIV CEFAS\Testosterone\Testosterone/20201116_Cefas_Test6-Run1/Plate 1/@1/G10_03.tif | D22: 43.2598 | E22: 30 | G22: 1298
A23: =IFERROR(LEFT(RIGHT(C23,LEN(C23)-SEARCH("@",C23)),SEARCH("/",RIGHT(C23,LEN(C23)-SEARCH("@",C23)-1))),"") -> 1 | B23: =LEFT(RIGHT(RIGHT(Tableau4[[#This Row],[file name]],LEN(Tableau4[[#This Row],[file name]])-SEARCH("@",Tableau4[[#This Row],[file name]])),LEN(RIGHT(Tableau4[[#This Row],[file name]],LEN(Tableau4[[#This Row],[file name]])-SEARCH("@",Tableau4[[#This Row],[file name]])))-SEARCH("/",RIGHT(Tableau4[[#This Row],[file name]],LEN(Tableau4[[#This Row],[file name]])-SEARCH("@",Tableau4[[#This Row],[file name]])))),1) -> H | C23: C:\Users\andre\Desktop\REACTIV CEFAS\Testosterone\Testosterone/20201116_Cefas_Test6-Run1/Plate 1/@1/H10_01.tif | D23: 1124.7545 | E23: 32.8269 | G23: 36922
A24: =IFERROR(LEFT(RIGHT(C24,LEN(C24)-SEARCH("@",C24)),SEARCH("/",RIGHT(C24,LEN(C24)-SEARCH("@",C24)-1))),"") -> 1 | B24: =LEFT(RIGHT(RIGHT(Tableau4[[#This Row],[file name]],LEN(Tableau4[[#This Row],[file name]])-SEARCH("@",Tableau4[[#This Row],[file name]])),LEN(RIGHT(Tableau4[[#This Row],[file name]],LEN(Tableau4[[#This Row],[file name]])-SEARCH("@",Tableau4[[#This Row],[file name]])))-SEARCH("/",RIGHT(Tableau4[[#This Row],[file name]],LEN(Tableau4[[#This Row],[file name]])-SEARCH("@",Tableau4[[#This Row],[file name]])))),1) -> H | C24: C:\Users\andre\Desktop\REACTIV CEFAS\Testosterone\Testosterone/20201116_Cefas_Test6-Run1/Plate 1/@1/H10_02.tif | D24: 3071.445 | E24: 36.2113 | G24: 111221
A25: =IFERROR(LEFT(RIGHT(C25,LEN(C25)-SEARCH("@",C25)),SEARCH("/",RIGHT(C25,LEN(C25)-SEARCH("@",C25)-1))),"") -> 1 | B25: =LEFT(RIGHT(RIGHT(Tableau4[[#This Row],[file name]],LEN(Tableau4[[#This Row],[file name]])-SEARCH("@",Tableau4[[#This Row],[file name]])),LEN(RIGHT(Tableau4[[#This Row],[file name]],LEN(Tableau4[[#This Row],[file name]])-SEARCH("@",Tableau4[[#This Row],[file name]])))-SEARCH("/",RIGHT(Tableau4[[#This Row],[file name]],LEN(Tableau4[[#This Row],[file name]])-SEARCH("@",Tableau4[[#This Row],[file name]])))),1) -> H | C25: C:\Users\andre\Desktop\REACTIV CEFAS\Testosterone\Testosterone/20201116_Cefas_Test6-Run1/Plate 1/@1/H10_03.tif | D25: 2876.776 | E25: 35.1429 | G25: 101098
A26: =IFERROR(LEFT(RIGHT(C26,LEN(C26)-SEARCH("@",C26)),SEARCH("/",RIGHT(C26,LEN(C26)-SEARCH("@",C26)-1))),"") | B26: =LEFT(RIGHT(RIGHT(Tableau4[[#This Row],[file name]],LEN(Tableau4[[#This Row],[file name]])-SEARCH("@",Tableau4[[#This Row],[file name]])),LEN(RIGHT(Tableau4[[#This Row],[file name]],LEN(Tableau4[[#This Row],[file name]])-SEARCH("@",Tableau4[[#This Row],[file name]])))-SEARCH("/",RIGHT(Tableau4[[#This Row],[file name]],LEN(Tableau4[[#This Row],[file name]])-SEARCH("@",Tableau4[[#This Row],[file name]])))),1) -> #VALUE!
A27: =IFERROR(LEFT(RIGHT(C27,LEN(C27)-SEARCH("@",C27)),SEARCH("/",RIGHT(C27,LEN(C27)-SEARCH("@",C27)-1))),"") | B27: =LEFT(RIGHT(RIGHT(Tableau4[[#This Row],[file name]],LEN(Tableau4[[#This Row],[file name]])-SEARCH("@",Tableau4[[#This Row],[file name]])),LEN(RIGHT(Tableau4[[#This Row],[file name]],LEN(Tableau4[[#This Row],[file name]])-SEARCH("@",Tableau4[[#This Row],[file name]])))-SEARCH("/",RIGHT(Tableau4[[#This Row],[file name]],LEN(Tableau4[[#This Row],[file name]])-SEARCH("@",Tableau4[[#This Row],[file name]])))),1) -> #VALUE! | C27: group | E27: mean of mean fluo | F27: SD mean fluo | G27: mean of total fluo | H27: SD total fluo | I27: n fluorescent | J27: n total
A28: =IFERROR(LEFT(RIGHT(C28,LEN(C28)-SEARCH("@",C28)),SEARCH("/",RIGHT(C28,LEN(C28)-SEARCH("@",C28)-1))),"") -> 1 | B28: =LEFT(RIGHT(RIGHT(Tableau4[[#This Row],[file name]],LEN(Tableau4[[#This Row],[file name]])-SEARCH("@",Tableau4[[#This Row],[file name]])),LEN(RIGHT(Tableau4[[#This Row],[file name]],LEN(Tableau4[[#This Row],[file name]])-SEARCH("@",Tableau4[[#This Row],[file name]])))-SEARCH("/",RIGHT(Tableau4[[#This Row],[file name]],LEN(Tableau4[[#This Row],[file name]])-SEARCH("@",Tableau4[[#This Row],[file name]])))),1) | C28: C:\Users\andre\Desktop\REACTIV CEFAS\Testosterone\Testosterone/20201116_Cefas_Test6-Run1/Plate 1/@1/ | E28: 37.1034 | F28: 3.4538 | G28: 208579.833 | H28: 153416.885 | I28: 24 | J28: 24
A29: =IFERROR(LEFT(RIGHT(C29,LEN(C29)-SEARCH("@",C29)),SEARCH("/",RIGHT(C29,LEN(C29)-SEARCH("@",C29)-1))),"") | B29: =LEFT(RIGHT(RIGHT(Tableau4[[#This Row],[file name]],LEN(Tableau4[[#This Row],[file name]])-SEARCH("@",Tableau4[[#This Row],[file name]])),LEN(RIGHT(Tableau4[[#This Row],[file name]],LEN(Tableau4[[#This Row],[file name]])-SEARCH("@",Tableau4[[#This Row],[file name]])))-SEARCH("/",RIGHT(Tableau4[[#This Row],[file name]],LEN(Tableau4[[#This Row],[file name]])-SEARCH("@",Tableau4[[#This Row],[file name]])))),1) -> #VALUE!
A30: =IFERROR(LEFT(RIGHT(C30,LEN(C30)-SEARCH("@",C30)),SEARCH("/",RIGHT(C30,LEN(C30)-SEARCH("@",C30)-1))),"") | B30: =LEFT(RIGHT(RIGHT(Tableau4[[#This Row],[file name]],LEN(Tableau4[[#This Row],[file name]])-SEARCH("@",Tableau4[[#This Row],[file name]])),LEN(RIGHT(Tableau4[[#This Row],[file name]],LEN(Tableau4[[#This Row],[file name]])-SEARCH("@",Tableau4[[#This Row],[file name]])))-SEARCH("/",RIGHT(Tableau4[[#This Row],[file name]],LEN(Tableau4[[#This Row],[file name]])-SEARCH("@",Tableau4[[#This Row],[file name]])))),1) -> #VALUE!
A31: =IFERROR(LEFT(RIGHT(C31,LEN(C31)-SEARCH("@",C31)),SEARCH("/",RIGHT(C31,LEN(C31)-SEARCH("@",C31)-1))),"") | B31: =LEFT(RIGHT(RIGHT(Tableau4[[#This Row],[file name]],LEN(Tableau4[[#This Row],[file name]])-SEARCH("@",Tableau4[[#This Row],[file name]])),LEN(RIGHT(Tableau4[[#This Row],[file name]],LEN(Tableau4[[#This Row],[file name]])-SEARCH("@",Tableau4[[#This Row],[file name]])))-SEARCH("/",RIGHT(Tableau4[[#This Row],[file name]],LEN(Tableau4[[#This Row],[file name]])-SEARCH("@",Tableau4[[#This Row],[file name]])))),1) -> #VALUE!
A32: =IFERROR(LEFT(RIGHT(C32,LEN(C32)-SEARCH("@",C32)),SEARCH("/",RIGHT(C32,LEN(C32)-SEARCH("@",C32)-1))),"") | B32: =LEFT(RIGHT(RIGHT(Tableau4[[#This Row],[file name]],LEN(Tableau4[[#This Row],[file name]])-SEARCH("@",Tableau4[[#This Row],[file name]])),LEN(RIGHT(Tableau4[[#This Row],[file name]],LEN(Tableau4[[#This Row],[file name]])-SEARCH("@",Tableau4[[#This Row],[file name]])))-SEARCH("/",RIGHT(Tableau4[[#This Row],[file name]],LEN(Tableau4[[#This Row],[file name]])-SEARCH("@",Tableau4[[#This Row],[file name]])))),1) -> #VALUE!
A33: =IFERROR(LEFT(RIGHT(C33,LEN(C33)-SEARCH("@",C33)),SEARCH("/",RIGHT(C33,LEN(C33)-SEARCH("@",C33)-1))),"") | B33: =LEFT(RIGHT(RIGHT(Tableau4[[#This Row],[file name]],LEN(Tableau4[[#This Row],[file name]])-SEARCH("@",Tableau4[[#This Row],[file name]])),LEN(RIGHT(Tableau4[[#This Row],[file name]],LEN(Tableau4[[#This Row],[file name]])-SEARCH("@",Tableau4[[#This Row],[file name]])))-SEARCH("/",RIGHT(Tableau4[[#This Row],[file name]],LEN(Tableau4[[#This Row],[file name]])-SEARCH("@",Tableau4[[#This Row],[file name]])))),1) -> #VALUE!
A34: =IFERROR(LEFT(RIGHT(C34,LEN(C34)-SEARCH("@",C34)),SEARCH("/",RIGHT(C34,LEN(C34)-SEARCH("@",C34)-1))),"") | B34: =LEFT(RIGHT(RIGHT(Tableau4[[#This Row],[file name]],LEN(Tableau4[[#This Row],[file name]])-SEARCH("@",Tableau4[[#This Row],[file name]])),LEN(RIGHT(Tableau4[[#This Row],[file name]],LEN(Tableau4[[#This Row],[file name]])-SEARCH("@",Tableau4[[#This Row],[file name]])))-SEARCH("/",RIGHT(Tableau4[[#This Row],[file name]],LEN(Tableau4[[#This Row],[file name]])-SEARCH("@",Tableau4[[#This Row],[file name]])))),1) -> #VALUE! | C34: file name | D34: total area | E34: mean intensity | G34: total fluorescence
A35: =IFERROR(LEFT(RIGHT(C35,LEN(C35)-SEARCH("@",C35)),SEARCH("/",RIGHT(C35,LEN(C35)-SEARCH("@",C35)-1))),"") -> 13 | B35: =LEFT(RIGHT(RIGHT(Tableau4[[#This Row],[file name]],LEN(Tableau4[[#This Row],[file name]])-SEARCH("@",Tableau4[[#This Row],[file name]])),LEN(RIGHT(Tableau4[[#This Row],[file name]],LEN(Tableau4[[#This Row],[file name]])-SEARCH("@",Tableau4[[#This Row],[file name]])))-SEARCH("/",RIGHT(Tableau4[[#This Row],[file name]],LEN(Tableau4[[#This Row],[file name]])-SEARCH("@",Tableau4[[#This Row],[file name]])))),1) -> A | C35: C:\Users\andre\Desktop\REACTIV CEFAS\Testosterone\Testosterone/20201116_Cefas_Test6-Run1/Plate 1/@13/A8_01.tif | D35: 54658.7437 | E35: 36.9577 | G35: 2020059
A36: =IFERROR(LEFT(RIGHT(C36,LEN(C36)-SEARCH("@",C36)),SEARCH("/",RIGHT(C36,LEN(C36)-SEARCH("@",C36)-1))),"") -> 13 | B36: =LEFT(RIGHT(RIGHT(Tableau4[[#This Row],[file name]],LEN(Tableau4[[#This Row],[file name]])-SEARCH("@",Tableau4[[#This Row],[file name]])),LEN(RIGHT(Tableau4[[#This Row],[file name]],LEN(Tableau4[[#This Row],[file name]])-SEARCH("@",Tableau4[[#This Row],[file name]])))-SEARCH("/",RIGHT(Tableau4[[#This Row],[file name]],LEN(Tableau4[[#This Row],[file name]])-SEARCH("@",Tableau4[[#This Row],[file name]])))),1) -> A | C36: C:\Users\andre\Desktop\REACTIV CEFAS\Testosterone\Testosterone/20201116_Cefas_Test6-Run1/Plate 1/@13/A8_02.tif | D36: 38782.4011 | E36: 34.9927 | G36: 1357103
A37: =IFERROR(LEFT(RIGHT(C37,LEN(C37)-SEARCH("@",C37)),SEARCH("/",RIGHT(C37,LEN(C37)-SEARCH("@",C37)-1))),"") -> 13 | B37: =LEFT(RIGHT(RIGHT(Tableau4[[#This Row],[file name]],LEN(Tableau4[[#This Row],[file name]])-SEARCH("@",Tableau4[[#This Row],[file name]])),LEN(RIGHT(Tableau4[[#This Row],[file name]],LEN(Tableau4[[#This Row],[file name]])-SEARCH("@",Tableau4[[#This Row],[file name]])))-SEARCH("/",RIGHT(Tableau4[[#This Row],[file name]],LEN(Tableau4[[#This Row],[file name]])-SEARCH("@",Tableau4[[#This Row],[file name]])))),1) -> A | C37: C:\Users\andre\Desktop\REACTIV CEFAS\Testosterone\Testosterone/20201116_Cefas_Test6-Run1/Plate 1/@13/A8_03.tif | D37: 47758.8073 | E37: 35.5077 | G37: 1695805
A38: =IFERROR(LEFT(RIGHT(C38,LEN(C38)-SEARCH("@",C38)),SEARCH("/",RIGHT(C38,LEN(C38)-SEARCH("@",C38)-1))),"") -> 13 | B38: =LEFT(RIGHT(RIGHT(Tableau4[[#This Row],[file name]],LEN(Tableau4[[#This Row],[file name]])-SEARCH("@",Tableau4[[#This Row],[file name]])),LEN(RIGHT(Tableau4[[#This Row],[file name]],LEN(Tableau4[[#This Row],[file name]])-SEARCH("@",Tableau4[[#This Row],[file name]])))-SEARCH("/",RIGHT(Tableau4[[#This Row],[file name]],LEN(Tableau4[[#This Row],[file name]])-SEARCH("@",Tableau4[[#This Row],[file name]])))),1) -> B | C38: C:\Users\andre\Desktop\REACTIV CEFAS\Testosterone\Testosterone/20201116_Cefas_Test6-Run1/Plate 1/@13/B8_01.tif | D38: 994.9752 | E38: 31.6957 | G38: 31536
A39: =IFERROR(LEFT(RIGHT(C39,LEN(C39)-SEARCH("@",C39)),SEARCH("/",RIGHT(C39,LEN(C39)-SEARCH("@",C39)-1))),"") -> 13 | B39: =LEFT(RIGHT(RIGHT(Tableau4[[#This Row],[file name]],LEN(Tableau4[[#This Row],[file name]])-SEARCH("@",Tableau4[[#This Row],[file name]])),LEN(RIGHT(Tableau4[[#This Row],[file name]],LEN(Tableau4[[#This Row],[file name]])-SEARCH("@",Tableau4[[#This Row],[file name]])))-SEARCH("/",RIGHT(Tableau4[[#This Row],[file name]],LEN(Tableau4[[#This Row],[file name]])-SEARCH("@",Tableau4[[#This Row],[file name]])))),1) -> B | C39: C:\Users\andre\Desktop\REACTIV CEFAS\Testosterone\Testosterone/20201116_Cefas_Test6-Run1/Plate 1/@13/B8_02.tif | D39: 1427.573 | E39: 31.1061 | G39: 44406
A40: =IFERROR(LEFT(RIGHT(C40,LEN(C40)-SEARCH("@",C40)),SEARCH("/",RIGHT(C40,LEN(C40)-SEARCH("@",C40)-1))),"") -> 13 | B40: =LEFT(RIGHT(RIGHT(Tableau4[[#This Row],[file name]],LEN(Tableau4[[#This Row],[file name]])-SEARCH("@",Tableau4[[#This Row],[file name]])),LEN(RIGHT(Tableau4[[#This Row],[file name]],LEN(Tableau4[[#This Row],[file name]])-SEARCH("@",Tableau4[[#This Row],[file name]])))-SEARCH("/",RIGHT(Tableau4[[#This Row],[file name]],LEN(Tableau4[[#This Row],[file name]])-SEARCH("@",Tableau4[[#This Row],[file name]])))),1) -> B | C40: C:\Users\andre\Desktop\REACTIV CEFAS\Testosterone\Testosterone/20201116_Cefas_Test6-Run1/Plate 1/@13/B8_03.tif | D40: 4455.7583 | E40: 31.7184 | G40: 141330
...

Sheet R1
A1: 3. Expérimentateur 1 : copier et coller les valeurs des intensités totales de fluorescences obtenues dans le fichier raw data lors du traitement des images.
A3: R1 | B3: Non dopé | AE3: avec testo
A4: Noms des groupes | B4: ='Page de garde'!A7 -> Témoin solvant | C4: ='Page de garde'!A9 -> EE2-33,8ng/L | D4: ='Page de garde'!A10 -> EE2-50,6ng/L | E4: ='Page de garde'!A11 -> EE2-76ng/L | F4: ='Page de garde'!A12 -> EE2-114ng/L | G4: ='Page de garde'!A13 -> EE2-170,9ng/L | H4: ='Page de garde'!A14 -> EE2-488ng/L | I4: Testo-3.7µg/L | J4: Testo-11µg/L | K4: Testo-33µg/L | L4: Testo-100µg/L | M4: Testo-300µg/L | N4: ='Page de garde'!A20 | O4: ='Page de garde'!A21 | P4: ='Page de garde'!A22 | Q4: ='Page de garde'!A23 | R4: ='Page de garde'!A24 | S4: ='Page de garde'!A25 | T4: ='Page de garde'!A26 | U4: ='Page de garde'!A27 | V4: ='Page de garde'!A28 | W4: ='Page de garde'!A29 | X4: ='Page de garde'!A30 | Y4: ='Page de garde'!A31 | Z4: ='Page de garde'!A32 | AA4: ='Page de garde'!A33 | AB4: ='Page de garde'!A34 | AC4: ='Page de garde'!A35 | AE4: ='Page de garde'!A36 -> Testo -30µg/L | AF4: ='Page de garde'!A37 -> Testo 30µg/L + EE2 -64ng/L | AG4: ='Page de garde'!A38 -> Testo 30µg/L + FAD-10mg/L | AH4: ='Page de garde'!A39 -> Testo-3,7µg/L + Testostérone | AI4: ='Page de garde'!A40 -> Testo-11µg/L + Testostérone | AJ4: ='Page de garde'!A41 -> Testo-33µg/L + Testostérone | AK4: ='Page de garde'!A42 -> Testo-100µg/L + Testostérone | AL4: ='Page de garde'!A43 -> Testo-300µg/L + Testostérone | AM4: ='Page de garde'!A44 -> 0-00 + Testostérone | AN4: ='Page de garde'!A45 -> 0-00 + Testostérone | AO4: ='Page de garde'!A46 -> 0-00 + Testostérone | AP4: ='Page de garde'!A47 -> 0-00 + Testostérone | AQ4: ='Page de garde'!A48 -> 0-00 + Testostérone | AR4: ='Page de garde'!A49 -> 0-00 + Testostérone | AS4: ='Page de garde'!A50 -> 0-00 + Testostérone | AT4: ='Page de garde'!A51 -> 0-00 + Testostérone | AU4: ='Page de garde'!A52 -> 0-00 + Testostérone | AV4: ='Page de garde'!A53 -> 0-00 + Testostérone | AW4: ='Page de garde'!A54 -> 0-00 + Testostérone | AX4: ='Page de garde'!A55 -> 0-00 + Testostérone | AY4: ='Page de garde'!A56 -> 0-00 + Testostérone | AZ4: ='Page de garde'!A57 -> 0-00 + Testostérone | BA4: ='Page de garde'!A58 -> 0-00 + Testostérone
A5: Données brutes | B5: 209831.33 | C5: 249277.33 | D5: 151596.67 | E5: 575607.33 | F5: 2841245.7 | G5: 3057292 | H5: 4148181 | I5: 73339.667 | J5: 1012502.3 | K5: 653835.33 | L5: 2189414 | M5: 1447905 | AE5: 1690989 | AF5: 5102852.3 | AG5: 50181.333 | AH5: 2533415.7 | AI5: 2262148.3 | AJ5: 1298795.7 | AK5: 2427724.7 | AL5: 3812312
B6: 216753.33 | C6: 39035 | D6: 98070 | E6: 1837502.5 | F6: 1625371 | G6: 458013.33 | H6: 3753572.7 | I6: 466621.5 | J6: 247900.33 | K6: 802743 | L6: 420218.67 | M6: 2740551 | AE6: 72424 | AF6: 4121381.3 | AG6: 133059.67 | AH6: 2744538.3 | AI6: 1332639.7 | AJ6: 2069130 | AK6: 88070
B7: 419093.67 | C7: 158482.33 | D7: 200970.67 | E7: 283315.67 | F7: 2885074.7 | G7: 3176144.5 | H7: 5196171.3 | I7: 248621.33 | J7: 265312.33 | K7: 1108928.7 | L7: 2273792.3 | AE7: 1480696 | AF7: 3965228.7 | AG7: 87741.5 | AH7: 582688 | AI7: 1975480 | AJ7: 78235 | AK7: 2548211 | AL7: 3468173.3
B8: 213660.33 | C8: 170876 | D8: 196478.67 | E8: 2692467.3 | F8: 2233452.3 | G8: 3915479.7 | H8: 4267585.3 | I8: 693368 | J8: 462879.67 | K8: 1739930.7 | L8: 3698322.7 | M8: 3041877 | AE8: 1059713.5 | AF8: 3489421.3 | AG8: 55019.333 | AH8: 1989135.7 | AI8: 2921074 | AJ8: 375999.67 | AK8: 454696.67 | AL8: 2352049
B9: 297079.33 | D9: 122757 | E9: 217106.33 | F9: 3019374.7 | G9: 4671148.7 | H9: 4224059 | I9: 482866 | J9: 383260 | K9: 1908427 | L9: 1352654.3 | M9: 1577627 | AE9: 337325.33 | AF9: 1875780.7 | AG9: 277677 | AH9: 120781.33 | AI9: 2636504 | AJ9: 1832268 | AK9: 195880.67 | AL9: 1029958
B10: 125057 | C10: 548231.33 | D10: 128229.33 | E10: 129245.67 | F10: 1470371.3 | G10: 3020247 | H10: 4025316.3 | I10: 348306 | J10: 1379154.5 | K10: 272053.67 | L10: 3893013.3 | M10: 3377832.3 | AE10: 2049014 | AF10: 2992027.3 | AG10: 32127.667 | AH10: 410160.67 | AI10: 2718863 | AJ10: 39453 | AK10: 338443 | AL10: 1568275.3
B11: 104083.33 | C11: 184849.33 | D11: 666510.67 | E11: 1235312.3 | F11: 2724429.7 | H11: 5225458 | I11: 139447.67 | J11: 180631 | K11: 171618.67 | L11: 182470 | M11: 2412468.3 | AE11: 24824 | AF11: 3668877 | AG11: 85200 | AH11: 442944.33 | AI11: 1241029.3 | AJ11: 3218398.7 | AK11: 919097.67 | AL11: 1886696.3
B12: 83080.333 | C12: 67319.333 | D12: 154502.33 | E12: 2268053 | F12: 2656165.7 | G12: 1460508.3 | H12: 3912307.3 | I12: 48797 | J12: 346136 | K12: 2017788.3 | L12: 1695300.3 | M12: 3572350.3 | AE12: 484726 | AF12: 3375410 | AG12: 197726 | AH12: 961787.67 | AI12: 296481 | AJ12: 488208.33 | AK12: 2417097.5 | AL12: 102417.67
AE13: 69677
AE14: 67434.667
AE15: 1772274.3
AE17: 378660.33
AE18: 530365
AE19: 185483.67
AE20: 693533.33
A22: =A4 -> Noms des groupes | B22: =B4 -> Témoin solvant | C22: =C4 -> EE2-33,8ng/L | D22: =D4 -> EE2-50,6ng/L | E22: =E4 -> EE2-76ng/L | F22: =F4 -> EE2-114ng/L | G22: =G4 -> EE2-170,9ng/L | H22: =H4 -> EE2-488ng/L | ... AC22: =AC4 | AD22: Nom des groupes | AE22: =AE4 -> Testo -30µg/L | AF22: =AF4 -> Testo 30µg/L + EE2 -64ng/L | AG22: =AG4 -> Testo 30µg/L + FAD-10mg/L | AH22: =AH4 -> Testo-3,7µg/L + Testostérone | AI22: =AI4 -> Testo-11µg/L + Testostérone | AJ22: =AJ4 -> Testo-33µg/L + Testostérone | AK22: =AK4 -> Testo-100µg/L + Testostérone | AL22: =AL4 -> Testo-300µg/L + Testostérone | ... BA22: =BA4 -> 0-00 + Testostérone
A23: mean | B23: =AVERAGE(B5:B20) -> 208579.83 | C23: =AVERAGE(C5:C20) -> 202581.52 | D23: =AVERAGE(D5:D20) -> 214889.42 | E23: =AVERAGE(E5:E20) -> 1154826.3 | F23: =AVERAGE(F5:F20) -> 2431935.6 | G23: =AVERAGE(G5:G20) -> 2822690.5 | H23: =AVERAGE(H5:H20) -> 4344081.4 | I23: =AVERAGE(I5:I20) -> 312670.9 | ... AC23: =AVERAGE(AC5:AC20) -> #DIV/0! | AD23: mean | AE23: =AVERAGE(AE5:AE20) -> 726476.01 | AF23: =AVERAGE(AF5:AF20) -> 3573872.3 | AG23: =AVERAGE(AG5:AG20) -> 114841.56 | AH23: =AVERAGE(AH5:AH20) -> 1223181.5 | AI23: =AVERAGE(AI5:AI20) -> 1923027.4 | AJ23: =AVERAGE(AJ5:AJ20) -> 1175061 | AK23: =AVERAGE(AK5:AK20) -> 1173652.6 | AL23: =AVERAGE(AL5:AL20) -> 2031411.7 | ... BA23: =AVERAGE(BA5:BA20) -> #DIV/0!
A24: SD | B24: =STDEV(B5:B20) -> 110768.82 | C24: =STDEV(C5:C20) -> 168306.28 | D24: =STDEV(D5:D20) -> 185854.07 | E24: =STDEV(E5:E20) -> 1007280.5 | F24: =STDEV(F5:F20) -> 593817.46 | G24: =STDEV(G5:G20) -> 1430455.7 | H24: =STDEV(H5:H20) -> 560389.73 | I24: =STDEV(I5:I20) -> 226742.4 | ... AC24: =STDEV(AC5:AC20) -> #DIV/0! | AD24: SD | AE24: =STDEV(AE5:AE20) -> 702133.27 | AF24: =STDEV(AF5:AF20) -> 931075.4 | AG24: =STDEV(AG5:AG20) -> 84457.409 | AH24: =STDEV(AH5:AH20) -> 1040710.2 | AI24: =STDEV(AI5:AI20) -> 903610.75 | AJ24: =STDEV(AJ5:AJ20) -> 1135449.4 | AK24: =STDEV(AK5:AK20) -> 1096882.7 | AL24: =STDEV(AL5:AL20) -> 1310093.1 | ... BA24: =STDEV(BA5:BA20) -> #DIV/0!
B26: Non dopé | AE26: avec testo
A27: Noms des groupes | B27: =B4 -> Témoin solvant | C27: =C4 -> EE2-33,8ng/L | D27: =D4 -> EE2-50,6ng/L | E27: =E4 -> EE2-76ng/L | F27: =F4 -> EE2-114ng/L | G27: =G4 -> EE2-170,9ng/L | H27: =H4 -> EE2-488ng/L | I27: =I4 -> Testo-3.7µg/L | ... AC27: =AC4 | AE27: =AE4 -> Testo -30µg/L | AF27: =AF4 -> Testo 30µg/L + EE2 -64ng/L | AG27: =AG4 -> Testo 30µg/L + FAD-10mg/L | AH27: =AH4 -> Testo-3,7µg/L + Testostérone | AI27: =AI4 -> Testo-11µg/L + Testostérone | AJ27: =AJ4 -> Testo-33µg/L + Testostérone | AK27: =AK4 -> Testo-100µg/L + Testostérone | AL27: =AL4 -> Testo-300µg/L + Testostérone | ... BA27: =BA4 -> 0-00 + Testostérone
A28: Données normalisées sur la moyenne du groupe "Testo" | B28: =IF(B5="","",(B5/$AE$23)) -> 0.2888345 | C28: =IF(C5="","",(C5/$AE$23)) -> 0.34313223 | D28: =IF(D5="","",(D5/$AE$23)) -> 0.20867402 | E28: =IF(E5="","",(E5/$AE$23)) -> 0.79232807 | F28: =IF(F5="","",(F5/$AE$23)) -> 3.9109972 | G28: =IF(G5="","",(G5/$AE$23)) -> 4.2083867 | H28: =IF(H5="","",(H5/$AE$23)) -> 5.7100041 | I28: =IF(I5="","",(I5/$AE$23)) -> 0.10095263 | ... AC28: =IF(AC5="","",(AC5/$AE$23)) | AE28: =IF(AE5="","",(AE5/$AE$23)) -> 2.3276598 | AF28: =IF(AF5="","",(AF5/$AE$23)) -> 7.0241168 | AG28: =IF(AG5="","",(AG5/$AE$23)) -> 0.069075004 | AH28: =IF(AH5="","",(AH5/$AE$23)) -> 3.4872668 | AI28: =IF(AI5="","",(AI5/$AE$23)) -> 3.1138652 | AJ28: =IF(AJ5="","",(AJ5/$AE$23)) -> 1.7878026 | AK28: =IF(AK5="","",(AK5/$AE$23)) -> 3.3417823 | AL28: =IF(AL5="","",(AL5/$AE$23)) -> 5.2476778 | ... BA28: =IF(BA5="","",(BA5/$AE$23))
B29: =IF(B6="","",(B6/$AE$23)) -> 0.29836269 | C29: =IF(C6="","",(C6/$AE$23)) -> 0.053731988 | D29: =IF(D6="","",(D6/$AE$23)) -> 0.13499413 | E29: =IF(E6="","",(E6/$AE$23)) -> 2.5293368 | F29: =IF(F6="","",(F6/$AE$23)) -> 2.2373361 | G29: =IF(G6="","",(G6/$AE$23)) -> 0.63045899 | H29: =IF(H6="","",(H6/$AE$23)) -> 5.1668226 | I29: =IF(I6="","",(I6/$AE$23)) -> 0.6423082 | ... AC29: =IF(AC6="","",(AC6/$AE$23)) | AE29: =IF(AE6="","",(AE6/$AE$23)) -> 0.099692211 | AF29: =IF(AF6="","",(AF6/$AE$23)) -> 5.6731141 | AG29: =IF(AG6="","",(AG6/$AE$23)) -> 0.18315769 | AH29: =IF(AH6="","",(AH6/$AE$23)) -> 3.7778788 | AI29: =IF(AI6="","",(AI6/$AE$23)) -> 1.8343891 | AJ29: =IF(AJ6="","",(AJ6/$AE$23)) -> 2.8481739 | AK29: =IF(AK6="","",(AK6/$AE$23)) -> 0.12122905 | AL29: =IF(AL6="","",(AL6/$AE$23)) | ... BA29: =IF(BA6="","",(BA6/$AE$23))
B30: =IF(B7="","",(B7/$AE$23)) -> 0.57688576 | C30: =IF(C7="","",(C7/$AE$23)) -> 0.21815219 | D30: =IF(D7="","",(D7/$AE$23)) -> 0.27663772 | E30: =IF(E7="","",(E7/$AE$23)) -> 0.38998627 | F30: =IF(F7="","",(F7/$AE$23)) -> 3.9713282 | G30: =IF(G7="","",(G7/$AE$23)) -> 4.3719881 | H30: =IF(H7="","",(H7/$AE$23)) -> 7.1525711 | I30: =IF(I7="","",(I7/$AE$23)) -> 0.34222924 | ... AC30: =IF(AC7="","",(AC7/$AE$23)) | AE30: =IF(AE7="","",(AE7/$AE$23)) -> 2.0381898 | AF30: =IF(AF7="","",(AF7/$AE$23)) -> 5.4581688 | AG30: =IF(AG7="","",(AG7/$AE$23)) -> 0.12077687 | AH30: =IF(AH7="","",(AH7/$AE$23)) -> 0.80207466 | AI30: =IF(AI7="","",(AI7/$AE$23)) -> 2.7192639 | AJ30: =IF(AJ7="","",(AJ7/$AE$23)) -> 0.1076911 | AK30: =IF(AK7="","",(AK7/$AE$23)) -> 3.5076327 | AL30: =IF(AL7="","",(AL7/$AE$23)) -> 4.7739681 | ... BA30: =IF(BA7="","",(BA7/$AE$23))
B31: =IF(B8="","",(B8/$AE$23)) -> 0.29410515 | C31: =IF(C8="","",(C8/$AE$23)) -> 0.23521217 | D31: =IF(D8="","",(D8/$AE$23)) -> 0.27045445 | E31: =IF(E8="","",(E8/$AE$23)) -> 3.7062027 | F31: =IF(F8="","",(F8/$AE$23)) -> 3.0743649 | G31: =IF(G8="","",(G8/$AE$23)) -> 5.3896889 | H31: =IF(H8="","",(H8/$AE$23)) -> 5.8743651 | I31: =IF(I8="","",(I8/$AE$23)) -> 0.95442656 | ... AC31: =IF(AC8="","",(AC8/$AE$23)) | AE31: =IF(AE8="","",(AE8/$AE$23)) -> 1.4587041 | AF31: =IF(AF8="","",(AF8/$AE$23)) -> 4.8032162 | AG31: =IF(AG8="","",(AG8/$AE$23)) -> 0.075734549 | AH31: =IF(AH8="","",(AH8/$AE$23)) -> 2.738061 | AI31: =IF(AI8="","",(AI8/$AE$23)) -> 4.0208816 | AJ31: =IF(AJ8="","",(AJ8/$AE$23)) -> 0.51756653 | AK31: =IF(AK8="","",(AK8/$AE$23)) -> 0.62589357 | AL31: =IF(AL8="","",(AL8/$AE$23)) -> 3.2376141 | ... BA31: =IF(BA8="","",(BA8/$AE$23))
B32: =IF(B9="","",(B9/$AE$23)) -> 0.40893206 | C32: =IF(C9="","",(C9/$AE$23)) | D32: =IF(D9="","",(D9/$AE$23)) -> 0.16897599 | E32: =IF(E9="","",(E9/$AE$23)) -> 0.29884859 | F32: =IF(F9="","",(F9/$AE$23)) -> 4.1561932 | G32: =IF(G9="","",(G9/$AE$23)) -> 6.4298732 | H32: =IF(H9="","",(H9/$AE$23)) -> 5.8144508 | I32: =IF(I9="","",(I9/$AE$23)) -> 0.66466888 | ... AC32: =IF(AC9="","",(AC9/$AE$23)) | AE32: =IF(AE9="","",(AE9/$AE$23)) -> 0.464331 | AF32: =IF(AF9="","",(AF9/$AE$23)) -> 2.582027 | AG32: =IF(AG9="","",(AG9/$AE$23)) -> 0.3822246 | AH32: =IF(AH9="","",(AH9/$AE$23)) -> 0.16625646 | AI32: =IF(AI9="","",(AI9/$AE$23)) -> 3.6291687 | AJ32: =IF(AJ9="","",(AJ9/$AE$23)) -> 2.5221315 | AK32: =IF(AK9="","",(AK9/$AE$23)) -> 0.26963129 | AL32: =IF(AL9="","",(AL9/$AE$23)) -> 1.4177454 | ... BA32: =IF(BA9="","",(BA9/$AE$23))
B33: =IF(B10="","",(B10/$AE$23)) -> 0.17214195 | C33: =IF(C10="","",(C10/$AE$23)) -> 0.75464479 | D33: =IF(D10="","",(D10/$AE$23)) -> 0.1765087 | E33: =IF(E10="","",(E10/$AE$23)) -> 0.17790769 | F33: =IF(F10="","",(F10/$AE$23)) -> 2.0239778 | G33: =IF(G10="","",(G10/$AE$23)) -> 4.157394 | H33: =IF(H10="","",(H10/$AE$23)) -> 5.5408799 | I33: =IF(I10="","",(I10/$AE$23)) -> 0.47944598 | ... AC33: =IF(AC10="","",(AC10/$AE$23)) | AE33: =IF(AE10="","",(AE10/$AE$23)) -> 2.820484 | AF33: =IF(AF10="","",(AF10/$AE$23)) -> 4.1185494 | AG33: =IF(AG10="","",(AG10/$AE$23)) -> 0.044223988 | AH33: =IF(AH10="","",(AH10/$AE$23)) -> 0.56458942 | AI33: =IF(AI10="","",(AI10/$AE$23)) -> 3.7425365 | AJ33: =IF(AJ10="","",(AJ10/$AE$23)) -> 0.054307368 | AK33: =IF(AK10="","",(AK10/$AE$23)) -> 0.46586948 | AL33: =IF(AL10="","",(AL10/$AE$23)) -> 2.1587435 | ... BA33: =IF(BA10="","",(BA10/$AE$23))
