Workbook

Sheet Page de garde
A1: 1. Expérimentateur 1 : copier et coller le n° de prestation et renseigner la date de réalisation de chaque réplica ainsi que le visa de l'expérimentateur.
A2: R1 | B2: Numéro d'expérience : | E2: Date de réalisation :
A3: R2 | B3: Numéro d'expérience : | E3: Date de réalisation :
A4: R3 | B4: Numéro d'expérience : | E4: Date de réalisation :
A5: 2. Expérimentateur 1 : copier et coller la dilution appliquée et le nom donné pour chaque des échantillons par le client. Conserver la mise en forme de l'exemple en italique. Ne pas remplir la colonne "nom sur graphique".
A6: Nom sur le graphique | B6: Code WF | C6: Concentration | D6: Unité | E6: Nom de l'échantillon donné par le client | F6: Dopage (+Testostérone / + EE2, ….)
A7: =IF(ISBLANK(liste_groupe[[#This Row],[Code WF]])," ",IF(ISBLANK(liste_groupe[[#This Row],[Unité]]),CONCATENATE(liste_groupe[[#This Row],[Nom de l''échantillon donné par le client]],liste_groupe[[#This Row],[Dopage (+Testostérone / + EE2, ….)]]),CONCATENATE(liste_groupe[[#This Row],[Nom de l''échantillon donné par le client]],"-",liste_groupe[[#This Row],[Concentration]],liste_groupe[[#This Row],[Unité]],liste_groupe[[#This Row],[Dopage (+Testostérone / + EE2, ….)]]))) -> Témoin solvant | B7: Témoin | E7: Témoin solvant
A8: =IF(ISBLANK(liste_groupe[[#This Row],[Code WF]])," ",IF(ISBLANK(liste_groupe[[#This Row],[Unité]]),CONCATENATE(liste_groupe[[#This Row],[Nom de l''échantillon donné par le client]],liste_groupe[[#This Row],[Dopage (+Testostérone / + EE2, ….)]]),CONCATENATE(liste_groupe[[#This Row],[Nom de l''échantillon donné par le client]],"-",liste_groupe[[#This Row],[Concentration]],liste_groupe[[#This Row],[Unité]],liste_groupe[[#This Row],[Dopage (+Testostérone / + EE2, ….)]]))) -> EE2-22,5ng/L | B8: Témoin | C8: 22.5 | D8: ng/L | E8: EE2
A9: =IF(ISBLANK(liste_groupe[[#This Row],[Code WF]])," ",IF(ISBLANK(liste_groupe[[#This Row],[Unité]]),CONCATENATE(liste_groupe[[#This Row],[Nom de l''échantillon donné par le client]],liste_groupe[[#This Row],[Dopage (+Testostérone / + EE2, ….)]]),CONCATENATE(liste_groupe[[#This Row],[Nom de l''échantillon donné par le client]],"-",liste_groupe[[#This Row],[Concentration]],liste_groupe[[#This Row],[Unité]],liste_groupe[[#This Row],[Dopage (+Testostérone / + EE2, ….)]]))) -> EE2-33,8ng/L | B9: Témoin | C9: 33.8 | D9: ng/L | E9: EE2
A10: =IF(ISBLANK(liste_groupe[[#This Row],[Code WF]])," ",IF(ISBLANK(liste_groupe[[#This Row],[Unité]]),CONCATENATE(liste_groupe[[#This Row],[Nom de l''échantillon donné par le client]],liste_groupe[[#This Row],[Dopage (+Testostérone / + EE2, ….)]]),CONCATENATE(liste_groupe[[#This Row],[Nom de l''échantillon donné par le client]],"-",liste_groupe[[#This Row],[Concentration]],liste_groupe[[#This Row],[Unité]],liste_groupe[[#This Row],[Dopage (+Testostérone / + EE2, ….)]]))) -> EE2-50,6ng/L | B10: Témoin | C10: 50.6 | D10: ng/L | E10: EE2
A11: =IF(ISBLANK(liste_groupe[[#This Row],[Code WF]])," ",IF(ISBLANK(liste_groupe[[#This Row],[Unité]]),CONCATENATE(liste_groupe[[#This Row],[Nom de l''échantillon donné par le client]],liste_groupe[[#This Row],[Dopage (+Testostérone / + EE2, ….)]]),CONCATENATE(liste_groupe[[#This Row],[Nom de l''échantillon donné par le client]],"-",liste_groupe[[#This Row],[Concentration]],liste_groupe[[#This Row],[Unité]],liste_groupe[[#This Row],[Dopage (+Testostérone / + EE2, ….)]]))) -> EE2-76ng/L | B11: Témoin | C11: 76 | D11: ng/L | E11: EE2
A12: =IF(ISBLANK(liste_groupe[[#This Row],[Code WF]])," ",IF(ISBLANK(liste_groupe[[#This Row],[Unité]]),CONCATENATE(liste_groupe[[#This Row],[Nom de l''échantillon donné par le client]],liste_groupe[[#This Row],[Dopage (+Testostérone / + EE2, ….)]]),CONCATENATE(liste_groupe[[#This Row],[Nom de l''échantillon donné par le client]],"-",liste_groupe[[#This Row],[Concentration]],liste_groupe[[#This Row],[Unité]],liste_groupe[[#This Row],[Dopage (+Testostérone / + EE2, ….)]]))) -> EE2-114ng/L | B12: Témoin | C12: 114 | D12: ng/L | E12: EE2
A13: =IF(ISBLANK(liste_groupe[[#This Row],[Code WF]])," ",IF(ISBLANK(liste_groupe[[#This Row],[Unité]]),CONCATENATE(liste_groupe[[#This Row],[Nom de l''échantillon donné par le client]],liste_groupe[[#This Row],[Dopage (+Testostérone / + EE2, ….)]]),CONCATENATE(liste_groupe[[#This Row],[Nom de l''échantillon donné par le client]],"-",liste_groupe[[#This Row],[Concentration]],liste_groupe[[#This Row],[Unité]],liste_groupe[[#This Row],[Dopage (+Testostérone / + EE2, ….)]]))) -> EE2-170,9ng/L | B13: Témoin | C13: 170.9 | D13: ng/L | E13: EE2
A14: =IF(ISBLANK(liste_groupe[[#This Row],[Code WF]])," ",IF(ISBLANK(liste_groupe[[#This Row],[Unité]]),CONCATENATE(liste_groupe[[#This Row],[Nom de l''échantillon donné par le client]],liste_groupe[[#This Row],[Dopage (+Testostérone / + EE2, ….)]]),CONCATENATE(liste_groupe[[#This Row],[Nom de l''échantillon donné par le client]],"-",liste_groupe[[#This Row],[Concentration]],liste_groupe[[#This Row],[Unité]],liste_groupe[[#This Row],[Dopage (+Testostérone / + EE2, ….)]]))) -> EE2-488ng/L | B14: Témoin | C14: 488 | D14: ng/L | E14: EE2
A15: =IF(ISBLANK(liste_groupe[[#This Row],[Code WF]])," ",IF(ISBLANK(liste_groupe[[#This Row],[Unité]]),CONCATENATE(liste_groupe[[#This Row],[Nom de l''échantillon donné par le client]],liste_groupe[[#This Row],[Dopage (+Testostérone / + EE2, ….)]]),CONCATENATE(liste_groupe[[#This Row],[Nom de l''échantillon donné par le client]],"-",liste_groupe[[#This Row],[Concentration]],liste_groupe[[#This Row],[Unité]],liste_groupe[[#This Row],[Dopage (+Testostérone / + EE2, ….)]])))
A16: =IF(ISBLANK(liste_groupe[[#This Row],[Code WF]])," ",IF(ISBLANK(liste_groupe[[#This Row],[Unité]]),CONCATENATE(liste_groupe[[#This Row],[Nom de l''échantillon donné par le client]],liste_groupe[[#This Row],[Dopage (+Testostérone / + EE2, ….)]]),CONCATENATE(liste_groupe[[#This Row],[Nom de l''échantillon donné par le client]],"-",liste_groupe[[#This Row],[Concentration]],liste_groupe[[#This Row],[Unité]],liste_groupe[[#This Row],[Dopage (+Testostérone / + EE2, ….)]])))
A17: =IF(ISBLANK(liste_groupe[[#This Row],[Code WF]])," ",IF(ISBLANK(liste_groupe[[#This Row],[Unité]]),CONCATENATE(liste_groupe[[#This Row],[Nom de l''échantillon donné par le client]],liste_groupe[[#This Row],[Dopage (+Testostérone / + EE2, ….)]]),CONCATENATE(liste_groupe[[#This Row],[Nom de l''échantillon donné par le client]],"-",liste_groupe[[#This Row],[Concentration]],liste_groupe[[#This Row],[Unité]],liste_groupe[[#This Row],[Dopage (+Testostérone / + EE2, ….)]])))
A18: =IF(ISBLANK(liste_groupe[[#This Row],[Code WF]])," ",IF(ISBLANK(liste_groupe[[#This Row],[Unité]]),CONCATENATE(liste_groupe[[#This Row],[Nom de l''échantillon donné par le client]],liste_groupe[[#This Row],[Dopage (+Testostérone / + EE2, ….)]]),CONCATENATE(liste_groupe[[#This Row],[Nom de l''échantillon donné par le client]],"-",liste_groupe[[#This Row],[Concentration]],liste_groupe[[#This Row],[Unité]],liste_groupe[[#This Row],[Dopage (+Testostérone / + EE2, ….)]])))
A19: =IF(ISBLANK(liste_groupe[[#This Row],[Code WF]])," ",IF(ISBLANK(liste_groupe[[#This Row],[Unité]]),CONCATENATE(liste_groupe[[#This Row],[Nom de l''échantillon donné par le client]],liste_groupe[[#This Row],[Dopage (+Testostérone / + EE2, ….)]]),CONCATENATE(liste_groupe[[#This Row],[Nom de l''échantillon donné par le client]],"-",liste_groupe[[#This Row],[Concentration]],liste_groupe[[#This Row],[Unité]],liste_groupe[[#This Row],[Dopage (+Testostérone / + EE2, ….)]])))
A20: =IF(ISBLANK(liste_groupe[[#This Row],[Code WF]])," ",IF(ISBLANK(liste_groupe[[#This Row],[Unité]]),CONCATENATE(liste_groupe[[#This Row],[Nom de l''échantillon donné par le client]],liste_groupe[[#This Row],[Dopage (+Testostérone / + EE2, ….)]]),CONCATENATE(liste_groupe[[#This Row],[Nom de l''échantillon donné par le client]],"-",liste_groupe[[#This Row],[Concentration]],liste_groupe[[#This Row],[Unité]],liste_groupe[[#This Row],[Dopage (+Testostérone / + EE2, ….)]])))
A21: =IF(ISBLANK(liste_groupe[[#This Row],[Code WF]])," ",IF(ISBLANK(liste_groupe[[#This Row],[Unité]]),CONCATENATE(liste_groupe[[#This Row],[Nom de l''échantillon donné par le client]],liste_groupe[[#This Row],[Dopage (+Testostérone / + EE2, ….)]]),CONCATENATE(liste_groupe[[#This Row],[Nom de l''échantillon donné par le client]],"-",liste_groupe[[#This Row],[Concentration]],liste_groupe[[#This Row],[Unité]],liste_groupe[[#This Row],[Dopage (+Testostérone / + EE2, ….)]])))
A22: =IF(ISBLANK(liste_groupe[[#This Row],[Code WF]])," ",IF(ISBLANK(liste_groupe[[#This Row],[Unité]]),CONCATENATE(liste_groupe[[#This Row],[Nom de l''échantillon donné par le client]],liste_groupe[[#This Row],[Dopage (+Testostérone / + EE2, ….)]]),CONCATENATE(liste_groupe[[#This Row],[Nom de l''échantillon donné par le client]],"-",liste_groupe[[#This Row],[Concentration]],liste_groupe[[#This Row],[Unité]],liste_groupe[[#This Row],[Dopage (+Testostérone / + EE2, ….)]])))
A23: =IF(ISBLANK(liste_groupe[[#This Row],[Code WF]])," ",IF(ISBLANK(liste_groupe[[#This Row],[Unité]]),CONCATENATE(liste_groupe[[#This Row],[Nom de l''échantillon donné par le client]],liste_groupe[[#This Row],[Dopage (+Testostérone / + EE2, ….)]]),CONCATENATE(liste_groupe[[#This Row],[Nom de l''échantillon donné par le client]],"-",liste_groupe[[#This Row],[Concentration]],liste_groupe[[#This Row],[Unité]],liste_groupe[[#This Row],[Dopage (+Testostérone / + EE2, ….)]])))
A24: =IF(ISBLANK(liste_groupe[[#This Row],[Code WF]])," ",IF(ISBLANK(liste_groupe[[#This Row],[Unité]]),CONCATENATE(liste_groupe[[#This Row],[Nom de l''échantillon donné par le client]],liste_groupe[[#This Row],[Dopage (+Testostérone / + EE2, ….)]]),CONCATENATE(liste_groupe[[#This Row],[Nom de l''échantillon donné par le client]],"-",liste_groupe[[#This Row],[Concentration]],liste_groupe[[#This Row],[Unité]],liste_groupe[[#This Row],[Dopage (+Testostérone / + EE2, ….)]])))
A25: =IF(ISBLANK(liste_groupe[[#This Row],[Code WF]])," ",IF(ISBLANK(liste_groupe[[#This Row],[Unité]]),CONCATENATE(liste_groupe[[#This Row],[Nom de l''échantillon donné par le client]],liste_groupe[[#This Row],[Dopage (+Testostérone / + EE2, ….)]]),CONCATENATE(liste_groupe[[#This Row],[Nom de l''échantillon donné par le client]],"-",liste_groupe[[#This Row],[Concentration]],liste_groupe[[#This Row],[Unité]],liste_groupe[[#This Row],[Dopage (+Testostérone / + EE2, ….)]])))
A26: =IF(ISBLANK(liste_groupe[[#This Row],[Code WF]])," ",IF(ISBLANK(liste_groupe[[#This Row],[Unité]]),CONCATENATE(liste_groupe[[#This Row],[Nom de l''échantillon donné par le client]],liste_groupe[[#This Row],[Dopage (+Testostérone / + EE2, ….)]]),CONCATENATE(liste_groupe[[#This Row],[Nom de l''échantillon donné par le client]],"-",liste_groupe[[#This Row],[Concentration]],liste_groupe[[#This Row],[Unité]],liste_groupe[[#This Row],[Dopage (+Testostérone / + EE2, ….)]])))
... A35: =IF(ISBLANK(liste_groupe[[#This Row],[Code WF]])," ",IF(ISBLANK(liste_groupe[[#This Row],[Unité]]),CONCATENATE(liste_groupe[[#This Row],[Nom de l''échantillon donné par le client]],liste_groupe[[#This Row],[Dopage (+Testostérone / + EE2, ….)]]),CONCATENATE(liste_groupe[[#This Row],[Nom de l''échantillon donné par le client]],"-",liste_groupe[[#This Row],[Concentration]],liste_groupe[[#This Row],[Unité]],liste_groupe[[#This Row],[Dopage (+Testostérone / + EE2, ….)]])))
A36: =IF(ISBLANK(liste_groupe[[#This Row],[Code WF]])," ",IF(ISBLANK(liste_groupe[[#This Row],[Unité]]),CONCATENATE(liste_groupe[[#This Row],[Nom de l''échantillon donné par le client]],liste_groupe[[#This Row],[Dopage (+Testostérone / + EE2, ….)]]),CONCATENATE(liste_groupe[[#This Row],[Nom de l''échantillon donné par le client]],"-",liste_groupe[[#This Row],[Concentration]],liste_groupe[[#This Row],[Unité]],liste_groupe[[#This Row],[Dopage (+Testostérone / + EE2, ….)]]))) -> Testo -30µg/L | B36: Témoin | C36: 30 | D36: µg/L | E36: Testo
A37: =IF(ISBLANK(liste_groupe[[#This Row],[Code WF]])," ",IF(ISBLANK(liste_groupe[[#This Row],[Unité]]),CONCATENATE(liste_groupe[[#This Row],[Nom de l''échantillon donné par le client]],liste_groupe[[#This Row],[Dopage (+Testostérone / + EE2, ….)]]),CONCATENATE(liste_groupe[[#This Row],[Nom de l''échantillon donné par le client]],"-",liste_groupe[[#This Row],[Concentration]],liste_groupe[[#This Row],[Unité]],liste_groupe[[#This Row],[Dopage (+Testostérone / + EE2, ….)]]))) -> Testo 30µg/L + EE2 -64ng/L | B37: Témoin | C37: 64 | D37: ng/L | E37: Testo 30µg/L + EE2
A38: =IF(ISBLANK(liste_groupe[[#This Row],[Code WF]])," ",IF(ISBLANK(liste_groupe[[#This Row],[Unité]]),CONCATENATE(liste_groupe[[#This Row],[Nom de l''échantillon donné par le client]],liste_groupe[[#This Row],[Dopage (+Testostérone / + EE2, ….)]]),CONCATENATE(liste_groupe[[#This Row],[Nom de l''échantillon donné par le client]],"-",liste_groupe[[#This Row],[Concentration]],liste_groupe[[#This Row],[Unité]],liste_groupe[[#This Row],[Dopage (+Testostérone / + EE2, ….)]]))) -> Testo 30µg/L + FAD-10mg/L | B38: Témoin | C38: 10 | D38: mg/L | E38: Testo 30µg/L + FAD
A39: =IF(ISBLANK(liste_groupe[[#This Row],[Code WF]])," ",IF(ISBLANK(liste_groupe[[#This Row],[Unité]]),CONCATENATE(liste_groupe[[#This Row],[Nom de l''échantillon donné par le client]],liste_groupe[[#This Row],[Dopage (+Testostérone / + EE2, ….)]]),CONCATENATE(liste_groupe[[#This Row],[Nom de l''échantillon donné par le client]],"-",liste_groupe[[#This Row],[Concentration]],liste_groupe[[#This Row],[Unité]],liste_groupe[[#This Row],[Dopage (+Testostérone / + EE2, ….)]]))) -> 0-00 + Testostérone | B39: =B15 -> 0 | C39: =C15 -> 0 | D39: =D15 -> 0 | E39: =E15 -> 0 | F39: + Testostérone
A40: =IF(ISBLANK(liste_groupe[[#This Row],[Code WF]])," ",IF(ISBLANK(liste_groupe[[#This Row],[Unité]]),CONCATENATE(liste_groupe[[#This Row],[Nom de l''échantillon donné par le client]],liste_groupe[[#This Row],[Dopage (+Testostérone / + EE2, ….)]]),CONCATENATE(liste_groupe[[#This Row],[Nom de l''échantillon donné par le client]],"-",liste_groupe[[#This Row],[Concentration]],liste_groupe[[#This Row],[Unité]],liste_groupe[[#This Row],[Dopage (+Testostérone / + EE2, ….)]]))) -> 0-00 + Testostérone | B40: =B16 -> 0 | C40: =C16 -> 0 | D40: =D16 -> 0 | E40: =E16 -> 0 | F40: + Testostérone
A41: =IF(ISBLANK(liste_groupe[[#This Row],[Code WF]])," ",IF(ISBLANK(liste_groupe[[#This Row],[Unité]]),CONCATENATE(liste_groupe[[#This Row],[Nom de l''échantillon donné par le client]],liste_groupe[[#This Row],[Dopage (+Testostérone / + EE2, ….)]]),CONCATENATE(liste_groupe[[#This Row],[Nom de l''échantillon donné par le client]],"-",liste_groupe[[#This Row],[Concentration]],liste_groupe[[#This Row],[Unité]],liste_groupe[[#This Row],[Dopage (+Testostérone / + EE2, ….)]]))) -> 0-00 + Testostérone | B41: =B17 -> 0 | C41: =C17 -> 0 | D41: =D17 -> 0 | E41: =E17 -> 0 | F41: + Testostérone
A42: =IF(ISBLANK(liste_groupe[[#This Row],[Code WF]])," ",IF(ISBLANK(liste_groupe[[#This Row],[Unité]]),CONCATENATE(liste_groupe[[#This Row],[Nom de l''échantillon donné par le client]],liste_groupe[[#This Row],[Dopage (+Testostérone / + EE2, ….)]]),CONCATENATE(liste_groupe[[#This Row],[Nom de l''échantillon donné par le client]],"-",liste_groupe[[#This Row],[Concentration]],liste_groupe[[#This Row],[Unité]],liste_groupe[[#This Row],[Dopage (+Testostérone / + EE2, ….)]]))) -> 0-00 + Testostérone | B42: =B18 -> 0 | C42: =C18 -> 0 | D42: =D18 -> 0 | E42: =E18 -> 0 | F42: + Testostérone
A43: =IF(ISBLANK(liste_groupe[[#This Row],[Code WF]])," ",IF(ISBLANK(liste_groupe[[#This Row],[Unité]]),CONCATENATE(liste_groupe[[#This Row],[Nom de l''échantillon donné par le client]],liste_groupe[[#This Row],[Dopage (+Testostérone / + EE2, ….)]]),CONCATENATE(liste_groupe[[#This Row],[Nom de l''échantillon donné par le client]],"-",liste_groupe[[#This Row],[Concentration]],liste_groupe[[#This Row],[Unité]],liste_groupe[[#This Row],[Dopage (+Testostérone / + EE2, ….)]]))) -> 0-00 + Testostérone | B43: =B19 -> 0 | C43: =C19 -> 0 | D43: =D19 -> 0 | E43: =E19 -> 0 | F43: + Testostérone
A44: =IF(ISBLANK(liste_groupe[[#This Row],[Code WF]])," ",IF(ISBLANK(liste_groupe[[#This Row],[Unité]]),CONCATENATE(liste_groupe[[#This Row],[Nom de l''échantillon donné par le client]],liste_groupe[[#This Row],[Dopage (+Testostérone / + EE2, ….)]]),CONCATENATE(liste_groupe[[#This Row],[Nom de l''échantillon donné par le client]],"-",liste_groupe[[#This Row],[Concentration]],liste_groupe[[#This Row],[Unité]],liste_groupe[[#This Row],[Dopage (+Testostérone / + EE2, ….)]]))) -> 0-00 + Testostérone | B44: =B20 -> 0 | C44: =C20 -> 0 | D44: =D20 -> 0 | E44: =E20 -> 0 | F44: + Testostérone
A45: =IF(ISBLANK(liste_groupe[[#This Row],[Code WF]])," ",IF(ISBLANK(liste_groupe[[#This Row],[Unité]]),CONCATENATE(liste_groupe[[#This Row],[Nom de l''échantillon donné par le client]],liste_groupe[[#This Row],[Dopage (+Testostérone / + EE2, ….)]]),CONCATENATE(liste_groupe[[#This Row],[Nom de l''échantillon donné par le client]],"-",liste_groupe[[#This Row],[Concentration]],liste_groupe[[#This Row],[Unité]],liste_groupe[[#This Row],[Dopage (+Testostérone / + EE2, ….)]]))) -> 0-00 + Testostérone | B45: =B21 -> 0 | C45: =C21 -> 0 | D45: =D21 -> 0 | E45: =E21 -> 0 | F45: + Testostérone
A46: =IF(ISBLANK(liste_groupe[[#This Row],[Code WF]])," ",IF(ISBLANK(liste_groupe[[#This Row],[Unité]]),CONCATENATE(liste_groupe[[#This Row],[Nom de l''échantillon donné par le client]],liste_groupe[[#This Row],[Dopage (+Testostérone / + EE2, ….)]]),CONCATENATE(liste_groupe[[#This Row],[Nom de l''échantillon donné par le client]],"-",liste_groupe[[#This Row],[Concentration]],liste_groupe[[#This Row],[Unité]],liste_groupe[[#This Row],[Dopage (+Testostérone / + EE2, ….)]]))) -> 0-00 + Testostérone | B46: =B22 -> 0 | C46: =C22 -> 0 | D46: =D22 -> 0 | E46: =E22 -> 0 | F46: + Testostérone
A47: =IF(ISBLANK(liste_groupe[[#This Row],[Code WF]])," ",IF(ISBLANK(liste_groupe[[#This Row],[Unité]]),CONCATENATE(liste_groupe[[#This Row],[Nom de l''échantillon donné par le client]],liste_groupe[[#This Row],[Dopage (+Testostérone / + EE2, ….)]]),CONCATENATE(liste_groupe[[#This Row],[Nom de l''échantillon donné par le client]],"-",liste_groupe[[#This Row],[Concentration]],liste_groupe[[#This Row],[Unité]],liste_groupe[[#This Row],[Dopage (+Testostérone / + EE2, ….)]]))) -> 0-00 + Testostérone | B47: =B23 -> 0 | C47: =C23 -> 0 | D47: =D23 -> 0 | E47: =E23 -> 0 | F47: + Testostérone
A48: =IF(ISBLANK(liste_groupe[[#This Row],[Code WF]])," ",IF(ISBLANK(liste_groupe[[#This Row],[Unité]]),CONCATENATE(liste_groupe[[#This Row],[Nom de l''échantillon donné par le client]],liste_groupe[[#This Row],[Dopage (+Testostérone / + EE2, ….)]]),CONCATENATE(liste_groupe[[#This Row],[Nom de l''échantillon donné par le client]],"-",liste_groupe[[#This Row],[Concentration]],liste_groupe[[#This Row],[Unité]],liste_groupe[[#This Row],[Dopage (+Testostérone / + EE2, ….)]]))) -> 0-00 + Testostérone | B48: =B24 -> 0 | C48: =C24 -> 0 | D48: =D24 -> 0 | E48: =E24 -> 0 | F48: + Testostérone
...

Sheet Feuil1
A1: Nom groupe | B1: N° de valeur | C1: file name | D1: total area | E1: mean intensity | G1: total fluorescence | I1: nbre de larves
A2: 01 EE2 0 | B2: A | C2: C:\Users\Olympus\Desktop\20190122\plaque1/@01 EE2 0/A1_1.tif | D2: 4931.616 | E2: 73.0526 | G2: 360268
A3: 01 EE2 0 | B3: A | C3: C:\Users\Olympus\Desktop\20190122\plaque1/@01 EE2 0/A1_2.tif | D3: 5234.4345 | E3: 71.1281 | G3: 372315
A4: 01 EE2 0 | B4: A | C4: C:\Users\Olympus\Desktop\20190122\plaque1/@01 EE2 0/A1_3.tif | D4: 3547.3027 | E4: 66.9878 | G4: 237626
A5: 01 EE2 0 | B5: A | C5: C:\Users\Olympus\Desktop\20190122\plaque3/@01 EE2 0/A1_3.tif | D5: 21456.8555 | E5: 67.0655 | G5: 1439015
A6: 01 EE2 0 | B6: A | C6: C:\Users\Olympus\Desktop\20190122\plaque3/@01 EE2 0/A1_2.tif | D6: 21586.6348 | E6: 66.4108 | G6: 1433586
A7: 01 EE2 0 | B7: A | C7: C:\Users\Olympus\Desktop\20190122\plaque3/@01 EE2 0/A1_1.tif | D7: 15984.4921 | E7: 69.7767 | G7: 1115346

Sheet Feuil2
A1: Nom groupe | B1: N° de valeur | C1: file name | D1: total area | E1: mean intensity | G1: total fluorescence | I1: nbre de larves
B2: #VALUE!
B3: #VALUE!
B4: #VALUE!
B5: #VALUE!
B6: #VALUE!
B7: #VALUE!
B8: #VALUE!
B9: #VALUE!
B10: #VALUE!
B11: #VALUE!
B12: #VALUE!
B13: #VALUE!
... B1557: #VALUE!

Sheet Raw data R1
A1: Nom groupe | B1: N° de valeur | C1: file name | D1: total area | E1: mean intensity | G1: total fluorescence | I1: nbre de larves | J1: Colonne1 | L1: (Tous)
A2: =IFERROR(LEFT(RIGHT(C2,LEN(C2)-SEARCH("@",C2)),SEARCH("/",RIGHT(C2,LEN(C2)-SEARCH("@",C2)-1))),"") | B2: =LEFT(RIGHT(RIGHT(Tableau4[[#This Row],[file name]],LEN(Tableau4[[#This Row],[file name]])-SEARCH("@",Tableau4[[#This Row],[file name]])),LEN(RIGHT(Tableau4[[#This Row],[file name]],LEN(Tableau4[[#This Row],[file name]])-SEARCH("@",Tableau4[[#This Row],[file name]])))-SEARCH("/",RIGHT(Tableau4[[#This Row],[file name]],LEN(Tableau4[[#This Row],[file name]])-SEARCH("@",Tableau4[[#This Row],[file name]])))),1) -> #VALUE! | C2: file name | D2: total area | E2: mean intensity | G2: total fluorescence | K2: Filtre lignes : Enlever (vide) et Néant | L2: Filtre colonnes : Enlever (vide) et " "
A3: =IFERROR(LEFT(RIGHT(C3,LEN(C3)-SEARCH("@",C3)),SEARCH("/",RIGHT(C3,LEN(C3)-SEARCH("@",C3)-1))),"") -> 1 | B3: =LEFT(RIGHT(RIGHT(Tableau4[[#This Row],[file name]],LEN(Tableau4[[#This Row],[file name]])-SEARCH("@",Tableau4[[#This Row],[file name]])),LEN(RIGHT(Tableau4[[#This Row],[file name]],LEN(Tableau4[[#This Row],[file name]])-SEARCH("@",Tableau4[[#This Row],[file name]])))-SEARCH("/",RIGHT(Tableau4[[#This Row],[file name]],LEN(Tableau4[[#This Row],[file name]])-SEARCH("@",Tableau4[[#This Row],[file name]])))),1) -> 2 | C3: C:\Users\cbarrier\Desktop\Calibration\20201110_Cefas_Test3_Run1/@1/20201110_Cefas_Test3_Run1/@1/A10- exclu.tif | K3: Moyenne de total fluorescence | L3: Étiquettes de colonnes
A4: =IFERROR(LEFT(RIGHT(C4,LEN(C4)-SEARCH("@",C4)),SEARCH("/",RIGHT(C4,LEN(C4)-SEARCH("@",C4)-1))),"") -> 1 | B4: =LEFT(RIGHT(RIGHT(Tableau4[[#This Row],[file name]],LEN(Tableau4[[#This Row],[file name]])-SEARCH("@",Tableau4[[#This Row],[file name]])),LEN(RIGHT(Tableau4[[#This Row],[file name]],LEN(Tableau4[[#This Row],[file name]])-SEARCH("@",Tableau4[[#This Row],[file name]])))-SEARCH("/",RIGHT(Tableau4[[#This Row],[file name]],LEN(Tableau4[[#This Row],[file name]])-SEARCH("@",Tableau4[[#This Row],[file name]])))),1) -> 2 | C4: C:\Users\cbarrier\Desktop\Calibration\20201110_Cefas_Test3_Run1/@1/20201110_Cefas_Test3_Run1/@1/B10.tif | D4: 116 | E4: 36.2845 | G4: 4209 | K4: Étiquettes de lignes | M4: 1 | N4: 13 | O4: 14 | P4: 15 | Q4: 16 | R4: 2 | S4: 3 | T4: 4 | U4: 5 | V4: 6 | W4: 7
A5: =IFERROR(LEFT(RIGHT(C5,LEN(C5)-SEARCH("@",C5)),SEARCH("/",RIGHT(C5,LEN(C5)-SEARCH("@",C5)-1))),"") -> 1 | B5: =LEFT(RIGHT(RIGHT(Tableau4[[#This Row],[file name]],LEN(Tableau4[[#This Row],[file name]])-SEARCH("@",Tableau4[[#This Row],[file name]])),LEN(RIGHT(Tableau4[[#This Row],[file name]],LEN(Tableau4[[#This Row],[file name]])-SEARCH("@",Tableau4[[#This Row],[file name]])))-SEARCH("/",RIGHT(Tableau4[[#This Row],[file name]],LEN(Tableau4[[#This Row],[file name]])-SEARCH("@",Tableau4[[#This Row],[file name]])))),1) -> 2 | C5: C:\Users\cbarrier\Desktop\Calibration\20201110_Cefas_Test3_Run1/@1/20201110_Cefas_Test3_Run1/@1/C10.tif | D5: 97 | E5: 34.866 | G5: 3382 | M5: 7558 | N5: #DIV/0! | O5: #DIV/0! | P5: #DIV/0! | Q5: 7586 | R5: #DIV/0! | S5: 7898 | T5: #DIV/0! | U5: #DIV/0! | V5: #DIV/0! | W5: #DIV/0!
A6: =IFERROR(LEFT(RIGHT(C6,LEN(C6)-SEARCH("@",C6)),SEARCH("/",RIGHT(C6,LEN(C6)-SEARCH("@",C6)-1))),"") -> 1 | B6: =LEFT(RIGHT(RIGHT(Tableau4[[#This Row],[file name]],LEN(Tableau4[[#This Row],[file name]])-SEARCH("@",Tableau4[[#This Row],[file name]])),LEN(RIGHT(Tableau4[[#This Row],[file name]],LEN(Tableau4[[#This Row],[file name]])-SEARCH("@",Tableau4[[#This Row],[file name]])))-SEARCH("/",RIGHT(Tableau4[[#This Row],[file name]],LEN(Tableau4[[#This Row],[file name]])-SEARCH("@",Tableau4[[#This Row],[file name]])))),1) -> 2 | C6: C:\Users\cbarrier\Desktop\Calibration\20201110_Cefas_Test3_Run1/@1/20201110_Cefas_Test3_Run1/@1/D10.tif | D6: 52 | E6: 35.9808 | G6: 1871 | K6: 2 | M6: 3119.1429 | N6: 85677.125 | O6: 72230.714 | P6: 171402.71 | Q6: 4461.1667 | R6: 10853.875 | S6: 9026.2857 | T6: 12785.625 | U6: 40793.714 | V6: 76725.625 | W6: 163917.86
A7: =IFERROR(LEFT(RIGHT(C7,LEN(C7)-SEARCH("@",C7)),SEARCH("/",RIGHT(C7,LEN(C7)-SEARCH("@",C7)-1))),"") -> 1 | B7: =LEFT(RIGHT(RIGHT(Tableau4[[#This Row],[file name]],LEN(Tableau4[[#This Row],[file name]])-SEARCH("@",Tableau4[[#This Row],[file name]])),LEN(RIGHT(Tableau4[[#This Row],[file name]],LEN(Tableau4[[#This Row],[file name]])-SEARCH("@",Tableau4[[#This Row],[file name]])))-SEARCH("/",RIGHT(Tableau4[[#This Row],[file name]],LEN(Tableau4[[#This Row],[file name]])-SEARCH("@",Tableau4[[#This Row],[file name]])))),1) -> 2 | C7: C:\Users\cbarrier\Desktop\Calibration\20201110_Cefas_Test3_Run1/@1/20201110_Cefas_Test3_Run1/@1/E10.tif | D7: 10 | E7: 31.1 | G7: 311 | K7: #VALEUR! | L7: #DIV/0!
A8: =IFERROR(LEFT(RIGHT(C8,LEN(C8)-SEARCH("@",C8)),SEARCH("/",RIGHT(C8,LEN(C8)-SEARCH("@",C8)-1))),"") -> 1 | B8: =LEFT(RIGHT(RIGHT(Tableau4[[#This Row],[file name]],LEN(Tableau4[[#This Row],[file name]])-SEARCH("@",Tableau4[[#This Row],[file name]])),LEN(RIGHT(Tableau4[[#This Row],[file name]],LEN(Tableau4[[#This Row],[file name]])-SEARCH("@",Tableau4[[#This Row],[file name]])))-SEARCH("/",RIGHT(Tableau4[[#This Row],[file name]],LEN(Tableau4[[#This Row],[file name]])-SEARCH("@",Tableau4[[#This Row],[file name]])))),1) -> 2 | C8: C:\Users\cbarrier\Desktop\Calibration\20201110_Cefas_Test3_Run1/@1/20201110_Cefas_Test3_Run1/@1/F10.tif | D8: 156 | E8: 34.0192 | G8: 5307
A9: =IFERROR(LEFT(RIGHT(C9,LEN(C9)-SEARCH("@",C9)),SEARCH("/",RIGHT(C9,LEN(C9)-SEARCH("@",C9)-1))),"") -> 1 | B9: =LEFT(RIGHT(RIGHT(Tableau4[[#This Row],[file name]],LEN(Tableau4[[#This Row],[file name]])-SEARCH("@",Tableau4[[#This Row],[file name]])),LEN(RIGHT(Tableau4[[#This Row],[file name]],LEN(Tableau4[[#This Row],[file name]])-SEARCH("@",Tableau4[[#This Row],[file name]])))-SEARCH("/",RIGHT(Tableau4[[#This Row],[file name]],LEN(Tableau4[[#This Row],[file name]])-SEARCH("@",Tableau4[[#This Row],[file name]])))),1) -> 2 | C9: C:\Users\cbarrier\Desktop\Calibration\20201110_Cefas_Test3_Run1/@1/20201110_Cefas_Test3_Run1/@1/G10.tif | D9: 102 | E9: 34.8137 | G9: 3551
A10: =IFERROR(LEFT(RIGHT(C10,LEN(C10)-SEARCH("@",C10)),SEARCH("/",RIGHT(C10,LEN(C10)-SEARCH("@",C10)-1))),"") -> 1 | B10: =LEFT(RIGHT(RIGHT(Tableau4[[#This Row],[file name]],LEN(Tableau4[[#This Row],[file name]])-SEARCH("@",Tableau4[[#This Row],[file name]])),LEN(RIGHT(Tableau4[[#This Row],[file name]],LEN(Tableau4[[#This Row],[file name]])-SEARCH("@",Tableau4[[#This Row],[file name]])))-SEARCH("/",RIGHT(Tableau4[[#This Row],[file name]],LEN(Tableau4[[#This Row],[file name]])-SEARCH("@",Tableau4[[#This Row],[file name]])))),1) -> 2 | C10: C:\Users\cbarrier\Desktop\Calibration\20201110_Cefas_Test3_Run1/@1/20201110_Cefas_Test3_Run1/@1/H10.tif | D10: 88 | E10: 36.3977 | G10: 3203
A11: =IFERROR(LEFT(RIGHT(C11,LEN(C11)-SEARCH("@",C11)),SEARCH("/",RIGHT(C11,LEN(C11)-SEARCH("@",C11)-1))),"") | B11: =LEFT(RIGHT(RIGHT(Tableau4[[#This Row],[file name]],LEN(Tableau4[[#This Row],[file name]])-SEARCH("@",Tableau4[[#This Row],[file name]])),LEN(RIGHT(Tableau4[[#This Row],[file name]],LEN(Tableau4[[#This Row],[file name]])-SEARCH("@",Tableau4[[#This Row],[file name]])))-SEARCH("/",RIGHT(Tableau4[[#This Row],[file name]],LEN(Tableau4[[#This Row],[file name]])-SEARCH("@",Tableau4[[#This Row],[file name]])))),1) -> #VALUE!
A12: =IFERROR(LEFT(RIGHT(C12,LEN(C12)-SEARCH("@",C12)),SEARCH("/",RIGHT(C12,LEN(C12)-SEARCH("@",C12)-1))),"") | B12: =LEFT(RIGHT(RIGHT(Tableau4[[#This Row],[file name]],LEN(Tableau4[[#This Row],[file name]])-SEARCH("@",Tableau4[[#This Row],[file name]])),LEN(RIGHT(Tableau4[[#This Row],[file name]],LEN(Tableau4[[#This Row],[file name]])-SEARCH("@",Tableau4[[#This Row],[file name]])))-SEARCH("/",RIGHT(Tableau4[[#This Row],[file name]],LEN(Tableau4[[#This Row],[file name]])-SEARCH("@",Tableau4[[#This Row],[file name]])))),1) -> #VALUE! | C12: group | E12: mean of mean fluo | F12: SD mean fluo | G12: mean of total fluo | H12: SD total fluo | I12: n fluorescent | J12: n total
A13: =IFERROR(LEFT(RIGHT(C13,LEN(C13)-SEARCH("@",C13)),SEARCH("/",RIGHT(C13,LEN(C13)-SEARCH("@",C13)-1))),"") -> 1 | B13: =LEFT(RIGHT(RIGHT(Tableau4[[#This Row],[file name]],LEN(Tableau4[[#This Row],[file name]])-SEARCH("@",Tableau4[[#This Row],[file name]])),LEN(RIGHT(Tableau4[[#This Row],[file name]],LEN(Tableau4[[#This Row],[file name]])-SEARCH("@",Tableau4[[#This Row],[file name]])))-SEARCH("/",RIGHT(Tableau4[[#This Row],[file name]],LEN(Tableau4[[#This Row],[file name]])-SEARCH("@",Tableau4[[#This Row],[file name]])))),1) | C13: C:\Users\cbarrier\Desktop\Calibration\20201110_Cefas_Test3_Run1/@1/ | E13: 37.6506 | F13: 8.2965 | G13: 7558 | H13: 12643.8806 | I13: 8 | J13: 8
A14: =IFERROR(LEFT(RIGHT(C14,LEN(C14)-SEARCH("@",C14)),SEARCH("/",RIGHT(C14,LEN(C14)-SEARCH("@",C14)-1))),"") | B14: =LEFT(RIGHT(RIGHT(Tableau4[[#This Row],[file name]],LEN(Tableau4[[#This Row],[file name]])-SEARCH("@",Tableau4[[#This Row],[file name]])),LEN(RIGHT(Tableau4[[#This Row],[file name]],LEN(Tableau4[[#This Row],[file name]])-SEARCH("@",Tableau4[[#This Row],[file name]])))-SEARCH("/",RIGHT(Tableau4[[#This Row],[file name]],LEN(Tableau4[[#This Row],[file name]])-SEARCH("@",Tableau4[[#This Row],[file name]])))),1) -> #VALUE!
A15: =IFERROR(LEFT(RIGHT(C15,LEN(C15)-SEARCH("@",C15)),SEARCH("/",RIGHT(C15,LEN(C15)-SEARCH("@",C15)-1))),"") | B15: =LEFT(RIGHT(RIGHT(Tableau4[[#This Row],[file name]],LEN(Tableau4[[#This Row],[file name]])-SEARCH("@",Tableau4[[#This Row],[file name]])),LEN(RIGHT(Tableau4[[#This Row],[file name]],LEN(Tableau4[[#This Row],[file name]])-SEARCH("@",Tableau4[[#This Row],[file name]])))-SEARCH("/",RIGHT(Tableau4[[#This Row],[file name]],LEN(Tableau4[[#This Row],[file name]])-SEARCH("@",Tableau4[[#This Row],[file name]])))),1) -> #VALUE!
A16: =IFERROR(LEFT(RIGHT(C16,LEN(C16)-SEARCH("@",C16)),SEARCH("/",RIGHT(C16,LEN(C16)-SEARCH("@",C16)-1))),"") | B16: =LEFT(RIGHT(RIGHT(Tableau4[[#This Row],[file name]],LEN(Tableau4[[#This Row],[file name]])-SEARCH("@",Tableau4[[#This Row],[file name]])),LEN(RIGHT(Tableau4[[#This Row],[file name]],LEN(Tableau4[[#This Row],[file name]])-SEARCH("@",Tableau4[[#This Row],[file name]])))-SEARCH("/",RIGHT(Tableau4[[#This Row],[file name]],LEN(Tableau4[[#This Row],[file name]])-SEARCH("@",Tableau4[[#This Row],[file name]])))),1) -> #VALUE!
A17: =IFERROR(LEFT(RIGHT(C17,LEN(C17)-SEARCH("@",C17)),SEARCH("/",RIGHT(C17,LEN(C17)-SEARCH("@",C17)-1))),"") | B17: =LEFT(RIGHT(RIGHT(Tableau4[[#This Row],[file name]],LEN(Tableau4[[#This Row],[file name]])-SEARCH("@",Tableau4[[#This Row],[file name]])),LEN(RIGHT(Tableau4[[#This Row],[file name]],LEN(Tableau4[[#This Row],[file name]])-SEARCH("@",Tableau4[[#This Row],[file name]])))-SEARCH("/",RIGHT(Tableau4[[#This Row],[file name]],LEN(Tableau4[[#This Row],[file name]])-SEARCH("@",Tableau4[[#This Row],[file name]])))),1) -> #VALUE!
A18: =IFERROR(LEFT(RIGHT(C18,LEN(C18)-SEARCH("@",C18)),SEARCH("/",RIGHT(C18,LEN(C18)-SEARCH("@",C18)-1))),"") | B18: =LEFT(RIGHT(RIGHT(Tableau4[[#This Row],[file name]],LEN(Tableau4[[#This Row],[file name]])-SEARCH("@",Tableau4[[#This Row],[file name]])),LEN(RIGHT(Tableau4[[#This Row],[file name]],LEN(Tableau4[[#This Row],[file name]])-SEARCH("@",Tableau4[[#This Row],[file name]])))-SEARCH("/",RIGHT(Tableau4[[#This Row],[file name]],LEN(Tableau4[[#This Row],[file name]])-SEARCH("@",Tableau4[[#This Row],[file name]])))),1) -> #VALUE!
A19: =IFERROR(LEFT(RIGHT(C19,LEN(C19)-SEARCH("@",C19)),SEARCH("/",RIGHT(C19,LEN(C19)-SEARCH("@",C19)-1))),"") | B19: =LEFT(RIGHT(RIGHT(Tableau4[[#This Row],[file name]],LEN(Tableau4[[#This Row],[file name]])-SEARCH("@",Tableau4[[#This Row],[file name]])),LEN(RIGHT(Tableau4[[#This Row],[file name]],LEN(Tableau4[[#This Row],[file name]])-SEARCH("@",Tableau4[[#This Row],[file name]])))-SEARCH("/",RIGHT(Tableau4[[#This Row],[file name]],LEN(Tableau4[[#This Row],[file name]])-SEARCH("@",Tableau4[[#This Row],[file name]])))),1) -> #VALUE! | C19: file name | D19: total area | E19: mean intensity | G19: total fluorescence
A20: =IFERROR(LEFT(RIGHT(C20,LEN(C20)-SEARCH("@",C20)),SEARCH("/",RIGHT(C20,LEN(C20)-SEARCH("@",C20)-1))),"") -> 13 | B20: =LEFT(RIGHT(RIGHT(Tableau4[[#This Row],[file name]],LEN(Tableau4[[#This Row],[file name]])-SEARCH("@",Tableau4[[#This Row],[file name]])),LEN(RIGHT(Tableau4[[#This Row],[file name]],LEN(Tableau4[[#This Row],[file name]])-SEARCH("@",Tableau4[[#This Row],[file name]])))-SEARCH("/",RIGHT(Tableau4[[#This Row],[file name]],LEN(Tableau4[[#This Row],[file name]])-SEARCH("@",Tableau4[[#This Row],[file name]])))),1) -> 2 | C20: C:\Users\cbarrier\Desktop\Calibration\20201110_Cefas_Test3_Run1/@13/20201110_Cefas_Test3_Run1/@13/A8.tif | D20: 2254 | E20: 40.7675 | G20: 91890
A21: =IFERROR(LEFT(RIGHT(C21,LEN(C21)-SEARCH("@",C21)),SEARCH("/",RIGHT(C21,LEN(C21)-SEARCH("@",C21)-1))),"") -> 13 | B21: =LEFT(RIGHT(RIGHT(Tableau4[[#This Row],[file name]],LEN(Tableau4[[#This Row],[file name]])-SEARCH("@",Tableau4[[#This Row],[file name]])),LEN(RIGHT(Tableau4[[#This Row],[file name]],LEN(Tableau4[[#This Row],[file name]])-SEARCH("@",Tableau4[[#This Row],[file name]])))-SEARCH("/",RIGHT(Tableau4[[#This Row],[file name]],LEN(Tableau4[[#This Row],[file name]])-SEARCH("@",Tableau4[[#This Row],[file name]])))),1) -> 2 | C21: C:\Users\cbarrier\Desktop\Calibration\20201110_Cefas_Test3_Run1/@13/20201110_Cefas_Test3_Run1/@13/B8.tif | D21: 455 | E21: 34.4396 | G21: 15670
A22: =IFERROR(LEFT(RIGHT(C22,LEN(C22)-SEARCH("@",C22)),SEARCH("/",RIGHT(C22,LEN(C22)-SEARCH("@",C22)-1))),"") -> 13 | B22: =LEFT(RIGHT(RIGHT(Tableau4[[#This Row],[file name]],LEN(Tableau4[[#This Row],[file name]])-SEARCH("@",Tableau4[[#This Row],[file name]])),LEN(RIGHT(Tableau4[[#This Row],[file name]],LEN(Tableau4[[#This Row],[file name]])-SEARCH("@",Tableau4[[#This Row],[file name]])))-SEARCH("/",RIGHT(Tableau4[[#This Row],[file name]],LEN(Tableau4[[#This Row],[file name]])-SEARCH("@",Tableau4[[#This Row],[file name]])))),1) -> 2 | C22: C:\Users\cbarrier\Desktop\Calibration\20201110_Cefas_Test3_Run1/@13/20201110_Cefas_Test3_Run1/@13/C8.tif | D22: 1593 | E22: 39.7307 | G22: 63291
A23: =IFERROR(LEFT(RIGHT(C23,LEN(C23)-SEARCH("@",C23)),SEARCH("/",RIGHT(C23,LEN(C23)-SEARCH("@",C23)-1))),"") -> 13 | B23: =LEFT(RIGHT(RIGHT(Tableau4[[#This Row],[file name]],LEN(Tableau4[[#This Row],[file name]])-SEARCH("@",Tableau4[[#This Row],[file name]])),LEN(RIGHT(Tableau4[[#This Row],[file name]],LEN(Tableau4[[#This Row],[file name]])-SEARCH("@",Tableau4[[#This Row],[file name]])))-SEARCH("/",RIGHT(Tableau4[[#This Row],[file name]],LEN(Tableau4[[#This Row],[file name]])-SEARCH("@",Tableau4[[#This Row],[file name]])))),1) -> 2 | C23: C:\Users\cbarrier\Desktop\Calibration\20201110_Cefas_Test3_Run1/@13/20201110_Cefas_Test3_Run1/@13/D8.tif | D23: 2460 | E23: 41.1683 | G23: 101274
A24: =IFERROR(LEFT(RIGHT(C24,LEN(C24)-SEARCH("@",C24)),SEARCH("/",RIGHT(C24,LEN(C24)-SEARCH("@",C24)-1))),"") -> 13 | B24: =LEFT(RIGHT(RIGHT(Tableau4[[#This Row],[file name]],LEN(Tableau4[[#This Row],[file name]])-SEARCH("@",Tableau4[[#This Row],[file name]])),LEN(RIGHT(Tableau4[[#This Row],[file name]],LEN(Tableau4[[#This Row],[file name]])-SEARCH("@",Tableau4[[#This Row],[file name]])))-SEARCH("/",RIGHT(Tableau4[[#This Row],[file name]],LEN(Tableau4[[#This Row],[file name]])-SEARCH("@",Tableau4[[#This Row],[file name]])))),1) -> 2 | C24: C:\Users\cbarrier\Desktop\Calibration\20201110_Cefas_Test3_Run1/@13/20201110_Cefas_Test3_Run1/@13/E8.tif | D24: 2990 | E24: 43.0151 | G24: 128615
A25: =IFERROR(LEFT(RIGHT(C25,LEN(C25)-SEARCH("@",C25)),SEARCH("/",RIGHT(C25,LEN(C25)-SEARCH("@",C25)-1))),"") -> 13 | B25: =LEFT(RIGHT(RIGHT(Tableau4[[#This Row],[file name]],LEN(Tableau4[[#This Row],[file name]])-SEARCH("@",Tableau4[[#This Row],[file name]])),LEN(RIGHT(Tableau4[[#This Row],[file name]],LEN(Tableau4[[#This Row],[file name]])-SEARCH("@",Tableau4[[#This Row],[file name]])))-SEARCH("/",RIGHT(Tableau4[[#This Row],[file name]],LEN(Tableau4[[#This Row],[file name]])-SEARCH("@",Tableau4[[#This Row],[file name]])))),1) -> 2 | C25: C:\Users\cbarrier\Desktop\Calibration\20201110_Cefas_Test3_Run1/@13/20201110_Cefas_Test3_Run1/@13/F8.tif | D25: 370 | E25: 34.6405 | G25: 12817
A26: =IFERROR(LEFT(RIGHT(C26,LEN(C26)-SEARCH("@",C26)),SEARCH("/",RIGHT(C26,LEN(C26)-SEARCH("@",C26)-1))),"") -> 13 | B26: =LEFT(RIGHT(RIGHT(Tableau4[[#This Row],[file name]],LEN(Tableau4[[#This Row],[file name]])-SEARCH("@",Tableau4[[#This Row],[file name]])),LEN(RIGHT(Tableau4[[#This Row],[file name]],LEN(Tableau4[[#This Row],[file name]])-SEARCH("@",Tableau4[[#This Row],[file name]])))-SEARCH("/",RIGHT(Tableau4[[#This Row],[file name]],LEN(Tableau4[[#This Row],[file name]])-SEARCH("@",Tableau4[[#This Row],[file name]])))),1) -> 2 | C26: C:\Users\cbarrier\Desktop\Calibration\20201110_Cefas_Test3_Run1/@13/20201110_Cefas_Test3_Run1/@13/G8.tif | D26: 2713 | E26: 50.4736 | G26: 136935
A27: =IFERROR(LEFT(RIGHT(C27,LEN(C27)-SEARCH("@",C27)),SEARCH("/",RIGHT(C27,LEN(C27)-SEARCH("@",C27)-1))),"") -> 13 | B27: =LEFT(RIGHT(RIGHT(Tableau4[[#This Row],[file name]],LEN(Tableau4[[#This Row],[file name]])-SEARCH("@",Tableau4[[#This Row],[file name]])),LEN(RIGHT(Tableau4[[#This Row],[file name]],LEN(Tableau4[[#This Row],[file name]])-SEARCH("@",Tableau4[[#This Row],[file name]])))-SEARCH("/",RIGHT(Tableau4[[#This Row],[file name]],LEN(Tableau4[[#This Row],[file name]])-SEARCH("@",Tableau4[[#This Row],[file name]])))),1) -> 2 | C27: C:\Users\cbarrier\Desktop\Calibration\20201110_Cefas_Test3_Run1/@13/20201110_Cefas_Test3_Run1/@13/H8.tif | D27: 2968 | E27: 45.4599 | G27: 134925
A28: =IFERROR(LEFT(RIGHT(C28,LEN(C28)-SEARCH("@",C28)),SEARCH("/",RIGHT(C28,LEN(C28)-SEARCH("@",C28)-1))),"") | B28: =LEFT(RIGHT(RIGHT(Tableau4[[#This Row],[file name]],LEN(Tableau4[[#This Row],[file name]])-SEARCH("@",Tableau4[[#This Row],[file name]])),LEN(RIGHT(Tableau4[[#This Row],[file name]],LEN(Tableau4[[#This Row],[file name]])-SEARCH("@",Tableau4[[#This Row],[file name]])))-SEARCH("/",RIGHT(Tableau4[[#This Row],[file name]],LEN(Tableau4[[#This Row],[file name]])-SEARCH("@",Tableau4[[#This Row],[file name]])))),1) -> #VALUE!
A29: =IFERROR(LEFT(RIGHT(C29,LEN(C29)-SEARCH("@",C29)),SEARCH("/",RIGHT(C29,LEN(C29)-SEARCH("@",C29)-1))),"") | B29: =LEFT(RIGHT(RIGHT(Tableau4[[#This Row],[file name]],LEN(Tableau4[[#This Row],[file name]])-SEARCH("@",Tableau4[[#This Row],[file name]])),LEN(RIGHT(Tableau4[[#This Row],[file name]],LEN(Tableau4[[#This Row],[file name]])-SEARCH("@",Tableau4[[#This Row],[file name]])))-SEARCH("/",RIGHT(Tableau4[[#This Row],[file name]],LEN(Tableau4[[#This Row],[file name]])-SEARCH("@",Tableau4[[#This Row],[file name]])))),1) -> #VALUE! | C29: group | E29: mean of mean fluo | F29: SD mean fluo | G29: mean of total fluo | H29: SD total fluo | I29: n fluorescent | J29: n total
A30: =IFERROR(LEFT(RIGHT(C30,LEN(C30)-SEARCH("@",C30)),SEARCH("/",RIGHT(C30,LEN(C30)-SEARCH("@",C30)-1))),"") -> 13 | B30: =LEFT(RIGHT(RIGHT(Tableau4[[#This Row],[file name]],LEN(Tableau4[[#This Row],[file name]])-SEARCH("@",Tableau4[[#This Row],[file name]])),LEN(RIGHT(Tableau4[[#This Row],[file name]],LEN(Tableau4[[#This Row],[file name]])-SEARCH("@",Tableau4[[#This Row],[file name]])))-SEARCH("/",RIGHT(Tableau4[[#This Row],[file name]],LEN(Tableau4[[#This Row],[file name]])-SEARCH("@",Tableau4[[#This Row],[file name]])))),1) | C30: C:\Users\cbarrier\Desktop\Calibration\20201110_Cefas_Test3_Run1/@13/ | E30: 41.2119 | F30: 5.3254 | G30: 85677.125 | H30: 50552.6322 | I30: 8 | J30: 8
A31: =IFERROR(LEFT(RIGHT(C31,LEN(C31)-SEARCH("@",C31)),SEARCH("/",RIGHT(C31,LEN(C31)-SEARCH("@",C31)-1))),"") | B31: =LEFT(RIGHT(RIGHT(Tableau4[[#This Row],[file name]],LEN(Tableau4[[#This Row],[file name]])-SEARCH("@",Tableau4[[#This Row],[file name]])),LEN(RIGHT(Tableau4[[#This Row],[file name]],LEN(Tableau4[[#This Row],[file name]])-SEARCH("@",Tableau4[[#This Row],[file name]])))-SEARCH("/",RIGHT(Tableau4[[#This Row],[file name]],LEN(Tableau4[[#This Row],[file name]])-SEARCH("@",Tableau4[[#This Row],[file name]])))),1) -> #VALUE!
A32: =IFERROR(LEFT(RIGHT(C32,LEN(C32)-SEARCH("@",C32)),SEARCH("/",RIGHT(C32,LEN(C32)-SEARCH("@",C32)-1))),"") | B32: =LEFT(RIGHT(RIGHT(Tableau4[[#This Row],[file name]],LEN(Tableau4[[#This Row],[file name]])-SEARCH("@",Tableau4[[#This Row],[file name]])),LEN(RIGHT(Tableau4[[#This Row],[file name]],LEN(Tableau4[[#This Row],[file name]])-SEARCH("@",Tableau4[[#This Row],[file name]])))-SEARCH("/",RIGHT(Tableau4[[#This Row],[file name]],LEN(Tableau4[[#This Row],[file name]])-SEARCH("@",Tableau4[[#This Row],[file name]])))),1) -> #VALUE!
A33: =IFERROR(LEFT(RIGHT(C33,LEN(C33)-SEARCH("@",C33)),SEARCH("/",RIGHT(C33,LEN(C33)-SEARCH("@",C33)-1))),"") | B33: =LEFT(RIGHT(RIGHT(Tableau4[[#This Row],[file name]],LEN(Tableau4[[#This Row],[file name]])-SEARCH("@",Tableau4[[#This Row],[file name]])),LEN(RIGHT(Tableau4[[#This Row],[file name]],LEN(Tableau4[[#This Row],[file name]])-SEARCH("@",Tableau4[[#This Row],[file name]])))-SEARCH("/",RIGHT(Tableau4[[#This Row],[file name]],LEN(Tableau4[[#This Row],[file name]])-SEARCH("@",Tableau4[[#This Row],[file name]])))),1) -> #VALUE!
A34: =IFERROR(LEFT(RIGHT(C34,LEN(C34)-SEARCH("@",C34)),SEARCH("/",RIGHT(C34,LEN(C34)-SEARCH("@",C34)-1))),"") | B34: =LEFT(RIGHT(RIGHT(Tableau4[[#This Row],[file name]],LEN(Tableau4[[#This Row],[file name]])-SEARCH("@",Tableau4[[#This Row],[file name]])),LEN(RIGHT(Tableau4[[#This Row],[file name]],LEN(Tableau4[[#This Row],[file name]])-SEARCH("@",Tableau4[[#This Row],[file name]])))-SEARCH("/",RIGHT(Tableau4[[#This Row],[file name]],LEN(Tableau4[[#This Row],[file name]])-SEARCH("@",Tableau4[[#This Row],[file name]])))),1) -> #VALUE!
A35: =IFERROR(LEFT(RIGHT(C35,LEN(C35)-SEARCH("@",C35)),SEARCH("/",RIGHT(C35,LEN(C35)-SEARCH("@",C35)-1))),"") | B35: =LEFT(RIGHT(RIGHT(Tableau4[[#This Row],[file name]],LEN(Tableau4[[#This Row],[file name]])-SEARCH("@",Tableau4[[#This Row],[file name]])),LEN(RIGHT(Tableau4[[#This Row],[file name]],LEN(Tableau4[[#This Row],[file name]])-SEARCH("@",Tableau4[[#This Row],[file name]])))-SEARCH("/",RIGHT(Tableau4[[#This Row],[file name]],LEN(Tableau4[[#This Row],[file name]])-SEARCH("@",Tableau4[[#This Row],[file name]])))),1) -> #VALUE!
A36: =IFERROR(LEFT(RIGHT(C36,LEN(C36)-SEARCH("@",C36)),SEARCH("/",RIGHT(C36,LEN(C36)-SEARCH("@",C36)-1))),"") | B36: =LEFT(RIGHT(RIGHT(Tableau4[[#This Row],[file name]],LEN(Tableau4[[#This Row],[file name]])-SEARCH("@",Tableau4[[#This Row],[file name]])),LEN(RIGHT(Tableau4[[#This Row],[file name]],LEN(Tableau4[[#This Row],[file name]])-SEARCH("@",Tableau4[[#This Row],[file name]])))-SEARCH("/",RIGHT(Tableau4[[#This Row],[file name]],LEN(Tableau4[[#This Row],[file name]])-SEARCH("@",Tableau4[[#This Row],[file name]])))),1) -> #VALUE! | C36: file name | D36: total area | E36: mean intensity | G36: total fluorescence
A37: =IFERROR(LEFT(RIGHT(C37,LEN(C37)-SEARCH("@",C37)),SEARCH("/",RIGHT(C37,LEN(C37)-SEARCH("@",C37)-1))),"") -> 14 | B37: =LEFT(RIGHT(RIGHT(Tableau4[[#This Row],[file name]],LEN(Tableau4[[#This Row],[file name]])-SEARCH("@",Tableau4[[#This Row],[file name]])),LEN(RIGHT(Tableau4[[#This Row],[file name]],LEN(Tableau4[[#This Row],[file name]])-SEARCH("@",Tableau4[[#This Row],[file name]])))-SEARCH("/",RIGHT(Tableau4[[#This Row],[file name]],LEN(Tableau4[[#This Row],[file name]])-SEARCH("@",Tableau4[[#This Row],[file name]])))),1) -> 2 | C37: C:\Users\cbarrier\Desktop\Calibration\20201110_Cefas_Test3_Run1/@14/20201110_Cefas_Test3_Run1/@14/A9- exclu.tif
A38: =IFERROR(LEFT(RIGHT(C38,LEN(C38)-SEARCH("@",C38)),SEARCH("/",RIGHT(C38,LEN(C38)-SEARCH("@",C38)-1))),"") -> 14 | B38: =LEFT(RIGHT(RIGHT(Tableau4[[#This Row],[file name]],LEN(Tableau4[[#This Row],[file name]])-SEARCH("@",Tableau4[[#This Row],[file name]])),LEN(RIGHT(Tableau4[[#This Row],[file name]],LEN(Tableau4[[#This Row],[file name]])-SEARCH("@",Tableau4[[#This Row],[file name]])))-SEARCH("/",RIGHT(Tableau4[[#This Row],[file name]],LEN(Tableau4[[#This Row],[file name]])-SEARCH("@",Tableau4[[#This Row],[file name]])))),1) -> 2 | C38: C:\Users\cbarrier\Desktop\Calibration\20201110_Cefas_Test3_Run1/@14/20201110_Cefas_Test3_Run1/@14/B9.tif | D38: 2444 | E38: 37.4247 | G38: 91466
A39: =IFERROR(LEFT(RIGHT(C39,LEN(C39)-SEARCH("@",C39)),SEARCH("/",RIGHT(C39,LEN(C39)-SEARCH("@",C39)-1))),"") -> 14 | B39: =LEFT(RIGHT(RIGHT(Tableau4[[#This Row],[file name]],LEN(Tableau4[[#This Row],[file name]])-SEARCH("@",Tableau4[[#This Row],[file name]])),LEN(RIGHT(Tableau4[[#This Row],[file name]],LEN(Tableau4[[#This Row],[file name]])-SEARCH("@",Tableau4[[#This Row],[file name]])))-SEARCH("/",RIGHT(Tableau4[[#This Row],[file name]],LEN(Tableau4[[#This Row],[file name]])-SEARCH("@",Tableau4[[#This Row],[file name]])))),1) -> 2 | C39: C:\Users\cbarrier\Desktop\Calibration\20201110_Cefas_Test3_Run1/@14/20201110_Cefas_Test3_Run1/@14/C9.tif | D39: 450 | E39: 33.4644 | G39: 15059
A40: =IFERROR(LEFT(RIGHT(C40,LEN(C40)-SEARCH("@",C40)),SEARCH("/",RIGHT(C40,LEN(C40)-SEARCH("@",C40)-1))),"") -> 14 | B40: =LEFT(RIGHT(RIGHT(Tableau4[[#This Row],[file name]],LEN(Tableau4[[#This Row],[file name]])-SEARCH("@",Tableau4[[#This Row],[file name]])),LEN(RIGHT(Tableau4[[#This Row],[file name]],LEN(Tableau4[[#This Row],[file name]])-SEARCH("@",Tableau4[[#This Row],[file name]])))-SEARCH("/",RIGHT(Tableau4[[#This Row],[file name]],LEN(Tableau4[[#This Row],[file name]])-SEARCH("@",Tableau4[[#This Row],[file name]])))),1) -> 2 | C40: C:\Users\cbarrier\Desktop\Calibration\20201110_Cefas_Test3_Run1/@14/20201110_Cefas_Test3_Run1/@14/D9.tif | D40: 2419 | E40: 40.1654 | G40: 97160
...

Sheet R1
A1: 3. Expérimentateur 1 : copier et coller les valeurs des intensités totales de fluorescences obtenues dans le fichier raw data lors du traitement des images.
A3: R1 | B3: Non dopé | J3: avec testo
A4: Noms des groupes | B4: ='Page de garde'!A7 -> Témoin solvant | C4: ='Page de garde'!A9 -> EE2-33,8ng/L | D4: ='Page de garde'!A10 -> EE2-50,6ng/L | E4: ='Page de garde'!A11 -> EE2-76ng/L | F4: ='Page de garde'!A12 -> EE2-114ng/L | G4: ='Page de garde'!A13 -> EE2-170,9ng/L | H4: ='Page de garde'!A14 -> EE2-488ng/L | J4: ='Page de garde'!A36 -> Testo -30µg/L | K4: ='Page de garde'!A37 -> Testo 30µg/L + EE2 -64ng/L | L4: ='Page de garde'!A38 -> Testo 30µg/L + FAD-10mg/L
A5: Données brutes | C5: ='Raw data R1'!G88 -> 16997 | D5: ='Raw data R1'!G105 -> 7725 | E5: ='Raw data R1'!G122 -> 4226 | G5: ='Raw data R1'!G156 -> 72128 | J5: ='Raw data R1'!G20 -> 91890 | K5: ='Raw data R1'!G54 -> 168782 | L5: ='Raw data R1'!G71 -> 3744
B6: ='Raw data R1'!G4 -> 4209 | C6: ='Raw data R1'!G89 -> 6244 | D6: ='Raw data R1'!G106 -> 9599 | E6: ='Raw data R1'!G123 -> 22487 | F6: ='Raw data R1'!G140 -> 22801 | G6: ='Raw data R1'!G157 -> 109241 | H6: ='Raw data R1'!G174 -> 212197 | J6: ='Raw data R1'!G21 -> 15670 | K6: ='Raw data R1'!G55 -> 170359 | L6: ='Raw data R1'!G72 -> 10945
B7: ='Raw data R1'!G5 -> 3382 | C7: ='Raw data R1'!G90 -> 20326 | D7: ='Raw data R1'!G107 -> 25340 | E7: ='Raw data R1'!G124 -> 15514 | F7: ='Raw data R1'!G141 -> 0 | G7: ='Raw data R1'!G158 -> 81161 | H7: ='Raw data R1'!G175 -> 180227 | J7: ='Raw data R1'!G22 -> 63291 | K7: ='Raw data R1'!G56 -> 173175
B8: ='Raw data R1'!G6 -> 1871 | C8: ='Raw data R1'!G91 -> 5217 | D8: ='Raw data R1'!G108 -> 17447 | E8: ='Raw data R1'!G125 -> 2959 | F8: ='Raw data R1'!G142 -> 71554 | G8: ='Raw data R1'!G159 -> 34302 | H8: ='Raw data R1'!G176 -> 147117 | J8: ='Raw data R1'!G23 -> 101274 | K8: ='Raw data R1'!G57 -> 224011
B9: ='Raw data R1'!G7 -> 311 | C9: ='Raw data R1'!G92 -> 4614 | D9: ='Raw data R1'!G109 -> 2231 | E9: ='Raw data R1'!G126 -> 5217 | F9: ='Raw data R1'!G143 -> 8531 | G9: ='Raw data R1'!G160 -> 15204 | H9: ='Raw data R1'!G177 -> 171179 | J9: ='Raw data R1'!G24 -> 128615 | K9: ='Raw data R1'!G58 -> 122186 | L9: ='Raw data R1'!G75 -> 4775
B10: ='Raw data R1'!G8 -> 5307 | C10: ='Raw data R1'!G93 -> 15082 | E10: ='Raw data R1'!G127 -> 47643 | F10: ='Raw data R1'!G144 -> 5071 | G10: ='Raw data R1'!G161 -> 172748 | H10: ='Raw data R1'!G178 -> 186014 | J10: ='Raw data R1'!G25 -> 12817 | L10: ='Raw data R1'!G76 -> 2787
B11: ='Raw data R1'!G9 -> 3551 | C11: ='Raw data R1'!G94 -> 400 | D11: ='Raw data R1'!G111 -> 0 | E11: ='Raw data R1'!G128 -> 968 | F11: ='Raw data R1'!G145 -> 129490 | G11: ='Raw data R1'!G162 -> 103987 | H11: ='Raw data R1'!G179 -> 37059 | J11: ='Raw data R1'!G26 -> 136935 | K11: ='Raw data R1'!G60 -> 176138 | L11: ='Raw data R1'!G77 -> 614
B12: ='Raw data R1'!G10 -> 3203 | C12: ='Raw data R1'!G95 -> 17951 | D12: ='Raw data R1'!G112 -> 842 | E12: ='Raw data R1'!G129 -> 3271 | F12: ='Raw data R1'!G146 -> 48109 | G12: ='Raw data R1'!G163 -> 25034 | H12: ='Raw data R1'!G180 -> 213632 | J12: ='Raw data R1'!G27 -> 134925 | K12: ='Raw data R1'!G61 -> 165168 | L12: ='Raw data R1'!G78 -> 3902
J14: ='Raw data R1'!G38 -> 91466
J15: ='Raw data R1'!G39 -> 15059
J16: ='Raw data R1'!G40 -> 97160
J17: ='Raw data R1'!G41 -> 31226
J18: ='Raw data R1'!G42 -> 109993
J19: ='Raw data R1'!G43 -> 74636
J20: ='Raw data R1'!G44 -> 86075
A22: =A4 -> Noms des groupes | B22: =B4 -> Témoin solvant | C22: =C4 -> EE2-33,8ng/L | D22: =D4 -> EE2-50,6ng/L | E22: =E4 -> EE2-76ng/L | F22: =F4 -> EE2-114ng/L | G22: =G4 -> EE2-170,9ng/L | H22: =H4 -> EE2-488ng/L | I22: Nom des groupes | J22: =J4 -> Testo -30µg/L | K22: =K4 -> Testo 30µg/L + EE2 -64ng/L | L22: =L4 -> Testo 30µg/L + FAD-10mg/L
A23: mean | B23: =AVERAGE(B5:B20) -> 3119.1429 | C23: =AVERAGE(C5:C20) -> 10853.875 | D23: =AVERAGE(D5:D20) -> 9026.2857 | E23: =AVERAGE(E5:E20) -> 12785.625 | F23: =AVERAGE(F5:F20) -> 40793.714 | G23: =AVERAGE(G5:G20) -> 76725.625 | H23: =AVERAGE(H5:H20) -> 163917.86 | I23: mean | J23: =AVERAGE(J5:J20) -> 79402.133 | K23: =AVERAGE(K5:K20) -> 171402.71 | L23: =AVERAGE(L5:L20) -> 4461.1667
A24: SD | B24: =STDEV(B5:B20) -> 1616.6148 | C24: =STDEV(C5:C20) -> 7530.4165 | D24: =STDEV(D5:D20) -> 9431.3248 | E24: =STDEV(E5:E20) -> 15918.971 | F24: =STDEV(F5:F20) -> 46853.672 | G24: =STDEV(G5:G20) -> 52533.306 | H24: =STDEV(H5:H20) -> 60532.033 | I24: SD | J24: =STDEV(J5:J20) -> 43201.262 | K24: =STDEV(K5:K20) -> 29615.057 | L24: =STDEV(L5:L20) -> 3480.4915
B26: Non dopé | J26: avec testo
A27: Noms des groupes | B27: =B4 -> Témoin solvant | C27: =C4 -> EE2-33,8ng/L | D27: =D4 -> EE2-50,6ng/L | E27: =E4 -> EE2-76ng/L | F27: =F4 -> EE2-114ng/L | G27: =G4 -> EE2-170,9ng/L | H27: =H4 -> EE2-488ng/L | J27: =J4 -> Testo -30µg/L | K27: =K4 -> Testo 30µg/L + EE2 -64ng/L | L27: =L4 -> Testo 30µg/L + FAD-10mg/L
A28: Données normalisées sur la moyenne du groupe "Testo" | B28: =IF(B5="","",(B5/$J$23)) | C28: =IF(C5="","",(C5/$J$23)) -> 0.21406226 | D28: =IF(D5="","",(D5/$J$23)) -> 0.097289577 | E28: =IF(E5="","",(E5/$J$23)) -> 0.053222751 | F28: =IF(F5="","",(F5/$J$23)) | G28: =IF(G5="","",(G5/$J$23)) -> 0.90838869 | H28: =IF(H5="","",(H5/$J$23)) | J28: =IF(J5="","",(J5/$J$23)) -> 1.1572737 | K28: =IF(K5="","",(K5/$J$23)) -> 2.1256608 | L28: =IF(L5="","",(L5/$J$23)) -> 0.047152385
B29: =IF(B6="","",(B6/$J$23)) -> 0.053008651 | C29: =IF(C6="","",(C6/$J$23)) -> 0.078637686 | D29: =IF(D6="","",(D6/$J$23)) -> 0.12089096 | E29: =IF(E6="","",(E6/$J$23)) -> 0.28320398 | F29: =IF(F6="","",(F6/$J$23)) -> 0.28715853 | G29: =IF(G6="","",(G6/$J$23)) -> 1.3757943 | H29: =IF(H6="","",(H6/$J$23)) -> 2.6724345 | J29: =IF(J6="","",(J6/$J$23)) -> 0.19734986 | K29: =IF(K6="","",(K6/$J$23)) -> 2.1455217 | L29: =IF(L6="","",(L6/$J$23)) -> 0.13784264
B30: =IF(B7="","",(B7/$J$23)) -> 0.042593314 | C30: =IF(C7="","",(C7/$J$23)) -> 0.25598808 | D30: =IF(D7="","",(D7/$J$23)) -> 0.319135 | E30: =IF(E7="","",(E7/$J$23)) -> 0.19538518 | F30: =IF(F7="","",(F7/$J$23)) -> 0 | G30: =IF(G7="","",(G7/$J$23)) -> 1.0221514 | H30: =IF(H7="","",(H7/$J$23)) -> 2.2698005 | J30: =IF(J7="","",(J7/$J$23)) -> 0.79709445 | K30: =IF(K7="","",(K7/$J$23)) -> 2.1809867 | L30: =IF(L7="","",(L7/$J$23))
B31: =IF(B8="","",(B8/$J$23)) -> 0.023563599 | C31: =IF(C8="","",(C8/$J$23)) -> 0.065703524 | D31: =IF(D8="","",(D8/$J$23)) -> 0.21972961 | E31: =IF(E8="","",(E8/$J$23)) -> 0.037266001 | F31: =IF(F8="","",(F8/$J$23)) -> 0.90115967 | G31: =IF(G8="","",(G8/$J$23)) -> 0.43200351 | H31: =IF(H8="","",(H8/$J$23)) -> 1.8528092 | J31: =IF(J8="","",(J8/$J$23)) -> 1.2754569 | K31: =IF(K8="","",(K8/$J$23)) -> 2.8212214 | L31: =IF(L8="","",(L8/$J$23))
B32: =IF(B9="","",(B9/$J$23)) -> 0.0039167713 | C32: =IF(C9="","",(C9/$J$23)) -> 0.05810927 | D32: =IF(D9="","",(D9/$J$23)) -> 0.028097482 | E32: =IF(E9="","",(E9/$J$23)) -> 0.065703524 | F32: =IF(F9="","",(F9/$J$23)) -> 0.10744044 | G32: =IF(G9="","",(G9/$J$23)) -> 0.191481 | H32: =IF(H9="","",(H9/$J$23)) -> 2.1558489 | J32: =IF(J9="","",(J9/$J$23)) -> 1.6197928 | K32: =IF(K9="","",(K9/$J$23)) -> 1.5388252 | L32: =IF(L9="","",(L9/$J$23)) -> 0.060136923
B33: =IF(B10="","",(B10/$J$23)) -> 0.066836995 | C33: =IF(C10="","",(C10/$J$23)) -> 0.18994452 | D33: =IF(D10="","",(D10/$J$23)) | E33: =IF(E10="","",(E10/$J$23)) -> 0.60002166 | F33: =IF(F10="","",(F10/$J$23)) -> 0.063864783 | G33: =IF(G10="","",(G10/$J$23)) -> 2.1756091 | H33: =IF(H10="","",(H10/$J$23)) -> 2.3426826 | J33: =IF(J10="","",(J10/$J$23)) -> 0.16141884 | K33: =IF(K10="","",(K10/$J$23)) | L33: =IF(L10="","",(L10/$J$23)) -> 0.035099813
B34: =IF(B11="","",(B11/$J$23)) -> 0.04472172 | C34: =IF(C11="","",(C11/$J$23)) -> 0.005037648 | D34: =IF(D11="","",(D11/$J$23)) -> 0 | E34: =IF(E11="","",(E11/$J$23)) -> 0.012191108 | F34: =IF(F11="","",(F11/$J$23)) -> 1.6308126 | G34: =IF(G11="","",(G11/$J$23)) -> 1.3096248 | H34: =IF(H11="","",(H11/$J$23)) -> 0.4667255 | J34: =IF(J11="","",(J11/$J$23)) -> 1.7245758 | K34: =IF(K11="","",(K11/$J$23)) -> 2.2183031 | L34: =IF(L11="","",(L11/$J$23)) -> 0.0077327897
B35: =IF(B12="","",(B12/$J$23)) -> 0.040338967 | C35: =IF(C12="","",(C12/$J$23)) -> 0.22607705 | D35: =IF(D12="","",(D12/$J$23)) -> 0.010604249 | E35: =IF(E12="","",(E12/$J$23)) -> 0.041195367 | F35: =IF(F12="","",(F12/$J$23)) -> 0.60589052 | G35: =IF(G12="","",(G12/$J$23)) -> 0.3152812 | H35: =IF(H12="","",(H12/$J$23)) -> 2.6905071 | J35: =IF(J12="","",(J12/$J$23)) -> 1.6992616 | K35: =IF(K12="","",(K12/$J$23)) -> 2.0801456 | L35: =IF(L12="","",(L12/$J$23)) -> 0.049142256
B36: =IF(B13="","",(B13/$J$23)) | C36: =IF(C13="","",(C13/$J$23)) | D36: =IF(D13="","",(D13/$J$23)) | E36: =IF(E13="","",(E13/$J$23)) | F36: =IF(F13="","",(F13/$J$23)) | G36: =IF(G13="","",(G13/$J$23)) | H36: =IF(H13="","",(H13/$J$23)) | J36: =IF(J13="","",(J13/$J$23)) | K36: =IF(K13="","",(K13/$J$23)) | L36: =IF(L13="","",(L13/$J$23))
B37: =IF(B14="","",(B14/$J$23)) | C37: =IF(C14="","",(C14/$J$23)) | D37: =IF(D14="","",(D14/$J$23)) | E37: =IF(E14="","",(E14/$J$23)) | F37: =IF(F14="","",(F14/$J$23)) | G37: =IF(G14="","",(G14/$J$23)) | H37: =IF(H14="","",(H14/$J$23)) | J37: =IF(J14="","",(J14/$J$23)) -> 1.1519338 | K37: =IF(K14="","",(K14/$J$23)) | L37: =IF(L14="","",(L14/$J$23))
B38: =IF(B15="","",(B15/$J$23)) | C38: =IF(C15="","",(C15/$J$23)) | D38: =IF(D15="","",(D15/$J$23)) | E38: =IF(E15="","",(E15/$J$23)) | F38: =IF(F15="","",(F15/$J$23)) | G38: =IF(G15="","",(G15/$J$23)) | H38: =IF(H15="","",(H15/$J$23)) | J38: =IF(J15="","",(J15/$J$23)) -> 0.18965485 | K38: =IF(K15="","",(K15/$J$23)) | L38: =IF(L15="","",(L15/$J$23))
B39: =IF(B16="","",(B16/$J$23)) | C39: =IF(C16="","",(C16/$J$23)) | D39: =IF(D16="","",(D16/$J$23)) | E39: =IF(E16="","",(E16/$J$23)) | F39: =IF(F16="","",(F16/$J$23)) | G39: =IF(G16="","",(G16/$J$23)) | H39: =IF(H16="","",(H16/$J$23)) | J39: =IF(J16="","",(J16/$J$23)) -> 1.2236447 | K39: =IF(K16="","",(K16/$J$23)) | L39: =IF(L16="","",(L16/$J$23))
B40: =IF(B17="","",(B17/$J$23)) | C40: =IF(C17="","",(C17/$J$23)) | D40: =IF(D17="","",(D17/$J$23)) | E40: =IF(E17="","",(E17/$J$23)) | F40: =IF(F17="","",(F17/$J$23)) | G40: =IF(G17="","",(G17/$J$23)) | H40: =IF(H17="","",(H17/$J$23)) | J40: =IF(J17="","",(J17/$J$23)) -> 0.39326399 | K40: =IF(K17="","",(K17/$J$23)) | L40: =IF(L17="","",(L17/$J$23))
... B43: =IF(B20="","",(B20/$J$23)) | C43: =IF(C20="","",(C20/$J$23)) | D43: =IF(D20="","",(D20/$J$23)) | E43: =IF(E20="","",(E20/$J$23)) | F43: =IF(F20="","",(F20/$J$23)) | G43: =IF(G20="","",(G20/$J$23)) | H43: =IF(H20="","",(H20/$J$23)) | J43: =IF(J20="","",(J20/$J$23)) -> 1.0840389 | K43: =IF(K20="","",(K20/$J$23)) | L43: =IF(L20="","",(L20/$J$23))
A45: =A4 -> Noms des groupes | B45: =B4 -> Témoin solvant | C45: =C4 -> EE2-33,8ng/L | D45: =D4 -> EE2-50,6ng/L | E45: =E4 -> EE2-76ng/L | F45: =F4 -> EE2-114ng/L | G45: =G4 -> EE2-170,9ng/L | H45: =H4 -> EE2-488ng/L | I45: =I22 -> Nom des groupes | J45: =J4 -> Testo -30µg/L | K45: =K4 -> Testo 30µg/L + EE2 -64ng/L | L45: =L4 -> Testo 30µg/L + FAD-10mg/L
A46: mean | B46: =AVERAGE(B28:B43) -> 0.03928286 | C46: =AVERAGE(C28:C43) -> 0.136695 | D46: =AVERAGE(D28:D43) -> 0.11367813 | E46: =AVERAGE(E28:E43) -> 0.1610237 | F46: =AVERAGE(F28:F43) -> 0.51376094 | G46: =AVERAGE(G28:G43) -> 0.96629173 | H46: =AVERAGE(H28:H43) -> 2.0644012 | I46: mean | J46: =AVERAGE(J28:J43) -> 1 | K46: =AVERAGE(K28:K43) -> 2.1586664 | L46: =AVERAGE(L28:L43) -> 0.056184469
A47: SD | B47: =STDEV(B28:B43) -> 0.020359841 | C47: =STDEV(C28:C43) -> 0.09483897 | D47: =STDEV(D28:D43) -> 0.11877924 | E47: =STDEV(E28:E43) -> 0.20048543 | F47: =STDEV(F28:F43) -> 0.59008077 | G47: =STDEV(G28:G43) -> 0.66161076 | H47: =STDEV(H28:H43) -> 0.76234769 | I47: SD | J47: =STDEV(J28:J43) -> 0.54408188 | K47: =STDEV(K28:K43) -> 0.37297559 | L47: =STDEV(L28:L43) -> 0.043833728
...

Sheet Raw data R2
A1: Nom groupe | B1: N° de valeur | C1: file name | D1: total area | E1: mean intensity | G1: total fluorescence | I1: nbre de larves | J1: Colonne1 | L1: (Tous)
A2: =IFERROR(LEFT(RIGHT(C2,LEN(C2)-SEARCH("@",C2)),SEARCH("/",RIGHT(C2,LEN(C2)-SEARCH("@",C2)-1))),"") -> 1 | B2: =LEFT(RIGHT(RIGHT(Tableau46[[#This Row],[file name]],LEN(Tableau46[[#This Row],[file name]])-SEARCH("@",Tableau46[[#This Row],[file name]])),LEN(RIGHT(Tableau46[[#This Row],[file name]],LEN(Tableau46[[#This Row],[file name]])-SEARCH("@",Tableau46[[#This Row],[file name]])))-SEARCH("/",RIGHT(Tableau46[[#This Row],[file name]],LEN(Tableau46[[#This Row],[file name]])-SEARCH("@",Tableau46[[#This Row],[file name]])))),1) -> 0 | C2: C:\Users\cbarrier\Desktop\Calibration\20201111_Cefas_Test4_Run2\@1/01_A10_A10-1_20201111_14011001.tif | D2: 379583.021 | E2: 44.6723 | G2: 16956864 | K2: Filtre lignes : Enlever (vide) et Néant | L2: Filtre colonnes : Enlever (vide) et " "
A3: =IFERROR(LEFT(RIGHT(C3,LEN(C3)-SEARCH("@",C3)),SEARCH("/",RIGHT(C3,LEN(C3)-SEARCH("@",C3)-1))),"") -> 1 | B3: =LEFT(RIGHT(RIGHT(Tableau46[[#This Row],[file name]],LEN(Tableau46[[#This Row],[file name]])-SEARCH("@",Tableau46[[#This Row],[file name]])),LEN(RIGHT(Tableau46[[#This Row],[file name]],LEN(Tableau46[[#This Row],[file name]])-SEARCH("@",Tableau46[[#This Row],[file name]])))-SEARCH("/",RIGHT(Tableau46[[#This Row],[file name]],LEN(Tableau46[[#This Row],[file name]])-SEARCH("@",Tableau46[[#This Row],[file name]])))),1) -> 0 | C3: C:\Users\cbarrier\Desktop\Calibration\20201111_Cefas_Test4_Run2\@1/01_B10_B10-1_20201111_14011401.tif | D3: 399396.004 | E3: 41.8538 | G3: 16716231 | K3: Moyenne de total fluorescence | L3: Étiquettes de colonnes
