Workbook

Sheet Front page
A2: R1 | B2: Experiment number : | E2: Date performed :
A3: R2 | B3: Experiment number : | E3: Date performed :
A4: R3 | B4: Experiment number : | E4: Date performed :
A6: Do not fill in | B6: Do not fill in2 | C6: Concentration | D6: Units | E6: Chemical name | F6: Do not fill in3
A7: =IF(ISBLANK(liste_groupe[[#This Row],[Do not fill in2]])," ",IF(ISBLANK(liste_groupe[[#This Row],[Units]]),CONCATENATE(liste_groupe[[#This Row],[Chemical name]],liste_groupe[[#This Row],[Do not fill in3]]),CONCATENATE(liste_groupe[[#This Row],[Chemical name]],"-",liste_groupe[[#This Row],[Concentration]],liste_groupe[[#This Row],[Units]],liste_groupe[[#This Row],[Do not fill in3]]))) -> Solvent control | B7: Control | E7: Solvent control
A8: =IF(ISBLANK(liste_groupe[[#This Row],[Do not fill in2]])," ",IF(ISBLANK(liste_groupe[[#This Row],[Units]]),CONCATENATE(liste_groupe[[#This Row],[Chemical name]],liste_groupe[[#This Row],[Do not fill in3]]),CONCATENATE(liste_groupe[[#This Row],[Chemical name]],"-",liste_groupe[[#This Row],[Concentration]],liste_groupe[[#This Row],[Units]],liste_groupe[[#This Row],[Do not fill in3]]))) -> EE2-33.8ng/L | B8: Control | C8: 33.8 | D8: ng/L | E8: EE2
A9: =IF(ISBLANK(liste_groupe[[#This Row],[Do not fill in2]])," ",IF(ISBLANK(liste_groupe[[#This Row],[Units]]),CONCATENATE(liste_groupe[[#This Row],[Chemical name]],liste_groupe[[#This Row],[Do not fill in3]]),CONCATENATE(liste_groupe[[#This Row],[Chemical name]],"-",liste_groupe[[#This Row],[Concentration]],liste_groupe[[#This Row],[Units]],liste_groupe[[#This Row],[Do not fill in3]]))) -> EE2-50.6ng/L | B9: Control | C9: 50.6 | D9: ng/L | E9: EE2
A10: =IF(ISBLANK(liste_groupe[[#This Row],[Do not fill in2]])," ",IF(ISBLANK(liste_groupe[[#This Row],[Units]]),CONCATENATE(liste_groupe[[#This Row],[Chemical name]],liste_groupe[[#This Row],[Do not fill in3]]),CONCATENATE(liste_groupe[[#This Row],[Chemical name]],"-",liste_groupe[[#This Row],[Concentration]],liste_groupe[[#This Row],[Units]],liste_groupe[[#This Row],[Do not fill in3]]))) -> EE2-76ng/L | B10: Control | C10: 76 | D10: ng/L | E10: EE2
A11: =IF(ISBLANK(liste_groupe[[#This Row],[Do not fill in2]])," ",IF(ISBLANK(liste_groupe[[#This Row],[Units]]),CONCATENATE(liste_groupe[[#This Row],[Chemical name]],liste_groupe[[#This Row],[Do not fill in3]]),CONCATENATE(liste_groupe[[#This Row],[Chemical name]],"-",liste_groupe[[#This Row],[Concentration]],liste_groupe[[#This Row],[Units]],liste_groupe[[#This Row],[Do not fill in3]]))) -> EE2-114ng/L | B11: Control | C11: 114 | D11: ng/L | E11: EE2
A12: =IF(ISBLANK(liste_groupe[[#This Row],[Do not fill in2]])," ",IF(ISBLANK(liste_groupe[[#This Row],[Units]]),CONCATENATE(liste_groupe[[#This Row],[Chemical name]],liste_groupe[[#This Row],[Do not fill in3]]),CONCATENATE(liste_groupe[[#This Row],[Chemical name]],"-",liste_groupe[[#This Row],[Concentration]],liste_groupe[[#This Row],[Units]],liste_groupe[[#This Row],[Do not fill in3]]))) -> EE2-170.9ng/L | B12: Control | C12: 170.9 | D12: ng/L | E12: EE2
A13: =IF(ISBLANK(liste_groupe[[#This Row],[Do not fill in2]])," ",IF(ISBLANK(liste_groupe[[#This Row],[Units]]),CONCATENATE(liste_groupe[[#This Row],[Chemical name]],liste_groupe[[#This Row],[Do not fill in3]]),CONCATENATE(liste_groupe[[#This Row],[Chemical name]],"-",liste_groupe[[#This Row],[Concentration]],liste_groupe[[#This Row],[Units]],liste_groupe[[#This Row],[Do not fill in3]]))) -> EE2-488ng/L | B13: Control | C13: 488 | D13: ng/L | E13: EE2
A14: =IF(ISBLANK(liste_groupe[[#This Row],[Do not fill in2]])," ",IF(ISBLANK(liste_groupe[[#This Row],[Units]]),CONCATENATE(liste_groupe[[#This Row],[Chemical name]],liste_groupe[[#This Row],[Do not fill in3]]),CONCATENATE(liste_groupe[[#This Row],[Chemical name]],"-",liste_groupe[[#This Row],[Concentration]],liste_groupe[[#This Row],[Units]],liste_groupe[[#This Row],[Do not fill in3]]))) -> Amantadine-0.001mg/L | B14: test chemical | C14: 0.001 | D14: mg/L | E14: Amantadine
A15: =IF(ISBLANK(liste_groupe[[#This Row],[Do not fill in2]])," ",IF(ISBLANK(liste_groupe[[#This Row],[Units]]),CONCATENATE(liste_groupe[[#This Row],[Chemical name]],liste_groupe[[#This Row],[Do not fill in3]]),CONCATENATE(liste_groupe[[#This Row],[Chemical name]],"-",liste_groupe[[#This Row],[Concentration]],liste_groupe[[#This Row],[Units]],liste_groupe[[#This Row],[Do not fill in3]]))) -> Amantadine-0.01mg/L | B15: test chemical | C15: 0.01 | D15: mg/L | E15: Amantadine
A16: =IF(ISBLANK(liste_groupe[[#This Row],[Do not fill in2]])," ",IF(ISBLANK(liste_groupe[[#This Row],[Units]]),CONCATENATE(liste_groupe[[#This Row],[Chemical name]],liste_groupe[[#This Row],[Do not fill in3]]),CONCATENATE(liste_groupe[[#This Row],[Chemical name]],"-",liste_groupe[[#This Row],[Concentration]],liste_groupe[[#This Row],[Units]],liste_groupe[[#This Row],[Do not fill in3]]))) -> Amantadine-0.1mg/L | B16: test chemical | C16: 0.1 | D16: mg/L | E16: Amantadine
A17: =IF(ISBLANK(liste_groupe[[#This Row],[Do not fill in2]])," ",IF(ISBLANK(liste_groupe[[#This Row],[Units]]),CONCATENATE(liste_groupe[[#This Row],[Chemical name]],liste_groupe[[#This Row],[Do not fill in3]]),CONCATENATE(liste_groupe[[#This Row],[Chemical name]],"-",liste_groupe[[#This Row],[Concentration]],liste_groupe[[#This Row],[Units]],liste_groupe[[#This Row],[Do not fill in3]]))) -> Amantadine-1mg/L | B17: test chemical | C17: 1 | D17: mg/L | E17: Amantadine
A18: =IF(ISBLANK(liste_groupe[[#This Row],[Do not fill in2]])," ",IF(ISBLANK(liste_groupe[[#This Row],[Units]]),CONCATENATE(liste_groupe[[#This Row],[Chemical name]],liste_groupe[[#This Row],[Do not fill in3]]),CONCATENATE(liste_groupe[[#This Row],[Chemical name]],"-",liste_groupe[[#This Row],[Concentration]],liste_groupe[[#This Row],[Units]],liste_groupe[[#This Row],[Do not fill in3]]))) -> Amantadine-10mg/L | B18: test chemical | C18: 10 | D18: mg/L | E18: Amantadine
A19: =IF(ISBLANK(liste_groupe[[#This Row],[Do not fill in2]])," ",IF(ISBLANK(liste_groupe[[#This Row],[Units]]),CONCATENATE(liste_groupe[[#This Row],[Chemical name]],liste_groupe[[#This Row],[Do not fill in3]]),CONCATENATE(liste_groupe[[#This Row],[Chemical name]],"-",liste_groupe[[#This Row],[Concentration]],liste_groupe[[#This Row],[Units]],liste_groupe[[#This Row],[Do not fill in3]]))) | B19: test chemical
A20: =IF(ISBLANK(liste_groupe[[#This Row],[Do not fill in2]])," ",IF(ISBLANK(liste_groupe[[#This Row],[Units]]),CONCATENATE(liste_groupe[[#This Row],[Chemical name]],liste_groupe[[#This Row],[Do not fill in3]]),CONCATENATE(liste_groupe[[#This Row],[Chemical name]],"-",liste_groupe[[#This Row],[Concentration]],liste_groupe[[#This Row],[Units]],liste_groupe[[#This Row],[Do not fill in3]]))) | B20: test chemical
A21: =IF(ISBLANK(liste_groupe[[#This Row],[Do not fill in2]])," ",IF(ISBLANK(liste_groupe[[#This Row],[Units]]),CONCATENATE(liste_groupe[[#This Row],[Chemical name]],liste_groupe[[#This Row],[Do not fill in3]]),CONCATENATE(liste_groupe[[#This Row],[Chemical name]],"-",liste_groupe[[#This Row],[Concentration]],liste_groupe[[#This Row],[Units]],liste_groupe[[#This Row],[Do not fill in3]]))) | B21: test chemical
A22: =IF(ISBLANK(liste_groupe[[#This Row],[Do not fill in2]])," ",IF(ISBLANK(liste_groupe[[#This Row],[Units]]),CONCATENATE(liste_groupe[[#This Row],[Chemical name]],liste_groupe[[#This Row],[Do not fill in3]]),CONCATENATE(liste_groupe[[#This Row],[Chemical name]],"-",liste_groupe[[#This Row],[Concentration]],liste_groupe[[#This Row],[Units]],liste_groupe[[#This Row],[Do not fill in3]]))) | B22: test chemical
A23: =IF(ISBLANK(liste_groupe[[#This Row],[Do not fill in2]])," ",IF(ISBLANK(liste_groupe[[#This Row],[Units]]),CONCATENATE(liste_groupe[[#This Row],[Chemical name]],liste_groupe[[#This Row],[Do not fill in3]]),CONCATENATE(liste_groupe[[#This Row],[Chemical name]],"-",liste_groupe[[#This Row],[Concentration]],liste_groupe[[#This Row],[Units]],liste_groupe[[#This Row],[Do not fill in3]]))) | B23: test chemical
A24: =IF(ISBLANK(liste_groupe[[#This Row],[Do not fill in2]])," ",IF(ISBLANK(liste_groupe[[#This Row],[Units]]),CONCATENATE(liste_groupe[[#This Row],[Chemical name]],liste_groupe[[#This Row],[Do not fill in3]]),CONCATENATE(liste_groupe[[#This Row],[Chemical name]],"-",liste_groupe[[#This Row],[Concentration]],liste_groupe[[#This Row],[Units]],liste_groupe[[#This Row],[Do not fill in3]]))) | B24: test chemical
A25: =IF(ISBLANK(liste_groupe[[#This Row],[Do not fill in2]])," ",IF(ISBLANK(liste_groupe[[#This Row],[Units]]),CONCATENATE(liste_groupe[[#This Row],[Chemical name]],liste_groupe[[#This Row],[Do not fill in3]]),CONCATENATE(liste_groupe[[#This Row],[Chemical name]],"-",liste_groupe[[#This Row],[Concentration]],liste_groupe[[#This Row],[Units]],liste_groupe[[#This Row],[Do not fill in3]]))) | B25: test chemical
A26: =IF(ISBLANK(liste_groupe[[#This Row],[Do not fill in2]])," ",IF(ISBLANK(liste_groupe[[#This Row],[Units]]),CONCATENATE(liste_groupe[[#This Row],[Chemical name]],liste_groupe[[#This Row],[Do not fill in3]]),CONCATENATE(liste_groupe[[#This Row],[Chemical name]],"-",liste_groupe[[#This Row],[Concentration]],liste_groupe[[#This Row],[Units]],liste_groupe[[#This Row],[Do not fill in3]]))) | B26: test chemical
A27: =IF(ISBLANK(liste_groupe[[#This Row],[Do not fill in2]])," ",IF(ISBLANK(liste_groupe[[#This Row],[Units]]),CONCATENATE(liste_groupe[[#This Row],[Chemical name]],liste_groupe[[#This Row],[Do not fill in3]]),CONCATENATE(liste_groupe[[#This Row],[Chemical name]],"-",liste_groupe[[#This Row],[Concentration]],liste_groupe[[#This Row],[Units]],liste_groupe[[#This Row],[Do not fill in3]]))) | B27: test chemical
A28: =IF(ISBLANK(liste_groupe[[#This Row],[Do not fill in2]])," ",IF(ISBLANK(liste_groupe[[#This Row],[Units]]),CONCATENATE(liste_groupe[[#This Row],[Chemical name]],liste_groupe[[#This Row],[Do not fill in3]]),CONCATENATE(liste_groupe[[#This Row],[Chemical name]],"-",liste_groupe[[#This Row],[Concentration]],liste_groupe[[#This Row],[Units]],liste_groupe[[#This Row],[Do not fill in3]]))) | B28: test chemical
A29: =IF(ISBLANK(liste_groupe[[#This Row],[Do not fill in2]])," ",IF(ISBLANK(liste_groupe[[#This Row],[Units]]),CONCATENATE(liste_groupe[[#This Row],[Chemical name]],liste_groupe[[#This Row],[Do not fill in3]]),CONCATENATE(liste_groupe[[#This Row],[Chemical name]],"-",liste_groupe[[#This Row],[Concentration]],liste_groupe[[#This Row],[Units]],liste_groupe[[#This Row],[Do not fill in3]]))) | B29: test chemical
A30: =IF(ISBLANK(liste_groupe[[#This Row],[Do not fill in2]])," ",IF(ISBLANK(liste_groupe[[#This Row],[Units]]),CONCATENATE(liste_groupe[[#This Row],[Chemical name]],liste_groupe[[#This Row],[Do not fill in3]]),CONCATENATE(liste_groupe[[#This Row],[Chemical name]],"-",liste_groupe[[#This Row],[Concentration]],liste_groupe[[#This Row],[Units]],liste_groupe[[#This Row],[Do not fill in3]]))) | B30: test chemical
... A34: =IF(ISBLANK(liste_groupe[[#This Row],[Do not fill in2]])," ",IF(ISBLANK(liste_groupe[[#This Row],[Units]]),CONCATENATE(liste_groupe[[#This Row],[Chemical name]],liste_groupe[[#This Row],[Do not fill in3]]),CONCATENATE(liste_groupe[[#This Row],[Chemical name]],"-",liste_groupe[[#This Row],[Concentration]],liste_groupe[[#This Row],[Units]],liste_groupe[[#This Row],[Do not fill in3]]))) | B34: test chemical
A35: =IF(ISBLANK(liste_groupe[[#This Row],[Do not fill in2]])," ",IF(ISBLANK(liste_groupe[[#This Row],[Units]]),CONCATENATE(liste_groupe[[#This Row],[Chemical name]],liste_groupe[[#This Row],[Do not fill in3]]),CONCATENATE(liste_groupe[[#This Row],[Chemical name]],"-",liste_groupe[[#This Row],[Concentration]],liste_groupe[[#This Row],[Units]],liste_groupe[[#This Row],[Do not fill in3]]))) -> Testo -30µg/L | B35: Control | C35: 30 | D35: µg/L | E35: Testo
A36: =IF(ISBLANK(liste_groupe[[#This Row],[Do not fill in2]])," ",IF(ISBLANK(liste_groupe[[#This Row],[Units]]),CONCATENATE(liste_groupe[[#This Row],[Chemical name]],liste_groupe[[#This Row],[Do not fill in3]]),CONCATENATE(liste_groupe[[#This Row],[Chemical name]],"-",liste_groupe[[#This Row],[Concentration]],liste_groupe[[#This Row],[Units]],liste_groupe[[#This Row],[Do not fill in3]]))) -> Testo 30µg/L + EE2 -64ng/L | B36: Control | C36: 64 | D36: ng/L | E36: Testo 30µg/L + EE2
A37: =IF(ISBLANK(liste_groupe[[#This Row],[Do not fill in2]])," ",IF(ISBLANK(liste_groupe[[#This Row],[Units]]),CONCATENATE(liste_groupe[[#This Row],[Chemical name]],liste_groupe[[#This Row],[Do not fill in3]]),CONCATENATE(liste_groupe[[#This Row],[Chemical name]],"-",liste_groupe[[#This Row],[Concentration]],liste_groupe[[#This Row],[Units]],liste_groupe[[#This Row],[Do not fill in3]]))) -> Testo 30µg/L + FAD-10mg/L | B37: Control | C37: 10 | D37: mg/L | E37: Testo 30µg/L + FAD
A38: =IF(ISBLANK(liste_groupe[[#This Row],[Do not fill in2]])," ",IF(ISBLANK(liste_groupe[[#This Row],[Units]]),CONCATENATE(liste_groupe[[#This Row],[Chemical name]],liste_groupe[[#This Row],[Do not fill in3]]),CONCATENATE(liste_groupe[[#This Row],[Chemical name]],"-",liste_groupe[[#This Row],[Concentration]],liste_groupe[[#This Row],[Units]],liste_groupe[[#This Row],[Do not fill in3]]))) -> Amantadine-0.001mg/L + Testostérone | B38: =B14 -> test chemical | C38: =C14 -> 0.001 | D38: =D14 -> mg/L | E38: =E14 -> Amantadine | F38: + Testostérone
A39: =IF(ISBLANK(liste_groupe[[#This Row],[Do not fill in2]])," ",IF(ISBLANK(liste_groupe[[#This Row],[Units]]),CONCATENATE(liste_groupe[[#This Row],[Chemical name]],liste_groupe[[#This Row],[Do not fill in3]]),CONCATENATE(liste_groupe[[#This Row],[Chemical name]],"-",liste_groupe[[#This Row],[Concentration]],liste_groupe[[#This Row],[Units]],liste_groupe[[#This Row],[Do not fill in3]]))) -> Amantadine-0.01mg/L + Testostérone | B39: =B15 -> test chemical | C39: =C15 -> 0.01 | D39: =D15 -> mg/L | E39: =E15 -> Amantadine | F39: + Testostérone
A40: =IF(ISBLANK(liste_groupe[[#This Row],[Do not fill in2]])," ",IF(ISBLANK(liste_groupe[[#This Row],[Units]]),CONCATENATE(liste_groupe[[#This Row],[Chemical name]],liste_groupe[[#This Row],[Do not fill in3]]),CONCATENATE(liste_groupe[[#This Row],[Chemical name]],"-",liste_groupe[[#This Row],[Concentration]],liste_groupe[[#This Row],[Units]],liste_groupe[[#This Row],[Do not fill in3]]))) -> Amantadine-0.1mg/L + Testostérone | B40: =B16 -> test chemical | C40: =C16 -> 0.1 | D40: =D16 -> mg/L | E40: =E16 -> Amantadine | F40: + Testostérone
A41: =IF(ISBLANK(liste_groupe[[#This Row],[Do not fill in2]])," ",IF(ISBLANK(liste_groupe[[#This Row],[Units]]),CONCATENATE(liste_groupe[[#This Row],[Chemical name]],liste_groupe[[#This Row],[Do not fill in3]]),CONCATENATE(liste_groupe[[#This Row],[Chemical name]],"-",liste_groupe[[#This Row],[Concentration]],liste_groupe[[#This Row],[Units]],liste_groupe[[#This Row],[Do not fill in3]]))) -> Amantadine-1mg/L + Testostérone | B41: =B17 -> test chemical | C41: =C17 -> 1 | D41: =D17 -> mg/L | E41: =E17 -> Amantadine | F41: + Testostérone
A42: =IF(ISBLANK(liste_groupe[[#This Row],[Do not fill in2]])," ",IF(ISBLANK(liste_groupe[[#This Row],[Units]]),CONCATENATE(liste_groupe[[#This Row],[Chemical name]],liste_groupe[[#This Row],[Do not fill in3]]),CONCATENATE(liste_groupe[[#This Row],[Chemical name]],"-",liste_groupe[[#This Row],[Concentration]],liste_groupe[[#This Row],[Units]],liste_groupe[[#This Row],[Do not fill in3]]))) -> Amantadine-10mg/L + Testostérone | B42: =B18 -> test chemical | C42: =C18 -> 10 | D42: =D18 -> mg/L | E42: =E18 -> Amantadine | F42: + Testostérone
A43: =IF(ISBLANK(liste_groupe[[#This Row],[Do not fill in2]])," ",IF(ISBLANK(liste_groupe[[#This Row],[Units]]),CONCATENATE(liste_groupe[[#This Row],[Chemical name]],liste_groupe[[#This Row],[Do not fill in3]]),CONCATENATE(liste_groupe[[#This Row],[Chemical name]],"-",liste_groupe[[#This Row],[Concentration]],liste_groupe[[#This Row],[Units]],liste_groupe[[#This Row],[Do not fill in3]]))) -> 0-00 + Testostérone | B43: =B19 -> test chemical | C43: =C19 -> 0 | D43: =D19 -> 0 | E43: =E19 -> 0 | F43: + Testostérone
A44: =IF(ISBLANK(liste_groupe[[#This Row],[Do not fill in2]])," ",IF(ISBLANK(liste_groupe[[#This Row],[Units]]),CONCATENATE(liste_groupe[[#This Row],[Chemical name]],liste_groupe[[#This Row],[Do not fill in3]]),CONCATENATE(liste_groupe[[#This Row],[Chemical name]],"-",liste_groupe[[#This Row],[Concentration]],liste_groupe[[#This Row],[Units]],liste_groupe[[#This Row],[Do not fill in3]]))) -> 0-00 + Testostérone | B44: =B20 -> test chemical | C44: =C20 -> 0 | D44: =D20 -> 0 | E44: =E20 -> 0 | F44: + Testostérone
A45: =IF(ISBLANK(liste_groupe[[#This Row],[Do not fill in2]])," ",IF(ISBLANK(liste_groupe[[#This Row],[Units]]),CONCATENATE(liste_groupe[[#This Row],[Chemical name]],liste_groupe[[#This Row],[Do not fill in3]]),CONCATENATE(liste_groupe[[#This Row],[Chemical name]],"-",liste_groupe[[#This Row],[Concentration]],liste_groupe[[#This Row],[Units]],liste_groupe[[#This Row],[Do not fill in3]]))) -> 0-00 + Testostérone | B45: =B21 -> test chemical | C45: =C21 -> 0 | D45: =D21 -> 0 | E45: =E21 -> 0 | F45: + Testostérone
...

Sheet Comments
A2: Start of the exposure: 15h45 (09.02.2022) start of reading : 15h30 (10.02.2022) (end of the reading 18h30)
A4: R1: contamination in the bottle 1 mg/L of amantadine, because of the lid.
A5: 7 embryos dead in the whole plate of amantadine, as we knew the replicats will be excluded because of the deads, we did not read the amantadine + testo plate
A6: The bottle 1 mg/L was changed
A8: In the group Testo + Fadrozole : only 7 pictures because a technical problem when the picture was saved (half of the picture is gray). We can get rid of the value or do another analysis with a croped picture?
A11: R1 done another time, because too much deads in the first R1.
A12: R1bis: Start of the exposure : 10.02, start of reading 12h until 15h
A13: R1bis : Only 4 embryos in the amantadine 0,1 mg/L well
A14: 1 dead and the 3 others where light up…. Contamination again?

Sheet R1
A3: R1 | B3: Unspiked | O3: Testosterone spiked
A4: Group names | B4: ='Front page'!A7 -> Solvent control | C4: ='Front page'!A8 -> EE2-33.8ng/L | D4: ='Front page'!A9 -> EE2-50.6ng/L | E4: ='Front page'!A10 -> EE2-76ng/L | F4: ='Front page'!A11 -> EE2-114ng/L | G4: ='Front page'!A12 -> EE2-170.9ng/L | H4: ='Front page'!A13 -> EE2-488ng/L | I4: ='Front page'!A14 -> Amantadine-0.001mg/L | J4: ='Front page'!A15 -> Amantadine-0.01mg/L | K4: ='Front page'!A16 -> Amantadine-0.1mg/L | L4: ='Front page'!A17 -> Amantadine-1mg/L | M4: ='Front page'!A18 -> Amantadine-10mg/L | O4: ='Front page'!A35 -> Testo -30µg/L | P4: ='Front page'!A36 -> Testo 30µg/L + EE2 -64ng/L | Q4: ='Front page'!A37 -> Testo 30µg/L + FAD-10mg/L | R4: ='Front page'!A38 -> Amantadine-0.001mg/L + Testostérone | S4: ='Front page'!A39 -> Amantadine-0.01mg/L + Testostérone | T4: ='Front page'!A40 -> Amantadine-0.1mg/L + Testostérone | U4: ='Front page'!A41 -> Amantadine-1mg/L + Testostérone | V4: ='Front page'!A42 -> Amantadine-10mg/L + Testostérone
A5: Raw data | B5: 222638 | C5: 332014 | D5: 462085 | E5: 318858 | F5: 1776859 | G5: 3699243 | H5: 4642912 | I5: 43831 | J5: 159532 | K5: 589442 | L5: 365803 | M5: 183726 | O5: 867403 | P5: 6131601 | Q5: 47135 | R5: 2267246 | S5: 814227 | T5: 3000897 | U5: 958702 | V5: 179158
B6: 16975 | C6: 663076 | D6: 521807 | E6: 905913 | F6: 4979776 | G6: 4253571 | H6: 8705082 | I6: 145896 | J6: 19094 | K6: 89016 | L6: 120486 | M6: 124422 | O6: 1550874 | P6: 5173886 | Q6: 44044 | R6: 710689 | S6: 2395040 | T6: 2835924 | U6: 2713263 | V6: 1217802
B7: 22029 | C7: 49973 | D7: 1784193 | E7: 343890 | F7: 4305872 | G7: 6565690 | H7: 8249044 | I7: 582534 | J7: 296079 | K7: 133372 | L7: 82771 | M7: 107719 | O7: 3675296 | P7: 4934501 | Q7: 64043 | R7: 1068730 | S7: 2834863 | T7: 2791345 | U7: 287227 | V7: 1491620
B8: 253918 | C8: 93822 | D8: 567762 | E8: 1772095 | F8: 2297666 | G8: 5433344 | H8: 6385360 | I8: 67649 | J8: 410120 | K8: 258541 | L8: 109472 | M8: 175386 | O8: 1521673 | P8: 5807811 | Q8: 43905 | R8: 2282390 | S8: 1469457 | T8: 2148400 | U8: 211128 | V8: 525788
B9: 143827 | C9: 112468 | D9: 480896 | E9: 1339325 | F9: 2748581 | G9: 4974674 | H9: 6478983 | I9: 79311 | J9: 135157 | K9: 58250 | L9: 16898 | M9: 166767 | O9: 1714008 | P9: 8835686 | Q9: 123795 | R9: 546861 | S9: 1219233 | T9: 862723 | U9: 1112492 | V9: 380033
B10: 118649 | C10: 85329 | D10: 761322 | E10: 2511109 | F10: 3731308 | G10: 4141934 | H10: 5890947 | I10: 116937 | J10: 118516 | K10: 22244 | L10: 109748 | M10: 20269 | O10: 2092881 | P10: 6849271 | Q10: 154427 | R10: 1008328 | S10: 4103156 | T10: 2029357 | U10: 628156 | V10: 9819
B11: 222019 | C11: 10859 | D11: 440522 | E11: 443388 | F11: 3632376 | G11: 5253269 | H11: 5785384 | I11: 116722 | J11: 140440 | K11: 132250 | L11: 122127 | M11: 78118 | O11: 49009 | P11: 4942199 | Q11: 8215 | R11: 673308 | S11: 1015345 | T11: 2709208 | U11: 3242334 | V11: 1688555
O12: 3246280 | R12: 3748497 | S12: 3121591 | T12: 1245888 | U12: 520160 | V12: 1553265
O13: 3815465
O14: 3044358
O15: 532549
O16: 2808474
O17: 43634
O18: 3572235
A22: =A4 -> Group names | B22: =B4 -> Solvent control | C22: =C4 -> EE2-33.8ng/L | D22: =D4 -> EE2-50.6ng/L | E22: =E4 -> EE2-76ng/L | F22: =F4 -> EE2-114ng/L | G22: =G4 -> EE2-170.9ng/L | H22: =H4 -> EE2-488ng/L | ... M22: =M4 -> Amantadine-10mg/L | N22: Nom des groupes | O22: =O4 -> Testo -30µg/L | P22: =P4 -> Testo 30µg/L + EE2 -64ng/L | Q22: =Q4 -> Testo 30µg/L + FAD-10mg/L | R22: =R4 -> Amantadine-0.001mg/L + Testostérone | S22: =S4 -> Amantadine-0.01mg/L + Testostérone | T22: =T4 -> Amantadine-0.1mg/L + Testostérone | U22: =U4 -> Amantadine-1mg/L + Testostérone | V22: =V4 -> Amantadine-10mg/L + Testostérone
A23: mean | B23: =AVERAGE(B5:B20) -> 142865 | C23: =AVERAGE(C5:C20) -> 192505.86 | D23: =AVERAGE(D5:D20) -> 716941 | E23: =AVERAGE(E5:E20) -> 1090654 | F23: =AVERAGE(F5:F20) -> 3353205.4 | G23: =AVERAGE(G5:G20) -> 4903103.6 | H23: =AVERAGE(H5:H20) -> 6591101.7 | I23: =AVERAGE(I5:I20) -> 164697.14 | ... M23: =AVERAGE(M5:M20) -> 122343.86 | N23: mean | O23: =AVERAGE(O5:O20) -> 2038152.8 | P23: =AVERAGE(P5:P20) -> 6096422.1 | Q23: =AVERAGE(Q5:Q20) -> 69366.286 | R23: =AVERAGE(R5:R20) -> 1538256.1 | S23: =AVERAGE(S5:S20) -> 2121614 | T23: =AVERAGE(T5:T20) -> 2202967.8 | U23: =AVERAGE(U5:U20) -> 1209182.8 | V23: =AVERAGE(V5:V20) -> 880755
A24: SD | B24: =STDEV(B5:B20) -> 96608.167 | C24: =STDEV(C5:C20) -> 231603.62 | D24: =STDEV(D5:D20) -> 482770.55 | E24: =STDEV(E5:E20) -> 831695.01 | F24: =STDEV(F5:F20) -> 1135694 | G24: =STDEV(G5:G20) -> 968128.66 | H24: =STDEV(H5:H20) -> 1426383.9 | I24: =STDEV(I5:I20) -> 187457.34 | ... M24: =STDEV(M5:M20) -> 59368.987 | N24: SD | O24: =STDEV(O5:O20) -> 1342857.3 | P24: =STDEV(P5:P20) -> 1395722.4 | Q24: =STDEV(Q5:Q20) -> 51233.701 | R24: =STDEV(R5:R20) -> 1126782.5 | S24: =STDEV(S5:S20) -> 1176109.9 | T24: =STDEV(T5:T20) -> 791487.54 | U24: =STDEV(U5:U20) -> 1141835.1 | V24: =STDEV(V5:V20) -> 678133.91
B26: Unspiked | O26: Testosterone spiked
A27: =A4 -> Group names | B27: =B4 -> Solvent control | C27: =C4 -> EE2-33.8ng/L | D27: =D4 -> EE2-50.6ng/L | E27: =E4 -> EE2-76ng/L | F27: =F4 -> EE2-114ng/L | G27: =G4 -> EE2-170.9ng/L | H27: =H4 -> EE2-488ng/L | ... M27: =M4 -> Amantadine-10mg/L | O27: =O4 -> Testo -30µg/L | P27: =P4 -> Testo 30µg/L + EE2 -64ng/L | Q27: =Q4 -> Testo 30µg/L + FAD-10mg/L | R27: =R4 -> Amantadine-0.001mg/L + Testostérone | S27: =S4 -> Amantadine-0.01mg/L + Testostérone | T27: =T4 -> Amantadine-0.1mg/L + Testostérone | U27: =U4 -> Amantadine-1mg/L + Testostérone | V27: =V4 -> Amantadine-10mg/L + Testostérone
A28: Data normalised to the "Testo" group | B28: =IF(B5="","",(B5/$O$23)) -> 0.10923519 | C28: =IF(C5="","",(C5/$O$23)) -> 0.16289947 | D28: =IF(D5="","",(D5/$O$23)) -> 0.22671755 | E28: =IF(E5="","",(E5/$O$23)) -> 0.1564446 | F28: =IF(F5="","",(F5/$O$23)) -> 0.87179873 | G28: =IF(G5="","",(G5/$O$23)) -> 1.8149979 | H28: =IF(H5="","",(H5/$O$23)) -> 2.278 | I28: =IF(I5="","",(I5/$O$23)) -> 0.021505257 | ... M28: =IF(M5="","",(M5/$O$23)) -> 0.090143389 | O28: =IF(O5="","",(O5/$O$23)) -> 0.42558291 | P28: =IF(P5="","",(P5/$O$23)) -> 3.0084109 | Q28: =IF(Q5="","",(Q5/$O$23)) -> 0.023126333 | R28: =IF(R5="","",(R5/$O$23)) -> 1.1124024 | S28: =IF(S5="","",(S5/$O$23)) -> 0.39949262 | T28: =IF(T5="","",(T5/$O$23)) -> 1.4723612 | U28: =IF(U5="","",(U5/$O$23)) -> 0.47037789 | V28: =IF(V5="","",(V5/$O$23)) -> 0.087902144
B29: =IF(B6="","",(B6/$O$23)) -> 0.00832862 | C29: =IF(C6="","",(C6/$O$23)) -> 0.32533184 | D29: =IF(D6="","",(D6/$O$23)) -> 0.25601957 | E29: =IF(E6="","",(E6/$O$23)) -> 0.44447747 | F29: =IF(F6="","",(F6/$O$23)) -> 2.443279 | G29: =IF(G6="","",(G6/$O$23)) -> 2.0869736 | H29: =IF(H6="","",(H6/$O$23)) -> 4.2710645 | I29: =IF(I6="","",(I6/$O$23)) -> 0.071582465 | ... M29: =IF(M6="","",(M6/$O$23)) -> 0.061046454 | O29: =IF(O6="","",(O6/$O$23)) -> 0.76092137 | P29: =IF(P6="","",(P6/$O$23)) -> 2.5385172 | Q29: =IF(Q6="","",(Q6/$O$23)) -> 0.021609764 | R29: =IF(R6="","",(R6/$O$23)) -> 0.3486927 | S29: =IF(S6="","",(S6/$O$23)) -> 1.1751033 | T29: =IF(T6="","",(T6/$O$23)) -> 1.3914187 | U29: =IF(U6="","",(U6/$O$23)) -> 1.3312363 | V29: =IF(V6="","",(V6/$O$23)) -> 0.5975028
B30: =IF(B7="","",(B7/$O$23)) -> 0.010808316 | C30: =IF(C7="","",(C7/$O$23)) -> 0.02451877 | D30: =IF(D7="","",(D7/$O$23)) -> 0.87539708 | E30: =IF(E7="","",(E7/$O$23)) -> 0.16872631 | F30: =IF(F7="","",(F7/$O$23)) -> 2.1126346 | G30: =IF(G7="","",(G7/$O$23)) -> 3.2213925 | H30: =IF(H7="","",(H7/$O$23)) -> 4.0473139 | I30: =IF(I7="","",(I7/$O$23)) -> 0.28581469 | ... M30: =IF(M7="","",(M7/$O$23)) -> 0.052851288 | O30: =IF(O7="","",(O7/$O$23)) -> 1.8032485 | P30: =IF(P7="","",(P7/$O$23)) -> 2.4210653 | Q30: =IF(Q7="","",(Q7/$O$23)) -> 0.03142208 | R30: =IF(R7="","",(R7/$O$23)) -> 0.52436206 | S30: =IF(S7="","",(S7/$O$23)) -> 1.3908982 | T30: =IF(T7="","",(T7/$O$23)) -> 1.3695465 | U30: =IF(U7="","",(U7/$O$23)) -> 0.14092516 | V30: =IF(V7="","",(V7/$O$23)) -> 0.73184896
B31: =IF(B8="","",(B8/$O$23)) -> 0.12458242 | C31: =IF(C8="","",(C8/$O$23)) -> 0.046032859 | D31: =IF(D8="","",(D8/$O$23)) -> 0.27856695 | E31: =IF(E8="","",(E8/$O$23)) -> 0.86946131 | F31: =IF(F8="","",(F8/$O$23)) -> 1.1273277 | G31: =IF(G8="","",(G8/$O$23)) -> 2.6658178 | H31: =IF(H8="","",(H8/$O$23)) -> 3.1329153 | I31: =IF(I8="","",(I8/$O$23)) -> 0.033191329 | ... M31: =IF(M8="","",(M8/$O$23)) -> 0.086051449 | O31: =IF(O8="","",(O8/$O$23)) -> 0.74659418 | P31: =IF(P8="","",(P8/$O$23)) -> 2.8495464 | Q31: =IF(Q8="","",(Q8/$O$23)) -> 0.021541565 | R31: =IF(R8="","",(R8/$O$23)) -> 1.1198326 | S31: =IF(S8="","",(S8/$O$23)) -> 0.7209749 | T31: =IF(T8="","",(T8/$O$23)) -> 1.0540917 | U31: =IF(U8="","",(U8/$O$23)) -> 0.10358792 | V31: =IF(V8="","",(V8/$O$23)) -> 0.25797281
B32: =IF(B9="","",(B9/$O$23)) -> 0.07056733 | C32: =IF(C9="","",(C9/$O$23)) -> 0.055181339 | D32: =IF(D9="","",(D9/$O$23)) -> 0.23594698 | E32: =IF(E9="","",(E9/$O$23)) -> 0.65712689 | F32: =IF(F9="","",(F9/$O$23)) -> 1.3485647 | G32: =IF(G9="","",(G9/$O$23)) -> 2.4407758 | H32: =IF(H9="","",(H9/$O$23)) -> 3.1788505 | I32: =IF(I9="","",(I9/$O$23)) -> 0.038913177 | ... M32: =IF(M9="","",(M9/$O$23)) -> 0.08182262 | O32: =IF(O9="","",(O9/$O$23)) -> 0.84096149 | P32: =IF(P9="","",(P9/$O$23)) -> 4.3351441 | Q32: =IF(Q9="","",(Q9/$O$23)) -> 0.060738822 | R32: =IF(R9="","",(R9/$O$23)) -> 0.26831207 | S32: =IF(S9="","",(S9/$O$23)) -> 0.59820491 | T32: =IF(T9="","",(T9/$O$23)) -> 0.42328672 | U32: =IF(U9="","",(U9/$O$23)) -> 0.54583347 | V32: =IF(V9="","",(V9/$O$23)) -> 0.18645952
B33: =IF(B10="","",(B10/$O$23)) -> 0.058213987 | C33: =IF(C10="","",(C10/$O$23)) -> 0.041865851 | D33: =IF(D10="","",(D10/$O$23)) -> 0.37353529 | E33: =IF(E10="","",(E10/$O$23)) -> 1.2320514 | F33: =IF(F10="","",(F10/$O$23)) -> 1.8307303 | G33: =IF(G10="","",(G10/$O$23)) -> 2.0322 | H33: =IF(H10="","",(H10/$O$23)) -> 2.8903363 | I33: =IF(I10="","",(I10/$O$23)) -> 0.057374011 | ... M33: =IF(M10="","",(M10/$O$23)) -> 0.0099447893 | O33: =IF(O10="","",(O10/$O$23)) -> 1.0268519 | P33: =IF(P10="","",(P10/$O$23)) -> 3.3605287 | Q33: =IF(Q10="","",(Q10/$O$23)) -> 0.075768118 | R33: =IF(R10="","",(R10/$O$23)) -> 0.4947264 | S33: =IF(S10="","",(S10/$O$23)) -> 2.0131739 | T33: =IF(T10="","",(T10/$O$23)) -> 0.99568443 | U33: =IF(U10="","",(U10/$O$23)) -> 0.30819868 | V33: =IF(V10="","",(V10/$O$23)) -> 0.0048175976
B34: =IF(B11="","",(B11/$O$23)) -> 0.10893148 | C34: =IF(C11="","",(C11/$O$23)) -> 0.0053278636 | D34: =IF(D11="","",(D11/$O$23)) -> 0.21613787 | E34: =IF(E11="","",(E11/$O$23)) -> 0.21754404 | F34: =IF(F11="","",(F11/$O$23)) -> 1.7821902 | G34: =IF(G11="","",(G11/$O$23)) -> 2.5774658 | H34: =IF(H11="","",(H11/$O$23)) -> 2.8385428 | I34: =IF(I11="","",(I11/$O$23)) -> 0.057268523 | ... M34: =IF(M11="","",(M11/$O$23)) -> 0.038327843 | O34: =IF(O11="","",(O11/$O$23)) -> 0.024045793 | P34: =IF(P11="","",(P11/$O$23)) -> 2.4248423 | Q34: =IF(Q11="","",(Q11/$O$23)) -> 0.0040306105 | R34: =IF(R11="","",(R11/$O$23)) -> 0.33035207 | S34: =IF(S11="","",(S11/$O$23)) -> 0.49816923 | T34: =IF(T11="","",(T11/$O$23)) -> 1.3292468 | U34: =IF(U11="","",(U11/$O$23)) -> 1.5908199 | V34: =IF(V11="","",(V11/$O$23)) -> 0.82847322
B35: =IF(B12="","",(B12/$O$23)) | C35: =IF(C12="","",(C12/$O$23)) | D35: =IF(D12="","",(D12/$O$23)) | E35: =IF(E12="","",(E12/$O$23)) | F35: =IF(F12="","",(F12/$O$23)) | G35: =IF(G12="","",(G12/$O$23)) | H35: =IF(H12="","",(H12/$O$23)) | I35: =IF(I12="","",(I12/$O$23)) | ... M35: =IF(M12="","",(M12/$O$23)) | O35: =IF(O12="","",(O12/$O$23)) -> 1.592756 | P35: =IF(P12="","",(P12/$O$23)) | Q35: =IF(Q12="","",(Q12/$O$23)) | R35: =IF(R12="","",(R12/$O$23)) -> 1.8391639 | S35: =IF(S12="","",(S12/$O$23)) -> 1.5315785 | T35: =IF(T12="","",(T12/$O$23)) -> 0.61128293 | U35: =IF(U12="","",(U12/$O$23)) -> 0.25521149 | V35: =IF(V12="","",(V12/$O$23)) -> 0.76209449
B36: =IF(B13="","",(B13/$O$23)) | C36: =IF(C13="","",(C13/$O$23)) | D36: =IF(D13="","",(D13/$O$23)) | E36: =IF(E13="","",(E13/$O$23)) | F36: =IF(F13="","",(F13/$O$23)) | G36: =IF(G13="","",(G13/$O$23)) | H36: =IF(H13="","",(H13/$O$23)) | I36: =IF(I13="","",(I13/$O$23)) | ... M36: =IF(M13="","",(M13/$O$23)) | O36: =IF(O13="","",(O13/$O$23)) -> 1.8720211 | P36: =IF(P13="","",(P13/$O$23)) | Q36: =IF(Q13="","",(Q13/$O$23)) | R36: =IF(R13="","",(R13/$O$23)) | S36: =IF(S13="","",(S13/$O$23)) | T36: =IF(T13="","",(T13/$O$23)) | U36: =IF(U13="","",(U13/$O$23)) | V36: =IF(V13="","",(V13/$O$23))
B37: =IF(B14="","",(B14/$O$23)) | C37: =IF(C14="","",(C14/$O$23)) | D37: =IF(D14="","",(D14/$O$23)) | E37: =IF(E14="","",(E14/$O$23)) | F37: =IF(F14="","",(F14/$O$23)) | G37: =IF(G14="","",(G14/$O$23)) | H37: =IF(H14="","",(H14/$O$23)) | I37: =IF(I14="","",(I14/$O$23)) | ... M37: =IF(M14="","",(M14/$O$23)) | O37: =IF(O14="","",(O14/$O$23)) -> 1.4936849 | P37: =IF(P14="","",(P14/$O$23)) | Q37: =IF(Q14="","",(Q14/$O$23)) | R37: =IF(R14="","",(R14/$O$23)) | S37: =IF(S14="","",(S14/$O$23)) | T37: =IF(T14="","",(T14/$O$23)) | U37: =IF(U14="","",(U14/$O$23)) | V37: =IF(V14="","",(V14/$O$23))
B38: =IF(B15="","",(B15/$O$23)) | C38: =IF(C15="","",(C15/$O$23)) | D38: =IF(D15="","",(D15/$O$23)) | E38: =IF(E15="","",(E15/$O$23)) | F38: =IF(F15="","",(F15/$O$23)) | G38: =IF(G15="","",(G15/$O$23)) | H38: =IF(H15="","",(H15/$O$23)) | I38: =IF(I15="","",(I15/$O$23)) | ... M38: =IF(M15="","",(M15/$O$23)) | O38: =IF(O15="","",(O15/$O$23)) -> 0.26129003 | P38: =IF(P15="","",(P15/$O$23)) | Q38: =IF(Q15="","",(Q15/$O$23)) | R38: =IF(R15="","",(R15/$O$23)) | S38: =IF(S15="","",(S15/$O$23)) | T38: =IF(T15="","",(T15/$O$23)) | U38: =IF(U15="","",(U15/$O$23)) | V38: =IF(V15="","",(V15/$O$23))
B39: =IF(B16="","",(B16/$O$23)) | C39: =IF(C16="","",(C16/$O$23)) | D39: =IF(D16="","",(D16/$O$23)) | E39: =IF(E16="","",(E16/$O$23)) | F39: =IF(F16="","",(F16/$O$23)) | G39: =IF(G16="","",(G16/$O$23)) | H39: =IF(H16="","",(H16/$O$23)) | I39: =IF(I16="","",(I16/$O$23)) | ... M39: =IF(M16="","",(M16/$O$23)) | O39: =IF(O16="","",(O16/$O$23)) -> 1.3779507 | P39: =IF(P16="","",(P16/$O$23)) | Q39: =IF(Q16="","",(Q16/$O$23)) | R39: =IF(R16="","",(R16/$O$23)) | S39: =IF(S16="","",(S16/$O$23)) | T39: =IF(T16="","",(T16/$O$23)) | U39: =IF(U16="","",(U16/$O$23)) | V39: =IF(V16="","",(V16/$O$23))
B40: =IF(B17="","",(B17/$O$23)) | C40: =IF(C17="","",(C17/$O$23)) | D40: =IF(D17="","",(D17/$O$23)) | E40: =IF(E17="","",(E17/$O$23)) | F40: =IF(F17="","",(F17/$O$23)) | G40: =IF(G17="","",(G17/$O$23)) | H40: =IF(H17="","",(H17/$O$23)) | I40: =IF(I17="","",(I17/$O$23)) | ... M40: =IF(M17="","",(M17/$O$23)) | O40: =IF(O17="","",(O17/$O$23)) -> 0.021408601 | P40: =IF(P17="","",(P17/$O$23)) | Q40: =IF(Q17="","",(Q17/$O$23)) | R40: =IF(R17="","",(R17/$O$23)) | S40: =IF(S17="","",(S17/$O$23)) | T40: =IF(T17="","",(T17/$O$23)) | U40: =IF(U17="","",(U17/$O$23)) | V40: =IF(V17="","",(V17/$O$23))
... B43: =IF(B20="","",(B20/$O$23)) | C43: =IF(C20="","",(C20/$O$23)) | D43: =IF(D20="","",(D20/$O$23)) | E43: =IF(E20="","",(E20/$O$23)) | F43: =IF(F20="","",(F20/$O$23)) | G43: =IF(G20="","",(G20/$O$23)) | H43: =IF(H20="","",(H20/$O$23)) | I43: =IF(I20="","",(I20/$O$23)) | ... M43: =IF(M20="","",(M20/$O$23)) | O43: =IF(O20="","",(O20/$O$23)) | P43: =IF(P20="","",(P20/$O$23)) | Q43: =IF(Q20="","",(Q20/$O$23)) | R43: =IF(R20="","",(R20/$O$23)) | S43: =IF(S20="","",(S20/$O$23)) | T43: =IF(T20="","",(T20/$O$23)) | U43: =IF(U20="","",(U20/$O$23)) | V43: =IF(V20="","",(V20/$O$23))
A45: =A4 -> Group names | B45: =B4 -> Solvent control | C45: =C4 -> EE2-33.8ng/L | D45: =D4 -> EE2-50.6ng/L | E45: =E4 -> EE2-76ng/L | F45: =F4 -> EE2-114ng/L | G45: =G4 -> EE2-170.9ng/L | H45: =H4 -> EE2-488ng/L | ... M45: =M4 -> Amantadine-10mg/L | N45: =N22 -> Nom des groupes | O45: =O4 -> Testo -30µg/L | P45: =P4 -> Testo 30µg/L + EE2 -64ng/L | Q45: =Q4 -> Testo 30µg/L + FAD-10mg/L | R45: =R4 -> Amantadine-0.001mg/L + Testostérone | S45: =S4 -> Amantadine-0.01mg/L + Testostérone | T45: =T4 -> Amantadine-0.1mg/L + Testostérone | U45: =U4 -> Amantadine-1mg/L + Testostérone | V45: =V4 -> Amantadine-10mg/L + Testostérone
A46: mean | B46: =AVERAGE(B28:B43) -> 0.070095334 | C46: =AVERAGE(C28:C43) -> 0.094451141 | D46: =AVERAGE(D28:D43) -> 0.35176018 | E46: =AVERAGE(E28:E43) -> 0.53511886 | F46: =AVERAGE(F28:F43) -> 1.6452179 | G46: =AVERAGE(G28:G43) -> 2.4056605 | H46: =AVERAGE(H28:H43) -> 3.2338605 | I46: =AVERAGE(I28:I43) -> 0.080807064 | ... M46: =AVERAGE(M28:M43) -> 0.060026833 | N46: mean | O46: =AVERAGE(O28:O43) -> 1 | P46: =AVERAGE(P28:P43) -> 2.9911507 | Q46: =AVERAGE(Q28:Q43) -> 0.034033899 | R46: =AVERAGE(R28:R43) -> 0.75473053 | S46: =AVERAGE(S28:S43) -> 1.0409494 | T46: =AVERAGE(T28:T43) -> 1.0808649 | U46: =AVERAGE(U28:U43) -> 0.59327385 | V46: =AVERAGE(V28:V43) -> 0.43213394
A47: SD | B47: =STDEV(B28:B43) -> 0.047399865 | C47: =STDEV(C28:C43) -> 0.11363408 | D47: =STDEV(D28:D43) -> 0.23686671 | E47: =STDEV(E28:E43) -> 0.40806313 | F47: =STDEV(F28:F43) -> 0.55721731 | G47: =STDEV(G28:G43) -> 0.47500299 | H47: =STDEV(H28:H43) -> 0.6998415 | I47: =STDEV(I28:I43) -> 0.091974136 | ... M47: =STDEV(M28:M43) -> 0.029128821 | N47: SD | O47: =STDEV(O28:O43) -> 0.65885996 | P47: =STDEV(P28:P43) -> 0.68479774 | Q47: =STDEV(Q28:Q43) -> 0.025137321 | R47: =STDEV(R28:R43) -> 0.55284496 | S47: =STDEV(S28:S43) -> 0.57704695 | T47: =STDEV(T28:T43) -> 0.38833572 | U47: =STDEV(U28:U43) -> 0.56023036 | V47: =STDEV(V28:V43) -> 0.33271986
A48: SEM | B48: =B47/SQRT(COUNT(B28:B43)) -> 0.017915465 | C48: =C47/SQRT(COUNT(C28:C43)) -> 0.042949646 | D48: =D47/SQRT(COUNT(D28:D43)) -> 0.089527203 | E48: =E47/SQRT(COUNT(E28:E43)) -> 0.15423337 | F48: =F47/SQRT(COUNT(F28:F43)) -> 0.21060835 | G48: =G47/SQRT(COUNT(G28:G43)) -> 0.17953425 | H48: =H47/SQRT(COUNT(H28:H43)) -> 0.26451523 | I48: =I47/SQRT(COUNT(I28:I43)) -> 0.034762956 | ... M48: =M47/SQRT(COUNT(M28:M43)) -> 0.011009659 | N48: SEM | O48: =O47/SQRT(COUNT(O28:O43)) -> 0.17608773 | P48: =P47/SQRT(COUNT(P28:P43)) -> 0.25882922 | Q48: =Q47/SQRT(COUNT(Q28:Q43)) -> 0.0095010142 | R48: =R47/SQRT(COUNT(R28:R43)) -> 0.19546021 | S48: =S47/SQRT(COUNT(S28:S43)) -> 0.20401691 | T48: =T47/SQRT(COUNT(T28:T43)) -> 0.13729741 | U48: =U47/SQRT(COUNT(U28:U43)) -> 0.19807134 | V48: =V47/SQRT(COUNT(V28:V43)) -> 0.11763424
A52: =A27 -> Group names | B52: =B27 -> Solvent control | C52: =C27 -> EE2-33.8ng/L | D52: =D27 -> EE2-50.6ng/L | E52: =E27 -> EE2-76ng/L | F52: =F27 -> EE2-114ng/L | G52: =G27 -> EE2-170.9ng/L | H52: =H27 -> EE2-488ng/L | I52: =I4 -> Amantadine-0.001mg/L | J52: =J4 -> Amantadine-0.01mg/L | K52: =K27 -> Amantadine-0.1mg/L | L52: =L27 -> Amantadine-1mg/L | M52: =M27 -> Amantadine-10mg/L | O52: =O27 -> Testo -30µg/L | P52: =P27 -> Testo 30µg/L + EE2 -64ng/L | Q52: =Q27 -> Testo 30µg/L + FAD-10mg/L | R52: =R27 -> Amantadine-0.001mg/L + Testostérone | S52: =S27 -> Amantadine-0.01mg/L + Testostérone | T52: =T27 -> Amantadine-0.1mg/L + Testostérone | U52: =U27 -> Amantadine-1mg/L + Testostérone | V52: =V27 -> Amantadine-10mg/L + Testostérone
...

Sheet R2
A3: R2 | B3: Unspiked | O3: Testosterone spiked
A4: Group names | B4: ='Front page'!A7 -> Solvent control | C4: ='Front page'!A8 -> EE2-33.8ng/L | D4: ='Front page'!A9 -> EE2-50.6ng/L | E4: ='Front page'!A10 -> EE2-76ng/L | F4: ='Front page'!A11 -> EE2-114ng/L | G4: ='Front page'!A12 -> EE2-170.9ng/L | H4: ='Front page'!A13 -> EE2-488ng/L | I4: ='Front page'!A14 -> Amantadine-0.001mg/L | J4: ='Front page'!A15 -> Amantadine-0.01mg/L | K4: ='Front page'!A16 -> Amantadine-0.1mg/L | L4: ='Front page'!A17 -> Amantadine-1mg/L | M4: ='Front page'!A18 -> Amantadine-10mg/L | O4: ='Front page'!A35 -> Testo -30µg/L | P4: ='Front page'!A36 -> Testo 30µg/L + EE2 -64ng/L | Q4: ='Front page'!A37 -> Testo 30µg/L + FAD-10mg/L | R4: ='Front page'!A38 -> Amantadine-0.001mg/L + Testostérone | S4: ='Front page'!A39 -> Amantadine-0.01mg/L + Testostérone | T4: ='Front page'!A40 -> Amantadine-0.1mg/L + Testostérone | U4: ='Front page'!A41 -> Amantadine-1mg/L + Testostérone | V4: ='Front page'!A42 -> Amantadine-10mg/L + Testostérone
A5: Raw data | B5: 305217 | C5: 58590 | D5: 95889 | E5: 3564799 | F5: 1183619 | G5: 4632668 | H5: 4381135 | I5: 37495 | J5: 56402 | K5: 1847345 | L5: 421683 | M5: 22840 | O5: 4057873 | P5: 6265745 | Q5: 118416 | R5: 156193 | S5: 1619929 | T5: 245507 | U5: 2500297 | V5: 5540342
B6: 26943 | C6: 803685 | D6: 1364889 | E6: 1570998 | F6: 9359684 | G6: 6058316 | H6: 6003363 | I6: 537998 | J6: 156553 | K6: 2388856 | L6: 68220 | M6: 224821 | O6: 5299284 | P6: 7834906 | Q6: 70832 | R6: 2584028 | S6: 2280913 | T6: 2846782 | U6: 4725543 | V6: 5194749
B7: 544707 | C7: 260148 | D7: 267311 | E7: 1022016 | F7: 6028957 | G7: 2730310 | H7: 10312751 | I7: 49266 | J7: 19706 | K7: 1276951 | L7: 13422 | M7: 120817 | O7: 4340526 | P7: 6122385 | Q7: 203420 | R7: 3147089 | S7: 137082 | T7: 1329787 | U7: 3669618 | V7: 3418535
B8: 1147853 | C8: 26991 | D8: 5725054 | E8: 3830520 | F8: 3080965 | G8: 4479328 | H8: 6819276 | I8: 62764 | J8: 468233 | L8: 522435 | M8: 313120 | O8: 3613929 | P8: 7044763 | Q8: 330439 | R8: 2346546 | S8: 4192672 | T8: 594810 | U8: 829961 | V8: 4029363
B9: 67656 | C9: 98975 | D9: 131205 | E9: 393420 | F9: 2434121 | G9: 4946377 | H9: 11599237 | I9: 42299 | J9: 652245 | L9: 128466 | M9: 273395 | O9: 3124823 | P9: 8078230 | Q9: 44878 | R9: 1254344 | S9: 2757066 | T9: 1224659 | U9: 2343259 | V9: 4419984
B10: 566626 | C10: 148075 | D10: 197768 | E10: 523581 | F10: 2879141 | G10: 4386312 | H10: 5877475 | I10: 127868 | J10: 34504 | L10: 113106 | M10: 35388 | O10: 4113260 | P10: 7807673 | Q10: 387437 | R10: 2702328 | S10: 2806794 | T10: 1740228 | U10: 3647649 | V10: 6942896
B11: 248673 | C11: 90741 | D11: 156354 | E11: 1647190 | F11: 818764 | G11: 5666062 | H11: 6872517 | I11: 426418 | J11: 55427 | L11: 49081 | M11: 281761 | O11: 1382800 | P11: 10322436 | Q11: 90708 | R11: 428864 | S11: 2384132 | T11: 2533741 | U11: 4462821 | V11: 2668519
B12: 71293 | C12: 389287 | D12: 69827 | E12: 1270264 | F12: 6472030 | G12: 2731667 | H12: 9989392 | I12: 22195 | J12: 80679 | L12: 186243 | M12: 321919 | O12: 4220841 | P12: 7771367 | Q12: 516219 | R12: 3245205 | S12: 4249879 | T12: 4963 | U12: 2603469 | V12: 4175698
O13: 1898306
O14: 4872254
O15: 3383261
O16: 3712936
O17: 3079447
O18: 2169490
O19: 4834729
O20: 257941
A22: =A4 -> Group names | B22: =B4 -> Solvent control | C22: =C4 -> EE2-33.8ng/L | D22: =D4 -> EE2-50.6ng/L | E22: =E4 -> EE2-76ng/L | F22: =F4 -> EE2-114ng/L | G22: =G4 -> EE2-170.9ng/L | H22: =H4 -> EE2-488ng/L | ... M22: =M4 -> Amantadine-10mg/L | N22: Noms des groupes | O22: =O4 -> Testo -30µg/L | P22: =P4 -> Testo 30µg/L + EE2 -64ng/L | Q22: =Q4 -> Testo 30µg/L + FAD-10mg/L | R22: =R4 -> Amantadine-0.001mg/L + Testostérone | S22: =S4 -> Amantadine-0.01mg/L + Testostérone | T22: =T4 -> Amantadine-0.1mg/L + Testostérone | U22: =U4 -> Amantadine-1mg/L + Testostérone | V22: =V4 -> Amantadine-10mg/L + Testostérone
A23: mean | B23: =AVERAGE(B5:B20) -> 372371 | C23: =AVERAGE(C5:C20) -> 234561.5 | D23: =AVERAGE(D5:D20) -> 1001037.1 | E23: =AVERAGE(E5:E20) -> 1727848.5 | F23: =AVERAGE(F5:F20) -> 4032160.1 | G23: =AVERAGE(G5:G20) -> 4453880 | H23: =AVERAGE(H5:H20) -> 7731893.2 | I23: =AVERAGE(I5:I20) -> 163287.88 | J23: =AVERAGE(J5:J20) -> 190468.62 | L23: =AVERAGE(L5:L20) -> 187832 | N23: mean | O23: =AVERAGE(O5:O20) -> 3397606.2 | P23: =AVERAGE(P5:P20) -> 7655938.1 | Q23: =AVERAGE(Q5:Q20) -> 220293.62 | R23: =AVERAGE(R5:R20) -> 1983074.6 | S23: =AVERAGE(S5:S20) -> 2553558.4 | T23: =AVERAGE(T5:T20) -> 1315059.6 | U23: =AVERAGE(U5:U20) -> 3097827.1 | V23: =AVERAGE(V5:V20) -> 4548760.8
A24: SD | B24: =STDEV(B5:B20) -> 376342.85 | C24: =STDEV(C5:C20) -> 258869.97 | D24: =STDEV(D5:D20) -> 1956266.9 | E24: =STDEV(E5:E20) -> 1296438.3 | F24: =STDEV(F5:F20) -> 2965292.8 | G24: =STDEV(G5:G20) -> 1210669.4 | H24: =STDEV(H5:H20) -> 2561783.3 | I24: =STDEV(I5:I20) -> 201556.48 | J24: =STDEV(J5:J20) -> 237032.08 | L24: =STDEV(L5:L20) -> 185061.38 | N24: SD | O24: =STDEV(O5:O20) -> 1375170.2 | P24: =STDEV(P5:P20) -> 1310118.6 | Q24: =STDEV(Q5:Q20) -> 172463.81 | R24: =STDEV(R5:R20) -> 1209639.8 | S24: =STDEV(S5:S20) -> 1335440.2 | T24: =STDEV(T5:T20) -> 1028144.7 | U24: =STDEV(U5:U20) -> 1279282.1 | V24: =STDEV(V5:V20) -> 1329375.3
B26: Unspiked | O26: Testosterone spiked
A27: =A4 -> Group names | B27: =B4 -> Solvent control | C27: =C4 -> EE2-33.8ng/L | D27: =D4 -> EE2-50.6ng/L | E27: =E4 -> EE2-76ng/L | F27: =F4 -> EE2-114ng/L | G27: =G4 -> EE2-170.9ng/L | H27: =H4 -> EE2-488ng/L | ... M27: =M4 -> Amantadine-10mg/L | O27: =O4 -> Testo -30µg/L | P27: =P4 -> Testo 30µg/L + EE2 -64ng/L | Q27: =Q4 -> Testo 30µg/L + FAD-10mg/L | R27: =R4 -> Amantadine-0.001mg/L + Testostérone | S27: =S4 -> Amantadine-0.01mg/L + Testostérone | T27: =T4 -> Amantadine-0.1mg/L + Testostérone | U27: =U4 -> Amantadine-1mg/L + Testostérone | V27: =V4 -> Amantadine-10mg/L + Testostérone
A28: Data normalised to the "Testo" group | B28: =IF(B5="","",(B5/$O$23)) -> 0.089832952 | C28: =IF(C5="","",(C5/$O$23)) -> 0.017244494 | D28: =IF(D5="","",(D5/$O$23)) -> 0.028222517 | E28: =IF(E5="","",(E5/$O$23)) -> 1.049209 | F28: =IF(F5="","",(F5/$O$23)) -> 0.3483685 | G28: =IF(G5="","",(G5/$O$23)) -> 1.3635094 | H28: =IF(H5="","",(H5/$O$23)) -> 1.289477 | I28: =IF(I5="","",(I5/$O$23)) -> 0.011035711 | ... M28: =IF(M5="","",(M5/$O$23)) -> 0.0067223799 | O28: =IF(O5="","",(O5/$O$23)) -> 1.1943329 | P28: =IF(P5="","",(P5/$O$23)) -> 1.8441645 | Q28: =IF(Q5="","",(Q5/$O$23)) -> 0.034852773 | R28: =IF(R5="","",(R5/$O$23)) -> 0.045971484 | S28: =IF(S5="","",(S5/$O$23)) -> 0.47678538 | T28: =IF(T5="","",(T5/$O$23)) -> 0.072258815 | U28: =IF(U5="","",(U5/$O$23)) -> 0.73589958 | V28: =IF(V5="","",(V5/$O$23)) -> 1.6306604
B29: =IF(B6="","",(B6/$O$23)) -> 0.0079299948 | C29: =IF(C6="","",(C6/$O$23)) -> 0.23654448 | D29: =IF(D6="","",(D6/$O$23)) -> 0.40172077 | E29: =IF(E6="","",(E6/$O$23)) -> 0.46238377 | F29: =IF(F6="","",(F6/$O$23)) -> 2.7547877 | G29: =IF(G6="","",(G6/$O$23)) -> 1.783113 | H29: =IF(H6="","",(H6/$O$23)) -> 1.766939 | I29: =IF(I6="","",(I6/$O$23)) -> 0.15834619 | ... M29: =IF(M6="","",(M6/$O$23)) -> 0.06617041 | O29: =IF(O6="","",(O6/$O$23)) -> 1.559711 | P29: =IF(P6="","",(P6/$O$23)) -> 2.3060076 | Q29: =IF(Q6="","",(Q6/$O$23)) -> 0.020847619 | R29: =IF(R6="","",(R6/$O$23)) -> 0.76054369 | S29: =IF(S6="","",(S6/$O$23)) -> 0.67132941 | T29: =IF(T6="","",(T6/$O$23)) -> 0.83787873 | U29: =IF(U6="","",(U6/$O$23)) -> 1.3908448 | V29: =IF(V6="","",(V6/$O$23)) -> 1.5289438
B30: =IF(B7="","",(B7/$O$23)) -> 0.16032081 | C30: =IF(C7="","",(C7/$O$23)) -> 0.076568025 | D30: =IF(D7="","",(D7/$O$23)) -> 0.078676274 | E30: =IF(E7="","",(E7/$O$23)) -> 0.30080472 | F30: =IF(F7="","",(F7/$O$23)) -> 1.774472 | G30: =IF(G7="","",(G7/$O$23)) -> 0.80359812 | H30: =IF(H7="","",(H7/$O$23)) -> 3.035299 | I30: =IF(I7="","",(I7/$O$23)) -> 0.014500209 | ... M30: =IF(M7="","",(M7/$O$23)) -> 0.035559447 | O30: =IF(O7="","",(O7/$O$23)) -> 1.2775247 | P30: =IF(P7="","",(P7/$O$23)) -> 1.8019701 | Q30: =IF(Q7="","",(Q7/$O$23)) -> 0.059871564 | R30: =IF(R7="","",(R7/$O$23)) -> 0.92626654 | S30: =IF(S7="","",(S7/$O$23)) -> 0.040346641 | T30: =IF(T7="","",(T7/$O$23)) -> 0.39138938 | U30: =IF(U7="","",(U7/$O$23)) -> 1.0800598 | V30: =IF(V7="","",(V7/$O$23)) -> 1.0061599
B31: =IF(B8="","",(B8/$O$23)) -> 0.33784168 | C31: =IF(C8="","",(C8/$O$23)) -> 0.0079441224 | D31: =IF(D8="","",(D8/$O$23)) -> 1.6850257 | E31: =IF(E8="","",(E8/$O$23)) -> 1.1274173 | F31: =IF(F8="","",(F8/$O$23)) -> 0.90680461 | G31: =IF(G8="","",(G8/$O$23)) -> 1.3183776 | H31: =IF(H8="","",(H8/$O$23)) -> 2.0070825 | I31: =IF(I8="","",(I8/$O$23)) -> 0.018473006 | ... M31: =IF(M8="","",(M8/$O$23)) -> 0.092159002 | O31: =IF(O8="","",(O8/$O$23)) -> 1.0636692 | P31: =IF(P8="","",(P8/$O$23)) -> 2.0734489 | Q31: =IF(Q8="","",(Q8/$O$23)) -> 0.097256414 | R31: =IF(R8="","",(R8/$O$23)) -> 0.69064683 | S31: =IF(S8="","",(S8/$O$23)) -> 1.2340076 | T31: =IF(T8="","",(T8/$O$23)) -> 0.17506737 | U31: =IF(U8="","",(U8/$O$23)) -> 0.24427816 | V31: =IF(V8="","",(V8/$O$23)) -> 1.1859417
B32: =IF(B9="","",(B9/$O$23)) -> 0.019912843 | C32: =IF(C9="","",(C9/$O$23)) -> 0.029130803 | D32: =IF(D9="","",(D9/$O$23)) -> 0.038616894 | E32: =IF(E9="","",(E9/$O$23)) -> 0.11579329 | F32: =IF(F9="","",(F9/$O$23)) -> 0.71642233 | G32: =IF(G9="","",(G9/$O$23)) -> 1.4558417 | H32: =IF(H9="","",(H9/$O$23)) -> 3.4139439 | I32: =IF(I9="","",(I9/$O$23)) -> 0.012449647 | ... M32: =IF(M9="","",(M9/$O$23)) -> 0.080466946 | O32: =IF(O9="","",(O9/$O$23)) -> 0.91971311 | P32: =IF(P9="","",(P9/$O$23)) -> 2.377624 | Q32: =IF(Q9="","",(Q9/$O$23)) -> 0.013208711 | R32: =IF(R9="","",(R9/$O$23)) -> 0.36918463 | S32: =IF(S9="","",(S9/$O$23)) -> 0.81147308 | T32: =IF(T9="","",(T9/$O$23)) -> 0.36044759 | U32: =IF(U9="","",(U9/$O$23)) -> 0.68967939 | V32: =IF(V9="","",(V9/$O$23)) -> 1.3009112
B33: =IF(B10="","",(B10/$O$23)) -> 0.16677212 | C33: =IF(C10="","",(C10/$O$23)) -> 0.043582154 | D33: =IF(D10="","",(D10/$O$23)) -> 0.05820804 | E33: =IF(E10="","",(E10/$O$23)) -> 0.15410291 | F33: =IF(F10="","",(F10/$O$23)) -> 0.84740279 | G33: =IF(G10="","",(G10/$O$23)) -> 1.2910007 | H33: =IF(H10="","",(H10/$O$23)) -> 1.729887 | I33: =IF(I10="","",(I10/$O$23)) -> 0.037634732 | ... M33: =IF(M10="","",(M10/$O$23)) -> 0.010415568 | O33: =IF(O10="","",(O10/$O$23)) -> 1.2106347 | P33: =IF(P10="","",(P10/$O$23)) -> 2.2979923 | Q33: =IF(Q10="","",(Q10/$O$23)) -> 0.11403234 | R33: =IF(R10="","",(R10/$O$23)) -> 0.79536232 | S33: =IF(S10="","",(S10/$O$23)) -> 0.82610926 | T33: =IF(T10="","",(T10/$O$23)) -> 0.51219237 | U33: =IF(U10="","",(U10/$O$23)) -> 1.0735938 | V33: =IF(V10="","",(V10/$O$23)) -> 2.0434669
B34: =IF(B11="","",(B11/$O$23)) -> 0.073190647 | C34: =IF(C11="","",(C11/$O$23)) -> 0.026707333 | D34: =IF(D11="","",(D11/$O$23)) -> 0.04601887 | E34: =IF(E11="","",(E11/$O$23)) -> 0.48480897 | F34: =IF(F11="","",(F11/$O$23)) -> 0.2409826 | G34: =IF(G11="","",(G11/$O$23)) -> 1.6676629 | H34: =IF(H11="","",(H11/$O$23)) -> 2.0227526 | I34: =IF(I11="","",(I11/$O$23)) -> 0.12550542 | ... M34: =IF(M11="","",(M11/$O$23)) -> 0.082929268 | O34: =IF(O11="","",(O11/$O$23)) -> 0.40699242 | P34: =IF(P11="","",(P11/$O$23)) -> 3.0381496 | Q34: =IF(Q11="","",(Q11/$O$23)) -> 0.02669762 | R34: =IF(R11="","",(R11/$O$23)) -> 0.12622534 | S34: =IF(S11="","",(S11/$O$23)) -> 0.70170933 | T34: =IF(T11="","",(T11/$O$23)) -> 0.74574298 | U34: =IF(U11="","",(U11/$O$23)) -> 1.3135192 | V34: =IF(V11="","",(V11/$O$23)) -> 0.78541149
B35: =IF(B12="","",(B12/$O$23)) -> 0.020983303 | C35: =IF(C12="","",(C12/$O$23)) -> 0.11457684 | D35: =IF(D12="","",(D12/$O$23)) -> 0.020551822 | E35: =IF(E12="","",(E12/$O$23)) -> 0.37387028 | F35: =IF(F12="","",(F12/$O$23)) -> 1.9048794 | G35: =IF(G12="","",(G12/$O$23)) -> 0.80399752 | H35: =IF(H12="","",(H12/$O$23)) -> 2.9401264 | I35: =IF(I12="","",(I12/$O$23)) -> 0.0065325404 | ... M35: =IF(M12="","",(M12/$O$23)) -> 0.094748766 | O35: =IF(O12="","",(O12/$O$23)) -> 1.2422985 | P35: =IF(P12="","",(P12/$O$23)) -> 2.2873065 | Q35: =IF(Q12="","",(Q12/$O$23)) -> 0.15193609 | R35: =IF(R12="","",(R12/$O$23)) -> 0.95514452 | S35: =IF(S12="","",(S12/$O$23)) -> 1.2508451 | T35: =IF(T12="","",(T12/$O$23)) -> 0.0014607343 | U35: =IF(U12="","",(U12/$O$23)) -> 0.76626566 | V35: =IF(V12="","",(V12/$O$23)) -> 1.2290117
B36: =IF(B13="","",(B13/$O$23)) | C36: =IF(C13="","",(C13/$O$23)) | D36: =IF(D13="","",(D13/$O$23)) | E36: =IF(E13="","",(E13/$O$23)) | F36: =IF(F13="","",(F13/$O$23)) | G36: =IF(G13="","",(G13/$O$23)) | H36: =IF(H13="","",(H13/$O$23)) | I36: =IF(I13="","",(I13/$O$23)) | ... M36: =IF(M13="","",(M13/$O$23)) | O36: =IF(O13="","",(O13/$O$23)) -> 0.55871866 | P36: =IF(P13="","",(P13/$O$23)) | Q36: =IF(Q13="","",(Q13/$O$23)) | R36: =IF(R13="","",(R13/$O$23)) | S36: =IF(S13="","",(S13/$O$23)) | T36: =IF(T13="","",(T13/$O$23)) | U36: =IF(U13="","",(U13/$O$23)) | V36: =IF(V13="","",(V13/$O$23))
B37: =IF(B14="","",(B14/$O$23)) | C37: =IF(C14="","",(C14/$O$23)) | D37: =IF(D14="","",(D14/$O$23)) | E37: =IF(E14="","",(E14/$O$23)) | F37: =IF(F14="","",(F14/$O$23)) | G37: =IF(G14="","",(G14/$O$23)) | H37: =IF(H14="","",(H14/$O$23)) | I37: =IF(I14="","",(I14/$O$23)) | ... M37: =IF(M14="","",(M14/$O$23)) | O37: =IF(O14="","",(O14/$O$23)) -> 1.4340255 | P37: =IF(P14="","",(P14/$O$23)) | Q37: =IF(Q14="","",(Q14/$O$23)) | R37: =IF(R14="","",(R14/$O$23)) | S37: =IF(S14="","",(S14/$O$23)) | T37: =IF(T14="","",(T14/$O$23)) | U37: =IF(U14="","",(U14/$O$23)) | V37: =IF(V14="","",(V14/$O$23))
B38: =IF(B15="","",(B15/$O$23)) | C38: =IF(C15="","",(C15/$O$23)) | D38: =IF(D15="","",(D15/$O$23)) | E38: =IF(E15="","",(E15/$O$23)) | F38: =IF(F15="","",(F15/$O$23)) | G38: =IF(G15="","",(G15/$O$23)) | H38: =IF(H15="","",(H15/$O$23)) | I38: =IF(I15="","",(I15/$O$23)) | ... M38: =IF(M15="","",(M15/$O$23)) | O38: =IF(O15="","",(O15/$O$23)) -> 0.99577784 | P38: =IF(P15="","",(P15/$O$23)) | Q38: =IF(Q15="","",(Q15/$O$23)) | R38: =IF(R15="","",(R15/$O$23)) | S38: =IF(S15="","",(S15/$O$23)) | T38: =IF(T15="","",(T15/$O$23)) | U38: =IF(U15="","",(U15/$O$23)) | V38: =IF(V15="","",(V15/$O$23))
B39: =IF(B16="","",(B16/$O$23)) | C39: =IF(C16="","",(C16/$O$23)) | D39: =IF(D16="","",(D16/$O$23)) | E39: =IF(E16="","",(E16/$O$23)) | F39: =IF(F16="","",(F16/$O$23)) | G39: =IF(G16="","",(G16/$O$23)) | H39: =IF(H16="","",(H16/$O$23)) | I39: =IF(I16="","",(I16/$O$23)) | ... M39: =IF(M16="","",(M16/$O$23)) | O39: =IF(O16="","",(O16/$O$23)) -> 1.0928094 | P39: =IF(P16="","",(P16/$O$23)) | Q39: =IF(Q16="","",(Q16/$O$23)) | R39: =IF(R16="","",(R16/$O$23)) | S39: =IF(S16="","",(S16/$O$23)) | T39: =IF(T16="","",(T16/$O$23)) | U39: =IF(U16="","",(U16/$O$23)) | V39: =IF(V16="","",(V16/$O$23))
B40: =IF(B17="","",(B17/$O$23)) | C40: =IF(C17="","",(C17/$O$23)) | D40: =IF(D17="","",(D17/$O$23)) | E40: =IF(E17="","",(E17/$O$23)) | F40: =IF(F17="","",(F17/$O$23)) | G40: =IF(G17="","",(G17/$O$23)) | H40: =IF(H17="","",(H17/$O$23)) | I40: =IF(I17="","",(I17/$O$23)) | ... M40: =IF(M17="","",(M17/$O$23)) | O40: =IF(O17="","",(O17/$O$23)) -> 0.90635782 | P40: =IF(P17="","",(P17/$O$23)) | Q40: =IF(Q17="","",(Q17/$O$23)) | R40: =IF(R17="","",(R17/$O$23)) | S40: =IF(S17="","",(S17/$O$23)) | T40: =IF(T17="","",(T17/$O$23)) | U40: =IF(U17="","",(U17/$O$23)) | V40: =IF(V17="","",(V17/$O$23))
... B43: =IF(B20="","",(B20/$O$23)) | C43: =IF(C20="","",(C20/$O$23)) | D43: =IF(D20="","",(D20/$O$23)) | E43: =IF(E20="","",(E20/$O$23)) | F43: =IF(F20="","",(F20/$O$23)) | G43: =IF(G20="","",(G20/$O$23)) | H43: =IF(H20="","",(H20/$O$23)) | I43: =IF(I20="","",(I20/$O$23)) | ... M43: =IF(M20="","",(M20/$O$23)) | O43: =IF(O20="","",(O20/$O$23)) -> 0.07591845 | P43: =IF(P20="","",(P20/$O$23)) | Q43: =IF(Q20="","",(Q20/$O$23)) | R43: =IF(R20="","",(R20/$O$23)) | S43: =IF(S20="","",(S20/$O$23)) | T43: =IF(T20="","",(T20/$O$23)) | U43: =IF(U20="","",(U20/$O$23)) | V43: =IF(V20="","",(V20/$O$23))
A45: =A4 -> Group names | B45: =B4 -> Solvent control | C45: =C4 -> EE2-33.8ng/L | D45: =D4 -> EE2-50.6ng/L | E45: =E4 -> EE2-76ng/L | F45: =F4 -> EE2-114ng/L | G45: =G4 -> EE2-170.9ng/L | H45: =H4 -> EE2-488ng/L | ... M45: =M4 -> Amantadine-10mg/L | O45: =O4 -> Testo -30µg/L | P45: =P4 -> Testo 30µg/L + EE2 -64ng/L | Q45: =Q4 -> Testo 30µg/L + FAD-10mg/L | R45: =R4 -> Amantadine-0.001mg/L + Testostérone | S45: =S4 -> Amantadine-0.01mg/L + Testostérone | T45: =T4 -> Amantadine-0.1mg/L + Testostérone | U45: =U4 -> Amantadine-1mg/L + Testostérone | V45: =V4 -> Amantadine-10mg/L + Testostérone
A46: mean | B46: =AVERAGE(B28:B43) -> 0.10959804 | C46: =AVERAGE(C28:C43) -> 0.069037282 | D46: =AVERAGE(D28:D43) -> 0.29463012 | E46: =AVERAGE(E28:E43) -> 0.50854878 | F46: =AVERAGE(F28:F43) -> 1.186765 | G46: =AVERAGE(G28:G43) -> 1.3108876 | H46: =AVERAGE(H28:H43) -> 2.2756884 | I46: =AVERAGE(I28:I43) -> 0.048059682 | ... M46: =AVERAGE(M28:M43) -> 0.058646474 | N46: mean | O46: =AVERAGE(O28:O43) -> 1 | P46: =AVERAGE(P28:P43) -> 2.253333 | Q46: =AVERAGE(Q28:Q43) -> 0.064837891 | R46: =AVERAGE(R28:R43) -> 0.58366817 | S46: =AVERAGE(S28:S43) -> 0.75157572 | T46: =AVERAGE(T28:T43) -> 0.38705475 | U46: =AVERAGE(U28:U43) -> 0.91176755 | V46: =AVERAGE(V28:V43) -> 1.3388134
A47: SD | B47: =STDEV(B28:B43) -> 0.11076706 | C47: =STDEV(C28:C43) -> 0.07619187 | D47: =STDEV(D28:D43) -> 0.575778 | E47: =STDEV(E28:E43) -> 0.38157402 | F47: =STDEV(F28:F43) -> 0.8727594 | G47: =STDEV(G28:G43) -> 0.35633011 | H47: =STDEV(H28:H43) -> 0.75399654 | I47: =STDEV(I28:I43) -> 0.059323083 | ... M47: =STDEV(M28:M43) -> 0.036063841 | N47: SD | O47: =STDEV(O28:O43) -> 0.40474677 | P47: =STDEV(P28:P43) -> 0.38560048 | Q47: =STDEV(Q28:Q43) -> 0.050760388 | R47: =STDEV(R28:R43) -> 0.35602708 | S47: =STDEV(S28:S43) -> 0.39305325 | T47: =STDEV(T28:T43) -> 0.30260855 | U47: =STDEV(U28:U43) -> 0.37652452 | V47: =STDEV(V28:V43) -> 0.3912682
...

Sheet R3
A3: R3 | B3: Unspiked | O3: Testosterone spiked
A4: Group names | B4: ='Front page'!A7 -> Solvent control | C4: ='Front page'!A8 -> EE2-33.8ng/L | D4: ='Front page'!A9 -> EE2-50.6ng/L | E4: ='Front page'!A10 -> EE2-76ng/L | F4: ='Front page'!A11 -> EE2-114ng/L | G4: ='Front page'!A12 -> EE2-170.9ng/L | H4: ='Front page'!A13 -> EE2-488ng/L | I4: ='Front page'!A14 -> Amantadine-0.001mg/L | J4: ='Front page'!A15 -> Amantadine-0.01mg/L | K4: ='Front page'!A16 -> Amantadine-0.1mg/L | L4: ='Front page'!A17 -> Amantadine-1mg/L | M4: ='Front page'!A18 -> Amantadine-10mg/L | O4: ='Front page'!A35 -> Testo -30µg/L | P4: ='Front page'!A36 -> Testo 30µg/L + EE2 -64ng/L | Q4: ='Front page'!A37 -> Testo 30µg/L + FAD-10mg/L | R4: ='Front page'!A38 -> Amantadine-0.001mg/L + Testostérone | S4: ='Front page'!A39 -> Amantadine-0.01mg/L + Testostérone | T4: ='Front page'!A40 -> Amantadine-0.1mg/L + Testostérone | U4: ='Front page'!A41 -> Amantadine-1mg/L + Testostérone | V4: ='Front page'!A42 -> Amantadine-10mg/L + Testostérone
A5: Raw data | B5: 65828 | C5: 19248 | D5: 2085088 | E5: 2144748 | F5: 5298040 | G5: 3309152 | H5: 9168257 | I5: 112487 | J5: 37071 | K5: 31870 | L5: 107222 | M5: 127043 | O5: 2273734 | P5: 4261304 | Q5: 145534 | R5: 1727134 | S5: 2675441 | T5: 5359200 | U5: 5440499 | V5: 4817559
B6: 254319 | C6: 717896 | D6: 175100 | E6: 2079630 | F6: 5927998 | G6: 4474601 | H6: 9456848 | I6: 444634 | J6: 360306 | K6: 75096 | L6: 129091 | M6: 21613 | O6: 7812045 | P6: 9290563 | Q6: 26099 | R6: 4944616 | S6: 510818 | T6: 2854494 | U6: 4889415 | V6: 5785092
B7: 45196 | C7: 209208 | D7: 676196 | E7: 3263927 | F7: 3848156 | G7: 9668809 | H7: 6344901 | I7: 15344 | J7: 252827 | K7: 721637 | L7: 51333 | M7: 52817 | O7: 2956671 | P7: 5956365 | Q7: 135885 | R7: 3954361 | S7: 4511283 | T7: 3897715 | U7: 2623659 | V7: 5838063
B8: 436295 | C8: 319263 | D8: 458793 | E8: 1896244 | F8: 8274130 | G8: 4263132 | H8: 12348654 | I8: 136895 | J8: 122104 | K8: 10551 | L8: 323782 | M8: 667978 | O8: 2730588 | P8: 5008126 | Q8: 154345 | R8: 1297089 | S8: 3174713 | T8: 1523173 | U8: 7584057 | V8: 5254266
B9: 23416 | C9: 58253 | D9: 388143 | E9: 1071499 | F9: 5309763 | G9: 4052710 | H9: 9217348 | I9: 38616 | J9: 21008 | K9: 68024 | L9: 231865 | M9: 15041 | O9: 2975822 | P9: 5982476 | Q9: 403306 | R9: 1765164 | S9: 58069 | T9: 1328705 | U9: 3107950 | V9: 7012340
B10: 19735 | C10: 675753 | D10: 197209 | E10: 2794335 | F10: 1247961 | G10: 6072953 | H10: 7591595 | I10: 41293 | J10: 28031 | K10: 173775 | L10: 237786 | M10: 722958 | O10: 2391468 | P10: 6396625 | Q10: 19909 | R10: 5325180 | S10: 915693 | T10: 7404092 | U10: 1181653 | V10: 4207882
B11: 591580 | C11: 121061 | D11: 231176 | E11: 1724296 | F11: 2405053 | G11: 6681931 | H11: 11965489 | I11: 208888 | J11: 211160 | K11: 252868 | L11: 31808 | M11: 93701 | O11: 2943625 | P11: 6349518 | Q11: 94642 | R11: 3653806 | S11: 4437673 | T11: 1504031 | U11: 481810 | V11: 1817219
B12: 216665 | C12: 679918 | D12: 443898 | E12: 5278261 | F12: 4450520 | G12: 4708326 | H12: 2689861 | I12: 157812 | J12: 110107 | K12: 66418 | L12: 66632 | M12: 85650 | O12: 4977926 | P12: 10084312 | Q12: 200261 | R12: 1924334 | S12: 3314090 | T12: 2317781 | U12: 1776972 | V12: 3814759
O13: 1257243
O14: 3667272
O15: 5268426
O16: 4578568
O17: 807062
O18: 5879638
O19: 2095365
O20: 4222775
A22: =A4 -> Group names | B22: =B4 -> Solvent control | C22: =C4 -> EE2-33.8ng/L | D22: =D4 -> EE2-50.6ng/L | E22: =E4 -> EE2-76ng/L | F22: =F4 -> EE2-114ng/L | G22: =G4 -> EE2-170.9ng/L | H22: =H4 -> EE2-488ng/L | ... M22: =M4 -> Amantadine-10mg/L | N22: Noms des groupes | O22: =O4 -> Testo -30µg/L | P22: =P4 -> Testo 30µg/L + EE2 -64ng/L | Q22: =Q4 -> Testo 30µg/L + FAD-10mg/L | R22: =R4 -> Amantadine-0.001mg/L + Testostérone | S22: =S4 -> Amantadine-0.01mg/L + Testostérone | T22: =T4 -> Amantadine-0.1mg/L + Testostérone | U22: =U4 -> Amantadine-1mg/L + Testostérone | V22: =V4 -> Amantadine-10mg/L + Testostérone
A23: mean | B23: =AVERAGE(B5:B20) -> 206629.25 | C23: =AVERAGE(C5:C20) -> 350075 | D23: =AVERAGE(D5:D20) -> 581950.38 | E23: =AVERAGE(E5:E20) -> 2531617.5 | F23: =AVERAGE(F5:F20) -> 4595202.6 | G23: =AVERAGE(G5:G20) -> 5403951.8 | H23: =AVERAGE(H5:H20) -> 8597869.1 | I23: =AVERAGE(I5:I20) -> 144496.12 | J23: =AVERAGE(J5:J20) -> 142826.75 | L23: =AVERAGE(L5:L20) -> 147439.88 | N23: mean | O23: =AVERAGE(O5:O20) -> 3552389.2 | P23: =AVERAGE(P5:P20) -> 6666161.1 | Q23: =AVERAGE(Q5:Q20) -> 147497.62 | R23: =AVERAGE(R5:R20) -> 3073960.5 | S23: =AVERAGE(S5:S20) -> 2449722.5 | T23: =AVERAGE(T5:T20) -> 3273648.9 | U23: =AVERAGE(U5:U20) -> 3385751.9 | V23: =AVERAGE(V5:V20) -> 4818397.5
A24: SD | B24: =STDEV(B5:B20) -> 213036.12 | C24: =STDEV(C5:C20) -> 297129.54 | D24: =STDEV(D5:D20) -> 629817.24 | E24: =STDEV(E5:E20) -> 1292324.7 | F24: =STDEV(F5:F20) -> 2167790.9 | G24: =STDEV(G5:G20) -> 2040059.5 | H24: =STDEV(H5:H20) -> 3113317.1 | I24: =STDEV(I5:I20) -> 138373.45 | J24: =STDEV(J5:J20) -> 122339.62 | L24: =STDEV(L5:L20) -> 105205.85 | N24: SD | O24: =STDEV(O5:O20) -> 1820196.8 | P24: =STDEV(P5:P20) -> 2008830.8 | Q24: =STDEV(Q5:Q20) -> 120840.92 | R24: =STDEV(R5:R20) -> 1589450.5 | S24: =STDEV(S5:S20) -> 1746763.3 | T24: =STDEV(T5:T20) -> 2166875.2 | U24: =STDEV(U5:U20) -> 2409677.4 | V24: =STDEV(V5:V20) -> 1575013.5
B26: Unspiked | O26: Testosterone spiked
