Workbook

Sheet Front page
A2: R1 | B2: Experiment number : | E2: Date performed :
A3: R2 | B3: Experiment number : | E3: Date performed :
A4: R3 | B4: Experiment number : | E4: Date performed :
A6: Do not fill in | B6: Do not fill in2 | C6: Concentration | D6: Units | E6: Chemical name | F6: Do not fill in3
A7: =IF(ISBLANK(liste_groupe[[#This Row],[Do not fill in2]])," ",IF(ISBLANK(liste_groupe[[#This Row],[Units]]),CONCATENATE(liste_groupe[[#This Row],[Chemical name]],liste_groupe[[#This Row],[Do not fill in3]]),CONCATENATE(liste_groupe[[#This Row],[Chemical name]],"-",liste_groupe[[#This Row],[Concentration]],liste_groupe[[#This Row],[Units]],liste_groupe[[#This Row],[Do not fill in3]]))) -> Solvent control | B7: Control | E7: Solvent control
A8: =IF(ISBLANK(liste_groupe[[#This Row],[Do not fill in2]])," ",IF(ISBLANK(liste_groupe[[#This Row],[Units]]),CONCATENATE(liste_groupe[[#This Row],[Chemical name]],liste_groupe[[#This Row],[Do not fill in3]]),CONCATENATE(liste_groupe[[#This Row],[Chemical name]],"-",liste_groupe[[#This Row],[Concentration]],liste_groupe[[#This Row],[Units]],liste_groupe[[#This Row],[Do not fill in3]]))) -> EE2-33.8ng/L | B8: Control | C8: 33.8 | D8: ng/L | E8: EE2
A9: =IF(ISBLANK(liste_groupe[[#This Row],[Do not fill in2]])," ",IF(ISBLANK(liste_groupe[[#This Row],[Units]]),CONCATENATE(liste_groupe[[#This Row],[Chemical name]],liste_groupe[[#This Row],[Do not fill in3]]),CONCATENATE(liste_groupe[[#This Row],[Chemical name]],"-",liste_groupe[[#This Row],[Concentration]],liste_groupe[[#This Row],[Units]],liste_groupe[[#This Row],[Do not fill in3]]))) -> EE2-50.6ng/L | B9: Control | C9: 50.6 | D9: ng/L | E9: EE2
A10: =IF(ISBLANK(liste_groupe[[#This Row],[Do not fill in2]])," ",IF(ISBLANK(liste_groupe[[#This Row],[Units]]),CONCATENATE(liste_groupe[[#This Row],[Chemical name]],liste_groupe[[#This Row],[Do not fill in3]]),CONCATENATE(liste_groupe[[#This Row],[Chemical name]],"-",liste_groupe[[#This Row],[Concentration]],liste_groupe[[#This Row],[Units]],liste_groupe[[#This Row],[Do not fill in3]]))) -> EE2-76ng/L | B10: Control | C10: 76 | D10: ng/L | E10: EE2
A11: =IF(ISBLANK(liste_groupe[[#This Row],[Do not fill in2]])," ",IF(ISBLANK(liste_groupe[[#This Row],[Units]]),CONCATENATE(liste_groupe[[#This Row],[Chemical name]],liste_groupe[[#This Row],[Do not fill in3]]),CONCATENATE(liste_groupe[[#This Row],[Chemical name]],"-",liste_groupe[[#This Row],[Concentration]],liste_groupe[[#This Row],[Units]],liste_groupe[[#This Row],[Do not fill in3]]))) -> EE2-114ng/L | B11: Control | C11: 114 | D11: ng/L | E11: EE2
A12: =IF(ISBLANK(liste_groupe[[#This Row],[Do not fill in2]])," ",IF(ISBLANK(liste_groupe[[#This Row],[Units]]),CONCATENATE(liste_groupe[[#This Row],[Chemical name]],liste_groupe[[#This Row],[Do not fill in3]]),CONCATENATE(liste_groupe[[#This Row],[Chemical name]],"-",liste_groupe[[#This Row],[Concentration]],liste_groupe[[#This Row],[Units]],liste_groupe[[#This Row],[Do not fill in3]]))) -> EE2-170.9ng/L | B12: Control | C12: 170.9 | D12: ng/L | E12: EE2
A13: =IF(ISBLANK(liste_groupe[[#This Row],[Do not fill in2]])," ",IF(ISBLANK(liste_groupe[[#This Row],[Units]]),CONCATENATE(liste_groupe[[#This Row],[Chemical name]],liste_groupe[[#This Row],[Do not fill in3]]),CONCATENATE(liste_groupe[[#This Row],[Chemical name]],"-",liste_groupe[[#This Row],[Concentration]],liste_groupe[[#This Row],[Units]],liste_groupe[[#This Row],[Do not fill in3]]))) -> EE2-488ng/L | B13: Control | C13: 488 | D13: ng/L | E13: EE2
A14: =IF(ISBLANK(liste_groupe[[#This Row],[Do not fill in2]])," ",IF(ISBLANK(liste_groupe[[#This Row],[Units]]),CONCATENATE(liste_groupe[[#This Row],[Chemical name]],liste_groupe[[#This Row],[Do not fill in3]]),CONCATENATE(liste_groupe[[#This Row],[Chemical name]],"-",liste_groupe[[#This Row],[Concentration]],liste_groupe[[#This Row],[Units]],liste_groupe[[#This Row],[Do not fill in3]]))) -> Estrone-0.04µg/L | B14: test chemical | C14: 0.04 | D14: µg/L | E14: Estrone
A15: =IF(ISBLANK(liste_groupe[[#This Row],[Do not fill in2]])," ",IF(ISBLANK(liste_groupe[[#This Row],[Units]]),CONCATENATE(liste_groupe[[#This Row],[Chemical name]],liste_groupe[[#This Row],[Do not fill in3]]),CONCATENATE(liste_groupe[[#This Row],[Chemical name]],"-",liste_groupe[[#This Row],[Concentration]],liste_groupe[[#This Row],[Units]],liste_groupe[[#This Row],[Do not fill in3]]))) -> Estrone-0.2µg/L | B15: test chemical | C15: 0.2 | D15: µg/L | E15: Estrone
A16: =IF(ISBLANK(liste_groupe[[#This Row],[Do not fill in2]])," ",IF(ISBLANK(liste_groupe[[#This Row],[Units]]),CONCATENATE(liste_groupe[[#This Row],[Chemical name]],liste_groupe[[#This Row],[Do not fill in3]]),CONCATENATE(liste_groupe[[#This Row],[Chemical name]],"-",liste_groupe[[#This Row],[Concentration]],liste_groupe[[#This Row],[Units]],liste_groupe[[#This Row],[Do not fill in3]]))) -> Estrone-1µg/L | B16: test chemical | C16: 1 | D16: µg/L | E16: Estrone
A17: =IF(ISBLANK(liste_groupe[[#This Row],[Do not fill in2]])," ",IF(ISBLANK(liste_groupe[[#This Row],[Units]]),CONCATENATE(liste_groupe[[#This Row],[Chemical name]],liste_groupe[[#This Row],[Do not fill in3]]),CONCATENATE(liste_groupe[[#This Row],[Chemical name]],"-",liste_groupe[[#This Row],[Concentration]],liste_groupe[[#This Row],[Units]],liste_groupe[[#This Row],[Do not fill in3]]))) -> Estrone-5µg/L | B17: test chemical | C17: 5 | D17: µg/L | E17: Estrone
A18: =IF(ISBLANK(liste_groupe[[#This Row],[Do not fill in2]])," ",IF(ISBLANK(liste_groupe[[#This Row],[Units]]),CONCATENATE(liste_groupe[[#This Row],[Chemical name]],liste_groupe[[#This Row],[Do not fill in3]]),CONCATENATE(liste_groupe[[#This Row],[Chemical name]],"-",liste_groupe[[#This Row],[Concentration]],liste_groupe[[#This Row],[Units]],liste_groupe[[#This Row],[Do not fill in3]]))) -> Estrone-25µg/L | B18: test chemical | C18: 25 | D18: µg/L | E18: Estrone
A19: =IF(ISBLANK(liste_groupe[[#This Row],[Do not fill in2]])," ",IF(ISBLANK(liste_groupe[[#This Row],[Units]]),CONCATENATE(liste_groupe[[#This Row],[Chemical name]],liste_groupe[[#This Row],[Do not fill in3]]),CONCATENATE(liste_groupe[[#This Row],[Chemical name]],"-",liste_groupe[[#This Row],[Concentration]],liste_groupe[[#This Row],[Units]],liste_groupe[[#This Row],[Do not fill in3]]))) | B19: test chemical
A20: =IF(ISBLANK(liste_groupe[[#This Row],[Do not fill in2]])," ",IF(ISBLANK(liste_groupe[[#This Row],[Units]]),CONCATENATE(liste_groupe[[#This Row],[Chemical name]],liste_groupe[[#This Row],[Do not fill in3]]),CONCATENATE(liste_groupe[[#This Row],[Chemical name]],"-",liste_groupe[[#This Row],[Concentration]],liste_groupe[[#This Row],[Units]],liste_groupe[[#This Row],[Do not fill in3]]))) | B20: test chemical
A21: =IF(ISBLANK(liste_groupe[[#This Row],[Do not fill in2]])," ",IF(ISBLANK(liste_groupe[[#This Row],[Units]]),CONCATENATE(liste_groupe[[#This Row],[Chemical name]],liste_groupe[[#This Row],[Do not fill in3]]),CONCATENATE(liste_groupe[[#This Row],[Chemical name]],"-",liste_groupe[[#This Row],[Concentration]],liste_groupe[[#This Row],[Units]],liste_groupe[[#This Row],[Do not fill in3]]))) | B21: test chemical
A22: =IF(ISBLANK(liste_groupe[[#This Row],[Do not fill in2]])," ",IF(ISBLANK(liste_groupe[[#This Row],[Units]]),CONCATENATE(liste_groupe[[#This Row],[Chemical name]],liste_groupe[[#This Row],[Do not fill in3]]),CONCATENATE(liste_groupe[[#This Row],[Chemical name]],"-",liste_groupe[[#This Row],[Concentration]],liste_groupe[[#This Row],[Units]],liste_groupe[[#This Row],[Do not fill in3]]))) | B22: test chemical
A23: =IF(ISBLANK(liste_groupe[[#This Row],[Do not fill in2]])," ",IF(ISBLANK(liste_groupe[[#This Row],[Units]]),CONCATENATE(liste_groupe[[#This Row],[Chemical name]],liste_groupe[[#This Row],[Do not fill in3]]),CONCATENATE(liste_groupe[[#This Row],[Chemical name]],"-",liste_groupe[[#This Row],[Concentration]],liste_groupe[[#This Row],[Units]],liste_groupe[[#This Row],[Do not fill in3]]))) | B23: test chemical
A24: =IF(ISBLANK(liste_groupe[[#This Row],[Do not fill in2]])," ",IF(ISBLANK(liste_groupe[[#This Row],[Units]]),CONCATENATE(liste_groupe[[#This Row],[Chemical name]],liste_groupe[[#This Row],[Do not fill in3]]),CONCATENATE(liste_groupe[[#This Row],[Chemical name]],"-",liste_groupe[[#This Row],[Concentration]],liste_groupe[[#This Row],[Units]],liste_groupe[[#This Row],[Do not fill in3]]))) | B24: test chemical
A25: =IF(ISBLANK(liste_groupe[[#This Row],[Do not fill in2]])," ",IF(ISBLANK(liste_groupe[[#This Row],[Units]]),CONCATENATE(liste_groupe[[#This Row],[Chemical name]],liste_groupe[[#This Row],[Do not fill in3]]),CONCATENATE(liste_groupe[[#This Row],[Chemical name]],"-",liste_groupe[[#This Row],[Concentration]],liste_groupe[[#This Row],[Units]],liste_groupe[[#This Row],[Do not fill in3]]))) | B25: test chemical
A26: =IF(ISBLANK(liste_groupe[[#This Row],[Do not fill in2]])," ",IF(ISBLANK(liste_groupe[[#This Row],[Units]]),CONCATENATE(liste_groupe[[#This Row],[Chemical name]],liste_groupe[[#This Row],[Do not fill in3]]),CONCATENATE(liste_groupe[[#This Row],[Chemical name]],"-",liste_groupe[[#This Row],[Concentration]],liste_groupe[[#This Row],[Units]],liste_groupe[[#This Row],[Do not fill in3]]))) | B26: test chemical
A27: =IF(ISBLANK(liste_groupe[[#This Row],[Do not fill in2]])," ",IF(ISBLANK(liste_groupe[[#This Row],[Units]]),CONCATENATE(liste_groupe[[#This Row],[Chemical name]],liste_groupe[[#This Row],[Do not fill in3]]),CONCATENATE(liste_groupe[[#This Row],[Chemical name]],"-",liste_groupe[[#This Row],[Concentration]],liste_groupe[[#This Row],[Units]],liste_groupe[[#This Row],[Do not fill in3]]))) | B27: test chemical
A28: =IF(ISBLANK(liste_groupe[[#This Row],[Do not fill in2]])," ",IF(ISBLANK(liste_groupe[[#This Row],[Units]]),CONCATENATE(liste_groupe[[#This Row],[Chemical name]],liste_groupe[[#This Row],[Do not fill in3]]),CONCATENATE(liste_groupe[[#This Row],[Chemical name]],"-",liste_groupe[[#This Row],[Concentration]],liste_groupe[[#This Row],[Units]],liste_groupe[[#This Row],[Do not fill in3]]))) | B28: test chemical
A29: =IF(ISBLANK(liste_groupe[[#This Row],[Do not fill in2]])," ",IF(ISBLANK(liste_groupe[[#This Row],[Units]]),CONCATENATE(liste_groupe[[#This Row],[Chemical name]],liste_groupe[[#This Row],[Do not fill in3]]),CONCATENATE(liste_groupe[[#This Row],[Chemical name]],"-",liste_groupe[[#This Row],[Concentration]],liste_groupe[[#This Row],[Units]],liste_groupe[[#This Row],[Do not fill in3]]))) | B29: test chemical
A30: =IF(ISBLANK(liste_groupe[[#This Row],[Do not fill in2]])," ",IF(ISBLANK(liste_groupe[[#This Row],[Units]]),CONCATENATE(liste_groupe[[#This Row],[Chemical name]],liste_groupe[[#This Row],[Do not fill in3]]),CONCATENATE(liste_groupe[[#This Row],[Chemical name]],"-",liste_groupe[[#This Row],[Concentration]],liste_groupe[[#This Row],[Units]],liste_groupe[[#This Row],[Do not fill in3]]))) | B30: test chemical
... A34: =IF(ISBLANK(liste_groupe[[#This Row],[Do not fill in2]])," ",IF(ISBLANK(liste_groupe[[#This Row],[Units]]),CONCATENATE(liste_groupe[[#This Row],[Chemical name]],liste_groupe[[#This Row],[Do not fill in3]]),CONCATENATE(liste_groupe[[#This Row],[Chemical name]],"-",liste_groupe[[#This Row],[Concentration]],liste_groupe[[#This Row],[Units]],liste_groupe[[#This Row],[Do not fill in3]]))) | B34: test chemical
A35: =IF(ISBLANK(liste_groupe[[#This Row],[Do not fill in2]])," ",IF(ISBLANK(liste_groupe[[#This Row],[Units]]),CONCATENATE(liste_groupe[[#This Row],[Chemical name]],liste_groupe[[#This Row],[Do not fill in3]]),CONCATENATE(liste_groupe[[#This Row],[Chemical name]],"-",liste_groupe[[#This Row],[Concentration]],liste_groupe[[#This Row],[Units]],liste_groupe[[#This Row],[Do not fill in3]]))) -> Testo -30µg/L | B35: Control | C35: 30 | D35: µg/L | E35: Testo
A36: =IF(ISBLANK(liste_groupe[[#This Row],[Do not fill in2]])," ",IF(ISBLANK(liste_groupe[[#This Row],[Units]]),CONCATENATE(liste_groupe[[#This Row],[Chemical name]],liste_groupe[[#This Row],[Do not fill in3]]),CONCATENATE(liste_groupe[[#This Row],[Chemical name]],"-",liste_groupe[[#This Row],[Concentration]],liste_groupe[[#This Row],[Units]],liste_groupe[[#This Row],[Do not fill in3]]))) -> Testo 30µg/L + EE2 -64ng/L | B36: Control | C36: 64 | D36: ng/L | E36: Testo 30µg/L + EE2
A37: =IF(ISBLANK(liste_groupe[[#This Row],[Do not fill in2]])," ",IF(ISBLANK(liste_groupe[[#This Row],[Units]]),CONCATENATE(liste_groupe[[#This Row],[Chemical name]],liste_groupe[[#This Row],[Do not fill in3]]),CONCATENATE(liste_groupe[[#This Row],[Chemical name]],"-",liste_groupe[[#This Row],[Concentration]],liste_groupe[[#This Row],[Units]],liste_groupe[[#This Row],[Do not fill in3]]))) -> Testo 30µg/L + FAD-10mg/L | B37: Control | C37: 10 | D37: mg/L | E37: Testo 30µg/L + FAD
A38: =IF(ISBLANK(liste_groupe[[#This Row],[Do not fill in2]])," ",IF(ISBLANK(liste_groupe[[#This Row],[Units]]),CONCATENATE(liste_groupe[[#This Row],[Chemical name]],liste_groupe[[#This Row],[Do not fill in3]]),CONCATENATE(liste_groupe[[#This Row],[Chemical name]],"-",liste_groupe[[#This Row],[Concentration]],liste_groupe[[#This Row],[Units]],liste_groupe[[#This Row],[Do not fill in3]]))) -> Estrone-0.04µg/L + Testostérone | B38: =B14 -> test chemical | C38: =C14 -> 0.04 | D38: =D14 -> µg/L | E38: =E14 -> Estrone | F38: + Testostérone
A39: =IF(ISBLANK(liste_groupe[[#This Row],[Do not fill in2]])," ",IF(ISBLANK(liste_groupe[[#This Row],[Units]]),CONCATENATE(liste_groupe[[#This Row],[Chemical name]],liste_groupe[[#This Row],[Do not fill in3]]),CONCATENATE(liste_groupe[[#This Row],[Chemical name]],"-",liste_groupe[[#This Row],[Concentration]],liste_groupe[[#This Row],[Units]],liste_groupe[[#This Row],[Do not fill in3]]))) -> Estrone-0.2µg/L + Testostérone | B39: =B15 -> test chemical | C39: =C15 -> 0.2 | D39: =D15 -> µg/L | E39: =E15 -> Estrone | F39: + Testostérone
A40: =IF(ISBLANK(liste_groupe[[#This Row],[Do not fill in2]])," ",IF(ISBLANK(liste_groupe[[#This Row],[Units]]),CONCATENATE(liste_groupe[[#This Row],[Chemical name]],liste_groupe[[#This Row],[Do not fill in3]]),CONCATENATE(liste_groupe[[#This Row],[Chemical name]],"-",liste_groupe[[#This Row],[Concentration]],liste_groupe[[#This Row],[Units]],liste_groupe[[#This Row],[Do not fill in3]]))) -> Estrone-1µg/L + Testostérone | B40: =B16 -> test chemical | C40: =C16 -> 1 | D40: =D16 -> µg/L | E40: =E16 -> Estrone | F40: + Testostérone
A41: =IF(ISBLANK(liste_groupe[[#This Row],[Do not fill in2]])," ",IF(ISBLANK(liste_groupe[[#This Row],[Units]]),CONCATENATE(liste_groupe[[#This Row],[Chemical name]],liste_groupe[[#This Row],[Do not fill in3]]),CONCATENATE(liste_groupe[[#This Row],[Chemical name]],"-",liste_groupe[[#This Row],[Concentration]],liste_groupe[[#This Row],[Units]],liste_groupe[[#This Row],[Do not fill in3]]))) -> Estrone-5µg/L + Testostérone | B41: =B17 -> test chemical | C41: =C17 -> 5 | D41: =D17 -> µg/L | E41: =E17 -> Estrone | F41: + Testostérone
A42: =IF(ISBLANK(liste_groupe[[#This Row],[Do not fill in2]])," ",IF(ISBLANK(liste_groupe[[#This Row],[Units]]),CONCATENATE(liste_groupe[[#This Row],[Chemical name]],liste_groupe[[#This Row],[Do not fill in3]]),CONCATENATE(liste_groupe[[#This Row],[Chemical name]],"-",liste_groupe[[#This Row],[Concentration]],liste_groupe[[#This Row],[Units]],liste_groupe[[#This Row],[Do not fill in3]]))) -> Estrone-25µg/L + Testostérone | B42: =B18 -> test chemical | C42: =C18 -> 25 | D42: =D18 -> µg/L | E42: =E18 -> Estrone | F42: + Testostérone
A43: =IF(ISBLANK(liste_groupe[[#This Row],[Do not fill in2]])," ",IF(ISBLANK(liste_groupe[[#This Row],[Units]]),CONCATENATE(liste_groupe[[#This Row],[Chemical name]],liste_groupe[[#This Row],[Do not fill in3]]),CONCATENATE(liste_groupe[[#This Row],[Chemical name]],"-",liste_groupe[[#This Row],[Concentration]],liste_groupe[[#This Row],[Units]],liste_groupe[[#This Row],[Do not fill in3]]))) -> 0-00 + Testostérone | B43: =B19 -> test chemical | C43: =C19 -> 0 | D43: =D19 -> 0 | E43: =E19 -> 0 | F43: + Testostérone
A44: =IF(ISBLANK(liste_groupe[[#This Row],[Do not fill in2]])," ",IF(ISBLANK(liste_groupe[[#This Row],[Units]]),CONCATENATE(liste_groupe[[#This Row],[Chemical name]],liste_groupe[[#This Row],[Do not fill in3]]),CONCATENATE(liste_groupe[[#This Row],[Chemical name]],"-",liste_groupe[[#This Row],[Concentration]],liste_groupe[[#This Row],[Units]],liste_groupe[[#This Row],[Do not fill in3]]))) -> 0-00 + Testostérone | B44: =B20 -> test chemical | C44: =C20 -> 0 | D44: =D20 -> 0 | E44: =E20 -> 0 | F44: + Testostérone
A45: =IF(ISBLANK(liste_groupe[[#This Row],[Do not fill in2]])," ",IF(ISBLANK(liste_groupe[[#This Row],[Units]]),CONCATENATE(liste_groupe[[#This Row],[Chemical name]],liste_groupe[[#This Row],[Do not fill in3]]),CONCATENATE(liste_groupe[[#This Row],[Chemical name]],"-",liste_groupe[[#This Row],[Concentration]],liste_groupe[[#This Row],[Units]],liste_groupe[[#This Row],[Do not fill in3]]))) -> 0-00 + Testostérone | B45: =B21 -> test chemical | C45: =C21 -> 0 | D45: =D21 -> 0 | E45: =E21 -> 0 | F45: + Testostérone
...

Sheet Feuil1
A1: R1 Start of the exposure: 15h45 (09.02.2022) start of reading : 15h30 (10.02.2022) (end of the reading 18h30)
A4: In the group Testo + Fadrozole : only 7 pictures because a technical problem when the picture was saved (half of the picture is gray). We can get rid of the value or do another analysis with a croped picture?
A8: R2 : Start of the exposure : 10.02, start of reading 12h until 15h
A10: 6 deads in the Estrone 25 mg/L well, the 2 remaining embryos was close to death. And not light up at all
A12: In the embryos used for R1 did not looked nice : 1/3 hatched correctly, 1/3 hatched with a curved spine, 1/3 didnt hatched at jpf7

Sheet R1
A3: R1 | B3: Unspiked | O3: Testosterone spiked
A4: Group names | B4: ='Front page'!A7 -> Solvent control | C4: ='Front page'!A8 -> EE2-33.8ng/L | D4: ='Front page'!A9 -> EE2-50.6ng/L | E4: ='Front page'!A10 -> EE2-76ng/L | F4: ='Front page'!A11 -> EE2-114ng/L | G4: ='Front page'!A12 -> EE2-170.9ng/L | H4: ='Front page'!A13 -> EE2-488ng/L | I4: ='Front page'!A14 -> Estrone-0.04µg/L | J4: ='Front page'!A15 -> Estrone-0.2µg/L | K4: ='Front page'!A16 -> Estrone-1µg/L | L4: ='Front page'!A17 -> Estrone-5µg/L | M4: ='Front page'!A18 -> Estrone-25µg/L | O4: ='Front page'!A35 -> Testo -30µg/L | P4: ='Front page'!A36 -> Testo 30µg/L + EE2 -64ng/L | Q4: ='Front page'!A37 -> Testo 30µg/L + FAD-10mg/L | R4: ='Front page'!A38 -> Estrone-0.04µg/L + Testostérone | S4: ='Front page'!A39 -> Estrone-0.2µg/L + Testostérone | T4: ='Front page'!A40 -> Estrone-1µg/L + Testostérone | U4: ='Front page'!A41 -> Estrone-5µg/L + Testostérone | V4: ='Front page'!A42 -> Estrone-25µg/L + Testostérone
A5: Raw data | B5: 460516 | C5: 154767 | D5: 304641 | E5: 767946 | F5: 3499126 | G5: 4065868 | H5: 6216468 | I5: 120140 | J5: 17127 | K5: 43276 | L5: 7350933 | M5: 10218264 | O5: 1208389 | P5: 4341670 | Q5: 59694 | R5: 1028627 | S5: 2288918 | T5: 4605139 | U5: 8227139 | V5: 6832148
B6: 121006 | C6: 34380 | D6: 217309 | E6: 197269 | F6: 2089830 | G6: 2699167 | H6: 8594881 | I6: 466554 | J6: 65450 | K6: 1577835 | L6: 4948028 | M6: 2031029 | O6: 610108 | P6: 1061513 | Q6: 193297 | R6: 3537944 | S6: 3909521 | T6: 7139065 | U6: 9532429 | V6: 5647024
B7: 40550 | C7: 360721 | D7: 146880 | E7: 597346 | F7: 1407147 | G7: 2824200 | H7: 8636929 | I7: 221890 | J7: 124360 | K7: 187670 | L7: 6830685 | M7: 10207333 | O7: 1051750 | P7: 6575230 | Q7: 509042 | R7: 3585093 | S7: 5050297 | T7: 2959656 | U7: 3061895 | V7: 9941655
B8: 53094 | C8: 344097 | D8: 748608 | E8: 302042 | F8: 3407131 | G8: 4204638 | H8: 8970874 | I8: 22654 | J8: 99056 | K8: 601125 | L8: 6970468 | M8: 9296723 | O8: 2595395 | P8: 5892886 | Q8: 757127 | R8: 4185361 | S8: 3591559 | T8: 5631530 | U8: 10406767 | V8: 8117949
B9: 75087 | C9: 77787 | D9: 234915 | E9: 700636 | F9: 1763103 | G9: 4443005 | H9: 6909642 | I9: 77501 | J9: 232367 | K9: 85237 | L9: 4069831 | M9: 11759164 | O9: 2510173 | P9: 6207305 | Q9: 600 | R9: 5178763 | S9: 6572033 | T9: 5108736 | U9: 5756618 | V9: 9521278
B10: 68929 | C10: 6194 | D10: 137492 | E10: 687994 | F10: 700008 | G10: 6553005 | H10: 3075559 | I10: 138073 | J10: 85130 | K10: 710239 | L10: 9605732 | M10: 6824751 | O10: 4189082 | P10: 5587389 | Q10: 72680 | R10: 2780175 | S10: 4362055 | T10: 1594421 | U10: 7961656 | V10: 9507970
B11: 276722 | C11: 131435 | D11: 490774 | E11: 863991 | F11: 4290628 | G11: 3745163 | H11: 10020915 | I11: 384 | J11: 30573 | K11: 86996 | L11: 6274060 | M11: 7589197 | O11: 147960 | P11: 2109787 | Q11: 271968 | R11: 432076 | S11: 913864 | T11: 5483057 | U11: 11349985 | V11: 5671926
B12: 253389 | C12: 11562 | D12: 128915 | E12: 1095426 | G12: 2374348 | H12: 4995155 | I12: 54294 | J12: 22296 | K12: 9588 | L12: 7498810 | M12: 9567521 | O12: 1523142 | P12: 4459517 | Q12: 8017175 | R12: 2150522 | S12: 2001073 | T12: 5423980 | V12: 9029063
O13: 3209674
O14: 3132146
O15: 2576970
O16: 4394890
O17: 2383529
O18: 2117810
O19: 548401
O20: 351225
A22: =A4 -> Group names | B22: =B4 -> Solvent control | C22: =C4 -> EE2-33.8ng/L | D22: =D4 -> EE2-50.6ng/L | E22: =E4 -> EE2-76ng/L | F22: =F4 -> EE2-114ng/L | G22: =G4 -> EE2-170.9ng/L | H22: =H4 -> EE2-488ng/L | ... M22: =M4 -> Estrone-25µg/L | N22: Nom des groupes | O22: =O4 -> Testo -30µg/L | P22: =P4 -> Testo 30µg/L + EE2 -64ng/L | Q22: =Q4 -> Testo 30µg/L + FAD-10mg/L | R22: =R4 -> Estrone-0.04µg/L + Testostérone | S22: =S4 -> Estrone-0.2µg/L + Testostérone | T22: =T4 -> Estrone-1µg/L + Testostérone | U22: =U4 -> Estrone-5µg/L + Testostérone | V22: =V4 -> Estrone-25µg/L + Testostérone
A23: mean | B23: =AVERAGE(B5:B20) -> 168661.62 | C23: =AVERAGE(C5:C20) -> 140117.88 | D23: =AVERAGE(D5:D20) -> 301191.75 | E23: =AVERAGE(E5:E20) -> 651581.25 | F23: =AVERAGE(F5:F20) -> 2450996.1 | G23: =AVERAGE(G5:G20) -> 3863674.2 | H23: =AVERAGE(H5:H20) -> 7177552.9 | I23: =AVERAGE(I5:I20) -> 137686.25 | ... M23: =AVERAGE(M5:M20) -> 8436747.8 | N23: mean | O23: =AVERAGE(O5:O20) -> 2034415.2 | P23: =AVERAGE(P5:P20) -> 4529412.1 | Q23: =AVERAGE(Q5:Q20) -> 1235197.9 | R23: =AVERAGE(R5:R20) -> 2859820.1 | S23: =AVERAGE(S5:S20) -> 3586165 | T23: =AVERAGE(T5:T20) -> 4743198 | U23: =AVERAGE(U5:U20) -> 8042355.6 | V23: =AVERAGE(V5:V20) -> 8033626.6
A24: SD | B24: =STDEV(B5:B20) -> 148697.72 | C24: =STDEV(C5:C20) -> 141467.34 | D24: =STDEV(D5:D20) -> 216416.45 | E24: =STDEV(E5:E20) -> 290543.3 | F24: =STDEV(F5:F20) -> 1301040.2 | G24: =STDEV(G5:G20) -> 1330627.4 | H24: =STDEV(H5:H20) -> 2330664.6 | I24: =STDEV(I5:I20) -> 150339.21 | ... M24: =STDEV(M5:M20) -> 3016988.5 | N24: SD | O24: =STDEV(O5:O20) -> 1324210.5 | P24: =STDEV(P5:P20) -> 1996429.5 | Q24: =STDEV(Q5:Q20) -> 2752192 | R24: =STDEV(R5:R20) -> 1598083 | S24: =STDEV(S5:S20) -> 1816678.4 | T24: =STDEV(T5:T20) -> 1723313.5 | U24: =STDEV(U5:U20) -> 2852525.6 | V24: =STDEV(V5:V20) -> 1762401.9
B26: Unspiked | O26: Testosterone spiked
A27: =A4 -> Group names | B27: =B4 -> Solvent control | C27: =C4 -> EE2-33.8ng/L | D27: =D4 -> EE2-50.6ng/L | E27: =E4 -> EE2-76ng/L | F27: =F4 -> EE2-114ng/L | G27: =G4 -> EE2-170.9ng/L | H27: =H4 -> EE2-488ng/L | ... M27: =M4 -> Estrone-25µg/L | O27: =O4 -> Testo -30µg/L | P27: =P4 -> Testo 30µg/L + EE2 -64ng/L | Q27: =Q4 -> Testo 30µg/L + FAD-10mg/L | R27: =R4 -> Estrone-0.04µg/L + Testostérone | S27: =S4 -> Estrone-0.2µg/L + Testostérone | T27: =T4 -> Estrone-1µg/L + Testostérone | U27: =U4 -> Estrone-5µg/L + Testostérone | V27: =V4 -> Estrone-25µg/L + Testostérone
A28: Data normalised to the "Testo" group | B28: =IF(B5="","",(B5/$O$23)) -> 0.22636283 | C28: =IF(C5="","",(C5/$O$23)) -> 0.07607444 | D28: =IF(D5="","",(D5/$O$23)) -> 0.14974377 | E28: =IF(E5="","",(E5/$O$23)) -> 0.37747751 | F28: =IF(F5="","",(F5/$O$23)) -> 1.7199665 | G28: =IF(G5="","",(G5/$O$23)) -> 1.9985438 | H28: =IF(H5="","",(H5/$O$23)) -> 3.0556535 | I28: =IF(I5="","",(I5/$O$23)) -> 0.059053824 | ... M28: =IF(M5="","",(M5/$O$23)) -> 5.0227032 | O28: =IF(O5="","",(O5/$O$23)) -> 0.59397362 | P28: =IF(P5="","",(P5/$O$23)) -> 2.134112 | Q28: =IF(Q5="","",(Q5/$O$23)) -> 0.029342092 | R28: =IF(R5="","",(R5/$O$23)) -> 0.5056131 | S28: =IF(S5="","",(S5/$O$23)) -> 1.1250987 | T28: =IF(T5="","",(T5/$O$23)) -> 2.263618 | U28: =IF(U5="","",(U5/$O$23)) -> 4.0439822 | V28: =IF(V5="","",(V5/$O$23)) -> 3.3582859
B29: =IF(B6="","",(B6/$O$23)) -> 0.059479499 | C29: =IF(C6="","",(C6/$O$23)) -> 0.016899205 | D29: =IF(D6="","",(D6/$O$23)) -> 0.10681644 | E29: =IF(E6="","",(E6/$O$23)) -> 0.096965946 | F29: =IF(F6="","",(F6/$O$23)) -> 1.0272387 | G29: =IF(G6="","",(G6/$O$23)) -> 1.3267532 | H29: =IF(H6="","",(H6/$O$23)) -> 4.2247427 | I29: =IF(I6="","",(I6/$O$23)) -> 0.22933076 | ... M29: =IF(M6="","",(M6/$O$23)) -> 0.99833552 | O29: =IF(O6="","",(O6/$O$23)) -> 0.29989354 | P29: =IF(P6="","",(P6/$O$23)) -> 0.52177794 | Q29: =IF(Q6="","",(Q6/$O$23)) -> 0.095013543 | R29: =IF(R6="","",(R6/$O$23)) -> 1.7390471 | S29: =IF(S6="","",(S6/$O$23)) -> 1.9216927 | T29: =IF(T6="","",(T6/$O$23)) -> 3.5091484 | U29: =IF(U6="","",(U6/$O$23)) -> 4.6855867 | V29: =IF(V6="","",(V6/$O$23)) -> 2.775748
B30: =IF(B7="","",(B7/$O$23)) -> 0.019932017 | C30: =IF(C7="","",(C7/$O$23)) -> 0.17730943 | D30: =IF(D7="","",(D7/$O$23)) -> 0.07219765 | E30: =IF(E7="","",(E7/$O$23)) -> 0.29362049 | F30: =IF(F7="","",(F7/$O$23)) -> 0.69167148 | G30: =IF(G7="","",(G7/$O$23)) -> 1.3882122 | H30: =IF(H7="","",(H7/$O$23)) -> 4.2454111 | I30: =IF(I7="","",(I7/$O$23)) -> 0.1090682 | ... M30: =IF(M7="","",(M7/$O$23)) -> 5.0173302 | O30: =IF(O7="","",(O7/$O$23)) -> 0.51697902 | P30: =IF(P7="","",(P7/$O$23)) -> 3.232 | Q30: =IF(Q7="","",(Q7/$O$23)) -> 0.25021539 | R30: =IF(R7="","",(R7/$O$23)) -> 1.7622228 | S30: =IF(S7="","",(S7/$O$23)) -> 2.4824317 | T30: =IF(T7="","",(T7/$O$23)) -> 1.4547944 | U30: =IF(U7="","",(U7/$O$23)) -> 1.5050492 | V30: =IF(V7="","",(V7/$O$23)) -> 4.8867383
B31: =IF(B8="","",(B8/$O$23)) -> 0.026097917 | C31: =IF(C8="","",(C8/$O$23)) -> 0.16913804 | D31: =IF(D8="","",(D8/$O$23)) -> 0.36797207 | E31: =IF(E8="","",(E8/$O$23)) -> 0.14846625 | F31: =IF(F8="","",(F8/$O$23)) -> 1.6747471 | G31: =IF(G8="","",(G8/$O$23)) -> 2.0667551 | H31: =IF(H8="","",(H8/$O$23)) -> 4.409559 | I31: =IF(I8="","",(I8/$O$23)) -> 0.011135386 | ... M31: =IF(M8="","",(M8/$O$23)) -> 4.5697273 | O31: =IF(O8="","",(O8/$O$23)) -> 1.275745 | P31: =IF(P8="","",(P8/$O$23)) -> 2.8965994 | Q31: =IF(Q8="","",(Q8/$O$23)) -> 0.37215952 | R31: =IF(R8="","",(R8/$O$23)) -> 2.0572796 | S31: =IF(S8="","",(S8/$O$23)) -> 1.7654011 | T31: =IF(T8="","",(T8/$O$23)) -> 2.768132 | U31: =IF(U8="","",(U8/$O$23)) -> 5.1153603 | V31: =IF(V8="","",(V8/$O$23)) -> 3.9903107
B32: =IF(B9="","",(B9/$O$23)) -> 0.036908394 | C32: =IF(C9="","",(C9/$O$23)) -> 0.038235557 | D32: =IF(D9="","",(D9/$O$23)) -> 0.11547053 | E32: =IF(E9="","",(E9/$O$23)) -> 0.34439183 | F32: =IF(F9="","",(F9/$O$23)) -> 0.86663871 | G32: =IF(G9="","",(G9/$O$23)) -> 2.1839224 | H32: =IF(H9="","",(H9/$O$23)) -> 3.3963774 | I32: =IF(I9="","",(I9/$O$23)) -> 0.038094976 | ... M32: =IF(M9="","",(M9/$O$23)) -> 5.7801199 | O32: =IF(O9="","",(O9/$O$23)) -> 1.2338548 | P32: =IF(P9="","",(P9/$O$23)) -> 3.0511495 | Q32: =IF(Q9="","",(Q9/$O$23)) -> 0.00029492504 | R32: =IF(R9="","",(R9/$O$23)) -> 2.5455781 | S32: =IF(S9="","",(S9/$O$23)) -> 3.2304285 | T32: =IF(T9="","",(T9/$O$23)) -> 2.511157 | U32: =IF(U9="","",(U9/$O$23)) -> 2.829618 | V32: =IF(V9="","",(V9/$O$23)) -> 4.6801055
B33: =IF(B10="","",(B10/$O$23)) -> 0.03388148 | C33: =IF(C10="","",(C10/$O$23)) -> 0.0030446095 | D33: =IF(D10="","",(D10/$O$23)) -> 0.067583056 | E33: =IF(E10="","",(E10/$O$23)) -> 0.33817776 | F33: =IF(F10="","",(F10/$O$23)) -> 0.34408315 | G33: =IF(G10="","",(G10/$O$23)) -> 3.2210754 | H33: =IF(H10="","",(H10/$O$23)) -> 1.5117656 | I33: =IF(I10="","",(I10/$O$23)) -> 0.067868642 | ... M33: =IF(M10="","",(M10/$O$23)) -> 3.3546499 | O33: =IF(O10="","",(O10/$O$23)) -> 2.0591086 | P33: =IF(P10="","",(P10/$O$23)) -> 2.7464349 | Q33: =IF(Q10="","",(Q10/$O$23)) -> 0.035725253 | R33: =IF(R10="","",(R10/$O$23)) -> 1.366572 | S33: =IF(S10="","",(S10/$O$23)) -> 2.1441321 | T33: =IF(T10="","",(T10/$O$23)) -> 0.78372446 | U33: =IF(U10="","",(U10/$O$23)) -> 3.9134862 | V33: =IF(V10="","",(V10/$O$23)) -> 4.6735641
B34: =IF(B11="","",(B11/$O$23)) -> 0.13602041 | C34: =IF(C11="","",(C11/$O$23)) -> 0.064605788 | D34: =IF(D11="","",(D11/$O$23)) -> 0.2412359 | E34: =IF(E11="","",(E11/$O$23)) -> 0.42468763 | F34: =IF(F11="","",(F11/$O$23)) -> 2.1090227 | G34: =IF(G11="","",(G11/$O$23)) -> 1.8409039 | H34: =IF(H11="","",(H11/$O$23)) -> 4.9256979 | I34: =IF(I11="","",(I11/$O$23)) -> 0.00018875203 | ... M34: =IF(M11="","",(M11/$O$23)) -> 3.7304071 | O34: =IF(O11="","",(O11/$O$23)) -> 0.072728515 | P34: =IF(P11="","",(P11/$O$23)) -> 1.0370484 | Q34: =IF(Q11="","",(Q11/$O$23)) -> 0.13368362 | R34: =IF(R11="","",(R11/$O$23)) -> 0.21238339 | S34: =IF(S11="","",(S11/$O$23)) -> 0.4492023 | T34: =IF(T11="","",(T11/$O$23)) -> 2.6951513 | U34: =IF(U11="","",(U11/$O$23)) -> 5.5789913 | V34: =IF(V11="","",(V11/$O$23)) -> 2.7879883
B35: =IF(B12="","",(B12/$O$23)) -> 0.12455127 | C35: =IF(C12="","",(C12/$O$23)) -> 0.0056832055 | D35: =IF(D12="","",(D12/$O$23)) -> 0.063367103 | E35: =IF(E12="","",(E12/$O$23)) -> 0.5384476 | F35: =IF(F12="","",(F12/$O$23)) | G35: =IF(G12="","",(G12/$O$23)) -> 1.1670911 | H35: =IF(H12="","",(H12/$O$23)) -> 2.4553272 | I35: =IF(I12="","",(I12/$O$23)) -> 0.026687767 | ... M35: =IF(M12="","",(M12/$O$23)) -> 4.7028359 | O35: =IF(O12="","",(O12/$O$23)) -> 0.74868786 | P35: =IF(P12="","",(P12/$O$23)) -> 2.1920387 | Q35: =IF(Q12="","",(Q12/$O$23)) -> 3.9407761 | R35: =IF(R12="","",(R12/$O$23)) -> 1.0570713 | S35: =IF(S12="","",(S12/$O$23)) -> 0.98361089 | T35: =IF(T12="","",(T12/$O$23)) -> 2.6661125 | U35: =IF(U12="","",(U12/$O$23)) | V35: =IF(V12="","",(V12/$O$23)) -> 4.4381613
B36: =IF(B13="","",(B13/$O$23)) | C36: =IF(C13="","",(C13/$O$23)) | D36: =IF(D13="","",(D13/$O$23)) | E36: =IF(E13="","",(E13/$O$23)) | F36: =IF(F13="","",(F13/$O$23)) | G36: =IF(G13="","",(G13/$O$23)) | H36: =IF(H13="","",(H13/$O$23)) | I36: =IF(I13="","",(I13/$O$23)) | ... M36: =IF(M13="","",(M13/$O$23)) | O36: =IF(O13="","",(O13/$O$23)) -> 1.5776887 | P36: =IF(P13="","",(P13/$O$23)) | Q36: =IF(Q13="","",(Q13/$O$23)) | R36: =IF(R13="","",(R13/$O$23)) | S36: =IF(S13="","",(S13/$O$23)) | T36: =IF(T13="","",(T13/$O$23)) | U36: =IF(U13="","",(U13/$O$23)) | V36: =IF(V13="","",(V13/$O$23))
B37: =IF(B14="","",(B14/$O$23)) | C37: =IF(C14="","",(C14/$O$23)) | D37: =IF(D14="","",(D14/$O$23)) | E37: =IF(E14="","",(E14/$O$23)) | F37: =IF(F14="","",(F14/$O$23)) | G37: =IF(G14="","",(G14/$O$23)) | H37: =IF(H14="","",(H14/$O$23)) | I37: =IF(I14="","",(I14/$O$23)) | ... M37: =IF(M14="","",(M14/$O$23)) | O37: =IF(O14="","",(O14/$O$23)) -> 1.5395805 | P37: =IF(P14="","",(P14/$O$23)) | Q37: =IF(Q14="","",(Q14/$O$23)) | R37: =IF(R14="","",(R14/$O$23)) | S37: =IF(S14="","",(S14/$O$23)) | T37: =IF(T14="","",(T14/$O$23)) | U37: =IF(U14="","",(U14/$O$23)) | V37: =IF(V14="","",(V14/$O$23))
B38: =IF(B15="","",(B15/$O$23)) | C38: =IF(C15="","",(C15/$O$23)) | D38: =IF(D15="","",(D15/$O$23)) | E38: =IF(E15="","",(E15/$O$23)) | F38: =IF(F15="","",(F15/$O$23)) | G38: =IF(G15="","",(G15/$O$23)) | H38: =IF(H15="","",(H15/$O$23)) | I38: =IF(I15="","",(I15/$O$23)) | ... M38: =IF(M15="","",(M15/$O$23)) | O38: =IF(O15="","",(O15/$O$23)) -> 1.2666883 | P38: =IF(P15="","",(P15/$O$23)) | Q38: =IF(Q15="","",(Q15/$O$23)) | R38: =IF(R15="","",(R15/$O$23)) | S38: =IF(S15="","",(S15/$O$23)) | T38: =IF(T15="","",(T15/$O$23)) | U38: =IF(U15="","",(U15/$O$23)) | V38: =IF(V15="","",(V15/$O$23))
B39: =IF(B16="","",(B16/$O$23)) | C39: =IF(C16="","",(C16/$O$23)) | D39: =IF(D16="","",(D16/$O$23)) | E39: =IF(E16="","",(E16/$O$23)) | F39: =IF(F16="","",(F16/$O$23)) | G39: =IF(G16="","",(G16/$O$23)) | H39: =IF(H16="","",(H16/$O$23)) | I39: =IF(I16="","",(I16/$O$23)) | ... M39: =IF(M16="","",(M16/$O$23)) | O39: =IF(O16="","",(O16/$O$23)) -> 2.1602719 | P39: =IF(P16="","",(P16/$O$23)) | Q39: =IF(Q16="","",(Q16/$O$23)) | R39: =IF(R16="","",(R16/$O$23)) | S39: =IF(S16="","",(S16/$O$23)) | T39: =IF(T16="","",(T16/$O$23)) | U39: =IF(U16="","",(U16/$O$23)) | V39: =IF(V16="","",(V16/$O$23))
B40: =IF(B17="","",(B17/$O$23)) | C40: =IF(C17="","",(C17/$O$23)) | D40: =IF(D17="","",(D17/$O$23)) | E40: =IF(E17="","",(E17/$O$23)) | F40: =IF(F17="","",(F17/$O$23)) | G40: =IF(G17="","",(G17/$O$23)) | H40: =IF(H17="","",(H17/$O$23)) | I40: =IF(I17="","",(I17/$O$23)) | ... M40: =IF(M17="","",(M17/$O$23)) | O40: =IF(O17="","",(O17/$O$23)) -> 1.171604 | P40: =IF(P17="","",(P17/$O$23)) | Q40: =IF(Q17="","",(Q17/$O$23)) | R40: =IF(R17="","",(R17/$O$23)) | S40: =IF(S17="","",(S17/$O$23)) | T40: =IF(T17="","",(T17/$O$23)) | U40: =IF(U17="","",(U17/$O$23)) | V40: =IF(V17="","",(V17/$O$23))
... B43: =IF(B20="","",(B20/$O$23)) | C43: =IF(C20="","",(C20/$O$23)) | D43: =IF(D20="","",(D20/$O$23)) | E43: =IF(E20="","",(E20/$O$23)) | F43: =IF(F20="","",(F20/$O$23)) | G43: =IF(G20="","",(G20/$O$23)) | H43: =IF(H20="","",(H20/$O$23)) | I43: =IF(I20="","",(I20/$O$23)) | ... M43: =IF(M20="","",(M20/$O$23)) | O43: =IF(O20="","",(O20/$O$23)) -> 0.17264175 | P43: =IF(P20="","",(P20/$O$23)) | Q43: =IF(Q20="","",(Q20/$O$23)) | R43: =IF(R20="","",(R20/$O$23)) | S43: =IF(S20="","",(S20/$O$23)) | T43: =IF(T20="","",(T20/$O$23)) | U43: =IF(U20="","",(U20/$O$23)) | V43: =IF(V20="","",(V20/$O$23))
A45: =A4 -> Group names | B45: =B4 -> Solvent control | C45: =C4 -> EE2-33.8ng/L | D45: =D4 -> EE2-50.6ng/L | E45: =E4 -> EE2-76ng/L | F45: =F4 -> EE2-114ng/L | G45: =G4 -> EE2-170.9ng/L | H45: =H4 -> EE2-488ng/L | ... M45: =M4 -> Estrone-25µg/L | N45: =N22 -> Nom des groupes | O45: =O4 -> Testo -30µg/L | P45: =P4 -> Testo 30µg/L + EE2 -64ng/L | Q45: =Q4 -> Testo 30µg/L + FAD-10mg/L | R45: =R4 -> Estrone-0.04µg/L + Testostérone | S45: =S4 -> Estrone-0.2µg/L + Testostérone | T45: =T4 -> Estrone-1µg/L + Testostérone | U45: =U4 -> Estrone-5µg/L + Testostérone | V45: =V4 -> Estrone-25µg/L + Testostérone
A46: mean | B46: =AVERAGE(B28:B43) -> 0.082904228 | C46: =AVERAGE(C28:C43) -> 0.068873783 | D46: =AVERAGE(D28:D43) -> 0.14804832 | E46: =AVERAGE(E28:E43) -> 0.32027938 | F46: =AVERAGE(F28:F43) -> 1.2047669 | G46: =AVERAGE(G28:G43) -> 1.8991571 | H46: =AVERAGE(H28:H43) -> 3.5280668 | I46: =AVERAGE(I28:I43) -> 0.067678538 | ... M46: =AVERAGE(M28:M43) -> 4.1470136 | N46: mean | O46: =AVERAGE(O28:O43) -> 1 | P46: =AVERAGE(P28:P43) -> 2.2263951 | Q46: =AVERAGE(Q28:Q43) -> 0.60715131 | R46: =AVERAGE(R28:R43) -> 1.4057209 | S46: =AVERAGE(S28:S43) -> 1.7627498 | T46: =AVERAGE(T28:T43) -> 2.3314798 | U46: =AVERAGE(U28:U43) -> 3.9531534 | V46: =AVERAGE(V28:V43) -> 3.9488628
A47: SD | B47: =STDEV(B28:B43) -> 0.073091134 | C47: =STDEV(C28:C43) -> 0.069537103 | D47: =STDEV(D28:D43) -> 0.10637772 | E47: =STDEV(E28:E43) -> 0.14281416 | F47: =STDEV(F28:F43) -> 0.63951557 | G47: =STDEV(G28:G43) -> 0.65405888 | H47: =STDEV(H28:H43) -> 1.1456189 | I47: =STDEV(I28:I43) -> 0.073897996 | ... M47: =STDEV(M28:M43) -> 1.4829757 | N47: SD | O47: =STDEV(O28:O43) -> 0.65090474 | P47: =STDEV(P28:P43) -> 0.98132839 | Q47: =STDEV(Q28:Q43) -> 1.3528172 | R47: =STDEV(R28:R43) -> 0.78552448 | S47: =STDEV(S28:S43) -> 0.89297325 | T47: =STDEV(T28:T43) -> 0.84708048 | U47: =STDEV(U28:U43) -> 1.4021354 | V47: =STDEV(V28:V43) -> 0.8662941
...

Sheet R2
A3: R2 | B3: Unspiked | O3: Testosterone spiked
A4: Group names | B4: ='Front page'!A7 -> Solvent control | C4: ='Front page'!A8 -> EE2-33.8ng/L | D4: ='Front page'!A9 -> EE2-50.6ng/L | E4: ='Front page'!A10 -> EE2-76ng/L | F4: ='Front page'!A11 -> EE2-114ng/L | G4: ='Front page'!A12 -> EE2-170.9ng/L | H4: ='Front page'!A13 -> EE2-488ng/L | I4: ='Front page'!A14 -> Estrone-0.04µg/L | J4: ='Front page'!A15 -> Estrone-0.2µg/L | K4: ='Front page'!A16 -> Estrone-1µg/L | L4: ='Front page'!A17 -> Estrone-5µg/L | M4: ='Front page'!A18 -> Estrone-25µg/L | O4: ='Front page'!A35 -> Testo -30µg/L | P4: ='Front page'!A36 -> Testo 30µg/L + EE2 -64ng/L | Q4: ='Front page'!A37 -> Testo 30µg/L + FAD-10mg/L | R4: ='Front page'!A38 -> Estrone-0.04µg/L + Testostérone | S4: ='Front page'!A39 -> Estrone-0.2µg/L + Testostérone | T4: ='Front page'!A40 -> Estrone-1µg/L + Testostérone | U4: ='Front page'!A41 -> Estrone-5µg/L + Testostérone | V4: ='Front page'!A42 -> Estrone-25µg/L + Testostérone
A5: Raw data | B5: 305217 | C5: 58590 | D5: 95889 | E5: 3564799 | F5: 1183619 | G5: 4632668 | H5: 4381135 | I5: 248905 | J5: 148896 | K5: 978579 | L5: 6338972 | O5: 4057873 | P5: 6265745 | Q5: 118416 | R5: 4397980 | S5: 3593712 | T5: 2250586 | U5: 6813132 | V5: 10909006
B6: 26943 | C6: 803685 | D6: 1364889 | E6: 1570998 | F6: 9359684 | G6: 6058316 | H6: 6003363 | I6: 78049 | J6: 88161 | K6: 1193809 | L6: 7666578 | O6: 5299284 | P6: 7834906 | Q6: 70832 | R6: 4259943 | S6: 3166045 | T6: 6080131 | U6: 10131885 | V6: 10109318
B7: 544707 | C7: 260148 | D7: 267311 | E7: 1022016 | F7: 6028957 | G7: 2730310 | H7: 10312751 | I7: 41033 | J7: 240187 | K7: 1444052 | L7: 7765633 | O7: 4340526 | P7: 6122385 | Q7: 203420 | R7: 3463646 | S7: 4669516 | T7: 5075563 | U7: 3783209 | V7: 8279756
B8: 1147853 | C8: 26991 | D8: 5725054 | E8: 3830520 | F8: 3080965 | G8: 4479328 | H8: 6819276 | I8: 52826 | J8: 127459 | K8: 106082 | L8: 3950339 | O8: 3613929 | P8: 7044763 | Q8: 330439 | R8: 2684299 | S8: 5020190 | T8: 6366718 | U8: 8793481 | V8: 7454509
B9: 67656 | C9: 98975 | D9: 131205 | E9: 393420 | F9: 2434121 | G9: 4946377 | H9: 11599237 | I9: 77445 | J9: 86562 | K9: 1270556 | L9: 8693529 | O9: 3124823 | P9: 8078230 | Q9: 44878 | R9: 2849756 | S9: 445360 | T9: 4550719 | U9: 9349788 | V9: 5373383
B10: 566626 | C10: 148075 | D10: 197768 | E10: 523581 | F10: 2879141 | G10: 4386312 | H10: 5877475 | I10: 98415 | J10: 22151 | K10: 1420485 | L10: 6791730 | O10: 4113260 | P10: 7807673 | Q10: 387437 | R10: 2308110 | S10: 3766427 | T10: 4686024 | U10: 4257696 | V10: 7124171
B11: 248673 | C11: 90741 | D11: 156354 | E11: 1647190 | F11: 818764 | G11: 5666062 | H11: 6872517 | I11: 888 | J11: 72892 | K11: 216801 | L11: 8761068 | O11: 1382800 | P11: 10322436 | Q11: 90708 | R11: 4460719 | S11: 4563775 | T11: 3467922 | U11: 9709234 | V11: 7182911
B12: 71293 | C12: 389287 | D12: 69827 | E12: 1270264 | F12: 6472030 | G12: 2731667 | H12: 9989392 | I12: 165172 | J12: 54811 | K12: 86174 | L12: 9450389 | O12: 4220841 | P12: 7771367 | Q12: 516219 | R12: 3500524 | S12: 5906541 | T12: 3862252 | U12: 7891671 | V12: 6092303
O13: 1898306
O14: 4872254
O15: 3383261
O16: 3712936
O17: 3079447
O18: 2169490
O19: 4834729
O20: 257941
A22: =A4 -> Group names | B22: =B4 -> Solvent control | C22: =C4 -> EE2-33.8ng/L | D22: =D4 -> EE2-50.6ng/L | E22: =E4 -> EE2-76ng/L | F22: =F4 -> EE2-114ng/L | G22: =G4 -> EE2-170.9ng/L | H22: =H4 -> EE2-488ng/L | ... M22: =M4 -> Estrone-25µg/L | N22: Noms des groupes | O22: =O4 -> Testo -30µg/L | P22: =P4 -> Testo 30µg/L + EE2 -64ng/L | Q22: =Q4 -> Testo 30µg/L + FAD-10mg/L | R22: =R4 -> Estrone-0.04µg/L + Testostérone | S22: =S4 -> Estrone-0.2µg/L + Testostérone | T22: =T4 -> Estrone-1µg/L + Testostérone | U22: =U4 -> Estrone-5µg/L + Testostérone | V22: =V4 -> Estrone-25µg/L + Testostérone
A23: mean | B23: =AVERAGE(B5:B20) -> 372371 | C23: =AVERAGE(C5:C20) -> 234561.5 | D23: =AVERAGE(D5:D20) -> 1001037.1 | E23: =AVERAGE(E5:E20) -> 1727848.5 | F23: =AVERAGE(F5:F20) -> 4032160.1 | G23: =AVERAGE(G5:G20) -> 4453880 | H23: =AVERAGE(H5:H20) -> 7731893.2 | I23: =AVERAGE(I5:I20) -> 95341.625 | J23: =AVERAGE(J5:J20) -> 105139.88 | L23: =AVERAGE(L5:L20) -> 7427279.8 | N23: mean | O23: =AVERAGE(O5:O20) -> 3397606.2 | P23: =AVERAGE(P5:P20) -> 7655938.1 | Q23: =AVERAGE(Q5:Q20) -> 220293.62 | R23: =AVERAGE(R5:R20) -> 3490622.1 | S23: =AVERAGE(S5:S20) -> 3891445.8 | T23: =AVERAGE(T5:T20) -> 4542489.4 | U23: =AVERAGE(U5:U20) -> 7591262 | V23: =AVERAGE(V5:V20) -> 7815669.6
A24: SD | B24: =STDEV(B5:B20) -> 376342.85 | C24: =STDEV(C5:C20) -> 258869.97 | D24: =STDEV(D5:D20) -> 1956266.9 | E24: =STDEV(E5:E20) -> 1296438.3 | F24: =STDEV(F5:F20) -> 2965292.8 | G24: =STDEV(G5:G20) -> 1210669.4 | H24: =STDEV(H5:H20) -> 2561783.3 | I24: =STDEV(I5:I20) -> 78162.152 | J24: =STDEV(J5:J20) -> 67341.308 | L24: =STDEV(L5:L20) -> 1745383.7 | N24: SD | O24: =STDEV(O5:O20) -> 1375170.2 | P24: =STDEV(P5:P20) -> 1310118.6 | Q24: =STDEV(Q5:Q20) -> 172463.81 | R24: =STDEV(R5:R20) -> 829480.73 | S24: =STDEV(S5:S20) -> 1643084.2 | T24: =STDEV(T5:T20) -> 1355793.3 | U24: =STDEV(U5:U20) -> 2443299.2 | V24: =STDEV(V5:V20) -> 1889394.3
B26: Unspiked | O26: Testosterone spiked
A27: =A4 -> Group names | B27: =B4 -> Solvent control | C27: =C4 -> EE2-33.8ng/L | D27: =D4 -> EE2-50.6ng/L | E27: =E4 -> EE2-76ng/L | F27: =F4 -> EE2-114ng/L | G27: =G4 -> EE2-170.9ng/L | H27: =H4 -> EE2-488ng/L | ... M27: =M4 -> Estrone-25µg/L | O27: =O4 -> Testo -30µg/L | P27: =P4 -> Testo 30µg/L + EE2 -64ng/L | Q27: =Q4 -> Testo 30µg/L + FAD-10mg/L | R27: =R4 -> Estrone-0.04µg/L + Testostérone | S27: =S4 -> Estrone-0.2µg/L + Testostérone | T27: =T4 -> Estrone-1µg/L + Testostérone | U27: =U4 -> Estrone-5µg/L + Testostérone | V27: =V4 -> Estrone-25µg/L + Testostérone
A28: Data normalised to the "Testo" group | B28: =IF(B5="","",(B5/$O$23)) -> 0.089832952 | C28: =IF(C5="","",(C5/$O$23)) -> 0.017244494 | D28: =IF(D5="","",(D5/$O$23)) -> 0.028222517 | E28: =IF(E5="","",(E5/$O$23)) -> 1.049209 | F28: =IF(F5="","",(F5/$O$23)) -> 0.3483685 | G28: =IF(G5="","",(G5/$O$23)) -> 1.3635094 | H28: =IF(H5="","",(H5/$O$23)) -> 1.289477 | I28: =IF(I5="","",(I5/$O$23)) -> 0.07325893 | ... M28: =IF(M5="","",(M5/$O$23)) | O28: =IF(O5="","",(O5/$O$23)) -> 1.1943329 | P28: =IF(P5="","",(P5/$O$23)) -> 1.8441645 | Q28: =IF(Q5="","",(Q5/$O$23)) -> 0.034852773 | R28: =IF(R5="","",(R5/$O$23)) -> 1.2944349 | S28: =IF(S5="","",(S5/$O$23)) -> 1.0577188 | T28: =IF(T5="","",(T5/$O$23)) -> 0.66240342 | U28: =IF(U5="","",(U5/$O$23)) -> 2.0052742 | V28: =IF(V5="","",(V5/$O$23)) -> 3.2107917
B29: =IF(B6="","",(B6/$O$23)) -> 0.0079299948 | C29: =IF(C6="","",(C6/$O$23)) -> 0.23654448 | D29: =IF(D6="","",(D6/$O$23)) -> 0.40172077 | E29: =IF(E6="","",(E6/$O$23)) -> 0.46238377 | F29: =IF(F6="","",(F6/$O$23)) -> 2.7547877 | G29: =IF(G6="","",(G6/$O$23)) -> 1.783113 | H29: =IF(H6="","",(H6/$O$23)) -> 1.766939 | I29: =IF(I6="","",(I6/$O$23)) -> 0.022971761 | ... M29: =IF(M6="","",(M6/$O$23)) | O29: =IF(O6="","",(O6/$O$23)) -> 1.559711 | P29: =IF(P6="","",(P6/$O$23)) -> 2.3060076 | Q29: =IF(Q6="","",(Q6/$O$23)) -> 0.020847619 | R29: =IF(R6="","",(R6/$O$23)) -> 1.2538071 | S29: =IF(S6="","",(S6/$O$23)) -> 0.93184577 | T29: =IF(T6="","",(T6/$O$23)) -> 1.7895337 | U29: =IF(U6="","",(U6/$O$23)) -> 2.9820657 | V29: =IF(V6="","",(V6/$O$23)) -> 2.9754237
B30: =IF(B7="","",(B7/$O$23)) -> 0.16032081 | C30: =IF(C7="","",(C7/$O$23)) -> 0.076568025 | D30: =IF(D7="","",(D7/$O$23)) -> 0.078676274 | E30: =IF(E7="","",(E7/$O$23)) -> 0.30080472 | F30: =IF(F7="","",(F7/$O$23)) -> 1.774472 | G30: =IF(G7="","",(G7/$O$23)) -> 0.80359812 | H30: =IF(H7="","",(H7/$O$23)) -> 3.035299 | I30: =IF(I7="","",(I7/$O$23)) -> 0.012077032 | ... M30: =IF(M7="","",(M7/$O$23)) | O30: =IF(O7="","",(O7/$O$23)) -> 1.2775247 | P30: =IF(P7="","",(P7/$O$23)) -> 1.8019701 | Q30: =IF(Q7="","",(Q7/$O$23)) -> 0.059871564 | R30: =IF(R7="","",(R7/$O$23)) -> 1.0194371 | S30: =IF(S7="","",(S7/$O$23)) -> 1.3743547 | T30: =IF(T7="","",(T7/$O$23)) -> 1.4938644 | U30: =IF(U7="","",(U7/$O$23)) -> 1.1134925 | V30: =IF(V7="","",(V7/$O$23)) -> 2.4369381
B31: =IF(B8="","",(B8/$O$23)) -> 0.33784168 | C31: =IF(C8="","",(C8/$O$23)) -> 0.0079441224 | D31: =IF(D8="","",(D8/$O$23)) -> 1.6850257 | E31: =IF(E8="","",(E8/$O$23)) -> 1.1274173 | F31: =IF(F8="","",(F8/$O$23)) -> 0.90680461 | G31: =IF(G8="","",(G8/$O$23)) -> 1.3183776 | H31: =IF(H8="","",(H8/$O$23)) -> 2.0070825 | I31: =IF(I8="","",(I8/$O$23)) -> 0.015548005 | ... M31: =IF(M8="","",(M8/$O$23)) | O31: =IF(O8="","",(O8/$O$23)) -> 1.0636692 | P31: =IF(P8="","",(P8/$O$23)) -> 2.0734489 | Q31: =IF(Q8="","",(Q8/$O$23)) -> 0.097256414 | R31: =IF(R8="","",(R8/$O$23)) -> 0.79005594 | S31: =IF(S8="","",(S8/$O$23)) -> 1.4775667 | T31: =IF(T8="","",(T8/$O$23)) -> 1.8738834 | U31: =IF(U8="","",(U8/$O$23)) -> 2.5881401 | V31: =IF(V8="","",(V8/$O$23)) -> 2.1940474
B32: =IF(B9="","",(B9/$O$23)) -> 0.019912843 | C32: =IF(C9="","",(C9/$O$23)) -> 0.029130803 | D32: =IF(D9="","",(D9/$O$23)) -> 0.038616894 | E32: =IF(E9="","",(E9/$O$23)) -> 0.11579329 | F32: =IF(F9="","",(F9/$O$23)) -> 0.71642233 | G32: =IF(G9="","",(G9/$O$23)) -> 1.4558417 | H32: =IF(H9="","",(H9/$O$23)) -> 3.4139439 | I32: =IF(I9="","",(I9/$O$23)) -> 0.022793989 | ... M32: =IF(M9="","",(M9/$O$23)) | O32: =IF(O9="","",(O9/$O$23)) -> 0.91971311 | P32: =IF(P9="","",(P9/$O$23)) -> 2.377624 | Q32: =IF(Q9="","",(Q9/$O$23)) -> 0.013208711 | R32: =IF(R9="","",(R9/$O$23)) -> 0.83875405 | S32: =IF(S9="","",(S9/$O$23)) -> 0.13108052 | T32: =IF(T9="","",(T9/$O$23)) -> 1.3393898 | U32: =IF(U9="","",(U9/$O$23)) -> 2.7518751 | V32: =IF(V9="","",(V9/$O$23)) -> 1.5815202
B33: =IF(B10="","",(B10/$O$23)) -> 0.16677212 | C33: =IF(C10="","",(C10/$O$23)) -> 0.043582154 | D33: =IF(D10="","",(D10/$O$23)) -> 0.05820804 | E33: =IF(E10="","",(E10/$O$23)) -> 0.15410291 | F33: =IF(F10="","",(F10/$O$23)) -> 0.84740279 | G33: =IF(G10="","",(G10/$O$23)) -> 1.2910007 | H33: =IF(H10="","",(H10/$O$23)) -> 1.729887 | I33: =IF(I10="","",(I10/$O$23)) -> 0.028965982 | ... M33: =IF(M10="","",(M10/$O$23)) | O33: =IF(O10="","",(O10/$O$23)) -> 1.2106347 | P33: =IF(P10="","",(P10/$O$23)) -> 2.2979923 | Q33: =IF(Q10="","",(Q10/$O$23)) -> 0.11403234 | R33: =IF(R10="","",(R10/$O$23)) -> 0.67933416 | S33: =IF(S10="","",(S10/$O$23)) -> 1.1085531 | T33: =IF(T10="","",(T10/$O$23)) -> 1.3792134 | U33: =IF(U10="","",(U10/$O$23)) -> 1.2531458 | V33: =IF(V10="","",(V10/$O$23)) -> 2.0968207
B34: =IF(B11="","",(B11/$O$23)) -> 0.073190647 | C34: =IF(C11="","",(C11/$O$23)) -> 0.026707333 | D34: =IF(D11="","",(D11/$O$23)) -> 0.04601887 | E34: =IF(E11="","",(E11/$O$23)) -> 0.48480897 | F34: =IF(F11="","",(F11/$O$23)) -> 0.2409826 | G34: =IF(G11="","",(G11/$O$23)) -> 1.6676629 | H34: =IF(H11="","",(H11/$O$23)) -> 2.0227526 | I34: =IF(I11="","",(I11/$O$23)) -> 0.00026136048 | ... M34: =IF(M11="","",(M11/$O$23)) | O34: =IF(O11="","",(O11/$O$23)) -> 0.40699242 | P34: =IF(P11="","",(P11/$O$23)) -> 3.0381496 | Q34: =IF(Q11="","",(Q11/$O$23)) -> 0.02669762 | R34: =IF(R11="","",(R11/$O$23)) -> 1.3129005 | S34: =IF(S11="","",(S11/$O$23)) -> 1.3432325 | T34: =IF(T11="","",(T11/$O$23)) -> 1.0206957 | U34: =IF(U11="","",(U11/$O$23)) -> 2.857669 | V34: =IF(V11="","",(V11/$O$23)) -> 2.1141093
B35: =IF(B12="","",(B12/$O$23)) -> 0.020983303 | C35: =IF(C12="","",(C12/$O$23)) -> 0.11457684 | D35: =IF(D12="","",(D12/$O$23)) -> 0.020551822 | E35: =IF(E12="","",(E12/$O$23)) -> 0.37387028 | F35: =IF(F12="","",(F12/$O$23)) -> 1.9048794 | G35: =IF(G12="","",(G12/$O$23)) -> 0.80399752 | H35: =IF(H12="","",(H12/$O$23)) -> 2.9401264 | I35: =IF(I12="","",(I12/$O$23)) -> 0.048614227 | ... M35: =IF(M12="","",(M12/$O$23)) | O35: =IF(O12="","",(O12/$O$23)) -> 1.2422985 | P35: =IF(P12="","",(P12/$O$23)) -> 2.2873065 | Q35: =IF(Q12="","",(Q12/$O$23)) -> 0.15193609 | R35: =IF(R12="","",(R12/$O$23)) -> 1.0302913 | S35: =IF(S12="","",(S12/$O$23)) -> 1.7384419 | T35: =IF(T12="","",(T12/$O$23)) -> 1.1367568 | U35: =IF(U12="","",(U12/$O$23)) -> 2.322715 | V35: =IF(V12="","",(V12/$O$23)) -> 1.7931163
B36: =IF(B13="","",(B13/$O$23)) | C36: =IF(C13="","",(C13/$O$23)) | D36: =IF(D13="","",(D13/$O$23)) | E36: =IF(E13="","",(E13/$O$23)) | F36: =IF(F13="","",(F13/$O$23)) | G36: =IF(G13="","",(G13/$O$23)) | H36: =IF(H13="","",(H13/$O$23)) | I36: =IF(I13="","",(I13/$O$23)) | ... M36: =IF(M13="","",(M13/$O$23)) | O36: =IF(O13="","",(O13/$O$23)) -> 0.55871866 | P36: =IF(P13="","",(P13/$O$23)) | Q36: =IF(Q13="","",(Q13/$O$23)) | R36: =IF(R13="","",(R13/$O$23)) | S36: =IF(S13="","",(S13/$O$23)) | T36: =IF(T13="","",(T13/$O$23)) | U36: =IF(U13="","",(U13/$O$23)) | V36: =IF(V13="","",(V13/$O$23))
B37: =IF(B14="","",(B14/$O$23)) | C37: =IF(C14="","",(C14/$O$23)) | D37: =IF(D14="","",(D14/$O$23)) | E37: =IF(E14="","",(E14/$O$23)) | F37: =IF(F14="","",(F14/$O$23)) | G37: =IF(G14="","",(G14/$O$23)) | H37: =IF(H14="","",(H14/$O$23)) | I37: =IF(I14="","",(I14/$O$23)) | ... M37: =IF(M14="","",(M14/$O$23)) | O37: =IF(O14="","",(O14/$O$23)) -> 1.4340255 | P37: =IF(P14="","",(P14/$O$23)) | Q37: =IF(Q14="","",(Q14/$O$23)) | R37: =IF(R14="","",(R14/$O$23)) | S37: =IF(S14="","",(S14/$O$23)) | T37: =IF(T14="","",(T14/$O$23)) | U37: =IF(U14="","",(U14/$O$23)) | V37: =IF(V14="","",(V14/$O$23))
B38: =IF(B15="","",(B15/$O$23)) | C38: =IF(C15="","",(C15/$O$23)) | D38: =IF(D15="","",(D15/$O$23)) | E38: =IF(E15="","",(E15/$O$23)) | F38: =IF(F15="","",(F15/$O$23)) | G38: =IF(G15="","",(G15/$O$23)) | H38: =IF(H15="","",(H15/$O$23)) | I38: =IF(I15="","",(I15/$O$23)) | ... M38: =IF(M15="","",(M15/$O$23)) | O38: =IF(O15="","",(O15/$O$23)) -> 0.99577784 | P38: =IF(P15="","",(P15/$O$23)) | Q38: =IF(Q15="","",(Q15/$O$23)) | R38: =IF(R15="","",(R15/$O$23)) | S38: =IF(S15="","",(S15/$O$23)) | T38: =IF(T15="","",(T15/$O$23)) | U38: =IF(U15="","",(U15/$O$23)) | V38: =IF(V15="","",(V15/$O$23))
B39: =IF(B16="","",(B16/$O$23)) | C39: =IF(C16="","",(C16/$O$23)) | D39: =IF(D16="","",(D16/$O$23)) | E39: =IF(E16="","",(E16/$O$23)) | F39: =IF(F16="","",(F16/$O$23)) | G39: =IF(G16="","",(G16/$O$23)) | H39: =IF(H16="","",(H16/$O$23)) | I39: =IF(I16="","",(I16/$O$23)) | ... M39: =IF(M16="","",(M16/$O$23)) | O39: =IF(O16="","",(O16/$O$23)) -> 1.0928094 | P39: =IF(P16="","",(P16/$O$23)) | Q39: =IF(Q16="","",(Q16/$O$23)) | R39: =IF(R16="","",(R16/$O$23)) | S39: =IF(S16="","",(S16/$O$23)) | T39: =IF(T16="","",(T16/$O$23)) | U39: =IF(U16="","",(U16/$O$23)) | V39: =IF(V16="","",(V16/$O$23))
B40: =IF(B17="","",(B17/$O$23)) | C40: =IF(C17="","",(C17/$O$23)) | D40: =IF(D17="","",(D17/$O$23)) | E40: =IF(E17="","",(E17/$O$23)) | F40: =IF(F17="","",(F17/$O$23)) | G40: =IF(G17="","",(G17/$O$23)) | H40: =IF(H17="","",(H17/$O$23)) | I40: =IF(I17="","",(I17/$O$23)) | ... M40: =IF(M17="","",(M17/$O$23)) | O40: =IF(O17="","",(O17/$O$23)) -> 0.90635782 | P40: =IF(P17="","",(P17/$O$23)) | Q40: =IF(Q17="","",(Q17/$O$23)) | R40: =IF(R17="","",(R17/$O$23)) | S40: =IF(S17="","",(S17/$O$23)) | T40: =IF(T17="","",(T17/$O$23)) | U40: =IF(U17="","",(U17/$O$23)) | V40: =IF(V17="","",(V17/$O$23))
... B43: =IF(B20="","",(B20/$O$23)) | C43: =IF(C20="","",(C20/$O$23)) | D43: =IF(D20="","",(D20/$O$23)) | E43: =IF(E20="","",(E20/$O$23)) | F43: =IF(F20="","",(F20/$O$23)) | G43: =IF(G20="","",(G20/$O$23)) | H43: =IF(H20="","",(H20/$O$23)) | I43: =IF(I20="","",(I20/$O$23)) | ... M43: =IF(M20="","",(M20/$O$23)) | O43: =IF(O20="","",(O20/$O$23)) -> 0.07591845 | P43: =IF(P20="","",(P20/$O$23)) | Q43: =IF(Q20="","",(Q20/$O$23)) | R43: =IF(R20="","",(R20/$O$23)) | S43: =IF(S20="","",(S20/$O$23)) | T43: =IF(T20="","",(T20/$O$23)) | U43: =IF(U20="","",(U20/$O$23)) | V43: =IF(V20="","",(V20/$O$23))
A45: =A4 -> Group names | B45: =B4 -> Solvent control | C45: =C4 -> EE2-33.8ng/L | D45: =D4 -> EE2-50.6ng/L | E45: =E4 -> EE2-76ng/L | F45: =F4 -> EE2-114ng/L | G45: =G4 -> EE2-170.9ng/L | H45: =H4 -> EE2-488ng/L | ... M45: =M4 -> Estrone-25µg/L | O45: =O4 -> Testo -30µg/L | P45: =P4 -> Testo 30µg/L + EE2 -64ng/L | Q45: =Q4 -> Testo 30µg/L + FAD-10mg/L | R45: =R4 -> Estrone-0.04µg/L + Testostérone | S45: =S4 -> Estrone-0.2µg/L + Testostérone | T45: =T4 -> Estrone-1µg/L + Testostérone | U45: =U4 -> Estrone-5µg/L + Testostérone | V45: =V4 -> Estrone-25µg/L + Testostérone
A46: mean | B46: =AVERAGE(B28:B43) -> 0.10959804 | C46: =AVERAGE(C28:C43) -> 0.069037282 | D46: =AVERAGE(D28:D43) -> 0.29463012 | E46: =AVERAGE(E28:E43) -> 0.50854878 | F46: =AVERAGE(F28:F43) -> 1.186765 | G46: =AVERAGE(G28:G43) -> 1.3108876 | H46: =AVERAGE(H28:H43) -> 2.2756884 | I46: =AVERAGE(I28:I43) -> 0.028061411 | ... M46: =AVERAGE(M28:M43) -> #DIV/0! | N46: mean | O46: =AVERAGE(O28:O43) -> 1 | P46: =AVERAGE(P28:P43) -> 2.253333 | Q46: =AVERAGE(Q28:Q43) -> 0.064837891 | R46: =AVERAGE(R28:R43) -> 1.0273769 | S46: =AVERAGE(S28:S43) -> 1.1453492 | T46: =AVERAGE(T28:T43) -> 1.3369676 | U46: =AVERAGE(U28:U43) -> 2.2342972 | V46: =AVERAGE(V28:V43) -> 2.3003459
A47: SD | B47: =STDEV(B28:B43) -> 0.11076706 | C47: =STDEV(C28:C43) -> 0.07619187 | D47: =STDEV(D28:D43) -> 0.575778 | E47: =STDEV(E28:E43) -> 0.38157402 | F47: =STDEV(F28:F43) -> 0.8727594 | G47: =STDEV(G28:G43) -> 0.35633011 | H47: =STDEV(H28:H43) -> 0.75399654 | I47: =STDEV(I28:I43) -> 0.023005065 | ... M47: =STDEV(M28:M43) -> #DIV/0! | N47: SD | O47: =STDEV(O28:O43) -> 0.40474677 | P47: =STDEV(P28:P43) -> 0.38560048 | Q47: =STDEV(Q28:Q43) -> 0.050760388 | R47: =STDEV(R28:R43) -> 0.2441368 | S47: =STDEV(S28:S43) -> 0.48360055 | T47: =STDEV(T28:T43) -> 0.39904368 | U47: =STDEV(U28:U43) -> 0.7191237 | V47: =STDEV(V28:V43) -> 0.55609573
...

Sheet R3
A3: R3 | B3: Unspiked | O3: Testosterone spiked
A4: Group names | B4: ='Front page'!A7 -> Solvent control | C4: ='Front page'!A8 -> EE2-33.8ng/L | D4: ='Front page'!A9 -> EE2-50.6ng/L | E4: ='Front page'!A10 -> EE2-76ng/L | F4: ='Front page'!A11 -> EE2-114ng/L | G4: ='Front page'!A12 -> EE2-170.9ng/L | H4: ='Front page'!A13 -> EE2-488ng/L | I4: ='Front page'!A14 -> Estrone-0.04µg/L | J4: ='Front page'!A15 -> Estrone-0.2µg/L | K4: ='Front page'!A16 -> Estrone-1µg/L | L4: ='Front page'!A17 -> Estrone-5µg/L | M4: ='Front page'!A18 -> Estrone-25µg/L | O4: ='Front page'!A35 -> Testo -30µg/L | P4: ='Front page'!A36 -> Testo 30µg/L + EE2 -64ng/L | Q4: ='Front page'!A37 -> Testo 30µg/L + FAD-10mg/L | R4: ='Front page'!A38 -> Estrone-0.04µg/L + Testostérone | S4: ='Front page'!A39 -> Estrone-0.2µg/L + Testostérone | T4: ='Front page'!A40 -> Estrone-1µg/L + Testostérone | U4: ='Front page'!A41 -> Estrone-5µg/L + Testostérone | V4: ='Front page'!A42 -> Estrone-25µg/L + Testostérone
A5: Raw data | B5: 74147 | C5: 44732 | D5: 379561 | E5: 1693508 | F5: 2099582 | G5: 7385815 | H5: 11108900 | I5: 35552 | J5: 234283 | K5: 44856 | L5: 7889678 | M5: 10096210 | O5: 485039 | P5: 8080152 | Q5: 58909 | R5: 1949562 | S5: 1176717 | T5: 5866028 | U5: 6503272 | V5: 8486113
B6: 32337 | C6: 46938 | D6: 860316 | E6: 1698245 | F6: 5003055 | G6: 6015837 | H6: 11528799 | I6: 36896 | J6: 152771 | K6: 265292 | L6: 7500991 | M6: 9627317 | O6: 112447 | P6: 6523110 | Q6: 55250 | R6: 3325414 | S6: 3235019 | T6: 5499959 | U6: 6481012 | V6: 4167481
B7: 40850 | C7: 221087 | D7: 41630 | E7: 1936651 | F7: 3402079 | G7: 5179779 | H7: 6444913 | I7: 161898 | J7: 94190 | K7: 125960 | L7: 6672793 | M7: 8749194 | O7: 555389 | P7: 7021303 | Q7: 434326 | R7: 1822805 | S7: 65034 | T7: 4407704 | U7: 5515866 | V7: 6843401
B8: 21127 | C8: 260557 | D8: 321176 | E8: 1271106 | F8: 1870947 | G8: 6938568 | H8: 8966832 | I8: 18883 | J8: 157569 | K8: 981392 | L8: 6948187 | M8: 8968394 | O8: 115346 | P8: 5287188 | Q8: 41237 | R8: 4111881 | S8: 4263252 | T8: 5740009 | U8: 8457445 | V8: 3094864
B9: 366325 | C9: 67106 | D9: 158651 | E9: 2624085 | F9: 3000802 | G9: 7838420 | H9: 9337913 | I9: 87198 | J9: 209 | K9: 173241 | L9: 3618729 | M9: 10477669 | O9: 10743 | P9: 4377155 | Q9: 97087 | R9: 2076272 | S9: 3061727 | T9: 3632917 | U9: 6933462 | V9: 7054948
B10: 7244 | C10: 100975 | D10: 34723 | E10: 1497454 | F10: 4966695 | G10: 5217063 | H10: 9818316 | I10: 65680 | J10: 112866 | K10: 86796 | L10: 8163852 | M10: 7909948 | O10: 3649789 | P10: 6433613 | Q10: 72705 | R10: 4128909 | S10: 1540764 | T10: 6882939 | U10: 6214024 | V10: 4292373
B11: 73747 | C11: 224536 | D11: 755279 | E11: 1657973 | F11: 3276385 | G11: 6554341 | H11: 8230668 | I11: 111858 | J11: 18016 | K11: 202526 | L11: 8060323 | M11: 10698201 | O11: 559411 | P11: 5069556 | Q11: 84081 | R11: 1646755 | S11: 87044 | T11: 6459448 | U11: 10116238 | V11: 8150576
B12: 36797 | C12: 57365 | D12: 430992 | E12: 4067395 | F12: 3878772 | G12: 5171850 | H12: 6069088 | I12: 49666 | J12: 399931 | K12: 446132 | M12: 10901177 | O12: 560834 | P12: 6371817 | Q12: 47105 | R12: 6343157 | S12: 7076917 | T12: 4069442 | U12: 7347925 | V12: 6975681
O13: 24030
O14: 1759750
O15: 3578469
O16: 1186434
O17: 3505936
O18: 1851091
O19: 776394
O20: 3359026
A22: =A4 -> Group names | B22: =B4 -> Solvent control | C22: =C4 -> EE2-33.8ng/L | D22: =D4 -> EE2-50.6ng/L | E22: =E4 -> EE2-76ng/L | F22: =F4 -> EE2-114ng/L | G22: =G4 -> EE2-170.9ng/L | H22: =H4 -> EE2-488ng/L | ... M22: =M4 -> Estrone-25µg/L | N22: Noms des groupes | O22: =O4 -> Testo -30µg/L | P22: =P4 -> Testo 30µg/L + EE2 -64ng/L | Q22: =Q4 -> Testo 30µg/L + FAD-10mg/L | R22: =R4 -> Estrone-0.04µg/L + Testostérone | S22: =S4 -> Estrone-0.2µg/L + Testostérone | T22: =T4 -> Estrone-1µg/L + Testostérone | U22: =U4 -> Estrone-5µg/L + Testostérone | V22: =V4 -> Estrone-25µg/L + Testostérone
A23: mean | B23: =AVERAGE(B5:B20) -> 81571.75 | C23: =AVERAGE(C5:C20) -> 127912 | D23: =AVERAGE(D5:D20) -> 372791 | E23: =AVERAGE(E5:E20) -> 2055802.1 | F23: =AVERAGE(F5:F20) -> 3437289.6 | G23: =AVERAGE(G5:G20) -> 6287709.1 | H23: =AVERAGE(H5:H20) -> 8938178.6 | I23: =AVERAGE(I5:I20) -> 70953.875 | J23: =AVERAGE(J5:J20) -> 146229.38 | L23: =AVERAGE(L5:L20) -> 6979221.9 | N23: mean | O23: =AVERAGE(O5:O20) -> 1380633 | P23: =AVERAGE(P5:P20) -> 6145486.8 | Q23: =AVERAGE(Q5:Q20) -> 111337.5 | R23: =AVERAGE(R5:R20) -> 3175594.4 | S23: =AVERAGE(S5:S20) -> 2563309.2 | T23: =AVERAGE(T5:T20) -> 5319805.8 | U23: =AVERAGE(U5:U20) -> 7196155.5 | V23: =AVERAGE(V5:V20) -> 6133179.6
A24: SD | B24: =STDEV(B5:B20) -> 117391.93 | C24: =STDEV(C5:C20) -> 91408.054 | D24: =STDEV(D5:D20) -> 307033.85 | E24: =STDEV(E5:E20) -> 904632.61 | F24: =STDEV(F5:F20) -> 1161658.4 | G24: =STDEV(G5:G20) -> 1055468.7 | H24: =STDEV(H5:H20) -> 1975102.9 | I24: =STDEV(I5:I20) -> 47529.612 | J24: =STDEV(J5:J20) -> 127543.36 | L24: =STDEV(L5:L20) -> 1584354.5 | N24: SD | O24: =STDEV(O5:O20) -> 1388865 | P24: =STDEV(P5:P20) -> 1183706.4 | Q24: =STDEV(Q5:Q20) -> 131851.91 | R24: =STDEV(R5:R20) -> 1635341.6 | S24: =STDEV(S5:S20) -> 2369556.3 | T24: =STDEV(T5:T20) -> 1164381.3 | U24: =STDEV(U5:U20) -> 1463325.4 | V24: =STDEV(V5:V20) -> 2005491.2
B26: Unspiked | O26: Testosterone spiked
A27: =A4 -> Group names | B27: =B4 -> Solvent control | C27: =C4 -> EE2-33.8ng/L | D27: =D4 -> EE2-50.6ng/L | E27: =E4 -> EE2-76ng/L | F27: =F4 -> EE2-114ng/L | G27: =G4 -> EE2-170.9ng/L | H27: =H4 -> EE2-488ng/L | ... M27: =M4 -> Estrone-25µg/L | O27: =O4 -> Testo -30µg/L | P27: =P4 -> Testo 30µg/L + EE2 -64ng/L | Q27: =Q4 -> Testo 30µg/L + FAD-10mg/L | R27: =R4 -> Estrone-0.04µg/L + Testostérone | S27: =S4 -> Estrone-0.2µg/L + Testostérone | T27: =T4 -> Estrone-1µg/L + Testostérone | U27: =U4 -> Estrone-5µg/L + Testostérone | V27: =V4 -> Estrone-25µg/L + Testostérone
A28: Data normalised to the "Testo" group | B28: =IF(B5="","",(B5/$O$23)) -> 0.053705076 | C28: =IF(C5="","",(C5/$O$23)) -> 0.032399631 | D28: =IF(D5="","",(D5/$O$23)) -> 0.2749181 | E28: =IF(E5="","",(E5/$O$23)) -> 1.2266171 | F28: =IF(F5="","",(F5/$O$23)) -> 1.5207387 | G28: =IF(G5="","",(G5/$O$23)) -> 5.349586 | H28: =IF(H5="","",(H5/$O$23)) -> 8.0462368 | I28: =IF(I5="","",(I5/$O$23)) -> 0.025750507 | ... M28: =IF(M5="","",(M5/$O$23)) -> 7.3127399 | O28: =IF(O5="","",(O5/$O$23)) -> 0.35131639 | P28: =IF(P5="","",(P5/$O$23)) -> 5.8524981 | Q28: =IF(Q5="","",(Q5/$O$23)) -> 0.042668109 | R28: =IF(R5="","",(R5/$O$23)) -> 1.4120784 | S28: =IF(S5="","",(S5/$O$23)) -> 0.85230253 | T28: =IF(T5="","",(T5/$O$23)) -> 4.248796 | U28: =IF(U5="","",(U5/$O$23)) -> 4.7103553 | V28: =IF(V5="","",(V5/$O$23)) -> 6.1465379
