Workbook

Sheet Front page
A2: R1 | B2: Experiment number : | E2: Date performed :
A3: R2 | B3: Experiment number : | E3: Date performed :
A4: R3 | B4: Experiment number : | E4: Date performed :
A6: Do not fill in | B6: Do not fill in2 | C6: Concentration | D6: Units | E6: Chemical name | F6: Do not fill in3
A7: =IF(ISBLANK(liste_groupe[[#This Row],[Do not fill in2]])," ",IF(ISBLANK(liste_groupe[[#This Row],[Units]]),CONCATENATE(liste_groupe[[#This Row],[Chemical name]],liste_groupe[[#This Row],[Do not fill in3]]),CONCATENATE(liste_groupe[[#This Row],[Chemical name]],"-",liste_groupe[[#This Row],[Concentration]],liste_groupe[[#This Row],[Units]],liste_groupe[[#This Row],[Do not fill in3]]))) -> Solvent control | B7: Control | E7: Solvent control
A8: =IF(ISBLANK(liste_groupe[[#This Row],[Do not fill in2]])," ",IF(ISBLANK(liste_groupe[[#This Row],[Units]]),CONCATENATE(liste_groupe[[#This Row],[Chemical name]],liste_groupe[[#This Row],[Do not fill in3]]),CONCATENATE(liste_groupe[[#This Row],[Chemical name]],"-",liste_groupe[[#This Row],[Concentration]],liste_groupe[[#This Row],[Units]],liste_groupe[[#This Row],[Do not fill in3]]))) -> EE2-33.8ng/L | B8: Control | C8: 33.8 | D8: ng/L | E8: EE2
A9: =IF(ISBLANK(liste_groupe[[#This Row],[Do not fill in2]])," ",IF(ISBLANK(liste_groupe[[#This Row],[Units]]),CONCATENATE(liste_groupe[[#This Row],[Chemical name]],liste_groupe[[#This Row],[Do not fill in3]]),CONCATENATE(liste_groupe[[#This Row],[Chemical name]],"-",liste_groupe[[#This Row],[Concentration]],liste_groupe[[#This Row],[Units]],liste_groupe[[#This Row],[Do not fill in3]]))) -> EE2-50.6ng/L | B9: Control | C9: 50.6 | D9: ng/L | E9: EE2
A10: =IF(ISBLANK(liste_groupe[[#This Row],[Do not fill in2]])," ",IF(ISBLANK(liste_groupe[[#This Row],[Units]]),CONCATENATE(liste_groupe[[#This Row],[Chemical name]],liste_groupe[[#This Row],[Do not fill in3]]),CONCATENATE(liste_groupe[[#This Row],[Chemical name]],"-",liste_groupe[[#This Row],[Concentration]],liste_groupe[[#This Row],[Units]],liste_groupe[[#This Row],[Do not fill in3]]))) -> EE2-76ng/L | B10: Control | C10: 76 | D10: ng/L | E10: EE2
A11: =IF(ISBLANK(liste_groupe[[#This Row],[Do not fill in2]])," ",IF(ISBLANK(liste_groupe[[#This Row],[Units]]),CONCATENATE(liste_groupe[[#This Row],[Chemical name]],liste_groupe[[#This Row],[Do not fill in3]]),CONCATENATE(liste_groupe[[#This Row],[Chemical name]],"-",liste_groupe[[#This Row],[Concentration]],liste_groupe[[#This Row],[Units]],liste_groupe[[#This Row],[Do not fill in3]]))) -> EE2-114ng/L | B11: Control | C11: 114 | D11: ng/L | E11: EE2
A12: =IF(ISBLANK(liste_groupe[[#This Row],[Do not fill in2]])," ",IF(ISBLANK(liste_groupe[[#This Row],[Units]]),CONCATENATE(liste_groupe[[#This Row],[Chemical name]],liste_groupe[[#This Row],[Do not fill in3]]),CONCATENATE(liste_groupe[[#This Row],[Chemical name]],"-",liste_groupe[[#This Row],[Concentration]],liste_groupe[[#This Row],[Units]],liste_groupe[[#This Row],[Do not fill in3]]))) -> EE2-170.9ng/L | B12: Control | C12: 170.9 | D12: ng/L | E12: EE2
A13: =IF(ISBLANK(liste_groupe[[#This Row],[Do not fill in2]])," ",IF(ISBLANK(liste_groupe[[#This Row],[Units]]),CONCATENATE(liste_groupe[[#This Row],[Chemical name]],liste_groupe[[#This Row],[Do not fill in3]]),CONCATENATE(liste_groupe[[#This Row],[Chemical name]],"-",liste_groupe[[#This Row],[Concentration]],liste_groupe[[#This Row],[Units]],liste_groupe[[#This Row],[Do not fill in3]]))) -> EE2-488ng/L | B13: Control | C13: 488 | D13: ng/L | E13: EE2
A14: =IF(ISBLANK(liste_groupe[[#This Row],[Do not fill in2]])," ",IF(ISBLANK(liste_groupe[[#This Row],[Units]]),CONCATENATE(liste_groupe[[#This Row],[Chemical name]],liste_groupe[[#This Row],[Do not fill in3]]),CONCATENATE(liste_groupe[[#This Row],[Chemical name]],"-",liste_groupe[[#This Row],[Concentration]],liste_groupe[[#This Row],[Units]],liste_groupe[[#This Row],[Do not fill in3]]))) -> BPA-1mg/L | B14: test chemical | C14: 1 | D14: mg/L | E14: BPA
A15: =IF(ISBLANK(liste_groupe[[#This Row],[Do not fill in2]])," ",IF(ISBLANK(liste_groupe[[#This Row],[Units]]),CONCATENATE(liste_groupe[[#This Row],[Chemical name]],liste_groupe[[#This Row],[Do not fill in3]]),CONCATENATE(liste_groupe[[#This Row],[Chemical name]],"-",liste_groupe[[#This Row],[Concentration]],liste_groupe[[#This Row],[Units]],liste_groupe[[#This Row],[Do not fill in3]]))) -> BPA-2mg/L | B15: test chemical | C15: 2 | D15: mg/L | E15: BPA
A16: =IF(ISBLANK(liste_groupe[[#This Row],[Do not fill in2]])," ",IF(ISBLANK(liste_groupe[[#This Row],[Units]]),CONCATENATE(liste_groupe[[#This Row],[Chemical name]],liste_groupe[[#This Row],[Do not fill in3]]),CONCATENATE(liste_groupe[[#This Row],[Chemical name]],"-",liste_groupe[[#This Row],[Concentration]],liste_groupe[[#This Row],[Units]],liste_groupe[[#This Row],[Do not fill in3]]))) -> BPA-3mg/L | B16: test chemical | C16: 3 | D16: mg/L | E16: BPA
A17: =IF(ISBLANK(liste_groupe[[#This Row],[Do not fill in2]])," ",IF(ISBLANK(liste_groupe[[#This Row],[Units]]),CONCATENATE(liste_groupe[[#This Row],[Chemical name]],liste_groupe[[#This Row],[Do not fill in3]]),CONCATENATE(liste_groupe[[#This Row],[Chemical name]],"-",liste_groupe[[#This Row],[Concentration]],liste_groupe[[#This Row],[Units]],liste_groupe[[#This Row],[Do not fill in3]]))) -> BPA-4mg/L | B17: test chemical | C17: 4 | D17: mg/L | E17: BPA
A18: =IF(ISBLANK(liste_groupe[[#This Row],[Do not fill in2]])," ",IF(ISBLANK(liste_groupe[[#This Row],[Units]]),CONCATENATE(liste_groupe[[#This Row],[Chemical name]],liste_groupe[[#This Row],[Do not fill in3]]),CONCATENATE(liste_groupe[[#This Row],[Chemical name]],"-",liste_groupe[[#This Row],[Concentration]],liste_groupe[[#This Row],[Units]],liste_groupe[[#This Row],[Do not fill in3]]))) -> BPA-5mg/L | B18: test chemical | C18: 5 | D18: mg/L | E18: BPA
A19: =IF(ISBLANK(liste_groupe[[#This Row],[Do not fill in2]])," ",IF(ISBLANK(liste_groupe[[#This Row],[Units]]),CONCATENATE(liste_groupe[[#This Row],[Chemical name]],liste_groupe[[#This Row],[Do not fill in3]]),CONCATENATE(liste_groupe[[#This Row],[Chemical name]],"-",liste_groupe[[#This Row],[Concentration]],liste_groupe[[#This Row],[Units]],liste_groupe[[#This Row],[Do not fill in3]]))) | B19: test chemical
A20: =IF(ISBLANK(liste_groupe[[#This Row],[Do not fill in2]])," ",IF(ISBLANK(liste_groupe[[#This Row],[Units]]),CONCATENATE(liste_groupe[[#This Row],[Chemical name]],liste_groupe[[#This Row],[Do not fill in3]]),CONCATENATE(liste_groupe[[#This Row],[Chemical name]],"-",liste_groupe[[#This Row],[Concentration]],liste_groupe[[#This Row],[Units]],liste_groupe[[#This Row],[Do not fill in3]]))) | B20: test chemical
A21: =IF(ISBLANK(liste_groupe[[#This Row],[Do not fill in2]])," ",IF(ISBLANK(liste_groupe[[#This Row],[Units]]),CONCATENATE(liste_groupe[[#This Row],[Chemical name]],liste_groupe[[#This Row],[Do not fill in3]]),CONCATENATE(liste_groupe[[#This Row],[Chemical name]],"-",liste_groupe[[#This Row],[Concentration]],liste_groupe[[#This Row],[Units]],liste_groupe[[#This Row],[Do not fill in3]]))) | B21: test chemical
A22: =IF(ISBLANK(liste_groupe[[#This Row],[Do not fill in2]])," ",IF(ISBLANK(liste_groupe[[#This Row],[Units]]),CONCATENATE(liste_groupe[[#This Row],[Chemical name]],liste_groupe[[#This Row],[Do not fill in3]]),CONCATENATE(liste_groupe[[#This Row],[Chemical name]],"-",liste_groupe[[#This Row],[Concentration]],liste_groupe[[#This Row],[Units]],liste_groupe[[#This Row],[Do not fill in3]]))) | B22: test chemical
A23: =IF(ISBLANK(liste_groupe[[#This Row],[Do not fill in2]])," ",IF(ISBLANK(liste_groupe[[#This Row],[Units]]),CONCATENATE(liste_groupe[[#This Row],[Chemical name]],liste_groupe[[#This Row],[Do not fill in3]]),CONCATENATE(liste_groupe[[#This Row],[Chemical name]],"-",liste_groupe[[#This Row],[Concentration]],liste_groupe[[#This Row],[Units]],liste_groupe[[#This Row],[Do not fill in3]]))) | B23: test chemical
A24: =IF(ISBLANK(liste_groupe[[#This Row],[Do not fill in2]])," ",IF(ISBLANK(liste_groupe[[#This Row],[Units]]),CONCATENATE(liste_groupe[[#This Row],[Chemical name]],liste_groupe[[#This Row],[Do not fill in3]]),CONCATENATE(liste_groupe[[#This Row],[Chemical name]],"-",liste_groupe[[#This Row],[Concentration]],liste_groupe[[#This Row],[Units]],liste_groupe[[#This Row],[Do not fill in3]]))) | B24: test chemical
A25: =IF(ISBLANK(liste_groupe[[#This Row],[Do not fill in2]])," ",IF(ISBLANK(liste_groupe[[#This Row],[Units]]),CONCATENATE(liste_groupe[[#This Row],[Chemical name]],liste_groupe[[#This Row],[Do not fill in3]]),CONCATENATE(liste_groupe[[#This Row],[Chemical name]],"-",liste_groupe[[#This Row],[Concentration]],liste_groupe[[#This Row],[Units]],liste_groupe[[#This Row],[Do not fill in3]]))) | B25: test chemical
A26: =IF(ISBLANK(liste_groupe[[#This Row],[Do not fill in2]])," ",IF(ISBLANK(liste_groupe[[#This Row],[Units]]),CONCATENATE(liste_groupe[[#This Row],[Chemical name]],liste_groupe[[#This Row],[Do not fill in3]]),CONCATENATE(liste_groupe[[#This Row],[Chemical name]],"-",liste_groupe[[#This Row],[Concentration]],liste_groupe[[#This Row],[Units]],liste_groupe[[#This Row],[Do not fill in3]]))) | B26: test chemical
A27: =IF(ISBLANK(liste_groupe[[#This Row],[Do not fill in2]])," ",IF(ISBLANK(liste_groupe[[#This Row],[Units]]),CONCATENATE(liste_groupe[[#This Row],[Chemical name]],liste_groupe[[#This Row],[Do not fill in3]]),CONCATENATE(liste_groupe[[#This Row],[Chemical name]],"-",liste_groupe[[#This Row],[Concentration]],liste_groupe[[#This Row],[Units]],liste_groupe[[#This Row],[Do not fill in3]]))) | B27: test chemical
A28: =IF(ISBLANK(liste_groupe[[#This Row],[Do not fill in2]])," ",IF(ISBLANK(liste_groupe[[#This Row],[Units]]),CONCATENATE(liste_groupe[[#This Row],[Chemical name]],liste_groupe[[#This Row],[Do not fill in3]]),CONCATENATE(liste_groupe[[#This Row],[Chemical name]],"-",liste_groupe[[#This Row],[Concentration]],liste_groupe[[#This Row],[Units]],liste_groupe[[#This Row],[Do not fill in3]]))) | B28: test chemical
A29: =IF(ISBLANK(liste_groupe[[#This Row],[Do not fill in2]])," ",IF(ISBLANK(liste_groupe[[#This Row],[Units]]),CONCATENATE(liste_groupe[[#This Row],[Chemical name]],liste_groupe[[#This Row],[Do not fill in3]]),CONCATENATE(liste_groupe[[#This Row],[Chemical name]],"-",liste_groupe[[#This Row],[Concentration]],liste_groupe[[#This Row],[Units]],liste_groupe[[#This Row],[Do not fill in3]]))) | B29: test chemical
A30: =IF(ISBLANK(liste_groupe[[#This Row],[Do not fill in2]])," ",IF(ISBLANK(liste_groupe[[#This Row],[Units]]),CONCATENATE(liste_groupe[[#This Row],[Chemical name]],liste_groupe[[#This Row],[Do not fill in3]]),CONCATENATE(liste_groupe[[#This Row],[Chemical name]],"-",liste_groupe[[#This Row],[Concentration]],liste_groupe[[#This Row],[Units]],liste_groupe[[#This Row],[Do not fill in3]]))) | B30: test chemical
... A34: =IF(ISBLANK(liste_groupe[[#This Row],[Do not fill in2]])," ",IF(ISBLANK(liste_groupe[[#This Row],[Units]]),CONCATENATE(liste_groupe[[#This Row],[Chemical name]],liste_groupe[[#This Row],[Do not fill in3]]),CONCATENATE(liste_groupe[[#This Row],[Chemical name]],"-",liste_groupe[[#This Row],[Concentration]],liste_groupe[[#This Row],[Units]],liste_groupe[[#This Row],[Do not fill in3]]))) | B34: test chemical
A35: =IF(ISBLANK(liste_groupe[[#This Row],[Do not fill in2]])," ",IF(ISBLANK(liste_groupe[[#This Row],[Units]]),CONCATENATE(liste_groupe[[#This Row],[Chemical name]],liste_groupe[[#This Row],[Do not fill in3]]),CONCATENATE(liste_groupe[[#This Row],[Chemical name]],"-",liste_groupe[[#This Row],[Concentration]],liste_groupe[[#This Row],[Units]],liste_groupe[[#This Row],[Do not fill in3]]))) -> Testo -30µg/L | B35: Control | C35: 30 | D35: µg/L | E35: Testo
A36: =IF(ISBLANK(liste_groupe[[#This Row],[Do not fill in2]])," ",IF(ISBLANK(liste_groupe[[#This Row],[Units]]),CONCATENATE(liste_groupe[[#This Row],[Chemical name]],liste_groupe[[#This Row],[Do not fill in3]]),CONCATENATE(liste_groupe[[#This Row],[Chemical name]],"-",liste_groupe[[#This Row],[Concentration]],liste_groupe[[#This Row],[Units]],liste_groupe[[#This Row],[Do not fill in3]]))) -> Testo 30µg/L + EE2 -64ng/L | B36: Control | C36: 64 | D36: ng/L | E36: Testo 30µg/L + EE2
A37: =IF(ISBLANK(liste_groupe[[#This Row],[Do not fill in2]])," ",IF(ISBLANK(liste_groupe[[#This Row],[Units]]),CONCATENATE(liste_groupe[[#This Row],[Chemical name]],liste_groupe[[#This Row],[Do not fill in3]]),CONCATENATE(liste_groupe[[#This Row],[Chemical name]],"-",liste_groupe[[#This Row],[Concentration]],liste_groupe[[#This Row],[Units]],liste_groupe[[#This Row],[Do not fill in3]]))) -> Testo 30µg/L + FAD-10mg/L | B37: Control | C37: 10 | D37: mg/L | E37: Testo 30µg/L + FAD
A38: =IF(ISBLANK(liste_groupe[[#This Row],[Do not fill in2]])," ",IF(ISBLANK(liste_groupe[[#This Row],[Units]]),CONCATENATE(liste_groupe[[#This Row],[Chemical name]],liste_groupe[[#This Row],[Do not fill in3]]),CONCATENATE(liste_groupe[[#This Row],[Chemical name]],"-",liste_groupe[[#This Row],[Concentration]],liste_groupe[[#This Row],[Units]],liste_groupe[[#This Row],[Do not fill in3]]))) -> BPA-1mg/L + Testostérone | B38: =B14 -> test chemical | C38: =C14 -> 1 | D38: =D14 -> mg/L | E38: =E14 -> BPA | F38: + Testostérone
A39: =IF(ISBLANK(liste_groupe[[#This Row],[Do not fill in2]])," ",IF(ISBLANK(liste_groupe[[#This Row],[Units]]),CONCATENATE(liste_groupe[[#This Row],[Chemical name]],liste_groupe[[#This Row],[Do not fill in3]]),CONCATENATE(liste_groupe[[#This Row],[Chemical name]],"-",liste_groupe[[#This Row],[Concentration]],liste_groupe[[#This Row],[Units]],liste_groupe[[#This Row],[Do not fill in3]]))) -> BPA-2mg/L + Testostérone | B39: =B15 -> test chemical | C39: =C15 -> 2 | D39: =D15 -> mg/L | E39: =E15 -> BPA | F39: + Testostérone
A40: =IF(ISBLANK(liste_groupe[[#This Row],[Do not fill in2]])," ",IF(ISBLANK(liste_groupe[[#This Row],[Units]]),CONCATENATE(liste_groupe[[#This Row],[Chemical name]],liste_groupe[[#This Row],[Do not fill in3]]),CONCATENATE(liste_groupe[[#This Row],[Chemical name]],"-",liste_groupe[[#This Row],[Concentration]],liste_groupe[[#This Row],[Units]],liste_groupe[[#This Row],[Do not fill in3]]))) -> BPA-3mg/L + Testostérone | B40: =B16 -> test chemical | C40: =C16 -> 3 | D40: =D16 -> mg/L | E40: =E16 -> BPA | F40: + Testostérone
A41: =IF(ISBLANK(liste_groupe[[#This Row],[Do not fill in2]])," ",IF(ISBLANK(liste_groupe[[#This Row],[Units]]),CONCATENATE(liste_groupe[[#This Row],[Chemical name]],liste_groupe[[#This Row],[Do not fill in3]]),CONCATENATE(liste_groupe[[#This Row],[Chemical name]],"-",liste_groupe[[#This Row],[Concentration]],liste_groupe[[#This Row],[Units]],liste_groupe[[#This Row],[Do not fill in3]]))) -> BPA-4mg/L + Testostérone | B41: =B17 -> test chemical | C41: =C17 -> 4 | D41: =D17 -> mg/L | E41: =E17 -> BPA | F41: + Testostérone
A42: =IF(ISBLANK(liste_groupe[[#This Row],[Do not fill in2]])," ",IF(ISBLANK(liste_groupe[[#This Row],[Units]]),CONCATENATE(liste_groupe[[#This Row],[Chemical name]],liste_groupe[[#This Row],[Do not fill in3]]),CONCATENATE(liste_groupe[[#This Row],[Chemical name]],"-",liste_groupe[[#This Row],[Concentration]],liste_groupe[[#This Row],[Units]],liste_groupe[[#This Row],[Do not fill in3]]))) -> BPA-5mg/L + Testostérone | B42: =B18 -> test chemical | C42: =C18 -> 5 | D42: =D18 -> mg/L | E42: =E18 -> BPA | F42: + Testostérone
A43: =IF(ISBLANK(liste_groupe[[#This Row],[Do not fill in2]])," ",IF(ISBLANK(liste_groupe[[#This Row],[Units]]),CONCATENATE(liste_groupe[[#This Row],[Chemical name]],liste_groupe[[#This Row],[Do not fill in3]]),CONCATENATE(liste_groupe[[#This Row],[Chemical name]],"-",liste_groupe[[#This Row],[Concentration]],liste_groupe[[#This Row],[Units]],liste_groupe[[#This Row],[Do not fill in3]]))) -> 0-00 + Testostérone | B43: =B19 -> test chemical | C43: =C19 -> 0 | D43: =D19 -> 0 | E43: =E19 -> 0 | F43: + Testostérone
A44: =IF(ISBLANK(liste_groupe[[#This Row],[Do not fill in2]])," ",IF(ISBLANK(liste_groupe[[#This Row],[Units]]),CONCATENATE(liste_groupe[[#This Row],[Chemical name]],liste_groupe[[#This Row],[Do not fill in3]]),CONCATENATE(liste_groupe[[#This Row],[Chemical name]],"-",liste_groupe[[#This Row],[Concentration]],liste_groupe[[#This Row],[Units]],liste_groupe[[#This Row],[Do not fill in3]]))) -> 0-00 + Testostérone | B44: =B20 -> test chemical | C44: =C20 -> 0 | D44: =D20 -> 0 | E44: =E20 -> 0 | F44: + Testostérone
A45: =IF(ISBLANK(liste_groupe[[#This Row],[Do not fill in2]])," ",IF(ISBLANK(liste_groupe[[#This Row],[Units]]),CONCATENATE(liste_groupe[[#This Row],[Chemical name]],liste_groupe[[#This Row],[Do not fill in3]]),CONCATENATE(liste_groupe[[#This Row],[Chemical name]],"-",liste_groupe[[#This Row],[Concentration]],liste_groupe[[#This Row],[Units]],liste_groupe[[#This Row],[Do not fill in3]]))) -> 0-00 + Testostérone | B45: =B21 -> test chemical | C45: =C21 -> 0 | D45: =D21 -> 0 | E45: =E21 -> 0 | F45: + Testostérone
...

Sheet Comments R1
A1: T+EE2: 3 embryos died
A2: -> whole replicate invalid?

Sheet R1
A3: R1 | B3: Unspiked | O3: Testosterone spiked
A4: Group names | B4: ='Front page'!A7 -> Solvent control | C4: ='Front page'!A8 -> EE2-33.8ng/L | D4: ='Front page'!A9 -> EE2-50.6ng/L | E4: ='Front page'!A10 -> EE2-76ng/L | F4: ='Front page'!A11 -> EE2-114ng/L | G4: ='Front page'!A12 -> EE2-170.9ng/L | H4: ='Front page'!A13 -> EE2-488ng/L | I4: ='Front page'!A14 -> BPA-1mg/L | J4: ='Front page'!A15 -> BPA-2mg/L | K4: ='Front page'!A16 -> BPA-3mg/L | L4: ='Front page'!A17 -> BPA-4mg/L | M4: ='Front page'!A18 -> BPA-5mg/L | O4: ='Front page'!A35 -> Testo -30µg/L | P4: ='Front page'!A36 -> Testo 30µg/L + EE2 -64ng/L | Q4: ='Front page'!A37 -> Testo 30µg/L + FAD-10mg/L | R4: ='Front page'!A38 -> BPA-1mg/L + Testostérone | S4: ='Front page'!A39 -> BPA-2mg/L + Testostérone | T4: ='Front page'!A40 -> BPA-3mg/L + Testostérone | U4: ='Front page'!A41 -> BPA-4mg/L + Testostérone | V4: ='Front page'!A42 -> BPA-5mg/L + Testostérone
A5: Raw data | B5: 222605 | C5: 368469 | D5: 918984 | E5: 1158111 | F5: 7010063 | G5: 7534801 | H5: 4753330 | I5: 66978 | J5: 282284 | K5: 1415318 | L5: 4501241 | M5: 1963839 | O5: 949028 | P5: 6194930 | Q5: 43325 | R5: 249928 | S5: 2750562 | T5: 4596206 | U5: 1173484 | V5: 6487540
B6: 363833 | C6: 349607 | D6: 733772 | E6: 4704011 | F6: 4204199 | G6: 6671012 | H6: 6705672 | I6: 332229 | J6: 382172 | K6: 506252 | L6: 2294645 | M6: 5600661 | O6: 1936445 | P6: 6492462 | Q6: 116986 | R6: 180652 | S6: 4323252 | T6: 268941 | U6: 2111671 | V6: 2097186
B7: 133670 | C7: 318952 | D7: 591331 | E7: 3322979 | F7: 1853987 | G7: 5553834 | H7: 6452982 | I7: 350692 | J7: 423739 | K7: 753523 | L7: 2236757 | M7: 7323612 | O7: 860195 | P7: 4589469 | Q7: 77528 | R7: 2443719 | S7: 3526977 | T7: 3790459 | U7: 1510665 | V7: 2374884
B8: 186730 | C8: 629539 | D8: 511032 | E8: 2240740 | F8: 2055104 | G8: 7797872 | H8: 5257803 | I8: 25094 | J8: 64844 | K8: 388267 | L8: 9549 | M8: 3415226 | O8: 507876 | P8: 3810216 | Q8: 32708 | R8: 505704 | S8: 1884982 | T8: 2240213 | U8: 691493 | V8: 606334
B9: 221315 | C9: 593125 | D9: 1838198 | E9: 3072023 | F9: 5139602 | G9: 10563051 | H9: 6049851 | I9: 110143 | J9: 74813 | K9: 1634422 | L9: 825922 | M9: 2985567 | O9: 1308266 | P9: 5762071 | Q9: 108302 | R9: 3175984 | S9: 6604582 | T9: 6829784 | U9: 3043250 | V9: 3570988
B10: 288374 | C10: 215960 | D10: 555107 | E10: 3715607 | F10: 4322859 | G10: 6441218 | H10: 5869784 | I10: 202756 | J10: 20314 | K10: 214644 | L10: 1693597 | M10: 2077564 | O10: 843067 | P10: 6937729 | Q10: 231497 | R10: 1381439 | S10: 732391 | T10: 3243506 | U10: 2952601 | V10: 4796955
B11: 47625 | C11: 503708 | D11: 1560404 | E11: 2010899 | F11: 8099620 | G11: 3737482 | H11: 6325128 | I11: 139028 | J11: 155160 | K11: 159770 | L11: 3724366 | M11: 3683146 | O11: 62484 | P11: 4262190 | Q11: 58234 | R11: 790144 | S11: 4713267 | T11: 3783747 | U11: 2277988 | V11: 1714502
O12: 383967 | R12: 1394166 | T12: 4319337 | U12: 3611260 | V12: 2065763
O13: 2156659
O14: 81945
O15: 1379026
O16: 2249219
O17: 1166966
O18: 2397788
A22: =A4 -> Group names | B22: =B4 -> Solvent control | C22: =C4 -> EE2-33.8ng/L | D22: =D4 -> EE2-50.6ng/L | E22: =E4 -> EE2-76ng/L | F22: =F4 -> EE2-114ng/L | G22: =G4 -> EE2-170.9ng/L | H22: =H4 -> EE2-488ng/L | ... M22: =M4 -> BPA-5mg/L | N22: Nom des groupes | O22: =O4 -> Testo -30µg/L | P22: =P4 -> Testo 30µg/L + EE2 -64ng/L | Q22: =Q4 -> Testo 30µg/L + FAD-10mg/L | R22: =R4 -> BPA-1mg/L + Testostérone | S22: =S4 -> BPA-2mg/L + Testostérone | T22: =T4 -> BPA-3mg/L + Testostérone | U22: =U4 -> BPA-4mg/L + Testostérone | V22: =V4 -> BPA-5mg/L + Testostérone
A23: mean | B23: =AVERAGE(B5:B20) -> 209164.57 | C23: =AVERAGE(C5:C20) -> 425622.86 | D23: =AVERAGE(D5:D20) -> 958404 | E23: =AVERAGE(E5:E20) -> 2889195.7 | F23: =AVERAGE(F5:F20) -> 4669347.7 | G23: =AVERAGE(G5:G20) -> 6899895.7 | H23: =AVERAGE(H5:H20) -> 5916364.3 | I23: =AVERAGE(I5:I20) -> 175274.29 | ... M23: =AVERAGE(M5:M20) -> 3864230.7 | N23: mean | O23: =AVERAGE(O5:O20) -> 1163066.5 | P23: =AVERAGE(P5:P20) -> 5435581 | Q23: =AVERAGE(Q5:Q20) -> 95511.429 | R23: =AVERAGE(R5:R20) -> 1265217 | S23: =AVERAGE(S5:S20) -> 3505144.7 | T23: =AVERAGE(T5:T20) -> 3634024.1 | U23: =AVERAGE(U5:U20) -> 2171551.5 | V23: =AVERAGE(V5:V20) -> 2964269
A24: SD | B24: =STDEV(B5:B20) -> 102325.06 | C24: =STDEV(C5:C20) -> 152817 | D24: =STDEV(D5:D20) -> 530092.4 | E24: =STDEV(E5:E20) -> 1182275.9 | F24: =STDEV(F5:F20) -> 2329656.6 | G24: =STDEV(G5:G20) -> 2109648 | H24: =STDEV(H5:H20) -> 693348.54 | I24: =STDEV(I5:I20) -> 126490.77 | ... M24: =STDEV(M5:M20) -> 1949043.5 | N24: SD | O24: =STDEV(O5:O20) -> 785134.03 | P24: =STDEV(P5:P20) -> 1210455.6 | Q24: =STDEV(Q5:Q20) -> 67697.287 | R24: =STDEV(R5:R20) -> 1074355.6 | S24: =STDEV(S5:S20) -> 1941577.2 | T24: =STDEV(T5:T20) -> 1892625.4 | U24: =STDEV(U5:U20) -> 1005772.9 | V24: =STDEV(V5:V20) -> 1896183.4
B26: Unspiked | O26: Testosterone spiked
A27: =A4 -> Group names | B27: =B4 -> Solvent control | C27: =C4 -> EE2-33.8ng/L | D27: =D4 -> EE2-50.6ng/L | E27: =E4 -> EE2-76ng/L | F27: =F4 -> EE2-114ng/L | G27: =G4 -> EE2-170.9ng/L | H27: =H4 -> EE2-488ng/L | ... M27: =M4 -> BPA-5mg/L | O27: =O4 -> Testo -30µg/L | P27: =P4 -> Testo 30µg/L + EE2 -64ng/L | Q27: =Q4 -> Testo 30µg/L + FAD-10mg/L | R27: =R4 -> BPA-1mg/L + Testostérone | S27: =S4 -> BPA-2mg/L + Testostérone | T27: =T4 -> BPA-3mg/L + Testostérone | U27: =U4 -> BPA-4mg/L + Testostérone | V27: =V4 -> BPA-5mg/L + Testostérone
A28: Data normalised to the "Testo" group | B28: =IF(B5="","",(B5/$O$23)) -> 0.1913949 | C28: =IF(C5="","",(C5/$O$23)) -> 0.3168082 | D28: =IF(D5="","",(D5/$O$23)) -> 0.79013883 | E28: =IF(E5="","",(E5/$O$23)) -> 0.99573928 | F28: =IF(F5="","",(F5/$O$23)) -> 6.0272246 | G28: =IF(G5="","",(G5/$O$23)) -> 6.4783923 | H28: =IF(H5="","",(H5/$O$23)) -> 4.0868944 | I28: =IF(I5="","",(I5/$O$23)) -> 0.057587421 | ... M28: =IF(M5="","",(M5/$O$23)) -> 1.688501 | O28: =IF(O5="","",(O5/$O$23)) -> 0.81597054 | P28: =IF(P5="","",(P5/$O$23)) -> 5.3263764 | Q28: =IF(Q5="","",(Q5/$O$23)) -> 0.037250665 | R28: =IF(R5="","",(R5/$O$23)) -> 0.21488711 | S28: =IF(S5="","",(S5/$O$23)) -> 2.3649224 | T28: =IF(T5="","",(T5/$O$23)) -> 3.9517998 | U28: =IF(U5="","",(U5/$O$23)) -> 1.0089569 | V28: =IF(V5="","",(V5/$O$23)) -> 5.5779614
B29: =IF(B6="","",(B6/$O$23)) -> 0.31282218 | C29: =IF(C6="","",(C6/$O$23)) -> 0.30059072 | D29: =IF(D6="","",(D6/$O$23)) -> 0.63089428 | E29: =IF(E6="","",(E6/$O$23)) -> 4.0444901 | F29: =IF(F6="","",(F6/$O$23)) -> 3.6147538 | G29: =IF(G6="","",(G6/$O$23)) -> 5.7357099 | H29: =IF(H6="","",(H6/$O$23)) -> 5.7655104 | I29: =IF(I6="","",(I6/$O$23)) -> 0.28564919 | ... M29: =IF(M6="","",(M6/$O$23)) -> 4.8154263 | O29: =IF(O6="","",(O6/$O$23)) -> 1.6649478 | P29: =IF(P6="","",(P6/$O$23)) -> 5.5821933 | Q29: =IF(Q6="","",(Q6/$O$23)) -> 0.1005841 | R29: =IF(R6="","",(R6/$O$23)) -> 0.15532388 | S29: =IF(S6="","",(S6/$O$23)) -> 3.7171151 | T29: =IF(T6="","",(T6/$O$23)) -> 0.23123441 | U29: =IF(U6="","",(U6/$O$23)) -> 1.8156064 | V29: =IF(V6="","",(V6/$O$23)) -> 1.8031523
B30: =IF(B7="","",(B7/$O$23)) -> 0.11492894 | C30: =IF(C7="","",(C7/$O$23)) -> 0.27423367 | D30: =IF(D7="","",(D7/$O$23)) -> 0.50842407 | E30: =IF(E7="","",(E7/$O$23)) -> 2.8570843 | F30: =IF(F7="","",(F7/$O$23)) -> 1.5940507 | G30: =IF(G7="","",(G7/$O$23)) -> 4.7751646 | H30: =IF(H7="","",(H7/$O$23)) -> 5.5482485 | I30: =IF(I7="","",(I7/$O$23)) -> 0.3015236 | ... M30: =IF(M7="","",(M7/$O$23)) -> 6.2968128 | O30: =IF(O7="","",(O7/$O$23)) -> 0.73959228 | P30: =IF(P7="","",(P7/$O$23)) -> 3.9460074 | Q30: =IF(Q7="","",(Q7/$O$23)) -> 0.066658269 | R30: =IF(R7="","",(R7/$O$23)) -> 2.1011 | S30: =IF(S7="","",(S7/$O$23)) -> 3.0324809 | T30: =IF(T7="","",(T7/$O$23)) -> 3.2590217 | U30: =IF(U7="","",(U7/$O$23)) -> 1.2988638 | V30: =IF(V7="","",(V7/$O$23)) -> 2.0419159
B31: =IF(B8="","",(B8/$O$23)) -> 0.16054972 | C31: =IF(C8="","",(C8/$O$23)) -> 0.54127515 | D31: =IF(D8="","",(D8/$O$23)) -> 0.4393833 | E31: =IF(E8="","",(E8/$O$23)) -> 1.9265794 | F31: =IF(F8="","",(F8/$O$23)) -> 1.7669703 | G31: =IF(G8="","",(G8/$O$23)) -> 6.7045797 | H31: =IF(H8="","",(H8/$O$23)) -> 4.5206383 | I31: =IF(I8="","",(I8/$O$23)) -> 0.021575722 | ... M31: =IF(M8="","",(M8/$O$23)) -> 2.9363979 | O31: =IF(O8="","",(O8/$O$23)) -> 0.43666979 | P31: =IF(P8="","",(P8/$O$23)) -> 3.2760087 | Q31: =IF(Q8="","",(Q8/$O$23)) -> 0.02812221 | R31: =IF(R8="","",(R8/$O$23)) -> 0.43480231 | S31: =IF(S8="","",(S8/$O$23)) -> 1.6207001 | T31: =IF(T8="","",(T8/$O$23)) -> 1.9261263 | U31: =IF(U8="","",(U8/$O$23)) -> 0.59454296 | V31: =IF(V8="","",(V8/$O$23)) -> 0.52132359
B32: =IF(B9="","",(B9/$O$23)) -> 0.19028577 | C32: =IF(C9="","",(C9/$O$23)) -> 0.50996654 | D32: =IF(D9="","",(D9/$O$23)) -> 1.5804754 | E32: =IF(E9="","",(E9/$O$23)) -> 2.6413133 | F32: =IF(F9="","",(F9/$O$23)) -> 4.4190096 | G32: =IF(G9="","",(G9/$O$23)) -> 9.0820697 | H32: =IF(H9="","",(H9/$O$23)) -> 5.2016381 | I32: =IF(I9="","",(I9/$O$23)) -> 0.094700518 | ... M32: =IF(M9="","",(M9/$O$23)) -> 2.5669788 | O32: =IF(O9="","",(O9/$O$23)) -> 1.124842 | P32: =IF(P9="","",(P9/$O$23)) -> 4.954206 | Q32: =IF(Q9="","",(Q9/$O$23)) -> 0.093117633 | R32: =IF(R9="","",(R9/$O$23)) -> 2.7306985 | S32: =IF(S9="","",(S9/$O$23)) -> 5.6785936 | T32: =IF(T9="","",(T9/$O$23)) -> 5.8722214 | U32: =IF(U9="","",(U9/$O$23)) -> 2.6165744 | V32: =IF(V9="","",(V9/$O$23)) -> 3.0703214
B33: =IF(B10="","",(B10/$O$23)) -> 0.24794283 | C33: =IF(C10="","",(C10/$O$23)) -> 0.18568156 | D33: =IF(D10="","",(D10/$O$23)) -> 0.47727881 | E33: =IF(E10="","",(E10/$O$23)) -> 3.1946643 | F33: =IF(F10="","",(F10/$O$23)) -> 3.7167772 | G33: =IF(G10="","",(G10/$O$23)) -> 5.5381339 | H33: =IF(H10="","",(H10/$O$23)) -> 5.0468172 | I33: =IF(I10="","",(I10/$O$23)) -> 0.17432881 | ... M33: =IF(M10="","",(M10/$O$23)) -> 1.7862814 | O33: =IF(O10="","",(O10/$O$23)) -> 0.72486569 | P33: =IF(P10="","",(P10/$O$23)) -> 5.9650321 | Q33: =IF(Q10="","",(Q10/$O$23)) -> 0.19904021 | R33: =IF(R10="","",(R10/$O$23)) -> 1.1877558 | S33: =IF(S10="","",(S10/$O$23)) -> 0.6297069 | T33: =IF(T10="","",(T10/$O$23)) -> 2.7887537 | U33: =IF(U10="","",(U10/$O$23)) -> 2.5386347 | V33: =IF(V10="","",(V10/$O$23)) -> 4.124403
B34: =IF(B11="","",(B11/$O$23)) -> 0.040947788 | C34: =IF(C11="","",(C11/$O$23)) -> 0.43308616 | D34: =IF(D11="","",(D11/$O$23)) -> 1.3416292 | E34: =IF(E11="","",(E11/$O$23)) -> 1.728963 | F34: =IF(F11="","",(F11/$O$23)) -> 6.9640214 | G34: =IF(G11="","",(G11/$O$23)) -> 3.2134723 | H34: =IF(H11="","",(H11/$O$23)) -> 5.4383202 | I34: =IF(I11="","",(I11/$O$23)) -> 0.11953573 | ... M34: =IF(M11="","",(M11/$O$23)) -> 3.1667544 | O34: =IF(O11="","",(O11/$O$23)) -> 0.053723497 | P34: =IF(P11="","",(P11/$O$23)) -> 3.6646142 | Q34: =IF(Q11="","",(Q11/$O$23)) -> 0.050069364 | R34: =IF(R11="","",(R11/$O$23)) -> 0.6793627 | S34: =IF(S11="","",(S11/$O$23)) -> 4.0524484 | T34: =IF(T11="","",(T11/$O$23)) -> 3.2532508 | U34: =IF(U11="","",(U11/$O$23)) -> 1.9586051 | V34: =IF(V11="","",(V11/$O$23)) -> 1.4741221
B35: =IF(B12="","",(B12/$O$23)) | C35: =IF(C12="","",(C12/$O$23)) | D35: =IF(D12="","",(D12/$O$23)) | E35: =IF(E12="","",(E12/$O$23)) | F35: =IF(F12="","",(F12/$O$23)) | G35: =IF(G12="","",(G12/$O$23)) | H35: =IF(H12="","",(H12/$O$23)) | I35: =IF(I12="","",(I12/$O$23)) | ... M35: =IF(M12="","",(M12/$O$23)) | O35: =IF(O12="","",(O12/$O$23)) -> 0.33013332 | P35: =IF(P12="","",(P12/$O$23)) | Q35: =IF(Q12="","",(Q12/$O$23)) | R35: =IF(R12="","",(R12/$O$23)) -> 1.1986984 | S35: =IF(S12="","",(S12/$O$23)) | T35: =IF(T12="","",(T12/$O$23)) -> 3.713749 | U35: =IF(U12="","",(U12/$O$23)) -> 3.1049471 | V35: =IF(V12="","",(V12/$O$23)) -> 1.7761349
B36: =IF(B13="","",(B13/$O$23)) | C36: =IF(C13="","",(C13/$O$23)) | D36: =IF(D13="","",(D13/$O$23)) | E36: =IF(E13="","",(E13/$O$23)) | F36: =IF(F13="","",(F13/$O$23)) | G36: =IF(G13="","",(G13/$O$23)) | H36: =IF(H13="","",(H13/$O$23)) | I36: =IF(I13="","",(I13/$O$23)) | ... M36: =IF(M13="","",(M13/$O$23)) | O36: =IF(O13="","",(O13/$O$23)) -> 1.8542869 | P36: =IF(P13="","",(P13/$O$23)) | Q36: =IF(Q13="","",(Q13/$O$23)) | R36: =IF(R13="","",(R13/$O$23)) | S36: =IF(S13="","",(S13/$O$23)) | T36: =IF(T13="","",(T13/$O$23)) | U36: =IF(U13="","",(U13/$O$23)) | V36: =IF(V13="","",(V13/$O$23))
B37: =IF(B14="","",(B14/$O$23)) | C37: =IF(C14="","",(C14/$O$23)) | D37: =IF(D14="","",(D14/$O$23)) | E37: =IF(E14="","",(E14/$O$23)) | F37: =IF(F14="","",(F14/$O$23)) | G37: =IF(G14="","",(G14/$O$23)) | H37: =IF(H14="","",(H14/$O$23)) | I37: =IF(I14="","",(I14/$O$23)) | ... M37: =IF(M14="","",(M14/$O$23)) | O37: =IF(O14="","",(O14/$O$23)) -> 0.070455989 | P37: =IF(P14="","",(P14/$O$23)) | Q37: =IF(Q14="","",(Q14/$O$23)) | R37: =IF(R14="","",(R14/$O$23)) | S37: =IF(S14="","",(S14/$O$23)) | T37: =IF(T14="","",(T14/$O$23)) | U37: =IF(U14="","",(U14/$O$23)) | V37: =IF(V14="","",(V14/$O$23))
B38: =IF(B15="","",(B15/$O$23)) | C38: =IF(C15="","",(C15/$O$23)) | D38: =IF(D15="","",(D15/$O$23)) | E38: =IF(E15="","",(E15/$O$23)) | F38: =IF(F15="","",(F15/$O$23)) | G38: =IF(G15="","",(G15/$O$23)) | H38: =IF(H15="","",(H15/$O$23)) | I38: =IF(I15="","",(I15/$O$23)) | ... M38: =IF(M15="","",(M15/$O$23)) | O38: =IF(O15="","",(O15/$O$23)) -> 1.1856811 | P38: =IF(P15="","",(P15/$O$23)) | Q38: =IF(Q15="","",(Q15/$O$23)) | R38: =IF(R15="","",(R15/$O$23)) | S38: =IF(S15="","",(S15/$O$23)) | T38: =IF(T15="","",(T15/$O$23)) | U38: =IF(U15="","",(U15/$O$23)) | V38: =IF(V15="","",(V15/$O$23))
B39: =IF(B16="","",(B16/$O$23)) | C39: =IF(C16="","",(C16/$O$23)) | D39: =IF(D16="","",(D16/$O$23)) | E39: =IF(E16="","",(E16/$O$23)) | F39: =IF(F16="","",(F16/$O$23)) | G39: =IF(G16="","",(G16/$O$23)) | H39: =IF(H16="","",(H16/$O$23)) | I39: =IF(I16="","",(I16/$O$23)) | ... M39: =IF(M16="","",(M16/$O$23)) | O39: =IF(O16="","",(O16/$O$23)) -> 1.9338696 | P39: =IF(P16="","",(P16/$O$23)) | Q39: =IF(Q16="","",(Q16/$O$23)) | R39: =IF(R16="","",(R16/$O$23)) | S39: =IF(S16="","",(S16/$O$23)) | T39: =IF(T16="","",(T16/$O$23)) | U39: =IF(U16="","",(U16/$O$23)) | V39: =IF(V16="","",(V16/$O$23))
B40: =IF(B17="","",(B17/$O$23)) | C40: =IF(C17="","",(C17/$O$23)) | D40: =IF(D17="","",(D17/$O$23)) | E40: =IF(E17="","",(E17/$O$23)) | F40: =IF(F17="","",(F17/$O$23)) | G40: =IF(G17="","",(G17/$O$23)) | H40: =IF(H17="","",(H17/$O$23)) | I40: =IF(I17="","",(I17/$O$23)) | ... M40: =IF(M17="","",(M17/$O$23)) | O40: =IF(O17="","",(O17/$O$23)) -> 1.0033528 | P40: =IF(P17="","",(P17/$O$23)) | Q40: =IF(Q17="","",(Q17/$O$23)) | R40: =IF(R17="","",(R17/$O$23)) | S40: =IF(S17="","",(S17/$O$23)) | T40: =IF(T17="","",(T17/$O$23)) | U40: =IF(U17="","",(U17/$O$23)) | V40: =IF(V17="","",(V17/$O$23))
... B43: =IF(B20="","",(B20/$O$23)) | C43: =IF(C20="","",(C20/$O$23)) | D43: =IF(D20="","",(D20/$O$23)) | E43: =IF(E20="","",(E20/$O$23)) | F43: =IF(F20="","",(F20/$O$23)) | G43: =IF(G20="","",(G20/$O$23)) | H43: =IF(H20="","",(H20/$O$23)) | I43: =IF(I20="","",(I20/$O$23)) | ... M43: =IF(M20="","",(M20/$O$23)) | O43: =IF(O20="","",(O20/$O$23)) | P43: =IF(P20="","",(P20/$O$23)) | Q43: =IF(Q20="","",(Q20/$O$23)) | R43: =IF(R20="","",(R20/$O$23)) | S43: =IF(S20="","",(S20/$O$23)) | T43: =IF(T20="","",(T20/$O$23)) | U43: =IF(U20="","",(U20/$O$23)) | V43: =IF(V20="","",(V20/$O$23))
A45: =A4 -> Group names | B45: =B4 -> Solvent control | C45: =C4 -> EE2-33.8ng/L | D45: =D4 -> EE2-50.6ng/L | E45: =E4 -> EE2-76ng/L | F45: =F4 -> EE2-114ng/L | G45: =G4 -> EE2-170.9ng/L | H45: =H4 -> EE2-488ng/L | ... M45: =M4 -> BPA-5mg/L | N45: =N22 -> Nom des groupes | O45: =O4 -> Testo -30µg/L | P45: =P4 -> Testo 30µg/L + EE2 -64ng/L | Q45: =Q4 -> Testo 30µg/L + FAD-10mg/L | R45: =R4 -> BPA-1mg/L + Testostérone | S45: =S4 -> BPA-2mg/L + Testostérone | T45: =T4 -> BPA-3mg/L + Testostérone | U45: =U4 -> BPA-4mg/L + Testostérone | V45: =V4 -> BPA-5mg/L + Testostérone
A46: mean | B46: =AVERAGE(B28:B43) -> 0.17983888 | C46: =AVERAGE(C28:C43) -> 0.36594886 | D46: =AVERAGE(D28:D43) -> 0.82403199 | E46: =AVERAGE(E28:E43) -> 2.4841191 | F46: =AVERAGE(F28:F43) -> 4.0146868 | G46: =AVERAGE(G28:G43) -> 5.9325032 | H46: =AVERAGE(H28:H43) -> 5.0868667 | I46: =AVERAGE(I28:I43) -> 0.15070014 | ... M46: =AVERAGE(M28:M43) -> 3.3224504 | N46: mean | O46: =AVERAGE(O28:O43) -> 1 | P46: =AVERAGE(P28:P43) -> 4.6734912 | Q46: =AVERAGE(Q28:Q43) -> 0.08212035 | R46: =AVERAGE(R28:R43) -> 1.0878286 | S46: =AVERAGE(S28:S43) -> 3.0137096 | T46: =AVERAGE(T28:T43) -> 3.1245196 | U46: =AVERAGE(U28:U43) -> 1.8670914 | V46: =AVERAGE(V28:V43) -> 2.5486668
A47: SD | B47: =STDEV(B28:B43) -> 0.087978684 | C47: =STDEV(C28:C43) -> 0.13139145 | D47: =STDEV(D28:D43) -> 0.45577136 | E47: =STDEV(E28:E43) -> 1.0165162 | F47: =STDEV(F28:F43) -> 2.0030296 | G47: =STDEV(G28:G43) -> 1.8138671 | H47: =STDEV(H28:H43) -> 0.59613834 | I47: =STDEV(I28:I43) -> 0.10875626 | ... M47: =STDEV(M28:M43) -> 1.6757799 | N47: SD | O47: =STDEV(O28:O43) -> 0.67505515 | P47: =STDEV(P28:P43) -> 1.0407449 | Q47: =STDEV(Q28:Q43) -> 0.058205861 | R47: =STDEV(R28:R43) -> 0.92372675 | S47: =STDEV(S28:S43) -> 1.6693605 | T47: =STDEV(T28:T43) -> 1.6272719 | U47: =STDEV(U28:U43) -> 0.86475961 | V47: =STDEV(V28:V43) -> 1.630331
A48: SEM | B48: =B47/SQRT(COUNT(B28:B43)) -> 0.033252817 | C48: =C47/SQRT(COUNT(C28:C43)) -> 0.049661302 | D48: =D47/SQRT(COUNT(D28:D43)) -> 0.17226538 | E48: =E47/SQRT(COUNT(E28:E43)) -> 0.384207 | F48: =F47/SQRT(COUNT(F28:F43)) -> 0.75707402 | G48: =G47/SQRT(COUNT(G28:G43)) -> 0.68557731 | H48: =H47/SQRT(COUNT(H28:H43)) -> 0.22531911 | I48: =I47/SQRT(COUNT(I28:I43)) -> 0.041106003 | ... M48: =M47/SQRT(COUNT(M28:M43)) -> 0.63338527 | N48: SEM | O48: =O47/SQRT(COUNT(O28:O43)) -> 0.18041608 | P48: =P47/SQRT(COUNT(P28:P43)) -> 0.39336461 | Q48: =Q47/SQRT(COUNT(Q28:Q43)) -> 0.021999748 | R48: =R47/SQRT(COUNT(R28:R43)) -> 0.32658672 | S48: =S47/SQRT(COUNT(S28:S43)) -> 0.63095894 | T48: =T47/SQRT(COUNT(T28:T43)) -> 0.57532748 | U48: =U47/SQRT(COUNT(U28:U43)) -> 0.30573869 | V48: =V47/SQRT(COUNT(V28:V43)) -> 0.57640906
A52: =A27 -> Group names | B52: =B27 -> Solvent control | C52: =C27 -> EE2-33.8ng/L | D52: =D27 -> EE2-50.6ng/L | E52: =E27 -> EE2-76ng/L | F52: =F27 -> EE2-114ng/L | G52: =G27 -> EE2-170.9ng/L | H52: =H27 -> EE2-488ng/L | I52: =I4 -> BPA-1mg/L | J52: =J4 -> BPA-2mg/L | K52: =K27 -> BPA-3mg/L | L52: =L27 -> BPA-4mg/L | M52: =M27 -> BPA-5mg/L | O52: =O27 -> Testo -30µg/L | P52: =P27 -> Testo 30µg/L + EE2 -64ng/L | Q52: =Q27 -> Testo 30µg/L + FAD-10mg/L | R52: =R27 -> BPA-1mg/L + Testostérone | S52: =S27 -> BPA-2mg/L + Testostérone | T52: =T27 -> BPA-3mg/L + Testostérone | U52: =U27 -> BPA-4mg/L + Testostérone | V52: =V27 -> BPA-5mg/L + Testostérone
...

Sheet R2
A3: R2 | B3: Unspiked | O3: Testosterone spiked
A4: Group names | B4: ='Front page'!A7 -> Solvent control | C4: ='Front page'!A8 -> EE2-33.8ng/L | D4: ='Front page'!A9 -> EE2-50.6ng/L | E4: ='Front page'!A10 -> EE2-76ng/L | F4: ='Front page'!A11 -> EE2-114ng/L | G4: ='Front page'!A12 -> EE2-170.9ng/L | H4: ='Front page'!A13 -> EE2-488ng/L | I4: ='Front page'!A14 -> BPA-1mg/L | J4: ='Front page'!A15 -> BPA-2mg/L | K4: ='Front page'!A16 -> BPA-3mg/L | L4: ='Front page'!A17 -> BPA-4mg/L | M4: ='Front page'!A18 -> BPA-5mg/L | O4: ='Front page'!A35 -> Testo -30µg/L | P4: ='Front page'!A36 -> Testo 30µg/L + EE2 -64ng/L | Q4: ='Front page'!A37 -> Testo 30µg/L + FAD-10mg/L | R4: ='Front page'!A38 -> BPA-1mg/L + Testostérone | S4: ='Front page'!A39 -> BPA-2mg/L + Testostérone | T4: ='Front page'!A40 -> BPA-3mg/L + Testostérone | U4: ='Front page'!A41 -> BPA-4mg/L + Testostérone | V4: ='Front page'!A42 -> BPA-5mg/L + Testostérone
A5: Raw data | B5: 14159 | C5: 1000998 | D5: 604592 | E5: 604880 | F5: 4881547 | G5: 6616378 | H5: 6372864 | I5: 22255 | J5: 330634 | K5: 112774 | L5: 127937 | M5: 3507802 | O5: 1122759 | P5: 8898570 | Q5: 75738 | R5: 2549754 | S5: 2732355 | T5: 7258804 | U5: 4914014 | V5: 7839765
B6: 28379 | C6: 72708 | D6: 1626818 | E6: 1117348 | F6: 1731234 | G6: 5547818 | H6: 8983010 | I6: 54887 | J6: 200790 | K6: 65221 | L6: 133525 | M6: 1629746 | O6: 1139274 | P6: 3772461 | Q6: 84948 | R6: 1157480 | S6: 2517073 | T6: 3434137 | U6: 5039732 | V6: 8411325
B7: 121513 | C7: 93227 | D7: 192314 | E7: 1984922 | F7: 4593435 | G7: 4474566 | H7: 7216257 | I7: 220335 | J7: 73117 | K7: 207057 | L7: 921921 | M7: 501995 | O7: 1978479 | P7: 3030272 | Q7: 79458 | R7: 15676 | S7: 1189142 | T7: 5132589 | U7: 3836848 | V7: 8623596
B8: 86474 | C8: 114241 | D8: 959452 | E8: 2160125 | F8: 7657514 | G8: 4844722 | H8: 5855810 | I8: 151881 | J8: 66284 | K8: 72661 | L8: 398271 | M8: 299894 | O8: 394517 | P8: 6261709 | Q8: 223033 | R8: 2731641 | S8: 298139 | T8: 4661554 | U8: 4726560 | V8: 5114176
B9: 174073 | C9: 217315 | D9: 837303 | E9: 4753438 | F9: 1644986 | G9: 2741081 | H9: 5145738 | I9: 142840 | J9: 604464 | K9: 131265 | L9: 54516 | M9: 1398473 | O9: 3776283 | P9: 3582444 | Q9: 19153 | R9: 457982 | S9: 2479461 | T9: 4402351 | U9: 4718432 | V9: 4847642
B10: 61514 | C10: 65767 | D10: 1788181 | E10: 3141552 | F10: 2674888 | G10: 3078429 | H10: 7205188 | I10: 314930 | J10: 40038 | K10: 1014563 | L10: 96669 | M10: 1037245 | O10: 1178854 | P10: 3029666 | Q10: 247241 | R10: 1438408 | S10: 2318809 | T10: 7526193 | U10: 3757971 | V10: 8706403
B11: 72001 | C11: 199728 | D11: 1345193 | E11: 2348048 | F11: 4876029 | G11: 4634261 | H11: 3596537 | I11: 64149 | J11: 94345 | K11: 290817 | L11: 381061 | M11: 1495106 | O11: 158801 | P11: 5111162 | Q11: 249971 | R11: 1074156 | S11: 2661982 | T11: 5038636 | U11: 6931512 | V11: 1612620
B12: 160380 | C12: 217854 | D12: 137764 | E12: 1802229 | F12: 3731776 | G12: 6124493 | H12: 10745023 | I12: 196706 | K12: 289115 | L12: 150132 | M12: 2413851 | O12: 763690 | Q12: 13739 | R12: 1020006 | S12: 3560716 | T12: 513672 | U12: 5786584 | V12: 4763648
O13: 1562924
O14: 1498603
O15: 1750872
O16: 9901
O17: 827890
O18: 166340
O19: 748759
O20: 148954
A22: =A4 -> Group names | B22: =B4 -> Solvent control | C22: =C4 -> EE2-33.8ng/L | D22: =D4 -> EE2-50.6ng/L | E22: =E4 -> EE2-76ng/L | F22: =F4 -> EE2-114ng/L | G22: =G4 -> EE2-170.9ng/L | H22: =H4 -> EE2-488ng/L | ... M22: =M4 -> BPA-5mg/L | N22: Noms des groupes | O22: =O4 -> Testo -30µg/L | P22: =P4 -> Testo 30µg/L + EE2 -64ng/L | Q22: =Q4 -> Testo 30µg/L + FAD-10mg/L | R22: =R4 -> BPA-1mg/L + Testostérone | S22: =S4 -> BPA-2mg/L + Testostérone | T22: =T4 -> BPA-3mg/L + Testostérone | U22: =U4 -> BPA-4mg/L + Testostérone | V22: =V4 -> BPA-5mg/L + Testostérone
A23: mean | B23: =AVERAGE(B5:B20) -> 89811.625 | C23: =AVERAGE(C5:C20) -> 247729.75 | D23: =AVERAGE(D5:D20) -> 936452.12 | E23: =AVERAGE(E5:E20) -> 2239067.8 | F23: =AVERAGE(F5:F20) -> 3973926.1 | G23: =AVERAGE(G5:G20) -> 4757718.5 | H23: =AVERAGE(H5:H20) -> 6890053.4 | I23: =AVERAGE(I5:I20) -> 145997.88 | J23: =AVERAGE(J5:J20) -> 201381.71 | L23: =AVERAGE(L5:L20) -> 283004 | N23: mean | O23: =AVERAGE(O5:O20) -> 1076681.2 | P23: =AVERAGE(P5:P20) -> 4812326.3 | Q23: =AVERAGE(Q5:Q20) -> 124160.12 | R23: =AVERAGE(R5:R20) -> 1305637.9 | S23: =AVERAGE(S5:S20) -> 2219709.6 | T23: =AVERAGE(T5:T20) -> 4745992 | U23: =AVERAGE(U5:U20) -> 4963956.6 | V23: =AVERAGE(V5:V20) -> 6239896.9
A24: SD | B24: =STDEV(B5:B20) -> 58200.703 | C24: =STDEV(C5:C20) -> 310981.91 | D24: =STDEV(D5:D20) -> 618898.93 | E24: =STDEV(E5:E20) -> 1272729.8 | F24: =STDEV(F5:F20) -> 1992483.8 | G24: =STDEV(G5:G20) -> 1359452.2 | H24: =STDEV(H5:H20) -> 2225630.2 | I24: =STDEV(I5:I20) -> 97828.346 | J24: =STDEV(J5:J20) -> 204684.19 | L24: =STDEV(L5:L20) -> 288367.03 | N24: SD | O24: =STDEV(O5:O20) -> 944782.77 | P24: =STDEV(P5:P20) -> 2153869.6 | Q24: =STDEV(Q5:Q20) -> 99894.957 | R24: =STDEV(R5:R20) -> 936450.75 | S24: =STDEV(S5:S20) -> 1012558.8 | T24: =STDEV(T5:T20) -> 2205109.5 | U24: =STDEV(U5:U20) -> 1028010.6 | V24: =STDEV(V5:V20) -> 2558933.2
B26: Unspiked | O26: Testosterone spiked
A27: =A4 -> Group names | B27: =B4 -> Solvent control | C27: =C4 -> EE2-33.8ng/L | D27: =D4 -> EE2-50.6ng/L | E27: =E4 -> EE2-76ng/L | F27: =F4 -> EE2-114ng/L | G27: =G4 -> EE2-170.9ng/L | H27: =H4 -> EE2-488ng/L | ... M27: =M4 -> BPA-5mg/L | O27: =O4 -> Testo -30µg/L | P27: =P4 -> Testo 30µg/L + EE2 -64ng/L | Q27: =Q4 -> Testo 30µg/L + FAD-10mg/L | R27: =R4 -> BPA-1mg/L + Testostérone | S27: =S4 -> BPA-2mg/L + Testostérone | T27: =T4 -> BPA-3mg/L + Testostérone | U27: =U4 -> BPA-4mg/L + Testostérone | V27: =V4 -> BPA-5mg/L + Testostérone
A28: Data normalised to the "Testo" group | B28: =IF(B5="","",(B5/$O$23)) -> 0.013150596 | C28: =IF(C5="","",(C5/$O$23)) -> 0.92970691 | D28: =IF(D5="","",(D5/$O$23)) -> 0.56153295 | E28: =IF(E5="","",(E5/$O$23)) -> 0.56180044 | F28: =IF(F5="","",(F5/$O$23)) -> 4.5338832 | G28: =IF(G5="","",(G5/$O$23)) -> 6.1451595 | H28: =IF(H5="","",(H5/$O$23)) -> 5.9189886 | I28: =IF(I5="","",(I5/$O$23)) -> 0.020669999 | ... M28: =IF(M5="","",(M5/$O$23)) -> 3.2579763 | O28: =IF(O5="","",(O5/$O$23)) -> 1.0427961 | P28: =IF(P5="","",(P5/$O$23)) -> 8.2648138 | Q28: =IF(Q5="","",(Q5/$O$23)) -> 0.070343939 | R28: =IF(R5="","",(R5/$O$23)) -> 2.3681605 | S28: =IF(S5="","",(S5/$O$23)) -> 2.5377566 | T28: =IF(T5="","",(T5/$O$23)) -> 6.7418319 | U28: =IF(U5="","",(U5/$O$23)) -> 4.5640379 | V28: =IF(V5="","",(V5/$O$23)) -> 7.2814169
B29: =IF(B6="","",(B6/$O$23)) -> 0.026357847 | C29: =IF(C6="","",(C6/$O$23)) -> 0.067529735 | D29: =IF(D6="","",(D6/$O$23)) -> 1.510956 | E29: =IF(E6="","",(E6/$O$23)) -> 1.0377705 | F29: =IF(F6="","",(F6/$O$23)) -> 1.6079355 | G29: =IF(G6="","",(G6/$O$23)) -> 5.1527023 | H29: =IF(H6="","",(H6/$O$23)) -> 8.3432399 | I29: =IF(I6="","",(I6/$O$23)) -> 0.050977947 | ... M29: =IF(M6="","",(M6/$O$23)) -> 1.5136755 | O29: =IF(O6="","",(O6/$O$23)) -> 1.0581349 | P29: =IF(P6="","",(P6/$O$23)) -> 3.5037863 | Q29: =IF(Q6="","",(Q6/$O$23)) -> 0.078898003 | R29: =IF(R6="","",(R6/$O$23)) -> 1.0750443 | S29: =IF(S6="","",(S6/$O$23)) -> 2.337807 | T29: =IF(T6="","",(T6/$O$23)) -> 3.1895577 | U29: =IF(U6="","",(U6/$O$23)) -> 4.6808022 | V29: =IF(V6="","",(V6/$O$23)) -> 7.8122703
B30: =IF(B7="","",(B7/$O$23)) -> 0.11285884 | C30: =IF(C7="","",(C7/$O$23)) -> 0.086587372 | D30: =IF(D7="","",(D7/$O$23)) -> 0.17861739 | E30: =IF(E7="","",(E7/$O$23)) -> 1.8435558 | F30: =IF(F7="","",(F7/$O$23)) -> 4.2662905 | G30: =IF(G7="","",(G7/$O$23)) -> 4.1558874 | H30: =IF(H7="","",(H7/$O$23)) -> 6.7023151 | I30: =IF(I7="","",(I7/$O$23)) -> 0.20464274 | ... M30: =IF(M7="","",(M7/$O$23)) -> 0.46624291 | O30: =IF(O7="","",(O7/$O$23)) -> 1.8375717 | P30: =IF(P7="","",(P7/$O$23)) -> 2.814456 | Q30: =IF(Q7="","",(Q7/$O$23)) -> 0.073799 | R30: =IF(R7="","",(R7/$O$23)) -> 0.014559555 | S30: =IF(S7="","",(S7/$O$23)) -> 1.1044513 | T30: =IF(T7="","",(T7/$O$23)) -> 4.767046 | U30: =IF(U7="","",(U7/$O$23)) -> 3.5635876 | V30: =IF(V7="","",(V7/$O$23)) -> 8.0094234
B31: =IF(B8="","",(B8/$O$23)) -> 0.080315321 | C31: =IF(C8="","",(C8/$O$23)) -> 0.10610475 | D31: =IF(D8="","",(D8/$O$23)) -> 0.89111982 | E31: =IF(E8="","",(E8/$O$23)) -> 2.0062809 | F31: =IF(F8="","",(F8/$O$23)) -> 7.1121458 | G31: =IF(G8="","",(G8/$O$23)) -> 4.4996808 | H31: =IF(H8="","",(H8/$O$23)) -> 5.4387591 | I31: =IF(I8="","",(I8/$O$23)) -> 0.14106403 | ... M31: =IF(M8="","",(M8/$O$23)) -> 0.27853555 | O31: =IF(O8="","",(O8/$O$23)) -> 0.3664195 | P31: =IF(P8="","",(P8/$O$23)) -> 5.81575 | Q31: =IF(Q8="","",(Q8/$O$23)) -> 0.20714859 | R31: =IF(R8="","",(R8/$O$23)) -> 2.5370935 | S31: =IF(S8="","",(S8/$O$23)) -> 0.27690554 | T31: =IF(T8="","",(T8/$O$23)) -> 4.3295581 | U31: =IF(U8="","",(U8/$O$23)) -> 4.3899343 | V31: =IF(V8="","",(V8/$O$23)) -> 4.7499443
B32: =IF(B9="","",(B9/$O$23)) -> 0.16167552 | C32: =IF(C9="","",(C9/$O$23)) -> 0.20183782 | D32: =IF(D9="","",(D9/$O$23)) -> 0.77767027 | E32: =IF(E9="","",(E9/$O$23)) -> 4.4148981 | F32: =IF(F9="","",(F9/$O$23)) -> 1.5278301 | G32: =IF(G9="","",(G9/$O$23)) -> 2.5458612 | H32: =IF(H9="","",(H9/$O$23)) -> 4.7792585 | I32: =IF(I9="","",(I9/$O$23)) -> 0.13266693 | ... M32: =IF(M9="","",(M9/$O$23)) -> 1.2988737 | O32: =IF(O9="","",(O9/$O$23)) -> 3.5073361 | P32: =IF(P9="","",(P9/$O$23)) -> 3.3273023 | Q32: =IF(Q9="","",(Q9/$O$23)) -> 0.017788923 | R32: =IF(R9="","",(R9/$O$23)) -> 0.42536452 | S32: =IF(S9="","",(S9/$O$23)) -> 2.3028738 | T32: =IF(T9="","",(T9/$O$23)) -> 4.0888155 | U32: =IF(U9="","",(U9/$O$23)) -> 4.3823852 | V32: =IF(V9="","",(V9/$O$23)) -> 4.5023929
B33: =IF(B10="","",(B10/$O$23)) -> 0.057132972 | C33: =IF(C10="","",(C10/$O$23)) -> 0.061083074 | D33: =IF(D10="","",(D10/$O$23)) -> 1.6608267 | E33: =IF(E10="","",(E10/$O$23)) -> 2.9178106 | F33: =IF(F10="","",(F10/$O$23)) -> 2.4843824 | G33: =IF(G10="","",(G10/$O$23)) -> 2.8591833 | H33: =IF(H10="","",(H10/$O$23)) -> 6.6920344 | I33: =IF(I10="","",(I10/$O$23)) -> 0.29250068 | ... M33: =IF(M10="","",(M10/$O$23)) -> 0.9633724 | O33: =IF(O10="","",(O10/$O$23)) -> 1.094896 | P33: =IF(P10="","",(P10/$O$23)) -> 2.8138932 | Q33: =IF(Q10="","",(Q10/$O$23)) -> 0.22963249 | R33: =IF(R10="","",(R10/$O$23)) -> 1.3359646 | S33: =IF(S10="","",(S10/$O$23)) -> 2.1536634 | T33: =IF(T10="","",(T10/$O$23)) -> 6.9901775 | U33: =IF(U10="","",(U10/$O$23)) -> 3.4903283 | V33: =IF(V10="","",(V10/$O$23)) -> 8.0863329
B34: =IF(B11="","",(B11/$O$23)) -> 0.066873088 | C34: =IF(C11="","",(C11/$O$23)) -> 0.18550337 | D34: =IF(D11="","",(D11/$O$23)) -> 1.2493883 | E34: =IF(E11="","",(E11/$O$23)) -> 2.18082 | F34: =IF(F11="","",(F11/$O$23)) -> 4.5287582 | G34: =IF(G11="","",(G11/$O$23)) -> 4.3042089 | H34: =IF(H11="","",(H11/$O$23)) -> 3.3403916 | I34: =IF(I11="","",(I11/$O$23)) -> 0.059580308 | ... M34: =IF(M11="","",(M11/$O$23)) -> 1.3886245 | O34: =IF(O11="","",(O11/$O$23)) -> 0.14749119 | P34: =IF(P11="","",(P11/$O$23)) -> 4.747145 | Q34: =IF(Q11="","",(Q11/$O$23)) -> 0.23216806 | R34: =IF(R11="","",(R11/$O$23)) -> 0.9976546 | S34: =IF(S11="","",(S11/$O$23)) -> 2.4723956 | T34: =IF(T11="","",(T11/$O$23)) -> 4.6797843 | U34: =IF(U11="","",(U11/$O$23)) -> 6.4378496 | V34: =IF(V11="","",(V11/$O$23)) -> 1.4977692
B35: =IF(B12="","",(B12/$O$23)) -> 0.14895773 | C35: =IF(C12="","",(C12/$O$23)) -> 0.20233844 | D35: =IF(D12="","",(D12/$O$23)) -> 0.12795245 | E35: =IF(E12="","",(E12/$O$23)) -> 1.6738742 | F35: =IF(F12="","",(F12/$O$23)) -> 3.4659989 | G35: =IF(G12="","",(G12/$O$23)) -> 5.6883065 | H35: =IF(H12="","",(H12/$O$23)) -> 9.9797623 | I35: =IF(I12="","",(I12/$O$23)) -> 0.1826966 | ... M35: =IF(M12="","",(M12/$O$23)) -> 2.2419365 | O35: =IF(O12="","",(O12/$O$23)) -> 0.70929999 | P35: =IF(P12="","",(P12/$O$23)) | Q35: =IF(Q12="","",(Q12/$O$23)) -> 0.012760508 | R35: =IF(R12="","",(R12/$O$23)) -> 0.94736116 | S35: =IF(S12="","",(S12/$O$23)) -> 3.3071218 | T35: =IF(T12="","",(T12/$O$23)) -> 0.47708827 | U35: =IF(U12="","",(U12/$O$23)) -> 5.3744634 | V35: =IF(V12="","",(V12/$O$23)) -> 4.4243809
B36: =IF(B13="","",(B13/$O$23)) | C36: =IF(C13="","",(C13/$O$23)) | D36: =IF(D13="","",(D13/$O$23)) | E36: =IF(E13="","",(E13/$O$23)) | F36: =IF(F13="","",(F13/$O$23)) | G36: =IF(G13="","",(G13/$O$23)) | H36: =IF(H13="","",(H13/$O$23)) | I36: =IF(I13="","",(I13/$O$23)) | ... M36: =IF(M13="","",(M13/$O$23)) | O36: =IF(O13="","",(O13/$O$23)) -> 1.4516125 | P36: =IF(P13="","",(P13/$O$23)) | Q36: =IF(Q13="","",(Q13/$O$23)) | R36: =IF(R13="","",(R13/$O$23)) | S36: =IF(S13="","",(S13/$O$23)) | T36: =IF(T13="","",(T13/$O$23)) | U36: =IF(U13="","",(U13/$O$23)) | V36: =IF(V13="","",(V13/$O$23))
B37: =IF(B14="","",(B14/$O$23)) | C37: =IF(C14="","",(C14/$O$23)) | D37: =IF(D14="","",(D14/$O$23)) | E37: =IF(E14="","",(E14/$O$23)) | F37: =IF(F14="","",(F14/$O$23)) | G37: =IF(G14="","",(G14/$O$23)) | H37: =IF(H14="","",(H14/$O$23)) | I37: =IF(I14="","",(I14/$O$23)) | ... M37: =IF(M14="","",(M14/$O$23)) | O37: =IF(O14="","",(O14/$O$23)) -> 1.3918725 | P37: =IF(P14="","",(P14/$O$23)) | Q37: =IF(Q14="","",(Q14/$O$23)) | R37: =IF(R14="","",(R14/$O$23)) | S37: =IF(S14="","",(S14/$O$23)) | T37: =IF(T14="","",(T14/$O$23)) | U37: =IF(U14="","",(U14/$O$23)) | V37: =IF(V14="","",(V14/$O$23))
B38: =IF(B15="","",(B15/$O$23)) | C38: =IF(C15="","",(C15/$O$23)) | D38: =IF(D15="","",(D15/$O$23)) | E38: =IF(E15="","",(E15/$O$23)) | F38: =IF(F15="","",(F15/$O$23)) | G38: =IF(G15="","",(G15/$O$23)) | H38: =IF(H15="","",(H15/$O$23)) | I38: =IF(I15="","",(I15/$O$23)) | ... M38: =IF(M15="","",(M15/$O$23)) | O38: =IF(O15="","",(O15/$O$23)) -> 1.6261749 | P38: =IF(P15="","",(P15/$O$23)) | Q38: =IF(Q15="","",(Q15/$O$23)) | R38: =IF(R15="","",(R15/$O$23)) | S38: =IF(S15="","",(S15/$O$23)) | T38: =IF(T15="","",(T15/$O$23)) | U38: =IF(U15="","",(U15/$O$23)) | V38: =IF(V15="","",(V15/$O$23))
B39: =IF(B16="","",(B16/$O$23)) | C39: =IF(C16="","",(C16/$O$23)) | D39: =IF(D16="","",(D16/$O$23)) | E39: =IF(E16="","",(E16/$O$23)) | F39: =IF(F16="","",(F16/$O$23)) | G39: =IF(G16="","",(G16/$O$23)) | H39: =IF(H16="","",(H16/$O$23)) | I39: =IF(I16="","",(I16/$O$23)) | ... M39: =IF(M16="","",(M16/$O$23)) | O39: =IF(O16="","",(O16/$O$23)) -> 0.0091958507 | P39: =IF(P16="","",(P16/$O$23)) | Q39: =IF(Q16="","",(Q16/$O$23)) | R39: =IF(R16="","",(R16/$O$23)) | S39: =IF(S16="","",(S16/$O$23)) | T39: =IF(T16="","",(T16/$O$23)) | U39: =IF(U16="","",(U16/$O$23)) | V39: =IF(V16="","",(V16/$O$23))
B40: =IF(B17="","",(B17/$O$23)) | C40: =IF(C17="","",(C17/$O$23)) | D40: =IF(D17="","",(D17/$O$23)) | E40: =IF(E17="","",(E17/$O$23)) | F40: =IF(F17="","",(F17/$O$23)) | G40: =IF(G17="","",(G17/$O$23)) | H40: =IF(H17="","",(H17/$O$23)) | I40: =IF(I17="","",(I17/$O$23)) | ... M40: =IF(M17="","",(M17/$O$23)) | O40: =IF(O17="","",(O17/$O$23)) -> 0.76892767 | P40: =IF(P17="","",(P17/$O$23)) | Q40: =IF(Q17="","",(Q17/$O$23)) | R40: =IF(R17="","",(R17/$O$23)) | S40: =IF(S17="","",(S17/$O$23)) | T40: =IF(T17="","",(T17/$O$23)) | U40: =IF(U17="","",(U17/$O$23)) | V40: =IF(V17="","",(V17/$O$23))
... B43: =IF(B20="","",(B20/$O$23)) | C43: =IF(C20="","",(C20/$O$23)) | D43: =IF(D20="","",(D20/$O$23)) | E43: =IF(E20="","",(E20/$O$23)) | F43: =IF(F20="","",(F20/$O$23)) | G43: =IF(G20="","",(G20/$O$23)) | H43: =IF(H20="","",(H20/$O$23)) | I43: =IF(I20="","",(I20/$O$23)) | ... M43: =IF(M20="","",(M20/$O$23)) | O43: =IF(O20="","",(O20/$O$23)) -> 0.13834549 | P43: =IF(P20="","",(P20/$O$23)) | Q43: =IF(Q20="","",(Q20/$O$23)) | R43: =IF(R20="","",(R20/$O$23)) | S43: =IF(S20="","",(S20/$O$23)) | T43: =IF(T20="","",(T20/$O$23)) | U43: =IF(U20="","",(U20/$O$23)) | V43: =IF(V20="","",(V20/$O$23))
A45: =A4 -> Group names | B45: =B4 -> Solvent control | C45: =C4 -> EE2-33.8ng/L | D45: =D4 -> EE2-50.6ng/L | E45: =E4 -> EE2-76ng/L | F45: =F4 -> EE2-114ng/L | G45: =G4 -> EE2-170.9ng/L | H45: =H4 -> EE2-488ng/L | ... M45: =M4 -> BPA-5mg/L | O45: =O4 -> Testo -30µg/L | P45: =P4 -> Testo 30µg/L + EE2 -64ng/L | Q45: =Q4 -> Testo 30µg/L + FAD-10mg/L | R45: =R4 -> BPA-1mg/L + Testostérone | S45: =S4 -> BPA-2mg/L + Testostérone | T45: =T4 -> BPA-3mg/L + Testostérone | U45: =U4 -> BPA-4mg/L + Testostérone | V45: =V4 -> BPA-5mg/L + Testostérone
A46: mean | B46: =AVERAGE(B28:B43) -> 0.08341524 | C46: =AVERAGE(C28:C43) -> 0.23008643 | D46: =AVERAGE(D28:D43) -> 0.86975799 | E46: =AVERAGE(E28:E43) -> 2.0796013 | F46: =AVERAGE(F28:F43) -> 3.6909031 | G46: =AVERAGE(G28:G43) -> 4.4188737 | H46: =AVERAGE(H28:H43) -> 6.3993437 | I46: =AVERAGE(I28:I43) -> 0.1355999 | ... M46: =AVERAGE(M28:M43) -> 1.4261547 | N46: mean | O46: =AVERAGE(O28:O43) -> 1 | P46: =AVERAGE(P28:P43) -> 4.4695924 | Q46: =AVERAGE(Q28:Q43) -> 0.11531744 | R46: =AVERAGE(R28:R43) -> 1.2126503 | S46: =AVERAGE(S28:S43) -> 2.0616219 | T46: =AVERAGE(T28:T43) -> 4.4079824 | U46: =AVERAGE(U28:U43) -> 4.6104236 | V46: =AVERAGE(V28:V43) -> 5.7954914
A47: SD | B47: =STDEV(B28:B43) -> 0.054055648 | C47: =STDEV(C28:C43) -> 0.28883378 | D47: =STDEV(D28:D43) -> 0.57482094 | E47: =STDEV(E28:E43) -> 1.1820859 | F47: =STDEV(F28:F43) -> 1.8505791 | G47: =STDEV(G28:G43) -> 1.262632 | H47: =STDEV(H28:H43) -> 2.0671208 | I47: =STDEV(I28:I43) -> 0.09086101 | ... M47: =STDEV(M28:M43) -> 0.96354754 | N47: SD | O47: =STDEV(O28:O43) -> 0.87749533 | P47: =STDEV(P28:P43) -> 2.000471 | Q47: =STDEV(Q28:Q43) -> 0.092780437 | R47: =STDEV(R28:R43) -> 0.86975672 | S47: =STDEV(S28:S43) -> 0.9404444 | T47: =STDEV(T28:T43) -> 2.0480616 | U47: =STDEV(U28:U43) -> 0.95479569 | V47: =STDEV(V28:V43) -> 2.376686
...

Sheet R3
A3: R3 | B3: Unspiked | O3: Testosterone spiked
A4: Group names | B4: ='Front page'!A7 -> Solvent control | C4: ='Front page'!A8 -> EE2-33.8ng/L | D4: ='Front page'!A9 -> EE2-50.6ng/L | E4: ='Front page'!A10 -> EE2-76ng/L | F4: ='Front page'!A11 -> EE2-114ng/L | G4: ='Front page'!A12 -> EE2-170.9ng/L | H4: ='Front page'!A13 -> EE2-488ng/L | I4: ='Front page'!A14 -> BPA-1mg/L | J4: ='Front page'!A15 -> BPA-2mg/L | K4: ='Front page'!A16 -> BPA-3mg/L | L4: ='Front page'!A17 -> BPA-4mg/L | M4: ='Front page'!A18 -> BPA-5mg/L | O4: ='Front page'!A35 -> Testo -30µg/L | P4: ='Front page'!A36 -> Testo 30µg/L + EE2 -64ng/L | Q4: ='Front page'!A37 -> Testo 30µg/L + FAD-10mg/L | R4: ='Front page'!A38 -> BPA-1mg/L + Testostérone | S4: ='Front page'!A39 -> BPA-2mg/L + Testostérone | T4: ='Front page'!A40 -> BPA-3mg/L + Testostérone | U4: ='Front page'!A41 -> BPA-4mg/L + Testostérone | V4: ='Front page'!A42 -> BPA-5mg/L + Testostérone
A5: Raw data | B5: 6911 | C5: 1648968 | D5: 445753 | E5: 5489152 | F5: 2827971 | G5: 4484880 | H5: 10694984 | I5: 128236 | J5: 86855 | K5: 327970 | L5: 257519 | M5: 5101983 | O5: 218391 | P5: 6590587 | Q5: 39988 | R5: 3998668 | S5: 4690088 | T5: 5361478 | U5: 6085711 | V5: 10627363
B6: 216594 | C6: 152137 | D6: 394912 | E6: 1364361 | F6: 3963432 | G6: 2022658 | H6: 9111769 | I6: 331674 | J6: 180000 | K6: 56716 | L6: 3479593 | M6: 4428339 | O6: 442182 | P6: 4992626 | Q6: 230269 | R6: 56335 | S6: 2390864 | T6: 4758370 | U6: 10555207 | V6: 7468181
B7: 406433 | C7: 260080 | D7: 2549385 | E7: 1375051 | F7: 6136127 | G7: 7239706 | H7: 8838133 | I7: 73917 | J7: 436004 | K7: 162338 | L7: 1780542 | M7: 1817260 | O7: 77842 | P7: 8264893 | Q7: 93765 | R7: 2190803 | S7: 3743230 | T7: 2761463 | U7: 4829283 | V7: 11339443
B8: 132138 | C8: 643147 | D8: 768008 | E8: 3105217 | F8: 6144825 | G8: 3428228 | H8: 7245433 | I8: 124630 | J8: 349787 | K8: 1073116 | L8: 454414 | M8: 2131036 | O8: 571078 | P8: 6090137 | Q8: 89197 | R8: 2908825 | S8: 3088549 | T8: 7366806 | U8: 6645220 | V8: 8794090
B9: 296339 | C9: 676651 | D9: 888575 | E9: 813487 | F9: 7017350 | G9: 1938409 | H9: 10500559 | I9: 82772 | J9: 811095 | K9: 173432 | L9: 187059 | M9: 1428169 | O9: 1485296 | P9: 4215322 | Q9: 336938 | R9: 2201276 | S9: 4877423 | T9: 5123669 | U9: 5773419 | V9: 7906172
B10: 37232 | C10: 224754 | D10: 1573807 | E10: 1154569 | F10: 2747901 | G10: 3895996 | H10: 4556952 | I10: 284475 | J10: 102173 | K10: 476976 | L10: 136486 | M10: 1217189 | O10: 553501 | P10: 2969960 | Q10: 66862 | R10: 3415238 | S10: 2254863 | T10: 2638681 | U10: 10482282 | V10: 4019764
B11: 148051 | C11: 309128 | D11: 2390513 | E11: 3504058 | F11: 5641961 | G11: 4625800 | H11: 7084399 | I11: 168423 | J11: 271209 | K11: 67930 | L11: 252776 | M11: 2649532 | O11: 309432 | P11: 5311357 | Q11: 10368 | R11: 5547527 | S11: 5227086 | T11: 3570985 | U11: 9791627 | V11: 7138129
B12: 177380 | C12: 177232 | E12: 2005353 | F12: 6816634 | G12: 6420797 | K12: 12408 | M12: 440929 | O12: 112509 | P12: 6219389 | Q12: 346761 | R12: 3347550 | S12: 3784047 | U12: 4913180 | V12: 4507671
O13: 6590587 | P13: 7377760
O14: 4992626
O15: 8264893
O16: 6090137
O17: 4215322
O18: 2969960
O19: 5311357
O20: 6219389
A22: =A4 -> Group names | B22: =B4 -> Solvent control | C22: =C4 -> EE2-33.8ng/L | D22: =D4 -> EE2-50.6ng/L | E22: =E4 -> EE2-76ng/L | F22: =F4 -> EE2-114ng/L | G22: =G4 -> EE2-170.9ng/L | H22: =H4 -> EE2-488ng/L | ... M22: =M4 -> BPA-5mg/L | N22: Noms des groupes | O22: =O4 -> Testo -30µg/L | P22: =P4 -> Testo 30µg/L + EE2 -64ng/L | Q22: =Q4 -> Testo 30µg/L + FAD-10mg/L | R22: =R4 -> BPA-1mg/L + Testostérone | S22: =S4 -> BPA-2mg/L + Testostérone | T22: =T4 -> BPA-3mg/L + Testostérone | U22: =U4 -> BPA-4mg/L + Testostérone | V22: =V4 -> BPA-5mg/L + Testostérone
A23: mean | B23: =AVERAGE(B5:B20) -> 177634.75 | C23: =AVERAGE(C5:C20) -> 511512.12 | D23: =AVERAGE(D5:D20) -> 1287279 | E23: =AVERAGE(E5:E20) -> 2351406 | F23: =AVERAGE(F5:F20) -> 5162025.1 | G23: =AVERAGE(G5:G20) -> 4257059.2 | H23: =AVERAGE(H5:H20) -> 8290318.4 | I23: =AVERAGE(I5:I20) -> 170589.57 | J23: =AVERAGE(J5:J20) -> 319589 | L23: =AVERAGE(L5:L20) -> 935484.14 | N23: mean | O23: =AVERAGE(O5:O20) -> 3026531.4 | P23: =AVERAGE(P5:P20) -> 5781336.8 | Q23: =AVERAGE(Q5:Q20) -> 151768.5 | R23: =AVERAGE(R5:R20) -> 2958277.8 | S23: =AVERAGE(S5:S20) -> 3757018.8 | T23: =AVERAGE(T5:T20) -> 4511636 | U23: =AVERAGE(U5:U20) -> 7384491.1 | V23: =AVERAGE(V5:V20) -> 7725101.6
A24: SD | B24: =STDEV(B5:B20) -> 130800.78 | C24: =STDEV(C5:C20) -> 502238.68 | D24: =STDEV(D5:D20) -> 896774.52 | E24: =STDEV(E5:E20) -> 1585072.4 | F24: =STDEV(F5:F20) -> 1733596.5 | G24: =STDEV(G5:G20) -> 1888000.9 | H24: =STDEV(H5:H20) -> 2165121.8 | I24: =STDEV(I5:I20) -> 99905.286 | J24: =STDEV(J5:J20) -> 251430.26 | L24: =STDEV(L5:L20) -> 1261104.4 | N24: SD | O24: =STDEV(O5:O20) -> 2873781.5 | P24: =STDEV(P5:P20) -> 1614695.8 | Q24: =STDEV(Q5:Q20) -> 133870.86 | R24: =STDEV(R5:R20) -> 1591618.9 | S24: =STDEV(S5:S20) -> 1124890.1 | T24: =STDEV(T5:T20) -> 1671605 | U24: =STDEV(U5:U20) -> 2475867 | V24: =STDEV(V5:V20) -> 2595436.6
B26: Unspiked | O26: Testosterone spiked
A27: =A4 -> Group names | B27: =B4 -> Solvent control | C27: =C4 -> EE2-33.8ng/L | D27: =D4 -> EE2-50.6ng/L | E27: =E4 -> EE2-76ng/L | F27: =F4 -> EE2-114ng/L | G27: =G4 -> EE2-170.9ng/L | H27: =H4 -> EE2-488ng/L | ... M27: =M4 -> BPA-5mg/L | O27: =O4 -> Testo -30µg/L | P27: =P4 -> Testo 30µg/L + EE2 -64ng/L | Q27: =Q4 -> Testo 30µg/L + FAD-10mg/L | R27: =R4 -> BPA-1mg/L + Testostérone | S27: =S4 -> BPA-2mg/L + Testostérone | T27: =T4 -> BPA-3mg/L + Testostérone | U27: =U4 -> BPA-4mg/L + Testostérone | V27: =V4 -> BPA-5mg/L + Testostérone
A28: Data normalised to the "Testo" group | B28: =IF(B5="","",(B5/$O$23)) -> 0.0022834721 | C28: =IF(C5="","",(C5/$O$23)) -> 0.54483757 | D28: =IF(D5="","",(D5/$O$23)) -> 0.1472818 | E28: =IF(E5="","",(E5/$O$23)) -> 1.8136775 | F28: =IF(F5="","",(F5/$O$23)) -> 0.93439342 | G28: =IF(G5="","",(G5/$O$23)) -> 1.4818548 | H28: =IF(H5="","",(H5/$O$23)) -> 3.533743 | I28: =IF(I5="","",(I5/$O$23)) -> 0.042370616 | ... M28: =IF(M5="","",(M5/$O$23)) -> 1.6857526 | O28: =IF(O5="","",(O5/$O$23)) -> 0.072158842 | P28: =IF(P5="","",(P5/$O$23)) -> 2.1776041 | Q28: =IF(Q5="","",(Q5/$O$23)) -> 0.013212485 | R28: =IF(R5="","",(R5/$O$23)) -> 1.3212049 | S28: =IF(S5="","",(S5/$O$23)) -> 1.5496578 | T28: =IF(T5="","",(T5/$O$23)) -> 1.7714926 | U28: =IF(U5="","",(U5/$O$23)) -> 2.0107873 | V28: =IF(V5="","",(V5/$O$23)) -> 3.5114002
