Workbook

Sheet Front page
A2: R1 | B2: Experiment number : | E2: Date performed :
A3: R2 | B3: Experiment number : | E3: Date performed :
A4: R3 | B4: Experiment number : | E4: Date performed :
A6: Do not fill in | B6: Do not fill in2 | C6: Concentration | D6: Units | E6: Chemical name | F6: Do not fill in3
A7: =IF(ISBLANK(liste_groupe[[#This Row],[Do not fill in2]])," ",IF(ISBLANK(liste_groupe[[#This Row],[Units]]),CONCATENATE(liste_groupe[[#This Row],[Chemical name]],liste_groupe[[#This Row],[Do not fill in3]]),CONCATENATE(liste_groupe[[#This Row],[Chemical name]],"-",liste_groupe[[#This Row],[Concentration]],liste_groupe[[#This Row],[Units]],liste_groupe[[#This Row],[Do not fill in3]]))) -> Solvent control | B7: Control | E7: Solvent control
A8: =IF(ISBLANK(liste_groupe[[#This Row],[Do not fill in2]])," ",IF(ISBLANK(liste_groupe[[#This Row],[Units]]),CONCATENATE(liste_groupe[[#This Row],[Chemical name]],liste_groupe[[#This Row],[Do not fill in3]]),CONCATENATE(liste_groupe[[#This Row],[Chemical name]],"-",liste_groupe[[#This Row],[Concentration]],liste_groupe[[#This Row],[Units]],liste_groupe[[#This Row],[Do not fill in3]]))) -> EE2-33.8ng/L | B8: Control | C8: 33.8 | D8: ng/L | E8: EE2
A9: =IF(ISBLANK(liste_groupe[[#This Row],[Do not fill in2]])," ",IF(ISBLANK(liste_groupe[[#This Row],[Units]]),CONCATENATE(liste_groupe[[#This Row],[Chemical name]],liste_groupe[[#This Row],[Do not fill in3]]),CONCATENATE(liste_groupe[[#This Row],[Chemical name]],"-",liste_groupe[[#This Row],[Concentration]],liste_groupe[[#This Row],[Units]],liste_groupe[[#This Row],[Do not fill in3]]))) -> EE2-50.6ng/L | B9: Control | C9: 50.6 | D9: ng/L | E9: EE2
A10: =IF(ISBLANK(liste_groupe[[#This Row],[Do not fill in2]])," ",IF(ISBLANK(liste_groupe[[#This Row],[Units]]),CONCATENATE(liste_groupe[[#This Row],[Chemical name]],liste_groupe[[#This Row],[Do not fill in3]]),CONCATENATE(liste_groupe[[#This Row],[Chemical name]],"-",liste_groupe[[#This Row],[Concentration]],liste_groupe[[#This Row],[Units]],liste_groupe[[#This Row],[Do not fill in3]]))) -> EE2-76ng/L | B10: Control | C10: 76 | D10: ng/L | E10: EE2
A11: =IF(ISBLANK(liste_groupe[[#This Row],[Do not fill in2]])," ",IF(ISBLANK(liste_groupe[[#This Row],[Units]]),CONCATENATE(liste_groupe[[#This Row],[Chemical name]],liste_groupe[[#This Row],[Do not fill in3]]),CONCATENATE(liste_groupe[[#This Row],[Chemical name]],"-",liste_groupe[[#This Row],[Concentration]],liste_groupe[[#This Row],[Units]],liste_groupe[[#This Row],[Do not fill in3]]))) -> EE2-114ng/L | B11: Control | C11: 114 | D11: ng/L | E11: EE2
A12: =IF(ISBLANK(liste_groupe[[#This Row],[Do not fill in2]])," ",IF(ISBLANK(liste_groupe[[#This Row],[Units]]),CONCATENATE(liste_groupe[[#This Row],[Chemical name]],liste_groupe[[#This Row],[Do not fill in3]]),CONCATENATE(liste_groupe[[#This Row],[Chemical name]],"-",liste_groupe[[#This Row],[Concentration]],liste_groupe[[#This Row],[Units]],liste_groupe[[#This Row],[Do not fill in3]]))) -> EE2-170.9ng/L | B12: Control | C12: 170.9 | D12: ng/L | E12: EE2
A13: =IF(ISBLANK(liste_groupe[[#This Row],[Do not fill in2]])," ",IF(ISBLANK(liste_groupe[[#This Row],[Units]]),CONCATENATE(liste_groupe[[#This Row],[Chemical name]],liste_groupe[[#This Row],[Do not fill in3]]),CONCATENATE(liste_groupe[[#This Row],[Chemical name]],"-",liste_groupe[[#This Row],[Concentration]],liste_groupe[[#This Row],[Units]],liste_groupe[[#This Row],[Do not fill in3]]))) -> EE2-488ng/L | B13: Control | C13: 488 | D13: ng/L | E13: EE2
A14: =IF(ISBLANK(liste_groupe[[#This Row],[Do not fill in2]])," ",IF(ISBLANK(liste_groupe[[#This Row],[Units]]),CONCATENATE(liste_groupe[[#This Row],[Chemical name]],liste_groupe[[#This Row],[Do not fill in3]]),CONCATENATE(liste_groupe[[#This Row],[Chemical name]],"-",liste_groupe[[#This Row],[Concentration]],liste_groupe[[#This Row],[Units]],liste_groupe[[#This Row],[Do not fill in3]]))) | B14: test chemical
A15: =IF(ISBLANK(liste_groupe[[#This Row],[Do not fill in2]])," ",IF(ISBLANK(liste_groupe[[#This Row],[Units]]),CONCATENATE(liste_groupe[[#This Row],[Chemical name]],liste_groupe[[#This Row],[Do not fill in3]]),CONCATENATE(liste_groupe[[#This Row],[Chemical name]],"-",liste_groupe[[#This Row],[Concentration]],liste_groupe[[#This Row],[Units]],liste_groupe[[#This Row],[Do not fill in3]]))) | B15: test chemical
A16: =IF(ISBLANK(liste_groupe[[#This Row],[Do not fill in2]])," ",IF(ISBLANK(liste_groupe[[#This Row],[Units]]),CONCATENATE(liste_groupe[[#This Row],[Chemical name]],liste_groupe[[#This Row],[Do not fill in3]]),CONCATENATE(liste_groupe[[#This Row],[Chemical name]],"-",liste_groupe[[#This Row],[Concentration]],liste_groupe[[#This Row],[Units]],liste_groupe[[#This Row],[Do not fill in3]]))) | B16: test chemical
A17: =IF(ISBLANK(liste_groupe[[#This Row],[Do not fill in2]])," ",IF(ISBLANK(liste_groupe[[#This Row],[Units]]),CONCATENATE(liste_groupe[[#This Row],[Chemical name]],liste_groupe[[#This Row],[Do not fill in3]]),CONCATENATE(liste_groupe[[#This Row],[Chemical name]],"-",liste_groupe[[#This Row],[Concentration]],liste_groupe[[#This Row],[Units]],liste_groupe[[#This Row],[Do not fill in3]]))) | B17: test chemical
A18: =IF(ISBLANK(liste_groupe[[#This Row],[Do not fill in2]])," ",IF(ISBLANK(liste_groupe[[#This Row],[Units]]),CONCATENATE(liste_groupe[[#This Row],[Chemical name]],liste_groupe[[#This Row],[Do not fill in3]]),CONCATENATE(liste_groupe[[#This Row],[Chemical name]],"-",liste_groupe[[#This Row],[Concentration]],liste_groupe[[#This Row],[Units]],liste_groupe[[#This Row],[Do not fill in3]]))) | B18: test chemical
A19: =IF(ISBLANK(liste_groupe[[#This Row],[Do not fill in2]])," ",IF(ISBLANK(liste_groupe[[#This Row],[Units]]),CONCATENATE(liste_groupe[[#This Row],[Chemical name]],liste_groupe[[#This Row],[Do not fill in3]]),CONCATENATE(liste_groupe[[#This Row],[Chemical name]],"-",liste_groupe[[#This Row],[Concentration]],liste_groupe[[#This Row],[Units]],liste_groupe[[#This Row],[Do not fill in3]]))) | B19: test chemical
A20: =IF(ISBLANK(liste_groupe[[#This Row],[Do not fill in2]])," ",IF(ISBLANK(liste_groupe[[#This Row],[Units]]),CONCATENATE(liste_groupe[[#This Row],[Chemical name]],liste_groupe[[#This Row],[Do not fill in3]]),CONCATENATE(liste_groupe[[#This Row],[Chemical name]],"-",liste_groupe[[#This Row],[Concentration]],liste_groupe[[#This Row],[Units]],liste_groupe[[#This Row],[Do not fill in3]]))) | B20: test chemical
A21: =IF(ISBLANK(liste_groupe[[#This Row],[Do not fill in2]])," ",IF(ISBLANK(liste_groupe[[#This Row],[Units]]),CONCATENATE(liste_groupe[[#This Row],[Chemical name]],liste_groupe[[#This Row],[Do not fill in3]]),CONCATENATE(liste_groupe[[#This Row],[Chemical name]],"-",liste_groupe[[#This Row],[Concentration]],liste_groupe[[#This Row],[Units]],liste_groupe[[#This Row],[Do not fill in3]]))) | B21: test chemical
A22: =IF(ISBLANK(liste_groupe[[#This Row],[Do not fill in2]])," ",IF(ISBLANK(liste_groupe[[#This Row],[Units]]),CONCATENATE(liste_groupe[[#This Row],[Chemical name]],liste_groupe[[#This Row],[Do not fill in3]]),CONCATENATE(liste_groupe[[#This Row],[Chemical name]],"-",liste_groupe[[#This Row],[Concentration]],liste_groupe[[#This Row],[Units]],liste_groupe[[#This Row],[Do not fill in3]]))) | B22: test chemical
A23: =IF(ISBLANK(liste_groupe[[#This Row],[Do not fill in2]])," ",IF(ISBLANK(liste_groupe[[#This Row],[Units]]),CONCATENATE(liste_groupe[[#This Row],[Chemical name]],liste_groupe[[#This Row],[Do not fill in3]]),CONCATENATE(liste_groupe[[#This Row],[Chemical name]],"-",liste_groupe[[#This Row],[Concentration]],liste_groupe[[#This Row],[Units]],liste_groupe[[#This Row],[Do not fill in3]]))) | B23: test chemical
A24: =IF(ISBLANK(liste_groupe[[#This Row],[Do not fill in2]])," ",IF(ISBLANK(liste_groupe[[#This Row],[Units]]),CONCATENATE(liste_groupe[[#This Row],[Chemical name]],liste_groupe[[#This Row],[Do not fill in3]]),CONCATENATE(liste_groupe[[#This Row],[Chemical name]],"-",liste_groupe[[#This Row],[Concentration]],liste_groupe[[#This Row],[Units]],liste_groupe[[#This Row],[Do not fill in3]]))) | B24: test chemical
A25: =IF(ISBLANK(liste_groupe[[#This Row],[Do not fill in2]])," ",IF(ISBLANK(liste_groupe[[#This Row],[Units]]),CONCATENATE(liste_groupe[[#This Row],[Chemical name]],liste_groupe[[#This Row],[Do not fill in3]]),CONCATENATE(liste_groupe[[#This Row],[Chemical name]],"-",liste_groupe[[#This Row],[Concentration]],liste_groupe[[#This Row],[Units]],liste_groupe[[#This Row],[Do not fill in3]]))) | B25: test chemical
... A34: =IF(ISBLANK(liste_groupe[[#This Row],[Do not fill in2]])," ",IF(ISBLANK(liste_groupe[[#This Row],[Units]]),CONCATENATE(liste_groupe[[#This Row],[Chemical name]],liste_groupe[[#This Row],[Do not fill in3]]),CONCATENATE(liste_groupe[[#This Row],[Chemical name]],"-",liste_groupe[[#This Row],[Concentration]],liste_groupe[[#This Row],[Units]],liste_groupe[[#This Row],[Do not fill in3]]))) | B34: test chemical
A35: =IF(ISBLANK(liste_groupe[[#This Row],[Do not fill in2]])," ",IF(ISBLANK(liste_groupe[[#This Row],[Units]]),CONCATENATE(liste_groupe[[#This Row],[Chemical name]],liste_groupe[[#This Row],[Do not fill in3]]),CONCATENATE(liste_groupe[[#This Row],[Chemical name]],"-",liste_groupe[[#This Row],[Concentration]],liste_groupe[[#This Row],[Units]],liste_groupe[[#This Row],[Do not fill in3]]))) -> Testo -30µg/L | B35: Control | C35: 30 | D35: µg/L | E35: Testo
A36: =IF(ISBLANK(liste_groupe[[#This Row],[Do not fill in2]])," ",IF(ISBLANK(liste_groupe[[#This Row],[Units]]),CONCATENATE(liste_groupe[[#This Row],[Chemical name]],liste_groupe[[#This Row],[Do not fill in3]]),CONCATENATE(liste_groupe[[#This Row],[Chemical name]],"-",liste_groupe[[#This Row],[Concentration]],liste_groupe[[#This Row],[Units]],liste_groupe[[#This Row],[Do not fill in3]]))) -> Testo 30µg/L + EE2 -64ng/L | B36: Control | C36: 64 | D36: ng/L | E36: Testo 30µg/L + EE2
A37: =IF(ISBLANK(liste_groupe[[#This Row],[Do not fill in2]])," ",IF(ISBLANK(liste_groupe[[#This Row],[Units]]),CONCATENATE(liste_groupe[[#This Row],[Chemical name]],liste_groupe[[#This Row],[Do not fill in3]]),CONCATENATE(liste_groupe[[#This Row],[Chemical name]],"-",liste_groupe[[#This Row],[Concentration]],liste_groupe[[#This Row],[Units]],liste_groupe[[#This Row],[Do not fill in3]]))) -> Testo 30µg/L + FAD-10mg/L | B37: Control | C37: 10 | D37: mg/L | E37: Testo 30µg/L + FAD
A38: =IF(ISBLANK(liste_groupe[[#This Row],[Do not fill in2]])," ",IF(ISBLANK(liste_groupe[[#This Row],[Units]]),CONCATENATE(liste_groupe[[#This Row],[Chemical name]],liste_groupe[[#This Row],[Do not fill in3]]),CONCATENATE(liste_groupe[[#This Row],[Chemical name]],"-",liste_groupe[[#This Row],[Concentration]],liste_groupe[[#This Row],[Units]],liste_groupe[[#This Row],[Do not fill in3]]))) -> 0-00 + Testostérone | B38: =B14 -> test chemical | C38: =C14 -> 0 | D38: =D14 -> 0 | E38: =E14 -> 0 | F38: + Testostérone
A39: =IF(ISBLANK(liste_groupe[[#This Row],[Do not fill in2]])," ",IF(ISBLANK(liste_groupe[[#This Row],[Units]]),CONCATENATE(liste_groupe[[#This Row],[Chemical name]],liste_groupe[[#This Row],[Do not fill in3]]),CONCATENATE(liste_groupe[[#This Row],[Chemical name]],"-",liste_groupe[[#This Row],[Concentration]],liste_groupe[[#This Row],[Units]],liste_groupe[[#This Row],[Do not fill in3]]))) -> 0-00 + Testostérone | B39: =B15 -> test chemical | C39: =C15 -> 0 | D39: =D15 -> 0 | E39: =E15 -> 0 | F39: + Testostérone
A40: =IF(ISBLANK(liste_groupe[[#This Row],[Do not fill in2]])," ",IF(ISBLANK(liste_groupe[[#This Row],[Units]]),CONCATENATE(liste_groupe[[#This Row],[Chemical name]],liste_groupe[[#This Row],[Do not fill in3]]),CONCATENATE(liste_groupe[[#This Row],[Chemical name]],"-",liste_groupe[[#This Row],[Concentration]],liste_groupe[[#This Row],[Units]],liste_groupe[[#This Row],[Do not fill in3]]))) -> 0-00 + Testostérone | B40: =B16 -> test chemical | C40: =C16 -> 0 | D40: =D16 -> 0 | E40: =E16 -> 0 | F40: + Testostérone
A41: =IF(ISBLANK(liste_groupe[[#This Row],[Do not fill in2]])," ",IF(ISBLANK(liste_groupe[[#This Row],[Units]]),CONCATENATE(liste_groupe[[#This Row],[Chemical name]],liste_groupe[[#This Row],[Do not fill in3]]),CONCATENATE(liste_groupe[[#This Row],[Chemical name]],"-",liste_groupe[[#This Row],[Concentration]],liste_groupe[[#This Row],[Units]],liste_groupe[[#This Row],[Do not fill in3]]))) -> 0-00 + Testostérone | B41: =B17 -> test chemical | C41: =C17 -> 0 | D41: =D17 -> 0 | E41: =E17 -> 0 | F41: + Testostérone
A42: =IF(ISBLANK(liste_groupe[[#This Row],[Do not fill in2]])," ",IF(ISBLANK(liste_groupe[[#This Row],[Units]]),CONCATENATE(liste_groupe[[#This Row],[Chemical name]],liste_groupe[[#This Row],[Do not fill in3]]),CONCATENATE(liste_groupe[[#This Row],[Chemical name]],"-",liste_groupe[[#This Row],[Concentration]],liste_groupe[[#This Row],[Units]],liste_groupe[[#This Row],[Do not fill in3]]))) -> 0-00 + Testostérone | B42: =B18 -> test chemical | C42: =C18 -> 0 | D42: =D18 -> 0 | E42: =E18 -> 0 | F42: + Testostérone
A43: =IF(ISBLANK(liste_groupe[[#This Row],[Do not fill in2]])," ",IF(ISBLANK(liste_groupe[[#This Row],[Units]]),CONCATENATE(liste_groupe[[#This Row],[Chemical name]],liste_groupe[[#This Row],[Do not fill in3]]),CONCATENATE(liste_groupe[[#This Row],[Chemical name]],"-",liste_groupe[[#This Row],[Concentration]],liste_groupe[[#This Row],[Units]],liste_groupe[[#This Row],[Do not fill in3]]))) -> 0-00 + Testostérone | B43: =B19 -> test chemical | C43: =C19 -> 0 | D43: =D19 -> 0 | E43: =E19 -> 0 | F43: + Testostérone
A44: =IF(ISBLANK(liste_groupe[[#This Row],[Do not fill in2]])," ",IF(ISBLANK(liste_groupe[[#This Row],[Units]]),CONCATENATE(liste_groupe[[#This Row],[Chemical name]],liste_groupe[[#This Row],[Do not fill in3]]),CONCATENATE(liste_groupe[[#This Row],[Chemical name]],"-",liste_groupe[[#This Row],[Concentration]],liste_groupe[[#This Row],[Units]],liste_groupe[[#This Row],[Do not fill in3]]))) -> 0-00 + Testostérone | B44: =B20 -> test chemical | C44: =C20 -> 0 | D44: =D20 -> 0 | E44: =E20 -> 0 | F44: + Testostérone
A45: =IF(ISBLANK(liste_groupe[[#This Row],[Do not fill in2]])," ",IF(ISBLANK(liste_groupe[[#This Row],[Units]]),CONCATENATE(liste_groupe[[#This Row],[Chemical name]],liste_groupe[[#This Row],[Do not fill in3]]),CONCATENATE(liste_groupe[[#This Row],[Chemical name]],"-",liste_groupe[[#This Row],[Concentration]],liste_groupe[[#This Row],[Units]],liste_groupe[[#This Row],[Do not fill in3]]))) -> 0-00 + Testostérone | B45: =B21 -> test chemical | C45: =C21 -> 0 | D45: =D21 -> 0 | E45: =E21 -> 0 | F45: + Testostérone
A46: =IF(ISBLANK(liste_groupe[[#This Row],[Do not fill in2]])," ",IF(ISBLANK(liste_groupe[[#This Row],[Units]]),CONCATENATE(liste_groupe[[#This Row],[Chemical name]],liste_groupe[[#This Row],[Do not fill in3]]),CONCATENATE(liste_groupe[[#This Row],[Chemical name]],"-",liste_groupe[[#This Row],[Concentration]],liste_groupe[[#This Row],[Units]],liste_groupe[[#This Row],[Do not fill in3]]))) -> 0-00 + Testostérone | B46: =B22 -> test chemical | C46: =C22 -> 0 | D46: =D22 -> 0 | E46: =E22 -> 0 | F46: + Testostérone
A47: =IF(ISBLANK(liste_groupe[[#This Row],[Do not fill in2]])," ",IF(ISBLANK(liste_groupe[[#This Row],[Units]]),CONCATENATE(liste_groupe[[#This Row],[Chemical name]],liste_groupe[[#This Row],[Do not fill in3]]),CONCATENATE(liste_groupe[[#This Row],[Chemical name]],"-",liste_groupe[[#This Row],[Concentration]],liste_groupe[[#This Row],[Units]],liste_groupe[[#This Row],[Do not fill in3]]))) -> 0-00 + Testostérone | B47: =B23 -> test chemical | C47: =C23 -> 0 | D47: =D23 -> 0 | E47: =E23 -> 0 | F47: + Testostérone
A48: =IF(ISBLANK(liste_groupe[[#This Row],[Do not fill in2]])," ",IF(ISBLANK(liste_groupe[[#This Row],[Units]]),CONCATENATE(liste_groupe[[#This Row],[Chemical name]],liste_groupe[[#This Row],[Do not fill in3]]),CONCATENATE(liste_groupe[[#This Row],[Chemical name]],"-",liste_groupe[[#This Row],[Concentration]],liste_groupe[[#This Row],[Units]],liste_groupe[[#This Row],[Do not fill in3]]))) -> 0-00 + Testostérone | B48: =B24 -> test chemical | C48: =C24 -> 0 | D48: =D24 -> 0 | E48: =E24 -> 0 | F48: + Testostérone
A49: =IF(ISBLANK(liste_groupe[[#This Row],[Do not fill in2]])," ",IF(ISBLANK(liste_groupe[[#This Row],[Units]]),CONCATENATE(liste_groupe[[#This Row],[Chemical name]],liste_groupe[[#This Row],[Do not fill in3]]),CONCATENATE(liste_groupe[[#This Row],[Chemical name]],"-",liste_groupe[[#This Row],[Concentration]],liste_groupe[[#This Row],[Units]],liste_groupe[[#This Row],[Do not fill in3]]))) -> 0-00 + Testostérone | B49: =B25 -> test chemical | C49: =C25 -> 0 | D49: =D25 -> 0 | E49: =E25 -> 0 | F49: + Testostérone
... A57: =IF(ISBLANK(liste_groupe[[#This Row],[Do not fill in2]])," ",IF(ISBLANK(liste_groupe[[#This Row],[Units]]),CONCATENATE(liste_groupe[[#This Row],[Chemical name]],liste_groupe[[#This Row],[Do not fill in3]]),CONCATENATE(liste_groupe[[#This Row],[Chemical name]],"-",liste_groupe[[#This Row],[Concentration]],liste_groupe[[#This Row],[Units]],liste_groupe[[#This Row],[Do not fill in3]]))) -> 0-00 + Testostérone | B57: =B33 -> test chemical | C57: =C33 -> 0 | D57: =D33 -> 0 | E57: =E33 -> 0 | F57: + Testostérone

Sheet R1
A3: R1 | B3: Unspiked | O3: Testosterone spiked
A4: Group names | B4: ='Front page'!A7 -> Solvent control | C4: ='Front page'!A8 -> EE2-33.8ng/L | D4: ='Front page'!A9 -> EE2-50.6ng/L | E4: ='Front page'!A10 -> EE2-76ng/L | F4: ='Front page'!A11 -> EE2-114ng/L | G4: ='Front page'!A12 -> EE2-170.9ng/L | H4: ='Front page'!A13 -> EE2-488ng/L | I4: ='Front page'!A14 | J4: ='Front page'!A15 | K4: ='Front page'!A16 | L4: ='Front page'!A17 | M4: ='Front page'!A18 | O4: ='Front page'!A35 -> Testo -30µg/L | P4: ='Front page'!A36 -> Testo 30µg/L + EE2 -64ng/L | Q4: ='Front page'!A37 -> Testo 30µg/L + FAD-10mg/L | R4: ='Front page'!A38 -> 0-00 + Testostérone | S4: ='Front page'!A39 -> 0-00 + Testostérone | T4: ='Front page'!A40 -> 0-00 + Testostérone | U4: ='Front page'!A41 -> 0-00 + Testostérone | V4: ='Front page'!A42 -> 0-00 + Testostérone
A5: Raw data | B5: 9621 | C5: 0 | D5: 220859 | E5: 1661818 | F5: 1712944 | G5: 2978520 | H5: 4759292 | O5: 25553 | P5: 2470247 | Q5: 534
B6: 80 | C6: 691325 | D6: 728223 | E6: 1659623 | F6: 907323 | G6: 3058448 | H6: 6160032 | O6: 1380826 | P6: 4260792 | Q6: 8839
B7: 14185 | C7: 139151 | D7: 61959 | E7: 751304 | F7: 1736873 | G7: 1942354 | H7: 6151823 | O7: 382790 | P7: 3583948 | Q7: 102339
B8: 3986 | C8: 10017 | D8: 105048 | E8: 932901 | F8: 1887601 | G8: 3054189 | H8: 5230018 | O8: 978105 | P8: 3049802 | Q8: 2171
B9: 88332 | C9: 199264 | D9: 483982 | E9: 1091106 | F9: 1968204 | G9: 3436693 | H9: 3351111 | O9: 3812296 | P9: 2728553 | Q9: 161
B10: 63757 | C10: 8819 | D10: 443040 | E10: 171922 | F10: 2293058 | G10: 3339876 | H10: 6349996 | O10: 806872 | P10: 2334006 | Q10: 31746
B11: 2024 | C11: 94728 | D11: 294993 | E11: 1358137 | F11: 1042513 | G11: 3544342 | H11: 5547647 | O11: 917857 | P11: 2602393 | Q11: 21607
C12: 31314 | D12: 418711 | E12: 844977 | F12: 990484 | G12: 3808794 | H12: 4542728 | O12: 1200236 | P12: 3104308 | Q12: 42282
O13: 472804
O14: 665329
O15: 1634223
O16: 605645
O17: 604155
O18: 3840707
O19: 2316143
O20: 1864971
A22: =A4 -> Group names | B22: =B4 -> Solvent control | C22: =C4 -> EE2-33.8ng/L | D22: =D4 -> EE2-50.6ng/L | E22: =E4 -> EE2-76ng/L | F22: =F4 -> EE2-114ng/L | G22: =G4 -> EE2-170.9ng/L | H22: =H4 -> EE2-488ng/L | ... M22: =M4 | N22: Nom des groupes | O22: =O4 -> Testo -30µg/L | P22: =P4 -> Testo 30µg/L + EE2 -64ng/L | Q22: =Q4 -> Testo 30µg/L + FAD-10mg/L | R22: =R4 -> 0-00 + Testostérone | S22: =S4 -> 0-00 + Testostérone | T22: =T4 -> 0-00 + Testostérone | U22: =U4 -> 0-00 + Testostérone | V22: =V4 -> 0-00 + Testostérone
A23: mean | B23: =AVERAGE(B5:B20) -> 25997.857 | C23: =AVERAGE(C5:C20) -> 146827.25 | D23: =AVERAGE(D5:D20) -> 344601.88 | E23: =AVERAGE(E5:E20) -> 1058973.5 | F23: =AVERAGE(F5:F20) -> 1567375 | G23: =AVERAGE(G5:G20) -> 3145402 | H23: =AVERAGE(H5:H20) -> 5261580.9 | I23: =AVERAGE(I5:I20) -> #DIV/0! | ... M23: =AVERAGE(M5:M20) -> #DIV/0! | N23: mean | O23: =AVERAGE(O5:O20) -> 1344282 | P23: =AVERAGE(P5:P20) -> 3016756.1 | Q23: =AVERAGE(Q5:Q20) -> 26209.875 | R23: =AVERAGE(R5:R20) -> #DIV/0! | S23: =AVERAGE(S5:S20) -> #DIV/0! | T23: =AVERAGE(T5:T20) -> #DIV/0! | U23: =AVERAGE(U5:U20) -> #DIV/0! | V23: =AVERAGE(V5:V20) -> #DIV/0!
A24: SD | B24: =STDEV(B5:B20) -> 35237.4 | C24: =STDEV(C5:C20) -> 231351.79 | D24: =STDEV(D5:D20) -> 219356.4 | E24: =STDEV(E5:E20) -> 501133.33 | F24: =STDEV(F5:F20) -> 518747.98 | G24: =STDEV(G5:G20) -> 562261.7 | H24: =STDEV(H5:H20) -> 1020235.4 | I24: =STDEV(I5:I20) -> #DIV/0! | ... M24: =STDEV(M5:M20) -> #DIV/0! | N24: SD | O24: =STDEV(O5:O20) -> 1132168.5 | P24: =STDEV(P5:P20) -> 643391.35 | Q24: =STDEV(Q5:Q20) -> 34482.296 | R24: =STDEV(R5:R20) -> #DIV/0! | S24: =STDEV(S5:S20) -> #DIV/0! | T24: =STDEV(T5:T20) -> #DIV/0! | U24: =STDEV(U5:U20) -> #DIV/0! | V24: =STDEV(V5:V20) -> #DIV/0!
B26: Unspiked | O26: Testosterone spiked
A27: =A4 -> Group names | B27: =B4 -> Solvent control | C27: =C4 -> EE2-33.8ng/L | D27: =D4 -> EE2-50.6ng/L | E27: =E4 -> EE2-76ng/L | F27: =F4 -> EE2-114ng/L | G27: =G4 -> EE2-170.9ng/L | H27: =H4 -> EE2-488ng/L | ... M27: =M4 | O27: =O4 -> Testo -30µg/L | P27: =P4 -> Testo 30µg/L + EE2 -64ng/L | Q27: =Q4 -> Testo 30µg/L + FAD-10mg/L | R27: =R4 -> 0-00 + Testostérone | S27: =S4 -> 0-00 + Testostérone | T27: =T4 -> 0-00 + Testostérone | U27: =U4 -> 0-00 + Testostérone | V27: =V4 -> 0-00 + Testostérone
A28: Data normalised to the "Testo" group | B28: =IF(B5="","",(B5/$O$23)) -> 0.0071569805 | C28: =IF(C5="","",(C5/$O$23)) -> 0 | D28: =IF(D5="","",(D5/$O$23)) -> 0.16429514 | E28: =IF(E5="","",(E5/$O$23)) -> 1.2362123 | F28: =IF(F5="","",(F5/$O$23)) -> 1.2742445 | G28: =IF(G5="","",(G5/$O$23)) -> 2.2156958 | H28: =IF(H5="","",(H5/$O$23)) -> 3.540397 | I28: =IF(I5="","",(I5/$O$23)) | ... M28: =IF(M5="","",(M5/$O$23)) | O28: =IF(O5="","",(O5/$O$23)) -> 0.01900866 | P28: =IF(P5="","",(P5/$O$23)) -> 1.8375958 | Q28: =IF(Q5="","",(Q5/$O$23)) -> 0.00039723808 | R28: =IF(R5="","",(R5/$O$23)) | S28: =IF(S5="","",(S5/$O$23)) | T28: =IF(T5="","",(T5/$O$23)) | U28: =IF(U5="","",(U5/$O$23)) | V28: =IF(V5="","",(V5/$O$23))
B29: =IF(B6="","",(B6/$O$23)) -> 5.9511323e-05 | C29: =IF(C6="","",(C6/$O$23)) -> 0.51427082 | D29: =IF(D6="","",(D6/$O$23)) -> 0.54171893 | E29: =IF(E6="","",(E6/$O$23)) -> 1.2345795 | F29: =IF(F6="","",(F6/$O$23)) -> 0.6749499 | G29: =IF(G6="","",(G6/$O$23)) -> 2.2751536 | H29: =IF(H6="","",(H6/$O$23)) -> 4.5823957 | I29: =IF(I6="","",(I6/$O$23)) | ... M29: =IF(M6="","",(M6/$O$23)) | O29: =IF(O6="","",(O6/$O$23)) -> 1.0271848 | P29: =IF(P6="","",(P6/$O$23)) -> 3.1695671 | Q29: =IF(Q6="","",(Q6/$O$23)) -> 0.0065752573 | R29: =IF(R6="","",(R6/$O$23)) | S29: =IF(S6="","",(S6/$O$23)) | T29: =IF(T6="","",(T6/$O$23)) | U29: =IF(U6="","",(U6/$O$23)) | V29: =IF(V6="","",(V6/$O$23))
B30: =IF(B7="","",(B7/$O$23)) -> 0.010552101 | C30: =IF(C7="","",(C7/$O$23)) -> 0.10351325 | D30: =IF(D7="","",(D7/$O$23)) -> 0.046090776 | E30: =IF(E7="","",(E7/$O$23)) -> 0.55888869 | F30: =IF(F7="","",(F7/$O$23)) -> 1.2920451 | G30: =IF(G7="","",(G7/$O$23)) -> 1.4449007 | H30: =IF(H7="","",(H7/$O$23)) -> 4.5762891 | I30: =IF(I7="","",(I7/$O$23)) | ... M30: =IF(M7="","",(M7/$O$23)) | O30: =IF(O7="","",(O7/$O$23)) -> 0.28475424 | P30: =IF(P7="","",(P7/$O$23)) -> 2.6660686 | Q30: =IF(Q7="","",(Q7/$O$23)) -> 0.076129116 | R30: =IF(R7="","",(R7/$O$23)) | S30: =IF(S7="","",(S7/$O$23)) | T30: =IF(T7="","",(T7/$O$23)) | U30: =IF(U7="","",(U7/$O$23)) | V30: =IF(V7="","",(V7/$O$23))
B31: =IF(B8="","",(B8/$O$23)) -> 0.0029651517 | C31: =IF(C8="","",(C8/$O$23)) -> 0.0074515615 | D31: =IF(D8="","",(D8/$O$23)) -> 0.078144318 | E31: =IF(E8="","",(E8/$O$23)) -> 0.69397716 | F31: =IF(F8="","",(F8/$O$23)) -> 1.4041704 | G31: =IF(G8="","",(G8/$O$23)) -> 2.2719853 | H31: =IF(H8="","",(H8/$O$23)) -> 3.8905661 | I31: =IF(I8="","",(I8/$O$23)) | ... M31: =IF(M8="","",(M8/$O$23)) | O31: =IF(O8="","",(O8/$O$23)) -> 0.72760403 | P31: =IF(P8="","",(P8/$O$23)) -> 2.2687219 | Q31: =IF(Q8="","",(Q8/$O$23)) -> 0.0016149885 | R31: =IF(R8="","",(R8/$O$23)) | S31: =IF(S8="","",(S8/$O$23)) | T31: =IF(T8="","",(T8/$O$23)) | U31: =IF(U8="","",(U8/$O$23)) | V31: =IF(V8="","",(V8/$O$23))
B32: =IF(B9="","",(B9/$O$23)) -> 0.065709427 | C32: =IF(C9="","",(C9/$O$23)) -> 0.1482308 | D32: =IF(D9="","",(D9/$O$23)) -> 0.36003011 | E32: =IF(E9="","",(E9/$O$23)) -> 0.81166452 | F32: =IF(F9="","",(F9/$O$23)) -> 1.4641303 | G32: =IF(G9="","",(G9/$O$23)) -> 2.5565268 | H32: =IF(H9="","",(H9/$O$23)) -> 2.4928631 | I32: =IF(I9="","",(I9/$O$23)) | ... M32: =IF(M9="","",(M9/$O$23)) | O32: =IF(O9="","",(O9/$O$23)) -> 2.8359347 | P32: =IF(P9="","",(P9/$O$23)) -> 2.0297475 | Q32: =IF(Q9="","",(Q9/$O$23)) -> 0.00011976654 | R32: =IF(R9="","",(R9/$O$23)) | S32: =IF(S9="","",(S9/$O$23)) | T32: =IF(T9="","",(T9/$O$23)) | U32: =IF(U9="","",(U9/$O$23)) | V32: =IF(V9="","",(V9/$O$23))
B33: =IF(B10="","",(B10/$O$23)) -> 0.047428293 | C33: =IF(C10="","",(C10/$O$23)) -> 0.0065603794 | D33: =IF(D10="","",(D10/$O$23)) -> 0.32957371 | E33: =IF(E10="","",(E10/$O$23)) -> 0.12789132 | F33: =IF(F10="","",(F10/$O$23)) -> 1.7057864 | G33: =IF(G10="","",(G10/$O$23)) -> 2.4845055 | H33: =IF(H10="","",(H10/$O$23)) -> 4.7237083 | I33: =IF(I10="","",(I10/$O$23)) | ... M33: =IF(M10="","",(M10/$O$23)) | O33: =IF(O10="","",(O10/$O$23)) -> 0.60022525 | P33: =IF(P10="","",(P10/$O$23)) -> 1.7362473 | Q33: =IF(Q10="","",(Q10/$O$23)) -> 0.023615581 | R33: =IF(R10="","",(R10/$O$23)) | S33: =IF(S10="","",(S10/$O$23)) | T33: =IF(T10="","",(T10/$O$23)) | U33: =IF(U10="","",(U10/$O$23)) | V33: =IF(V10="","",(V10/$O$23))
B34: =IF(B11="","",(B11/$O$23)) -> 0.0015056365 | C34: =IF(C11="","",(C11/$O$23)) -> 0.070467357 | D34: =IF(D11="","",(D11/$O$23)) -> 0.2194428 | E34: =IF(E11="","",(E11/$O$23)) -> 1.0103066 | F34: =IF(F11="","",(F11/$O$23)) -> 0.7755166 | G34: =IF(G11="","",(G11/$O$23)) -> 2.636606 | H34: =IF(H11="","",(H11/$O$23)) -> 4.1268476 | I34: =IF(I11="","",(I11/$O$23)) | ... M34: =IF(M11="","",(M11/$O$23)) | O34: =IF(O11="","",(O11/$O$23)) -> 0.68278605 | P34: =IF(P11="","",(P11/$O$23)) -> 1.9358981 | Q34: =IF(Q11="","",(Q11/$O$23)) -> 0.016073264 | R34: =IF(R11="","",(R11/$O$23)) | S34: =IF(S11="","",(S11/$O$23)) | T34: =IF(T11="","",(T11/$O$23)) | U34: =IF(U11="","",(U11/$O$23)) | V34: =IF(V11="","",(V11/$O$23))
B35: =IF(B12="","",(B12/$O$23)) | C35: =IF(C12="","",(C12/$O$23)) -> 0.02329422 | D35: =IF(D12="","",(D12/$O$23)) -> 0.31147557 | E35: =IF(E12="","",(E12/$O$23)) -> 0.62857124 | F35: =IF(F12="","",(F12/$O$23)) -> 0.73681266 | G35: =IF(G12="","",(G12/$O$23)) -> 2.8333296 | H35: =IF(H12="","",(H12/$O$23)) -> 3.3792969 | I35: =IF(I12="","",(I12/$O$23)) | ... M35: =IF(M12="","",(M12/$O$23)) | O35: =IF(O12="","",(O12/$O$23)) -> 0.8928454 | P35: =IF(P12="","",(P12/$O$23)) -> 2.3092684 | Q35: =IF(Q12="","",(Q12/$O$23)) -> 0.031453222 | R35: =IF(R12="","",(R12/$O$23)) | S35: =IF(S12="","",(S12/$O$23)) | T35: =IF(T12="","",(T12/$O$23)) | U35: =IF(U12="","",(U12/$O$23)) | V35: =IF(V12="","",(V12/$O$23))
B36: =IF(B13="","",(B13/$O$23)) | C36: =IF(C13="","",(C13/$O$23)) | D36: =IF(D13="","",(D13/$O$23)) | E36: =IF(E13="","",(E13/$O$23)) | F36: =IF(F13="","",(F13/$O$23)) | G36: =IF(G13="","",(G13/$O$23)) | H36: =IF(H13="","",(H13/$O$23)) | I36: =IF(I13="","",(I13/$O$23)) | ... M36: =IF(M13="","",(M13/$O$23)) | O36: =IF(O13="","",(O13/$O$23)) -> 0.35171489 | P36: =IF(P13="","",(P13/$O$23)) | Q36: =IF(Q13="","",(Q13/$O$23)) | R36: =IF(R13="","",(R13/$O$23)) | S36: =IF(S13="","",(S13/$O$23)) | T36: =IF(T13="","",(T13/$O$23)) | U36: =IF(U13="","",(U13/$O$23)) | V36: =IF(V13="","",(V13/$O$23))
B37: =IF(B14="","",(B14/$O$23)) | C37: =IF(C14="","",(C14/$O$23)) | D37: =IF(D14="","",(D14/$O$23)) | E37: =IF(E14="","",(E14/$O$23)) | F37: =IF(F14="","",(F14/$O$23)) | G37: =IF(G14="","",(G14/$O$23)) | H37: =IF(H14="","",(H14/$O$23)) | I37: =IF(I14="","",(I14/$O$23)) | ... M37: =IF(M14="","",(M14/$O$23)) | O37: =IF(O14="","",(O14/$O$23)) -> 0.49493261 | P37: =IF(P14="","",(P14/$O$23)) | Q37: =IF(Q14="","",(Q14/$O$23)) | R37: =IF(R14="","",(R14/$O$23)) | S37: =IF(S14="","",(S14/$O$23)) | T37: =IF(T14="","",(T14/$O$23)) | U37: =IF(U14="","",(U14/$O$23)) | V37: =IF(V14="","",(V14/$O$23))
B38: =IF(B15="","",(B15/$O$23)) | C38: =IF(C15="","",(C15/$O$23)) | D38: =IF(D15="","",(D15/$O$23)) | E38: =IF(E15="","",(E15/$O$23)) | F38: =IF(F15="","",(F15/$O$23)) | G38: =IF(G15="","",(G15/$O$23)) | H38: =IF(H15="","",(H15/$O$23)) | I38: =IF(I15="","",(I15/$O$23)) | ... M38: =IF(M15="","",(M15/$O$23)) | O38: =IF(O15="","",(O15/$O$23)) -> 1.2156847 | P38: =IF(P15="","",(P15/$O$23)) | Q38: =IF(Q15="","",(Q15/$O$23)) | R38: =IF(R15="","",(R15/$O$23)) | S38: =IF(S15="","",(S15/$O$23)) | T38: =IF(T15="","",(T15/$O$23)) | U38: =IF(U15="","",(U15/$O$23)) | V38: =IF(V15="","",(V15/$O$23))
B39: =IF(B16="","",(B16/$O$23)) | C39: =IF(C16="","",(C16/$O$23)) | D39: =IF(D16="","",(D16/$O$23)) | E39: =IF(E16="","",(E16/$O$23)) | F39: =IF(F16="","",(F16/$O$23)) | G39: =IF(G16="","",(G16/$O$23)) | H39: =IF(H16="","",(H16/$O$23)) | I39: =IF(I16="","",(I16/$O$23)) | ... M39: =IF(M16="","",(M16/$O$23)) | O39: =IF(O16="","",(O16/$O$23)) -> 0.45053419 | P39: =IF(P16="","",(P16/$O$23)) | Q39: =IF(Q16="","",(Q16/$O$23)) | R39: =IF(R16="","",(R16/$O$23)) | S39: =IF(S16="","",(S16/$O$23)) | T39: =IF(T16="","",(T16/$O$23)) | U39: =IF(U16="","",(U16/$O$23)) | V39: =IF(V16="","",(V16/$O$23))
B40: =IF(B17="","",(B17/$O$23)) | C40: =IF(C17="","",(C17/$O$23)) | D40: =IF(D17="","",(D17/$O$23)) | E40: =IF(E17="","",(E17/$O$23)) | F40: =IF(F17="","",(F17/$O$23)) | G40: =IF(G17="","",(G17/$O$23)) | H40: =IF(H17="","",(H17/$O$23)) | I40: =IF(I17="","",(I17/$O$23)) | ... M40: =IF(M17="","",(M17/$O$23)) | O40: =IF(O17="","",(O17/$O$23)) -> 0.44942579 | P40: =IF(P17="","",(P17/$O$23)) | Q40: =IF(Q17="","",(Q17/$O$23)) | R40: =IF(R17="","",(R17/$O$23)) | S40: =IF(S17="","",(S17/$O$23)) | T40: =IF(T17="","",(T17/$O$23)) | U40: =IF(U17="","",(U17/$O$23)) | V40: =IF(V17="","",(V17/$O$23))
... B43: =IF(B20="","",(B20/$O$23)) | C43: =IF(C20="","",(C20/$O$23)) | D43: =IF(D20="","",(D20/$O$23)) | E43: =IF(E20="","",(E20/$O$23)) | F43: =IF(F20="","",(F20/$O$23)) | G43: =IF(G20="","",(G20/$O$23)) | H43: =IF(H20="","",(H20/$O$23)) | I43: =IF(I20="","",(I20/$O$23)) | ... M43: =IF(M20="","",(M20/$O$23)) | O43: =IF(O20="","",(O20/$O$23)) -> 1.3873361 | P43: =IF(P20="","",(P20/$O$23)) | Q43: =IF(Q20="","",(Q20/$O$23)) | R43: =IF(R20="","",(R20/$O$23)) | S43: =IF(S20="","",(S20/$O$23)) | T43: =IF(T20="","",(T20/$O$23)) | U43: =IF(U20="","",(U20/$O$23)) | V43: =IF(V20="","",(V20/$O$23))
A45: =A4 -> Group names | B45: =B4 -> Solvent control | C45: =C4 -> EE2-33.8ng/L | D45: =D4 -> EE2-50.6ng/L | E45: =E4 -> EE2-76ng/L | F45: =F4 -> EE2-114ng/L | G45: =G4 -> EE2-170.9ng/L | H45: =H4 -> EE2-488ng/L | ... M45: =M4 | N45: =N22 -> Nom des groupes | O45: =O4 -> Testo -30µg/L | P45: =P4 -> Testo 30µg/L + EE2 -64ng/L | Q45: =Q4 -> Testo 30µg/L + FAD-10mg/L | R45: =R4 -> 0-00 + Testostérone | S45: =S4 -> 0-00 + Testostérone | T45: =T4 -> 0-00 + Testostérone | U45: =U4 -> 0-00 + Testostérone | V45: =V4 -> 0-00 + Testostérone
A46: mean | B46: =AVERAGE(B28:B43) -> 0.019339586 | C46: =AVERAGE(C28:C43) -> 0.10922355 | D46: =AVERAGE(D28:D43) -> 0.25634642 | E46: =AVERAGE(E28:E43) -> 0.78776142 | F46: =AVERAGE(F28:F43) -> 1.165957 | G46: =AVERAGE(G28:G43) -> 2.3398379 | H46: =AVERAGE(H28:H43) -> 3.9140455 | I46: =AVERAGE(I28:I43) -> #DIV/0! | ... M46: =AVERAGE(M28:M43) -> #DIV/0! | N46: mean | O46: =AVERAGE(O28:O43) -> 1 | P46: =AVERAGE(P28:P43) -> 2.2441393 | Q46: =AVERAGE(Q28:Q43) -> 0.019497304 | R46: =AVERAGE(R28:R43) -> #DIV/0! | S46: =AVERAGE(S28:S43) -> #DIV/0! | T46: =AVERAGE(T28:T43) -> #DIV/0! | U46: =AVERAGE(U28:U43) -> #DIV/0! | V46: =AVERAGE(V28:V43) -> #DIV/0!
A47: SD | B47: =STDEV(B28:B43) -> 0.026212804 | C47: =STDEV(C28:C43) -> 0.17210064 | D47: =STDEV(D28:D43) -> 0.16317737 | E47: =STDEV(E28:E43) -> 0.37278884 | F47: =STDEV(F28:F43) -> 0.38589223 | G47: =STDEV(G28:G43) -> 0.41826172 | H47: =STDEV(H28:H43) -> 0.75894447 | I47: =STDEV(I28:I43) -> #DIV/0! | ... M47: =STDEV(M28:M43) -> #DIV/0! | N47: SD | O47: =STDEV(O28:O43) -> 0.84221055 | P47: =STDEV(P28:P43) -> 0.47861338 | Q47: =STDEV(Q28:Q43) -> 0.025651088 | R47: =STDEV(R28:R43) -> #DIV/0! | S47: =STDEV(S28:S43) -> #DIV/0! | T47: =STDEV(T28:T43) -> #DIV/0! | U47: =STDEV(U28:U43) -> #DIV/0! | V47: =STDEV(V28:V43) -> #DIV/0!
...

Sheet R2
A3: R2 | B3: Unspiked | O3: Testosterone spiked
A4: Group names | B4: ='Front page'!A7 -> Solvent control | C4: ='Front page'!A8 -> EE2-33.8ng/L | D4: ='Front page'!A9 -> EE2-50.6ng/L | E4: ='Front page'!A10 -> EE2-76ng/L | F4: ='Front page'!A11 -> EE2-114ng/L | G4: ='Front page'!A12 -> EE2-170.9ng/L | H4: ='Front page'!A13 -> EE2-488ng/L | I4: ='Front page'!A14 | J4: ='Front page'!A15 | K4: ='Front page'!A16 | L4: ='Front page'!A17 | M4: ='Front page'!A18 | O4: ='Front page'!A35 -> Testo -30µg/L | P4: ='Front page'!A36 -> Testo 30µg/L + EE2 -64ng/L | Q4: ='Front page'!A37 -> Testo 30µg/L + FAD-10mg/L | R4: ='Front page'!A38 -> 0-00 + Testostérone | S4: ='Front page'!A39 -> 0-00 + Testostérone | T4: ='Front page'!A40 -> 0-00 + Testostérone | U4: ='Front page'!A41 -> 0-00 + Testostérone | V4: ='Front page'!A42 -> 0-00 + Testostérone
A5: Raw data | B5: 17989 | C5: 24686 | D5: 327131 | E5: 99312 | F5: 2050617 | G5: 3669626 | H5: 7421219 | O5: 2468526 | P5: 3641274 | Q5: 42365
B6: 46343 | C6: 63921 | D6: 337570 | E6: 850684 | F6: 1321934 | G6: 2245239 | H6: 3998463 | O6: 952230 | P6: 3092059 | Q6: 19776
B7: 32511 | C7: 33900 | D7: 81717 | E7: 115769 | F7: 2153975 | G7: 3543558 | H7: 5563780 | O7: 1530422 | P7: 4358666 | Q7: 38819
B8: 5495 | C8: 97885 | D8: 137468 | E8: 202713 | F8: 1739012 | G8: 3470236 | H8: 5478839 | O8: 2293459 | P8: 3540388 | Q8: 28774
B9: 11994 | C9: 88032 | D9: 16564 | E9: 204590 | F9: 2872576 | G9: 2366366 | H9: 9369790 | O9: 1801693 | P9: 3442128 | Q9: 16152
B10: 39328 | C10: 8586 | D10: 19085 | E10: 97157 | F10: 1981536 | G10: 308872 | H10: 6878373 | O10: 2384302 | P10: 4415005 | Q10: 51211
B11: 55730 | C11: 117411 | D11: 15673 | E11: 101742 | F11: 837609 | G11: 2219626 | H11: 5729499 | O11: 2636591 | P11: 4228085 | Q11: 24203
B12: 62121 | C12: 10457 | D12: 11057 | E12: 378841 | F12: 1079857 | G12: 2112436 | H12: 9075731 | O12: 2079357 | P12: 3187367 | Q12: 40768
O13: 2563447
O14: 2813133
O15: 1929592
O16: 2028750
O17: 4318419
O18: 3004893
O19: 3474370
O20: 3057373
O21: 832643
A22: =A4 -> Group names | B22: =B4 -> Solvent control | C22: =C4 -> EE2-33.8ng/L | D22: =D4 -> EE2-50.6ng/L | E22: =E4 -> EE2-76ng/L | F22: =F4 -> EE2-114ng/L | G22: =G4 -> EE2-170.9ng/L | H22: =H4 -> EE2-488ng/L | ... M22: =M4 | N22: Noms des groupes | O22: =O4 -> Testo -30µg/L | P22: =P4 -> Testo 30µg/L + EE2 -64ng/L | Q22: =Q4 -> Testo 30µg/L + FAD-10mg/L | R22: =R4 -> 0-00 + Testostérone | S22: =S4 -> 0-00 + Testostérone | T22: =T4 -> 0-00 + Testostérone | U22: =U4 -> 0-00 + Testostérone | V22: =V4 -> 0-00 + Testostérone
A23: mean | B23: =AVERAGE(B5:B20) -> 33938.875 | C23: =AVERAGE(C5:C20) -> 55609.75 | D23: =AVERAGE(D5:D20) -> 118283.12 | E23: =AVERAGE(E5:E20) -> 256351 | F23: =AVERAGE(F5:F20) -> 1754639.5 | G23: =AVERAGE(G5:G20) -> 2491994.9 | H23: =AVERAGE(H5:H20) -> 6689461.8 | I23: =AVERAGE(I5:I20) -> #DIV/0! | J23: =AVERAGE(J5:J20) -> #DIV/0! | L23: =AVERAGE(L5:L20) -> #DIV/0! | N23: mean | O23: =AVERAGE(O5:O20) -> 2458534.8 | P23: =AVERAGE(P5:P20) -> 3738121.5 | Q23: =AVERAGE(Q5:Q20) -> 32758.5 | R23: =AVERAGE(R5:R20) -> #DIV/0! | S23: =AVERAGE(S5:S20) -> #DIV/0! | T23: =AVERAGE(T5:T20) -> #DIV/0! | U23: =AVERAGE(U5:U20) -> #DIV/0! | V23: =AVERAGE(V5:V20) -> #DIV/0!
A24: SD | B24: =STDEV(B5:B20) -> 20698.72 | C24: =STDEV(C5:C20) -> 42095.921 | D24: =STDEV(D5:D20) -> 139192.9 | E24: =STDEV(E5:E20) -> 258419.09 | F24: =STDEV(F5:F20) -> 658145.68 | G24: =STDEV(G5:G20) -> 1102626.9 | H24: =STDEV(H5:H20) -> 1864915.4 | I24: =STDEV(I5:I20) -> #DIV/0! | J24: =STDEV(J5:J20) -> #DIV/0! | L24: =STDEV(L5:L20) -> #DIV/0! | N24: SD | O24: =STDEV(O5:O20) -> 796641.94 | P24: =STDEV(P5:P20) -> 526461.01 | Q24: =STDEV(Q5:Q20) -> 12346.517 | R24: =STDEV(R5:R20) -> #DIV/0! | S24: =STDEV(S5:S20) -> #DIV/0! | T24: =STDEV(T5:T20) -> #DIV/0! | U24: =STDEV(U5:U20) -> #DIV/0! | V24: =STDEV(V5:V20) -> #DIV/0!
B26: Unspiked | O26: Testosterone spiked
A27: =A4 -> Group names | B27: =B4 -> Solvent control | C27: =C4 -> EE2-33.8ng/L | D27: =D4 -> EE2-50.6ng/L | E27: =E4 -> EE2-76ng/L | F27: =F4 -> EE2-114ng/L | G27: =G4 -> EE2-170.9ng/L | H27: =H4 -> EE2-488ng/L | ... M27: =M4 | O27: =O4 -> Testo -30µg/L | P27: =P4 -> Testo 30µg/L + EE2 -64ng/L | Q27: =Q4 -> Testo 30µg/L + FAD-10mg/L | R27: =R4 -> 0-00 + Testostérone | S27: =S4 -> 0-00 + Testostérone | T27: =T4 -> 0-00 + Testostérone | U27: =U4 -> 0-00 + Testostérone | V27: =V4 -> 0-00 + Testostérone
A28: Data normalised to the "Testo" group | B28: =IF(B5="","",(B5/$O$23)) -> 0.0073169596 | C28: =IF(C5="","",(C5/$O$23)) -> 0.01004094 | D28: =IF(D5="","",(D5/$O$23)) -> 0.13305933 | E28: =IF(E5="","",(E5/$O$23)) -> 0.040394791 | F28: =IF(F5="","",(F5/$O$23)) -> 0.83408093 | G28: =IF(G5="","",(G5/$O$23)) -> 1.4926069 | H28: =IF(H5="","",(H5/$O$23)) -> 3.0185536 | I28: =IF(I5="","",(I5/$O$23)) | ... M28: =IF(M5="","",(M5/$O$23)) | O28: =IF(O5="","",(O5/$O$23)) -> 1.0040639 | P28: =IF(P5="","",(P5/$O$23)) -> 1.4810748 | Q28: =IF(Q5="","",(Q5/$O$23)) -> 0.017231808 | R28: =IF(R5="","",(R5/$O$23)) | S28: =IF(S5="","",(S5/$O$23)) | T28: =IF(T5="","",(T5/$O$23)) | U28: =IF(U5="","",(U5/$O$23)) | V28: =IF(V5="","",(V5/$O$23))
B29: =IF(B6="","",(B6/$O$23)) -> 0.018849845 | C29: =IF(C6="","",(C6/$O$23)) -> 0.025999632 | D29: =IF(D6="","",(D6/$O$23)) -> 0.13730536 | E29: =IF(E6="","",(E6/$O$23)) -> 0.34601259 | F29: =IF(F6="","",(F6/$O$23)) -> 0.5376918 | G29: =IF(G6="","",(G6/$O$23)) -> 0.91324271 | H29: =IF(H6="","",(H6/$O$23)) -> 1.6263601 | I29: =IF(I6="","",(I6/$O$23)) | ... M29: =IF(M6="","",(M6/$O$23)) | O29: =IF(O6="","",(O6/$O$23)) -> 0.38731605 | P29: =IF(P6="","",(P6/$O$23)) -> 1.2576836 | Q29: =IF(Q6="","",(Q6/$O$23)) -> 0.0080438153 | R29: =IF(R6="","",(R6/$O$23)) | S29: =IF(S6="","",(S6/$O$23)) | T29: =IF(T6="","",(T6/$O$23)) | U29: =IF(U6="","",(U6/$O$23)) | V29: =IF(V6="","",(V6/$O$23))
B30: =IF(B7="","",(B7/$O$23)) -> 0.01322373 | C30: =IF(C7="","",(C7/$O$23)) -> 0.0137887 | D30: =IF(D7="","",(D7/$O$23)) -> 0.033238089 | E30: =IF(E7="","",(E7/$O$23)) -> 0.047088615 | F30: =IF(F7="","",(F7/$O$23)) -> 0.87612142 | G30: =IF(G7="","",(G7/$O$23)) -> 1.4413292 | H30: =IF(H7="","",(H7/$O$23)) -> 2.2630471 | I30: =IF(I7="","",(I7/$O$23)) | ... M30: =IF(M7="","",(M7/$O$23)) | O30: =IF(O7="","",(O7/$O$23)) -> 0.62249352 | P30: =IF(P7="","",(P7/$O$23)) -> 1.7728714 | Q30: =IF(Q7="","",(Q7/$O$23)) -> 0.015789486 | R30: =IF(R7="","",(R7/$O$23)) | S30: =IF(S7="","",(S7/$O$23)) | T30: =IF(T7="","",(T7/$O$23)) | U30: =IF(U7="","",(U7/$O$23)) | V30: =IF(V7="","",(V7/$O$23))
B31: =IF(B8="","",(B8/$O$23)) -> 0.0022350711 | C31: =IF(C8="","",(C8/$O$23)) -> 0.039814364 | D31: =IF(D8="","",(D8/$O$23)) -> 0.055914604 | E31: =IF(E8="","",(E8/$O$23)) -> 0.082452768 | F31: =IF(F8="","",(F8/$O$23)) -> 0.70733674 | G31: =IF(G8="","",(G8/$O$23)) -> 1.4115057 | H31: =IF(H8="","",(H8/$O$23)) -> 2.2284976 | I31: =IF(I8="","",(I8/$O$23)) | ... M31: =IF(M8="","",(M8/$O$23)) | O31: =IF(O8="","",(O8/$O$23)) -> 0.93285602 | P31: =IF(P8="","",(P8/$O$23)) -> 1.4400398 | Q31: =IF(Q8="","",(Q8/$O$23)) -> 0.011703719 | R31: =IF(R8="","",(R8/$O$23)) | S31: =IF(S8="","",(S8/$O$23)) | T31: =IF(T8="","",(T8/$O$23)) | U31: =IF(U8="","",(U8/$O$23)) | V31: =IF(V8="","",(V8/$O$23))
B32: =IF(B9="","",(B9/$O$23)) -> 0.0048785154 | C32: =IF(C9="","",(C9/$O$23)) -> 0.035806692 | D32: =IF(D9="","",(D9/$O$23)) -> 0.0067373461 | E32: =IF(E9="","",(E9/$O$23)) -> 0.083216231 | F32: =IF(F9="","",(F9/$O$23)) -> 1.1684097 | G32: =IF(G9="","",(G9/$O$23)) -> 0.96251067 | H32: =IF(H9="","",(H9/$O$23)) -> 3.8111276 | I32: =IF(I9="","",(I9/$O$23)) | ... M32: =IF(M9="","",(M9/$O$23)) | O32: =IF(O9="","",(O9/$O$23)) -> 0.73283201 | P32: =IF(P9="","",(P9/$O$23)) -> 1.4000729 | Q32: =IF(Q9="","",(Q9/$O$23)) -> 0.0065697666 | R32: =IF(R9="","",(R9/$O$23)) | S32: =IF(S9="","",(S9/$O$23)) | T32: =IF(T9="","",(T9/$O$23)) | U32: =IF(U9="","",(U9/$O$23)) | V32: =IF(V9="","",(V9/$O$23))
B33: =IF(B10="","",(B10/$O$23)) -> 0.015996519 | C33: =IF(C10="","",(C10/$O$23)) -> 0.0034923239 | D33: =IF(D10="","",(D10/$O$23)) -> 0.0077627536 | E33: =IF(E10="","",(E10/$O$23)) -> 0.039518253 | F33: =IF(F10="","",(F10/$O$23)) -> 0.80598249 | G33: =IF(G10="","",(G10/$O$23)) -> 0.12563255 | H33: =IF(H10="","",(H10/$O$23)) -> 2.7977529 | I33: =IF(I10="","",(I10/$O$23)) | ... M33: =IF(M10="","",(M10/$O$23)) | O33: =IF(O10="","",(O10/$O$23)) -> 0.96980608 | P33: =IF(P10="","",(P10/$O$23)) -> 1.7957871 | Q33: =IF(Q10="","",(Q10/$O$23)) -> 0.020829886 | R33: =IF(R10="","",(R10/$O$23)) | S33: =IF(S10="","",(S10/$O$23)) | T33: =IF(T10="","",(T10/$O$23)) | U33: =IF(U10="","",(U10/$O$23)) | V33: =IF(V10="","",(V10/$O$23))
B34: =IF(B11="","",(B11/$O$23)) -> 0.022667973 | C34: =IF(C11="","",(C11/$O$23)) -> 0.047756493 | D34: =IF(D11="","",(D11/$O$23)) -> 0.0063749352 | E34: =IF(E11="","",(E11/$O$23)) -> 0.041383185 | F34: =IF(F11="","",(F11/$O$23)) -> 0.34069438 | G34: =IF(G11="","",(G11/$O$23)) -> 0.90282472 | H34: =IF(H11="","",(H11/$O$23)) -> 2.3304527 | I34: =IF(I11="","",(I11/$O$23)) | ... M34: =IF(M11="","",(M11/$O$23)) | O34: =IF(O11="","",(O11/$O$23)) -> 1.0724237 | P34: =IF(P11="","",(P11/$O$23)) -> 1.719758 | Q34: =IF(Q11="","",(Q11/$O$23)) -> 0.0098444813 | R34: =IF(R11="","",(R11/$O$23)) | S34: =IF(S11="","",(S11/$O$23)) | T34: =IF(T11="","",(T11/$O$23)) | U34: =IF(U11="","",(U11/$O$23)) | V34: =IF(V11="","",(V11/$O$23))
B35: =IF(B12="","",(B12/$O$23)) -> 0.025267488 | C35: =IF(C12="","",(C12/$O$23)) -> 0.0042533463 | D35: =IF(D12="","",(D12/$O$23)) -> 0.0044973941 | E35: =IF(E12="","",(E12/$O$23)) -> 0.15409218 | F35: =IF(F12="","",(F12/$O$23)) -> 0.43922787 | G35: =IF(G12="","",(G12/$O$23)) -> 0.85922558 | H35: =IF(H12="","",(H12/$O$23)) -> 3.6915202 | I35: =IF(I12="","",(I12/$O$23)) | ... M35: =IF(M12="","",(M12/$O$23)) | O35: =IF(O12="","",(O12/$O$23)) -> 0.84577082 | P35: =IF(P12="","",(P12/$O$23)) -> 1.2964498 | Q35: =IF(Q12="","",(Q12/$O$23)) -> 0.016582234 | R35: =IF(R12="","",(R12/$O$23)) | S35: =IF(S12="","",(S12/$O$23)) | T35: =IF(T12="","",(T12/$O$23)) | U35: =IF(U12="","",(U12/$O$23)) | V35: =IF(V12="","",(V12/$O$23))
B36: =IF(B13="","",(B13/$O$23)) | C36: =IF(C13="","",(C13/$O$23)) | D36: =IF(D13="","",(D13/$O$23)) | E36: =IF(E13="","",(E13/$O$23)) | F36: =IF(F13="","",(F13/$O$23)) | G36: =IF(G13="","",(G13/$O$23)) | H36: =IF(H13="","",(H13/$O$23)) | I36: =IF(I13="","",(I13/$O$23)) | ... M36: =IF(M13="","",(M13/$O$23)) | O36: =IF(O13="","",(O13/$O$23)) -> 1.0426726 | P36: =IF(P13="","",(P13/$O$23)) | Q36: =IF(Q13="","",(Q13/$O$23)) | R36: =IF(R13="","",(R13/$O$23)) | S36: =IF(S13="","",(S13/$O$23)) | T36: =IF(T13="","",(T13/$O$23)) | U36: =IF(U13="","",(U13/$O$23)) | V36: =IF(V13="","",(V13/$O$23))
B37: =IF(B14="","",(B14/$O$23)) | C37: =IF(C14="","",(C14/$O$23)) | D37: =IF(D14="","",(D14/$O$23)) | E37: =IF(E14="","",(E14/$O$23)) | F37: =IF(F14="","",(F14/$O$23)) | G37: =IF(G14="","",(G14/$O$23)) | H37: =IF(H14="","",(H14/$O$23)) | I37: =IF(I14="","",(I14/$O$23)) | ... M37: =IF(M14="","",(M14/$O$23)) | O37: =IF(O14="","",(O14/$O$23)) -> 1.1442315 | P37: =IF(P14="","",(P14/$O$23)) | Q37: =IF(Q14="","",(Q14/$O$23)) | R37: =IF(R14="","",(R14/$O$23)) | S37: =IF(S14="","",(S14/$O$23)) | T37: =IF(T14="","",(T14/$O$23)) | U37: =IF(U14="","",(U14/$O$23)) | V37: =IF(V14="","",(V14/$O$23))
B38: =IF(B15="","",(B15/$O$23)) | C38: =IF(C15="","",(C15/$O$23)) | D38: =IF(D15="","",(D15/$O$23)) | E38: =IF(E15="","",(E15/$O$23)) | F38: =IF(F15="","",(F15/$O$23)) | G38: =IF(G15="","",(G15/$O$23)) | H38: =IF(H15="","",(H15/$O$23)) | I38: =IF(I15="","",(I15/$O$23)) | ... M38: =IF(M15="","",(M15/$O$23)) | O38: =IF(O15="","",(O15/$O$23)) -> 0.78485445 | P38: =IF(P15="","",(P15/$O$23)) | Q38: =IF(Q15="","",(Q15/$O$23)) | R38: =IF(R15="","",(R15/$O$23)) | S38: =IF(S15="","",(S15/$O$23)) | T38: =IF(T15="","",(T15/$O$23)) | U38: =IF(U15="","",(U15/$O$23)) | V38: =IF(V15="","",(V15/$O$23))
B39: =IF(B16="","",(B16/$O$23)) | C39: =IF(C16="","",(C16/$O$23)) | D39: =IF(D16="","",(D16/$O$23)) | E39: =IF(E16="","",(E16/$O$23)) | F39: =IF(F16="","",(F16/$O$23)) | G39: =IF(G16="","",(G16/$O$23)) | H39: =IF(H16="","",(H16/$O$23)) | I39: =IF(I16="","",(I16/$O$23)) | ... M39: =IF(M16="","",(M16/$O$23)) | O39: =IF(O16="","",(O16/$O$23)) -> 0.82518661 | P39: =IF(P16="","",(P16/$O$23)) | Q39: =IF(Q16="","",(Q16/$O$23)) | R39: =IF(R16="","",(R16/$O$23)) | S39: =IF(S16="","",(S16/$O$23)) | T39: =IF(T16="","",(T16/$O$23)) | U39: =IF(U16="","",(U16/$O$23)) | V39: =IF(V16="","",(V16/$O$23))
B40: =IF(B17="","",(B17/$O$23)) | C40: =IF(C17="","",(C17/$O$23)) | D40: =IF(D17="","",(D17/$O$23)) | E40: =IF(E17="","",(E17/$O$23)) | F40: =IF(F17="","",(F17/$O$23)) | G40: =IF(G17="","",(G17/$O$23)) | H40: =IF(H17="","",(H17/$O$23)) | I40: =IF(I17="","",(I17/$O$23)) | ... M40: =IF(M17="","",(M17/$O$23)) | O40: =IF(O17="","",(O17/$O$23)) -> 1.7565011 | P40: =IF(P17="","",(P17/$O$23)) | Q40: =IF(Q17="","",(Q17/$O$23)) | R40: =IF(R17="","",(R17/$O$23)) | S40: =IF(S17="","",(S17/$O$23)) | T40: =IF(T17="","",(T17/$O$23)) | U40: =IF(U17="","",(U17/$O$23)) | V40: =IF(V17="","",(V17/$O$23))
... B43: =IF(B20="","",(B20/$O$23)) | C43: =IF(C20="","",(C20/$O$23)) | D43: =IF(D20="","",(D20/$O$23)) | E43: =IF(E20="","",(E20/$O$23)) | F43: =IF(F20="","",(F20/$O$23)) | G43: =IF(G20="","",(G20/$O$23)) | H43: =IF(H20="","",(H20/$O$23)) | I43: =IF(I20="","",(I20/$O$23)) | ... M43: =IF(M20="","",(M20/$O$23)) | O43: =IF(O20="","",(O20/$O$23)) -> 1.2435752 | P43: =IF(P20="","",(P20/$O$23)) | Q43: =IF(Q20="","",(Q20/$O$23)) | R43: =IF(R20="","",(R20/$O$23)) | S43: =IF(S20="","",(S20/$O$23)) | T43: =IF(T20="","",(T20/$O$23)) | U43: =IF(U20="","",(U20/$O$23)) | V43: =IF(V20="","",(V20/$O$23))
A45: =A4 -> Group names | B45: =B4 -> Solvent control | C45: =C4 -> EE2-33.8ng/L | D45: =D4 -> EE2-50.6ng/L | E45: =E4 -> EE2-76ng/L | F45: =F4 -> EE2-114ng/L | G45: =G4 -> EE2-170.9ng/L | H45: =H4 -> EE2-488ng/L | ... M45: =M4 | O45: =O4 -> Testo -30µg/L | P45: =P4 -> Testo 30µg/L + EE2 -64ng/L | Q45: =Q4 -> Testo 30µg/L + FAD-10mg/L | R45: =R4 -> 0-00 + Testostérone | S45: =S4 -> 0-00 + Testostérone | T45: =T4 -> 0-00 + Testostérone | U45: =U4 -> 0-00 + Testostérone | V45: =V4 -> 0-00 + Testostérone
A46: mean | B46: =AVERAGE(B28:B43) -> 0.013804513 | C46: =AVERAGE(C28:C43) -> 0.022619061 | D46: =AVERAGE(D28:D43) -> 0.048111226 | E46: =AVERAGE(E28:E43) -> 0.10426983 | F46: =AVERAGE(F28:F43) -> 0.71369317 | G46: =AVERAGE(G28:G43) -> 1.0136098 | H46: =AVERAGE(H28:H43) -> 2.720914 | I46: =AVERAGE(I28:I43) -> #DIV/0! | ... M46: =AVERAGE(M28:M43) -> #DIV/0! | N46: mean | O46: =AVERAGE(O28:O43) -> 1 | P46: =AVERAGE(P28:P43) -> 1.5204672 | Q46: =AVERAGE(Q28:Q43) -> 0.013324399 | R46: =AVERAGE(R28:R43) -> #DIV/0! | S46: =AVERAGE(S28:S43) -> #DIV/0! | T46: =AVERAGE(T28:T43) -> #DIV/0! | U46: =AVERAGE(U28:U43) -> #DIV/0! | V46: =AVERAGE(V28:V43) -> #DIV/0!
...

Sheet R3
A3: R3 | B3: Unspiked | O3: Testosterone spiked
A4: Group names | B4: ='Front page'!A7 -> Solvent control | C4: ='Front page'!A8 -> EE2-33.8ng/L | D4: ='Front page'!A9 -> EE2-50.6ng/L | E4: ='Front page'!A10 -> EE2-76ng/L | F4: ='Front page'!A11 -> EE2-114ng/L | G4: ='Front page'!A12 -> EE2-170.9ng/L | H4: ='Front page'!A13 -> EE2-488ng/L | I4: ='Front page'!A14 | J4: ='Front page'!A15 | K4: ='Front page'!A16 | L4: ='Front page'!A17 | M4: ='Front page'!A18 | O4: ='Front page'!A35 -> Testo -30µg/L | P4: ='Front page'!A36 -> Testo 30µg/L + EE2 -64ng/L | Q4: ='Front page'!A37 -> Testo 30µg/L + FAD-10mg/L | R4: ='Front page'!A38 -> 0-00 + Testostérone | S4: ='Front page'!A39 -> 0-00 + Testostérone | T4: ='Front page'!A40 -> 0-00 + Testostérone | U4: ='Front page'!A41 -> 0-00 + Testostérone | V4: ='Front page'!A42 -> 0-00 + Testostérone
A5: Raw data | B5: 33298 | C5: 42656 | D5: 55230 | E5: 1666467 | F5: 3192997 | G5: 2927137 | H5: 6248301 | O5: 1950149 | P5: 3815865 | Q5: 7085
B6: 39902 | C6: 27920 | D6: 100111 | E6: 1271819 | F6: 1930408 | G6: 1713728 | H6: 8796415 | O6: 1948735 | P6: 3571623 | Q6: 30952
B7: 1835 | C7: 7937 | D7: 113718 | E7: 866893 | F7: 3069752 | G7: 2316748 | H7: 4890450 | O7: 1938092 | P7: 3280312 | Q7: 43812
B8: 16758 | C8: 60641 | D8: 56665 | E8: 1347945 | F8: 5468555 | G8: 2305939 | H8: 8092615 | O8: 1935757 | P8: 3750603 | Q8: 117906
B9: 19799 | C9: 17118 | D9: 21918 | E9: 1119940 | F9: 2907950 | G9: 2855299 | H9: 6536120 | O9: 4257890 | P9: 3340395 | Q9: 32884
B10: 422 | C10: 27467 | D10: 30331 | E10: 1186472 | F10: 3711475 | G10: 1887435 | H10: 8615534 | O10: 2867482 | P10: 4574119 | Q10: 27979
B11: 28958 | C11: 70845 | D11: 46748 | E11: 1838088 | F11: 2722659 | G11: 2211214 | H11: 6265676 | O11: 1803452 | P11: 2099808 | Q11: 42676
B12: 10371 | C12: 45757 | D12: 13395 | E12: 433215 | F12: 4419874 | G12: 3754386 | H12: 6008420 | O12: 1946995 | P12: 3895621 | Q12: 25595
O13: 1971639
O14: 2625907
O15: 3240113
O16: 543556
O17: 3058989
O18: 4228130
O19: 3469812
O20: 883475
A22: =A4 -> Group names | B22: =B4 -> Solvent control | C22: =C4 -> EE2-33.8ng/L | D22: =D4 -> EE2-50.6ng/L | E22: =E4 -> EE2-76ng/L | F22: =F4 -> EE2-114ng/L | G22: =G4 -> EE2-170.9ng/L | H22: =H4 -> EE2-488ng/L | ... M22: =M4 | N22: Noms des groupes | O22: =O4 -> Testo -30µg/L | P22: =P4 -> Testo 30µg/L + EE2 -64ng/L | Q22: =Q4 -> Testo 30µg/L + FAD-10mg/L | R22: =R4 -> 0-00 + Testostérone | S22: =S4 -> 0-00 + Testostérone | T22: =T4 -> 0-00 + Testostérone | U22: =U4 -> 0-00 + Testostérone | V22: =V4 -> 0-00 + Testostérone
A23: mean | B23: =AVERAGE(B5:B20) -> 18917.875 | C23: =AVERAGE(C5:C20) -> 37542.625 | D23: =AVERAGE(D5:D20) -> 54764.5 | E23: =AVERAGE(E5:E20) -> 1216354.9 | F23: =AVERAGE(F5:F20) -> 3427958.8 | G23: =AVERAGE(G5:G20) -> 2496485.8 | H23: =AVERAGE(H5:H20) -> 6931691.4 | I23: =AVERAGE(I5:I20) -> #DIV/0! | J23: =AVERAGE(J5:J20) -> #DIV/0! | L23: =AVERAGE(L5:L20) -> #DIV/0! | N23: mean | O23: =AVERAGE(O5:O20) -> 2416885.8 | P23: =AVERAGE(P5:P20) -> 3541043.2 | Q23: =AVERAGE(Q5:Q20) -> 41111.125 | R23: =AVERAGE(R5:R20) -> #DIV/0! | S23: =AVERAGE(S5:S20) -> #DIV/0! | T23: =AVERAGE(T5:T20) -> #DIV/0! | U23: =AVERAGE(U5:U20) -> #DIV/0! | V23: =AVERAGE(V5:V20) -> #DIV/0!
A24: SD | B24: =STDEV(B5:B20) -> 14443.674 | C24: =STDEV(C5:C20) -> 21460.852 | D24: =STDEV(D5:D20) -> 35831.425 | E24: =STDEV(E5:E20) -> 439994.43 | F24: =STDEV(F5:F20) -> 1096901.1 | G24: =STDEV(G5:G20) -> 657936.89 | H24: =STDEV(H5:H20) -> 1401348.1 | I24: =STDEV(I5:I20) -> #DIV/0! | J24: =STDEV(J5:J20) -> #DIV/0! | L24: =STDEV(L5:L20) -> #DIV/0! | N24: SD | O24: =STDEV(O5:O20) -> 1054168.7 | P24: =STDEV(P5:P20) -> 706980.28 | Q24: =STDEV(Q5:Q20) -> 33056.38 | R24: =STDEV(R5:R20) -> #DIV/0! | S24: =STDEV(S5:S20) -> #DIV/0! | T24: =STDEV(T5:T20) -> #DIV/0! | U24: =STDEV(U5:U20) -> #DIV/0! | V24: =STDEV(V5:V20) -> #DIV/0!
B26: Unspiked | O26: Testosterone spiked
A27: =A4 -> Group names | B27: =B4 -> Solvent control | C27: =C4 -> EE2-33.8ng/L | D27: =D4 -> EE2-50.6ng/L | E27: =E4 -> EE2-76ng/L | F27: =F4 -> EE2-114ng/L | G27: =G4 -> EE2-170.9ng/L | H27: =H4 -> EE2-488ng/L | ... M27: =M4 | O27: =O4 -> Testo -30µg/L | P27: =P4 -> Testo 30µg/L + EE2 -64ng/L | Q27: =Q4 -> Testo 30µg/L + FAD-10mg/L | R27: =R4 -> 0-00 + Testostérone | S27: =S4 -> 0-00 + Testostérone | T27: =T4 -> 0-00 + Testostérone | U27: =U4 -> 0-00 + Testostérone | V27: =V4 -> 0-00 + Testostérone
A28: Data normalised to the "Testo" group | B28: =IF(B5="","",(B5/$O$23)) -> 0.013777233 | C28: =IF(C5="","",(C5/$O$23)) -> 0.017649158 | D28: =IF(D5="","",(D5/$O$23)) -> 0.022851721 | E28: =IF(E5="","",(E5/$O$23)) -> 0.68951003 | F28: =IF(F5="","",(F5/$O$23)) -> 1.3211203 | G28: =IF(G5="","",(G5/$O$23)) -> 1.2111193 | H28: =IF(H5="","",(H5/$O$23)) -> 2.5852694 | I28: =IF(I5="","",(I5/$O$23)) | ... M28: =IF(M5="","",(M5/$O$23)) | O28: =IF(O5="","",(O5/$O$23)) -> 0.80688504 | P28: =IF(P5="","",(P5/$O$23)) -> 1.5788355 | Q28: =IF(Q5="","",(Q5/$O$23)) -> 0.0029314583 | R28: =IF(R5="","",(R5/$O$23)) | S28: =IF(S5="","",(S5/$O$23)) | T28: =IF(T5="","",(T5/$O$23)) | U28: =IF(U5="","",(U5/$O$23)) | V28: =IF(V5="","",(V5/$O$23))
B29: =IF(B6="","",(B6/$O$23)) -> 0.016509675 | C29: =IF(C6="","",(C6/$O$23)) -> 0.011552056 | D29: =IF(D6="","",(D6/$O$23)) -> 0.041421485 | E29: =IF(E6="","",(E6/$O$23)) -> 0.52622221 | F29: =IF(F6="","",(F6/$O$23)) -> 0.79871709 | G29: =IF(G6="","",(G6/$O$23)) -> 0.70906453 | H29: =IF(H6="","",(H6/$O$23)) -> 3.6395658 | I29: =IF(I6="","",(I6/$O$23)) | ... M29: =IF(M6="","",(M6/$O$23)) | O29: =IF(O6="","",(O6/$O$23)) -> 0.80629999 | P29: =IF(P6="","",(P6/$O$23)) -> 1.477779 | Q29: =IF(Q6="","",(Q6/$O$23)) -> 0.012806563 | R29: =IF(R6="","",(R6/$O$23)) | S29: =IF(S6="","",(S6/$O$23)) | T29: =IF(T6="","",(T6/$O$23)) | U29: =IF(U6="","",(U6/$O$23)) | V29: =IF(V6="","",(V6/$O$23))
B30: =IF(B7="","",(B7/$O$23)) -> 0.0007592415 | C30: =IF(C7="","",(C7/$O$23)) -> 0.0032839781 | D30: =IF(D7="","",(D7/$O$23)) -> 0.047051457 | E30: =IF(E7="","",(E7/$O$23)) -> 0.35868182 | F30: =IF(F7="","",(F7/$O$23)) -> 1.270127 | G30: =IF(G7="","",(G7/$O$23)) -> 0.95856742 | H30: =IF(H7="","",(H7/$O$23)) -> 2.023451 | I30: =IF(I7="","",(I7/$O$23)) | ... M30: =IF(M7="","",(M7/$O$23)) | O30: =IF(O7="","",(O7/$O$23)) -> 0.80189639 | P30: =IF(P7="","",(P7/$O$23)) -> 1.3572474 | Q30: =IF(Q7="","",(Q7/$O$23)) -> 0.01812746 | R30: =IF(R7="","",(R7/$O$23)) | S30: =IF(S7="","",(S7/$O$23)) | T30: =IF(T7="","",(T7/$O$23)) | U30: =IF(U7="","",(U7/$O$23)) | V30: =IF(V7="","",(V7/$O$23))
B31: =IF(B8="","",(B8/$O$23)) -> 0.0069337161 | C31: =IF(C8="","",(C8/$O$23)) -> 0.025090552 | D31: =IF(D8="","",(D8/$O$23)) -> 0.02344546 | E31: =IF(E8="","",(E8/$O$23)) -> 0.55771977 | F31: =IF(F8="","",(F8/$O$23)) -> 2.2626452 | G31: =IF(G8="","",(G8/$O$23)) -> 0.95409514 | H31: =IF(H8="","",(H8/$O$23)) -> 3.3483646 | I31: =IF(I8="","",(I8/$O$23)) | ... M31: =IF(M8="","",(M8/$O$23)) | O31: =IF(O8="","",(O8/$O$23)) -> 0.80093027 | P31: =IF(P8="","",(P8/$O$23)) -> 1.5518329 | Q31: =IF(Q8="","",(Q8/$O$23)) -> 0.048784266 | R31: =IF(R8="","",(R8/$O$23)) | S31: =IF(S8="","",(S8/$O$23)) | T31: =IF(T8="","",(T8/$O$23)) | U31: =IF(U8="","",(U8/$O$23)) | V31: =IF(V8="","",(V8/$O$23))
B32: =IF(B9="","",(B9/$O$23)) -> 0.0081919468 | C32: =IF(C9="","",(C9/$O$23)) -> 0.0070826681 | D32: =IF(D9="","",(D9/$O$23)) -> 0.0090686949 | E32: =IF(E9="","",(E9/$O$23)) -> 0.46338143 | F32: =IF(F9="","",(F9/$O$23)) -> 1.2031805 | G32: =IF(G9="","",(G9/$O$23)) -> 1.1813959 | H32: =IF(H9="","",(H9/$O$23)) -> 2.7043561 | I32: =IF(I9="","",(I9/$O$23)) | ... M32: =IF(M9="","",(M9/$O$23)) | O32: =IF(O9="","",(O9/$O$23)) -> 1.7617258 | P32: =IF(P9="","",(P9/$O$23)) -> 1.3821071 | Q32: =IF(Q9="","",(Q9/$O$23)) -> 0.013605939 | R32: =IF(R9="","",(R9/$O$23)) | S32: =IF(S9="","",(S9/$O$23)) | T32: =IF(T9="","",(T9/$O$23)) | U32: =IF(U9="","",(U9/$O$23)) | V32: =IF(V9="","",(V9/$O$23))
B33: =IF(B10="","",(B10/$O$23)) -> 0.00017460486 | C33: =IF(C10="","",(C10/$O$23)) -> 0.011364625 | D33: =IF(D10="","",(D10/$O$23)) -> 0.012549621 | E33: =IF(E10="","",(E10/$O$23)) -> 0.49090941 | F33: =IF(F10="","",(F10/$O$23)) -> 1.5356435 | G33: =IF(G10="","",(G10/$O$23)) -> 0.78093677 | H33: =IF(H10="","",(H10/$O$23)) -> 3.5647253 | I33: =IF(I10="","",(I10/$O$23)) | ... M33: =IF(M10="","",(M10/$O$23)) | O33: =IF(O10="","",(O10/$O$23)) -> 1.1864367 | P33: =IF(P10="","",(P10/$O$23)) -> 1.8925673 | Q33: =IF(Q10="","",(Q10/$O$23)) -> 0.011576467 | R33: =IF(R10="","",(R10/$O$23)) | S33: =IF(S10="","",(S10/$O$23)) | T33: =IF(T10="","",(T10/$O$23)) | U33: =IF(U10="","",(U10/$O$23)) | V33: =IF(V10="","",(V10/$O$23))
B34: =IF(B11="","",(B11/$O$23)) -> 0.011981534 | C34: =IF(C11="","",(C11/$O$23)) -> 0.029312514 | D34: =IF(D11="","",(D11/$O$23)) -> 0.019342246 | E34: =IF(E11="","",(E11/$O$23)) -> 0.76051917 | F34: =IF(F11="","",(F11/$O$23)) -> 1.1265154 | G34: =IF(G11="","",(G11/$O$23)) -> 0.91490214 | H34: =IF(H11="","",(H11/$O$23)) -> 2.5924584 | I34: =IF(I11="","",(I11/$O$23)) | ... M34: =IF(M11="","",(M11/$O$23)) | O34: =IF(O11="","",(O11/$O$23)) -> 0.74618833 | P34: =IF(P11="","",(P11/$O$23)) -> 0.86880728 | Q34: =IF(Q11="","",(Q11/$O$23)) -> 0.017657433 | R34: =IF(R11="","",(R11/$O$23)) | S34: =IF(S11="","",(S11/$O$23)) | T34: =IF(T11="","",(T11/$O$23)) | U34: =IF(U11="","",(U11/$O$23)) | V34: =IF(V11="","",(V11/$O$23))
B35: =IF(B12="","",(B12/$O$23)) -> 0.0042910592 | C35: =IF(C12="","",(C12/$O$23)) -> 0.018932214 | D35: =IF(D12="","",(D12/$O$23)) -> 0.005542256 | E35: =IF(E12="","",(E12/$O$23)) -> 0.17924513 | F35: =IF(F12="","",(F12/$O$23)) -> 1.8287475 | G35: =IF(G12="","",(G12/$O$23)) -> 1.5533982 | H35: =IF(H12="","",(H12/$O$23)) -> 2.4860173 | I35: =IF(I12="","",(I12/$O$23)) | ... M35: =IF(M12="","",(M12/$O$23)) | O35: =IF(O12="","",(O12/$O$23)) -> 0.80558005 | P35: =IF(P12="","",(P12/$O$23)) -> 1.6118349 | Q35: =IF(Q12="","",(Q12/$O$23)) -> 0.010590074 | R35: =IF(R12="","",(R12/$O$23)) | S35: =IF(S12="","",(S12/$O$23)) | T35: =IF(T12="","",(T12/$O$23)) | U35: =IF(U12="","",(U12/$O$23)) | V35: =IF(V12="","",(V12/$O$23))
B36: =IF(B13="","",(B13/$O$23)) | C36: =IF(C13="","",(C13/$O$23)) | D36: =IF(D13="","",(D13/$O$23)) | E36: =IF(E13="","",(E13/$O$23)) | F36: =IF(F13="","",(F13/$O$23)) | G36: =IF(G13="","",(G13/$O$23)) | H36: =IF(H13="","",(H13/$O$23)) | I36: =IF(I13="","",(I13/$O$23)) | ... M36: =IF(M13="","",(M13/$O$23)) | O36: =IF(O13="","",(O13/$O$23)) -> 0.81577665 | P36: =IF(P13="","",(P13/$O$23)) | Q36: =IF(Q13="","",(Q13/$O$23)) | R36: =IF(R13="","",(R13/$O$23)) | S36: =IF(S13="","",(S13/$O$23)) | T36: =IF(T13="","",(T13/$O$23)) | U36: =IF(U13="","",(U13/$O$23)) | V36: =IF(V13="","",(V13/$O$23))
B37: =IF(B14="","",(B14/$O$23)) | C37: =IF(C14="","",(C14/$O$23)) | D37: =IF(D14="","",(D14/$O$23)) | E37: =IF(E14="","",(E14/$O$23)) | F37: =IF(F14="","",(F14/$O$23)) | G37: =IF(G14="","",(G14/$O$23)) | H37: =IF(H14="","",(H14/$O$23)) | I37: =IF(I14="","",(I14/$O$23)) | ... M37: =IF(M14="","",(M14/$O$23)) | O37: =IF(O14="","",(O14/$O$23)) -> 1.0864837 | P37: =IF(P14="","",(P14/$O$23)) | Q37: =IF(Q14="","",(Q14/$O$23)) | R37: =IF(R14="","",(R14/$O$23)) | S37: =IF(S14="","",(S14/$O$23)) | T37: =IF(T14="","",(T14/$O$23)) | U37: =IF(U14="","",(U14/$O$23)) | V37: =IF(V14="","",(V14/$O$23))
B38: =IF(B15="","",(B15/$O$23)) | C38: =IF(C15="","",(C15/$O$23)) | D38: =IF(D15="","",(D15/$O$23)) | E38: =IF(E15="","",(E15/$O$23)) | F38: =IF(F15="","",(F15/$O$23)) | G38: =IF(G15="","",(G15/$O$23)) | H38: =IF(H15="","",(H15/$O$23)) | I38: =IF(I15="","",(I15/$O$23)) | ... M38: =IF(M15="","",(M15/$O$23)) | O38: =IF(O15="","",(O15/$O$23)) -> 1.3406148 | P38: =IF(P15="","",(P15/$O$23)) | Q38: =IF(Q15="","",(Q15/$O$23)) | R38: =IF(R15="","",(R15/$O$23)) | S38: =IF(S15="","",(S15/$O$23)) | T38: =IF(T15="","",(T15/$O$23)) | U38: =IF(U15="","",(U15/$O$23)) | V38: =IF(V15="","",(V15/$O$23))
B39: =IF(B16="","",(B16/$O$23)) | C39: =IF(C16="","",(C16/$O$23)) | D39: =IF(D16="","",(D16/$O$23)) | E39: =IF(E16="","",(E16/$O$23)) | F39: =IF(F16="","",(F16/$O$23)) | G39: =IF(G16="","",(G16/$O$23)) | H39: =IF(H16="","",(H16/$O$23)) | I39: =IF(I16="","",(I16/$O$23)) | ... M39: =IF(M16="","",(M16/$O$23)) | O39: =IF(O16="","",(O16/$O$23)) -> 0.22489933 | P39: =IF(P16="","",(P16/$O$23)) | Q39: =IF(Q16="","",(Q16/$O$23)) | R39: =IF(R16="","",(R16/$O$23)) | S39: =IF(S16="","",(S16/$O$23)) | T39: =IF(T16="","",(T16/$O$23)) | U39: =IF(U16="","",(U16/$O$23)) | V39: =IF(V16="","",(V16/$O$23))
