Workbook

Sheet Page de garde
A1: 1. Expérimentateur 1 : copier et coller le n° de prestation et renseigner la date de réalisation de chaque réplica ainsi que le visa de l'expérimentateur.
A2: R1 | B2: Numéro d'expérience : | E2: Date de réalisation :
A3: R2 | B3: Numéro d'expérience : | E3: Date de réalisation :
A4: R3 | B4: Numéro d'expérience : | E4: Date de réalisation :
A5: 2. Expérimentateur 1 : copier et coller la dilution appliquée et le nom donné pour chaque des échantillons par le client. Conserver la mise en forme de l'exemple en italique. Ne pas remplir la colonne "nom sur graphique".
A6: Nom sur le graphique | B6: Code WF | C6: Concentration | D6: Unité | E6: Nom de l'échantillon donné par le client | F6: Dopage (+Testostérone / + EE2, ….)
A7: =IF(ISBLANK(liste_groupe[[#This Row],[Code WF]])," ",IF(ISBLANK(liste_groupe[[#This Row],[Unité]]),CONCATENATE(liste_groupe[[#This Row],[Nom de l''échantillon donné par le client]],liste_groupe[[#This Row],[Dopage (+Testostérone / + EE2, ….)]]),CONCATENATE(liste_groupe[[#This Row],[Nom de l''échantillon donné par le client]],"-",liste_groupe[[#This Row],[Concentration]],liste_groupe[[#This Row],[Unité]],liste_groupe[[#This Row],[Dopage (+Testostérone / + EE2, ….)]]))) -> Témoin solvant | B7: Témoin | E7: Témoin solvant
A8: =IF(ISBLANK(liste_groupe[[#This Row],[Code WF]])," ",IF(ISBLANK(liste_groupe[[#This Row],[Unité]]),CONCATENATE(liste_groupe[[#This Row],[Nom de l''échantillon donné par le client]],liste_groupe[[#This Row],[Dopage (+Testostérone / + EE2, ….)]]),CONCATENATE(liste_groupe[[#This Row],[Nom de l''échantillon donné par le client]],"-",liste_groupe[[#This Row],[Concentration]],liste_groupe[[#This Row],[Unité]],liste_groupe[[#This Row],[Dopage (+Testostérone / + EE2, ….)]]))) -> EE2-22,5ng/L | B8: Témoin | C8: 22.5 | D8: ng/L | E8: EE2
A9: =IF(ISBLANK(liste_groupe[[#This Row],[Code WF]])," ",IF(ISBLANK(liste_groupe[[#This Row],[Unité]]),CONCATENATE(liste_groupe[[#This Row],[Nom de l''échantillon donné par le client]],liste_groupe[[#This Row],[Dopage (+Testostérone / + EE2, ….)]]),CONCATENATE(liste_groupe[[#This Row],[Nom de l''échantillon donné par le client]],"-",liste_groupe[[#This Row],[Concentration]],liste_groupe[[#This Row],[Unité]],liste_groupe[[#This Row],[Dopage (+Testostérone / + EE2, ….)]]))) -> EE2-33,8ng/L | B9: Témoin | C9: 33.8 | D9: ng/L | E9: EE2
A10: =IF(ISBLANK(liste_groupe[[#This Row],[Code WF]])," ",IF(ISBLANK(liste_groupe[[#This Row],[Unité]]),CONCATENATE(liste_groupe[[#This Row],[Nom de l''échantillon donné par le client]],liste_groupe[[#This Row],[Dopage (+Testostérone / + EE2, ….)]]),CONCATENATE(liste_groupe[[#This Row],[Nom de l''échantillon donné par le client]],"-",liste_groupe[[#This Row],[Concentration]],liste_groupe[[#This Row],[Unité]],liste_groupe[[#This Row],[Dopage (+Testostérone / + EE2, ….)]]))) -> EE2-50,6ng/L | B10: Témoin | C10: 50.6 | D10: ng/L | E10: EE2
A11: =IF(ISBLANK(liste_groupe[[#This Row],[Code WF]])," ",IF(ISBLANK(liste_groupe[[#This Row],[Unité]]),CONCATENATE(liste_groupe[[#This Row],[Nom de l''échantillon donné par le client]],liste_groupe[[#This Row],[Dopage (+Testostérone / + EE2, ….)]]),CONCATENATE(liste_groupe[[#This Row],[Nom de l''échantillon donné par le client]],"-",liste_groupe[[#This Row],[Concentration]],liste_groupe[[#This Row],[Unité]],liste_groupe[[#This Row],[Dopage (+Testostérone / + EE2, ….)]]))) -> EE2-76ng/L | B11: Témoin | C11: 76 | D11: ng/L | E11: EE2
A12: =IF(ISBLANK(liste_groupe[[#This Row],[Code WF]])," ",IF(ISBLANK(liste_groupe[[#This Row],[Unité]]),CONCATENATE(liste_groupe[[#This Row],[Nom de l''échantillon donné par le client]],liste_groupe[[#This Row],[Dopage (+Testostérone / + EE2, ….)]]),CONCATENATE(liste_groupe[[#This Row],[Nom de l''échantillon donné par le client]],"-",liste_groupe[[#This Row],[Concentration]],liste_groupe[[#This Row],[Unité]],liste_groupe[[#This Row],[Dopage (+Testostérone / + EE2, ….)]]))) -> EE2-114ng/L | B12: Témoin | C12: 114 | D12: ng/L | E12: EE2
A13: =IF(ISBLANK(liste_groupe[[#This Row],[Code WF]])," ",IF(ISBLANK(liste_groupe[[#This Row],[Unité]]),CONCATENATE(liste_groupe[[#This Row],[Nom de l''échantillon donné par le client]],liste_groupe[[#This Row],[Dopage (+Testostérone / + EE2, ….)]]),CONCATENATE(liste_groupe[[#This Row],[Nom de l''échantillon donné par le client]],"-",liste_groupe[[#This Row],[Concentration]],liste_groupe[[#This Row],[Unité]],liste_groupe[[#This Row],[Dopage (+Testostérone / + EE2, ….)]]))) -> EE2-170,9ng/L | B13: Témoin | C13: 170.9 | D13: ng/L | E13: EE2
A14: =IF(ISBLANK(liste_groupe[[#This Row],[Code WF]])," ",IF(ISBLANK(liste_groupe[[#This Row],[Unité]]),CONCATENATE(liste_groupe[[#This Row],[Nom de l''échantillon donné par le client]],liste_groupe[[#This Row],[Dopage (+Testostérone / + EE2, ….)]]),CONCATENATE(liste_groupe[[#This Row],[Nom de l''échantillon donné par le client]],"-",liste_groupe[[#This Row],[Concentration]],liste_groupe[[#This Row],[Unité]],liste_groupe[[#This Row],[Dopage (+Testostérone / + EE2, ….)]]))) -> EE2-488ng/L | B14: Témoin | C14: 488 | D14: ng/L | E14: EE2
A15: Testosterone 3,7µg/L | C15: 3.7 | D15: µg/L | E15: Testosterone
A16: Testosterone 11µg/L | C16: 11 | D16: µg/L | E16: Testosterone
A17: Testosterone 33µg/L | C17: 33 | D17: µg/L | E17: Testosterone
A18: Testosterone 100µg/L | C18: 100 | D18: µg/L | E18: Testosterone
A19: Testosterone 300µg/L | C19: 300 | D19: µg/L | E19: Testosterone
A20: =IF(ISBLANK(liste_groupe[[#This Row],[Code WF]])," ",IF(ISBLANK(liste_groupe[[#This Row],[Unité]]),CONCATENATE(liste_groupe[[#This Row],[Nom de l''échantillon donné par le client]],liste_groupe[[#This Row],[Dopage (+Testostérone / + EE2, ….)]]),CONCATENATE(liste_groupe[[#This Row],[Nom de l''échantillon donné par le client]],"-",liste_groupe[[#This Row],[Concentration]],liste_groupe[[#This Row],[Unité]],liste_groupe[[#This Row],[Dopage (+Testostérone / + EE2, ….)]])))
A21: =IF(ISBLANK(liste_groupe[[#This Row],[Code WF]])," ",IF(ISBLANK(liste_groupe[[#This Row],[Unité]]),CONCATENATE(liste_groupe[[#This Row],[Nom de l''échantillon donné par le client]],liste_groupe[[#This Row],[Dopage (+Testostérone / + EE2, ….)]]),CONCATENATE(liste_groupe[[#This Row],[Nom de l''échantillon donné par le client]],"-",liste_groupe[[#This Row],[Concentration]],liste_groupe[[#This Row],[Unité]],liste_groupe[[#This Row],[Dopage (+Testostérone / + EE2, ….)]])))
A22: =IF(ISBLANK(liste_groupe[[#This Row],[Code WF]])," ",IF(ISBLANK(liste_groupe[[#This Row],[Unité]]),CONCATENATE(liste_groupe[[#This Row],[Nom de l''échantillon donné par le client]],liste_groupe[[#This Row],[Dopage (+Testostérone / + EE2, ….)]]),CONCATENATE(liste_groupe[[#This Row],[Nom de l''échantillon donné par le client]],"-",liste_groupe[[#This Row],[Concentration]],liste_groupe[[#This Row],[Unité]],liste_groupe[[#This Row],[Dopage (+Testostérone / + EE2, ….)]])))
A23: =IF(ISBLANK(liste_groupe[[#This Row],[Code WF]])," ",IF(ISBLANK(liste_groupe[[#This Row],[Unité]]),CONCATENATE(liste_groupe[[#This Row],[Nom de l''échantillon donné par le client]],liste_groupe[[#This Row],[Dopage (+Testostérone / + EE2, ….)]]),CONCATENATE(liste_groupe[[#This Row],[Nom de l''échantillon donné par le client]],"-",liste_groupe[[#This Row],[Concentration]],liste_groupe[[#This Row],[Unité]],liste_groupe[[#This Row],[Dopage (+Testostérone / + EE2, ….)]])))
A24: =IF(ISBLANK(liste_groupe[[#This Row],[Code WF]])," ",IF(ISBLANK(liste_groupe[[#This Row],[Unité]]),CONCATENATE(liste_groupe[[#This Row],[Nom de l''échantillon donné par le client]],liste_groupe[[#This Row],[Dopage (+Testostérone / + EE2, ….)]]),CONCATENATE(liste_groupe[[#This Row],[Nom de l''échantillon donné par le client]],"-",liste_groupe[[#This Row],[Concentration]],liste_groupe[[#This Row],[Unité]],liste_groupe[[#This Row],[Dopage (+Testostérone / + EE2, ….)]])))
A25: =IF(ISBLANK(liste_groupe[[#This Row],[Code WF]])," ",IF(ISBLANK(liste_groupe[[#This Row],[Unité]]),CONCATENATE(liste_groupe[[#This Row],[Nom de l''échantillon donné par le client]],liste_groupe[[#This Row],[Dopage (+Testostérone / + EE2, ….)]]),CONCATENATE(liste_groupe[[#This Row],[Nom de l''échantillon donné par le client]],"-",liste_groupe[[#This Row],[Concentration]],liste_groupe[[#This Row],[Unité]],liste_groupe[[#This Row],[Dopage (+Testostérone / + EE2, ….)]])))
A26: =IF(ISBLANK(liste_groupe[[#This Row],[Code WF]])," ",IF(ISBLANK(liste_groupe[[#This Row],[Unité]]),CONCATENATE(liste_groupe[[#This Row],[Nom de l''échantillon donné par le client]],liste_groupe[[#This Row],[Dopage (+Testostérone / + EE2, ….)]]),CONCATENATE(liste_groupe[[#This Row],[Nom de l''échantillon donné par le client]],"-",liste_groupe[[#This Row],[Concentration]],liste_groupe[[#This Row],[Unité]],liste_groupe[[#This Row],[Dopage (+Testostérone / + EE2, ….)]])))
A27: =IF(ISBLANK(liste_groupe[[#This Row],[Code WF]])," ",IF(ISBLANK(liste_groupe[[#This Row],[Unité]]),CONCATENATE(liste_groupe[[#This Row],[Nom de l''échantillon donné par le client]],liste_groupe[[#This Row],[Dopage (+Testostérone / + EE2, ….)]]),CONCATENATE(liste_groupe[[#This Row],[Nom de l''échantillon donné par le client]],"-",liste_groupe[[#This Row],[Concentration]],liste_groupe[[#This Row],[Unité]],liste_groupe[[#This Row],[Dopage (+Testostérone / + EE2, ….)]])))
A28: =IF(ISBLANK(liste_groupe[[#This Row],[Code WF]])," ",IF(ISBLANK(liste_groupe[[#This Row],[Unité]]),CONCATENATE(liste_groupe[[#This Row],[Nom de l''échantillon donné par le client]],liste_groupe[[#This Row],[Dopage (+Testostérone / + EE2, ….)]]),CONCATENATE(liste_groupe[[#This Row],[Nom de l''échantillon donné par le client]],"-",liste_groupe[[#This Row],[Concentration]],liste_groupe[[#This Row],[Unité]],liste_groupe[[#This Row],[Dopage (+Testostérone / + EE2, ….)]])))
A29: =IF(ISBLANK(liste_groupe[[#This Row],[Code WF]])," ",IF(ISBLANK(liste_groupe[[#This Row],[Unité]]),CONCATENATE(liste_groupe[[#This Row],[Nom de l''échantillon donné par le client]],liste_groupe[[#This Row],[Dopage (+Testostérone / + EE2, ….)]]),CONCATENATE(liste_groupe[[#This Row],[Nom de l''échantillon donné par le client]],"-",liste_groupe[[#This Row],[Concentration]],liste_groupe[[#This Row],[Unité]],liste_groupe[[#This Row],[Dopage (+Testostérone / + EE2, ….)]])))
A30: =IF(ISBLANK(liste_groupe[[#This Row],[Code WF]])," ",IF(ISBLANK(liste_groupe[[#This Row],[Unité]]),CONCATENATE(liste_groupe[[#This Row],[Nom de l''échantillon donné par le client]],liste_groupe[[#This Row],[Dopage (+Testostérone / + EE2, ….)]]),CONCATENATE(liste_groupe[[#This Row],[Nom de l''échantillon donné par le client]],"-",liste_groupe[[#This Row],[Concentration]],liste_groupe[[#This Row],[Unité]],liste_groupe[[#This Row],[Dopage (+Testostérone / + EE2, ….)]])))
A31: =IF(ISBLANK(liste_groupe[[#This Row],[Code WF]])," ",IF(ISBLANK(liste_groupe[[#This Row],[Unité]]),CONCATENATE(liste_groupe[[#This Row],[Nom de l''échantillon donné par le client]],liste_groupe[[#This Row],[Dopage (+Testostérone / + EE2, ….)]]),CONCATENATE(liste_groupe[[#This Row],[Nom de l''échantillon donné par le client]],"-",liste_groupe[[#This Row],[Concentration]],liste_groupe[[#This Row],[Unité]],liste_groupe[[#This Row],[Dopage (+Testostérone / + EE2, ….)]])))
... A35: =IF(ISBLANK(liste_groupe[[#This Row],[Code WF]])," ",IF(ISBLANK(liste_groupe[[#This Row],[Unité]]),CONCATENATE(liste_groupe[[#This Row],[Nom de l''échantillon donné par le client]],liste_groupe[[#This Row],[Dopage (+Testostérone / + EE2, ….)]]),CONCATENATE(liste_groupe[[#This Row],[Nom de l''échantillon donné par le client]],"-",liste_groupe[[#This Row],[Concentration]],liste_groupe[[#This Row],[Unité]],liste_groupe[[#This Row],[Dopage (+Testostérone / + EE2, ….)]])))
A36: =IF(ISBLANK(liste_groupe[[#This Row],[Code WF]])," ",IF(ISBLANK(liste_groupe[[#This Row],[Unité]]),CONCATENATE(liste_groupe[[#This Row],[Nom de l''échantillon donné par le client]],liste_groupe[[#This Row],[Dopage (+Testostérone / + EE2, ….)]]),CONCATENATE(liste_groupe[[#This Row],[Nom de l''échantillon donné par le client]],"-",liste_groupe[[#This Row],[Concentration]],liste_groupe[[#This Row],[Unité]],liste_groupe[[#This Row],[Dopage (+Testostérone / + EE2, ….)]]))) -> Testo -30µg/L | B36: Témoin | C36: 30 | D36: µg/L | E36: Testo
A37: =IF(ISBLANK(liste_groupe[[#This Row],[Code WF]])," ",IF(ISBLANK(liste_groupe[[#This Row],[Unité]]),CONCATENATE(liste_groupe[[#This Row],[Nom de l''échantillon donné par le client]],liste_groupe[[#This Row],[Dopage (+Testostérone / + EE2, ….)]]),CONCATENATE(liste_groupe[[#This Row],[Nom de l''échantillon donné par le client]],"-",liste_groupe[[#This Row],[Concentration]],liste_groupe[[#This Row],[Unité]],liste_groupe[[#This Row],[Dopage (+Testostérone / + EE2, ….)]]))) -> Testo 30µg/L + EE2 -64ng/L | B37: Témoin | C37: 64 | D37: ng/L | E37: Testo 30µg/L + EE2
A38: =IF(ISBLANK(liste_groupe[[#This Row],[Code WF]])," ",IF(ISBLANK(liste_groupe[[#This Row],[Unité]]),CONCATENATE(liste_groupe[[#This Row],[Nom de l''échantillon donné par le client]],liste_groupe[[#This Row],[Dopage (+Testostérone / + EE2, ….)]]),CONCATENATE(liste_groupe[[#This Row],[Nom de l''échantillon donné par le client]],"-",liste_groupe[[#This Row],[Concentration]],liste_groupe[[#This Row],[Unité]],liste_groupe[[#This Row],[Dopage (+Testostérone / + EE2, ….)]]))) -> Testo 30µg/L + FAD-10µg/L | B38: Témoin | C38: 10 | D38: µg/L | E38: Testo 30µg/L + FAD
A39: =IF(ISBLANK(liste_groupe[[#This Row],[Code WF]])," ",IF(ISBLANK(liste_groupe[[#This Row],[Unité]]),CONCATENATE(liste_groupe[[#This Row],[Nom de l''échantillon donné par le client]],liste_groupe[[#This Row],[Dopage (+Testostérone / + EE2, ….)]]),CONCATENATE(liste_groupe[[#This Row],[Nom de l''échantillon donné par le client]],"-",liste_groupe[[#This Row],[Concentration]],liste_groupe[[#This Row],[Unité]],liste_groupe[[#This Row],[Dopage (+Testostérone / + EE2, ….)]]))) -> Testosterone-3,7µg/L + Testostérone | B39: =B15 -> 0 | C39: =C15 -> 3.7 | D39: =D15 -> µg/L | E39: =E15 -> Testosterone | F39: + Testostérone
A40: =IF(ISBLANK(liste_groupe[[#This Row],[Code WF]])," ",IF(ISBLANK(liste_groupe[[#This Row],[Unité]]),CONCATENATE(liste_groupe[[#This Row],[Nom de l''échantillon donné par le client]],liste_groupe[[#This Row],[Dopage (+Testostérone / + EE2, ….)]]),CONCATENATE(liste_groupe[[#This Row],[Nom de l''échantillon donné par le client]],"-",liste_groupe[[#This Row],[Concentration]],liste_groupe[[#This Row],[Unité]],liste_groupe[[#This Row],[Dopage (+Testostérone / + EE2, ….)]]))) -> Testosterone-11µg/L + Testostérone | B40: =B16 -> 0 | C40: =C16 -> 11 | D40: =D16 -> µg/L | E40: =E16 -> Testosterone | F40: + Testostérone
A41: =IF(ISBLANK(liste_groupe[[#This Row],[Code WF]])," ",IF(ISBLANK(liste_groupe[[#This Row],[Unité]]),CONCATENATE(liste_groupe[[#This Row],[Nom de l''échantillon donné par le client]],liste_groupe[[#This Row],[Dopage (+Testostérone / + EE2, ….)]]),CONCATENATE(liste_groupe[[#This Row],[Nom de l''échantillon donné par le client]],"-",liste_groupe[[#This Row],[Concentration]],liste_groupe[[#This Row],[Unité]],liste_groupe[[#This Row],[Dopage (+Testostérone / + EE2, ….)]]))) -> Testosterone-33µg/L + Testostérone | B41: =B17 -> 0 | C41: =C17 -> 33 | D41: =D17 -> µg/L | E41: =E17 -> Testosterone | F41: + Testostérone
A42: =IF(ISBLANK(liste_groupe[[#This Row],[Code WF]])," ",IF(ISBLANK(liste_groupe[[#This Row],[Unité]]),CONCATENATE(liste_groupe[[#This Row],[Nom de l''échantillon donné par le client]],liste_groupe[[#This Row],[Dopage (+Testostérone / + EE2, ….)]]),CONCATENATE(liste_groupe[[#This Row],[Nom de l''échantillon donné par le client]],"-",liste_groupe[[#This Row],[Concentration]],liste_groupe[[#This Row],[Unité]],liste_groupe[[#This Row],[Dopage (+Testostérone / + EE2, ….)]]))) -> Testosterone-100µg/L + Testostérone | B42: =B18 -> 0 | C42: =C18 -> 100 | D42: =D18 -> µg/L | E42: =E18 -> Testosterone | F42: + Testostérone
A43: =IF(ISBLANK(liste_groupe[[#This Row],[Code WF]])," ",IF(ISBLANK(liste_groupe[[#This Row],[Unité]]),CONCATENATE(liste_groupe[[#This Row],[Nom de l''échantillon donné par le client]],liste_groupe[[#This Row],[Dopage (+Testostérone / + EE2, ….)]]),CONCATENATE(liste_groupe[[#This Row],[Nom de l''échantillon donné par le client]],"-",liste_groupe[[#This Row],[Concentration]],liste_groupe[[#This Row],[Unité]],liste_groupe[[#This Row],[Dopage (+Testostérone / + EE2, ….)]]))) -> Testosterone-300µg/L + Testostérone | B43: =B19 -> 0 | C43: =C19 -> 300 | D43: =D19 -> µg/L | E43: =E19 -> Testosterone | F43: + Testostérone
...

Sheet Feuil1
A1: Nom groupe | B1: N° de valeur | C1: file name | D1: total area | E1: mean intensity | G1: total fluorescence | I1: nbre de larves
A2: 01 EE2 0 | B2: A | C2: C:\Users\Olympus\Desktop\20190122\plaque1/@01 EE2 0/A1_1.tif | D2: 4931.616 | E2: 73.0526 | G2: 360268
A3: 01 EE2 0 | B3: A | C3: C:\Users\Olympus\Desktop\20190122\plaque1/@01 EE2 0/A1_2.tif | D3: 5234.4345 | E3: 71.1281 | G3: 372315
A4: 01 EE2 0 | B4: A | C4: C:\Users\Olympus\Desktop\20190122\plaque1/@01 EE2 0/A1_3.tif | D4: 3547.3027 | E4: 66.9878 | G4: 237626
A5: 01 EE2 0 | B5: A | C5: C:\Users\Olympus\Desktop\20190122\plaque3/@01 EE2 0/A1_3.tif | D5: 21456.8555 | E5: 67.0655 | G5: 1439015
A6: 01 EE2 0 | B6: A | C6: C:\Users\Olympus\Desktop\20190122\plaque3/@01 EE2 0/A1_2.tif | D6: 21586.6348 | E6: 66.4108 | G6: 1433586
A7: 01 EE2 0 | B7: A | C7: C:\Users\Olympus\Desktop\20190122\plaque3/@01 EE2 0/A1_1.tif | D7: 15984.4921 | E7: 69.7767 | G7: 1115346

Sheet Raw data R1
A1: Nom groupe | B1: N° de valeur | C1: file name | D1: total area | E1: mean intensity | G1: total fluorescence | I1: nbre de larves | J1: Colonne1 | L1: (Tous)
A2: =IFERROR(LEFT(RIGHT(C2,LEN(C2)-SEARCH("@",C2)),SEARCH("/",RIGHT(C2,LEN(C2)-SEARCH("@",C2)-1))),"") -> 01 Evian + 0.2% DMSO | B2: =LEFT(RIGHT(RIGHT(Tableau4[[#This Row],[file name]],LEN(Tableau4[[#This Row],[file name]])-SEARCH("@",Tableau4[[#This Row],[file name]])),LEN(RIGHT(Tableau4[[#This Row],[file name]],LEN(Tableau4[[#This Row],[file name]])-SEARCH("@",Tableau4[[#This Row],[file name]])))-SEARCH("/",RIGHT(Tableau4[[#This Row],[file name]],LEN(Tableau4[[#This Row],[file name]])-SEARCH("@",Tableau4[[#This Row],[file name]])))),1) -> A | C2: F:\images\20210304\plaque 1/@01 Evian + 0.2% DMSO/A1_01.tif | D2: 2660.477 | E2: 66.2439 | G2: 176240 | K2: Filtre lignes : Enlever (vide) et Néant | L2: Filtre colonnes : Enlever (vide) et " "
A3: =IFERROR(LEFT(RIGHT(C3,LEN(C3)-SEARCH("@",C3)),SEARCH("/",RIGHT(C3,LEN(C3)-SEARCH("@",C3)-1))),"") -> 01 Evian + 0.2% DMSO | B3: =LEFT(RIGHT(RIGHT(Tableau4[[#This Row],[file name]],LEN(Tableau4[[#This Row],[file name]])-SEARCH("@",Tableau4[[#This Row],[file name]])),LEN(RIGHT(Tableau4[[#This Row],[file name]],LEN(Tableau4[[#This Row],[file name]])-SEARCH("@",Tableau4[[#This Row],[file name]])))-SEARCH("/",RIGHT(Tableau4[[#This Row],[file name]],LEN(Tableau4[[#This Row],[file name]])-SEARCH("@",Tableau4[[#This Row],[file name]])))),1) -> A | C3: F:\images\20210304\plaque 1/@01 Evian + 0.2% DMSO/A1_02.tif | D3: 237.9288 | E3: 63.6364 | G3: 15141 | K3: Moyenne de total fluorescence | L3: Étiquettes de colonnes
A4: =IFERROR(LEFT(RIGHT(C4,LEN(C4)-SEARCH("@",C4)),SEARCH("/",RIGHT(C4,LEN(C4)-SEARCH("@",C4)-1))),"") -> 01 Evian + 0.2% DMSO | B4: =LEFT(RIGHT(RIGHT(Tableau4[[#This Row],[file name]],LEN(Tableau4[[#This Row],[file name]])-SEARCH("@",Tableau4[[#This Row],[file name]])),LEN(RIGHT(Tableau4[[#This Row],[file name]],LEN(Tableau4[[#This Row],[file name]])-SEARCH("@",Tableau4[[#This Row],[file name]])))-SEARCH("/",RIGHT(Tableau4[[#This Row],[file name]],LEN(Tableau4[[#This Row],[file name]])-SEARCH("@",Tableau4[[#This Row],[file name]])))),1) -> A | C4: F:\images\20210304\plaque 1/@01 Evian + 0.2% DMSO/A1_03.tif | D4: 237.9288 | E4: 62.7273 | G4: 14925 | K4: Étiquettes de lignes | L4: 01 Evian + 0.2% DMSO | M4: 02 EE2 33.8 | N4: 03 EE2 50.6 | O4: 04 EE2 76 | P4: 05 EE2 114 | Q4: 06 EE2 170.9 | R4: 07 EE2 488 | S4: 08 Testosterone 3.7 µg_L | T4: 09 Testosterone 11 µg_L | U4: 10 Testosterone 33 µg_L | V4: 11 Testosterone 100 µg_L | W4: 12 Testosterone 300 µg_L | X4: 01 Testo 30 | Y4: 02 Testo 30 | Z4: 03 Testo+ EE2 64 | AA4: 04 Testo+ FAD | AB4: 05 Testosterone 3.7 µg_L dopé | AC4: 06 Testosterone 11 µg_Ldopé | AD4: 07 Testosterone 33 µg_Ldopé | AE4: 08 Testosterone 100 µg_Ldopé | AF4: 09 Testosterone 300 µg_L dopé
A5: =IFERROR(LEFT(RIGHT(C5,LEN(C5)-SEARCH("@",C5)),SEARCH("/",RIGHT(C5,LEN(C5)-SEARCH("@",C5)-1))),"") -> 01 Evian + 0.2% DMSO | B5: =LEFT(RIGHT(RIGHT(Tableau4[[#This Row],[file name]],LEN(Tableau4[[#This Row],[file name]])-SEARCH("@",Tableau4[[#This Row],[file name]])),LEN(RIGHT(Tableau4[[#This Row],[file name]],LEN(Tableau4[[#This Row],[file name]])-SEARCH("@",Tableau4[[#This Row],[file name]])))-SEARCH("/",RIGHT(Tableau4[[#This Row],[file name]],LEN(Tableau4[[#This Row],[file name]])-SEARCH("@",Tableau4[[#This Row],[file name]])))),1) -> B | C5: F:\images\20210304\plaque 1/@01 Evian + 0.2% DMSO/B1_01.tif | D5: 10987.9865 | E5: 69.3563 | G5: 762086 | K5: A | L5: 68768.667 | M5: 117774.67 | N5: 61234 | O5: 804891.67 | P5: 1291982.3 | Q5: 3183070 | R5: 7591134.3 | S5: 316207.5 | T5: 449130.33 | U5: 364911 | V5: 3101734.3 | W5: 1137155.7 | X5: 3308443.7 | Y5: 4555356.7 | Z5: 4775199.5 | AA5: 190047.33 | AB5: 4143581.3 | AC5: 4570317.3 | AD5: 3195658.3 | AE5: 2425662.7 | AF5: 3811641.7
A6: =IFERROR(LEFT(RIGHT(C6,LEN(C6)-SEARCH("@",C6)),SEARCH("/",RIGHT(C6,LEN(C6)-SEARCH("@",C6)-1))),"") -> 01 Evian + 0.2% DMSO | B6: =LEFT(RIGHT(RIGHT(Tableau4[[#This Row],[file name]],LEN(Tableau4[[#This Row],[file name]])-SEARCH("@",Tableau4[[#This Row],[file name]])),LEN(RIGHT(Tableau4[[#This Row],[file name]],LEN(Tableau4[[#This Row],[file name]])-SEARCH("@",Tableau4[[#This Row],[file name]])))-SEARCH("/",RIGHT(Tableau4[[#This Row],[file name]],LEN(Tableau4[[#This Row],[file name]])-SEARCH("@",Tableau4[[#This Row],[file name]])))),1) -> B | C6: F:\images\20210304\plaque 1/@01 Evian + 0.2% DMSO/B1_02.tif | D6: 6791.7869 | E6: 64.9363 | G6: 441034 | K6: B | L6: 475692 | M6: 353551 | N6: 183320.67 | O6: 241007.67 | P6: 2077897.7 | Q6: 3757920.3 | R6: 5661120.3 | S6: 279512 | T6: 38991.333 | U6: 3691869.7 | V6: 3529054.3 | W6: 3980621.7 | X6: 97713 | Y6: 872571.33 | Z6: 5366412.7 | AA6: 108928 | AB6: 1600583.3 | AC6: 4237361.3 | AD6: 3253850 | AE6: 3705604.7 | AF6: 4674436.5
A7: =IFERROR(LEFT(RIGHT(C7,LEN(C7)-SEARCH("@",C7)),SEARCH("/",RIGHT(C7,LEN(C7)-SEARCH("@",C7)-1))),"") -> 01 Evian + 0.2% DMSO | B7: =LEFT(RIGHT(RIGHT(Tableau4[[#This Row],[file name]],LEN(Tableau4[[#This Row],[file name]])-SEARCH("@",Tableau4[[#This Row],[file name]])),LEN(RIGHT(Tableau4[[#This Row],[file name]],LEN(Tableau4[[#This Row],[file name]])-SEARCH("@",Tableau4[[#This Row],[file name]])))-SEARCH("/",RIGHT(Tableau4[[#This Row],[file name]],LEN(Tableau4[[#This Row],[file name]])-SEARCH("@",Tableau4[[#This Row],[file name]])))),1) -> B | C7: F:\images\20210304\plaque 1/@01 Evian + 0.2% DMSO/B1_03.tif | D7: 3525.6728 | E7: 63.5215 | G7: 223956 | K7: C | L7: 299847.67 | M7: 450665.67 | N7: 183882.67 | O7: 380556.33 | P7: 1025495 | Q7: 3448338.7 | R7: 7082716.3 | S7: 75589.667 | T7: 168230 | U7: 3644377.3 | V7: 3511555.7 | W7: 2428467.7 | X7: 2785577.3 | Y7: 1911866.7 | Z7: 2757054.7 | AA7: 98293.333 | AB7: 2411242.7 | AC7: 1381278 | AD7: 1831792.3 | AE7: 373148.5 | AF7: 4489667
A8: =IFERROR(LEFT(RIGHT(C8,LEN(C8)-SEARCH("@",C8)),SEARCH("/",RIGHT(C8,LEN(C8)-SEARCH("@",C8)-1))),"") -> 01 Evian + 0.2% DMSO | B8: =LEFT(RIGHT(RIGHT(Tableau4[[#This Row],[file name]],LEN(Tableau4[[#This Row],[file name]])-SEARCH("@",Tableau4[[#This Row],[file name]])),LEN(RIGHT(Tableau4[[#This Row],[file name]],LEN(Tableau4[[#This Row],[file name]])-SEARCH("@",Tableau4[[#This Row],[file name]])))-SEARCH("/",RIGHT(Tableau4[[#This Row],[file name]],LEN(Tableau4[[#This Row],[file name]])-SEARCH("@",Tableau4[[#This Row],[file name]])))),1) -> C | C8: F:\images\20210304\plaque 1/@01 Evian + 0.2% DMSO/C1_01.tif | D8: 4304.349 | E8: 71.9548 | G8: 309718 | K8: D | L8: 10598.667 | M8: 108459.33 | N8: 59266 | O8: 218548 | P8: 2209191 | Q8: 612486.67 | R8: 6204261 | S8: 216753 | T8: 82496.5 | U8: 2777494.7 | V8: 1464344 | W8: 4806617 | X8: 3859169.7 | Y8: 3733702.3 | Z8: 4483174 | AA8: 80874 | AB8: 1506911.3 | AC8: 1828677.7 | AD8: 1484921.3 | AE8: 2876206.3 | AF8: 3181317.7
A9: =IFERROR(LEFT(RIGHT(C9,LEN(C9)-SEARCH("@",C9)),SEARCH("/",RIGHT(C9,LEN(C9)-SEARCH("@",C9)-1))),"") -> 01 Evian + 0.2% DMSO | B9: =LEFT(RIGHT(RIGHT(Tableau4[[#This Row],[file name]],LEN(Tableau4[[#This Row],[file name]])-SEARCH("@",Tableau4[[#This Row],[file name]])),LEN(RIGHT(Tableau4[[#This Row],[file name]],LEN(Tableau4[[#This Row],[file name]])-SEARCH("@",Tableau4[[#This Row],[file name]])))-SEARCH("/",RIGHT(Tableau4[[#This Row],[file name]],LEN(Tableau4[[#This Row],[file name]])-SEARCH("@",Tableau4[[#This Row],[file name]])))),1) -> C | C9: F:\images\20210304\plaque 1/@01 Evian + 0.2% DMSO/C1_02.tif | D9: 3893.381 | E9: 70.35 | G9: 273899 | K9: E | L9: 13684.333 | M9: 334946.33 | N9: 94003.5 | O9: 3039735.7 | P9: 827163.33 | Q9: 3525521.5 | R9: 3664198 | S9: 16338 | T9: 111992.33 | U9: 4078417.7 | V9: 3553525 | W9: 1695726 | X9: 2492420 | Y9: 24060 | Z9: 1136074.3 | AB9: 4343794.7 | AC9: 4424157 | AD9: 795115 | AF9: 2115324.3
A10: =IFERROR(LEFT(RIGHT(C10,LEN(C10)-SEARCH("@",C10)),SEARCH("/",RIGHT(C10,LEN(C10)-SEARCH("@",C10)-1))),"") -> 01 Evian + 0.2% DMSO | B10: =LEFT(RIGHT(RIGHT(Tableau4[[#This Row],[file name]],LEN(Tableau4[[#This Row],[file name]])-SEARCH("@",Tableau4[[#This Row],[file name]])),LEN(RIGHT(Tableau4[[#This Row],[file name]],LEN(Tableau4[[#This Row],[file name]])-SEARCH("@",Tableau4[[#This Row],[file name]])))-SEARCH("/",RIGHT(Tableau4[[#This Row],[file name]],LEN(Tableau4[[#This Row],[file name]])-SEARCH("@",Tableau4[[#This Row],[file name]])))),1) -> C | C10: F:\images\20210304\plaque 1/@01 Evian + 0.2% DMSO/C1_03.tif | D10: 4672.0572 | E10: 67.6204 | G10: 315926 | K10: F | L10: 33735.667 | M10: 13540.333 | N10: 16345 | O10: 184120.67 | P10: 582723.67 | Q10: 2931045 | R10: 5786768.3 | S10: 103261.33 | T10: 37214.5 | U10: 101869.67 | V10: 2515773.3 | W10: 1694521.7 | X10: 2586719 | Y10: 1584894.3 | Z10: 4541585.7 | AA10: 206298.67 | AB10: 2589855.3 | AC10: 2713535.3 | AD10: 2159946.7 | AE10: 2030852.3 | AF10: 3999028.3
A11: =IFERROR(LEFT(RIGHT(C11,LEN(C11)-SEARCH("@",C11)),SEARCH("/",RIGHT(C11,LEN(C11)-SEARCH("@",C11)-1))),"") -> 01 Evian + 0.2% DMSO | B11: =LEFT(RIGHT(RIGHT(Tableau4[[#This Row],[file name]],LEN(Tableau4[[#This Row],[file name]])-SEARCH("@",Tableau4[[#This Row],[file name]])),LEN(RIGHT(Tableau4[[#This Row],[file name]],LEN(Tableau4[[#This Row],[file name]])-SEARCH("@",Tableau4[[#This Row],[file name]])))-SEARCH("/",RIGHT(Tableau4[[#This Row],[file name]],LEN(Tableau4[[#This Row],[file name]])-SEARCH("@",Tableau4[[#This Row],[file name]])))),1) -> D | C11: F:\images\20210304\plaque 1/@01 Evian + 0.2% DMSO/D1_01.tif | D11: 302.8185 | E11: 64.5 | G11: 19532 | K11: G | L11: 232391.33 | M11: 75481 | N11: 97219 | O11: 654672 | P11: 2310779.3 | Q11: 3257365 | R11: 5149306.7 | S11: 29676.333 | T11: 91505 | U11: 1198505 | V11: 3638890.7 | W11: 1914505.3 | X11: 1719857.7 | Y11: 3421726.7 | Z11: 6096804 | AA11: 116282.33 | AB11: 2873401.7 | AC11: 3984039.3 | AD11: 2123652 | AE11: 1787307 | AF11: 2804864
A12: =IFERROR(LEFT(RIGHT(C12,LEN(C12)-SEARCH("@",C12)),SEARCH("/",RIGHT(C12,LEN(C12)-SEARCH("@",C12)-1))),"") -> 01 Evian + 0.2% DMSO | B12: =LEFT(RIGHT(RIGHT(Tableau4[[#This Row],[file name]],LEN(Tableau4[[#This Row],[file name]])-SEARCH("@",Tableau4[[#This Row],[file name]])),LEN(RIGHT(Tableau4[[#This Row],[file name]],LEN(Tableau4[[#This Row],[file name]])-SEARCH("@",Tableau4[[#This Row],[file name]])))-SEARCH("/",RIGHT(Tableau4[[#This Row],[file name]],LEN(Tableau4[[#This Row],[file name]])-SEARCH("@",Tableau4[[#This Row],[file name]])))),1) -> D | C12: F:\images\20210304\plaque 1/@01 Evian + 0.2% DMSO/D1_02.tif | D12: 108.1495 | E12: 64.8 | G12: 7008 | K12: H | L12: 12048 | M12: 191435.5 | N12: 191489.5 | O12: 182888 | P12: 2356627.3 | R12: 7155472 | S12: 30981 | T12: 26172 | U12: 1005667.3 | V12: 1664824 | W12: 3085494 | X12: 554720.33 | Y12: 280251.33 | Z12: 4954421 | AA12: 320605.33 | AB12: 1912436 | AC12: 2755922.7 | AD12: 3391257.3 | AE12: 2833029.5 | AF12: 2048675.3
A13: =IFERROR(LEFT(RIGHT(C13,LEN(C13)-SEARCH("@",C13)),SEARCH("/",RIGHT(C13,LEN(C13)-SEARCH("@",C13)-1))),"") -> 01 Evian + 0.2% DMSO | B13: =LEFT(RIGHT(RIGHT(Tableau4[[#This Row],[file name]],LEN(Tableau4[[#This Row],[file name]])-SEARCH("@",Tableau4[[#This Row],[file name]])),LEN(RIGHT(Tableau4[[#This Row],[file name]],LEN(Tableau4[[#This Row],[file name]])-SEARCH("@",Tableau4[[#This Row],[file name]])))-SEARCH("/",RIGHT(Tableau4[[#This Row],[file name]],LEN(Tableau4[[#This Row],[file name]])-SEARCH("@",Tableau4[[#This Row],[file name]])))),1) -> D | C13: F:\images\20210304\plaque 1/@01 Evian + 0.2% DMSO/D1_03.tif | D13: 86.5196 | E13: 60.75 | G13: 5256
A14: =IFERROR(LEFT(RIGHT(C14,LEN(C14)-SEARCH("@",C14)),SEARCH("/",RIGHT(C14,LEN(C14)-SEARCH("@",C14)-1))),"") -> 01 Evian + 0.2% DMSO | B14: =LEFT(RIGHT(RIGHT(Tableau4[[#This Row],[file name]],LEN(Tableau4[[#This Row],[file name]])-SEARCH("@",Tableau4[[#This Row],[file name]])),LEN(RIGHT(Tableau4[[#This Row],[file name]],LEN(Tableau4[[#This Row],[file name]])-SEARCH("@",Tableau4[[#This Row],[file name]])))-SEARCH("/",RIGHT(Tableau4[[#This Row],[file name]],LEN(Tableau4[[#This Row],[file name]])-SEARCH("@",Tableau4[[#This Row],[file name]])))),1) -> E | C14: F:\images\20210304\plaque 1/@01 Evian + 0.2% DMSO/E1_01.tif | D14: 173.0392 | E14: 65.375 | G14: 11312
A15: =IFERROR(LEFT(RIGHT(C15,LEN(C15)-SEARCH("@",C15)),SEARCH("/",RIGHT(C15,LEN(C15)-SEARCH("@",C15)-1))),"") -> 01 Evian + 0.2% DMSO | B15: =LEFT(RIGHT(RIGHT(Tableau4[[#This Row],[file name]],LEN(Tableau4[[#This Row],[file name]])-SEARCH("@",Tableau4[[#This Row],[file name]])),LEN(RIGHT(Tableau4[[#This Row],[file name]],LEN(Tableau4[[#This Row],[file name]])-SEARCH("@",Tableau4[[#This Row],[file name]])))-SEARCH("/",RIGHT(Tableau4[[#This Row],[file name]],LEN(Tableau4[[#This Row],[file name]])-SEARCH("@",Tableau4[[#This Row],[file name]])))),1) -> E | C15: F:\images\20210304\plaque 1/@01 Evian + 0.2% DMSO/E1_02.tif | D15: 281.1886 | E15: 65.2308 | G15: 18342
A16: =IFERROR(LEFT(RIGHT(C16,LEN(C16)-SEARCH("@",C16)),SEARCH("/",RIGHT(C16,LEN(C16)-SEARCH("@",C16)-1))),"") -> 01 Evian + 0.2% DMSO | B16: =LEFT(RIGHT(RIGHT(Tableau4[[#This Row],[file name]],LEN(Tableau4[[#This Row],[file name]])-SEARCH("@",Tableau4[[#This Row],[file name]])),LEN(RIGHT(Tableau4[[#This Row],[file name]],LEN(Tableau4[[#This Row],[file name]])-SEARCH("@",Tableau4[[#This Row],[file name]])))-SEARCH("/",RIGHT(Tableau4[[#This Row],[file name]],LEN(Tableau4[[#This Row],[file name]])-SEARCH("@",Tableau4[[#This Row],[file name]])))),1) -> E | C16: F:\images\20210304\plaque 1/@01 Evian + 0.2% DMSO/E1_03.tif | D16: 173.0392 | E16: 65.875 | G16: 11399
A17: =IFERROR(LEFT(RIGHT(C17,LEN(C17)-SEARCH("@",C17)),SEARCH("/",RIGHT(C17,LEN(C17)-SEARCH("@",C17)-1))),"") -> 01 Evian + 0.2% DMSO | B17: =LEFT(RIGHT(RIGHT(Tableau4[[#This Row],[file name]],LEN(Tableau4[[#This Row],[file name]])-SEARCH("@",Tableau4[[#This Row],[file name]])),LEN(RIGHT(Tableau4[[#This Row],[file name]],LEN(Tableau4[[#This Row],[file name]])-SEARCH("@",Tableau4[[#This Row],[file name]])))-SEARCH("/",RIGHT(Tableau4[[#This Row],[file name]],LEN(Tableau4[[#This Row],[file name]])-SEARCH("@",Tableau4[[#This Row],[file name]])))),1) -> F | C17: F:\images\20210304\plaque 1/@01 Evian + 0.2% DMSO/F1_01.tif | D17: 670.5267 | E17: 65.3226 | G17: 43801
A18: =IFERROR(LEFT(RIGHT(C18,LEN(C18)-SEARCH("@",C18)),SEARCH("/",RIGHT(C18,LEN(C18)-SEARCH("@",C18)-1))),"") -> 01 Evian + 0.2% DMSO | B18: =LEFT(RIGHT(RIGHT(Tableau4[[#This Row],[file name]],LEN(Tableau4[[#This Row],[file name]])-SEARCH("@",Tableau4[[#This Row],[file name]])),LEN(RIGHT(Tableau4[[#This Row],[file name]],LEN(Tableau4[[#This Row],[file name]])-SEARCH("@",Tableau4[[#This Row],[file name]])))-SEARCH("/",RIGHT(Tableau4[[#This Row],[file name]],LEN(Tableau4[[#This Row],[file name]])-SEARCH("@",Tableau4[[#This Row],[file name]])))),1) -> F | C18: F:\images\20210304\plaque 1/@01 Evian + 0.2% DMSO/F1_02.tif | D18: 713.7865 | E18: 64.8788 | G18: 46310
A19: =IFERROR(LEFT(RIGHT(C19,LEN(C19)-SEARCH("@",C19)),SEARCH("/",RIGHT(C19,LEN(C19)-SEARCH("@",C19)-1))),"") -> 01 Evian + 0.2% DMSO | B19: =LEFT(RIGHT(RIGHT(Tableau4[[#This Row],[file name]],LEN(Tableau4[[#This Row],[file name]])-SEARCH("@",Tableau4[[#This Row],[file name]])),LEN(RIGHT(Tableau4[[#This Row],[file name]],LEN(Tableau4[[#This Row],[file name]])-SEARCH("@",Tableau4[[#This Row],[file name]])))-SEARCH("/",RIGHT(Tableau4[[#This Row],[file name]],LEN(Tableau4[[#This Row],[file name]])-SEARCH("@",Tableau4[[#This Row],[file name]])))),1) -> F | C19: F:\images\20210304\plaque 1/@01 Evian + 0.2% DMSO/F1_03.tif | D19: 173.0392 | E19: 64.125 | G19: 11096
A20: =IFERROR(LEFT(RIGHT(C20,LEN(C20)-SEARCH("@",C20)),SEARCH("/",RIGHT(C20,LEN(C20)-SEARCH("@",C20)-1))),"") -> 01 Evian + 0.2% DMSO | B20: =LEFT(RIGHT(RIGHT(Tableau4[[#This Row],[file name]],LEN(Tableau4[[#This Row],[file name]])-SEARCH("@",Tableau4[[#This Row],[file name]])),LEN(RIGHT(Tableau4[[#This Row],[file name]],LEN(Tableau4[[#This Row],[file name]])-SEARCH("@",Tableau4[[#This Row],[file name]])))-SEARCH("/",RIGHT(Tableau4[[#This Row],[file name]],LEN(Tableau4[[#This Row],[file name]])-SEARCH("@",Tableau4[[#This Row],[file name]])))),1) -> G | C20: F:\images\20210304\plaque 1/@01 Evian + 0.2% DMSO/G1_01.tif | D20: 6272.6694 | E20: 68.9793 | G20: 432684
A21: =IFERROR(LEFT(RIGHT(C21,LEN(C21)-SEARCH("@",C21)),SEARCH("/",RIGHT(C21,LEN(C21)-SEARCH("@",C21)-1))),"") -> 01 Evian + 0.2% DMSO | B21: =LEFT(RIGHT(RIGHT(Tableau4[[#This Row],[file name]],LEN(Tableau4[[#This Row],[file name]])-SEARCH("@",Tableau4[[#This Row],[file name]])),LEN(RIGHT(Tableau4[[#This Row],[file name]],LEN(Tableau4[[#This Row],[file name]])-SEARCH("@",Tableau4[[#This Row],[file name]])))-SEARCH("/",RIGHT(Tableau4[[#This Row],[file name]],LEN(Tableau4[[#This Row],[file name]])-SEARCH("@",Tableau4[[#This Row],[file name]])))),1) -> G | C21: F:\images\20210304\plaque 1/@01 Evian + 0.2% DMSO/G1_02.tif | D21: 3741.9718 | E21: 67.3468 | G21: 252010
A22: =IFERROR(LEFT(RIGHT(C22,LEN(C22)-SEARCH("@",C22)),SEARCH("/",RIGHT(C22,LEN(C22)-SEARCH("@",C22)-1))),"") -> 01 Evian + 0.2% DMSO | B22: =LEFT(RIGHT(RIGHT(Tableau4[[#This Row],[file name]],LEN(Tableau4[[#This Row],[file name]])-SEARCH("@",Tableau4[[#This Row],[file name]])),LEN(RIGHT(Tableau4[[#This Row],[file name]],LEN(Tableau4[[#This Row],[file name]])-SEARCH("@",Tableau4[[#This Row],[file name]])))-SEARCH("/",RIGHT(Tableau4[[#This Row],[file name]],LEN(Tableau4[[#This Row],[file name]])-SEARCH("@",Tableau4[[#This Row],[file name]])))),1) -> G | C22: F:\images\20210304\plaque 1/@01 Evian + 0.2% DMSO/G1_03.tif | D22: 194.6691 | E22: 64.1111 | G22: 12480
A23: =IFERROR(LEFT(RIGHT(C23,LEN(C23)-SEARCH("@",C23)),SEARCH("/",RIGHT(C23,LEN(C23)-SEARCH("@",C23)-1))),"") -> 01 Evian + 0.2% DMSO | B23: =LEFT(RIGHT(RIGHT(Tableau4[[#This Row],[file name]],LEN(Tableau4[[#This Row],[file name]])-SEARCH("@",Tableau4[[#This Row],[file name]])),LEN(RIGHT(Tableau4[[#This Row],[file name]],LEN(Tableau4[[#This Row],[file name]])-SEARCH("@",Tableau4[[#This Row],[file name]])))-SEARCH("/",RIGHT(Tableau4[[#This Row],[file name]],LEN(Tableau4[[#This Row],[file name]])-SEARCH("@",Tableau4[[#This Row],[file name]])))),1) -> H | C23: F:\images\20210304\plaque 1/@01 Evian + 0.2% DMSO/H1_01.tif | D23: 194.6691 | E23: 61.8889 | G23: 12048
A24: =IFERROR(LEFT(RIGHT(C24,LEN(C24)-SEARCH("@",C24)),SEARCH("/",RIGHT(C24,LEN(C24)-SEARCH("@",C24)-1))),"") -> 01 Evian + 0.2% DMSO | B24: =LEFT(RIGHT(RIGHT(Tableau4[[#This Row],[file name]],LEN(Tableau4[[#This Row],[file name]])-SEARCH("@",Tableau4[[#This Row],[file name]])),LEN(RIGHT(Tableau4[[#This Row],[file name]],LEN(Tableau4[[#This Row],[file name]])-SEARCH("@",Tableau4[[#This Row],[file name]])))-SEARCH("/",RIGHT(Tableau4[[#This Row],[file name]],LEN(Tableau4[[#This Row],[file name]])-SEARCH("@",Tableau4[[#This Row],[file name]])))),1) -> H | C24: F:\images\20210304\plaque 1/@01 Evian + 0.2% DMSO/H1_02- exclu.tif
A25: =IFERROR(LEFT(RIGHT(C25,LEN(C25)-SEARCH("@",C25)),SEARCH("/",RIGHT(C25,LEN(C25)-SEARCH("@",C25)-1))),"") -> 01 Evian + 0.2% DMSO | B25: =LEFT(RIGHT(RIGHT(Tableau4[[#This Row],[file name]],LEN(Tableau4[[#This Row],[file name]])-SEARCH("@",Tableau4[[#This Row],[file name]])),LEN(RIGHT(Tableau4[[#This Row],[file name]],LEN(Tableau4[[#This Row],[file name]])-SEARCH("@",Tableau4[[#This Row],[file name]])))-SEARCH("/",RIGHT(Tableau4[[#This Row],[file name]],LEN(Tableau4[[#This Row],[file name]])-SEARCH("@",Tableau4[[#This Row],[file name]])))),1) -> H | C25: F:\images\20210304\plaque 1/@01 Evian + 0.2% DMSO/H1_03- exclu.tif
A26: =IFERROR(LEFT(RIGHT(C26,LEN(C26)-SEARCH("@",C26)),SEARCH("/",RIGHT(C26,LEN(C26)-SEARCH("@",C26)-1))),"") | B26: =LEFT(RIGHT(RIGHT(Tableau4[[#This Row],[file name]],LEN(Tableau4[[#This Row],[file name]])-SEARCH("@",Tableau4[[#This Row],[file name]])),LEN(RIGHT(Tableau4[[#This Row],[file name]],LEN(Tableau4[[#This Row],[file name]])-SEARCH("@",Tableau4[[#This Row],[file name]])))-SEARCH("/",RIGHT(Tableau4[[#This Row],[file name]],LEN(Tableau4[[#This Row],[file name]])-SEARCH("@",Tableau4[[#This Row],[file name]])))),1) -> #VALUE!
A27: =IFERROR(LEFT(RIGHT(C27,LEN(C27)-SEARCH("@",C27)),SEARCH("/",RIGHT(C27,LEN(C27)-SEARCH("@",C27)-1))),"") | B27: =LEFT(RIGHT(RIGHT(Tableau4[[#This Row],[file name]],LEN(Tableau4[[#This Row],[file name]])-SEARCH("@",Tableau4[[#This Row],[file name]])),LEN(RIGHT(Tableau4[[#This Row],[file name]],LEN(Tableau4[[#This Row],[file name]])-SEARCH("@",Tableau4[[#This Row],[file name]])))-SEARCH("/",RIGHT(Tableau4[[#This Row],[file name]],LEN(Tableau4[[#This Row],[file name]])-SEARCH("@",Tableau4[[#This Row],[file name]])))),1) -> #VALUE! | C27: group | E27: mean of mean fluo | F27: SD mean fluo | G27: mean of total fluo | H27: SD total fluo | I27: n fluorescent | J27: n total
A28: =IFERROR(LEFT(RIGHT(C28,LEN(C28)-SEARCH("@",C28)),SEARCH("/",RIGHT(C28,LEN(C28)-SEARCH("@",C28)-1))),"") -> 01 Evian + 0.2% DMSO | B28: =LEFT(RIGHT(RIGHT(Tableau4[[#This Row],[file name]],LEN(Tableau4[[#This Row],[file name]])-SEARCH("@",Tableau4[[#This Row],[file name]])),LEN(RIGHT(Tableau4[[#This Row],[file name]],LEN(Tableau4[[#This Row],[file name]])-SEARCH("@",Tableau4[[#This Row],[file name]])))-SEARCH("/",RIGHT(Tableau4[[#This Row],[file name]],LEN(Tableau4[[#This Row],[file name]])-SEARCH("@",Tableau4[[#This Row],[file name]])))),1) | C28: F:\images\20210304\plaque 1/@01 Evian + 0.2% DMSO/ | E28: 65.405 | F28: 2.7194 | G28: 142913.208 | H28: 197143.036 | I28: 24 | J28: 24
A29: =IFERROR(LEFT(RIGHT(C29,LEN(C29)-SEARCH("@",C29)),SEARCH("/",RIGHT(C29,LEN(C29)-SEARCH("@",C29)-1))),"") | B29: =LEFT(RIGHT(RIGHT(Tableau4[[#This Row],[file name]],LEN(Tableau4[[#This Row],[file name]])-SEARCH("@",Tableau4[[#This Row],[file name]])),LEN(RIGHT(Tableau4[[#This Row],[file name]],LEN(Tableau4[[#This Row],[file name]])-SEARCH("@",Tableau4[[#This Row],[file name]])))-SEARCH("/",RIGHT(Tableau4[[#This Row],[file name]],LEN(Tableau4[[#This Row],[file name]])-SEARCH("@",Tableau4[[#This Row],[file name]])))),1) -> #VALUE!
A30: =IFERROR(LEFT(RIGHT(C30,LEN(C30)-SEARCH("@",C30)),SEARCH("/",RIGHT(C30,LEN(C30)-SEARCH("@",C30)-1))),"") | B30: =LEFT(RIGHT(RIGHT(Tableau4[[#This Row],[file name]],LEN(Tableau4[[#This Row],[file name]])-SEARCH("@",Tableau4[[#This Row],[file name]])),LEN(RIGHT(Tableau4[[#This Row],[file name]],LEN(Tableau4[[#This Row],[file name]])-SEARCH("@",Tableau4[[#This Row],[file name]])))-SEARCH("/",RIGHT(Tableau4[[#This Row],[file name]],LEN(Tableau4[[#This Row],[file name]])-SEARCH("@",Tableau4[[#This Row],[file name]])))),1) -> #VALUE!
A31: =IFERROR(LEFT(RIGHT(C31,LEN(C31)-SEARCH("@",C31)),SEARCH("/",RIGHT(C31,LEN(C31)-SEARCH("@",C31)-1))),"") | B31: =LEFT(RIGHT(RIGHT(Tableau4[[#This Row],[file name]],LEN(Tableau4[[#This Row],[file name]])-SEARCH("@",Tableau4[[#This Row],[file name]])),LEN(RIGHT(Tableau4[[#This Row],[file name]],LEN(Tableau4[[#This Row],[file name]])-SEARCH("@",Tableau4[[#This Row],[file name]])))-SEARCH("/",RIGHT(Tableau4[[#This Row],[file name]],LEN(Tableau4[[#This Row],[file name]])-SEARCH("@",Tableau4[[#This Row],[file name]])))),1) -> #VALUE!
A32: =IFERROR(LEFT(RIGHT(C32,LEN(C32)-SEARCH("@",C32)),SEARCH("/",RIGHT(C32,LEN(C32)-SEARCH("@",C32)-1))),"") | B32: =LEFT(RIGHT(RIGHT(Tableau4[[#This Row],[file name]],LEN(Tableau4[[#This Row],[file name]])-SEARCH("@",Tableau4[[#This Row],[file name]])),LEN(RIGHT(Tableau4[[#This Row],[file name]],LEN(Tableau4[[#This Row],[file name]])-SEARCH("@",Tableau4[[#This Row],[file name]])))-SEARCH("/",RIGHT(Tableau4[[#This Row],[file name]],LEN(Tableau4[[#This Row],[file name]])-SEARCH("@",Tableau4[[#This Row],[file name]])))),1) -> #VALUE!
A33: =IFERROR(LEFT(RIGHT(C33,LEN(C33)-SEARCH("@",C33)),SEARCH("/",RIGHT(C33,LEN(C33)-SEARCH("@",C33)-1))),"") | B33: =LEFT(RIGHT(RIGHT(Tableau4[[#This Row],[file name]],LEN(Tableau4[[#This Row],[file name]])-SEARCH("@",Tableau4[[#This Row],[file name]])),LEN(RIGHT(Tableau4[[#This Row],[file name]],LEN(Tableau4[[#This Row],[file name]])-SEARCH("@",Tableau4[[#This Row],[file name]])))-SEARCH("/",RIGHT(Tableau4[[#This Row],[file name]],LEN(Tableau4[[#This Row],[file name]])-SEARCH("@",Tableau4[[#This Row],[file name]])))),1) -> #VALUE!
A34: =IFERROR(LEFT(RIGHT(C34,LEN(C34)-SEARCH("@",C34)),SEARCH("/",RIGHT(C34,LEN(C34)-SEARCH("@",C34)-1))),"") | B34: =LEFT(RIGHT(RIGHT(Tableau4[[#This Row],[file name]],LEN(Tableau4[[#This Row],[file name]])-SEARCH("@",Tableau4[[#This Row],[file name]])),LEN(RIGHT(Tableau4[[#This Row],[file name]],LEN(Tableau4[[#This Row],[file name]])-SEARCH("@",Tableau4[[#This Row],[file name]])))-SEARCH("/",RIGHT(Tableau4[[#This Row],[file name]],LEN(Tableau4[[#This Row],[file name]])-SEARCH("@",Tableau4[[#This Row],[file name]])))),1) -> #VALUE! | C34: file name | D34: total area | E34: mean intensity | G34: total fluorescence
A35: =IFERROR(LEFT(RIGHT(C35,LEN(C35)-SEARCH("@",C35)),SEARCH("/",RIGHT(C35,LEN(C35)-SEARCH("@",C35)-1))),"") -> 02 EE2 33.8 | B35: =LEFT(RIGHT(RIGHT(Tableau4[[#This Row],[file name]],LEN(Tableau4[[#This Row],[file name]])-SEARCH("@",Tableau4[[#This Row],[file name]])),LEN(RIGHT(Tableau4[[#This Row],[file name]],LEN(Tableau4[[#This Row],[file name]])-SEARCH("@",Tableau4[[#This Row],[file name]])))-SEARCH("/",RIGHT(Tableau4[[#This Row],[file name]],LEN(Tableau4[[#This Row],[file name]])-SEARCH("@",Tableau4[[#This Row],[file name]])))),1) -> A | C35: F:\images\20210304\plaque 1/@02 EE2 33.8/A2_01.tif | D35: 1211.2741 | E35: 67.6071 | G35: 81891
A36: =IFERROR(LEFT(RIGHT(C36,LEN(C36)-SEARCH("@",C36)),SEARCH("/",RIGHT(C36,LEN(C36)-SEARCH("@",C36)-1))),"") -> 02 EE2 33.8 | B36: =LEFT(RIGHT(RIGHT(Tableau4[[#This Row],[file name]],LEN(Tableau4[[#This Row],[file name]])-SEARCH("@",Tableau4[[#This Row],[file name]])),LEN(RIGHT(Tableau4[[#This Row],[file name]],LEN(Tableau4[[#This Row],[file name]])-SEARCH("@",Tableau4[[#This Row],[file name]])))-SEARCH("/",RIGHT(Tableau4[[#This Row],[file name]],LEN(Tableau4[[#This Row],[file name]])-SEARCH("@",Tableau4[[#This Row],[file name]])))),1) -> A | C36: F:\images\20210304\plaque 1/@02 EE2 33.8/A2_02.tif | D36: 3395.8935 | E36: 65.4459 | G36: 222247
A37: =IFERROR(LEFT(RIGHT(C37,LEN(C37)-SEARCH("@",C37)),SEARCH("/",RIGHT(C37,LEN(C37)-SEARCH("@",C37)-1))),"") -> 02 EE2 33.8 | B37: =LEFT(RIGHT(RIGHT(Tableau4[[#This Row],[file name]],LEN(Tableau4[[#This Row],[file name]])-SEARCH("@",Tableau4[[#This Row],[file name]])),LEN(RIGHT(Tableau4[[#This Row],[file name]],LEN(Tableau4[[#This Row],[file name]])-SEARCH("@",Tableau4[[#This Row],[file name]])))-SEARCH("/",RIGHT(Tableau4[[#This Row],[file name]],LEN(Tableau4[[#This Row],[file name]])-SEARCH("@",Tableau4[[#This Row],[file name]])))),1) -> A | C37: F:\images\20210304\plaque 1/@02 EE2 33.8/A2_03.tif | D37: 778.6762 | E37: 63.1667 | G37: 49186
A38: =IFERROR(LEFT(RIGHT(C38,LEN(C38)-SEARCH("@",C38)),SEARCH("/",RIGHT(C38,LEN(C38)-SEARCH("@",C38)-1))),"") -> 02 EE2 33.8 | B38: =LEFT(RIGHT(RIGHT(Tableau4[[#This Row],[file name]],LEN(Tableau4[[#This Row],[file name]])-SEARCH("@",Tableau4[[#This Row],[file name]])),LEN(RIGHT(Tableau4[[#This Row],[file name]],LEN(Tableau4[[#This Row],[file name]])-SEARCH("@",Tableau4[[#This Row],[file name]])))-SEARCH("/",RIGHT(Tableau4[[#This Row],[file name]],LEN(Tableau4[[#This Row],[file name]])-SEARCH("@",Tableau4[[#This Row],[file name]])))),1) -> B | C38: F:\images\20210304\plaque 1/@02 EE2 33.8/B2_01.tif | D38: 4801.8366 | E38: 73.8964 | G38: 354838
A39: =IFERROR(LEFT(RIGHT(C39,LEN(C39)-SEARCH("@",C39)),SEARCH("/",RIGHT(C39,LEN(C39)-SEARCH("@",C39)-1))),"") -> 02 EE2 33.8 | B39: =LEFT(RIGHT(RIGHT(Tableau4[[#This Row],[file name]],LEN(Tableau4[[#This Row],[file name]])-SEARCH("@",Tableau4[[#This Row],[file name]])),LEN(RIGHT(Tableau4[[#This Row],[file name]],LEN(Tableau4[[#This Row],[file name]])-SEARCH("@",Tableau4[[#This Row],[file name]])))-SEARCH("/",RIGHT(Tableau4[[#This Row],[file name]],LEN(Tableau4[[#This Row],[file name]])-SEARCH("@",Tableau4[[#This Row],[file name]])))),1) -> B | C39: F:\images\20210304\plaque 1/@02 EE2 33.8/B2_02.tif | D39: 5126.285 | E39: 68.7173 | G39: 352264
A40: =IFERROR(LEFT(RIGHT(C40,LEN(C40)-SEARCH("@",C40)),SEARCH("/",RIGHT(C40,LEN(C40)-SEARCH("@",C40)-1))),"") -> 02 EE2 33.8 | B40: =LEFT(RIGHT(RIGHT(Tableau4[[#This Row],[file name]],LEN(Tableau4[[#This Row],[file name]])-SEARCH("@",Tableau4[[#This Row],[file name]])),LEN(RIGHT(Tableau4[[#This Row],[file name]],LEN(Tableau4[[#This Row],[file name]])-SEARCH("@",Tableau4[[#This Row],[file name]])))-SEARCH("/",RIGHT(Tableau4[[#This Row],[file name]],LEN(Tableau4[[#This Row],[file name]])-SEARCH("@",Tableau4[[#This Row],[file name]])))),1) -> B | C40: F:\images\20210304\plaque 1/@02 EE2 33.8/B2_03- exclu.tif
...

Sheet R1
A1: 3. Expérimentateur 1 : copier et coller les valeurs des intensités totales de fluorescences obtenues dans le fichier raw data lors du traitement des images.
A3: R1 | B3: Non dopé | O3: avec testo
A4: Noms des groupes | B4: ='Page de garde'!A7 -> Témoin solvant | C4: ='Page de garde'!A9 -> EE2-33,8ng/L | D4: ='Page de garde'!A10 -> EE2-50,6ng/L | E4: ='Page de garde'!A11 -> EE2-76ng/L | F4: ='Page de garde'!A12 -> EE2-114ng/L | G4: ='Page de garde'!A13 -> EE2-170,9ng/L | H4: ='Page de garde'!A14 -> EE2-488ng/L | I4: ='Page de garde'!A15 -> Testosterone 3,7µg/L | J4: ='Page de garde'!A16 -> Testosterone 11µg/L | K4: ='Page de garde'!A17 -> Testosterone 33µg/L | L4: ='Page de garde'!A18 -> Testosterone 100µg/L | M4: ='Page de garde'!A19 -> Testosterone 300µg/L | O4: ='Page de garde'!A36 -> Testo -30µg/L | P4: ='Page de garde'!A37 -> Testo 30µg/L + EE2 -64ng/L | Q4: ='Page de garde'!A38 -> Testo 30µg/L + FAD-10µg/L | R4: ='Page de garde'!A39 -> Testosterone-3,7µg/L + Testostérone | S4: ='Page de garde'!A40 -> Testosterone-11µg/L + Testostérone | T4: ='Page de garde'!A41 -> Testosterone-33µg/L + Testostérone | U4: ='Page de garde'!A42 -> Testosterone-100µg/L + Testostérone | V4: ='Page de garde'!A43 -> Testosterone-300µg/L + Testostérone
A5: Données brutes | B5: 68768.667 | C5: 117774.67 | D5: 61234 | E5: 804891.67 | F5: 1291982.3 | G5: 3183070 | H5: 7591134.3 | I5: 316207.5 | J5: 449130.33 | K5: 364911 | L5: 3101734.3 | M5: 1137155.7 | O5: 3308443.7 | P5: 4775199.5 | Q5: 190047.33 | R5: 4143581.3 | S5: 4570317.3 | T5: 3195658.3 | U5: 2425662.7 | V5: 3811641.7
B6: 475692 | C6: 353551 | D6: 183320.67 | E6: 241007.67 | F6: 2077897.7 | G6: 3757920.3 | H6: 5661120.3 | I6: 279512 | J6: 38991.333 | K6: 3691869.7 | L6: 3529054.3 | M6: 3980621.7 | O6: 97713 | P6: 5366412.7 | Q6: 108928 | R6: 1600583.3 | S6: 4237361.3 | T6: 3253850 | U6: 3705604.7 | V6: 4674436.5
B7: 299847.67 | C7: 450665.67 | D7: 183882.67 | E7: 380556.33 | F7: 1025495 | G7: 3448338.7 | H7: 7082716.3 | I7: 75589.667 | J7: 168230 | K7: 3644377.3 | L7: 3511555.7 | M7: 2428467.7 | O7: 2785577.3 | P7: 2757054.7 | Q7: 98293.333 | R7: 2411242.7 | S7: 1381278 | T7: 1831792.3 | U7: 373148.5 | V7: 4489667
B8: 10598.667 | C8: 108459.33 | D8: 59266 | E8: 218548 | F8: 2209191 | G8: 612486.67 | H8: 6204261 | I8: 216753 | J8: 82496.5 | K8: 2777494.7 | L8: 1464344 | M8: 4806617 | O8: 3859169.7 | P8: 4483174 | Q8: 80874 | R8: 1506911.3 | S8: 1828677.7 | T8: 1484921.3 | U8: 2876206.3 | V8: 3181317.7
B9: 13684.333 | C9: 334946.33 | D9: 94003.5 | E9: 3039735.7 | F9: 827163.33 | G9: 3525521.5 | H9: 3664198 | I9: 16338 | J9: 111992.33 | K9: 4078417.7 | L9: 3553525 | M9: 1695726 | O9: 2492420 | P9: 1136074.3 | R9: 4343794.7 | S9: 4424157 | T9: 795115 | V9: 2115324.3
B10: 33735.667 | C10: 13540.333 | D10: 16345 | E10: 184120.67 | F10: 582723.67 | G10: 2931045 | H10: 5786768.3 | I10: 103261.33 | J10: 37214.5 | K10: 101869.67 | L10: 2515773.3 | M10: 1694521.7 | O10: 2586719 | P10: 4541585.7 | Q10: 206298.67 | R10: 2589855.3 | S10: 2713535.3 | T10: 2159946.7 | U10: 2030852.3 | V10: 3999028.3
B11: 232391.33 | C11: 75481 | D11: 97219 | E11: 654672 | F11: 2310779.3 | G11: 3257365 | H11: 5149306.7 | I11: 29676.333 | J11: 91505 | K11: 1198505 | L11: 3638890.7 | M11: 1914505.3 | O11: 1719857.7 | P11: 6096804 | Q11: 116282.33 | R11: 2873401.7 | S11: 3984039.3 | T11: 2123652 | U11: 1787307 | V11: 2804864
B12: 12048 | C12: 191435.5 | D12: 191489.5 | E12: 182888 | F12: 2356627.3 | H12: 7155472 | I12: 30981 | J12: 26172 | K12: 1005667.3 | L12: 1664824 | M12: 3085494 | O12: 554720.33 | P12: 4954421 | Q12: 320605.33 | R12: 1912436 | S12: 2755922.7 | T12: 3391257.3 | U12: 2833029.5 | V12: 2048675.3
O13: 4555356.7
O14: 872571.33
O15: 1911866.7
O16: 3733702.3
O17: 24060
O18: 1584894.3
O19: 3421726.7
O20: 280251.33
A22: =A4 -> Noms des groupes | B22: =B4 -> Témoin solvant | C22: =C4 -> EE2-33,8ng/L | D22: =D4 -> EE2-50,6ng/L | E22: =E4 -> EE2-76ng/L | F22: =F4 -> EE2-114ng/L | G22: =G4 -> EE2-170,9ng/L | H22: =H4 -> EE2-488ng/L | ... M22: =M4 -> Testosterone 300µg/L | N22: Nom des groupes | O22: =O4 -> Testo -30µg/L | P22: =P4 -> Testo 30µg/L + EE2 -64ng/L | Q22: =Q4 -> Testo 30µg/L + FAD-10µg/L | R22: =R4 -> Testosterone-3,7µg/L + Testostérone | S22: =S4 -> Testosterone-11µg/L + Testostérone | T22: =T4 -> Testosterone-33µg/L + Testostérone | U22: =U4 -> Testosterone-100µg/L + Testostérone | V22: =V4 -> Testosterone-300µg/L + Testostérone
A23: mean | B23: =AVERAGE(B5:B20) -> 143345.79 | C23: =AVERAGE(C5:C20) -> 205731.73 | D23: =AVERAGE(D5:D20) -> 110845.04 | E23: =AVERAGE(E5:E20) -> 713302.5 | F23: =AVERAGE(F5:F20) -> 1585232.5 | G23: =AVERAGE(G5:G20) -> 2959392.5 | H23: =AVERAGE(H5:H20) -> 6036872.1 | I23: =AVERAGE(I5:I20) -> 133539.85 | ... M23: =AVERAGE(M5:M20) -> 2592888.6 | N23: mean | O23: =AVERAGE(O5:O20) -> 2111815.6 | P23: =AVERAGE(P5:P20) -> 4263840.7 | Q23: =AVERAGE(Q5:Q20) -> 160189.86 | R23: =AVERAGE(R5:R20) -> 2672725.8 | S23: =AVERAGE(S5:S20) -> 3236911.1 | T23: =AVERAGE(T5:T20) -> 2279524.1 | U23: =AVERAGE(U5:U20) -> 2290258.7 | V23: =AVERAGE(V5:V20) -> 3390619.4
A24: SD | B24: =STDEV(B5:B20) -> 174079.24 | C24: =STDEV(C5:C20) -> 155767.74 | D24: =STDEV(D5:D20) -> 67201.145 | E24: =STDEV(E5:E20) -> 968360.53 | F24: =STDEV(F5:F20) -> 730215.81 | G24: =STDEV(G5:G20) -> 1068082.9 | H24: =STDEV(H5:H20) -> 1276709.1 | I24: =STDEV(I5:I20) -> 120069.62 | ... M24: =STDEV(M5:M20) -> 1269837.8 | N24: SD | O24: =STDEV(O5:O20) -> 1456669.2 | P24: =STDEV(P5:P20) -> 1580794.8 | Q24: =STDEV(Q5:Q20) -> 85076.877 | R24: =STDEV(R5:R20) -> 1079553.6 | S24: =STDEV(S5:S20) -> 1235105.2 | T24: =STDEV(T5:T20) -> 933387.55 | U24: =STDEV(U5:U20) -> 1053172.7 | V24: =STDEV(V5:V20) -> 1015425.4
B26: Non dopé | O26: avec testo
A27: Noms des groupes | B27: =B4 -> Témoin solvant | C27: =C4 -> EE2-33,8ng/L | D27: =D4 -> EE2-50,6ng/L | E27: =E4 -> EE2-76ng/L | F27: =F4 -> EE2-114ng/L | G27: =G4 -> EE2-170,9ng/L | H27: =H4 -> EE2-488ng/L | I27: =I4 -> Testosterone 3,7µg/L | ... M27: =M4 -> Testosterone 300µg/L | O27: =O4 -> Testo -30µg/L | P27: =P4 -> Testo 30µg/L + EE2 -64ng/L | Q27: =Q4 -> Testo 30µg/L + FAD-10µg/L | R27: =R4 -> Testosterone-3,7µg/L + Testostérone | S27: =S4 -> Testosterone-11µg/L + Testostérone | T27: =T4 -> Testosterone-33µg/L + Testostérone | U27: =U4 -> Testosterone-100µg/L + Testostérone | V27: =V4 -> Testosterone-300µg/L + Testostérone
A28: Données normalisées sur la moyenne du groupe "Testo" | B28: =IF(B5="","",(B5/$O$23)) -> 0.032563764 | C28: =IF(C5="","",(C5/$O$23)) -> 0.055769389 | D28: =IF(D5="","",(D5/$O$23)) -> 0.028995903 | E28: =IF(E5="","",(E5/$O$23)) -> 0.38113728 | F28: =IF(F5="","",(F5/$O$23)) -> 0.61178747 | G28: =IF(G5="","",(G5/$O$23)) -> 1.507267 | H28: =IF(H5="","",(H5/$O$23)) -> 3.5946009 | I28: =IF(I5="","",(I5/$O$23)) -> 0.14973253 | ... M28: =IF(M5="","",(M5/$O$23)) -> 0.53847299 | O28: =IF(O5="","",(O5/$O$23)) -> 1.5666347 | P28: =IF(P5="","",(P5/$O$23)) -> 2.261182 | Q28: =IF(Q5="","",(Q5/$O$23)) -> 0.089992389 | R28: =IF(R5="","",(R5/$O$23)) -> 1.9620943 | S28: =IF(S5="","",(S5/$O$23)) -> 2.1641649 | T28: =IF(T5="","",(T5/$O$23)) -> 1.5132279 | U28: =IF(U5="","",(U5/$O$23)) -> 1.1486148 | V28: =IF(V5="","",(V5/$O$23)) -> 1.8049121
B29: =IF(B6="","",(B6/$O$23)) -> 0.22525262 | C29: =IF(C6="","",(C6/$O$23)) -> 0.16741566 | D29: =IF(D6="","",(D6/$O$23)) -> 0.086807136 | E29: =IF(E6="","",(E6/$O$23)) -> 0.11412344 | F29: =IF(F6="","",(F6/$O$23)) -> 0.98393896 | G29: =IF(G6="","",(G6/$O$23)) -> 1.7794737 | H29: =IF(H6="","",(H6/$O$23)) -> 2.6806887 | I29: =IF(I6="","",(I6/$O$23)) -> 0.13235625 | ... M29: =IF(M6="","",(M6/$O$23)) -> 1.8849286 | O29: =IF(O6="","",(O6/$O$23)) -> 0.046269664 | P29: =IF(P6="","",(P6/$O$23)) -> 2.5411369 | Q29: =IF(Q6="","",(Q6/$O$23)) -> 0.05158026 | R29: =IF(R6="","",(R6/$O$23)) -> 0.75791812 | S29: =IF(S6="","",(S6/$O$23)) -> 2.0065016 | T29: =IF(T6="","",(T6/$O$23)) -> 1.5407832 | U29: =IF(U6="","",(U6/$O$23)) -> 1.7547008 | V29: =IF(V6="","",(V6/$O$23)) -> 2.2134681
B30: =IF(B7="","",(B7/$O$23)) -> 0.14198572 | C30: =IF(C7="","",(C7/$O$23)) -> 0.21340199 | D30: =IF(D7="","",(D7/$O$23)) -> 0.087073258 | E30: =IF(E7="","",(E7/$O$23)) -> 0.18020339 | F30: =IF(F7="","",(F7/$O$23)) -> 0.48559874 | G30: =IF(G7="","",(G7/$O$23)) -> 1.6328787 | H30: =IF(H7="","",(H7/$O$23)) -> 3.3538517 | I30: =IF(I7="","",(I7/$O$23)) -> 0.035793687 | ... M30: =IF(M7="","",(M7/$O$23)) -> 1.149943 | O30: =IF(O7="","",(O7/$O$23)) -> 1.3190438 | P30: =IF(P7="","",(P7/$O$23)) -> 1.3055376 | Q30: =IF(Q7="","",(Q7/$O$23)) -> 0.046544467 | R30: =IF(R7="","",(R7/$O$23)) -> 1.1417865 | S30: =IF(S7="","",(S7/$O$23)) -> 0.6540713 | T30: =IF(T7="","",(T7/$O$23)) -> 0.86740164 | U30: =IF(U7="","",(U7/$O$23)) -> 0.17669559 | V30: =IF(V7="","",(V7/$O$23)) -> 2.1259749
B31: =IF(B8="","",(B8/$O$23)) -> 0.0050187462 | C31: =IF(C8="","",(C8/$O$23)) -> 0.051358335 | D31: =IF(D8="","",(D8/$O$23)) -> 0.028064003 | E31: =IF(E8="","",(E8/$O$23)) -> 0.1034882 | F31: =IF(F8="","",(F8/$O$23)) -> 1.0461098 | G31: =IF(G8="","",(G8/$O$23)) -> 0.29002848 | H31: =IF(H8="","",(H8/$O$23)) -> 2.9378801 | I31: =IF(I8="","",(I8/$O$23)) -> 0.10263822 | ... M31: =IF(M8="","",(M8/$O$23)) -> 2.276059 | O31: =IF(O8="","",(O8/$O$23)) -> 1.8274179 | P31: =IF(P8="","",(P8/$O$23)) -> 2.1229003 | Q31: =IF(Q8="","",(Q8/$O$23)) -> 0.038295957 | R31: =IF(R8="","",(R8/$O$23)) -> 0.71356198 | S31: =IF(S8="","",(S8/$O$23)) -> 0.86592676 | T31: =IF(T8="","",(T8/$O$23)) -> 0.70314914 | U31: =IF(U8="","",(U8/$O$23)) -> 1.361959 | V31: =IF(V8="","",(V8/$O$23)) -> 1.5064372
B32: =IF(B9="","",(B9/$O$23)) -> 0.0064798902 | C32: =IF(C9="","",(C9/$O$23)) -> 0.15860586 | D32: =IF(D9="","",(D9/$O$23)) -> 0.044513119 | E32: =IF(E9="","",(E9/$O$23)) -> 1.4393944 | F32: =IF(F9="","",(F9/$O$23)) -> 0.3916835 | G32: =IF(G9="","",(G9/$O$23)) -> 1.6694268 | H32: =IF(H9="","",(H9/$O$23)) -> 1.7350937 | I32: =IF(I9="","",(I9/$O$23)) -> 0.0077364708 | ... M32: =IF(M9="","",(M9/$O$23)) -> 0.80297067 | O32: =IF(O9="","",(O9/$O$23)) -> 1.1802261 | P32: =IF(P9="","",(P9/$O$23)) -> 0.53796095 | Q32: =IF(Q9="","",(Q9/$O$23)) | R32: =IF(R9="","",(R9/$O$23)) -> 2.0569005 | S32: =IF(S9="","",(S9/$O$23)) -> 2.0949542 | T32: =IF(T9="","",(T9/$O$23)) -> 0.37650777 | U32: =IF(U9="","",(U9/$O$23)) | V32: =IF(V9="","",(V9/$O$23)) -> 1.0016615
B33: =IF(B10="","",(B10/$O$23)) -> 0.015974722 | C33: =IF(C10="","",(C10/$O$23)) -> 0.0064117024 | D33: =IF(D10="","",(D10/$O$23)) -> 0.0077397855 | E33: =IF(E10="","",(E10/$O$23)) -> 0.087185957 | F33: =IF(F10="","",(F10/$O$23)) -> 0.27593492 | G33: =IF(G10="","",(G10/$O$23)) -> 1.3879266 | H33: =IF(H10="","",(H10/$O$23)) -> 2.7401863 | I33: =IF(I10="","",(I10/$O$23)) -> 0.048896945 | ... M33: =IF(M10="","",(M10/$O$23)) -> 0.80240038 | O33: =IF(O10="","",(O10/$O$23)) -> 1.2248792 | P33: =IF(P10="","",(P10/$O$23)) -> 2.1505597 | Q33: =IF(Q10="","",(Q10/$O$23)) -> 0.097687821 | R33: =IF(R10="","",(R10/$O$23)) -> 1.2263643 | S33: =IF(S10="","",(S10/$O$23)) -> 1.28493 | T33: =IF(T10="","",(T10/$O$23)) -> 1.0227913 | U33: =IF(U10="","",(U10/$O$23)) -> 0.96166176 | V33: =IF(V10="","",(V10/$O$23)) -> 1.8936446
B34: =IF(B11="","",(B11/$O$23)) -> 0.11004338 | C34: =IF(C11="","",(C11/$O$23)) -> 0.03574223 | D34: =IF(D11="","",(D11/$O$23)) -> 0.046035742 | E34: =IF(E11="","",(E11/$O$23)) -> 0.31000434 | F34: =IF(F11="","",(F11/$O$23)) -> 1.0942145 | G34: =IF(G11="","",(G11/$O$23)) -> 1.5424476 | H34: =IF(H11="","",(H11/$O$23)) -> 2.4383316 | I34: =IF(I11="","",(I11/$O$23)) -> 0.014052521 | ... M34: =IF(M11="","",(M11/$O$23)) -> 0.90656841 | O34: =IF(O11="","",(O11/$O$23)) -> 0.81439764 | P34: =IF(P11="","",(P11/$O$23)) -> 2.8869963 | Q34: =IF(Q11="","",(Q11/$O$23)) -> 0.05506273 | R34: =IF(R11="","",(R11/$O$23)) -> 1.3606309 | S34: =IF(S11="","",(S11/$O$23)) -> 1.886547 | T34: =IF(T11="","",(T11/$O$23)) -> 1.0056048 | U34: =IF(U11="","",(U11/$O$23)) -> 0.84633667 | V34: =IF(V11="","",(V11/$O$23)) -> 1.3281766
B35: =IF(B12="","",(B12/$O$23)) -> 0.0057050435 | C35: =IF(C12="","",(C12/$O$23)) -> 0.090649722 | D35: =IF(D12="","",(D12/$O$23)) -> 0.090675293 | E35: =IF(E12="","",(E12/$O$23)) -> 0.086602257 | F35: =IF(F12="","",(F12/$O$23)) -> 1.1159248 | G35: =IF(G12="","",(G12/$O$23)) | H35: =IF(H12="","",(H12/$O$23)) -> 3.3883034 | I35: =IF(I12="","",(I12/$O$23)) -> 0.014670315 | ... M35: =IF(M12="","",(M12/$O$23)) -> 1.4610622 | O35: =IF(O12="","",(O12/$O$23)) -> 0.2626746 | P35: =IF(P12="","",(P12/$O$23)) -> 2.3460481 | Q35: =IF(Q12="","",(Q12/$O$23)) -> 0.15181502 | R35: =IF(R12="","",(R12/$O$23)) -> 0.90558853 | S35: =IF(S12="","",(S12/$O$23)) -> 1.3050016 | T35: =IF(T12="","",(T12/$O$23)) -> 1.6058492 | U35: =IF(U12="","",(U12/$O$23)) -> 1.3415137 | V35: =IF(V12="","",(V12/$O$23)) -> 0.97010142
B36: =IF(B13="","",(B13/$O$23)) | C36: =IF(C13="","",(C13/$O$23)) | D36: =IF(D13="","",(D13/$O$23)) | E36: =IF(E13="","",(E13/$O$23)) | F36: =IF(F13="","",(F13/$O$23)) | G36: =IF(G13="","",(G13/$O$23)) | H36: =IF(H13="","",(H13/$O$23)) | I36: =IF(I13="","",(I13/$O$23)) | ... M36: =IF(M13="","",(M13/$O$23)) | O36: =IF(O13="","",(O13/$O$23)) -> 2.1570807 | P36: =IF(P13="","",(P13/$O$23)) | Q36: =IF(Q13="","",(Q13/$O$23)) | R36: =IF(R13="","",(R13/$O$23)) | S36: =IF(S13="","",(S13/$O$23)) | T36: =IF(T13="","",(T13/$O$23)) | U36: =IF(U13="","",(U13/$O$23)) | V36: =IF(V13="","",(V13/$O$23))
B37: =IF(B14="","",(B14/$O$23)) | C37: =IF(C14="","",(C14/$O$23)) | D37: =IF(D14="","",(D14/$O$23)) | E37: =IF(E14="","",(E14/$O$23)) | F37: =IF(F14="","",(F14/$O$23)) | G37: =IF(G14="","",(G14/$O$23)) | H37: =IF(H14="","",(H14/$O$23)) | I37: =IF(I14="","",(I14/$O$23)) | ... M37: =IF(M14="","",(M14/$O$23)) | O37: =IF(O14="","",(O14/$O$23)) -> 0.41318538 | P37: =IF(P14="","",(P14/$O$23)) | Q37: =IF(Q14="","",(Q14/$O$23)) | R37: =IF(R14="","",(R14/$O$23)) | S37: =IF(S14="","",(S14/$O$23)) | T37: =IF(T14="","",(T14/$O$23)) | U37: =IF(U14="","",(U14/$O$23)) | V37: =IF(V14="","",(V14/$O$23))
