Workbook

Sheet Page de garde
A1: 1. Expérimentateur 1 : copier et coller le n° de prestation et renseigner la date de réalisation de chaque réplica ainsi que le visa de l'expérimentateur.
A2: R1 | B2: Numéro d'expérience : | E2: Date de réalisation :
A3: R2 | B3: Numéro d'expérience : | E3: Date de réalisation :
A4: R3 | B4: Numéro d'expérience : | E4: Date de réalisation :
A5: 2. Expérimentateur 1 : copier et coller la dilution appliquée et le nom donné pour chaque des échantillons par le client. Conserver la mise en forme de l'exemple en italique. Ne pas remplir la colonne "nom sur graphique".
A6: Nom sur le graphique | B6: Code WF | C6: Concentration | D6: Unité | E6: Nom de l'échantillon donné par le client | F6: Dopage (+Testostérone / + EE2, ….)
A7: =IF(ISBLANK(liste_groupe[[#This Row],[Code WF]])," ",IF(ISBLANK(liste_groupe[[#This Row],[Unité]]),CONCATENATE(liste_groupe[[#This Row],[Nom de l''échantillon donné par le client]],liste_groupe[[#This Row],[Dopage (+Testostérone / + EE2, ….)]]),CONCATENATE(liste_groupe[[#This Row],[Nom de l''échantillon donné par le client]],"-",liste_groupe[[#This Row],[Concentration]],liste_groupe[[#This Row],[Unité]],liste_groupe[[#This Row],[Dopage (+Testostérone / + EE2, ….)]]))) -> Témoin solvant | B7: Témoin | E7: Témoin solvant
A8: =IF(ISBLANK(liste_groupe[[#This Row],[Code WF]])," ",IF(ISBLANK(liste_groupe[[#This Row],[Unité]]),CONCATENATE(liste_groupe[[#This Row],[Nom de l''échantillon donné par le client]],liste_groupe[[#This Row],[Dopage (+Testostérone / + EE2, ….)]]),CONCATENATE(liste_groupe[[#This Row],[Nom de l''échantillon donné par le client]],"-",liste_groupe[[#This Row],[Concentration]],liste_groupe[[#This Row],[Unité]],liste_groupe[[#This Row],[Dopage (+Testostérone / + EE2, ….)]]))) -> EE2-22.5ng/L | B8: Témoin | C8: 22.5 | D8: ng/L | E8: EE2
A9: =IF(ISBLANK(liste_groupe[[#This Row],[Code WF]])," ",IF(ISBLANK(liste_groupe[[#This Row],[Unité]]),CONCATENATE(liste_groupe[[#This Row],[Nom de l''échantillon donné par le client]],liste_groupe[[#This Row],[Dopage (+Testostérone / + EE2, ….)]]),CONCATENATE(liste_groupe[[#This Row],[Nom de l''échantillon donné par le client]],"-",liste_groupe[[#This Row],[Concentration]],liste_groupe[[#This Row],[Unité]],liste_groupe[[#This Row],[Dopage (+Testostérone / + EE2, ….)]]))) -> EE2-33.8ng/L | B9: Témoin | C9: 33.8 | D9: ng/L | E9: EE2
A10: =IF(ISBLANK(liste_groupe[[#This Row],[Code WF]])," ",IF(ISBLANK(liste_groupe[[#This Row],[Unité]]),CONCATENATE(liste_groupe[[#This Row],[Nom de l''échantillon donné par le client]],liste_groupe[[#This Row],[Dopage (+Testostérone / + EE2, ….)]]),CONCATENATE(liste_groupe[[#This Row],[Nom de l''échantillon donné par le client]],"-",liste_groupe[[#This Row],[Concentration]],liste_groupe[[#This Row],[Unité]],liste_groupe[[#This Row],[Dopage (+Testostérone / + EE2, ….)]]))) -> EE2-50.6ng/L | B10: Témoin | C10: 50.6 | D10: ng/L | E10: EE2
A11: =IF(ISBLANK(liste_groupe[[#This Row],[Code WF]])," ",IF(ISBLANK(liste_groupe[[#This Row],[Unité]]),CONCATENATE(liste_groupe[[#This Row],[Nom de l''échantillon donné par le client]],liste_groupe[[#This Row],[Dopage (+Testostérone / + EE2, ….)]]),CONCATENATE(liste_groupe[[#This Row],[Nom de l''échantillon donné par le client]],"-",liste_groupe[[#This Row],[Concentration]],liste_groupe[[#This Row],[Unité]],liste_groupe[[#This Row],[Dopage (+Testostérone / + EE2, ….)]]))) -> EE2-76ng/L | B11: Témoin | C11: 76 | D11: ng/L | E11: EE2
A12: =IF(ISBLANK(liste_groupe[[#This Row],[Code WF]])," ",IF(ISBLANK(liste_groupe[[#This Row],[Unité]]),CONCATENATE(liste_groupe[[#This Row],[Nom de l''échantillon donné par le client]],liste_groupe[[#This Row],[Dopage (+Testostérone / + EE2, ….)]]),CONCATENATE(liste_groupe[[#This Row],[Nom de l''échantillon donné par le client]],"-",liste_groupe[[#This Row],[Concentration]],liste_groupe[[#This Row],[Unité]],liste_groupe[[#This Row],[Dopage (+Testostérone / + EE2, ….)]]))) -> EE2-114ng/L | B12: Témoin | C12: 114 | D12: ng/L | E12: EE2
A13: =IF(ISBLANK(liste_groupe[[#This Row],[Code WF]])," ",IF(ISBLANK(liste_groupe[[#This Row],[Unité]]),CONCATENATE(liste_groupe[[#This Row],[Nom de l''échantillon donné par le client]],liste_groupe[[#This Row],[Dopage (+Testostérone / + EE2, ….)]]),CONCATENATE(liste_groupe[[#This Row],[Nom de l''échantillon donné par le client]],"-",liste_groupe[[#This Row],[Concentration]],liste_groupe[[#This Row],[Unité]],liste_groupe[[#This Row],[Dopage (+Testostérone / + EE2, ….)]]))) -> EE2-170.9ng/L | B13: Témoin | C13: 170.9 | D13: ng/L | E13: EE2
A14: =IF(ISBLANK(liste_groupe[[#This Row],[Code WF]])," ",IF(ISBLANK(liste_groupe[[#This Row],[Unité]]),CONCATENATE(liste_groupe[[#This Row],[Nom de l''échantillon donné par le client]],liste_groupe[[#This Row],[Dopage (+Testostérone / + EE2, ….)]]),CONCATENATE(liste_groupe[[#This Row],[Nom de l''échantillon donné par le client]],"-",liste_groupe[[#This Row],[Concentration]],liste_groupe[[#This Row],[Unité]],liste_groupe[[#This Row],[Dopage (+Testostérone / + EE2, ….)]]))) -> EE2-488ng/L | B14: Témoin | C14: 488 | D14: ng/L | E14: EE2
A15: Tamoxifen-30,2µg/L | C15: 30.2 | D15: µg/L | E15: Tamoxifen
A16: Tamoxifen-60,4µg/L | C16: 60.4 | D16: µg/L | E16: Tamoxifen
A17: Tamoxifen-121µg/L | C17: 121 | D17: µg/L | E17: Tamoxifen
A18: Tamoxifen-242µg/L | C18: 242 | D18: µg/L | E18: Tamoxifen
A19: Tamoxifen-483µg/L | C19: 483 | D19: µg/L | E19: Tamoxifen
A20: =IF(ISBLANK(liste_groupe[[#This Row],[Code WF]])," ",IF(ISBLANK(liste_groupe[[#This Row],[Unité]]),CONCATENATE(liste_groupe[[#This Row],[Nom de l''échantillon donné par le client]],liste_groupe[[#This Row],[Dopage (+Testostérone / + EE2, ….)]]),CONCATENATE(liste_groupe[[#This Row],[Nom de l''échantillon donné par le client]],"-",liste_groupe[[#This Row],[Concentration]],liste_groupe[[#This Row],[Unité]],liste_groupe[[#This Row],[Dopage (+Testostérone / + EE2, ….)]])))
A21: =IF(ISBLANK(liste_groupe[[#This Row],[Code WF]])," ",IF(ISBLANK(liste_groupe[[#This Row],[Unité]]),CONCATENATE(liste_groupe[[#This Row],[Nom de l''échantillon donné par le client]],liste_groupe[[#This Row],[Dopage (+Testostérone / + EE2, ….)]]),CONCATENATE(liste_groupe[[#This Row],[Nom de l''échantillon donné par le client]],"-",liste_groupe[[#This Row],[Concentration]],liste_groupe[[#This Row],[Unité]],liste_groupe[[#This Row],[Dopage (+Testostérone / + EE2, ….)]])))
A22: =IF(ISBLANK(liste_groupe[[#This Row],[Code WF]])," ",IF(ISBLANK(liste_groupe[[#This Row],[Unité]]),CONCATENATE(liste_groupe[[#This Row],[Nom de l''échantillon donné par le client]],liste_groupe[[#This Row],[Dopage (+Testostérone / + EE2, ….)]]),CONCATENATE(liste_groupe[[#This Row],[Nom de l''échantillon donné par le client]],"-",liste_groupe[[#This Row],[Concentration]],liste_groupe[[#This Row],[Unité]],liste_groupe[[#This Row],[Dopage (+Testostérone / + EE2, ….)]])))
A23: =IF(ISBLANK(liste_groupe[[#This Row],[Code WF]])," ",IF(ISBLANK(liste_groupe[[#This Row],[Unité]]),CONCATENATE(liste_groupe[[#This Row],[Nom de l''échantillon donné par le client]],liste_groupe[[#This Row],[Dopage (+Testostérone / + EE2, ….)]]),CONCATENATE(liste_groupe[[#This Row],[Nom de l''échantillon donné par le client]],"-",liste_groupe[[#This Row],[Concentration]],liste_groupe[[#This Row],[Unité]],liste_groupe[[#This Row],[Dopage (+Testostérone / + EE2, ….)]])))
A24: =IF(ISBLANK(liste_groupe[[#This Row],[Code WF]])," ",IF(ISBLANK(liste_groupe[[#This Row],[Unité]]),CONCATENATE(liste_groupe[[#This Row],[Nom de l''échantillon donné par le client]],liste_groupe[[#This Row],[Dopage (+Testostérone / + EE2, ….)]]),CONCATENATE(liste_groupe[[#This Row],[Nom de l''échantillon donné par le client]],"-",liste_groupe[[#This Row],[Concentration]],liste_groupe[[#This Row],[Unité]],liste_groupe[[#This Row],[Dopage (+Testostérone / + EE2, ….)]])))
A25: =IF(ISBLANK(liste_groupe[[#This Row],[Code WF]])," ",IF(ISBLANK(liste_groupe[[#This Row],[Unité]]),CONCATENATE(liste_groupe[[#This Row],[Nom de l''échantillon donné par le client]],liste_groupe[[#This Row],[Dopage (+Testostérone / + EE2, ….)]]),CONCATENATE(liste_groupe[[#This Row],[Nom de l''échantillon donné par le client]],"-",liste_groupe[[#This Row],[Concentration]],liste_groupe[[#This Row],[Unité]],liste_groupe[[#This Row],[Dopage (+Testostérone / + EE2, ….)]])))
A26: =IF(ISBLANK(liste_groupe[[#This Row],[Code WF]])," ",IF(ISBLANK(liste_groupe[[#This Row],[Unité]]),CONCATENATE(liste_groupe[[#This Row],[Nom de l''échantillon donné par le client]],liste_groupe[[#This Row],[Dopage (+Testostérone / + EE2, ….)]]),CONCATENATE(liste_groupe[[#This Row],[Nom de l''échantillon donné par le client]],"-",liste_groupe[[#This Row],[Concentration]],liste_groupe[[#This Row],[Unité]],liste_groupe[[#This Row],[Dopage (+Testostérone / + EE2, ….)]])))
A27: =IF(ISBLANK(liste_groupe[[#This Row],[Code WF]])," ",IF(ISBLANK(liste_groupe[[#This Row],[Unité]]),CONCATENATE(liste_groupe[[#This Row],[Nom de l''échantillon donné par le client]],liste_groupe[[#This Row],[Dopage (+Testostérone / + EE2, ….)]]),CONCATENATE(liste_groupe[[#This Row],[Nom de l''échantillon donné par le client]],"-",liste_groupe[[#This Row],[Concentration]],liste_groupe[[#This Row],[Unité]],liste_groupe[[#This Row],[Dopage (+Testostérone / + EE2, ….)]])))
A28: =IF(ISBLANK(liste_groupe[[#This Row],[Code WF]])," ",IF(ISBLANK(liste_groupe[[#This Row],[Unité]]),CONCATENATE(liste_groupe[[#This Row],[Nom de l''échantillon donné par le client]],liste_groupe[[#This Row],[Dopage (+Testostérone / + EE2, ….)]]),CONCATENATE(liste_groupe[[#This Row],[Nom de l''échantillon donné par le client]],"-",liste_groupe[[#This Row],[Concentration]],liste_groupe[[#This Row],[Unité]],liste_groupe[[#This Row],[Dopage (+Testostérone / + EE2, ….)]])))
A29: =IF(ISBLANK(liste_groupe[[#This Row],[Code WF]])," ",IF(ISBLANK(liste_groupe[[#This Row],[Unité]]),CONCATENATE(liste_groupe[[#This Row],[Nom de l''échantillon donné par le client]],liste_groupe[[#This Row],[Dopage (+Testostérone / + EE2, ….)]]),CONCATENATE(liste_groupe[[#This Row],[Nom de l''échantillon donné par le client]],"-",liste_groupe[[#This Row],[Concentration]],liste_groupe[[#This Row],[Unité]],liste_groupe[[#This Row],[Dopage (+Testostérone / + EE2, ….)]])))
A30: =IF(ISBLANK(liste_groupe[[#This Row],[Code WF]])," ",IF(ISBLANK(liste_groupe[[#This Row],[Unité]]),CONCATENATE(liste_groupe[[#This Row],[Nom de l''échantillon donné par le client]],liste_groupe[[#This Row],[Dopage (+Testostérone / + EE2, ….)]]),CONCATENATE(liste_groupe[[#This Row],[Nom de l''échantillon donné par le client]],"-",liste_groupe[[#This Row],[Concentration]],liste_groupe[[#This Row],[Unité]],liste_groupe[[#This Row],[Dopage (+Testostérone / + EE2, ….)]])))
A31: =IF(ISBLANK(liste_groupe[[#This Row],[Code WF]])," ",IF(ISBLANK(liste_groupe[[#This Row],[Unité]]),CONCATENATE(liste_groupe[[#This Row],[Nom de l''échantillon donné par le client]],liste_groupe[[#This Row],[Dopage (+Testostérone / + EE2, ….)]]),CONCATENATE(liste_groupe[[#This Row],[Nom de l''échantillon donné par le client]],"-",liste_groupe[[#This Row],[Concentration]],liste_groupe[[#This Row],[Unité]],liste_groupe[[#This Row],[Dopage (+Testostérone / + EE2, ….)]])))
... A35: =IF(ISBLANK(liste_groupe[[#This Row],[Code WF]])," ",IF(ISBLANK(liste_groupe[[#This Row],[Unité]]),CONCATENATE(liste_groupe[[#This Row],[Nom de l''échantillon donné par le client]],liste_groupe[[#This Row],[Dopage (+Testostérone / + EE2, ….)]]),CONCATENATE(liste_groupe[[#This Row],[Nom de l''échantillon donné par le client]],"-",liste_groupe[[#This Row],[Concentration]],liste_groupe[[#This Row],[Unité]],liste_groupe[[#This Row],[Dopage (+Testostérone / + EE2, ….)]])))
A36: =IF(ISBLANK(liste_groupe[[#This Row],[Code WF]])," ",IF(ISBLANK(liste_groupe[[#This Row],[Unité]]),CONCATENATE(liste_groupe[[#This Row],[Nom de l''échantillon donné par le client]],liste_groupe[[#This Row],[Dopage (+Testostérone / + EE2, ….)]]),CONCATENATE(liste_groupe[[#This Row],[Nom de l''échantillon donné par le client]],"-",liste_groupe[[#This Row],[Concentration]],liste_groupe[[#This Row],[Unité]],liste_groupe[[#This Row],[Dopage (+Testostérone / + EE2, ….)]]))) -> Testo -30µg/L | B36: Témoin | C36: 30 | D36: µg/L | E36: Testo
A37: =IF(ISBLANK(liste_groupe[[#This Row],[Code WF]])," ",IF(ISBLANK(liste_groupe[[#This Row],[Unité]]),CONCATENATE(liste_groupe[[#This Row],[Nom de l''échantillon donné par le client]],liste_groupe[[#This Row],[Dopage (+Testostérone / + EE2, ….)]]),CONCATENATE(liste_groupe[[#This Row],[Nom de l''échantillon donné par le client]],"-",liste_groupe[[#This Row],[Concentration]],liste_groupe[[#This Row],[Unité]],liste_groupe[[#This Row],[Dopage (+Testostérone / + EE2, ….)]]))) -> Testo 30µg/L + EE2 -64ng/L | B37: Témoin | C37: 64 | D37: ng/L | E37: Testo 30µg/L + EE2
A38: =IF(ISBLANK(liste_groupe[[#This Row],[Code WF]])," ",IF(ISBLANK(liste_groupe[[#This Row],[Unité]]),CONCATENATE(liste_groupe[[#This Row],[Nom de l''échantillon donné par le client]],liste_groupe[[#This Row],[Dopage (+Testostérone / + EE2, ….)]]),CONCATENATE(liste_groupe[[#This Row],[Nom de l''échantillon donné par le client]],"-",liste_groupe[[#This Row],[Concentration]],liste_groupe[[#This Row],[Unité]],liste_groupe[[#This Row],[Dopage (+Testostérone / + EE2, ….)]]))) -> Testo 30µg/L + FAD-10µg/L | B38: Témoin | C38: 10 | D38: µg/L | E38: Testo 30µg/L + FAD
A39: =IF(ISBLANK(liste_groupe[[#This Row],[Code WF]])," ",IF(ISBLANK(liste_groupe[[#This Row],[Unité]]),CONCATENATE(liste_groupe[[#This Row],[Nom de l''échantillon donné par le client]],liste_groupe[[#This Row],[Dopage (+Testostérone / + EE2, ….)]]),CONCATENATE(liste_groupe[[#This Row],[Nom de l''échantillon donné par le client]],"-",liste_groupe[[#This Row],[Concentration]],liste_groupe[[#This Row],[Unité]],liste_groupe[[#This Row],[Dopage (+Testostérone / + EE2, ….)]]))) -> Tamoxifen-30.2µg/L + Testostérone | B39: =B15 -> 0 | C39: =C15 -> 30.2 | D39: =D15 -> µg/L | E39: =E15 -> Tamoxifen | F39: + Testostérone
A40: =IF(ISBLANK(liste_groupe[[#This Row],[Code WF]])," ",IF(ISBLANK(liste_groupe[[#This Row],[Unité]]),CONCATENATE(liste_groupe[[#This Row],[Nom de l''échantillon donné par le client]],liste_groupe[[#This Row],[Dopage (+Testostérone / + EE2, ….)]]),CONCATENATE(liste_groupe[[#This Row],[Nom de l''échantillon donné par le client]],"-",liste_groupe[[#This Row],[Concentration]],liste_groupe[[#This Row],[Unité]],liste_groupe[[#This Row],[Dopage (+Testostérone / + EE2, ….)]]))) -> Tamoxifen-60.4µg/L + Testostérone | B40: =B16 -> 0 | C40: =C16 -> 60.4 | D40: =D16 -> µg/L | E40: =E16 -> Tamoxifen | F40: + Testostérone
A41: =IF(ISBLANK(liste_groupe[[#This Row],[Code WF]])," ",IF(ISBLANK(liste_groupe[[#This Row],[Unité]]),CONCATENATE(liste_groupe[[#This Row],[Nom de l''échantillon donné par le client]],liste_groupe[[#This Row],[Dopage (+Testostérone / + EE2, ….)]]),CONCATENATE(liste_groupe[[#This Row],[Nom de l''échantillon donné par le client]],"-",liste_groupe[[#This Row],[Concentration]],liste_groupe[[#This Row],[Unité]],liste_groupe[[#This Row],[Dopage (+Testostérone / + EE2, ….)]]))) -> Tamoxifen-121µg/L + Testostérone | B41: =B17 -> 0 | C41: =C17 -> 121 | D41: =D17 -> µg/L | E41: =E17 -> Tamoxifen | F41: + Testostérone
A42: =IF(ISBLANK(liste_groupe[[#This Row],[Code WF]])," ",IF(ISBLANK(liste_groupe[[#This Row],[Unité]]),CONCATENATE(liste_groupe[[#This Row],[Nom de l''échantillon donné par le client]],liste_groupe[[#This Row],[Dopage (+Testostérone / + EE2, ….)]]),CONCATENATE(liste_groupe[[#This Row],[Nom de l''échantillon donné par le client]],"-",liste_groupe[[#This Row],[Concentration]],liste_groupe[[#This Row],[Unité]],liste_groupe[[#This Row],[Dopage (+Testostérone / + EE2, ….)]]))) -> Tamoxifen-242µg/L + Testostérone | B42: =B18 -> 0 | C42: =C18 -> 242 | D42: =D18 -> µg/L | E42: =E18 -> Tamoxifen | F42: + Testostérone
A43: =IF(ISBLANK(liste_groupe[[#This Row],[Code WF]])," ",IF(ISBLANK(liste_groupe[[#This Row],[Unité]]),CONCATENATE(liste_groupe[[#This Row],[Nom de l''échantillon donné par le client]],liste_groupe[[#This Row],[Dopage (+Testostérone / + EE2, ….)]]),CONCATENATE(liste_groupe[[#This Row],[Nom de l''échantillon donné par le client]],"-",liste_groupe[[#This Row],[Concentration]],liste_groupe[[#This Row],[Unité]],liste_groupe[[#This Row],[Dopage (+Testostérone / + EE2, ….)]]))) -> Tamoxifen-483µg/L + Testostérone | B43: =B19 -> 0 | C43: =C19 -> 483 | D43: =D19 -> µg/L | E43: =E19 -> Tamoxifen | F43: + Testostérone
...

Sheet Feuil1
A1: Nom groupe | B1: N° de valeur | C1: file name | D1: total area | E1: mean intensity | G1: total fluorescence | I1: nbre de larves
A2: 01 EE2 0 | B2: A | C2: C:\Users\Olympus\Desktop\20190122\plaque1/@01 EE2 0/A1_1.tif | D2: 4931.616 | E2: 73.0526 | G2: 360268
A3: 01 EE2 0 | B3: A | C3: C:\Users\Olympus\Desktop\20190122\plaque1/@01 EE2 0/A1_2.tif | D3: 5234.4345 | E3: 71.1281 | G3: 372315
A4: 01 EE2 0 | B4: A | C4: C:\Users\Olympus\Desktop\20190122\plaque1/@01 EE2 0/A1_3.tif | D4: 3547.3027 | E4: 66.9878 | G4: 237626
A5: 01 EE2 0 | B5: A | C5: C:\Users\Olympus\Desktop\20190122\plaque3/@01 EE2 0/A1_3.tif | D5: 21456.8555 | E5: 67.0655 | G5: 1439015
A6: 01 EE2 0 | B6: A | C6: C:\Users\Olympus\Desktop\20190122\plaque3/@01 EE2 0/A1_2.tif | D6: 21586.6348 | E6: 66.4108 | G6: 1433586
A7: 01 EE2 0 | B7: A | C7: C:\Users\Olympus\Desktop\20190122\plaque3/@01 EE2 0/A1_1.tif | D7: 15984.4921 | E7: 69.7767 | G7: 1115346

Sheet Raw data R4
A1: Nom groupe | B1: N° de valeur | C1: file name | D1: total area | E1: mean intensity | G1: total fluorescence | I1: nbre de larves | J1: Colonne1 | L1: (Tous)
A2: =IFERROR(LEFT(RIGHT(C2,LEN(C2)-SEARCH("@",C2)),SEARCH("/",RIGHT(C2,LEN(C2)-SEARCH("@",C2)-1))),"") -> 01 Témoins solvant | B2: =LEFT(RIGHT(RIGHT(Tableau4[[#This Row],[file name]],LEN(Tableau4[[#This Row],[file name]])-SEARCH("@",Tableau4[[#This Row],[file name]])),LEN(RIGHT(Tableau4[[#This Row],[file name]],LEN(Tableau4[[#This Row],[file name]])-SEARCH("@",Tableau4[[#This Row],[file name]])))-SEARCH("/",RIGHT(Tableau4[[#This Row],[file name]],LEN(Tableau4[[#This Row],[file name]])-SEARCH("@",Tableau4[[#This Row],[file name]])))),1) -> A | C2: D:\Images\20210706\plaque 1/@01 Témoins solvant/A1_01.tif | D2: 3309.3739 | E2: 64.1242 | G2: 212211 | K2: Filtre lignes : Enlever (vide) et Néant | L2: Filtre colonnes : Enlever (vide) et " "
A3: =IFERROR(LEFT(RIGHT(C3,LEN(C3)-SEARCH("@",C3)),SEARCH("/",RIGHT(C3,LEN(C3)-SEARCH("@",C3)-1))),"") -> 01 Témoins solvant | B3: =LEFT(RIGHT(RIGHT(Tableau4[[#This Row],[file name]],LEN(Tableau4[[#This Row],[file name]])-SEARCH("@",Tableau4[[#This Row],[file name]])),LEN(RIGHT(Tableau4[[#This Row],[file name]],LEN(Tableau4[[#This Row],[file name]])-SEARCH("@",Tableau4[[#This Row],[file name]])))-SEARCH("/",RIGHT(Tableau4[[#This Row],[file name]],LEN(Tableau4[[#This Row],[file name]])-SEARCH("@",Tableau4[[#This Row],[file name]])))),1) -> A | C3: D:\Images\20210706\plaque 1/@01 Témoins solvant/A1_02.tif | D3: 3806.8615 | E3: 63.8977 | G3: 243250 | K3: Moyenne de total fluorescence | L3: Étiquettes de colonnes
A4: =IFERROR(LEFT(RIGHT(C4,LEN(C4)-SEARCH("@",C4)),SEARCH("/",RIGHT(C4,LEN(C4)-SEARCH("@",C4)-1))),"") -> 01 Témoins solvant | B4: =LEFT(RIGHT(RIGHT(Tableau4[[#This Row],[file name]],LEN(Tableau4[[#This Row],[file name]])-SEARCH("@",Tableau4[[#This Row],[file name]])),LEN(RIGHT(Tableau4[[#This Row],[file name]],LEN(Tableau4[[#This Row],[file name]])-SEARCH("@",Tableau4[[#This Row],[file name]])))-SEARCH("/",RIGHT(Tableau4[[#This Row],[file name]],LEN(Tableau4[[#This Row],[file name]])-SEARCH("@",Tableau4[[#This Row],[file name]])))),1) -> A | C4: D:\Images\20210706\plaque 1/@01 Témoins solvant/A1_03.tif | D4: 2660.477 | E4: 64.8862 | G4: 172628 | K4: Étiquettes de lignes | L4: 01 Témoins solvant | M4: 02 EE2 33.8 | N4: 03 EE2 50 | O4: 04 EE2 76 | P4: 05 EE2 114 | Q4: 06 EE2 170 | R4: 07 EE2 488 | S4: 08tam 30.2µg_L | T4: 09 tam 60.4µg_L | U4: 10 tam 121µg_L | V4: 11 tam 242µg_L | W4: 12 tam 483µg_L | X4: 01 testo 30 | Y4: 02 testo 30 | Z4: 03Testo + EE2 64 | AA4: 04 Testo +FAD | AB4: 05 tam 30.2 + testo | AC4: 06 tam 60.4 + testo | AD4: 07 tam 121 + testo | AE4: 08 tam 242 + testo | AF4: 09 tam 483 + testo
A5: =IFERROR(LEFT(RIGHT(C5,LEN(C5)-SEARCH("@",C5)),SEARCH("/",RIGHT(C5,LEN(C5)-SEARCH("@",C5)-1))),"") -> 01 Témoins solvant | B5: =LEFT(RIGHT(RIGHT(Tableau4[[#This Row],[file name]],LEN(Tableau4[[#This Row],[file name]])-SEARCH("@",Tableau4[[#This Row],[file name]])),LEN(RIGHT(Tableau4[[#This Row],[file name]],LEN(Tableau4[[#This Row],[file name]])-SEARCH("@",Tableau4[[#This Row],[file name]])))-SEARCH("/",RIGHT(Tableau4[[#This Row],[file name]],LEN(Tableau4[[#This Row],[file name]])-SEARCH("@",Tableau4[[#This Row],[file name]])))),1) -> B | C5: D:\Images\20210706\plaque 1/@01 Témoins solvant/B1_01.tif | D5: 6078.0004 | E5: 69.0605 | G5: 419750 | K5: A | L5: 209363 | M5: 763340.33 | N5: 212852.67 | O5: 1535448.3 | P5: 3204036.3 | Q5: 2781247.5 | R5: 3334371 | S5: 327923.67 | T5: 59842.667 | U5: 296776.33 | W5: 202340.33 | X5: 2451907.3 | Y5: 763391 | Z5: 1351450.3 | AA5: 276977.67 | AB5: 1020822.7 | AC5: 1475454.7 | AD5: 2472672 | AE5: 402997.5
A6: =IFERROR(LEFT(RIGHT(C6,LEN(C6)-SEARCH("@",C6)),SEARCH("/",RIGHT(C6,LEN(C6)-SEARCH("@",C6)-1))),"") -> 01 Témoins solvant | B6: =LEFT(RIGHT(RIGHT(Tableau4[[#This Row],[file name]],LEN(Tableau4[[#This Row],[file name]])-SEARCH("@",Tableau4[[#This Row],[file name]])),LEN(RIGHT(Tableau4[[#This Row],[file name]],LEN(Tableau4[[#This Row],[file name]])-SEARCH("@",Tableau4[[#This Row],[file name]])))-SEARCH("/",RIGHT(Tableau4[[#This Row],[file name]],LEN(Tableau4[[#This Row],[file name]])-SEARCH("@",Tableau4[[#This Row],[file name]])))),1) -> B | C6: D:\Images\20210706\plaque 1/@01 Témoins solvant/B1_02.tif | D6: 3006.5554 | E6: 65.2734 | G6: 196248 | K6: B | L6: 223862.33 | M6: 220336.67 | N6: 305969.33 | O6: 76267 | P6: 470212.67 | Q6: 2656338.3 | R6: 4608624 | S6: 191021 | T6: 911880 | U6: 66721.333 | V6: 55448.5 | W6: 567157.33 | X6: 2295905 | Y6: 1951211.3 | Z6: 3585811.3 | AA6: 107738.33 | AB6: 2013930.7 | AC6: 3171346.7 | AD6: 2977910.3 | AE6: 4320794.7 | AF6: 1415395.3
A7: =IFERROR(LEFT(RIGHT(C7,LEN(C7)-SEARCH("@",C7)),SEARCH("/",RIGHT(C7,LEN(C7)-SEARCH("@",C7)-1))),"") -> 01 Témoins solvant | B7: =LEFT(RIGHT(RIGHT(Tableau4[[#This Row],[file name]],LEN(Tableau4[[#This Row],[file name]])-SEARCH("@",Tableau4[[#This Row],[file name]])),LEN(RIGHT(Tableau4[[#This Row],[file name]],LEN(Tableau4[[#This Row],[file name]])-SEARCH("@",Tableau4[[#This Row],[file name]])))-SEARCH("/",RIGHT(Tableau4[[#This Row],[file name]],LEN(Tableau4[[#This Row],[file name]])-SEARCH("@",Tableau4[[#This Row],[file name]])))),1) -> B | C7: D:\Images\20210706\plaque 1/@01 Témoins solvant/B1_03.tif | D7: 886.8257 | E7: 62.6829 | G7: 55589 | K7: C | L7: 165223.33 | M7: 247208 | N7: 53224 | O7: 730484.67 | P7: 848194.67 | Q7: 2253150 | R7: 5526207.7 | S7: 58227.667 | T7: 290287.67 | U7: 205823 | V7: 135554.33 | W7: 653129 | X7: 3237843.5 | Y7: 200292.67 | Z7: 5725325 | AA7: 236999 | AB7: 875347.67 | AC7: 3095786 | AD7: 2143399.7 | AE7: 4419535.3 | AF7: 1568311.3
A8: =IFERROR(LEFT(RIGHT(C8,LEN(C8)-SEARCH("@",C8)),SEARCH("/",RIGHT(C8,LEN(C8)-SEARCH("@",C8)-1))),"") -> 01 Témoins solvant | B8: =LEFT(RIGHT(RIGHT(Tableau4[[#This Row],[file name]],LEN(Tableau4[[#This Row],[file name]])-SEARCH("@",Tableau4[[#This Row],[file name]])),LEN(RIGHT(Tableau4[[#This Row],[file name]],LEN(Tableau4[[#This Row],[file name]])-SEARCH("@",Tableau4[[#This Row],[file name]])))-SEARCH("/",RIGHT(Tableau4[[#This Row],[file name]],LEN(Tableau4[[#This Row],[file name]])-SEARCH("@",Tableau4[[#This Row],[file name]])))),1) -> C | C8: D:\Images\20210706\plaque 1/@01 Témoins solvant/C1_01.tif | D8: 1925.0606 | E8: 64.0562 | G8: 123312 | K8: D | L8: 22358 | M8: 290352.33 | N8: 910041.67 | O8: 295471.67 | P8: 2160336 | Q8: 1398430.3 | R8: 8878170.7 | S8: 358234.33 | T8: 123564.33 | U8: 244014.33 | V8: 200206.33 | W8: 485194.67 | X8: 2340426.7 | Y8: 2068997 | Z8: 4350810 | AA8: 433665 | AB8: 1527078 | AC8: 505966.33 | AD8: 4255782.7 | AE8: 3419736.7 | AF8: 1466290.7
A9: =IFERROR(LEFT(RIGHT(C9,LEN(C9)-SEARCH("@",C9)),SEARCH("/",RIGHT(C9,LEN(C9)-SEARCH("@",C9)-1))),"") -> 01 Témoins solvant | B9: =LEFT(RIGHT(RIGHT(Tableau4[[#This Row],[file name]],LEN(Tableau4[[#This Row],[file name]])-SEARCH("@",Tableau4[[#This Row],[file name]])),LEN(RIGHT(Tableau4[[#This Row],[file name]],LEN(Tableau4[[#This Row],[file name]])-SEARCH("@",Tableau4[[#This Row],[file name]])))-SEARCH("/",RIGHT(Tableau4[[#This Row],[file name]],LEN(Tableau4[[#This Row],[file name]])-SEARCH("@",Tableau4[[#This Row],[file name]])))),1) -> C | C9: D:\Images\20210706\plaque 1/@01 Témoins solvant/C1_02.tif | D9: 2422.5482 | E9: 64.3839 | G9: 155973 | K9: E | L9: 455100.33 | M9: 187394.33 | N9: 282587.33 | O9: 3249625 | P9: 524078 | Q9: 2271600.3 | R9: 4329440 | S9: 521324 | T9: 233350.33 | U9: 118892 | V9: 383699.67 | W9: 1320469 | X9: 4353982.3 | Y9: 2197222.7 | Z9: 3518809.3 | AA9: 408285.67 | AB9: 3179875.7 | AC9: 2457357.7 | AD9: 2619640 | AE9: 1259300 | AF9: 1384854
A10: =IFERROR(LEFT(RIGHT(C10,LEN(C10)-SEARCH("@",C10)),SEARCH("/",RIGHT(C10,LEN(C10)-SEARCH("@",C10)-1))),"") -> 01 Témoins solvant | B10: =LEFT(RIGHT(RIGHT(Tableau4[[#This Row],[file name]],LEN(Tableau4[[#This Row],[file name]])-SEARCH("@",Tableau4[[#This Row],[file name]])),LEN(RIGHT(Tableau4[[#This Row],[file name]],LEN(Tableau4[[#This Row],[file name]])-SEARCH("@",Tableau4[[#This Row],[file name]])))-SEARCH("/",RIGHT(Tableau4[[#This Row],[file name]],LEN(Tableau4[[#This Row],[file name]])-SEARCH("@",Tableau4[[#This Row],[file name]])))),1) -> C | C10: D:\Images\20210706\plaque 1/@01 Témoins solvant/C1_03.tif | D10: 3266.1141 | E10: 66.2517 | G10: 216385 | K10: F | L10: 279696 | M10: 206291.67 | N10: 72748.333 | O10: 400953 | P10: 553494.33 | Q10: 757846.67 | R10: 4509148 | S10: 101833.67 | T10: 68026 | U10: 29272.333 | V10: 96844.333 | W10: 152952.33 | X10: 1818043 | Y10: 4282805.7 | Z10: 3497251.5 | AA10: 439721.33 | AB10: 542910.33 | AC10: 2364861.3 | AD10: 738112.67 | AE10: 3096492.5 | AF10: 316200.33
A11: =IFERROR(LEFT(RIGHT(C11,LEN(C11)-SEARCH("@",C11)),SEARCH("/",RIGHT(C11,LEN(C11)-SEARCH("@",C11)-1))),"") -> 01 Témoins solvant | B11: =LEFT(RIGHT(RIGHT(Tableau4[[#This Row],[file name]],LEN(Tableau4[[#This Row],[file name]])-SEARCH("@",Tableau4[[#This Row],[file name]])),LEN(RIGHT(Tableau4[[#This Row],[file name]],LEN(Tableau4[[#This Row],[file name]])-SEARCH("@",Tableau4[[#This Row],[file name]])))-SEARCH("/",RIGHT(Tableau4[[#This Row],[file name]],LEN(Tableau4[[#This Row],[file name]])-SEARCH("@",Tableau4[[#This Row],[file name]])))),1) -> D | C11: D:\Images\20210706\plaque 1/@01 Témoins solvant/D1_01.tif | D11: 584.0072 | E11: 66.4444 | G11: 38804 | K11: G | L11: 178014.33 | M11: 492718 | N11: 214143 | O11: 241880 | P11: 1198137.7 | Q11: 2592890.7 | R11: 4464727.3 | S11: 117529.67 | T11: 744551.67 | U11: 172620.67 | V11: 334549.33 | W11: 1292797.5 | X11: 3591514 | Y11: 703483.67 | Z11: 3239653.7 | AA11: 19164 | AB11: 1208462.3 | AC11: 779245.67 | AD11: 321896.33 | AE11: 2484626 | AF11: 1967087.3
A12: =IFERROR(LEFT(RIGHT(C12,LEN(C12)-SEARCH("@",C12)),SEARCH("/",RIGHT(C12,LEN(C12)-SEARCH("@",C12)-1))),"") -> 01 Témoins solvant | B12: =LEFT(RIGHT(RIGHT(Tableau4[[#This Row],[file name]],LEN(Tableau4[[#This Row],[file name]])-SEARCH("@",Tableau4[[#This Row],[file name]])),LEN(RIGHT(Tableau4[[#This Row],[file name]],LEN(Tableau4[[#This Row],[file name]])-SEARCH("@",Tableau4[[#This Row],[file name]])))-SEARCH("/",RIGHT(Tableau4[[#This Row],[file name]],LEN(Tableau4[[#This Row],[file name]])-SEARCH("@",Tableau4[[#This Row],[file name]])))),1) -> D | C12: D:\Images\20210706\plaque 1/@01 Témoins solvant/D1_02.tif | D12: 237.9288 | E12: 66.5455 | G12: 15833 | K12: H | L12: 86649.333 | M12: 234648.33 | N12: 254764 | O12: 454379.33 | P12: 910914.33 | Q12: 2426628.7 | R12: 3400637.3 | S12: 27542 | T12: 305399.33 | U12: 164986 | V12: 234107.67 | W12: 165144 | X12: 2326497.3 | Y12: 918506.33 | Z12: 3217490 | AC12: 2155137.7 | AD12: 2269026 | AE12: 1810840 | AF12: 2080089
A13: =IFERROR(LEFT(RIGHT(C13,LEN(C13)-SEARCH("@",C13)),SEARCH("/",RIGHT(C13,LEN(C13)-SEARCH("@",C13)-1))),"") -> 01 Témoins solvant | B13: =LEFT(RIGHT(RIGHT(Tableau4[[#This Row],[file name]],LEN(Tableau4[[#This Row],[file name]])-SEARCH("@",Tableau4[[#This Row],[file name]])),LEN(RIGHT(Tableau4[[#This Row],[file name]],LEN(Tableau4[[#This Row],[file name]])-SEARCH("@",Tableau4[[#This Row],[file name]])))-SEARCH("/",RIGHT(Tableau4[[#This Row],[file name]],LEN(Tableau4[[#This Row],[file name]])-SEARCH("@",Tableau4[[#This Row],[file name]])))),1) -> D | C13: D:\Images\20210706\plaque 1/@01 Témoins solvant/D1_03.tif | D13: 194.6691 | E13: 63.8889 | G13: 12437
A14: =IFERROR(LEFT(RIGHT(C14,LEN(C14)-SEARCH("@",C14)),SEARCH("/",RIGHT(C14,LEN(C14)-SEARCH("@",C14)-1))),"") -> 01 Témoins solvant | B14: =LEFT(RIGHT(RIGHT(Tableau4[[#This Row],[file name]],LEN(Tableau4[[#This Row],[file name]])-SEARCH("@",Tableau4[[#This Row],[file name]])),LEN(RIGHT(Tableau4[[#This Row],[file name]],LEN(Tableau4[[#This Row],[file name]])-SEARCH("@",Tableau4[[#This Row],[file name]])))-SEARCH("/",RIGHT(Tableau4[[#This Row],[file name]],LEN(Tableau4[[#This Row],[file name]])-SEARCH("@",Tableau4[[#This Row],[file name]])))),1) -> E | C14: D:\Images\20210706\plaque 1/@01 Témoins solvant/E1_01.tif | D14: 4477.3882 | E14: 66.4686 | G14: 297606
A15: =IFERROR(LEFT(RIGHT(C15,LEN(C15)-SEARCH("@",C15)),SEARCH("/",RIGHT(C15,LEN(C15)-SEARCH("@",C15)-1))),"") -> 01 Témoins solvant | B15: =LEFT(RIGHT(RIGHT(Tableau4[[#This Row],[file name]],LEN(Tableau4[[#This Row],[file name]])-SEARCH("@",Tableau4[[#This Row],[file name]])),LEN(RIGHT(Tableau4[[#This Row],[file name]],LEN(Tableau4[[#This Row],[file name]])-SEARCH("@",Tableau4[[#This Row],[file name]])))-SEARCH("/",RIGHT(Tableau4[[#This Row],[file name]],LEN(Tableau4[[#This Row],[file name]])-SEARCH("@",Tableau4[[#This Row],[file name]])))),1) -> E | C15: D:\Images\20210706\plaque 1/@01 Témoins solvant/E1_02.tif | D15: 6791.7869 | E15: 72.5573 | G15: 492794
A16: =IFERROR(LEFT(RIGHT(C16,LEN(C16)-SEARCH("@",C16)),SEARCH("/",RIGHT(C16,LEN(C16)-SEARCH("@",C16)-1))),"") -> 01 Témoins solvant | B16: =LEFT(RIGHT(RIGHT(Tableau4[[#This Row],[file name]],LEN(Tableau4[[#This Row],[file name]])-SEARCH("@",Tableau4[[#This Row],[file name]])),LEN(RIGHT(Tableau4[[#This Row],[file name]],LEN(Tableau4[[#This Row],[file name]])-SEARCH("@",Tableau4[[#This Row],[file name]])))-SEARCH("/",RIGHT(Tableau4[[#This Row],[file name]],LEN(Tableau4[[#This Row],[file name]])-SEARCH("@",Tableau4[[#This Row],[file name]])))),1) -> E | C16: D:\Images\20210706\plaque 1/@01 Témoins solvant/E1_03.tif | D16: 8240.9899 | E16: 69.7612 | G16: 574901
A17: =IFERROR(LEFT(RIGHT(C17,LEN(C17)-SEARCH("@",C17)),SEARCH("/",RIGHT(C17,LEN(C17)-SEARCH("@",C17)-1))),"") -> 01 Témoins solvant | B17: =LEFT(RIGHT(RIGHT(Tableau4[[#This Row],[file name]],LEN(Tableau4[[#This Row],[file name]])-SEARCH("@",Tableau4[[#This Row],[file name]])),LEN(RIGHT(Tableau4[[#This Row],[file name]],LEN(Tableau4[[#This Row],[file name]])-SEARCH("@",Tableau4[[#This Row],[file name]])))-SEARCH("/",RIGHT(Tableau4[[#This Row],[file name]],LEN(Tableau4[[#This Row],[file name]])-SEARCH("@",Tableau4[[#This Row],[file name]])))),1) -> F | C17: D:\Images\20210706\plaque 1/@01 Témoins solvant/F1_01.tif | D17: 4066.4202 | E17: 63.2553 | G17: 257223
A18: =IFERROR(LEFT(RIGHT(C18,LEN(C18)-SEARCH("@",C18)),SEARCH("/",RIGHT(C18,LEN(C18)-SEARCH("@",C18)-1))),"") -> 01 Témoins solvant | B18: =LEFT(RIGHT(RIGHT(Tableau4[[#This Row],[file name]],LEN(Tableau4[[#This Row],[file name]])-SEARCH("@",Tableau4[[#This Row],[file name]])),LEN(RIGHT(Tableau4[[#This Row],[file name]],LEN(Tableau4[[#This Row],[file name]])-SEARCH("@",Tableau4[[#This Row],[file name]])))-SEARCH("/",RIGHT(Tableau4[[#This Row],[file name]],LEN(Tableau4[[#This Row],[file name]])-SEARCH("@",Tableau4[[#This Row],[file name]])))),1) -> F | C18: D:\Images\20210706\plaque 1/@01 Témoins solvant/F1_02.tif | D18: 4736.9469 | E18: 64.3242 | G18: 304700
A19: =IFERROR(LEFT(RIGHT(C19,LEN(C19)-SEARCH("@",C19)),SEARCH("/",RIGHT(C19,LEN(C19)-SEARCH("@",C19)-1))),"") -> 01 Témoins solvant | B19: =LEFT(RIGHT(RIGHT(Tableau4[[#This Row],[file name]],LEN(Tableau4[[#This Row],[file name]])-SEARCH("@",Tableau4[[#This Row],[file name]])),LEN(RIGHT(Tableau4[[#This Row],[file name]],LEN(Tableau4[[#This Row],[file name]])-SEARCH("@",Tableau4[[#This Row],[file name]])))-SEARCH("/",RIGHT(Tableau4[[#This Row],[file name]],LEN(Tableau4[[#This Row],[file name]])-SEARCH("@",Tableau4[[#This Row],[file name]])))),1) -> F | C19: D:\Images\20210706\plaque 1/@01 Témoins solvant/F1_03.tif | D19: 4347.6088 | E19: 63.7512 | G19: 277165
A20: =IFERROR(LEFT(RIGHT(C20,LEN(C20)-SEARCH("@",C20)),SEARCH("/",RIGHT(C20,LEN(C20)-SEARCH("@",C20)-1))),"") -> 01 Témoins solvant | B20: =LEFT(RIGHT(RIGHT(Tableau4[[#This Row],[file name]],LEN(Tableau4[[#This Row],[file name]])-SEARCH("@",Tableau4[[#This Row],[file name]])),LEN(RIGHT(Tableau4[[#This Row],[file name]],LEN(Tableau4[[#This Row],[file name]])-SEARCH("@",Tableau4[[#This Row],[file name]])))-SEARCH("/",RIGHT(Tableau4[[#This Row],[file name]],LEN(Tableau4[[#This Row],[file name]])-SEARCH("@",Tableau4[[#This Row],[file name]])))),1) -> G | C20: D:\Images\20210706\plaque 1/@01 Témoins solvant/G1_01.tif | D20: 3093.0749 | E20: 66.2727 | G20: 204987
A21: =IFERROR(LEFT(RIGHT(C21,LEN(C21)-SEARCH("@",C21)),SEARCH("/",RIGHT(C21,LEN(C21)-SEARCH("@",C21)-1))),"") -> 01 Témoins solvant | B21: =LEFT(RIGHT(RIGHT(Tableau4[[#This Row],[file name]],LEN(Tableau4[[#This Row],[file name]])-SEARCH("@",Tableau4[[#This Row],[file name]])),LEN(RIGHT(Tableau4[[#This Row],[file name]],LEN(Tableau4[[#This Row],[file name]])-SEARCH("@",Tableau4[[#This Row],[file name]])))-SEARCH("/",RIGHT(Tableau4[[#This Row],[file name]],LEN(Tableau4[[#This Row],[file name]])-SEARCH("@",Tableau4[[#This Row],[file name]])))),1) -> G | C21: D:\Images\20210706\plaque 1/@01 Témoins solvant/G1_02.tif | D21: 800.3061 | E21: 63.5676 | G21: 50874
A22: =IFERROR(LEFT(RIGHT(C22,LEN(C22)-SEARCH("@",C22)),SEARCH("/",RIGHT(C22,LEN(C22)-SEARCH("@",C22)-1))),"") -> 01 Témoins solvant | B22: =LEFT(RIGHT(RIGHT(Tableau4[[#This Row],[file name]],LEN(Tableau4[[#This Row],[file name]])-SEARCH("@",Tableau4[[#This Row],[file name]])),LEN(RIGHT(Tableau4[[#This Row],[file name]],LEN(Tableau4[[#This Row],[file name]])-SEARCH("@",Tableau4[[#This Row],[file name]])))-SEARCH("/",RIGHT(Tableau4[[#This Row],[file name]],LEN(Tableau4[[#This Row],[file name]])-SEARCH("@",Tableau4[[#This Row],[file name]])))),1) -> G | C22: D:\Images\20210706\plaque 1/@01 Témoins solvant/G1_03.tif | D22: 4282.7191 | E22: 64.9545 | G22: 278182
A23: =IFERROR(LEFT(RIGHT(C23,LEN(C23)-SEARCH("@",C23)),SEARCH("/",RIGHT(C23,LEN(C23)-SEARCH("@",C23)-1))),"") -> 01 Témoins solvant | B23: =LEFT(RIGHT(RIGHT(Tableau4[[#This Row],[file name]],LEN(Tableau4[[#This Row],[file name]])-SEARCH("@",Tableau4[[#This Row],[file name]])),LEN(RIGHT(Tableau4[[#This Row],[file name]],LEN(Tableau4[[#This Row],[file name]])-SEARCH("@",Tableau4[[#This Row],[file name]])))-SEARCH("/",RIGHT(Tableau4[[#This Row],[file name]],LEN(Tableau4[[#This Row],[file name]])-SEARCH("@",Tableau4[[#This Row],[file name]])))),1) -> H | C23: D:\Images\20210706\plaque 1/@01 Témoins solvant/H1_01.tif | D23: 1838.541 | E23: 65.5529 | G23: 120522
A24: =IFERROR(LEFT(RIGHT(C24,LEN(C24)-SEARCH("@",C24)),SEARCH("/",RIGHT(C24,LEN(C24)-SEARCH("@",C24)-1))),"") -> 01 Témoins solvant | B24: =LEFT(RIGHT(RIGHT(Tableau4[[#This Row],[file name]],LEN(Tableau4[[#This Row],[file name]])-SEARCH("@",Tableau4[[#This Row],[file name]])),LEN(RIGHT(Tableau4[[#This Row],[file name]],LEN(Tableau4[[#This Row],[file name]])-SEARCH("@",Tableau4[[#This Row],[file name]])))-SEARCH("/",RIGHT(Tableau4[[#This Row],[file name]],LEN(Tableau4[[#This Row],[file name]])-SEARCH("@",Tableau4[[#This Row],[file name]])))),1) -> H | C24: D:\Images\20210706\plaque 1/@01 Témoins solvant/H1_02.tif | D24: 994.9752 | E24: 64.4783 | G24: 64154
A25: =IFERROR(LEFT(RIGHT(C25,LEN(C25)-SEARCH("@",C25)),SEARCH("/",RIGHT(C25,LEN(C25)-SEARCH("@",C25)-1))),"") -> 01 Témoins solvant | B25: =LEFT(RIGHT(RIGHT(Tableau4[[#This Row],[file name]],LEN(Tableau4[[#This Row],[file name]])-SEARCH("@",Tableau4[[#This Row],[file name]])),LEN(RIGHT(Tableau4[[#This Row],[file name]],LEN(Tableau4[[#This Row],[file name]])-SEARCH("@",Tableau4[[#This Row],[file name]])))-SEARCH("/",RIGHT(Tableau4[[#This Row],[file name]],LEN(Tableau4[[#This Row],[file name]])-SEARCH("@",Tableau4[[#This Row],[file name]])))),1) -> H | C25: D:\Images\20210706\plaque 1/@01 Témoins solvant/H1_03.tif | D25: 1189.6442 | E25: 63.2727 | G25: 75272
A26: =IFERROR(LEFT(RIGHT(C26,LEN(C26)-SEARCH("@",C26)),SEARCH("/",RIGHT(C26,LEN(C26)-SEARCH("@",C26)-1))),"") | B26: =LEFT(RIGHT(RIGHT(Tableau4[[#This Row],[file name]],LEN(Tableau4[[#This Row],[file name]])-SEARCH("@",Tableau4[[#This Row],[file name]])),LEN(RIGHT(Tableau4[[#This Row],[file name]],LEN(Tableau4[[#This Row],[file name]])-SEARCH("@",Tableau4[[#This Row],[file name]])))-SEARCH("/",RIGHT(Tableau4[[#This Row],[file name]],LEN(Tableau4[[#This Row],[file name]])-SEARCH("@",Tableau4[[#This Row],[file name]])))),1) -> #VALUE!
A27: =IFERROR(LEFT(RIGHT(C27,LEN(C27)-SEARCH("@",C27)),SEARCH("/",RIGHT(C27,LEN(C27)-SEARCH("@",C27)-1))),"") | B27: =LEFT(RIGHT(RIGHT(Tableau4[[#This Row],[file name]],LEN(Tableau4[[#This Row],[file name]])-SEARCH("@",Tableau4[[#This Row],[file name]])),LEN(RIGHT(Tableau4[[#This Row],[file name]],LEN(Tableau4[[#This Row],[file name]])-SEARCH("@",Tableau4[[#This Row],[file name]])))-SEARCH("/",RIGHT(Tableau4[[#This Row],[file name]],LEN(Tableau4[[#This Row],[file name]])-SEARCH("@",Tableau4[[#This Row],[file name]])))),1) -> #VALUE! | C27: group | E27: mean of mean fluo | F27: SD mean fluo | G27: mean of total fluo | H27: SD total fluo | I27: n fluorescent | J27: n total
A28: =IFERROR(LEFT(RIGHT(C28,LEN(C28)-SEARCH("@",C28)),SEARCH("/",RIGHT(C28,LEN(C28)-SEARCH("@",C28)-1))),"") -> 01 Témoins solvant | B28: =LEFT(RIGHT(RIGHT(Tableau4[[#This Row],[file name]],LEN(Tableau4[[#This Row],[file name]])-SEARCH("@",Tableau4[[#This Row],[file name]])),LEN(RIGHT(Tableau4[[#This Row],[file name]],LEN(Tableau4[[#This Row],[file name]])-SEARCH("@",Tableau4[[#This Row],[file name]])))-SEARCH("/",RIGHT(Tableau4[[#This Row],[file name]],LEN(Tableau4[[#This Row],[file name]])-SEARCH("@",Tableau4[[#This Row],[file name]])))),1) | C28: D:\Images\20210706\plaque 1/@01 Témoins solvant/ | E28: 65.4047 | F28: 2.3104 | G28: 202533.333 | H28: 147389.427 | I28: 24 | J28: 24
A29: =IFERROR(LEFT(RIGHT(C29,LEN(C29)-SEARCH("@",C29)),SEARCH("/",RIGHT(C29,LEN(C29)-SEARCH("@",C29)-1))),"") | B29: =LEFT(RIGHT(RIGHT(Tableau4[[#This Row],[file name]],LEN(Tableau4[[#This Row],[file name]])-SEARCH("@",Tableau4[[#This Row],[file name]])),LEN(RIGHT(Tableau4[[#This Row],[file name]],LEN(Tableau4[[#This Row],[file name]])-SEARCH("@",Tableau4[[#This Row],[file name]])))-SEARCH("/",RIGHT(Tableau4[[#This Row],[file name]],LEN(Tableau4[[#This Row],[file name]])-SEARCH("@",Tableau4[[#This Row],[file name]])))),1) -> #VALUE!
A30: =IFERROR(LEFT(RIGHT(C30,LEN(C30)-SEARCH("@",C30)),SEARCH("/",RIGHT(C30,LEN(C30)-SEARCH("@",C30)-1))),"") | B30: =LEFT(RIGHT(RIGHT(Tableau4[[#This Row],[file name]],LEN(Tableau4[[#This Row],[file name]])-SEARCH("@",Tableau4[[#This Row],[file name]])),LEN(RIGHT(Tableau4[[#This Row],[file name]],LEN(Tableau4[[#This Row],[file name]])-SEARCH("@",Tableau4[[#This Row],[file name]])))-SEARCH("/",RIGHT(Tableau4[[#This Row],[file name]],LEN(Tableau4[[#This Row],[file name]])-SEARCH("@",Tableau4[[#This Row],[file name]])))),1) -> #VALUE!
A31: =IFERROR(LEFT(RIGHT(C31,LEN(C31)-SEARCH("@",C31)),SEARCH("/",RIGHT(C31,LEN(C31)-SEARCH("@",C31)-1))),"") | B31: =LEFT(RIGHT(RIGHT(Tableau4[[#This Row],[file name]],LEN(Tableau4[[#This Row],[file name]])-SEARCH("@",Tableau4[[#This Row],[file name]])),LEN(RIGHT(Tableau4[[#This Row],[file name]],LEN(Tableau4[[#This Row],[file name]])-SEARCH("@",Tableau4[[#This Row],[file name]])))-SEARCH("/",RIGHT(Tableau4[[#This Row],[file name]],LEN(Tableau4[[#This Row],[file name]])-SEARCH("@",Tableau4[[#This Row],[file name]])))),1) -> #VALUE!
A32: =IFERROR(LEFT(RIGHT(C32,LEN(C32)-SEARCH("@",C32)),SEARCH("/",RIGHT(C32,LEN(C32)-SEARCH("@",C32)-1))),"") | B32: =LEFT(RIGHT(RIGHT(Tableau4[[#This Row],[file name]],LEN(Tableau4[[#This Row],[file name]])-SEARCH("@",Tableau4[[#This Row],[file name]])),LEN(RIGHT(Tableau4[[#This Row],[file name]],LEN(Tableau4[[#This Row],[file name]])-SEARCH("@",Tableau4[[#This Row],[file name]])))-SEARCH("/",RIGHT(Tableau4[[#This Row],[file name]],LEN(Tableau4[[#This Row],[file name]])-SEARCH("@",Tableau4[[#This Row],[file name]])))),1) -> #VALUE!
A33: =IFERROR(LEFT(RIGHT(C33,LEN(C33)-SEARCH("@",C33)),SEARCH("/",RIGHT(C33,LEN(C33)-SEARCH("@",C33)-1))),"") | B33: =LEFT(RIGHT(RIGHT(Tableau4[[#This Row],[file name]],LEN(Tableau4[[#This Row],[file name]])-SEARCH("@",Tableau4[[#This Row],[file name]])),LEN(RIGHT(Tableau4[[#This Row],[file name]],LEN(Tableau4[[#This Row],[file name]])-SEARCH("@",Tableau4[[#This Row],[file name]])))-SEARCH("/",RIGHT(Tableau4[[#This Row],[file name]],LEN(Tableau4[[#This Row],[file name]])-SEARCH("@",Tableau4[[#This Row],[file name]])))),1) -> #VALUE!
A34: =IFERROR(LEFT(RIGHT(C34,LEN(C34)-SEARCH("@",C34)),SEARCH("/",RIGHT(C34,LEN(C34)-SEARCH("@",C34)-1))),"") | B34: =LEFT(RIGHT(RIGHT(Tableau4[[#This Row],[file name]],LEN(Tableau4[[#This Row],[file name]])-SEARCH("@",Tableau4[[#This Row],[file name]])),LEN(RIGHT(Tableau4[[#This Row],[file name]],LEN(Tableau4[[#This Row],[file name]])-SEARCH("@",Tableau4[[#This Row],[file name]])))-SEARCH("/",RIGHT(Tableau4[[#This Row],[file name]],LEN(Tableau4[[#This Row],[file name]])-SEARCH("@",Tableau4[[#This Row],[file name]])))),1) -> #VALUE! | C34: file name | D34: total area | E34: mean intensity | G34: total fluorescence
A35: =IFERROR(LEFT(RIGHT(C35,LEN(C35)-SEARCH("@",C35)),SEARCH("/",RIGHT(C35,LEN(C35)-SEARCH("@",C35)-1))),"") -> 02 EE2 33.8 | B35: =LEFT(RIGHT(RIGHT(Tableau4[[#This Row],[file name]],LEN(Tableau4[[#This Row],[file name]])-SEARCH("@",Tableau4[[#This Row],[file name]])),LEN(RIGHT(Tableau4[[#This Row],[file name]],LEN(Tableau4[[#This Row],[file name]])-SEARCH("@",Tableau4[[#This Row],[file name]])))-SEARCH("/",RIGHT(Tableau4[[#This Row],[file name]],LEN(Tableau4[[#This Row],[file name]])-SEARCH("@",Tableau4[[#This Row],[file name]])))),1) -> A | C35: D:\Images\20210706\plaque 1/@02 EE2 33.8/A2_01.tif | D35: 11636.8833 | E35: 69.0483 | G35: 803507
A36: =IFERROR(LEFT(RIGHT(C36,LEN(C36)-SEARCH("@",C36)),SEARCH("/",RIGHT(C36,LEN(C36)-SEARCH("@",C36)-1))),"") -> 02 EE2 33.8 | B36: =LEFT(RIGHT(RIGHT(Tableau4[[#This Row],[file name]],LEN(Tableau4[[#This Row],[file name]])-SEARCH("@",Tableau4[[#This Row],[file name]])),LEN(RIGHT(Tableau4[[#This Row],[file name]],LEN(Tableau4[[#This Row],[file name]])-SEARCH("@",Tableau4[[#This Row],[file name]])))-SEARCH("/",RIGHT(Tableau4[[#This Row],[file name]],LEN(Tableau4[[#This Row],[file name]])-SEARCH("@",Tableau4[[#This Row],[file name]])))),1) -> A | C36: D:\Images\20210706\plaque 1/@02 EE2 33.8/A2_02.tif | D36: 12220.8905 | E36: 68.7186 | G36: 839802
A37: =IFERROR(LEFT(RIGHT(C37,LEN(C37)-SEARCH("@",C37)),SEARCH("/",RIGHT(C37,LEN(C37)-SEARCH("@",C37)-1))),"") -> 02 EE2 33.8 | B37: =LEFT(RIGHT(RIGHT(Tableau4[[#This Row],[file name]],LEN(Tableau4[[#This Row],[file name]])-SEARCH("@",Tableau4[[#This Row],[file name]])),LEN(RIGHT(Tableau4[[#This Row],[file name]],LEN(Tableau4[[#This Row],[file name]])-SEARCH("@",Tableau4[[#This Row],[file name]])))-SEARCH("/",RIGHT(Tableau4[[#This Row],[file name]],LEN(Tableau4[[#This Row],[file name]])-SEARCH("@",Tableau4[[#This Row],[file name]])))),1) -> A | C37: D:\Images\20210706\plaque 1/@02 EE2 33.8/A2_03.tif | D37: 9690.1928 | E37: 66.7388 | G37: 646712
A38: =IFERROR(LEFT(RIGHT(C38,LEN(C38)-SEARCH("@",C38)),SEARCH("/",RIGHT(C38,LEN(C38)-SEARCH("@",C38)-1))),"") -> 02 EE2 33.8 | B38: =LEFT(RIGHT(RIGHT(Tableau4[[#This Row],[file name]],LEN(Tableau4[[#This Row],[file name]])-SEARCH("@",Tableau4[[#This Row],[file name]])),LEN(RIGHT(Tableau4[[#This Row],[file name]],LEN(Tableau4[[#This Row],[file name]])-SEARCH("@",Tableau4[[#This Row],[file name]])))-SEARCH("/",RIGHT(Tableau4[[#This Row],[file name]],LEN(Tableau4[[#This Row],[file name]])-SEARCH("@",Tableau4[[#This Row],[file name]])))),1) -> B | C38: D:\Images\20210706\plaque 1/@02 EE2 33.8/B2_01.tif | D38: 2292.7688 | E38: 65.8491 | G38: 150977
A39: =IFERROR(LEFT(RIGHT(C39,LEN(C39)-SEARCH("@",C39)),SEARCH("/",RIGHT(C39,LEN(C39)-SEARCH("@",C39)-1))),"") -> 02 EE2 33.8 | B39: =LEFT(RIGHT(RIGHT(Tableau4[[#This Row],[file name]],LEN(Tableau4[[#This Row],[file name]])-SEARCH("@",Tableau4[[#This Row],[file name]])),LEN(RIGHT(Tableau4[[#This Row],[file name]],LEN(Tableau4[[#This Row],[file name]])-SEARCH("@",Tableau4[[#This Row],[file name]])))-SEARCH("/",RIGHT(Tableau4[[#This Row],[file name]],LEN(Tableau4[[#This Row],[file name]])-SEARCH("@",Tableau4[[#This Row],[file name]])))),1) -> B | C39: D:\Images\20210706\plaque 1/@02 EE2 33.8/B2_02.tif | D39: 2054.84 | E39: 64.0526 | G39: 131618
A40: =IFERROR(LEFT(RIGHT(C40,LEN(C40)-SEARCH("@",C40)),SEARCH("/",RIGHT(C40,LEN(C40)-SEARCH("@",C40)-1))),"") -> 02 EE2 33.8 | B40: =LEFT(RIGHT(RIGHT(Tableau4[[#This Row],[file name]],LEN(Tableau4[[#This Row],[file name]])-SEARCH("@",Tableau4[[#This Row],[file name]])),LEN(RIGHT(Tableau4[[#This Row],[file name]],LEN(Tableau4[[#This Row],[file name]])-SEARCH("@",Tableau4[[#This Row],[file name]])))-SEARCH("/",RIGHT(Tableau4[[#This Row],[file name]],LEN(Tableau4[[#This Row],[file name]])-SEARCH("@",Tableau4[[#This Row],[file name]])))),1) -> B | C40: D:\Images\20210706\plaque 1/@02 EE2 33.8/B2_03.tif | D40: 5710.2922 | E40: 66.2689 | G40: 378415
...

Sheet R1
A1: 3. Expérimentateur 1 : copier et coller les valeurs des intensités totales de fluorescences obtenues dans le fichier raw data lors du traitement des images.
A3: R1 | B3: Non dopé | O3: avec testo
A4: Noms des groupes | B4: ='Page de garde'!A7 -> Témoin solvant | C4: ='Page de garde'!A9 -> EE2-33.8ng/L | D4: ='Page de garde'!A10 -> EE2-50.6ng/L | E4: ='Page de garde'!A11 -> EE2-76ng/L | F4: ='Page de garde'!A12 -> EE2-114ng/L | G4: ='Page de garde'!A13 -> EE2-170.9ng/L | H4: ='Page de garde'!A14 -> EE2-488ng/L | I4: ='Page de garde'!A15 -> Tamoxifen-30,2µg/L | J4: ='Page de garde'!A16 -> Tamoxifen-60,4µg/L | K4: ='Page de garde'!A17 -> Tamoxifen-121µg/L | L4: ='Page de garde'!A18 -> Tamoxifen-242µg/L | M4: ='Page de garde'!A19 -> Tamoxifen-483µg/L | O4: ='Page de garde'!A36 -> Testo -30µg/L | P4: ='Page de garde'!A37 -> Testo 30µg/L + EE2 -64ng/L | Q4: ='Page de garde'!A38 -> Testo 30µg/L + FAD-10µg/L | R4: ='Page de garde'!A39 -> Tamoxifen-30.2µg/L + Testostérone | S4: ='Page de garde'!A40 -> Tamoxifen-60.4µg/L + Testostérone | T4: ='Page de garde'!A41 -> Tamoxifen-121µg/L + Testostérone | U4: ='Page de garde'!A42 -> Tamoxifen-242µg/L + Testostérone | V4: ='Page de garde'!A43 -> Tamoxifen-483µg/L + Testostérone
A5: Données brutes | B5: 209363 | C5: 763340.33 | D5: 212852.67 | E5: 1535448.3 | F5: 3204036.3 | G5: 2781247.5 | H5: 3334371 | I5: 327923.67 | J5: 59842.667 | K5: 296776.33 | M5: 202340.33 | O5: 2451907.3 | P5: 1351450.3 | Q5: 276977.67 | R5: 1020822.7 | S5: 1475454.7 | T5: 2472672 | U5: 402997.5
B6: 223862.33 | C6: 220336.67 | D6: 305969.33 | E6: 76267 | F6: 470212.67 | G6: 2656338.3 | H6: 4608624 | I6: 191021 | J6: 911880 | K6: 66721.333 | L6: 55448.5 | M6: 567157.33 | O6: 2295905 | P6: 3585811.3 | Q6: 107738.33 | R6: 2013930.7 | S6: 3171346.7 | T6: 2977910.3 | U6: 4320794.7 | V6: 1415395.3
B7: 165223.33 | C7: 247208 | D7: 53224 | E7: 730484.67 | F7: 848194.67 | G7: 2253150 | H7: 5526207.7 | I7: 58227.667 | J7: 290287.67 | K7: 205823 | L7: 135554.33 | M7: 653129 | O7: 3237843.5 | P7: 5725325 | Q7: 236999 | R7: 875347.67 | S7: 3095786 | T7: 2143399.7 | U7: 4419535.3 | V7: 1568311.3
B8: 22358 | C8: 290352.33 | D8: 910041.67 | E8: 295471.67 | F8: 2160336 | G8: 1398430.3 | H8: 8878170.7 | I8: 358234.33 | J8: 123564.33 | K8: 244014.33 | L8: 200206.33 | M8: 485194.67 | O8: 2340426.7 | P8: 4350810 | Q8: 433665 | R8: 1527078 | S8: 505966.33 | T8: 4255782.7 | U8: 3419736.7 | V8: 1466290.7
B9: 455100.33 | C9: 187394.33 | D9: 282587.33 | E9: 3249625 | F9: 524078 | G9: 2271600.3 | H9: 4329440 | I9: 521324 | J9: 233350.33 | K9: 118892 | L9: 383699.67 | M9: 1320469 | O9: 4353982.3 | P9: 3518809.3 | Q9: 408285.67 | R9: 3179875.7 | S9: 2457357.7 | T9: 2619640 | U9: 1259300 | V9: 1384854
B10: 279696 | C10: 206291.67 | D10: 72748.333 | E10: 400953 | F10: 553494.33 | G10: 757846.67 | H10: 4509148 | I10: 101833.67 | J10: 68026 | K10: 29272.333 | L10: 96844.333 | M10: 152952.33 | O10: 1818043 | P10: 3497251.5 | Q10: 439721.33 | R10: 542910.33 | S10: 2364861.3 | T10: 738112.67 | U10: 3096492.5 | V10: 316200.33
B11: 178014.33 | C11: 492718 | D11: 214143 | E11: 241880 | F11: 1198137.7 | G11: 2592890.7 | H11: 4464727.3 | I11: 117529.67 | J11: 744551.67 | K11: 172620.67 | L11: 334549.33 | M11: 1292797.5 | O11: 3591514 | P11: 3239653.7 | Q11: 19164 | R11: 1208462.3 | S11: 779245.67 | T11: 321896.33 | U11: 2484626 | V11: 1967087.3
B12: 86649.333 | C12: 234648.33 | D12: 254764 | E12: 454379.33 | F12: 910914.33 | G12: 2426628.7 | H12: 3400637.3 | I12: 27542 | J12: 305399.33 | K12: 164986 | L12: 234107.67 | M12: 165144 | O12: 2326497.3 | P12: 3217490 | S12: 2155137.7 | T12: 2269026 | U12: 1810840 | V12: 2080089
O13: 763391
O14: 1951211.3
O15: 200292.67
O16: 2068997
O17: 2197222.7
O18: 4282805.7
O19: 703483.67
O20: 918506.33
A22: =A4 -> Noms des groupes | B22: =B4 -> Témoin solvant | C22: =C4 -> EE2-33.8ng/L | D22: =D4 -> EE2-50.6ng/L | E22: =E4 -> EE2-76ng/L | F22: =F4 -> EE2-114ng/L | G22: =G4 -> EE2-170.9ng/L | H22: =H4 -> EE2-488ng/L | ... M22: =M4 -> Tamoxifen-483µg/L | N22: Nom des groupes | O22: =O4 -> Testo -30µg/L | P22: =P4 -> Testo 30µg/L + EE2 -64ng/L | Q22: =Q4 -> Testo 30µg/L + FAD-10µg/L | R22: =R4 -> Tamoxifen-30.2µg/L + Testostérone | S22: =S4 -> Tamoxifen-60.4µg/L + Testostérone | T22: =T4 -> Tamoxifen-121µg/L + Testostérone | U22: =U4 -> Tamoxifen-242µg/L + Testostérone | V22: =V4 -> Tamoxifen-483µg/L + Testostérone
A23: mean | B23: =AVERAGE(B5:B20) -> 202533.33 | C23: =AVERAGE(C5:C20) -> 330286.21 | D23: =AVERAGE(D5:D20) -> 288291.29 | E23: =AVERAGE(E5:E20) -> 873063.62 | F23: =AVERAGE(F5:F20) -> 1233675.5 | G23: =AVERAGE(G5:G20) -> 2142266.6 | H23: =AVERAGE(H5:H20) -> 4881415.8 | I23: =AVERAGE(I5:I20) -> 212954.5 | ... M23: =AVERAGE(M5:M20) -> 604898.02 | N23: mean | O23: =AVERAGE(O5:O20) -> 2218876.8 | P23: =AVERAGE(P5:P20) -> 3560825.1 | Q23: =AVERAGE(Q5:Q20) -> 274650.14 | R23: =AVERAGE(R5:R20) -> 1481203.9 | S23: =AVERAGE(S5:S20) -> 2000644.5 | T23: =AVERAGE(T5:T20) -> 2224805 | U23: =AVERAGE(U5:U20) -> 2651790.3 | V23: =AVERAGE(V5:V20) -> 1456889.7
A24: SD | B24: =STDEV(B5:B20) -> 129907.22 | C24: =STDEV(C5:C20) -> 199801.65 | D24: =STDEV(D5:D20) -> 267514.22 | E24: =STDEV(E5:E20) -> 1060471.7 | F24: =STDEV(F5:F20) -> 966887.88 | G24: =STDEV(G5:G20) -> 702589.44 | H24: =STDEV(H5:H20) -> 1759349.1 | I24: =STDEV(I5:I20) -> 173068.48 | ... M24: =STDEV(M5:M20) -> 472533.93 | N24: SD | O24: =STDEV(O5:O20) -> 1218284.1 | P24: =STDEV(P5:P20) -> 1219949.3 | Q24: =STDEV(Q5:Q20) -> 165805.32 | R24: =STDEV(R5:R20) -> 885549.12 | S24: =STDEV(S5:S20) -> 995467.57 | T24: =STDEV(T5:T20) -> 1239197.2 | U24: =STDEV(U5:U20) -> 1435729.7 | V24: =STDEV(V5:V20) -> 572896.92
B26: Non dopé | O26: avec testo
A27: Noms des groupes | B27: =B4 -> Témoin solvant | C27: =C4 -> EE2-33.8ng/L | D27: =D4 -> EE2-50.6ng/L | E27: =E4 -> EE2-76ng/L | F27: =F4 -> EE2-114ng/L | G27: =G4 -> EE2-170.9ng/L | H27: =H4 -> EE2-488ng/L | I27: =I4 -> Tamoxifen-30,2µg/L | ... M27: =M4 -> Tamoxifen-483µg/L | O27: =O4 -> Testo -30µg/L | P27: =P4 -> Testo 30µg/L + EE2 -64ng/L | Q27: =Q4 -> Testo 30µg/L + FAD-10µg/L | R27: =R4 -> Tamoxifen-30.2µg/L + Testostérone | S27: =S4 -> Tamoxifen-60.4µg/L + Testostérone | T27: =T4 -> Tamoxifen-121µg/L + Testostérone | U27: =U4 -> Tamoxifen-242µg/L + Testostérone | V27: =V4 -> Tamoxifen-483µg/L + Testostérone
A28: Données normalisées sur la moyenne du groupe "Testo" | B28: =IF(B5="","",(B5/$O$23)) -> 0.094355395 | C28: =IF(C5="","",(C5/$O$23)) -> 0.34402105 | D28: =IF(D5="","",(D5/$O$23)) -> 0.095928112 | E28: =IF(E5="","",(E5/$O$23)) -> 0.69199349 | F28: =IF(F5="","",(F5/$O$23)) -> 1.4439902 | G28: =IF(G5="","",(G5/$O$23)) -> 1.2534483 | H28: =IF(H5="","",(H5/$O$23)) -> 1.5027292 | I28: =IF(I5="","",(I5/$O$23)) -> 0.14778813 | ... M28: =IF(M5="","",(M5/$O$23)) -> 0.09119043 | O28: =IF(O5="","",(O5/$O$23)) -> 1.1050218 | P28: =IF(P5="","",(P5/$O$23)) -> 0.60906956 | Q28: =IF(Q5="","",(Q5/$O$23)) -> 0.12482787 | R28: =IF(R5="","",(R5/$O$23)) -> 0.46006279 | S28: =IF(S5="","",(S5/$O$23)) -> 0.66495564 | T28: =IF(T5="","",(T5/$O$23)) -> 1.11438 | U28: =IF(U5="","",(U5/$O$23)) -> 0.18162229 | V28: =IF(V5="","",(V5/$O$23))
B29: =IF(B6="","",(B6/$O$23)) -> 0.10088993 | C29: =IF(C6="","",(C6/$O$23)) -> 0.09930099 | D29: =IF(D6="","",(D6/$O$23)) -> 0.13789379 | E29: =IF(E6="","",(E6/$O$23)) -> 0.034371894 | F29: =IF(F6="","",(F6/$O$23)) -> 0.21191472 | G29: =IF(G6="","",(G6/$O$23)) -> 1.1971545 | H29: =IF(H6="","",(H6/$O$23)) -> 2.0770076 | I29: =IF(I6="","",(I6/$O$23)) -> 0.08608905 | ... M29: =IF(M6="","",(M6/$O$23)) -> 0.25560559 | O29: =IF(O6="","",(O6/$O$23)) -> 1.0347149 | P29: =IF(P6="","",(P6/$O$23)) -> 1.6160479 | Q29: =IF(Q6="","",(Q6/$O$23)) -> 0.048555346 | R29: =IF(R6="","",(R6/$O$23)) -> 0.90763517 | S29: =IF(S6="","",(S6/$O$23)) -> 1.4292576 | T29: =IF(T6="","",(T6/$O$23)) -> 1.34208 | U29: =IF(U6="","",(U6/$O$23)) -> 1.9472891 | V29: =IF(V6="","",(V6/$O$23)) -> 0.63788819
B30: =IF(B7="","",(B7/$O$23)) -> 0.074462598 | C30: =IF(C7="","",(C7/$O$23)) -> 0.11141132 | D30: =IF(D7="","",(D7/$O$23)) -> 0.02398691 | E30: =IF(E7="","",(E7/$O$23)) -> 0.3292137 | F30: =IF(F7="","",(F7/$O$23)) -> 0.38226307 | G30: =IF(G7="","",(G7/$O$23)) -> 1.0154462 | H30: =IF(H7="","",(H7/$O$23)) -> 2.4905428 | I30: =IF(I7="","",(I7/$O$23)) -> 0.026241955 | ... M30: =IF(M7="","",(M7/$O$23)) -> 0.29435117 | O30: =IF(O7="","",(O7/$O$23)) -> 1.4592263 | P30: =IF(P7="","",(P7/$O$23)) -> 2.5802807 | Q30: =IF(Q7="","",(Q7/$O$23)) -> 0.10681034 | R30: =IF(R7="","",(R7/$O$23)) -> 0.39450034 | S30: =IF(S7="","",(S7/$O$23)) -> 1.3952041 | T30: =IF(T7="","",(T7/$O$23)) -> 0.96598406 | U30: =IF(U7="","",(U7/$O$23)) -> 1.9917894 | V30: =IF(V7="","",(V7/$O$23)) -> 0.70680414
B31: =IF(B8="","",(B8/$O$23)) -> 0.010076269 | C31: =IF(C8="","",(C8/$O$23)) -> 0.13085554 | D31: =IF(D8="","",(D8/$O$23)) -> 0.41013618 | E31: =IF(E8="","",(E8/$O$23)) -> 0.13316272 | F31: =IF(F8="","",(F8/$O$23)) -> 0.9736169 | G31: =IF(G8="","",(G8/$O$23)) -> 0.63024243 | H31: =IF(H8="","",(H8/$O$23)) -> 4.0012003 | I31: =IF(I8="","",(I8/$O$23)) -> 0.1614485 | ... M31: =IF(M8="","",(M8/$O$23)) -> 0.21866679 | O31: =IF(O8="","",(O8/$O$23)) -> 1.0547799 | P31: =IF(P8="","",(P8/$O$23)) -> 1.9608164 | Q31: =IF(Q8="","",(Q8/$O$23)) -> 0.19544347 | R31: =IF(R8="","",(R8/$O$23)) -> 0.68822116 | S31: =IF(S8="","",(S8/$O$23)) -> 0.22802813 | T31: =IF(T8="","",(T8/$O$23)) -> 1.9179896 | U31: =IF(U8="","",(U8/$O$23)) -> 1.5412017 | V31: =IF(V8="","",(V8/$O$23)) -> 0.66082562
B32: =IF(B9="","",(B9/$O$23)) -> 0.20510392 | C32: =IF(C9="","",(C9/$O$23)) -> 0.08445459 | D32: =IF(D9="","",(D9/$O$23)) -> 0.12735602 | E32: =IF(E9="","",(E9/$O$23)) -> 1.464536 | F32: =IF(F9="","",(F9/$O$23)) -> 0.23619067 | G32: =IF(G9="","",(G9/$O$23)) -> 1.0237613 | H32: =IF(H9="","",(H9/$O$23)) -> 1.9511854 | I32: =IF(I9="","",(I9/$O$23)) -> 0.2349495 | ... M32: =IF(M9="","",(M9/$O$23)) -> 0.59510694 | O32: =IF(O9="","",(O9/$O$23)) -> 1.9622461 | P32: =IF(P9="","",(P9/$O$23)) -> 1.5858516 | Q32: =IF(Q9="","",(Q9/$O$23)) -> 0.18400556 | R32: =IF(R9="","",(R9/$O$23)) -> 1.4331015 | S32: =IF(S9="","",(S9/$O$23)) -> 1.1074782 | T32: =IF(T9="","",(T9/$O$23)) -> 1.1806153 | U32: =IF(U9="","",(U9/$O$23)) -> 0.56753939 | V32: =IF(V9="","",(V9/$O$23)) -> 0.62412387
B33: =IF(B10="","",(B10/$O$23)) -> 0.12605296 | C33: =IF(C10="","",(C10/$O$23)) -> 0.092971211 | D33: =IF(D10="","",(D10/$O$23)) -> 0.032786107 | E33: =IF(E10="","",(E10/$O$23)) -> 0.18070088 | F33: =IF(F10="","",(F10/$O$23)) -> 0.24944797 | G33: =IF(G10="","",(G10/$O$23)) -> 0.34154517 | H33: =IF(H10="","",(H10/$O$23)) -> 2.0321759 | I33: =IF(I10="","",(I10/$O$23)) -> 0.04589424 | ... M33: =IF(M10="","",(M10/$O$23)) -> 0.068932322 | O33: =IF(O10="","",(O10/$O$23)) -> 0.81935282 | P33: =IF(P10="","",(P10/$O$23)) -> 1.5761359 | Q33: =IF(Q10="","",(Q10/$O$23)) -> 0.19817293 | R33: =IF(R10="","",(R10/$O$23)) -> 0.24467799 | S33: =IF(S10="","",(S10/$O$23)) -> 1.0657921 | T33: =IF(T10="","",(T10/$O$23)) -> 0.33265148 | U33: =IF(U10="","",(U10/$O$23)) -> 1.3955225 | V33: =IF(V10="","",(V10/$O$23)) -> 0.14250468
B34: =IF(B11="","",(B11/$O$23)) -> 0.080227226 | C34: =IF(C11="","",(C11/$O$23)) -> 0.22205739 | D34: =IF(D11="","",(D11/$O$23)) -> 0.096509638 | E34: =IF(E11="","",(E11/$O$23)) -> 0.10901011 | F34: =IF(F11="","",(F11/$O$23)) -> 0.53997484 | G34: =IF(G11="","",(G11/$O$23)) -> 1.16856 | H34: =IF(H11="","",(H11/$O$23)) -> 2.0121564 | I34: =IF(I11="","",(I11/$O$23)) -> 0.052968089 | ... M34: =IF(M11="","",(M11/$O$23)) -> 0.58263599 | O34: =IF(O11="","",(O11/$O$23)) -> 1.618618 | P34: =IF(P11="","",(P11/$O$23)) -> 1.4600421 | Q34: =IF(Q11="","",(Q11/$O$23)) -> 0.008636802 | R34: =IF(R11="","",(R11/$O$23)) -> 0.54462794 | S34: =IF(S11="","",(S11/$O$23)) -> 0.35118924 | T34: =IF(T11="","",(T11/$O$23)) -> 0.14507174 | U34: =IF(U11="","",(U11/$O$23)) -> 1.1197674 | V34: =IF(V11="","",(V11/$O$23)) -> 0.88652389
B35: =IF(B12="","",(B12/$O$23)) -> 0.039050988 | C35: =IF(C12="","",(C12/$O$23)) -> 0.10575095 | D35: =IF(D12="","",(D12/$O$23)) -> 0.11481665 | E35: =IF(E12="","",(E12/$O$23)) -> 0.20477898 | F35: =IF(F12="","",(F12/$O$23)) -> 0.41052947 | G35: =IF(G12="","",(G12/$O$23)) -> 1.0936293 | H35: =IF(H12="","",(H12/$O$23)) -> 1.532594 | I35: =IF(I12="","",(I12/$O$23)) -> 0.012412586 | ... M35: =IF(M12="","",(M12/$O$23)) -> 0.074426844 | O35: =IF(O12="","",(O12/$O$23)) -> 1.0485022 | P35: =IF(P12="","",(P12/$O$23)) -> 1.4500534 | Q35: =IF(Q12="","",(Q12/$O$23)) | R35: =IF(R12="","",(R12/$O$23)) | S35: =IF(S12="","",(S12/$O$23)) -> 0.97127413 | T35: =IF(T12="","",(T12/$O$23)) -> 1.0226011 | U35: =IF(U12="","",(U12/$O$23)) -> 0.81610658 | V35: =IF(V12="","",(V12/$O$23)) -> 0.93745131
B36: =IF(B13="","",(B13/$O$23)) | C36: =IF(C13="","",(C13/$O$23)) | D36: =IF(D13="","",(D13/$O$23)) | E36: =IF(E13="","",(E13/$O$23)) | F36: =IF(F13="","",(F13/$O$23)) | G36: =IF(G13="","",(G13/$O$23)) | H36: =IF(H13="","",(H13/$O$23)) | I36: =IF(I13="","",(I13/$O$23)) | ... M36: =IF(M13="","",(M13/$O$23)) | O36: =IF(O13="","",(O13/$O$23)) -> 0.34404388 | P36: =IF(P13="","",(P13/$O$23)) | Q36: =IF(Q13="","",(Q13/$O$23)) | R36: =IF(R13="","",(R13/$O$23)) | S36: =IF(S13="","",(S13/$O$23)) | T36: =IF(T13="","",(T13/$O$23)) | U36: =IF(U13="","",(U13/$O$23)) | V36: =IF(V13="","",(V13/$O$23))
B37: =IF(B14="","",(B14/$O$23)) | C37: =IF(C14="","",(C14/$O$23)) | D37: =IF(D14="","",(D14/$O$23)) | E37: =IF(E14="","",(E14/$O$23)) | F37: =IF(F14="","",(F14/$O$23)) | G37: =IF(G14="","",(G14/$O$23)) | H37: =IF(H14="","",(H14/$O$23)) | I37: =IF(I14="","",(I14/$O$23)) | ... M37: =IF(M14="","",(M14/$O$23)) | O37: =IF(O14="","",(O14/$O$23)) -> 0.87936892 | P37: =IF(P14="","",(P14/$O$23)) | Q37: =IF(Q14="","",(Q14/$O$23)) | R37: =IF(R14="","",(R14/$O$23)) | S37: =IF(S14="","",(S14/$O$23)) | T37: =IF(T14="","",(T14/$O$23)) | U37: =IF(U14="","",(U14/$O$23)) | V37: =IF(V14="","",(V14/$O$23))
