Workbook

Sheet Page de garde
A1: 1. Expérimentateur 1 : copier et coller le n° de prestation et renseigner la date de réalisation de chaque réplica ainsi que le visa de l'expérimentateur.
A2: R1 | B2: Numéro d'expérience : | E2: Date de réalisation :
A3: R2 | B3: Numéro d'expérience : | E3: Date de réalisation :
A4: R3 | B4: Numéro d'expérience : | E4: Date de réalisation :
A5: 2. Expérimentateur 1 : copier et coller la dilution appliquée et le nom donné pour chaque des échantillons par le client. Conserver la mise en forme de l'exemple en italique. Ne pas remplir la colonne "nom sur graphique".
A6: Nom sur le graphique | B6: Code WF | C6: Concentration | D6: Unité | E6: Nom de l'échantillon donné par le client | F6: Dopage (+Testostérone / + EE2, ….)
A7: =IF(ISBLANK(liste_groupe[[#This Row],[Code WF]])," ",IF(ISBLANK(liste_groupe[[#This Row],[Unité]]),CONCATENATE(liste_groupe[[#This Row],[Nom de l''échantillon donné par le client]],liste_groupe[[#This Row],[Dopage (+Testostérone / + EE2, ….)]]),CONCATENATE(liste_groupe[[#This Row],[Nom de l''échantillon donné par le client]],"-",liste_groupe[[#This Row],[Concentration]],liste_groupe[[#This Row],[Unité]],liste_groupe[[#This Row],[Dopage (+Testostérone / + EE2, ….)]]))) -> Témoin solvant | B7: Témoin | E7: Témoin solvant
A8: =IF(ISBLANK(liste_groupe[[#This Row],[Code WF]])," ",IF(ISBLANK(liste_groupe[[#This Row],[Unité]]),CONCATENATE(liste_groupe[[#This Row],[Nom de l''échantillon donné par le client]],liste_groupe[[#This Row],[Dopage (+Testostérone / + EE2, ….)]]),CONCATENATE(liste_groupe[[#This Row],[Nom de l''échantillon donné par le client]],"-",liste_groupe[[#This Row],[Concentration]],liste_groupe[[#This Row],[Unité]],liste_groupe[[#This Row],[Dopage (+Testostérone / + EE2, ….)]]))) -> EE2-22.5ng/L | B8: Témoin | C8: 22.5 | D8: ng/L | E8: EE2
A9: =IF(ISBLANK(liste_groupe[[#This Row],[Code WF]])," ",IF(ISBLANK(liste_groupe[[#This Row],[Unité]]),CONCATENATE(liste_groupe[[#This Row],[Nom de l''échantillon donné par le client]],liste_groupe[[#This Row],[Dopage (+Testostérone / + EE2, ….)]]),CONCATENATE(liste_groupe[[#This Row],[Nom de l''échantillon donné par le client]],"-",liste_groupe[[#This Row],[Concentration]],liste_groupe[[#This Row],[Unité]],liste_groupe[[#This Row],[Dopage (+Testostérone / + EE2, ….)]]))) -> EE2-33.8ng/L | B9: Témoin | C9: 33.8 | D9: ng/L | E9: EE2
A10: =IF(ISBLANK(liste_groupe[[#This Row],[Code WF]])," ",IF(ISBLANK(liste_groupe[[#This Row],[Unité]]),CONCATENATE(liste_groupe[[#This Row],[Nom de l''échantillon donné par le client]],liste_groupe[[#This Row],[Dopage (+Testostérone / + EE2, ….)]]),CONCATENATE(liste_groupe[[#This Row],[Nom de l''échantillon donné par le client]],"-",liste_groupe[[#This Row],[Concentration]],liste_groupe[[#This Row],[Unité]],liste_groupe[[#This Row],[Dopage (+Testostérone / + EE2, ….)]]))) -> EE2-50.6ng/L | B10: Témoin | C10: 50.6 | D10: ng/L | E10: EE2
A11: =IF(ISBLANK(liste_groupe[[#This Row],[Code WF]])," ",IF(ISBLANK(liste_groupe[[#This Row],[Unité]]),CONCATENATE(liste_groupe[[#This Row],[Nom de l''échantillon donné par le client]],liste_groupe[[#This Row],[Dopage (+Testostérone / + EE2, ….)]]),CONCATENATE(liste_groupe[[#This Row],[Nom de l''échantillon donné par le client]],"-",liste_groupe[[#This Row],[Concentration]],liste_groupe[[#This Row],[Unité]],liste_groupe[[#This Row],[Dopage (+Testostérone / + EE2, ….)]]))) -> EE2-76ng/L | B11: Témoin | C11: 76 | D11: ng/L | E11: EE2
A12: =IF(ISBLANK(liste_groupe[[#This Row],[Code WF]])," ",IF(ISBLANK(liste_groupe[[#This Row],[Unité]]),CONCATENATE(liste_groupe[[#This Row],[Nom de l''échantillon donné par le client]],liste_groupe[[#This Row],[Dopage (+Testostérone / + EE2, ….)]]),CONCATENATE(liste_groupe[[#This Row],[Nom de l''échantillon donné par le client]],"-",liste_groupe[[#This Row],[Concentration]],liste_groupe[[#This Row],[Unité]],liste_groupe[[#This Row],[Dopage (+Testostérone / + EE2, ….)]]))) -> EE2-114ng/L | B12: Témoin | C12: 114 | D12: ng/L | E12: EE2
A13: =IF(ISBLANK(liste_groupe[[#This Row],[Code WF]])," ",IF(ISBLANK(liste_groupe[[#This Row],[Unité]]),CONCATENATE(liste_groupe[[#This Row],[Nom de l''échantillon donné par le client]],liste_groupe[[#This Row],[Dopage (+Testostérone / + EE2, ….)]]),CONCATENATE(liste_groupe[[#This Row],[Nom de l''échantillon donné par le client]],"-",liste_groupe[[#This Row],[Concentration]],liste_groupe[[#This Row],[Unité]],liste_groupe[[#This Row],[Dopage (+Testostérone / + EE2, ….)]]))) -> EE2-170.9ng/L | B13: Témoin | C13: 170.9 | D13: ng/L | E13: EE2
A14: =IF(ISBLANK(liste_groupe[[#This Row],[Code WF]])," ",IF(ISBLANK(liste_groupe[[#This Row],[Unité]]),CONCATENATE(liste_groupe[[#This Row],[Nom de l''échantillon donné par le client]],liste_groupe[[#This Row],[Dopage (+Testostérone / + EE2, ….)]]),CONCATENATE(liste_groupe[[#This Row],[Nom de l''échantillon donné par le client]],"-",liste_groupe[[#This Row],[Concentration]],liste_groupe[[#This Row],[Unité]],liste_groupe[[#This Row],[Dopage (+Testostérone / + EE2, ….)]]))) -> EE2-488ng/L | B14: Témoin | C14: 488 | D14: ng/L | E14: EE2
A15: =IF(ISBLANK(liste_groupe[[#This Row],[Code WF]])," ",IF(ISBLANK(liste_groupe[[#This Row],[Unité]]),CONCATENATE(liste_groupe[[#This Row],[Nom de l''échantillon donné par le client]],liste_groupe[[#This Row],[Dopage (+Testostérone / + EE2, ….)]]),CONCATENATE(liste_groupe[[#This Row],[Nom de l''échantillon donné par le client]],"-",liste_groupe[[#This Row],[Concentration]],liste_groupe[[#This Row],[Unité]],liste_groupe[[#This Row],[Dopage (+Testostérone / + EE2, ….)]]))) -> Arabinose-0.01mg/L | B15: Test | C15: 0.01 | D15: mg/L | E15: Arabinose
A16: =IF(ISBLANK(liste_groupe[[#This Row],[Code WF]])," ",IF(ISBLANK(liste_groupe[[#This Row],[Unité]]),CONCATENATE(liste_groupe[[#This Row],[Nom de l''échantillon donné par le client]],liste_groupe[[#This Row],[Dopage (+Testostérone / + EE2, ….)]]),CONCATENATE(liste_groupe[[#This Row],[Nom de l''échantillon donné par le client]],"-",liste_groupe[[#This Row],[Concentration]],liste_groupe[[#This Row],[Unité]],liste_groupe[[#This Row],[Dopage (+Testostérone / + EE2, ….)]]))) -> Arabinose-0.1mg/L | B16: Test | C16: 0.1 | D16: mg/L | E16: Arabinose
A17: =IF(ISBLANK(liste_groupe[[#This Row],[Code WF]])," ",IF(ISBLANK(liste_groupe[[#This Row],[Unité]]),CONCATENATE(liste_groupe[[#This Row],[Nom de l''échantillon donné par le client]],liste_groupe[[#This Row],[Dopage (+Testostérone / + EE2, ….)]]),CONCATENATE(liste_groupe[[#This Row],[Nom de l''échantillon donné par le client]],"-",liste_groupe[[#This Row],[Concentration]],liste_groupe[[#This Row],[Unité]],liste_groupe[[#This Row],[Dopage (+Testostérone / + EE2, ….)]]))) -> Arabinose-1mg/L | B17: Test | C17: 1 | D17: mg/L | E17: Arabinose
A18: =IF(ISBLANK(liste_groupe[[#This Row],[Code WF]])," ",IF(ISBLANK(liste_groupe[[#This Row],[Unité]]),CONCATENATE(liste_groupe[[#This Row],[Nom de l''échantillon donné par le client]],liste_groupe[[#This Row],[Dopage (+Testostérone / + EE2, ….)]]),CONCATENATE(liste_groupe[[#This Row],[Nom de l''échantillon donné par le client]],"-",liste_groupe[[#This Row],[Concentration]],liste_groupe[[#This Row],[Unité]],liste_groupe[[#This Row],[Dopage (+Testostérone / + EE2, ….)]]))) -> Arabinose-10mg/L | B18: Test | C18: 10 | D18: mg/L | E18: Arabinose
A19: =IF(ISBLANK(liste_groupe[[#This Row],[Code WF]])," ",IF(ISBLANK(liste_groupe[[#This Row],[Unité]]),CONCATENATE(liste_groupe[[#This Row],[Nom de l''échantillon donné par le client]],liste_groupe[[#This Row],[Dopage (+Testostérone / + EE2, ….)]]),CONCATENATE(liste_groupe[[#This Row],[Nom de l''échantillon donné par le client]],"-",liste_groupe[[#This Row],[Concentration]],liste_groupe[[#This Row],[Unité]],liste_groupe[[#This Row],[Dopage (+Testostérone / + EE2, ….)]]))) -> Arabinose-100mg/L | B19: Test | C19: 100 | D19: mg/L | E19: Arabinose
A20: =IF(ISBLANK(liste_groupe[[#This Row],[Code WF]])," ",IF(ISBLANK(liste_groupe[[#This Row],[Unité]]),CONCATENATE(liste_groupe[[#This Row],[Nom de l''échantillon donné par le client]],liste_groupe[[#This Row],[Dopage (+Testostérone / + EE2, ….)]]),CONCATENATE(liste_groupe[[#This Row],[Nom de l''échantillon donné par le client]],"-",liste_groupe[[#This Row],[Concentration]],liste_groupe[[#This Row],[Unité]],liste_groupe[[#This Row],[Dopage (+Testostérone / + EE2, ….)]])))
A21: =IF(ISBLANK(liste_groupe[[#This Row],[Code WF]])," ",IF(ISBLANK(liste_groupe[[#This Row],[Unité]]),CONCATENATE(liste_groupe[[#This Row],[Nom de l''échantillon donné par le client]],liste_groupe[[#This Row],[Dopage (+Testostérone / + EE2, ….)]]),CONCATENATE(liste_groupe[[#This Row],[Nom de l''échantillon donné par le client]],"-",liste_groupe[[#This Row],[Concentration]],liste_groupe[[#This Row],[Unité]],liste_groupe[[#This Row],[Dopage (+Testostérone / + EE2, ….)]])))
A22: =IF(ISBLANK(liste_groupe[[#This Row],[Code WF]])," ",IF(ISBLANK(liste_groupe[[#This Row],[Unité]]),CONCATENATE(liste_groupe[[#This Row],[Nom de l''échantillon donné par le client]],liste_groupe[[#This Row],[Dopage (+Testostérone / + EE2, ….)]]),CONCATENATE(liste_groupe[[#This Row],[Nom de l''échantillon donné par le client]],"-",liste_groupe[[#This Row],[Concentration]],liste_groupe[[#This Row],[Unité]],liste_groupe[[#This Row],[Dopage (+Testostérone / + EE2, ….)]])))
A23: =IF(ISBLANK(liste_groupe[[#This Row],[Code WF]])," ",IF(ISBLANK(liste_groupe[[#This Row],[Unité]]),CONCATENATE(liste_groupe[[#This Row],[Nom de l''échantillon donné par le client]],liste_groupe[[#This Row],[Dopage (+Testostérone / + EE2, ….)]]),CONCATENATE(liste_groupe[[#This Row],[Nom de l''échantillon donné par le client]],"-",liste_groupe[[#This Row],[Concentration]],liste_groupe[[#This Row],[Unité]],liste_groupe[[#This Row],[Dopage (+Testostérone / + EE2, ….)]])))
A24: =IF(ISBLANK(liste_groupe[[#This Row],[Code WF]])," ",IF(ISBLANK(liste_groupe[[#This Row],[Unité]]),CONCATENATE(liste_groupe[[#This Row],[Nom de l''échantillon donné par le client]],liste_groupe[[#This Row],[Dopage (+Testostérone / + EE2, ….)]]),CONCATENATE(liste_groupe[[#This Row],[Nom de l''échantillon donné par le client]],"-",liste_groupe[[#This Row],[Concentration]],liste_groupe[[#This Row],[Unité]],liste_groupe[[#This Row],[Dopage (+Testostérone / + EE2, ….)]])))
A25: =IF(ISBLANK(liste_groupe[[#This Row],[Code WF]])," ",IF(ISBLANK(liste_groupe[[#This Row],[Unité]]),CONCATENATE(liste_groupe[[#This Row],[Nom de l''échantillon donné par le client]],liste_groupe[[#This Row],[Dopage (+Testostérone / + EE2, ….)]]),CONCATENATE(liste_groupe[[#This Row],[Nom de l''échantillon donné par le client]],"-",liste_groupe[[#This Row],[Concentration]],liste_groupe[[#This Row],[Unité]],liste_groupe[[#This Row],[Dopage (+Testostérone / + EE2, ….)]])))
A26: =IF(ISBLANK(liste_groupe[[#This Row],[Code WF]])," ",IF(ISBLANK(liste_groupe[[#This Row],[Unité]]),CONCATENATE(liste_groupe[[#This Row],[Nom de l''échantillon donné par le client]],liste_groupe[[#This Row],[Dopage (+Testostérone / + EE2, ….)]]),CONCATENATE(liste_groupe[[#This Row],[Nom de l''échantillon donné par le client]],"-",liste_groupe[[#This Row],[Concentration]],liste_groupe[[#This Row],[Unité]],liste_groupe[[#This Row],[Dopage (+Testostérone / + EE2, ….)]])))
A27: =IF(ISBLANK(liste_groupe[[#This Row],[Code WF]])," ",IF(ISBLANK(liste_groupe[[#This Row],[Unité]]),CONCATENATE(liste_groupe[[#This Row],[Nom de l''échantillon donné par le client]],liste_groupe[[#This Row],[Dopage (+Testostérone / + EE2, ….)]]),CONCATENATE(liste_groupe[[#This Row],[Nom de l''échantillon donné par le client]],"-",liste_groupe[[#This Row],[Concentration]],liste_groupe[[#This Row],[Unité]],liste_groupe[[#This Row],[Dopage (+Testostérone / + EE2, ….)]])))
A28: =IF(ISBLANK(liste_groupe[[#This Row],[Code WF]])," ",IF(ISBLANK(liste_groupe[[#This Row],[Unité]]),CONCATENATE(liste_groupe[[#This Row],[Nom de l''échantillon donné par le client]],liste_groupe[[#This Row],[Dopage (+Testostérone / + EE2, ….)]]),CONCATENATE(liste_groupe[[#This Row],[Nom de l''échantillon donné par le client]],"-",liste_groupe[[#This Row],[Concentration]],liste_groupe[[#This Row],[Unité]],liste_groupe[[#This Row],[Dopage (+Testostérone / + EE2, ….)]])))
A29: =IF(ISBLANK(liste_groupe[[#This Row],[Code WF]])," ",IF(ISBLANK(liste_groupe[[#This Row],[Unité]]),CONCATENATE(liste_groupe[[#This Row],[Nom de l''échantillon donné par le client]],liste_groupe[[#This Row],[Dopage (+Testostérone / + EE2, ….)]]),CONCATENATE(liste_groupe[[#This Row],[Nom de l''échantillon donné par le client]],"-",liste_groupe[[#This Row],[Concentration]],liste_groupe[[#This Row],[Unité]],liste_groupe[[#This Row],[Dopage (+Testostérone / + EE2, ….)]])))
A30: =IF(ISBLANK(liste_groupe[[#This Row],[Code WF]])," ",IF(ISBLANK(liste_groupe[[#This Row],[Unité]]),CONCATENATE(liste_groupe[[#This Row],[Nom de l''échantillon donné par le client]],liste_groupe[[#This Row],[Dopage (+Testostérone / + EE2, ….)]]),CONCATENATE(liste_groupe[[#This Row],[Nom de l''échantillon donné par le client]],"-",liste_groupe[[#This Row],[Concentration]],liste_groupe[[#This Row],[Unité]],liste_groupe[[#This Row],[Dopage (+Testostérone / + EE2, ….)]])))
A31: =IF(ISBLANK(liste_groupe[[#This Row],[Code WF]])," ",IF(ISBLANK(liste_groupe[[#This Row],[Unité]]),CONCATENATE(liste_groupe[[#This Row],[Nom de l''échantillon donné par le client]],liste_groupe[[#This Row],[Dopage (+Testostérone / + EE2, ….)]]),CONCATENATE(liste_groupe[[#This Row],[Nom de l''échantillon donné par le client]],"-",liste_groupe[[#This Row],[Concentration]],liste_groupe[[#This Row],[Unité]],liste_groupe[[#This Row],[Dopage (+Testostérone / + EE2, ….)]])))
... A35: =IF(ISBLANK(liste_groupe[[#This Row],[Code WF]])," ",IF(ISBLANK(liste_groupe[[#This Row],[Unité]]),CONCATENATE(liste_groupe[[#This Row],[Nom de l''échantillon donné par le client]],liste_groupe[[#This Row],[Dopage (+Testostérone / + EE2, ….)]]),CONCATENATE(liste_groupe[[#This Row],[Nom de l''échantillon donné par le client]],"-",liste_groupe[[#This Row],[Concentration]],liste_groupe[[#This Row],[Unité]],liste_groupe[[#This Row],[Dopage (+Testostérone / + EE2, ….)]])))
A36: =IF(ISBLANK(liste_groupe[[#This Row],[Code WF]])," ",IF(ISBLANK(liste_groupe[[#This Row],[Unité]]),CONCATENATE(liste_groupe[[#This Row],[Nom de l''échantillon donné par le client]],liste_groupe[[#This Row],[Dopage (+Testostérone / + EE2, ….)]]),CONCATENATE(liste_groupe[[#This Row],[Nom de l''échantillon donné par le client]],"-",liste_groupe[[#This Row],[Concentration]],liste_groupe[[#This Row],[Unité]],liste_groupe[[#This Row],[Dopage (+Testostérone / + EE2, ….)]]))) -> Testo -30µg/L | B36: Témoin | C36: 30 | D36: µg/L | E36: Testo
A37: =IF(ISBLANK(liste_groupe[[#This Row],[Code WF]])," ",IF(ISBLANK(liste_groupe[[#This Row],[Unité]]),CONCATENATE(liste_groupe[[#This Row],[Nom de l''échantillon donné par le client]],liste_groupe[[#This Row],[Dopage (+Testostérone / + EE2, ….)]]),CONCATENATE(liste_groupe[[#This Row],[Nom de l''échantillon donné par le client]],"-",liste_groupe[[#This Row],[Concentration]],liste_groupe[[#This Row],[Unité]],liste_groupe[[#This Row],[Dopage (+Testostérone / + EE2, ….)]]))) -> Testo 30µg/L + EE2 -64ng/L | B37: Témoin | C37: 64 | D37: ng/L | E37: Testo 30µg/L + EE2
A38: =IF(ISBLANK(liste_groupe[[#This Row],[Code WF]])," ",IF(ISBLANK(liste_groupe[[#This Row],[Unité]]),CONCATENATE(liste_groupe[[#This Row],[Nom de l''échantillon donné par le client]],liste_groupe[[#This Row],[Dopage (+Testostérone / + EE2, ….)]]),CONCATENATE(liste_groupe[[#This Row],[Nom de l''échantillon donné par le client]],"-",liste_groupe[[#This Row],[Concentration]],liste_groupe[[#This Row],[Unité]],liste_groupe[[#This Row],[Dopage (+Testostérone / + EE2, ….)]]))) -> Testo 30µg/L + FAD-10µg/L | B38: Témoin | C38: 10 | D38: µg/L | E38: Testo 30µg/L + FAD
A39: =IF(ISBLANK(liste_groupe[[#This Row],[Code WF]])," ",IF(ISBLANK(liste_groupe[[#This Row],[Unité]]),CONCATENATE(liste_groupe[[#This Row],[Nom de l''échantillon donné par le client]],liste_groupe[[#This Row],[Dopage (+Testostérone / + EE2, ….)]]),CONCATENATE(liste_groupe[[#This Row],[Nom de l''échantillon donné par le client]],"-",liste_groupe[[#This Row],[Concentration]],liste_groupe[[#This Row],[Unité]],liste_groupe[[#This Row],[Dopage (+Testostérone / + EE2, ….)]]))) -> Arabinose-0.01mg/L + Testostérone | B39: =B15 -> Test | C39: =C15 -> 0.01 | D39: =D15 -> mg/L | E39: =E15 -> Arabinose | F39: + Testostérone
A40: =IF(ISBLANK(liste_groupe[[#This Row],[Code WF]])," ",IF(ISBLANK(liste_groupe[[#This Row],[Unité]]),CONCATENATE(liste_groupe[[#This Row],[Nom de l''échantillon donné par le client]],liste_groupe[[#This Row],[Dopage (+Testostérone / + EE2, ….)]]),CONCATENATE(liste_groupe[[#This Row],[Nom de l''échantillon donné par le client]],"-",liste_groupe[[#This Row],[Concentration]],liste_groupe[[#This Row],[Unité]],liste_groupe[[#This Row],[Dopage (+Testostérone / + EE2, ….)]]))) -> Arabinose-0.1mg/L + Testostérone | B40: =B16 -> Test | C40: =C16 -> 0.1 | D40: =D16 -> mg/L | E40: =E16 -> Arabinose | F40: + Testostérone
A41: =IF(ISBLANK(liste_groupe[[#This Row],[Code WF]])," ",IF(ISBLANK(liste_groupe[[#This Row],[Unité]]),CONCATENATE(liste_groupe[[#This Row],[Nom de l''échantillon donné par le client]],liste_groupe[[#This Row],[Dopage (+Testostérone / + EE2, ….)]]),CONCATENATE(liste_groupe[[#This Row],[Nom de l''échantillon donné par le client]],"-",liste_groupe[[#This Row],[Concentration]],liste_groupe[[#This Row],[Unité]],liste_groupe[[#This Row],[Dopage (+Testostérone / + EE2, ….)]]))) -> Arabinose-1mg/L + Testostérone | B41: =B17 -> Test | C41: =C17 -> 1 | D41: =D17 -> mg/L | E41: =E17 -> Arabinose | F41: + Testostérone
A42: =IF(ISBLANK(liste_groupe[[#This Row],[Code WF]])," ",IF(ISBLANK(liste_groupe[[#This Row],[Unité]]),CONCATENATE(liste_groupe[[#This Row],[Nom de l''échantillon donné par le client]],liste_groupe[[#This Row],[Dopage (+Testostérone / + EE2, ….)]]),CONCATENATE(liste_groupe[[#This Row],[Nom de l''échantillon donné par le client]],"-",liste_groupe[[#This Row],[Concentration]],liste_groupe[[#This Row],[Unité]],liste_groupe[[#This Row],[Dopage (+Testostérone / + EE2, ….)]]))) -> Arabinose-10mg/L + Testostérone | B42: =B18 -> Test | C42: =C18 -> 10 | D42: =D18 -> mg/L | E42: =E18 -> Arabinose | F42: + Testostérone
A43: =IF(ISBLANK(liste_groupe[[#This Row],[Code WF]])," ",IF(ISBLANK(liste_groupe[[#This Row],[Unité]]),CONCATENATE(liste_groupe[[#This Row],[Nom de l''échantillon donné par le client]],liste_groupe[[#This Row],[Dopage (+Testostérone / + EE2, ….)]]),CONCATENATE(liste_groupe[[#This Row],[Nom de l''échantillon donné par le client]],"-",liste_groupe[[#This Row],[Concentration]],liste_groupe[[#This Row],[Unité]],liste_groupe[[#This Row],[Dopage (+Testostérone / + EE2, ….)]]))) -> Arabinose-100mg/L + Testostérone | B43: =B19 -> Test | C43: =C19 -> 100 | D43: =D19 -> mg/L | E43: =E19 -> Arabinose | F43: + Testostérone
...

Sheet Feuil1
A1: Nom groupe | B1: N° de valeur | C1: file name | D1: total area | E1: mean intensity | G1: total fluorescence | I1: nbre de larves
A2: 01 EE2 0 | B2: A | C2: C:\Users\Olympus\Desktop\20190122\plaque1/@01 EE2 0/A1_1.tif | D2: 4931.616 | E2: 73.0526 | G2: 360268
A3: 01 EE2 0 | B3: A | C3: C:\Users\Olympus\Desktop\20190122\plaque1/@01 EE2 0/A1_2.tif | D3: 5234.4345 | E3: 71.1281 | G3: 372315
A4: 01 EE2 0 | B4: A | C4: C:\Users\Olympus\Desktop\20190122\plaque1/@01 EE2 0/A1_3.tif | D4: 3547.3027 | E4: 66.9878 | G4: 237626
A5: 01 EE2 0 | B5: A | C5: C:\Users\Olympus\Desktop\20190122\plaque3/@01 EE2 0/A1_3.tif | D5: 21456.8555 | E5: 67.0655 | G5: 1439015
A6: 01 EE2 0 | B6: A | C6: C:\Users\Olympus\Desktop\20190122\plaque3/@01 EE2 0/A1_2.tif | D6: 21586.6348 | E6: 66.4108 | G6: 1433586
A7: 01 EE2 0 | B7: A | C7: C:\Users\Olympus\Desktop\20190122\plaque3/@01 EE2 0/A1_1.tif | D7: 15984.4921 | E7: 69.7767 | G7: 1115346

Sheet Raw data R4
A1: Nom groupe | B1: N° de valeur | C1: file name | D1: total area | E1: mean intensity | G1: total fluorescence | I1: nbre de larves | J1: Colonne1 | L1: (Tous)
A2: =IFERROR(LEFT(RIGHT(C2,LEN(C2)-SEARCH("@",C2)),SEARCH("/",RIGHT(C2,LEN(C2)-SEARCH("@",C2)-1))),"") -> 01 TS | B2: =LEFT(RIGHT(RIGHT(Tableau4[[#This Row],[file name]],LEN(Tableau4[[#This Row],[file name]])-SEARCH("@",Tableau4[[#This Row],[file name]])),LEN(RIGHT(Tableau4[[#This Row],[file name]],LEN(Tableau4[[#This Row],[file name]])-SEARCH("@",Tableau4[[#This Row],[file name]])))-SEARCH("/",RIGHT(Tableau4[[#This Row],[file name]],LEN(Tableau4[[#This Row],[file name]])-SEARCH("@",Tableau4[[#This Row],[file name]])))),1) -> A | C2: \\192.168.24.208\images\R&D\2-Test oestrogénique\OECD and AOPs\REACTIV oecd interlaboratory validation\WF data\Repeats for invalid experiments - EBO\2022-EBO-ARABINOSE R4\plaque 1/@01 TS/A1_01.tif | D2: 108.7688 | E2: 62.2 | G2: 6765 | K2: Filtre lignes : Enlever (vide) et Néant | L2: Filtre colonnes : Enlever (vide) et " "
A3: =IFERROR(LEFT(RIGHT(C3,LEN(C3)-SEARCH("@",C3)),SEARCH("/",RIGHT(C3,LEN(C3)-SEARCH("@",C3)-1))),"") -> 01 TS | B3: =LEFT(RIGHT(RIGHT(Tableau4[[#This Row],[file name]],LEN(Tableau4[[#This Row],[file name]])-SEARCH("@",Tableau4[[#This Row],[file name]])),LEN(RIGHT(Tableau4[[#This Row],[file name]],LEN(Tableau4[[#This Row],[file name]])-SEARCH("@",Tableau4[[#This Row],[file name]])))-SEARCH("/",RIGHT(Tableau4[[#This Row],[file name]],LEN(Tableau4[[#This Row],[file name]])-SEARCH("@",Tableau4[[#This Row],[file name]])))),1) -> A | C3: \\192.168.24.208\images\R&D\2-Test oestrogénique\OECD and AOPs\REACTIV oecd interlaboratory validation\WF data\Repeats for invalid experiments - EBO\2022-EBO-ARABINOSE R4\plaque 1/@01 TS/A1_02.tif | D3: 282.7988 | E3: 63.1538 | G3: 17860 | K3: Moyenne de total fluorescence | L3: Étiquettes de colonnes
A4: =IFERROR(LEFT(RIGHT(C4,LEN(C4)-SEARCH("@",C4)),SEARCH("/",RIGHT(C4,LEN(C4)-SEARCH("@",C4)-1))),"") -> 01 TS | B4: =LEFT(RIGHT(RIGHT(Tableau4[[#This Row],[file name]],LEN(Tableau4[[#This Row],[file name]])-SEARCH("@",Tableau4[[#This Row],[file name]])),LEN(RIGHT(Tableau4[[#This Row],[file name]],LEN(Tableau4[[#This Row],[file name]])-SEARCH("@",Tableau4[[#This Row],[file name]])))-SEARCH("/",RIGHT(Tableau4[[#This Row],[file name]],LEN(Tableau4[[#This Row],[file name]])-SEARCH("@",Tableau4[[#This Row],[file name]])))),1) -> A | C4: \\192.168.24.208\images\R&D\2-Test oestrogénique\OECD and AOPs\REACTIV oecd interlaboratory validation\WF data\Repeats for invalid experiments - EBO\2022-EBO-ARABINOSE R4\plaque 1/@01 TS/A1_03.tif | D4: 261.0451 | E4: 62.6667 | G4: 16359 | K4: Étiquettes de lignes | L4: 01 TS | M4: 02 EE2 34 | N4: 03 EE2 51 | O4: 04 EE2 76 | P4: 05 EE2 114 | Q4: 06 EE2 171 | R4: 07 EE2 488 | S4: 08 ARABINOSE 0.01 | T4: 09 ARABINOSE 0.1 | U4: 10 ARABINOSE 1 | V4: 11 ARABINOSE 10 | W4: 12 ARABINOSE 100 | X4: 13 TESTO 0.2 | Y4: 14 TESTO 0.2 | Z4: 15 TESTO +EE2 | AA4: 16 TESTO + FAD | AB4: 17 ARABINOSE 0.01 + TESTO | AC4: 18 ARABINOSE 0.1 + TESTO | AD4: 19 ARABINOSE 1 + TESTO | AE4: 20 ARABINOSE 10 + TESTO | AF4: 21 ARABINOSE 100 + TESTO
A5: =IFERROR(LEFT(RIGHT(C5,LEN(C5)-SEARCH("@",C5)),SEARCH("/",RIGHT(C5,LEN(C5)-SEARCH("@",C5)-1))),"") -> 01 TS | B5: =LEFT(RIGHT(RIGHT(Tableau4[[#This Row],[file name]],LEN(Tableau4[[#This Row],[file name]])-SEARCH("@",Tableau4[[#This Row],[file name]])),LEN(RIGHT(Tableau4[[#This Row],[file name]],LEN(Tableau4[[#This Row],[file name]])-SEARCH("@",Tableau4[[#This Row],[file name]])))-SEARCH("/",RIGHT(Tableau4[[#This Row],[file name]],LEN(Tableau4[[#This Row],[file name]])-SEARCH("@",Tableau4[[#This Row],[file name]])))),1) -> B | C5: \\192.168.24.208\images\R&D\2-Test oestrogénique\OECD and AOPs\REACTIV oecd interlaboratory validation\WF data\Repeats for invalid experiments - EBO\2022-EBO-ARABINOSE R4\plaque 1/@01 TS/B1_01.tif | D5: 957.1652 | E5: 65.25 | G5: 62455 | K5: A | L5: 13661.333 | M5: 18440.333 | N5: 20535.5 | P5: 909024.33 | Q5: 1665191.7 | S5: 13755.667 | T5: 18675.5 | U5: 97261 | V5: 14582.333 | W5: 129130.33 | X5: 180610.5 | Y5: 3066750.3 | Z5: 4221483 | AA5: 63782 | AB5: 955613.67 | AC5: 1551804.3 | AD5: 2392594 | AE5: 2430909.7 | AF5: 1534589.7
A6: =IFERROR(LEFT(RIGHT(C6,LEN(C6)-SEARCH("@",C6)),SEARCH("/",RIGHT(C6,LEN(C6)-SEARCH("@",C6)-1))),"") -> 01 TS | B6: =LEFT(RIGHT(RIGHT(Tableau4[[#This Row],[file name]],LEN(Tableau4[[#This Row],[file name]])-SEARCH("@",Tableau4[[#This Row],[file name]])),LEN(RIGHT(Tableau4[[#This Row],[file name]],LEN(Tableau4[[#This Row],[file name]])-SEARCH("@",Tableau4[[#This Row],[file name]])))-SEARCH("/",RIGHT(Tableau4[[#This Row],[file name]],LEN(Tableau4[[#This Row],[file name]])-SEARCH("@",Tableau4[[#This Row],[file name]])))),1) -> B | C6: \\192.168.24.208\images\R&D\2-Test oestrogénique\OECD and AOPs\REACTIV oecd interlaboratory validation\WF data\Repeats for invalid experiments - EBO\2022-EBO-ARABINOSE R4\plaque 1/@01 TS/B1_02.tif | D6: 674.3664 | E6: 66.871 | G6: 45096 | K6: B | L6: 38562.333 | M6: 641823 | N6: 48641.5 | O6: 95020.5 | P6: 288629 | Q6: 2163063 | R6: 7890659.7 | S6: 18084.667 | T6: 31760.5 | U6: 17381.333 | W6: 66348.667 | X6: 2857972 | Y6: 1708235 | Z6: 5468220 | AA6: 128267.33 | AB6: 2972549.3 | AC6: 2715528.3 | AD6: 2228672.3 | AE6: 1147663 | AF6: 1359609.7
A7: =IFERROR(LEFT(RIGHT(C7,LEN(C7)-SEARCH("@",C7)),SEARCH("/",RIGHT(C7,LEN(C7)-SEARCH("@",C7)-1))),"") -> 01 TS | B7: =LEFT(RIGHT(RIGHT(Tableau4[[#This Row],[file name]],LEN(Tableau4[[#This Row],[file name]])-SEARCH("@",Tableau4[[#This Row],[file name]])),LEN(RIGHT(Tableau4[[#This Row],[file name]],LEN(Tableau4[[#This Row],[file name]])-SEARCH("@",Tableau4[[#This Row],[file name]])))-SEARCH("/",RIGHT(Tableau4[[#This Row],[file name]],LEN(Tableau4[[#This Row],[file name]])-SEARCH("@",Tableau4[[#This Row],[file name]])))),1) -> B | C7: \\192.168.24.208\images\R&D\2-Test oestrogénique\OECD and AOPs\REACTIV oecd interlaboratory validation\WF data\Repeats for invalid experiments - EBO\2022-EBO-ARABINOSE R4\plaque 1/@01 TS/B1_03.tif | D7: 130.5225 | E7: 62.3333 | G7: 8136 | K7: C | L7: 19738 | M7: 16039.667 | N7: 112336.33 | O7: 110110 | P7: 958369 | Q7: 2674798 | R7: 6349058.3 | S7: 17156.333 | T7: 222889 | U7: 117956 | V7: 182760.67 | W7: 146802 | X7: 3857789.3 | AA7: 92703.5 | AB7: 3929707 | AC7: 3475843.7 | AD7: 826766 | AE7: 2392449.3 | AF7: 2190320.3
A8: =IFERROR(LEFT(RIGHT(C8,LEN(C8)-SEARCH("@",C8)),SEARCH("/",RIGHT(C8,LEN(C8)-SEARCH("@",C8)-1))),"") -> 01 TS | B8: =LEFT(RIGHT(RIGHT(Tableau4[[#This Row],[file name]],LEN(Tableau4[[#This Row],[file name]])-SEARCH("@",Tableau4[[#This Row],[file name]])),LEN(RIGHT(Tableau4[[#This Row],[file name]],LEN(Tableau4[[#This Row],[file name]])-SEARCH("@",Tableau4[[#This Row],[file name]])))-SEARCH("/",RIGHT(Tableau4[[#This Row],[file name]],LEN(Tableau4[[#This Row],[file name]])-SEARCH("@",Tableau4[[#This Row],[file name]])))),1) -> C | C8: \\192.168.24.208\images\R&D\2-Test oestrogénique\OECD and AOPs\REACTIV oecd interlaboratory validation\WF data\Repeats for invalid experiments - EBO\2022-EBO-ARABINOSE R4\plaque 1/@01 TS/C1_01.tif | D8: 174.03 | E8: 66.125 | G8: 11508 | K8: D | L8: 66980 | N8: 270268.67 | O8: 129674.33 | P8: 3738404.7 | Q8: 2429720.5 | R8: 5811754.7 | S8: 68774.5 | T8: 49431.667 | U8: 25502.667 | V8: 434140 | W8: 279231 | X8: 1958316.3 | Y8: 2630261 | Z8: 5785933 | AA8: 17388.667 | AB8: 2988030.7 | AC8: 61077.333 | AD8: 193445 | AE8: 76443 | AF8: 2035375.7
A9: =IFERROR(LEFT(RIGHT(C9,LEN(C9)-SEARCH("@",C9)),SEARCH("/",RIGHT(C9,LEN(C9)-SEARCH("@",C9)-1))),"") -> 01 TS | B9: =LEFT(RIGHT(RIGHT(Tableau4[[#This Row],[file name]],LEN(Tableau4[[#This Row],[file name]])-SEARCH("@",Tableau4[[#This Row],[file name]])),LEN(RIGHT(Tableau4[[#This Row],[file name]],LEN(Tableau4[[#This Row],[file name]])-SEARCH("@",Tableau4[[#This Row],[file name]])))-SEARCH("/",RIGHT(Tableau4[[#This Row],[file name]],LEN(Tableau4[[#This Row],[file name]])-SEARCH("@",Tableau4[[#This Row],[file name]])))),1) -> C | C9: \\192.168.24.208\images\R&D\2-Test oestrogénique\OECD and AOPs\REACTIV oecd interlaboratory validation\WF data\Repeats for invalid experiments - EBO\2022-EBO-ARABINOSE R4\plaque 1/@01 TS/C1_02.tif | D9: 435.0751 | E9: 62.4 | G9: 27149 | K9: E | L9: 15315 | M9: 38815.667 | N9: 181078 | O9: 13284.333 | P9: 378218 | Q9: 1476391 | R9: 4770540.3 | S9: 62955.333 | T9: 52535.333 | U9: 107213 | V9: 81772 | W9: 22319.5 | X9: 2014934.7 | Y9: 722805 | Z9: 5361691.5 | AA9: 18469 | AB9: 51165 | AC9: 1668371.5 | AD9: 139014 | AE9: 131001 | AF9: 3212790
A10: =IFERROR(LEFT(RIGHT(C10,LEN(C10)-SEARCH("@",C10)),SEARCH("/",RIGHT(C10,LEN(C10)-SEARCH("@",C10)-1))),"") -> 01 TS | B10: =LEFT(RIGHT(RIGHT(Tableau4[[#This Row],[file name]],LEN(Tableau4[[#This Row],[file name]])-SEARCH("@",Tableau4[[#This Row],[file name]])),LEN(RIGHT(Tableau4[[#This Row],[file name]],LEN(Tableau4[[#This Row],[file name]])-SEARCH("@",Tableau4[[#This Row],[file name]])))-SEARCH("/",RIGHT(Tableau4[[#This Row],[file name]],LEN(Tableau4[[#This Row],[file name]])-SEARCH("@",Tableau4[[#This Row],[file name]])))),1) -> C | C10: \\192.168.24.208\images\R&D\2-Test oestrogénique\OECD and AOPs\REACTIV oecd interlaboratory validation\WF data\Repeats for invalid experiments - EBO\2022-EBO-ARABINOSE R4\plaque 1/@01 TS/C1_03.tif | D10: 326.3063 | E10: 63 | G10: 20557 | K10: F | L10: 97805 | M10: 13596 | N10: 58031.667 | O10: 149056.67 | P10: 844263.33 | Q10: 4128920.7 | R10: 6414696.7 | S10: 70888.333 | T10: 54413.667 | U10: 100654.67 | V10: 46872 | W10: 212969.33 | X10: 548564.33 | Y10: 1621851.3 | Z10: 4713168.7 | AA10: 40897 | AB10: 709379 | AD10: 1273812.5 | AE10: 1725500.3 | AF10: 926264
A11: =IFERROR(LEFT(RIGHT(C11,LEN(C11)-SEARCH("@",C11)),SEARCH("/",RIGHT(C11,LEN(C11)-SEARCH("@",C11)-1))),"") -> 01 TS | B11: =LEFT(RIGHT(RIGHT(Tableau4[[#This Row],[file name]],LEN(Tableau4[[#This Row],[file name]])-SEARCH("@",Tableau4[[#This Row],[file name]])),LEN(RIGHT(Tableau4[[#This Row],[file name]],LEN(Tableau4[[#This Row],[file name]])-SEARCH("@",Tableau4[[#This Row],[file name]])))-SEARCH("/",RIGHT(Tableau4[[#This Row],[file name]],LEN(Tableau4[[#This Row],[file name]])-SEARCH("@",Tableau4[[#This Row],[file name]])))),1) -> D | C11: \\192.168.24.208\images\R&D\2-Test oestrogénique\OECD and AOPs\REACTIV oecd interlaboratory validation\WF data\Repeats for invalid experiments - EBO\2022-EBO-ARABINOSE R4\plaque 1/@01 TS/D1_01.tif | D11: 1196.4565 | E11: 63.5273 | G11: 76008 | K11: G | L11: 24828.333 | M11: 26423.667 | N11: 17272.5 | O11: 156496.33 | P11: 234143 | Q11: 2408880.3 | R11: 3195749.7 | S11: 278339.33 | T11: 452315 | U11: 96470.333 | V11: 45911.5 | X11: 379465.33 | Y11: 2054946.3 | Z11: 6739059.7 | AA11: 80967.5 | AB11: 20960 | AC11: 718461.33 | AD11: 1414668.5 | AE11: 1486963.3 | AF11: 112387.33
A12: =IFERROR(LEFT(RIGHT(C12,LEN(C12)-SEARCH("@",C12)),SEARCH("/",RIGHT(C12,LEN(C12)-SEARCH("@",C12)-1))),"") -> 01 TS | B12: =LEFT(RIGHT(RIGHT(Tableau4[[#This Row],[file name]],LEN(Tableau4[[#This Row],[file name]])-SEARCH("@",Tableau4[[#This Row],[file name]])),LEN(RIGHT(Tableau4[[#This Row],[file name]],LEN(Tableau4[[#This Row],[file name]])-SEARCH("@",Tableau4[[#This Row],[file name]])))-SEARCH("/",RIGHT(Tableau4[[#This Row],[file name]],LEN(Tableau4[[#This Row],[file name]])-SEARCH("@",Tableau4[[#This Row],[file name]])))),1) -> D | C12: \\192.168.24.208\images\R&D\2-Test oestrogénique\OECD and AOPs\REACTIV oecd interlaboratory validation\WF data\Repeats for invalid experiments - EBO\2022-EBO-ARABINOSE R4\plaque 1/@01 TS/D1_02.tif | D12: 1000.6727 | E12: 63.8696 | G12: 63913 | K12: H | L12: 54551 | M12: 11333.667 | O12: 128586.67 | P12: 1812421.3 | Q12: 1650798 | R12: 5537578 | S12: 49729 | T12: 45792 | U12: 20571.667 | V12: 184645.67 | W12: 167047 | X12: 2613293 | Y12: 1524024.3 | Z12: 4751984.7 | AA12: 302921 | AB12: 509893.67 | AC12: 2403608.7 | AD12: 856782.5 | AE12: 244055 | AF12: 15634
A13: =IFERROR(LEFT(RIGHT(C13,LEN(C13)-SEARCH("@",C13)),SEARCH("/",RIGHT(C13,LEN(C13)-SEARCH("@",C13)-1))),"") -> 01 TS | B13: =LEFT(RIGHT(RIGHT(Tableau4[[#This Row],[file name]],LEN(Tableau4[[#This Row],[file name]])-SEARCH("@",Tableau4[[#This Row],[file name]])),LEN(RIGHT(Tableau4[[#This Row],[file name]],LEN(Tableau4[[#This Row],[file name]])-SEARCH("@",Tableau4[[#This Row],[file name]])))-SEARCH("/",RIGHT(Tableau4[[#This Row],[file name]],LEN(Tableau4[[#This Row],[file name]])-SEARCH("@",Tableau4[[#This Row],[file name]])))),1) -> D | C13: \\192.168.24.208\images\R&D\2-Test oestrogénique\OECD and AOPs\REACTIV oecd interlaboratory validation\WF data\Repeats for invalid experiments - EBO\2022-EBO-ARABINOSE R4\plaque 1/@01 TS/D1_03.tif | D13: 957.1652 | E13: 63.75 | G13: 61019
A14: =IFERROR(LEFT(RIGHT(C14,LEN(C14)-SEARCH("@",C14)),SEARCH("/",RIGHT(C14,LEN(C14)-SEARCH("@",C14)-1))),"") -> 01 TS | B14: =LEFT(RIGHT(RIGHT(Tableau4[[#This Row],[file name]],LEN(Tableau4[[#This Row],[file name]])-SEARCH("@",Tableau4[[#This Row],[file name]])),LEN(RIGHT(Tableau4[[#This Row],[file name]],LEN(Tableau4[[#This Row],[file name]])-SEARCH("@",Tableau4[[#This Row],[file name]])))-SEARCH("/",RIGHT(Tableau4[[#This Row],[file name]],LEN(Tableau4[[#This Row],[file name]])-SEARCH("@",Tableau4[[#This Row],[file name]])))),1) -> E | C14: \\192.168.24.208\images\R&D\2-Test oestrogénique\OECD and AOPs\REACTIV oecd interlaboratory validation\WF data\Repeats for invalid experiments - EBO\2022-EBO-ARABINOSE R4\plaque 1/@01 TS/E1_01.tif | D14: 282.7988 | E14: 64.4615 | G14: 18230
A15: =IFERROR(LEFT(RIGHT(C15,LEN(C15)-SEARCH("@",C15)),SEARCH("/",RIGHT(C15,LEN(C15)-SEARCH("@",C15)-1))),"") -> 01 TS | B15: =LEFT(RIGHT(RIGHT(Tableau4[[#This Row],[file name]],LEN(Tableau4[[#This Row],[file name]])-SEARCH("@",Tableau4[[#This Row],[file name]])),LEN(RIGHT(Tableau4[[#This Row],[file name]],LEN(Tableau4[[#This Row],[file name]])-SEARCH("@",Tableau4[[#This Row],[file name]])))-SEARCH("/",RIGHT(Tableau4[[#This Row],[file name]],LEN(Tableau4[[#This Row],[file name]])-SEARCH("@",Tableau4[[#This Row],[file name]])))),1) -> E | C15: \\192.168.24.208\images\R&D\2-Test oestrogénique\OECD and AOPs\REACTIV oecd interlaboratory validation\WF data\Repeats for invalid experiments - EBO\2022-EBO-ARABINOSE R4\plaque 1/@01 TS/E1_02.tif | D15: 195.7838 | E15: 63.3333 | G15: 12400
A16: =IFERROR(LEFT(RIGHT(C16,LEN(C16)-SEARCH("@",C16)),SEARCH("/",RIGHT(C16,LEN(C16)-SEARCH("@",C16)-1))),"") -> 01 TS | B16: =LEFT(RIGHT(RIGHT(Tableau4[[#This Row],[file name]],LEN(Tableau4[[#This Row],[file name]])-SEARCH("@",Tableau4[[#This Row],[file name]])),LEN(RIGHT(Tableau4[[#This Row],[file name]],LEN(Tableau4[[#This Row],[file name]])-SEARCH("@",Tableau4[[#This Row],[file name]])))-SEARCH("/",RIGHT(Tableau4[[#This Row],[file name]],LEN(Tableau4[[#This Row],[file name]])-SEARCH("@",Tableau4[[#This Row],[file name]])))),1) -> E | C16: \\192.168.24.208\images\R&D\2-Test oestrogénique\OECD and AOPs\REACTIV oecd interlaboratory validation\WF data\Repeats for invalid experiments - EBO\2022-EBO-ARABINOSE R4\plaque 1/@01 TS/E1_03- exclu.tif
A17: =IFERROR(LEFT(RIGHT(C17,LEN(C17)-SEARCH("@",C17)),SEARCH("/",RIGHT(C17,LEN(C17)-SEARCH("@",C17)-1))),"") -> 01 TS | B17: =LEFT(RIGHT(RIGHT(Tableau4[[#This Row],[file name]],LEN(Tableau4[[#This Row],[file name]])-SEARCH("@",Tableau4[[#This Row],[file name]])),LEN(RIGHT(Tableau4[[#This Row],[file name]],LEN(Tableau4[[#This Row],[file name]])-SEARCH("@",Tableau4[[#This Row],[file name]])))-SEARCH("/",RIGHT(Tableau4[[#This Row],[file name]],LEN(Tableau4[[#This Row],[file name]])-SEARCH("@",Tableau4[[#This Row],[file name]])))),1) -> F | C17: \\192.168.24.208\images\R&D\2-Test oestrogénique\OECD and AOPs\REACTIV oecd interlaboratory validation\WF data\Repeats for invalid experiments - EBO\2022-EBO-ARABINOSE R4\plaque 1/@01 TS/F1_01.tif | D17: 3154.2945 | E17: 68.0414 | G17: 214623
A18: =IFERROR(LEFT(RIGHT(C18,LEN(C18)-SEARCH("@",C18)),SEARCH("/",RIGHT(C18,LEN(C18)-SEARCH("@",C18)-1))),"") -> 01 TS | B18: =LEFT(RIGHT(RIGHT(Tableau4[[#This Row],[file name]],LEN(Tableau4[[#This Row],[file name]])-SEARCH("@",Tableau4[[#This Row],[file name]])),LEN(RIGHT(Tableau4[[#This Row],[file name]],LEN(Tableau4[[#This Row],[file name]])-SEARCH("@",Tableau4[[#This Row],[file name]])))-SEARCH("/",RIGHT(Tableau4[[#This Row],[file name]],LEN(Tableau4[[#This Row],[file name]])-SEARCH("@",Tableau4[[#This Row],[file name]])))),1) -> F | C18: \\192.168.24.208\images\R&D\2-Test oestrogénique\OECD and AOPs\REACTIV oecd interlaboratory validation\WF data\Repeats for invalid experiments - EBO\2022-EBO-ARABINOSE R4\plaque 1/@01 TS/F1_02.tif | D18: 804.8889 | E18: 64.7838 | G18: 52144
A19: =IFERROR(LEFT(RIGHT(C19,LEN(C19)-SEARCH("@",C19)),SEARCH("/",RIGHT(C19,LEN(C19)-SEARCH("@",C19)-1))),"") -> 01 TS | B19: =LEFT(RIGHT(RIGHT(Tableau4[[#This Row],[file name]],LEN(Tableau4[[#This Row],[file name]])-SEARCH("@",Tableau4[[#This Row],[file name]])),LEN(RIGHT(Tableau4[[#This Row],[file name]],LEN(Tableau4[[#This Row],[file name]])-SEARCH("@",Tableau4[[#This Row],[file name]])))-SEARCH("/",RIGHT(Tableau4[[#This Row],[file name]],LEN(Tableau4[[#This Row],[file name]])-SEARCH("@",Tableau4[[#This Row],[file name]])))),1) -> F | C19: \\192.168.24.208\images\R&D\2-Test oestrogénique\OECD and AOPs\REACTIV oecd interlaboratory validation\WF data\Repeats for invalid experiments - EBO\2022-EBO-ARABINOSE R4\plaque 1/@01 TS/F1_03.tif | D19: 413.3213 | E19: 64.4737 | G19: 26648
A20: =IFERROR(LEFT(RIGHT(C20,LEN(C20)-SEARCH("@",C20)),SEARCH("/",RIGHT(C20,LEN(C20)-SEARCH("@",C20)-1))),"") -> 01 TS | B20: =LEFT(RIGHT(RIGHT(Tableau4[[#This Row],[file name]],LEN(Tableau4[[#This Row],[file name]])-SEARCH("@",Tableau4[[#This Row],[file name]])),LEN(RIGHT(Tableau4[[#This Row],[file name]],LEN(Tableau4[[#This Row],[file name]])-SEARCH("@",Tableau4[[#This Row],[file name]])))-SEARCH("/",RIGHT(Tableau4[[#This Row],[file name]],LEN(Tableau4[[#This Row],[file name]])-SEARCH("@",Tableau4[[#This Row],[file name]])))),1) -> G | C20: \\192.168.24.208\images\R&D\2-Test oestrogénique\OECD and AOPs\REACTIV oecd interlaboratory validation\WF data\Repeats for invalid experiments - EBO\2022-EBO-ARABINOSE R4\plaque 1/@01 TS/G1_01.tif | D20: 413.3213 | E20: 64.2632 | G20: 26561
A21: =IFERROR(LEFT(RIGHT(C21,LEN(C21)-SEARCH("@",C21)),SEARCH("/",RIGHT(C21,LEN(C21)-SEARCH("@",C21)-1))),"") -> 01 TS | B21: =LEFT(RIGHT(RIGHT(Tableau4[[#This Row],[file name]],LEN(Tableau4[[#This Row],[file name]])-SEARCH("@",Tableau4[[#This Row],[file name]])),LEN(RIGHT(Tableau4[[#This Row],[file name]],LEN(Tableau4[[#This Row],[file name]])-SEARCH("@",Tableau4[[#This Row],[file name]])))-SEARCH("/",RIGHT(Tableau4[[#This Row],[file name]],LEN(Tableau4[[#This Row],[file name]])-SEARCH("@",Tableau4[[#This Row],[file name]])))),1) -> G | C21: \\192.168.24.208\images\R&D\2-Test oestrogénique\OECD and AOPs\REACTIV oecd interlaboratory validation\WF data\Repeats for invalid experiments - EBO\2022-EBO-ARABINOSE R4\plaque 1/@01 TS/G1_02.tif | D21: 435.0751 | E21: 63.15 | G21: 27475
A22: =IFERROR(LEFT(RIGHT(C22,LEN(C22)-SEARCH("@",C22)),SEARCH("/",RIGHT(C22,LEN(C22)-SEARCH("@",C22)-1))),"") -> 01 TS | B22: =LEFT(RIGHT(RIGHT(Tableau4[[#This Row],[file name]],LEN(Tableau4[[#This Row],[file name]])-SEARCH("@",Tableau4[[#This Row],[file name]])),LEN(RIGHT(Tableau4[[#This Row],[file name]],LEN(Tableau4[[#This Row],[file name]])-SEARCH("@",Tableau4[[#This Row],[file name]])))-SEARCH("/",RIGHT(Tableau4[[#This Row],[file name]],LEN(Tableau4[[#This Row],[file name]])-SEARCH("@",Tableau4[[#This Row],[file name]])))),1) -> G | C22: \\192.168.24.208\images\R&D\2-Test oestrogénique\OECD and AOPs\REACTIV oecd interlaboratory validation\WF data\Repeats for invalid experiments - EBO\2022-EBO-ARABINOSE R4\plaque 1/@01 TS/G1_03.tif | D22: 326.3063 | E22: 62.6667 | G22: 20449
A23: =IFERROR(LEFT(RIGHT(C23,LEN(C23)-SEARCH("@",C23)),SEARCH("/",RIGHT(C23,LEN(C23)-SEARCH("@",C23)-1))),"") -> 01 TS | B23: =LEFT(RIGHT(RIGHT(Tableau4[[#This Row],[file name]],LEN(Tableau4[[#This Row],[file name]])-SEARCH("@",Tableau4[[#This Row],[file name]])),LEN(RIGHT(Tableau4[[#This Row],[file name]],LEN(Tableau4[[#This Row],[file name]])-SEARCH("@",Tableau4[[#This Row],[file name]])))-SEARCH("/",RIGHT(Tableau4[[#This Row],[file name]],LEN(Tableau4[[#This Row],[file name]])-SEARCH("@",Tableau4[[#This Row],[file name]])))),1) -> H | C23: \\192.168.24.208\images\R&D\2-Test oestrogénique\OECD and AOPs\REACTIV oecd interlaboratory validation\WF data\Repeats for invalid experiments - EBO\2022-EBO-ARABINOSE R4\plaque 1/@01 TS/H1_01.tif | D23: 239.2913 | E23: 62.7273 | G23: 15010
A24: =IFERROR(LEFT(RIGHT(C24,LEN(C24)-SEARCH("@",C24)),SEARCH("/",RIGHT(C24,LEN(C24)-SEARCH("@",C24)-1))),"") -> 01 TS | B24: =LEFT(RIGHT(RIGHT(Tableau4[[#This Row],[file name]],LEN(Tableau4[[#This Row],[file name]])-SEARCH("@",Tableau4[[#This Row],[file name]])),LEN(RIGHT(Tableau4[[#This Row],[file name]],LEN(Tableau4[[#This Row],[file name]])-SEARCH("@",Tableau4[[#This Row],[file name]])))-SEARCH("/",RIGHT(Tableau4[[#This Row],[file name]],LEN(Tableau4[[#This Row],[file name]])-SEARCH("@",Tableau4[[#This Row],[file name]])))),1) -> H | C24: \\192.168.24.208\images\R&D\2-Test oestrogénique\OECD and AOPs\REACTIV oecd interlaboratory validation\WF data\Repeats for invalid experiments - EBO\2022-EBO-ARABINOSE R4\plaque 1/@01 TS/H1_02.tif | D24: 1892.5767 | E24: 64.7356 | G24: 122517
A25: =IFERROR(LEFT(RIGHT(C25,LEN(C25)-SEARCH("@",C25)),SEARCH("/",RIGHT(C25,LEN(C25)-SEARCH("@",C25)-1))),"") -> 01 TS | B25: =LEFT(RIGHT(RIGHT(Tableau4[[#This Row],[file name]],LEN(Tableau4[[#This Row],[file name]])-SEARCH("@",Tableau4[[#This Row],[file name]])),LEN(RIGHT(Tableau4[[#This Row],[file name]],LEN(Tableau4[[#This Row],[file name]])-SEARCH("@",Tableau4[[#This Row],[file name]])))-SEARCH("/",RIGHT(Tableau4[[#This Row],[file name]],LEN(Tableau4[[#This Row],[file name]])-SEARCH("@",Tableau4[[#This Row],[file name]])))),1) -> H | C25: \\192.168.24.208\images\R&D\2-Test oestrogénique\OECD and AOPs\REACTIV oecd interlaboratory validation\WF data\Repeats for invalid experiments - EBO\2022-EBO-ARABINOSE R4\plaque 1/@01 TS/H1_03.tif | D25: 413.3213 | E25: 63.2105 | G25: 26126
A26: =IFERROR(LEFT(RIGHT(C26,LEN(C26)-SEARCH("@",C26)),SEARCH("/",RIGHT(C26,LEN(C26)-SEARCH("@",C26)-1))),"") | B26: =LEFT(RIGHT(RIGHT(Tableau4[[#This Row],[file name]],LEN(Tableau4[[#This Row],[file name]])-SEARCH("@",Tableau4[[#This Row],[file name]])),LEN(RIGHT(Tableau4[[#This Row],[file name]],LEN(Tableau4[[#This Row],[file name]])-SEARCH("@",Tableau4[[#This Row],[file name]])))-SEARCH("/",RIGHT(Tableau4[[#This Row],[file name]],LEN(Tableau4[[#This Row],[file name]])-SEARCH("@",Tableau4[[#This Row],[file name]])))),1) -> #VALUE!
A27: =IFERROR(LEFT(RIGHT(C27,LEN(C27)-SEARCH("@",C27)),SEARCH("/",RIGHT(C27,LEN(C27)-SEARCH("@",C27)-1))),"") | B27: =LEFT(RIGHT(RIGHT(Tableau4[[#This Row],[file name]],LEN(Tableau4[[#This Row],[file name]])-SEARCH("@",Tableau4[[#This Row],[file name]])),LEN(RIGHT(Tableau4[[#This Row],[file name]],LEN(Tableau4[[#This Row],[file name]])-SEARCH("@",Tableau4[[#This Row],[file name]])))-SEARCH("/",RIGHT(Tableau4[[#This Row],[file name]],LEN(Tableau4[[#This Row],[file name]])-SEARCH("@",Tableau4[[#This Row],[file name]])))),1) -> #VALUE! | C27: group | E27: mean of mean fluo | F27: SD mean fluo | G27: mean of total fluo | H27: SD total fluo | I27: n fluorescent | J27: n total
A28: =IFERROR(LEFT(RIGHT(C28,LEN(C28)-SEARCH("@",C28)),SEARCH("/",RIGHT(C28,LEN(C28)-SEARCH("@",C28)-1))),"") -> 01 TS | B28: =LEFT(RIGHT(RIGHT(Tableau4[[#This Row],[file name]],LEN(Tableau4[[#This Row],[file name]])-SEARCH("@",Tableau4[[#This Row],[file name]])),LEN(RIGHT(Tableau4[[#This Row],[file name]],LEN(Tableau4[[#This Row],[file name]])-SEARCH("@",Tableau4[[#This Row],[file name]])))-SEARCH("/",RIGHT(Tableau4[[#This Row],[file name]],LEN(Tableau4[[#This Row],[file name]])-SEARCH("@",Tableau4[[#This Row],[file name]])))),1) | C28: \\192.168.24.208\images\R&D\2-Test oestrogénique\OECD and AOPs\REACTIV oecd interlaboratory validation\WF data\Repeats for invalid experiments - EBO\2022-EBO-ARABINOSE R4\plaque 1/@01 TS/ | E28: 63.9521 | F28: 1.4721 | G28: 41197.1667 | H28: 45990.0627 | I28: 24 | J28: 24
A29: =IFERROR(LEFT(RIGHT(C29,LEN(C29)-SEARCH("@",C29)),SEARCH("/",RIGHT(C29,LEN(C29)-SEARCH("@",C29)-1))),"") | B29: =LEFT(RIGHT(RIGHT(Tableau4[[#This Row],[file name]],LEN(Tableau4[[#This Row],[file name]])-SEARCH("@",Tableau4[[#This Row],[file name]])),LEN(RIGHT(Tableau4[[#This Row],[file name]],LEN(Tableau4[[#This Row],[file name]])-SEARCH("@",Tableau4[[#This Row],[file name]])))-SEARCH("/",RIGHT(Tableau4[[#This Row],[file name]],LEN(Tableau4[[#This Row],[file name]])-SEARCH("@",Tableau4[[#This Row],[file name]])))),1) -> #VALUE!
A30: =IFERROR(LEFT(RIGHT(C30,LEN(C30)-SEARCH("@",C30)),SEARCH("/",RIGHT(C30,LEN(C30)-SEARCH("@",C30)-1))),"") | B30: =LEFT(RIGHT(RIGHT(Tableau4[[#This Row],[file name]],LEN(Tableau4[[#This Row],[file name]])-SEARCH("@",Tableau4[[#This Row],[file name]])),LEN(RIGHT(Tableau4[[#This Row],[file name]],LEN(Tableau4[[#This Row],[file name]])-SEARCH("@",Tableau4[[#This Row],[file name]])))-SEARCH("/",RIGHT(Tableau4[[#This Row],[file name]],LEN(Tableau4[[#This Row],[file name]])-SEARCH("@",Tableau4[[#This Row],[file name]])))),1) -> #VALUE!
A31: =IFERROR(LEFT(RIGHT(C31,LEN(C31)-SEARCH("@",C31)),SEARCH("/",RIGHT(C31,LEN(C31)-SEARCH("@",C31)-1))),"") | B31: =LEFT(RIGHT(RIGHT(Tableau4[[#This Row],[file name]],LEN(Tableau4[[#This Row],[file name]])-SEARCH("@",Tableau4[[#This Row],[file name]])),LEN(RIGHT(Tableau4[[#This Row],[file name]],LEN(Tableau4[[#This Row],[file name]])-SEARCH("@",Tableau4[[#This Row],[file name]])))-SEARCH("/",RIGHT(Tableau4[[#This Row],[file name]],LEN(Tableau4[[#This Row],[file name]])-SEARCH("@",Tableau4[[#This Row],[file name]])))),1) -> #VALUE!
A32: =IFERROR(LEFT(RIGHT(C32,LEN(C32)-SEARCH("@",C32)),SEARCH("/",RIGHT(C32,LEN(C32)-SEARCH("@",C32)-1))),"") | B32: =LEFT(RIGHT(RIGHT(Tableau4[[#This Row],[file name]],LEN(Tableau4[[#This Row],[file name]])-SEARCH("@",Tableau4[[#This Row],[file name]])),LEN(RIGHT(Tableau4[[#This Row],[file name]],LEN(Tableau4[[#This Row],[file name]])-SEARCH("@",Tableau4[[#This Row],[file name]])))-SEARCH("/",RIGHT(Tableau4[[#This Row],[file name]],LEN(Tableau4[[#This Row],[file name]])-SEARCH("@",Tableau4[[#This Row],[file name]])))),1) -> #VALUE!
A33: =IFERROR(LEFT(RIGHT(C33,LEN(C33)-SEARCH("@",C33)),SEARCH("/",RIGHT(C33,LEN(C33)-SEARCH("@",C33)-1))),"") | B33: =LEFT(RIGHT(RIGHT(Tableau4[[#This Row],[file name]],LEN(Tableau4[[#This Row],[file name]])-SEARCH("@",Tableau4[[#This Row],[file name]])),LEN(RIGHT(Tableau4[[#This Row],[file name]],LEN(Tableau4[[#This Row],[file name]])-SEARCH("@",Tableau4[[#This Row],[file name]])))-SEARCH("/",RIGHT(Tableau4[[#This Row],[file name]],LEN(Tableau4[[#This Row],[file name]])-SEARCH("@",Tableau4[[#This Row],[file name]])))),1) -> #VALUE!
A34: =IFERROR(LEFT(RIGHT(C34,LEN(C34)-SEARCH("@",C34)),SEARCH("/",RIGHT(C34,LEN(C34)-SEARCH("@",C34)-1))),"") | B34: =LEFT(RIGHT(RIGHT(Tableau4[[#This Row],[file name]],LEN(Tableau4[[#This Row],[file name]])-SEARCH("@",Tableau4[[#This Row],[file name]])),LEN(RIGHT(Tableau4[[#This Row],[file name]],LEN(Tableau4[[#This Row],[file name]])-SEARCH("@",Tableau4[[#This Row],[file name]])))-SEARCH("/",RIGHT(Tableau4[[#This Row],[file name]],LEN(Tableau4[[#This Row],[file name]])-SEARCH("@",Tableau4[[#This Row],[file name]])))),1) -> #VALUE! | C34: file name | D34: total area | E34: mean intensity | G34: total fluorescence
A35: =IFERROR(LEFT(RIGHT(C35,LEN(C35)-SEARCH("@",C35)),SEARCH("/",RIGHT(C35,LEN(C35)-SEARCH("@",C35)-1))),"") -> 02 EE2 34 | B35: =LEFT(RIGHT(RIGHT(Tableau4[[#This Row],[file name]],LEN(Tableau4[[#This Row],[file name]])-SEARCH("@",Tableau4[[#This Row],[file name]])),LEN(RIGHT(Tableau4[[#This Row],[file name]],LEN(Tableau4[[#This Row],[file name]])-SEARCH("@",Tableau4[[#This Row],[file name]])))-SEARCH("/",RIGHT(Tableau4[[#This Row],[file name]],LEN(Tableau4[[#This Row],[file name]])-SEARCH("@",Tableau4[[#This Row],[file name]])))),1) -> A | C35: \\192.168.24.208\images\R&D\2-Test oestrogénique\OECD and AOPs\REACTIV oecd interlaboratory validation\WF data\Repeats for invalid experiments - EBO\2022-EBO-ARABINOSE R4\plaque 1/@02 EE2 34/A2_01.tif | D35: 282.7988 | E35: 63.2308 | G35: 17882
A36: =IFERROR(LEFT(RIGHT(C36,LEN(C36)-SEARCH("@",C36)),SEARCH("/",RIGHT(C36,LEN(C36)-SEARCH("@",C36)-1))),"") -> 02 EE2 34 | B36: =LEFT(RIGHT(RIGHT(Tableau4[[#This Row],[file name]],LEN(Tableau4[[#This Row],[file name]])-SEARCH("@",Tableau4[[#This Row],[file name]])),LEN(RIGHT(Tableau4[[#This Row],[file name]],LEN(Tableau4[[#This Row],[file name]])-SEARCH("@",Tableau4[[#This Row],[file name]])))-SEARCH("/",RIGHT(Tableau4[[#This Row],[file name]],LEN(Tableau4[[#This Row],[file name]])-SEARCH("@",Tableau4[[#This Row],[file name]])))),1) -> A | C36: \\192.168.24.208\images\R&D\2-Test oestrogénique\OECD and AOPs\REACTIV oecd interlaboratory validation\WF data\Repeats for invalid experiments - EBO\2022-EBO-ARABINOSE R4\plaque 1/@02 EE2 34/A2_02.tif | D36: 239.2913 | E36: 62.1818 | G36: 14880
A37: =IFERROR(LEFT(RIGHT(C37,LEN(C37)-SEARCH("@",C37)),SEARCH("/",RIGHT(C37,LEN(C37)-SEARCH("@",C37)-1))),"") -> 02 EE2 34 | B37: =LEFT(RIGHT(RIGHT(Tableau4[[#This Row],[file name]],LEN(Tableau4[[#This Row],[file name]])-SEARCH("@",Tableau4[[#This Row],[file name]])),LEN(RIGHT(Tableau4[[#This Row],[file name]],LEN(Tableau4[[#This Row],[file name]])-SEARCH("@",Tableau4[[#This Row],[file name]])))-SEARCH("/",RIGHT(Tableau4[[#This Row],[file name]],LEN(Tableau4[[#This Row],[file name]])-SEARCH("@",Tableau4[[#This Row],[file name]])))),1) -> A | C37: \\192.168.24.208\images\R&D\2-Test oestrogénique\OECD and AOPs\REACTIV oecd interlaboratory validation\WF data\Repeats for invalid experiments - EBO\2022-EBO-ARABINOSE R4\plaque 1/@02 EE2 34/A2_03.tif | D37: 348.0601 | E37: 64.8125 | G37: 22559
A38: =IFERROR(LEFT(RIGHT(C38,LEN(C38)-SEARCH("@",C38)),SEARCH("/",RIGHT(C38,LEN(C38)-SEARCH("@",C38)-1))),"") -> 02 EE2 34 | B38: =LEFT(RIGHT(RIGHT(Tableau4[[#This Row],[file name]],LEN(Tableau4[[#This Row],[file name]])-SEARCH("@",Tableau4[[#This Row],[file name]])),LEN(RIGHT(Tableau4[[#This Row],[file name]],LEN(Tableau4[[#This Row],[file name]])-SEARCH("@",Tableau4[[#This Row],[file name]])))-SEARCH("/",RIGHT(Tableau4[[#This Row],[file name]],LEN(Tableau4[[#This Row],[file name]])-SEARCH("@",Tableau4[[#This Row],[file name]])))),1) -> B | C38: \\192.168.24.208\images\R&D\2-Test oestrogénique\OECD and AOPs\REACTIV oecd interlaboratory validation\WF data\Repeats for invalid experiments - EBO\2022-EBO-ARABINOSE R4\plaque 1/@02 EE2 34/B2_01.tif | D38: 9354.1147 | E38: 68.614 | G38: 641823
A39: =IFERROR(LEFT(RIGHT(C39,LEN(C39)-SEARCH("@",C39)),SEARCH("/",RIGHT(C39,LEN(C39)-SEARCH("@",C39)-1))),"") -> 02 EE2 34 | B39: =LEFT(RIGHT(RIGHT(Tableau4[[#This Row],[file name]],LEN(Tableau4[[#This Row],[file name]])-SEARCH("@",Tableau4[[#This Row],[file name]])),LEN(RIGHT(Tableau4[[#This Row],[file name]],LEN(Tableau4[[#This Row],[file name]])-SEARCH("@",Tableau4[[#This Row],[file name]])))-SEARCH("/",RIGHT(Tableau4[[#This Row],[file name]],LEN(Tableau4[[#This Row],[file name]])-SEARCH("@",Tableau4[[#This Row],[file name]])))),1) -> B | C39: \\192.168.24.208\images\R&D\2-Test oestrogénique\OECD and AOPs\REACTIV oecd interlaboratory validation\WF data\Repeats for invalid experiments - EBO\2022-EBO-ARABINOSE R4\plaque 1/@02 EE2 34/B2_02- exclu.tif
A40: =IFERROR(LEFT(RIGHT(C40,LEN(C40)-SEARCH("@",C40)),SEARCH("/",RIGHT(C40,LEN(C40)-SEARCH("@",C40)-1))),"") -> 02 EE2 34 | B40: =LEFT(RIGHT(RIGHT(Tableau4[[#This Row],[file name]],LEN(Tableau4[[#This Row],[file name]])-SEARCH("@",Tableau4[[#This Row],[file name]])),LEN(RIGHT(Tableau4[[#This Row],[file name]],LEN(Tableau4[[#This Row],[file name]])-SEARCH("@",Tableau4[[#This Row],[file name]])))-SEARCH("/",RIGHT(Tableau4[[#This Row],[file name]],LEN(Tableau4[[#This Row],[file name]])-SEARCH("@",Tableau4[[#This Row],[file name]])))),1) -> B | C40: \\192.168.24.208\images\R&D\2-Test oestrogénique\OECD and AOPs\REACTIV oecd interlaboratory validation\WF data\Repeats for invalid experiments - EBO\2022-EBO-ARABINOSE R4\plaque 1/@02 EE2 34/B2_03- exclu.tif
...

Sheet R1
A1: 3. Expérimentateur 1 : copier et coller les valeurs des intensités totales de fluorescences obtenues dans le fichier raw data lors du traitement des images.
A3: R1 | B3: Non dopé | O3: avec testo
A4: Noms des groupes | B4: ='Page de garde'!A7 -> Témoin solvant | C4: ='Page de garde'!A9 -> EE2-33.8ng/L | D4: ='Page de garde'!A10 -> EE2-50.6ng/L | E4: ='Page de garde'!A11 -> EE2-76ng/L | F4: ='Page de garde'!A12 -> EE2-114ng/L | G4: ='Page de garde'!A13 -> EE2-170.9ng/L | H4: ='Page de garde'!A14 -> EE2-488ng/L | I4: ='Page de garde'!A15 -> Arabinose-0.01mg/L | J4: ='Page de garde'!A16 -> Arabinose-0.1mg/L | K4: ='Page de garde'!A17 -> Arabinose-1mg/L | L4: ='Page de garde'!A18 -> Arabinose-10mg/L | M4: ='Page de garde'!A19 -> Arabinose-100mg/L | O4: ='Page de garde'!A36 -> Testo -30µg/L | P4: ='Page de garde'!A37 -> Testo 30µg/L + EE2 -64ng/L | Q4: ='Page de garde'!A38 -> Testo 30µg/L + FAD-10µg/L | R4: ='Page de garde'!A39 -> Arabinose-0.01mg/L + Testostérone | S4: ='Page de garde'!A40 -> Arabinose-0.1mg/L + Testostérone | T4: ='Page de garde'!A41 -> Arabinose-1mg/L + Testostérone | U4: ='Page de garde'!A42 -> Arabinose-10mg/L + Testostérone | V4: ='Page de garde'!A43 -> Arabinose-100mg/L + Testostérone
A5: Données brutes | B5: 13661.333 | C5: 18440.333 | D5: 20535.5 | F5: 909024.33 | G5: 1665191.7 | I5: 13755.667 | J5: 18675.5 | K5: 97261 | L5: 14582.333 | M5: 129130.33 | O5: 3066750.3 | P5: 4221483 | Q5: 63782 | R5: 955613.67 | S5: 1551804.3 | T5: 2392594 | U5: 2430909.7 | V5: 1534589.7
B6: 38562.333 | C6: 641823 | D6: 48641.5 | E6: 95020.5 | F6: 288629 | G6: 2163063 | H6: 7890659.7 | I6: 18084.667 | J6: 31760.5 | K6: 17381.333 | M6: 66348.667 | O6: 1708235 | P6: 5468220 | Q6: 128267.33 | R6: 2972549.3 | S6: 2715528.3 | T6: 2228672.3 | U6: 1147663 | V6: 1359609.7
B7: 19738 | C7: 16039.667 | D7: 112336.33 | E7: 110110 | F7: 958369 | G7: 2674798 | H7: 6349058.3 | I7: 17156.333 | J7: 222889 | K7: 117956 | L7: 182760.67 | M7: 146802 | Q7: 92703.5 | R7: 3929707 | S7: 3475843.7 | T7: 826766 | U7: 2392449.3 | V7: 2190320.3
B8: 66980 | D8: 270268.67 | E8: 129674.33 | F8: 3738404.7 | G8: 2429720.5 | H8: 5811754.7 | I8: 68774.5 | J8: 49431.667 | K8: 25502.667 | L8: 434140 | M8: 279231 | O8: 2630261 | P8: 5785933 | Q8: 17388.667 | R8: 2988030.7 | S8: 61077.333 | T8: 193445 | U8: 76443 | V8: 2035375.7
B9: 15315 | C9: 38815.667 | D9: 181078 | E9: 13284.333 | F9: 378218 | G9: 1476391 | H9: 4770540.3 | I9: 62955.333 | J9: 52535.333 | K9: 107213 | L9: 81772 | M9: 22319.5 | O9: 722805 | P9: 5361691.5 | Q9: 18469 | R9: 51165 | S9: 1668371.5 | T9: 139014 | U9: 131001 | V9: 3212790
B10: 97805 | C10: 13596 | D10: 58031.667 | E10: 149056.67 | F10: 844263.33 | G10: 4128920.7 | H10: 6414696.7 | I10: 70888.333 | J10: 54413.667 | K10: 100654.67 | L10: 46872 | M10: 212969.33 | O10: 1621851.3 | P10: 4713168.7 | Q10: 40897 | R10: 709379 | T10: 1273812.5 | U10: 1725500.3 | V10: 926264
B11: 24828.333 | C11: 26423.667 | D11: 17272.5 | E11: 156496.33 | F11: 234143 | G11: 2408880.3 | H11: 3195749.7 | I11: 278339.33 | J11: 452315 | K11: 96470.333 | L11: 45911.5 | O11: 2054946.3 | P11: 6739059.7 | Q11: 80967.5 | R11: 20960 | S11: 718461.33 | T11: 1414668.5 | U11: 1486963.3 | V11: 112387.33
B12: 54551 | C12: 11333.667 | E12: 128586.67 | F12: 1812421.3 | G12: 1650798 | H12: 5537578 | I12: 49729 | J12: 45792 | K12: 20571.667 | L12: 184645.67 | M12: 167047 | O12: 1524024.3 | P12: 4751984.7 | Q12: 302921 | R12: 509893.67 | S12: 2403608.7 | T12: 856782.5 | U12: 244055 | V12: 15634
O13: 180610.5
O14: 2857972
O15: 3857789.3
O16: 1958316.3
O17: 2014934.7
O18: 548564.33
O19: 379465.33
O20: 2613293
A22: =A4 -> Noms des groupes | B22: =B4 -> Témoin solvant | C22: =C4 -> EE2-33.8ng/L | D22: =D4 -> EE2-50.6ng/L | E22: =E4 -> EE2-76ng/L | F22: =F4 -> EE2-114ng/L | G22: =G4 -> EE2-170.9ng/L | H22: =H4 -> EE2-488ng/L | ... M22: =M4 -> Arabinose-100mg/L | N22: Nom des groupes | O22: =O4 -> Testo -30µg/L | P22: =P4 -> Testo 30µg/L + EE2 -64ng/L | Q22: =Q4 -> Testo 30µg/L + FAD-10µg/L | R22: =R4 -> Arabinose-0.01mg/L + Testostérone | S22: =S4 -> Arabinose-0.1mg/L + Testostérone | T22: =T4 -> Arabinose-1mg/L + Testostérone | U22: =U4 -> Arabinose-10mg/L + Testostérone | V22: =V4 -> Arabinose-100mg/L + Testostérone
A23: mean | B23: =AVERAGE(B5:B20) -> 41430.125 | C23: =AVERAGE(C5:C20) -> 109496 | D23: =AVERAGE(D5:D20) -> 101166.31 | E23: =AVERAGE(E5:E20) -> 111746.98 | F23: =AVERAGE(F5:F20) -> 1145434.1 | G23: =AVERAGE(G5:G20) -> 2324720.4 | H23: =AVERAGE(H5:H20) -> 5710005.3 | I23: =AVERAGE(I5:I20) -> 72460.396 | ... M23: =AVERAGE(M5:M20) -> 146263.98 | N23: mean | O23: =AVERAGE(O5:O20) -> 1849321.3 | P23: =AVERAGE(P5:P20) -> 5291648.6 | Q23: =AVERAGE(Q5:Q20) -> 93174.5 | R23: =AVERAGE(R5:R20) -> 1517162.3 | S23: =AVERAGE(S5:S20) -> 1799242.2 | T23: =AVERAGE(T5:T20) -> 1165719.4 | U23: =AVERAGE(U5:U20) -> 1204373.1 | V23: =AVERAGE(V5:V20) -> 1423371.3
A24: SD | B24: =STDEV(B5:B20) -> 29786.328 | C24: =STDEV(C5:C20) -> 234920.78 | D24: =STDEV(D5:D20) -> 94220.669 | E24: =STDEV(E5:E20) -> 48264.601 | F24: =STDEV(F5:F20) -> 1165157.4 | G24: =STDEV(G5:G20) -> 847748.81 | H24: =STDEV(H5:H20) -> 1466537.4 | I24: =STDEV(I5:I20) -> 86578.421 | ... M24: =STDEV(M5:M20) -> 86220.946 | N24: SD | O24: =STDEV(O5:O20) -> 1065434.5 | P24: =STDEV(P5:P20) -> 831317.22 | Q24: =STDEV(Q5:Q20) -> 92809.786 | R24: =STDEV(R5:R20) -> 1534004.4 | S24: =STDEV(S5:S20) -> 1174981.5 | T24: =STDEV(T5:T20) -> 838239.9 | U24: =STDEV(U5:U20) -> 972267.51 | V24: =STDEV(V5:V20) -> 1077612
B26: Non dopé | O26: avec testo
A27: Noms des groupes | B27: =B4 -> Témoin solvant | C27: =C4 -> EE2-33.8ng/L | D27: =D4 -> EE2-50.6ng/L | E27: =E4 -> EE2-76ng/L | F27: =F4 -> EE2-114ng/L | G27: =G4 -> EE2-170.9ng/L | H27: =H4 -> EE2-488ng/L | I27: =I4 -> Arabinose-0.01mg/L | ... M27: =M4 -> Arabinose-100mg/L | O27: =O4 -> Testo -30µg/L | P27: =P4 -> Testo 30µg/L + EE2 -64ng/L | Q27: =Q4 -> Testo 30µg/L + FAD-10µg/L | R27: =R4 -> Arabinose-0.01mg/L + Testostérone | S27: =S4 -> Arabinose-0.1mg/L + Testostérone | T27: =T4 -> Arabinose-1mg/L + Testostérone | U27: =U4 -> Arabinose-10mg/L + Testostérone | V27: =V4 -> Arabinose-100mg/L + Testostérone
A28: Données normalisées sur la moyenne du groupe "Testo" | B28: =IF(B5="","",(B5/$O$23)) -> 0.0073872148 | C28: =IF(C5="","",(C5/$O$23)) -> 0.0099714061 | D28: =IF(D5="","",(D5/$O$23)) -> 0.011104344 | E28: =IF(E5="","",(E5/$O$23)) | F28: =IF(F5="","",(F5/$O$23)) -> 0.49154485 | G28: =IF(G5="","",(G5/$O$23)) -> 0.90043396 | H28: =IF(H5="","",(H5/$O$23)) | I28: =IF(I5="","",(I5/$O$23)) -> 0.0074382245 | ... M28: =IF(M5="","",(M5/$O$23)) -> 0.069825798 | O28: =IF(O5="","",(O5/$O$23)) -> 1.6583113 | P28: =IF(P5="","",(P5/$O$23)) -> 2.2827202 | Q28: =IF(Q5="","",(Q5/$O$23)) -> 0.034489411 | R28: =IF(R5="","",(R5/$O$23)) -> 0.51673751 | S28: =IF(S5="","",(S5/$O$23)) -> 0.83912102 | T28: =IF(T5="","",(T5/$O$23)) -> 1.2937687 | U28: =IF(U5="","",(U5/$O$23)) -> 1.3144875 | V28: =IF(V5="","",(V5/$O$23)) -> 0.82981238
B29: =IF(B6="","",(B6/$O$23)) -> 0.020852155 | C29: =IF(C6="","",(C6/$O$23)) -> 0.34705868 | D29: =IF(D6="","",(D6/$O$23)) -> 0.026302353 | E29: =IF(E6="","",(E6/$O$23)) -> 0.051381284 | F29: =IF(F6="","",(F6/$O$23)) -> 0.15607294 | G29: =IF(G6="","",(G6/$O$23)) -> 1.1696524 | H29: =IF(H6="","",(H6/$O$23)) -> 4.2667869 | I29: =IF(I6="","",(I6/$O$23)) -> 0.0097790833 | ... M29: =IF(M6="","",(M6/$O$23)) -> 0.035877307 | O29: =IF(O6="","",(O6/$O$23)) -> 0.92370917 | P29: =IF(P6="","",(P6/$O$23)) -> 2.9568794 | Q29: =IF(Q6="","",(Q6/$O$23)) -> 0.069359141 | R29: =IF(R6="","",(R6/$O$23)) -> 1.6073732 | S29: =IF(S6="","",(S6/$O$23)) -> 1.4683919 | T29: =IF(T6="","",(T6/$O$23)) -> 1.2051299 | U29: =IF(U6="","",(U6/$O$23)) -> 0.62058606 | V29: =IF(V6="","",(V6/$O$23)) -> 0.73519388
