Workbook

Sheet Page de garde
A1: 1. Expérimentateur 1 : copier et coller le n° de prestation et renseigner la date de réalisation de chaque réplica ainsi que le visa de l'expérimentateur.
A2: R1 | B2: Numéro d'expérience : | E2: Date de réalisation :
A3: R2 | B3: Numéro d'expérience : | E3: Date de réalisation :
A4: R3 | B4: Numéro d'expérience : | E4: Date de réalisation :
A5: 2. Expérimentateur 1 : copier et coller la dilution appliquée et le nom donné pour chaque des échantillons par le client. Conserver la mise en forme de l'exemple en italique. Ne pas remplir la colonne "nom sur graphique".
A6: Nom sur le graphique | B6: Code WF | C6: Concentration | D6: Unité | E6: Nom de l'échantillon donné par le client | F6: Dopage (+Testostérone / + EE2, ….)
A7: =IF(ISBLANK(liste_groupe[[#This Row],[Code WF]])," ",IF(ISBLANK(liste_groupe[[#This Row],[Unité]]),CONCATENATE(liste_groupe[[#This Row],[Nom de l''échantillon donné par le client]],liste_groupe[[#This Row],[Dopage (+Testostérone / + EE2, ….)]]),CONCATENATE(liste_groupe[[#This Row],[Nom de l''échantillon donné par le client]],"-",liste_groupe[[#This Row],[Concentration]],liste_groupe[[#This Row],[Unité]],liste_groupe[[#This Row],[Dopage (+Testostérone / + EE2, ….)]]))) -> Témoin solvant | B7: Témoin | E7: Témoin solvant
A8: =IF(ISBLANK(liste_groupe[[#This Row],[Code WF]])," ",IF(ISBLANK(liste_groupe[[#This Row],[Unité]]),CONCATENATE(liste_groupe[[#This Row],[Nom de l''échantillon donné par le client]],liste_groupe[[#This Row],[Dopage (+Testostérone / + EE2, ….)]]),CONCATENATE(liste_groupe[[#This Row],[Nom de l''échantillon donné par le client]],"-",liste_groupe[[#This Row],[Concentration]],liste_groupe[[#This Row],[Unité]],liste_groupe[[#This Row],[Dopage (+Testostérone / + EE2, ….)]]))) -> EE2-22,5ng/L | B8: Témoin | C8: 22.5 | D8: ng/L | E8: EE2
A9: =IF(ISBLANK(liste_groupe[[#This Row],[Code WF]])," ",IF(ISBLANK(liste_groupe[[#This Row],[Unité]]),CONCATENATE(liste_groupe[[#This Row],[Nom de l''échantillon donné par le client]],liste_groupe[[#This Row],[Dopage (+Testostérone / + EE2, ….)]]),CONCATENATE(liste_groupe[[#This Row],[Nom de l''échantillon donné par le client]],"-",liste_groupe[[#This Row],[Concentration]],liste_groupe[[#This Row],[Unité]],liste_groupe[[#This Row],[Dopage (+Testostérone / + EE2, ….)]]))) -> EE2-33,8ng/L | B9: Témoin | C9: 33.8 | D9: ng/L | E9: EE2
A10: =IF(ISBLANK(liste_groupe[[#This Row],[Code WF]])," ",IF(ISBLANK(liste_groupe[[#This Row],[Unité]]),CONCATENATE(liste_groupe[[#This Row],[Nom de l''échantillon donné par le client]],liste_groupe[[#This Row],[Dopage (+Testostérone / + EE2, ….)]]),CONCATENATE(liste_groupe[[#This Row],[Nom de l''échantillon donné par le client]],"-",liste_groupe[[#This Row],[Concentration]],liste_groupe[[#This Row],[Unité]],liste_groupe[[#This Row],[Dopage (+Testostérone / + EE2, ….)]]))) -> EE2-50,6ng/L | B10: Témoin | C10: 50.6 | D10: ng/L | E10: EE2
A11: =IF(ISBLANK(liste_groupe[[#This Row],[Code WF]])," ",IF(ISBLANK(liste_groupe[[#This Row],[Unité]]),CONCATENATE(liste_groupe[[#This Row],[Nom de l''échantillon donné par le client]],liste_groupe[[#This Row],[Dopage (+Testostérone / + EE2, ….)]]),CONCATENATE(liste_groupe[[#This Row],[Nom de l''échantillon donné par le client]],"-",liste_groupe[[#This Row],[Concentration]],liste_groupe[[#This Row],[Unité]],liste_groupe[[#This Row],[Dopage (+Testostérone / + EE2, ….)]]))) -> EE2-76ng/L | B11: Témoin | C11: 76 | D11: ng/L | E11: EE2
A12: =IF(ISBLANK(liste_groupe[[#This Row],[Code WF]])," ",IF(ISBLANK(liste_groupe[[#This Row],[Unité]]),CONCATENATE(liste_groupe[[#This Row],[Nom de l''échantillon donné par le client]],liste_groupe[[#This Row],[Dopage (+Testostérone / + EE2, ….)]]),CONCATENATE(liste_groupe[[#This Row],[Nom de l''échantillon donné par le client]],"-",liste_groupe[[#This Row],[Concentration]],liste_groupe[[#This Row],[Unité]],liste_groupe[[#This Row],[Dopage (+Testostérone / + EE2, ….)]]))) -> EE2-114ng/L | B12: Témoin | C12: 114 | D12: ng/L | E12: EE2
A13: =IF(ISBLANK(liste_groupe[[#This Row],[Code WF]])," ",IF(ISBLANK(liste_groupe[[#This Row],[Unité]]),CONCATENATE(liste_groupe[[#This Row],[Nom de l''échantillon donné par le client]],liste_groupe[[#This Row],[Dopage (+Testostérone / + EE2, ….)]]),CONCATENATE(liste_groupe[[#This Row],[Nom de l''échantillon donné par le client]],"-",liste_groupe[[#This Row],[Concentration]],liste_groupe[[#This Row],[Unité]],liste_groupe[[#This Row],[Dopage (+Testostérone / + EE2, ….)]]))) -> EE2-170,9ng/L | B13: Témoin | C13: 170.9 | D13: ng/L | E13: EE2
A14: =IF(ISBLANK(liste_groupe[[#This Row],[Code WF]])," ",IF(ISBLANK(liste_groupe[[#This Row],[Unité]]),CONCATENATE(liste_groupe[[#This Row],[Nom de l''échantillon donné par le client]],liste_groupe[[#This Row],[Dopage (+Testostérone / + EE2, ….)]]),CONCATENATE(liste_groupe[[#This Row],[Nom de l''échantillon donné par le client]],"-",liste_groupe[[#This Row],[Concentration]],liste_groupe[[#This Row],[Unité]],liste_groupe[[#This Row],[Dopage (+Testostérone / + EE2, ….)]]))) -> EE2-488ng/L | B14: Témoin | C14: 488 | D14: ng/L | E14: EE2
A15: Anastrozole 0,032 ug/L | C15: 0.032 | D15: ug/L
A16: Anastrozole 0,16 ug/L | C16: 0.16 | D16: ug/L
A17: Anastrozole 0,8 ug/L | C17: 0.8 | D17: ug/L
A18: Anastrozole 4 ug/L | C18: 4 | D18: ug/L
A19: Anastrozole 20 ug/L | C19: 20 | D19: ug/L
A20: =IF(ISBLANK(liste_groupe[[#This Row],[Code WF]])," ",IF(ISBLANK(liste_groupe[[#This Row],[Unité]]),CONCATENATE(liste_groupe[[#This Row],[Nom de l''échantillon donné par le client]],liste_groupe[[#This Row],[Dopage (+Testostérone / + EE2, ….)]]),CONCATENATE(liste_groupe[[#This Row],[Nom de l''échantillon donné par le client]],"-",liste_groupe[[#This Row],[Concentration]],liste_groupe[[#This Row],[Unité]],liste_groupe[[#This Row],[Dopage (+Testostérone / + EE2, ….)]])))
A21: =IF(ISBLANK(liste_groupe[[#This Row],[Code WF]])," ",IF(ISBLANK(liste_groupe[[#This Row],[Unité]]),CONCATENATE(liste_groupe[[#This Row],[Nom de l''échantillon donné par le client]],liste_groupe[[#This Row],[Dopage (+Testostérone / + EE2, ….)]]),CONCATENATE(liste_groupe[[#This Row],[Nom de l''échantillon donné par le client]],"-",liste_groupe[[#This Row],[Concentration]],liste_groupe[[#This Row],[Unité]],liste_groupe[[#This Row],[Dopage (+Testostérone / + EE2, ….)]])))
A22: =IF(ISBLANK(liste_groupe[[#This Row],[Code WF]])," ",IF(ISBLANK(liste_groupe[[#This Row],[Unité]]),CONCATENATE(liste_groupe[[#This Row],[Nom de l''échantillon donné par le client]],liste_groupe[[#This Row],[Dopage (+Testostérone / + EE2, ….)]]),CONCATENATE(liste_groupe[[#This Row],[Nom de l''échantillon donné par le client]],"-",liste_groupe[[#This Row],[Concentration]],liste_groupe[[#This Row],[Unité]],liste_groupe[[#This Row],[Dopage (+Testostérone / + EE2, ….)]])))
A23: =IF(ISBLANK(liste_groupe[[#This Row],[Code WF]])," ",IF(ISBLANK(liste_groupe[[#This Row],[Unité]]),CONCATENATE(liste_groupe[[#This Row],[Nom de l''échantillon donné par le client]],liste_groupe[[#This Row],[Dopage (+Testostérone / + EE2, ….)]]),CONCATENATE(liste_groupe[[#This Row],[Nom de l''échantillon donné par le client]],"-",liste_groupe[[#This Row],[Concentration]],liste_groupe[[#This Row],[Unité]],liste_groupe[[#This Row],[Dopage (+Testostérone / + EE2, ….)]])))
A24: =IF(ISBLANK(liste_groupe[[#This Row],[Code WF]])," ",IF(ISBLANK(liste_groupe[[#This Row],[Unité]]),CONCATENATE(liste_groupe[[#This Row],[Nom de l''échantillon donné par le client]],liste_groupe[[#This Row],[Dopage (+Testostérone / + EE2, ….)]]),CONCATENATE(liste_groupe[[#This Row],[Nom de l''échantillon donné par le client]],"-",liste_groupe[[#This Row],[Concentration]],liste_groupe[[#This Row],[Unité]],liste_groupe[[#This Row],[Dopage (+Testostérone / + EE2, ….)]])))
A25: =IF(ISBLANK(liste_groupe[[#This Row],[Code WF]])," ",IF(ISBLANK(liste_groupe[[#This Row],[Unité]]),CONCATENATE(liste_groupe[[#This Row],[Nom de l''échantillon donné par le client]],liste_groupe[[#This Row],[Dopage (+Testostérone / + EE2, ….)]]),CONCATENATE(liste_groupe[[#This Row],[Nom de l''échantillon donné par le client]],"-",liste_groupe[[#This Row],[Concentration]],liste_groupe[[#This Row],[Unité]],liste_groupe[[#This Row],[Dopage (+Testostérone / + EE2, ….)]])))
A26: =IF(ISBLANK(liste_groupe[[#This Row],[Code WF]])," ",IF(ISBLANK(liste_groupe[[#This Row],[Unité]]),CONCATENATE(liste_groupe[[#This Row],[Nom de l''échantillon donné par le client]],liste_groupe[[#This Row],[Dopage (+Testostérone / + EE2, ….)]]),CONCATENATE(liste_groupe[[#This Row],[Nom de l''échantillon donné par le client]],"-",liste_groupe[[#This Row],[Concentration]],liste_groupe[[#This Row],[Unité]],liste_groupe[[#This Row],[Dopage (+Testostérone / + EE2, ….)]])))
A27: =IF(ISBLANK(liste_groupe[[#This Row],[Code WF]])," ",IF(ISBLANK(liste_groupe[[#This Row],[Unité]]),CONCATENATE(liste_groupe[[#This Row],[Nom de l''échantillon donné par le client]],liste_groupe[[#This Row],[Dopage (+Testostérone / + EE2, ….)]]),CONCATENATE(liste_groupe[[#This Row],[Nom de l''échantillon donné par le client]],"-",liste_groupe[[#This Row],[Concentration]],liste_groupe[[#This Row],[Unité]],liste_groupe[[#This Row],[Dopage (+Testostérone / + EE2, ….)]])))
A28: =IF(ISBLANK(liste_groupe[[#This Row],[Code WF]])," ",IF(ISBLANK(liste_groupe[[#This Row],[Unité]]),CONCATENATE(liste_groupe[[#This Row],[Nom de l''échantillon donné par le client]],liste_groupe[[#This Row],[Dopage (+Testostérone / + EE2, ….)]]),CONCATENATE(liste_groupe[[#This Row],[Nom de l''échantillon donné par le client]],"-",liste_groupe[[#This Row],[Concentration]],liste_groupe[[#This Row],[Unité]],liste_groupe[[#This Row],[Dopage (+Testostérone / + EE2, ….)]])))
A29: =IF(ISBLANK(liste_groupe[[#This Row],[Code WF]])," ",IF(ISBLANK(liste_groupe[[#This Row],[Unité]]),CONCATENATE(liste_groupe[[#This Row],[Nom de l''échantillon donné par le client]],liste_groupe[[#This Row],[Dopage (+Testostérone / + EE2, ….)]]),CONCATENATE(liste_groupe[[#This Row],[Nom de l''échantillon donné par le client]],"-",liste_groupe[[#This Row],[Concentration]],liste_groupe[[#This Row],[Unité]],liste_groupe[[#This Row],[Dopage (+Testostérone / + EE2, ….)]])))
A30: =IF(ISBLANK(liste_groupe[[#This Row],[Code WF]])," ",IF(ISBLANK(liste_groupe[[#This Row],[Unité]]),CONCATENATE(liste_groupe[[#This Row],[Nom de l''échantillon donné par le client]],liste_groupe[[#This Row],[Dopage (+Testostérone / + EE2, ….)]]),CONCATENATE(liste_groupe[[#This Row],[Nom de l''échantillon donné par le client]],"-",liste_groupe[[#This Row],[Concentration]],liste_groupe[[#This Row],[Unité]],liste_groupe[[#This Row],[Dopage (+Testostérone / + EE2, ….)]])))
A31: =IF(ISBLANK(liste_groupe[[#This Row],[Code WF]])," ",IF(ISBLANK(liste_groupe[[#This Row],[Unité]]),CONCATENATE(liste_groupe[[#This Row],[Nom de l''échantillon donné par le client]],liste_groupe[[#This Row],[Dopage (+Testostérone / + EE2, ….)]]),CONCATENATE(liste_groupe[[#This Row],[Nom de l''échantillon donné par le client]],"-",liste_groupe[[#This Row],[Concentration]],liste_groupe[[#This Row],[Unité]],liste_groupe[[#This Row],[Dopage (+Testostérone / + EE2, ….)]])))
... A35: =IF(ISBLANK(liste_groupe[[#This Row],[Code WF]])," ",IF(ISBLANK(liste_groupe[[#This Row],[Unité]]),CONCATENATE(liste_groupe[[#This Row],[Nom de l''échantillon donné par le client]],liste_groupe[[#This Row],[Dopage (+Testostérone / + EE2, ….)]]),CONCATENATE(liste_groupe[[#This Row],[Nom de l''échantillon donné par le client]],"-",liste_groupe[[#This Row],[Concentration]],liste_groupe[[#This Row],[Unité]],liste_groupe[[#This Row],[Dopage (+Testostérone / + EE2, ….)]])))
A36: =IF(ISBLANK(liste_groupe[[#This Row],[Code WF]])," ",IF(ISBLANK(liste_groupe[[#This Row],[Unité]]),CONCATENATE(liste_groupe[[#This Row],[Nom de l''échantillon donné par le client]],liste_groupe[[#This Row],[Dopage (+Testostérone / + EE2, ….)]]),CONCATENATE(liste_groupe[[#This Row],[Nom de l''échantillon donné par le client]],"-",liste_groupe[[#This Row],[Concentration]],liste_groupe[[#This Row],[Unité]],liste_groupe[[#This Row],[Dopage (+Testostérone / + EE2, ….)]]))) -> Testo -30µg/L | B36: Témoin | C36: 30 | D36: µg/L | E36: Testo
A37: =IF(ISBLANK(liste_groupe[[#This Row],[Code WF]])," ",IF(ISBLANK(liste_groupe[[#This Row],[Unité]]),CONCATENATE(liste_groupe[[#This Row],[Nom de l''échantillon donné par le client]],liste_groupe[[#This Row],[Dopage (+Testostérone / + EE2, ….)]]),CONCATENATE(liste_groupe[[#This Row],[Nom de l''échantillon donné par le client]],"-",liste_groupe[[#This Row],[Concentration]],liste_groupe[[#This Row],[Unité]],liste_groupe[[#This Row],[Dopage (+Testostérone / + EE2, ….)]]))) -> Testo 30µg/L + EE2 -64ng/L | B37: Témoin | C37: 64 | D37: ng/L | E37: Testo 30µg/L + EE2
A38: =IF(ISBLANK(liste_groupe[[#This Row],[Code WF]])," ",IF(ISBLANK(liste_groupe[[#This Row],[Unité]]),CONCATENATE(liste_groupe[[#This Row],[Nom de l''échantillon donné par le client]],liste_groupe[[#This Row],[Dopage (+Testostérone / + EE2, ….)]]),CONCATENATE(liste_groupe[[#This Row],[Nom de l''échantillon donné par le client]],"-",liste_groupe[[#This Row],[Concentration]],liste_groupe[[#This Row],[Unité]],liste_groupe[[#This Row],[Dopage (+Testostérone / + EE2, ….)]]))) -> Testo 30µg/L + FAD-10mg/L | B38: Témoin | C38: 10 | D38: mg/L | E38: Testo 30µg/L + FAD
A39: =IF(ISBLANK(liste_groupe[[#This Row],[Code WF]])," ",IF(ISBLANK(liste_groupe[[#This Row],[Unité]]),CONCATENATE(liste_groupe[[#This Row],[Nom de l''échantillon donné par le client]],liste_groupe[[#This Row],[Dopage (+Testostérone / + EE2, ….)]]),CONCATENATE(liste_groupe[[#This Row],[Nom de l''échantillon donné par le client]],"-",liste_groupe[[#This Row],[Concentration]],liste_groupe[[#This Row],[Unité]],liste_groupe[[#This Row],[Dopage (+Testostérone / + EE2, ….)]]))) -> Anastrozole-0,032ug/L + Testostérone | B39: =B15 -> 0 | C39: =C15 -> 0.032 | D39: =D15 -> ug/L | E39: Anastrozole | F39: + Testostérone
A40: =IF(ISBLANK(liste_groupe[[#This Row],[Code WF]])," ",IF(ISBLANK(liste_groupe[[#This Row],[Unité]]),CONCATENATE(liste_groupe[[#This Row],[Nom de l''échantillon donné par le client]],liste_groupe[[#This Row],[Dopage (+Testostérone / + EE2, ….)]]),CONCATENATE(liste_groupe[[#This Row],[Nom de l''échantillon donné par le client]],"-",liste_groupe[[#This Row],[Concentration]],liste_groupe[[#This Row],[Unité]],liste_groupe[[#This Row],[Dopage (+Testostérone / + EE2, ….)]]))) -> Anastrozole-0,16ug/L + Testostérone | B40: =B16 -> 0 | C40: =C16 -> 0.16 | D40: =D16 -> ug/L | E40: Anastrozole | F40: + Testostérone
A41: =IF(ISBLANK(liste_groupe[[#This Row],[Code WF]])," ",IF(ISBLANK(liste_groupe[[#This Row],[Unité]]),CONCATENATE(liste_groupe[[#This Row],[Nom de l''échantillon donné par le client]],liste_groupe[[#This Row],[Dopage (+Testostérone / + EE2, ….)]]),CONCATENATE(liste_groupe[[#This Row],[Nom de l''échantillon donné par le client]],"-",liste_groupe[[#This Row],[Concentration]],liste_groupe[[#This Row],[Unité]],liste_groupe[[#This Row],[Dopage (+Testostérone / + EE2, ….)]]))) -> Anastrozole-0,8ug/L + Testostérone | B41: =B17 -> 0 | C41: =C17 -> 0.8 | D41: =D17 -> ug/L | E41: Anastrozole | F41: + Testostérone
A42: =IF(ISBLANK(liste_groupe[[#This Row],[Code WF]])," ",IF(ISBLANK(liste_groupe[[#This Row],[Unité]]),CONCATENATE(liste_groupe[[#This Row],[Nom de l''échantillon donné par le client]],liste_groupe[[#This Row],[Dopage (+Testostérone / + EE2, ….)]]),CONCATENATE(liste_groupe[[#This Row],[Nom de l''échantillon donné par le client]],"-",liste_groupe[[#This Row],[Concentration]],liste_groupe[[#This Row],[Unité]],liste_groupe[[#This Row],[Dopage (+Testostérone / + EE2, ….)]]))) -> Anastrozole-4ug/L + Testostérone | B42: =B18 -> 0 | C42: =C18 -> 4 | D42: =D18 -> ug/L | E42: Anastrozole | F42: + Testostérone
A43: =IF(ISBLANK(liste_groupe[[#This Row],[Code WF]])," ",IF(ISBLANK(liste_groupe[[#This Row],[Unité]]),CONCATENATE(liste_groupe[[#This Row],[Nom de l''échantillon donné par le client]],liste_groupe[[#This Row],[Dopage (+Testostérone / + EE2, ….)]]),CONCATENATE(liste_groupe[[#This Row],[Nom de l''échantillon donné par le client]],"-",liste_groupe[[#This Row],[Concentration]],liste_groupe[[#This Row],[Unité]],liste_groupe[[#This Row],[Dopage (+Testostérone / + EE2, ….)]]))) -> Anastrozole-20ug/L + Testostérone | B43: =B19 -> 0 | C43: =C19 -> 20 | D43: =D19 -> ug/L | E43: Anastrozole | F43: + Testostérone
...

Sheet Feuil1
A1: Nom groupe | B1: N° de valeur | C1: file name | D1: total area | E1: mean intensity | G1: total fluorescence | I1: nbre de larves
A2: 01 EE2 0 | B2: A | C2: C:\Users\Olympus\Desktop\20190122\plaque1/@01 EE2 0/A1_1.tif | D2: 4931.616 | E2: 73.0526 | G2: 360268
A3: 01 EE2 0 | B3: A | C3: C:\Users\Olympus\Desktop\20190122\plaque1/@01 EE2 0/A1_2.tif | D3: 5234.4345 | E3: 71.1281 | G3: 372315
A4: 01 EE2 0 | B4: A | C4: C:\Users\Olympus\Desktop\20190122\plaque1/@01 EE2 0/A1_3.tif | D4: 3547.3027 | E4: 66.9878 | G4: 237626
A5: 01 EE2 0 | B5: A | C5: C:\Users\Olympus\Desktop\20190122\plaque3/@01 EE2 0/A1_3.tif | D5: 21456.8555 | E5: 67.0655 | G5: 1439015
A6: 01 EE2 0 | B6: A | C6: C:\Users\Olympus\Desktop\20190122\plaque3/@01 EE2 0/A1_2.tif | D6: 21586.6348 | E6: 66.4108 | G6: 1433586
A7: 01 EE2 0 | B7: A | C7: C:\Users\Olympus\Desktop\20190122\plaque3/@01 EE2 0/A1_1.tif | D7: 15984.4921 | E7: 69.7767 | G7: 1115346

Sheet Raw data R1
A1: Nom groupe | B1: N° de valeur | C1: file name | D1: total area | E1: mean intensity | G1: total fluorescence | I1: nbre de larves | J1: Colonne1 | L1: (Tous)
A2: =IFERROR(LEFT(RIGHT(C2,LEN(C2)-SEARCH("@",C2)),SEARCH("/",RIGHT(C2,LEN(C2)-SEARCH("@",C2)-1))),"") -> 01 ts | B2: =LEFT(RIGHT(RIGHT(Tableau4[[#This Row],[file name]],LEN(Tableau4[[#This Row],[file name]])-SEARCH("@",Tableau4[[#This Row],[file name]])),LEN(RIGHT(Tableau4[[#This Row],[file name]],LEN(Tableau4[[#This Row],[file name]])-SEARCH("@",Tableau4[[#This Row],[file name]])))-SEARCH("/",RIGHT(Tableau4[[#This Row],[file name]],LEN(Tableau4[[#This Row],[file name]])-SEARCH("@",Tableau4[[#This Row],[file name]])))),1) -> A | C2: \\192.168.24.208\images\R&D\2-Test oestrogénique\OECD and AOPs\REACTIV oecd interlaboratory validation\Results WF\Résultats CBA\2021-CHG-CBA-Anastrozole\plaque 1/@01 ts/A1_01.tif | D2: 6765.4178 | E2: 69.3601 | G2: 469250 | K2: Filtre lignes : Enlever (vide) et Néant | L2: Filtre colonnes : Enlever (vide) et " "
A3: =IFERROR(LEFT(RIGHT(C3,LEN(C3)-SEARCH("@",C3)),SEARCH("/",RIGHT(C3,LEN(C3)-SEARCH("@",C3)-1))),"") -> 01 ts | B3: =LEFT(RIGHT(RIGHT(Tableau4[[#This Row],[file name]],LEN(Tableau4[[#This Row],[file name]])-SEARCH("@",Tableau4[[#This Row],[file name]])),LEN(RIGHT(Tableau4[[#This Row],[file name]],LEN(Tableau4[[#This Row],[file name]])-SEARCH("@",Tableau4[[#This Row],[file name]])))-SEARCH("/",RIGHT(Tableau4[[#This Row],[file name]],LEN(Tableau4[[#This Row],[file name]])-SEARCH("@",Tableau4[[#This Row],[file name]])))),1) -> A | C3: \\192.168.24.208\images\R&D\2-Test oestrogénique\OECD and AOPs\REACTIV oecd interlaboratory validation\Results WF\Résultats CBA\2021-CHG-CBA-Anastrozole\plaque 1/@01 ts/A1_02.tif | D3: 5590.715 | E3: 67.537 | G3: 377580 | K3: Moyenne de total fluorescence | L3: Étiquettes de colonnes
A4: =IFERROR(LEFT(RIGHT(C4,LEN(C4)-SEARCH("@",C4)),SEARCH("/",RIGHT(C4,LEN(C4)-SEARCH("@",C4)-1))),"") -> 01 ts | B4: =LEFT(RIGHT(RIGHT(Tableau4[[#This Row],[file name]],LEN(Tableau4[[#This Row],[file name]])-SEARCH("@",Tableau4[[#This Row],[file name]])),LEN(RIGHT(Tableau4[[#This Row],[file name]],LEN(Tableau4[[#This Row],[file name]])-SEARCH("@",Tableau4[[#This Row],[file name]])))-SEARCH("/",RIGHT(Tableau4[[#This Row],[file name]],LEN(Tableau4[[#This Row],[file name]])-SEARCH("@",Tableau4[[#This Row],[file name]])))),1) -> A | C4: \\192.168.24.208\images\R&D\2-Test oestrogénique\OECD and AOPs\REACTIV oecd interlaboratory validation\Results WF\Résultats CBA\2021-CHG-CBA-Anastrozole\plaque 1/@01 ts/A1_03.tif | D4: 2392.9131 | E4: 64.7545 | G4: 154952 | K4: Étiquettes de lignes | L4: 01 ts | M4: 02 ee2 33 | N4: 03 ee2 50 | O4: 04 ee2 76 | P4: 05 ee2 114 | Q4: 06 ee2 170 | R4: 07 ee2 488 | S4: 08 Anastrozole 0.032 | T4: 09 Anastrozole 0.16 | U4: 10 Anastrozole 0.8 | V4: 11 Anastrozole 4 | W4: 12 Anastrozole 20 | X4: 01 TESTO | Y4: 02 TESTO | Z4: 03 TESTO + EE2 | AA4: 04 TESTO + FAD | AB4: 05 Anastrozole 0.032 | AC4: 06Anastrozole 0.16 | AD4: 07 Anastrozole 0.8 | AE4: 08 Anastrozole 4 | AF4: 09 Anastrozole 20
A5: =IFERROR(LEFT(RIGHT(C5,LEN(C5)-SEARCH("@",C5)),SEARCH("/",RIGHT(C5,LEN(C5)-SEARCH("@",C5)-1))),"") -> 01 ts | B5: =LEFT(RIGHT(RIGHT(Tableau4[[#This Row],[file name]],LEN(Tableau4[[#This Row],[file name]])-SEARCH("@",Tableau4[[#This Row],[file name]])),LEN(RIGHT(Tableau4[[#This Row],[file name]],LEN(Tableau4[[#This Row],[file name]])-SEARCH("@",Tableau4[[#This Row],[file name]])))-SEARCH("/",RIGHT(Tableau4[[#This Row],[file name]],LEN(Tableau4[[#This Row],[file name]])-SEARCH("@",Tableau4[[#This Row],[file name]])))),1) -> B | C5: \\192.168.24.208\images\R&D\2-Test oestrogénique\OECD and AOPs\REACTIV oecd interlaboratory validation\Results WF\Résultats CBA\2021-CHG-CBA-Anastrozole\plaque 1/@01 ts/B1_01.tif | D5: 2740.9731 | E5: 65.5873 | G5: 179773 | K5: A | L5: 333927.33 | M5: 154451.67 | N5: 418999 | O5: 1406641.5 | P5: 1579246.5 | Q5: 4877416.7 | R5: 7861807 | S5: 376093.67 | T5: 630511 | U5: 225448.67 | V5: 116505.67 | W5: 800375 | X5: 2015137 | Y5: 2196259 | Z5: 2925532 | AA5: 67226.333 | AB5: 605508.67 | AC5: 78393.333 | AD5: 49352 | AE5: 715357.67 | AF5: 348603.67
A6: =IFERROR(LEFT(RIGHT(C6,LEN(C6)-SEARCH("@",C6)),SEARCH("/",RIGHT(C6,LEN(C6)-SEARCH("@",C6)-1))),"") -> 01 ts | B6: =LEFT(RIGHT(RIGHT(Tableau4[[#This Row],[file name]],LEN(Tableau4[[#This Row],[file name]])-SEARCH("@",Tableau4[[#This Row],[file name]])),LEN(RIGHT(Tableau4[[#This Row],[file name]],LEN(Tableau4[[#This Row],[file name]])-SEARCH("@",Tableau4[[#This Row],[file name]])))-SEARCH("/",RIGHT(Tableau4[[#This Row],[file name]],LEN(Tableau4[[#This Row],[file name]])-SEARCH("@",Tableau4[[#This Row],[file name]])))),1) -> B | C6: \\192.168.24.208\images\R&D\2-Test oestrogénique\OECD and AOPs\REACTIV oecd interlaboratory validation\Results WF\Résultats CBA\2021-CHG-CBA-Anastrozole\plaque 1/@01 ts/B1_02.tif | D6: 369.8138 | E6: 61.8235 | G6: 22863 | K6: B | L6: 83041.333 | M6: 65283 | N6: 325784.33 | O6: 1002195.7 | P6: 1011332 | Q6: 5322179.3 | R6: 6430729.3 | S6: 215696 | T6: 222280 | U6: 208611.33 | V6: 27953.667 | W6: 266581 | X6: 2180052.3 | Y6: 1584217.5 | Z6: 6507614.3 | AA6: 181687.33 | AB6: 1502815 | AC6: 2103124 | AD6: 344035.5 | AE6: 361525.67 | AF6: 186531.33
A7: =IFERROR(LEFT(RIGHT(C7,LEN(C7)-SEARCH("@",C7)),SEARCH("/",RIGHT(C7,LEN(C7)-SEARCH("@",C7)-1))),"") -> 01 ts | B7: =LEFT(RIGHT(RIGHT(Tableau4[[#This Row],[file name]],LEN(Tableau4[[#This Row],[file name]])-SEARCH("@",Tableau4[[#This Row],[file name]])),LEN(RIGHT(Tableau4[[#This Row],[file name]],LEN(Tableau4[[#This Row],[file name]])-SEARCH("@",Tableau4[[#This Row],[file name]])))-SEARCH("/",RIGHT(Tableau4[[#This Row],[file name]],LEN(Tableau4[[#This Row],[file name]])-SEARCH("@",Tableau4[[#This Row],[file name]])))),1) -> B | C7: \\192.168.24.208\images\R&D\2-Test oestrogénique\OECD and AOPs\REACTIV oecd interlaboratory validation\Results WF\Résultats CBA\2021-CHG-CBA-Anastrozole\plaque 1/@01 ts/B1_03.tif | D7: 739.6277 | E7: 62.8529 | G7: 46488 | K7: C | L7: 698933.67 | M7: 29969.333 | N7: 59268 | O7: 1129527.7 | P7: 166561.33 | R7: 6716704 | S7: 170593 | T7: 311651.33 | U7: 426649 | V7: 107717.33 | W7: 264982.67 | X7: 3341695.7 | Y7: 3401402.7 | Z7: 3250837.3 | AA7: 29835 | AB7: 1131949.3 | AC7: 1233133.3 | AD7: 247086.33 | AE7: 41738.333 | AF7: 195457.33
A8: =IFERROR(LEFT(RIGHT(C8,LEN(C8)-SEARCH("@",C8)),SEARCH("/",RIGHT(C8,LEN(C8)-SEARCH("@",C8)-1))),"") -> 01 ts | B8: =LEFT(RIGHT(RIGHT(Tableau4[[#This Row],[file name]],LEN(Tableau4[[#This Row],[file name]])-SEARCH("@",Tableau4[[#This Row],[file name]])),LEN(RIGHT(Tableau4[[#This Row],[file name]],LEN(Tableau4[[#This Row],[file name]])-SEARCH("@",Tableau4[[#This Row],[file name]])))-SEARCH("/",RIGHT(Tableau4[[#This Row],[file name]],LEN(Tableau4[[#This Row],[file name]])-SEARCH("@",Tableau4[[#This Row],[file name]])))),1) -> C | C8: \\192.168.24.208\images\R&D\2-Test oestrogénique\OECD and AOPs\REACTIV oecd interlaboratory validation\Results WF\Résultats CBA\2021-CHG-CBA-Anastrozole\plaque 1/@01 ts/C1_01.tif | D8: 11029.1538 | E8: 69.4536 | G8: 766015 | K8: D | L8: 653613.5 | M8: 26974.333 | N8: 84593 | O8: 807883.67 | P8: 2014213 | Q8: 2960055 | R8: 8495160.7 | S8: 116476.67 | T8: 149078.67 | U8: 164030.67 | V8: 158193.33 | W8: 226906 | X8: 1320540 | Y8: 220387 | Z8: 2818144.5 | AA8: 22370 | AB8: 1714776 | AC8: 1219551.7 | AD8: 13785 | AE8: 131595.67 | AF8: 343985
A9: =IFERROR(LEFT(RIGHT(C9,LEN(C9)-SEARCH("@",C9)),SEARCH("/",RIGHT(C9,LEN(C9)-SEARCH("@",C9)-1))),"") -> 01 ts | B9: =LEFT(RIGHT(RIGHT(Tableau4[[#This Row],[file name]],LEN(Tableau4[[#This Row],[file name]])-SEARCH("@",Tableau4[[#This Row],[file name]])),LEN(RIGHT(Tableau4[[#This Row],[file name]],LEN(Tableau4[[#This Row],[file name]])-SEARCH("@",Tableau4[[#This Row],[file name]])))-SEARCH("/",RIGHT(Tableau4[[#This Row],[file name]],LEN(Tableau4[[#This Row],[file name]])-SEARCH("@",Tableau4[[#This Row],[file name]])))),1) -> C | C9: \\192.168.24.208\images\R&D\2-Test oestrogénique\OECD and AOPs\REACTIV oecd interlaboratory validation\Results WF\Résultats CBA\2021-CHG-CBA-Anastrozole\plaque 1/@01 ts/C1_02.tif | D9: 8701.502 | E9: 67.8025 | G9: 589984 | K9: E | L9: 61911.5 | M9: 96510.5 | N9: 363316.67 | O9: 27895.667 | P9: 937985.67 | Q9: 1751547 | R9: 7859262 | S9: 521133 | T9: 34371 | U9: 151754 | V9: 190548.33 | W9: 28033.333 | X9: 3397429 | Y9: 1900615 | Z9: 2535248 | AA9: 379375 | AB9: 1478204 | AC9: 273981.33 | AD9: 41542.333 | AE9: 144988.67 | AF9: 209496
A10: =IFERROR(LEFT(RIGHT(C10,LEN(C10)-SEARCH("@",C10)),SEARCH("/",RIGHT(C10,LEN(C10)-SEARCH("@",C10)-1))),"") -> 01 ts | B10: =LEFT(RIGHT(RIGHT(Tableau4[[#This Row],[file name]],LEN(Tableau4[[#This Row],[file name]])-SEARCH("@",Tableau4[[#This Row],[file name]])),LEN(RIGHT(Tableau4[[#This Row],[file name]],LEN(Tableau4[[#This Row],[file name]])-SEARCH("@",Tableau4[[#This Row],[file name]])))-SEARCH("/",RIGHT(Tableau4[[#This Row],[file name]],LEN(Tableau4[[#This Row],[file name]])-SEARCH("@",Tableau4[[#This Row],[file name]])))),1) -> C | C10: \\192.168.24.208\images\R&D\2-Test oestrogénique\OECD and AOPs\REACTIV oecd interlaboratory validation\Results WF\Résultats CBA\2021-CHG-CBA-Anastrozole\plaque 1/@01 ts/C1_03.tif | D10: 10942.1388 | E10: 67.7018 | G10: 740802 | K10: F | L10: 22537 | M10: 932895.33 | N10: 310571.33 | O10: 115762.5 | P10: 3500810 | Q10: 4247195.7 | R10: 8062326 | S10: 286431.67 | T10: 157939.67 | U10: 26670.333 | V10: 333825.67 | W10: 340674.5 | X10: 4111818.5 | Y10: 2190052.3 | Z10: 2834275 | AA10: 29142.667 | AB10: 1368659 | AC10: 294524 | AD10: 203172.67 | AE10: 79133 | AF10: 94302.333
A11: =IFERROR(LEFT(RIGHT(C11,LEN(C11)-SEARCH("@",C11)),SEARCH("/",RIGHT(C11,LEN(C11)-SEARCH("@",C11)-1))),"") -> 01 ts | B11: =LEFT(RIGHT(RIGHT(Tableau4[[#This Row],[file name]],LEN(Tableau4[[#This Row],[file name]])-SEARCH("@",Tableau4[[#This Row],[file name]])),LEN(RIGHT(Tableau4[[#This Row],[file name]],LEN(Tableau4[[#This Row],[file name]])-SEARCH("@",Tableau4[[#This Row],[file name]])))-SEARCH("/",RIGHT(Tableau4[[#This Row],[file name]],LEN(Tableau4[[#This Row],[file name]])-SEARCH("@",Tableau4[[#This Row],[file name]])))),1) -> D | C11: \\192.168.24.208\images\R&D\2-Test oestrogénique\OECD and AOPs\REACTIV oecd interlaboratory validation\Results WF\Résultats CBA\2021-CHG-CBA-Anastrozole\plaque 1/@01 ts/D1_01.tif | D11: 10093.7423 | E11: 72.3664 | G11: 730448 | K11: G | L11: 80880.5 | M11: 29498 | N11: 31151 | O11: 250705 | P11: 2659788 | Q11: 4246412.7 | R11: 3455330.3 | S11: 211163.67 | T11: 273009.5 | U11: 255642.67 | V11: 935955.33 | W11: 91387.667 | X11: 4673816 | Y11: 18324 | Z11: 2822006 | AA11: 178801.33 | AB11: 792989.67 | AC11: 1399125.5 | AD11: 132633 | AE11: 387594 | AF11: 14901.333
A12: =IFERROR(LEFT(RIGHT(C12,LEN(C12)-SEARCH("@",C12)),SEARCH("/",RIGHT(C12,LEN(C12)-SEARCH("@",C12)-1))),"") -> 01 ts | B12: =LEFT(RIGHT(RIGHT(Tableau4[[#This Row],[file name]],LEN(Tableau4[[#This Row],[file name]])-SEARCH("@",Tableau4[[#This Row],[file name]])),LEN(RIGHT(Tableau4[[#This Row],[file name]],LEN(Tableau4[[#This Row],[file name]])-SEARCH("@",Tableau4[[#This Row],[file name]])))-SEARCH("/",RIGHT(Tableau4[[#This Row],[file name]],LEN(Tableau4[[#This Row],[file name]])-SEARCH("@",Tableau4[[#This Row],[file name]])))),1) -> D | C12: \\192.168.24.208\images\R&D\2-Test oestrogénique\OECD and AOPs\REACTIV oecd interlaboratory validation\Results WF\Résultats CBA\2021-CHG-CBA-Anastrozole\plaque 1/@01 ts/D1_02- exclu.tif | K12: H | L12: 50839 | M12: 204253.33 | N12: 260566.33 | O12: 814554.67 | P12: 1652372 | Q12: 2773049 | R12: 5030642.7 | T12: 417730.33 | U12: 325378.33 | W12: 146489.67 | X12: 4192884 | Y12: 492911.33 | Z12: 6209348.3 | AA12: 501786.33 | AB12: 588243 | AC12: 207835.33 | AD12: 170904.67 | AE12: 438099 | AF12: 560906
A13: =IFERROR(LEFT(RIGHT(C13,LEN(C13)-SEARCH("@",C13)),SEARCH("/",RIGHT(C13,LEN(C13)-SEARCH("@",C13)-1))),"") -> 01 ts | B13: =LEFT(RIGHT(RIGHT(Tableau4[[#This Row],[file name]],LEN(Tableau4[[#This Row],[file name]])-SEARCH("@",Tableau4[[#This Row],[file name]])),LEN(RIGHT(Tableau4[[#This Row],[file name]],LEN(Tableau4[[#This Row],[file name]])-SEARCH("@",Tableau4[[#This Row],[file name]])))-SEARCH("/",RIGHT(Tableau4[[#This Row],[file name]],LEN(Tableau4[[#This Row],[file name]])-SEARCH("@",Tableau4[[#This Row],[file name]])))),1) -> D | C13: \\192.168.24.208\images\R&D\2-Test oestrogénique\OECD and AOPs\REACTIV oecd interlaboratory validation\Results WF\Résultats CBA\2021-CHG-CBA-Anastrozole\plaque 1/@01 ts/D1_03.tif | D13: 8418.7032 | E13: 68.5116 | G13: 576779
A14: =IFERROR(LEFT(RIGHT(C14,LEN(C14)-SEARCH("@",C14)),SEARCH("/",RIGHT(C14,LEN(C14)-SEARCH("@",C14)-1))),"") -> 01 ts | B14: =LEFT(RIGHT(RIGHT(Tableau4[[#This Row],[file name]],LEN(Tableau4[[#This Row],[file name]])-SEARCH("@",Tableau4[[#This Row],[file name]])),LEN(RIGHT(Tableau4[[#This Row],[file name]],LEN(Tableau4[[#This Row],[file name]])-SEARCH("@",Tableau4[[#This Row],[file name]])))-SEARCH("/",RIGHT(Tableau4[[#This Row],[file name]],LEN(Tableau4[[#This Row],[file name]])-SEARCH("@",Tableau4[[#This Row],[file name]])))),1) -> E | C14: \\192.168.24.208\images\R&D\2-Test oestrogénique\OECD and AOPs\REACTIV oecd interlaboratory validation\Results WF\Résultats CBA\2021-CHG-CBA-Anastrozole\plaque 1/@01 ts/E1_01- exclu.tif
A15: =IFERROR(LEFT(RIGHT(C15,LEN(C15)-SEARCH("@",C15)),SEARCH("/",RIGHT(C15,LEN(C15)-SEARCH("@",C15)-1))),"") -> 01 ts | B15: =LEFT(RIGHT(RIGHT(Tableau4[[#This Row],[file name]],LEN(Tableau4[[#This Row],[file name]])-SEARCH("@",Tableau4[[#This Row],[file name]])),LEN(RIGHT(Tableau4[[#This Row],[file name]],LEN(Tableau4[[#This Row],[file name]])-SEARCH("@",Tableau4[[#This Row],[file name]])))-SEARCH("/",RIGHT(Tableau4[[#This Row],[file name]],LEN(Tableau4[[#This Row],[file name]])-SEARCH("@",Tableau4[[#This Row],[file name]])))),1) -> E | C15: \\192.168.24.208\images\R&D\2-Test oestrogénique\OECD and AOPs\REACTIV oecd interlaboratory validation\Results WF\Résultats CBA\2021-CHG-CBA-Anastrozole\plaque 1/@01 ts/E1_02.tif | D15: 1588.0241 | E15: 63.2603 | G15: 100459
A16: =IFERROR(LEFT(RIGHT(C16,LEN(C16)-SEARCH("@",C16)),SEARCH("/",RIGHT(C16,LEN(C16)-SEARCH("@",C16)-1))),"") -> 01 ts | B16: =LEFT(RIGHT(RIGHT(Tableau4[[#This Row],[file name]],LEN(Tableau4[[#This Row],[file name]])-SEARCH("@",Tableau4[[#This Row],[file name]])),LEN(RIGHT(Tableau4[[#This Row],[file name]],LEN(Tableau4[[#This Row],[file name]])-SEARCH("@",Tableau4[[#This Row],[file name]])))-SEARCH("/",RIGHT(Tableau4[[#This Row],[file name]],LEN(Tableau4[[#This Row],[file name]])-SEARCH("@",Tableau4[[#This Row],[file name]])))),1) -> E | C16: \\192.168.24.208\images\R&D\2-Test oestrogénique\OECD and AOPs\REACTIV oecd interlaboratory validation\Results WF\Résultats CBA\2021-CHG-CBA-Anastrozole\plaque 1/@01 ts/E1_03.tif | D16: 369.8138 | E16: 63.1765 | G16: 23364
A17: =IFERROR(LEFT(RIGHT(C17,LEN(C17)-SEARCH("@",C17)),SEARCH("/",RIGHT(C17,LEN(C17)-SEARCH("@",C17)-1))),"") -> 01 ts | B17: =LEFT(RIGHT(RIGHT(Tableau4[[#This Row],[file name]],LEN(Tableau4[[#This Row],[file name]])-SEARCH("@",Tableau4[[#This Row],[file name]])),LEN(RIGHT(Tableau4[[#This Row],[file name]],LEN(Tableau4[[#This Row],[file name]])-SEARCH("@",Tableau4[[#This Row],[file name]])))-SEARCH("/",RIGHT(Tableau4[[#This Row],[file name]],LEN(Tableau4[[#This Row],[file name]])-SEARCH("@",Tableau4[[#This Row],[file name]])))),1) -> F | C17: \\192.168.24.208\images\R&D\2-Test oestrogénique\OECD and AOPs\REACTIV oecd interlaboratory validation\Results WF\Résultats CBA\2021-CHG-CBA-Anastrozole\plaque 1/@01 ts/F1_01.tif | D17: 435.0751 | E17: 64.45 | G17: 28041
A18: =IFERROR(LEFT(RIGHT(C18,LEN(C18)-SEARCH("@",C18)),SEARCH("/",RIGHT(C18,LEN(C18)-SEARCH("@",C18)-1))),"") -> 01 ts | B18: =LEFT(RIGHT(RIGHT(Tableau4[[#This Row],[file name]],LEN(Tableau4[[#This Row],[file name]])-SEARCH("@",Tableau4[[#This Row],[file name]])),LEN(RIGHT(Tableau4[[#This Row],[file name]],LEN(Tableau4[[#This Row],[file name]])-SEARCH("@",Tableau4[[#This Row],[file name]])))-SEARCH("/",RIGHT(Tableau4[[#This Row],[file name]],LEN(Tableau4[[#This Row],[file name]])-SEARCH("@",Tableau4[[#This Row],[file name]])))),1) -> F | C18: \\192.168.24.208\images\R&D\2-Test oestrogénique\OECD and AOPs\REACTIV oecd interlaboratory validation\Results WF\Résultats CBA\2021-CHG-CBA-Anastrozole\plaque 1/@01 ts/F1_02.tif | D18: 326.3063 | E18: 62.7333 | G18: 20470
A19: =IFERROR(LEFT(RIGHT(C19,LEN(C19)-SEARCH("@",C19)),SEARCH("/",RIGHT(C19,LEN(C19)-SEARCH("@",C19)-1))),"") -> 01 ts | B19: =LEFT(RIGHT(RIGHT(Tableau4[[#This Row],[file name]],LEN(Tableau4[[#This Row],[file name]])-SEARCH("@",Tableau4[[#This Row],[file name]])),LEN(RIGHT(Tableau4[[#This Row],[file name]],LEN(Tableau4[[#This Row],[file name]])-SEARCH("@",Tableau4[[#This Row],[file name]])))-SEARCH("/",RIGHT(Tableau4[[#This Row],[file name]],LEN(Tableau4[[#This Row],[file name]])-SEARCH("@",Tableau4[[#This Row],[file name]])))),1) -> F | C19: \\192.168.24.208\images\R&D\2-Test oestrogénique\OECD and AOPs\REACTIV oecd interlaboratory validation\Results WF\Résultats CBA\2021-CHG-CBA-Anastrozole\plaque 1/@01 ts/F1_03.tif | D19: 304.5526 | E19: 62.7143 | G19: 19100
A20: =IFERROR(LEFT(RIGHT(C20,LEN(C20)-SEARCH("@",C20)),SEARCH("/",RIGHT(C20,LEN(C20)-SEARCH("@",C20)-1))),"") -> 01 ts | B20: =LEFT(RIGHT(RIGHT(Tableau4[[#This Row],[file name]],LEN(Tableau4[[#This Row],[file name]])-SEARCH("@",Tableau4[[#This Row],[file name]])),LEN(RIGHT(Tableau4[[#This Row],[file name]],LEN(Tableau4[[#This Row],[file name]])-SEARCH("@",Tableau4[[#This Row],[file name]])))-SEARCH("/",RIGHT(Tableau4[[#This Row],[file name]],LEN(Tableau4[[#This Row],[file name]])-SEARCH("@",Tableau4[[#This Row],[file name]])))),1) -> G | C20: \\192.168.24.208\images\R&D\2-Test oestrogénique\OECD and AOPs\REACTIV oecd interlaboratory validation\Results WF\Résultats CBA\2021-CHG-CBA-Anastrozole\plaque 1/@01 ts/G1_01- exclu.tif
A21: =IFERROR(LEFT(RIGHT(C21,LEN(C21)-SEARCH("@",C21)),SEARCH("/",RIGHT(C21,LEN(C21)-SEARCH("@",C21)-1))),"") -> 01 ts | B21: =LEFT(RIGHT(RIGHT(Tableau4[[#This Row],[file name]],LEN(Tableau4[[#This Row],[file name]])-SEARCH("@",Tableau4[[#This Row],[file name]])),LEN(RIGHT(Tableau4[[#This Row],[file name]],LEN(Tableau4[[#This Row],[file name]])-SEARCH("@",Tableau4[[#This Row],[file name]])))-SEARCH("/",RIGHT(Tableau4[[#This Row],[file name]],LEN(Tableau4[[#This Row],[file name]])-SEARCH("@",Tableau4[[#This Row],[file name]])))),1) -> G | C21: \\192.168.24.208\images\R&D\2-Test oestrogénique\OECD and AOPs\REACTIV oecd interlaboratory validation\Results WF\Résultats CBA\2021-CHG-CBA-Anastrozole\plaque 1/@01 ts/G1_02.tif | D21: 1218.2103 | E21: 63.4107 | G21: 77248
A22: =IFERROR(LEFT(RIGHT(C22,LEN(C22)-SEARCH("@",C22)),SEARCH("/",RIGHT(C22,LEN(C22)-SEARCH("@",C22)-1))),"") -> 01 ts | B22: =LEFT(RIGHT(RIGHT(Tableau4[[#This Row],[file name]],LEN(Tableau4[[#This Row],[file name]])-SEARCH("@",Tableau4[[#This Row],[file name]])),LEN(RIGHT(Tableau4[[#This Row],[file name]],LEN(Tableau4[[#This Row],[file name]])-SEARCH("@",Tableau4[[#This Row],[file name]])))-SEARCH("/",RIGHT(Tableau4[[#This Row],[file name]],LEN(Tableau4[[#This Row],[file name]])-SEARCH("@",Tableau4[[#This Row],[file name]])))),1) -> G | C22: \\192.168.24.208\images\R&D\2-Test oestrogénique\OECD and AOPs\REACTIV oecd interlaboratory validation\Results WF\Résultats CBA\2021-CHG-CBA-Anastrozole\plaque 1/@01 ts/G1_03.tif | D22: 1348.7328 | E22: 62.6613 | G22: 84513
A23: =IFERROR(LEFT(RIGHT(C23,LEN(C23)-SEARCH("@",C23)),SEARCH("/",RIGHT(C23,LEN(C23)-SEARCH("@",C23)-1))),"") -> 01 ts | B23: =LEFT(RIGHT(RIGHT(Tableau4[[#This Row],[file name]],LEN(Tableau4[[#This Row],[file name]])-SEARCH("@",Tableau4[[#This Row],[file name]])),LEN(RIGHT(Tableau4[[#This Row],[file name]],LEN(Tableau4[[#This Row],[file name]])-SEARCH("@",Tableau4[[#This Row],[file name]])))-SEARCH("/",RIGHT(Tableau4[[#This Row],[file name]],LEN(Tableau4[[#This Row],[file name]])-SEARCH("@",Tableau4[[#This Row],[file name]])))),1) -> H | C23: \\192.168.24.208\images\R&D\2-Test oestrogénique\OECD and AOPs\REACTIV oecd interlaboratory validation\Results WF\Résultats CBA\2021-CHG-CBA-Anastrozole\plaque 1/@01 ts/H1_01- exclu.tif
A24: =IFERROR(LEFT(RIGHT(C24,LEN(C24)-SEARCH("@",C24)),SEARCH("/",RIGHT(C24,LEN(C24)-SEARCH("@",C24)-1))),"") -> 01 ts | B24: =LEFT(RIGHT(RIGHT(Tableau4[[#This Row],[file name]],LEN(Tableau4[[#This Row],[file name]])-SEARCH("@",Tableau4[[#This Row],[file name]])),LEN(RIGHT(Tableau4[[#This Row],[file name]],LEN(Tableau4[[#This Row],[file name]])-SEARCH("@",Tableau4[[#This Row],[file name]])))-SEARCH("/",RIGHT(Tableau4[[#This Row],[file name]],LEN(Tableau4[[#This Row],[file name]])-SEARCH("@",Tableau4[[#This Row],[file name]])))),1) -> H | C24: \\192.168.24.208\images\R&D\2-Test oestrogénique\OECD and AOPs\REACTIV oecd interlaboratory validation\Results WF\Résultats CBA\2021-CHG-CBA-Anastrozole\plaque 1/@01 ts/H1_02- exclu.tif
A25: =IFERROR(LEFT(RIGHT(C25,LEN(C25)-SEARCH("@",C25)),SEARCH("/",RIGHT(C25,LEN(C25)-SEARCH("@",C25)-1))),"") -> 01 ts | B25: =LEFT(RIGHT(RIGHT(Tableau4[[#This Row],[file name]],LEN(Tableau4[[#This Row],[file name]])-SEARCH("@",Tableau4[[#This Row],[file name]])),LEN(RIGHT(Tableau4[[#This Row],[file name]],LEN(Tableau4[[#This Row],[file name]])-SEARCH("@",Tableau4[[#This Row],[file name]])))-SEARCH("/",RIGHT(Tableau4[[#This Row],[file name]],LEN(Tableau4[[#This Row],[file name]])-SEARCH("@",Tableau4[[#This Row],[file name]])))),1) -> H | C25: \\192.168.24.208\images\R&D\2-Test oestrogénique\OECD and AOPs\REACTIV oecd interlaboratory validation\Results WF\Résultats CBA\2021-CHG-CBA-Anastrozole\plaque 1/@01 ts/H1_03.tif | D25: 783.1352 | E25: 64.9167 | G25: 50839
A26: =IFERROR(LEFT(RIGHT(C26,LEN(C26)-SEARCH("@",C26)),SEARCH("/",RIGHT(C26,LEN(C26)-SEARCH("@",C26)-1))),"") | B26: =LEFT(RIGHT(RIGHT(Tableau4[[#This Row],[file name]],LEN(Tableau4[[#This Row],[file name]])-SEARCH("@",Tableau4[[#This Row],[file name]])),LEN(RIGHT(Tableau4[[#This Row],[file name]],LEN(Tableau4[[#This Row],[file name]])-SEARCH("@",Tableau4[[#This Row],[file name]])))-SEARCH("/",RIGHT(Tableau4[[#This Row],[file name]],LEN(Tableau4[[#This Row],[file name]])-SEARCH("@",Tableau4[[#This Row],[file name]])))),1) -> #VALUE!
A27: =IFERROR(LEFT(RIGHT(C27,LEN(C27)-SEARCH("@",C27)),SEARCH("/",RIGHT(C27,LEN(C27)-SEARCH("@",C27)-1))),"") | B27: =LEFT(RIGHT(RIGHT(Tableau4[[#This Row],[file name]],LEN(Tableau4[[#This Row],[file name]])-SEARCH("@",Tableau4[[#This Row],[file name]])),LEN(RIGHT(Tableau4[[#This Row],[file name]],LEN(Tableau4[[#This Row],[file name]])-SEARCH("@",Tableau4[[#This Row],[file name]])))-SEARCH("/",RIGHT(Tableau4[[#This Row],[file name]],LEN(Tableau4[[#This Row],[file name]])-SEARCH("@",Tableau4[[#This Row],[file name]])))),1) -> #VALUE! | C27: group | E27: mean of mean fluo | F27: SD mean fluo | G27: mean of total fluo | H27: SD total fluo | I27: n fluorescent | J27: n total
A28: =IFERROR(LEFT(RIGHT(C28,LEN(C28)-SEARCH("@",C28)),SEARCH("/",RIGHT(C28,LEN(C28)-SEARCH("@",C28)-1))),"") -> 01 ts | B28: =LEFT(RIGHT(RIGHT(Tableau4[[#This Row],[file name]],LEN(Tableau4[[#This Row],[file name]])-SEARCH("@",Tableau4[[#This Row],[file name]])),LEN(RIGHT(Tableau4[[#This Row],[file name]],LEN(Tableau4[[#This Row],[file name]])-SEARCH("@",Tableau4[[#This Row],[file name]])))-SEARCH("/",RIGHT(Tableau4[[#This Row],[file name]],LEN(Tableau4[[#This Row],[file name]])-SEARCH("@",Tableau4[[#This Row],[file name]])))),1) | C28: \\192.168.24.208\images\R&D\2-Test oestrogénique\OECD and AOPs\REACTIV oecd interlaboratory validation\Results WF\Résultats CBA\2021-CHG-CBA-Anastrozole\plaque 1/@01 ts/ | E28: 65.1416 | F28: 2.8199 | G28: 222960.667 | H28: 266441.607 | I28: 24 | J28: 24
A29: =IFERROR(LEFT(RIGHT(C29,LEN(C29)-SEARCH("@",C29)),SEARCH("/",RIGHT(C29,LEN(C29)-SEARCH("@",C29)-1))),"") | B29: =LEFT(RIGHT(RIGHT(Tableau4[[#This Row],[file name]],LEN(Tableau4[[#This Row],[file name]])-SEARCH("@",Tableau4[[#This Row],[file name]])),LEN(RIGHT(Tableau4[[#This Row],[file name]],LEN(Tableau4[[#This Row],[file name]])-SEARCH("@",Tableau4[[#This Row],[file name]])))-SEARCH("/",RIGHT(Tableau4[[#This Row],[file name]],LEN(Tableau4[[#This Row],[file name]])-SEARCH("@",Tableau4[[#This Row],[file name]])))),1) -> #VALUE!
A30: =IFERROR(LEFT(RIGHT(C30,LEN(C30)-SEARCH("@",C30)),SEARCH("/",RIGHT(C30,LEN(C30)-SEARCH("@",C30)-1))),"") | B30: =LEFT(RIGHT(RIGHT(Tableau4[[#This Row],[file name]],LEN(Tableau4[[#This Row],[file name]])-SEARCH("@",Tableau4[[#This Row],[file name]])),LEN(RIGHT(Tableau4[[#This Row],[file name]],LEN(Tableau4[[#This Row],[file name]])-SEARCH("@",Tableau4[[#This Row],[file name]])))-SEARCH("/",RIGHT(Tableau4[[#This Row],[file name]],LEN(Tableau4[[#This Row],[file name]])-SEARCH("@",Tableau4[[#This Row],[file name]])))),1) -> #VALUE!
A31: =IFERROR(LEFT(RIGHT(C31,LEN(C31)-SEARCH("@",C31)),SEARCH("/",RIGHT(C31,LEN(C31)-SEARCH("@",C31)-1))),"") | B31: =LEFT(RIGHT(RIGHT(Tableau4[[#This Row],[file name]],LEN(Tableau4[[#This Row],[file name]])-SEARCH("@",Tableau4[[#This Row],[file name]])),LEN(RIGHT(Tableau4[[#This Row],[file name]],LEN(Tableau4[[#This Row],[file name]])-SEARCH("@",Tableau4[[#This Row],[file name]])))-SEARCH("/",RIGHT(Tableau4[[#This Row],[file name]],LEN(Tableau4[[#This Row],[file name]])-SEARCH("@",Tableau4[[#This Row],[file name]])))),1) -> #VALUE!
A32: =IFERROR(LEFT(RIGHT(C32,LEN(C32)-SEARCH("@",C32)),SEARCH("/",RIGHT(C32,LEN(C32)-SEARCH("@",C32)-1))),"") | B32: =LEFT(RIGHT(RIGHT(Tableau4[[#This Row],[file name]],LEN(Tableau4[[#This Row],[file name]])-SEARCH("@",Tableau4[[#This Row],[file name]])),LEN(RIGHT(Tableau4[[#This Row],[file name]],LEN(Tableau4[[#This Row],[file name]])-SEARCH("@",Tableau4[[#This Row],[file name]])))-SEARCH("/",RIGHT(Tableau4[[#This Row],[file name]],LEN(Tableau4[[#This Row],[file name]])-SEARCH("@",Tableau4[[#This Row],[file name]])))),1) -> #VALUE!
A33: =IFERROR(LEFT(RIGHT(C33,LEN(C33)-SEARCH("@",C33)),SEARCH("/",RIGHT(C33,LEN(C33)-SEARCH("@",C33)-1))),"") | B33: =LEFT(RIGHT(RIGHT(Tableau4[[#This Row],[file name]],LEN(Tableau4[[#This Row],[file name]])-SEARCH("@",Tableau4[[#This Row],[file name]])),LEN(RIGHT(Tableau4[[#This Row],[file name]],LEN(Tableau4[[#This Row],[file name]])-SEARCH("@",Tableau4[[#This Row],[file name]])))-SEARCH("/",RIGHT(Tableau4[[#This Row],[file name]],LEN(Tableau4[[#This Row],[file name]])-SEARCH("@",Tableau4[[#This Row],[file name]])))),1) -> #VALUE!
A34: =IFERROR(LEFT(RIGHT(C34,LEN(C34)-SEARCH("@",C34)),SEARCH("/",RIGHT(C34,LEN(C34)-SEARCH("@",C34)-1))),"") | B34: =LEFT(RIGHT(RIGHT(Tableau4[[#This Row],[file name]],LEN(Tableau4[[#This Row],[file name]])-SEARCH("@",Tableau4[[#This Row],[file name]])),LEN(RIGHT(Tableau4[[#This Row],[file name]],LEN(Tableau4[[#This Row],[file name]])-SEARCH("@",Tableau4[[#This Row],[file name]])))-SEARCH("/",RIGHT(Tableau4[[#This Row],[file name]],LEN(Tableau4[[#This Row],[file name]])-SEARCH("@",Tableau4[[#This Row],[file name]])))),1) -> #VALUE! | C34: file name | D34: total area | E34: mean intensity | G34: total fluorescence
A35: =IFERROR(LEFT(RIGHT(C35,LEN(C35)-SEARCH("@",C35)),SEARCH("/",RIGHT(C35,LEN(C35)-SEARCH("@",C35)-1))),"") -> 02 ee2 33 | B35: =LEFT(RIGHT(RIGHT(Tableau4[[#This Row],[file name]],LEN(Tableau4[[#This Row],[file name]])-SEARCH("@",Tableau4[[#This Row],[file name]])),LEN(RIGHT(Tableau4[[#This Row],[file name]],LEN(Tableau4[[#This Row],[file name]])-SEARCH("@",Tableau4[[#This Row],[file name]])))-SEARCH("/",RIGHT(Tableau4[[#This Row],[file name]],LEN(Tableau4[[#This Row],[file name]])-SEARCH("@",Tableau4[[#This Row],[file name]])))),1) -> A | C35: \\192.168.24.208\images\R&D\2-Test oestrogénique\OECD and AOPs\REACTIV oecd interlaboratory validation\Results WF\Résultats CBA\2021-CHG-CBA-Anastrozole\plaque 1/@02 ee2 33/A2_01.tif | D35: 3806.9071 | E35: 69.0514 | G35: 262872
A36: =IFERROR(LEFT(RIGHT(C36,LEN(C36)-SEARCH("@",C36)),SEARCH("/",RIGHT(C36,LEN(C36)-SEARCH("@",C36)-1))),"") -> 02 ee2 33 | B36: =LEFT(RIGHT(RIGHT(Tableau4[[#This Row],[file name]],LEN(Tableau4[[#This Row],[file name]])-SEARCH("@",Tableau4[[#This Row],[file name]])),LEN(RIGHT(Tableau4[[#This Row],[file name]],LEN(Tableau4[[#This Row],[file name]])-SEARCH("@",Tableau4[[#This Row],[file name]])))-SEARCH("/",RIGHT(Tableau4[[#This Row],[file name]],LEN(Tableau4[[#This Row],[file name]])-SEARCH("@",Tableau4[[#This Row],[file name]])))),1) -> A | C36: \\192.168.24.208\images\R&D\2-Test oestrogénique\OECD and AOPs\REACTIV oecd interlaboratory validation\Results WF\Résultats CBA\2021-CHG-CBA-Anastrozole\plaque 1/@02 ee2 33/A2_02.tif | D36: 2697.4656 | E36: 65.1694 | G36: 175792
A37: =IFERROR(LEFT(RIGHT(C37,LEN(C37)-SEARCH("@",C37)),SEARCH("/",RIGHT(C37,LEN(C37)-SEARCH("@",C37)-1))),"") -> 02 ee2 33 | B37: =LEFT(RIGHT(RIGHT(Tableau4[[#This Row],[file name]],LEN(Tableau4[[#This Row],[file name]])-SEARCH("@",Tableau4[[#This Row],[file name]])),LEN(RIGHT(Tableau4[[#This Row],[file name]],LEN(Tableau4[[#This Row],[file name]])-SEARCH("@",Tableau4[[#This Row],[file name]])))-SEARCH("/",RIGHT(Tableau4[[#This Row],[file name]],LEN(Tableau4[[#This Row],[file name]])-SEARCH("@",Tableau4[[#This Row],[file name]])))),1) -> A | C37: \\192.168.24.208\images\R&D\2-Test oestrogénique\OECD and AOPs\REACTIV oecd interlaboratory validation\Results WF\Résultats CBA\2021-CHG-CBA-Anastrozole\plaque 1/@02 ee2 33/A2_03.tif | D37: 391.5676 | E37: 63.0556 | G37: 24691
A38: =IFERROR(LEFT(RIGHT(C38,LEN(C38)-SEARCH("@",C38)),SEARCH("/",RIGHT(C38,LEN(C38)-SEARCH("@",C38)-1))),"") -> 02 ee2 33 | B38: =LEFT(RIGHT(RIGHT(Tableau4[[#This Row],[file name]],LEN(Tableau4[[#This Row],[file name]])-SEARCH("@",Tableau4[[#This Row],[file name]])),LEN(RIGHT(Tableau4[[#This Row],[file name]],LEN(Tableau4[[#This Row],[file name]])-SEARCH("@",Tableau4[[#This Row],[file name]])))-SEARCH("/",RIGHT(Tableau4[[#This Row],[file name]],LEN(Tableau4[[#This Row],[file name]])-SEARCH("@",Tableau4[[#This Row],[file name]])))),1) -> B | C38: \\192.168.24.208\images\R&D\2-Test oestrogénique\OECD and AOPs\REACTIV oecd interlaboratory validation\Results WF\Résultats CBA\2021-CHG-CBA-Anastrozole\plaque 1/@02 ee2 33/B2_01.tif | D38: 522.0901 | E38: 62.7917 | G38: 32783
A39: =IFERROR(LEFT(RIGHT(C39,LEN(C39)-SEARCH("@",C39)),SEARCH("/",RIGHT(C39,LEN(C39)-SEARCH("@",C39)-1))),"") -> 02 ee2 33 | B39: =LEFT(RIGHT(RIGHT(Tableau4[[#This Row],[file name]],LEN(Tableau4[[#This Row],[file name]])-SEARCH("@",Tableau4[[#This Row],[file name]])),LEN(RIGHT(Tableau4[[#This Row],[file name]],LEN(Tableau4[[#This Row],[file name]])-SEARCH("@",Tableau4[[#This Row],[file name]])))-SEARCH("/",RIGHT(Tableau4[[#This Row],[file name]],LEN(Tableau4[[#This Row],[file name]])-SEARCH("@",Tableau4[[#This Row],[file name]])))),1) -> B | C39: \\192.168.24.208\images\R&D\2-Test oestrogénique\OECD and AOPs\REACTIV oecd interlaboratory validation\Results WF\Résultats CBA\2021-CHG-CBA-Anastrozole\plaque 1/@02 ee2 33/B2_02.tif | D39: 543.8439 | E39: 63.2 | G39: 34371
A40: =IFERROR(LEFT(RIGHT(C40,LEN(C40)-SEARCH("@",C40)),SEARCH("/",RIGHT(C40,LEN(C40)-SEARCH("@",C40)-1))),"") -> 02 ee2 33 | B40: =LEFT(RIGHT(RIGHT(Tableau4[[#This Row],[file name]],LEN(Tableau4[[#This Row],[file name]])-SEARCH("@",Tableau4[[#This Row],[file name]])),LEN(RIGHT(Tableau4[[#This Row],[file name]],LEN(Tableau4[[#This Row],[file name]])-SEARCH("@",Tableau4[[#This Row],[file name]])))-SEARCH("/",RIGHT(Tableau4[[#This Row],[file name]],LEN(Tableau4[[#This Row],[file name]])-SEARCH("@",Tableau4[[#This Row],[file name]])))),1) -> B | C40: \\192.168.24.208\images\R&D\2-Test oestrogénique\OECD and AOPs\REACTIV oecd interlaboratory validation\Results WF\Résultats CBA\2021-CHG-CBA-Anastrozole\plaque 1/@02 ee2 33/B2_03.tif | D40: 2001.3455 | E40: 64.3043 | G40: 128695
...

Sheet R1
A1: 3. Expérimentateur 1 : copier et coller les valeurs des intensités totales de fluorescences obtenues dans le fichier raw data lors du traitement des images.
A3: R1 | B3: Non dopé | O3: avec testo
A4: Noms des groupes | B4: ='Page de garde'!A7 -> Témoin solvant | C4: ='Page de garde'!A9 -> EE2-33,8ng/L | D4: ='Page de garde'!A10 -> EE2-50,6ng/L | E4: ='Page de garde'!A11 -> EE2-76ng/L | F4: ='Page de garde'!A12 -> EE2-114ng/L | G4: ='Page de garde'!A13 -> EE2-170,9ng/L | H4: ='Page de garde'!A14 -> EE2-488ng/L | I4: ='Page de garde'!A15 -> Anastrozole 0,032 ug/L | J4: ='Page de garde'!A16 -> Anastrozole 0,16 ug/L | K4: ='Page de garde'!A17 -> Anastrozole 0,8 ug/L | L4: ='Page de garde'!A18 -> Anastrozole 4 ug/L | M4: ='Page de garde'!A19 -> Anastrozole 20 ug/L | O4: ='Page de garde'!A36 -> Testo -30µg/L | P4: ='Page de garde'!A37 -> Testo 30µg/L + EE2 -64ng/L | Q4: ='Page de garde'!A38 -> Testo 30µg/L + FAD-10mg/L | R4: ='Page de garde'!A39 -> Anastrozole-0,032ug/L + Testostérone | S4: ='Page de garde'!A40 -> Anastrozole-0,16ug/L + Testostérone | T4: ='Page de garde'!A41 -> Anastrozole-0,8ug/L + Testostérone | U4: ='Page de garde'!A42 -> Anastrozole-4ug/L + Testostérone | V4: ='Page de garde'!A43 -> Anastrozole-20ug/L + Testostérone | W4: ='Page de garde'!A44 -> 0-00 + Testostérone | X4: ='Page de garde'!A45 -> 0-00 + Testostérone | Y4: ='Page de garde'!A46 -> 0-00 + Testostérone | Z4: ='Page de garde'!A47 -> 0-00 + Testostérone | AA4: ='Page de garde'!A48 -> 0-00 + Testostérone | AB4: ='Page de garde'!A49 -> 0-00 + Testostérone | AC4: ='Page de garde'!A50 -> 0-00 + Testostérone | AD4: ='Page de garde'!A51 -> 0-00 + Testostérone | AE4: ='Page de garde'!A52 -> 0-00 + Testostérone | AF4: ='Page de garde'!A53 -> 0-00 + Testostérone | AG4: ='Page de garde'!A54 -> 0-00 + Testostérone | AH4: ='Page de garde'!A55 -> 0-00 + Testostérone | AI4: ='Page de garde'!A56 -> 0-00 + Testostérone | AJ4: ='Page de garde'!A57 -> 0-00 + Testostérone | AK4: ='Page de garde'!A58 -> 0-00 + Testostérone
A5: Données brutes | B5: 333927.33 | C5: 154451.67 | D5: 418999 | E5: 1406641.5 | F5: 1579246.5 | G5: 4877416.7 | H5: 7861807 | I5: 376093.67 | J5: 630511 | K5: 225448.67 | L5: 116505.67 | M5: 800375 | O5: 2015137 | P5: 2925532 | Q5: 67226.333 | R5: 605508.67 | S5: 78393.333 | T5: 49352 | U5: 715357.67 | V5: 348603.67
B6: 83041.333 | C6: 65283 | D6: 325784.33 | E6: 1002195.7 | F6: 1011332 | G6: 5322179.3 | H6: 6430729.3 | I6: 215696 | J6: 222280 | K6: 208611.33 | L6: 27953.667 | M6: 266581 | O6: 2180052.3 | P6: 6507614.3 | Q6: 181687.33 | R6: 1502815 | S6: 2103124 | T6: 344035.5 | U6: 361525.67 | V6: 186531.33
B7: 698933.67 | C7: 29969.333 | D7: 59268 | E7: 1129527.7 | F7: 166561.33 | H7: 6716704 | I7: 170593 | J7: 311651.33 | K7: 426649 | L7: 107717.33 | M7: 264982.67 | O7: 3341695.7 | P7: 3250837.3 | Q7: 29835 | R7: 1131949.3 | S7: 1233133.3 | T7: 247086.33 | U7: 41738.333 | V7: 195457.33
B8: 653613.5 | C8: 26974.333 | D8: 84593 | E8: 807883.67 | F8: 2014213 | G8: 2960055 | H8: 8495160.7 | I8: 116476.67 | J8: 149078.67 | K8: 164030.67 | L8: 158193.33 | M8: 226906 | O8: 1320540 | P8: 2818144.5 | Q8: 22370 | R8: 1714776 | S8: 1219551.7 | T8: 13785 | U8: 131595.67 | V8: 343985
B9: 61911.5 | C9: 96510.5 | D9: 363316.67 | E9: 27895.667 | F9: 937985.67 | G9: 1751547 | H9: 7859262 | I9: 521133 | J9: 34371 | K9: 151754 | L9: 190548.33 | M9: 28033.333 | O9: 3397429 | P9: 2535248 | Q9: 379375 | R9: 1478204 | S9: 273981.33 | T9: 41542.333 | U9: 144988.67 | V9: 209496
B10: 22537 | C10: 932895.33 | D10: 310571.33 | E10: 115762.5 | F10: 3500810 | G10: 4247195.7 | H10: 8062326 | I10: 286431.67 | J10: 157939.67 | K10: 26670.333 | L10: 333825.67 | M10: 340674.5 | O10: 4111818.5 | P10: 2834275 | Q10: 29142.667 | R10: 1368659 | S10: 294524 | T10: 203172.67 | U10: 79133 | V10: 94302.333
B11: 80880.5 | C11: 29498 | D11: 31151 | E11: 250705 | F11: 2659788 | G11: 4246412.7 | H11: 3455330.3 | I11: 211163.67 | J11: 273009.5 | K11: 255642.67 | L11: 935955.33 | M11: 91387.667 | O11: 4673816 | P11: 2822006 | Q11: 178801.33 | R11: 792989.67 | S11: 1399125.5 | T11: 132633 | U11: 387594 | V11: 14901.333
B12: 50839 | C12: 204253.33 | D12: 260566.33 | E12: 814554.67 | F12: 1652372 | G12: 2773049 | H12: 5030642.7 | J12: 417730.33 | K12: 325378.33 | M12: 146489.67 | O12: 4192884 | P12: 6209348.3 | Q12: 501786.33 | R12: 588243 | S12: 207835.33 | T12: 170904.67 | U12: 438099 | V12: 560906
O13: 2196259
O14: 1584217.5
O15: 3401402.7
O16: 220387
O17: 1900615
O18: 2190052.3
O19: 18324
O20: 492911.33
A22: =A4 -> Noms des groupes | B22: =B4 -> Témoin solvant | C22: =C4 -> EE2-33,8ng/L | D22: =D4 -> EE2-50,6ng/L | E22: =E4 -> EE2-76ng/L | F22: =F4 -> EE2-114ng/L | G22: =G4 -> EE2-170,9ng/L | H22: =H4 -> EE2-488ng/L | ... M22: =M4 -> Anastrozole 20 ug/L | N22: Nom des groupes | O22: =O4 -> Testo -30µg/L | P22: =P4 -> Testo 30µg/L + EE2 -64ng/L | Q22: =Q4 -> Testo 30µg/L + FAD-10mg/L | R22: =R4 -> Anastrozole-0,032ug/L + Testostérone | S22: =S4 -> Anastrozole-0,16ug/L + Testostérone | T22: =T4 -> Anastrozole-0,8ug/L + Testostérone | U22: =U4 -> Anastrozole-4ug/L + Testostérone | V22: =V4 -> Anastrozole-20ug/L + Testostérone | ... AK22: =AK4 -> 0-00 + Testostérone
A23: mean | B23: =AVERAGE(B5:B20) -> 248210.48 | C23: =AVERAGE(C5:C20) -> 192479.44 | D23: =AVERAGE(D5:D20) -> 231781.21 | E23: =AVERAGE(E5:E20) -> 694395.79 | F23: =AVERAGE(F5:F20) -> 1690288.6 | G23: =AVERAGE(G5:G20) -> 3739693.6 | H23: =AVERAGE(H5:H20) -> 6738995.2 | I23: =AVERAGE(I5:I20) -> 271083.95 | ... M23: =AVERAGE(M5:M20) -> 270678.73 | N23: mean | O23: =AVERAGE(O5:O20) -> 2327346.3 | P23: =AVERAGE(P5:P20) -> 3737875.7 | Q23: =AVERAGE(Q5:Q20) -> 173778 | R23: =AVERAGE(R5:R20) -> 1147893.1 | S23: =AVERAGE(S5:S20) -> 851208.56 | T23: =AVERAGE(T5:T20) -> 150313.94 | U23: =AVERAGE(U5:U20) -> 287504 | V23: =AVERAGE(V5:V20) -> 244272.88 | ... AK23: =AVERAGE(AK5:AK20) -> #DIV/0!
A24: SD | B24: =STDEV(B5:B20) -> 281506.63 | C24: =STDEV(C5:C20) -> 306023.77 | D24: =STDEV(D5:D20) -> 151139.85 | E24: =STDEV(E5:E20) -> 506330.29 | F24: =STDEV(F5:F20) -> 1047807.1 | G24: =STDEV(G5:G20) -> 1278538.4 | H24: =STDEV(H5:H20) -> 1738121.9 | I24: =STDEV(I5:I20) -> 138110.6 | ... M24: =STDEV(M5:M20) -> 237212.33 | N24: SD | O24: =STDEV(O5:O20) -> 1426821.3 | P24: =STDEV(P5:P20) -> 1631137.6 | Q24: =STDEV(Q5:Q20) -> 179628.18 | R24: =STDEV(R5:R20) -> 437324.4 | S24: =STDEV(S5:S20) -> 737109.21 | T24: =STDEV(T5:T20) -> 114072.85 | U24: =STDEV(U5:U20) -> 229804.92 | V24: =STDEV(V5:V20) -> 170341.21 | ... AK24: =STDEV(AK5:AK20) -> #DIV/0!
B26: Non dopé | O26: avec testo
A27: Noms des groupes | B27: =B4 -> Témoin solvant | C27: =C4 -> EE2-33,8ng/L | D27: =D4 -> EE2-50,6ng/L | E27: =E4 -> EE2-76ng/L | F27: =F4 -> EE2-114ng/L | G27: =G4 -> EE2-170,9ng/L | H27: =H4 -> EE2-488ng/L | I27: =I4 -> Anastrozole 0,032 ug/L | ... M27: =M4 -> Anastrozole 20 ug/L | O27: =O4 -> Testo -30µg/L | P27: =P4 -> Testo 30µg/L + EE2 -64ng/L | Q27: =Q4 -> Testo 30µg/L + FAD-10mg/L | R27: =R4 -> Anastrozole-0,032ug/L + Testostérone | S27: =S4 -> Anastrozole-0,16ug/L + Testostérone | T27: =T4 -> Anastrozole-0,8ug/L + Testostérone | U27: =U4 -> Anastrozole-4ug/L + Testostérone | V27: =V4 -> Anastrozole-20ug/L + Testostérone | ... AK27: =AK4 -> 0-00 + Testostérone
A28: Données normalisées sur la moyenne du groupe "Testo" | B28: =IF(B5="","",(B5/$O$23)) -> 0.14347986 | C28: =IF(C5="","",(C5/$O$23)) -> 0.066363852 | D28: =IF(D5="","",(D5/$O$23)) -> 0.18003294 | E28: =IF(E5="","",(E5/$O$23)) -> 0.60439715 | F28: =IF(F5="","",(F5/$O$23)) -> 0.67856102 | G28: =IF(G5="","",(G5/$O$23)) -> 2.0956987 | H28: =IF(H5="","",(H5/$O$23)) -> 3.3780134 | I28: =IF(I5="","",(I5/$O$23)) -> 0.16159764 | ... M28: =IF(M5="","",(M5/$O$23)) -> 0.34390026 | O28: =IF(O5="","",(O5/$O$23)) -> 0.86585179 | P28: =IF(P5="","",(P5/$O$23)) -> 1.2570248 | Q28: =IF(Q5="","",(Q5/$O$23)) -> 0.028885402 | R28: =IF(R5="","",(R5/$O$23)) -> 0.26017128 | S28: =IF(S5="","",(S5/$O$23)) -> 0.03368357 | T28: =IF(T5="","",(T5/$O$23)) -> 0.021205267 | U28: =IF(U5="","",(U5/$O$23)) -> 0.30737053 | V28: =IF(V5="","",(V5/$O$23)) -> 0.1497859 | ... AK28: =IF(AK5="","",(AK5/$O$23))
B29: =IF(B6="","",(B6/$O$23)) -> 0.035680694 | C29: =IF(C6="","",(C6/$O$23)) -> 0.028050402 | D29: =IF(D6="","",(D6/$O$23)) -> 0.13998103 | E29: =IF(E6="","",(E6/$O$23)) -> 0.43061733 | F29: =IF(F6="","",(F6/$O$23)) -> 0.43454298 | G29: =IF(G6="","",(G6/$O$23)) -> 2.2868016 | H29: =IF(H6="","",(H6/$O$23)) -> 2.7631166 | I29: =IF(I6="","",(I6/$O$23)) -> 0.092678944 | ... M29: =IF(M6="","",(M6/$O$23)) -> 0.1145429 | O29: =IF(O6="","",(O6/$O$23)) -> 0.93671161 | P29: =IF(P6="","",(P6/$O$23)) -> 2.7961521 | Q29: =IF(Q6="","",(Q6/$O$23)) -> 0.078066307 | R29: =IF(R6="","",(R6/$O$23)) -> 0.6457204 | S29: =IF(S6="","",(S6/$O$23)) -> 0.90365751 | T29: =IF(T6="","",(T6/$O$23)) -> 0.14782308 | U29: =IF(U6="","",(U6/$O$23)) -> 0.15533815 | V29: =IF(V6="","",(V6/$O$23)) -> 0.080147647 | ... AK29: =IF(AK6="","",(AK6/$O$23))
B30: =IF(B7="","",(B7/$O$23)) -> 0.30031356 | C30: =IF(C7="","",(C7/$O$23)) -> 0.012877041 | D30: =IF(D7="","",(D7/$O$23)) -> 0.025465913 | E30: =IF(E7="","",(E7/$O$23)) -> 0.48532857 | F30: =IF(F7="","",(F7/$O$23)) -> 0.071567059 | G30: =IF(G7="","",(G7/$O$23)) | H30: =IF(H7="","",(H7/$O$23)) -> 2.8859925 | I30: =IF(I7="","",(I7/$O$23)) -> 0.073299361 | ... M30: =IF(M7="","",(M7/$O$23)) -> 0.11385614 | O30: =IF(O7="","",(O7/$O$23)) -> 1.4358394 | P30: =IF(P7="","",(P7/$O$23)) -> 1.3968 | Q30: =IF(Q7="","",(Q7/$O$23)) -> 0.012819321 | R30: =IF(R7="","",(R7/$O$23)) -> 0.4863691 | S30: =IF(S7="","",(S7/$O$23)) -> 0.52984522 | T30: =IF(T7="","",(T7/$O$23)) -> 0.10616655 | U30: =IF(U7="","",(U7/$O$23)) -> 0.017933873 | V30: =IF(V7="","",(V7/$O$23)) -> 0.083982917 | ... AK30: =IF(AK7="","",(AK7/$O$23))
B31: =IF(B8="","",(B8/$O$23)) -> 0.28084067 | C31: =IF(C8="","",(C8/$O$23)) -> 0.011590167 | D31: =IF(D8="","",(D8/$O$23)) -> 0.036347405 | E31: =IF(E8="","",(E8/$O$23)) -> 0.34712653 | F31: =IF(F8="","",(F8/$O$23)) -> 0.86545478 | G31: =IF(G8="","",(G8/$O$23)) -> 1.2718584 | H31: =IF(H8="","",(H8/$O$23)) -> 3.6501489 | I31: =IF(I8="","",(I8/$O$23)) -> 0.050046985 | ... M31: =IF(M8="","",(M8/$O$23)) -> 0.097495588 | O31: =IF(O8="","",(O8/$O$23)) -> 0.56740159 | P31: =IF(P8="","",(P8/$O$23)) -> 1.2108832 | Q31: =IF(Q8="","",(Q8/$O$23)) -> 0.0096118054 | R31: =IF(R8="","",(R8/$O$23)) -> 0.73679451 | S31: =IF(S8="","",(S8/$O$23)) -> 0.52400953 | T31: =IF(T8="","",(T8/$O$23)) -> 0.0059230549 | U31: =IF(U8="","",(U8/$O$23)) -> 0.056543225 | V31: =IF(V8="","",(V8/$O$23)) -> 0.14780138 | ... AK31: =IF(AK8="","",(AK8/$O$23))
