Workbook

Sheet Page de garde
A1: 1. Expérimentateur 1 : copier et coller le n° de prestation et renseigner la date de réalisation de chaque réplica ainsi que le visa de l'expérimentateur.
A2: R1 | B2: Numéro d'expérience : | E2: Date de réalisation :
A3: R2 | B3: Numéro d'expérience : | E3: Date de réalisation :
A4: R3 | B4: Numéro d'expérience : | E4: Date de réalisation :
A5: 2. Expérimentateur 1 : copier et coller la dilution appliquée et le nom donné pour chaque des échantillons par le client. Conserver la mise en forme de l'exemple en italique. Ne pas remplir la colonne "nom sur graphique".
A6: Nom sur le graphique | B6: Code WF | C6: Concentration | D6: Unité | E6: Nom de l'échantillon donné par le client | F6: Dopage (+Testostérone / + EE2, ….)
A7: =IF(ISBLANK(liste_groupe[[#This Row],[Code WF]])," ",IF(ISBLANK(liste_groupe[[#This Row],[Unité]]),CONCATENATE(liste_groupe[[#This Row],[Nom de l''échantillon donné par le client]],liste_groupe[[#This Row],[Dopage (+Testostérone / + EE2, ….)]]),CONCATENATE(liste_groupe[[#This Row],[Nom de l''échantillon donné par le client]],"-",liste_groupe[[#This Row],[Concentration]],liste_groupe[[#This Row],[Unité]],liste_groupe[[#This Row],[Dopage (+Testostérone / + EE2, ….)]]))) -> Témoin solvant | B7: Témoin | E7: Témoin solvant
A8: =IF(ISBLANK(liste_groupe[[#This Row],[Code WF]])," ",IF(ISBLANK(liste_groupe[[#This Row],[Unité]]),CONCATENATE(liste_groupe[[#This Row],[Nom de l''échantillon donné par le client]],liste_groupe[[#This Row],[Dopage (+Testostérone / + EE2, ….)]]),CONCATENATE(liste_groupe[[#This Row],[Nom de l''échantillon donné par le client]],"-",liste_groupe[[#This Row],[Concentration]],liste_groupe[[#This Row],[Unité]],liste_groupe[[#This Row],[Dopage (+Testostérone / + EE2, ….)]]))) -> EE2-22,5ng/L | B8: Témoin | C8: 22.5 | D8: ng/L | E8: EE2
A9: =IF(ISBLANK(liste_groupe[[#This Row],[Code WF]])," ",IF(ISBLANK(liste_groupe[[#This Row],[Unité]]),CONCATENATE(liste_groupe[[#This Row],[Nom de l''échantillon donné par le client]],liste_groupe[[#This Row],[Dopage (+Testostérone / + EE2, ….)]]),CONCATENATE(liste_groupe[[#This Row],[Nom de l''échantillon donné par le client]],"-",liste_groupe[[#This Row],[Concentration]],liste_groupe[[#This Row],[Unité]],liste_groupe[[#This Row],[Dopage (+Testostérone / + EE2, ….)]]))) -> EE2-33,8ng/L | B9: Témoin | C9: 33.8 | D9: ng/L | E9: EE2
A10: =IF(ISBLANK(liste_groupe[[#This Row],[Code WF]])," ",IF(ISBLANK(liste_groupe[[#This Row],[Unité]]),CONCATENATE(liste_groupe[[#This Row],[Nom de l''échantillon donné par le client]],liste_groupe[[#This Row],[Dopage (+Testostérone / + EE2, ….)]]),CONCATENATE(liste_groupe[[#This Row],[Nom de l''échantillon donné par le client]],"-",liste_groupe[[#This Row],[Concentration]],liste_groupe[[#This Row],[Unité]],liste_groupe[[#This Row],[Dopage (+Testostérone / + EE2, ….)]]))) -> EE2-50,6ng/L | B10: Témoin | C10: 50.6 | D10: ng/L | E10: EE2
A11: =IF(ISBLANK(liste_groupe[[#This Row],[Code WF]])," ",IF(ISBLANK(liste_groupe[[#This Row],[Unité]]),CONCATENATE(liste_groupe[[#This Row],[Nom de l''échantillon donné par le client]],liste_groupe[[#This Row],[Dopage (+Testostérone / + EE2, ….)]]),CONCATENATE(liste_groupe[[#This Row],[Nom de l''échantillon donné par le client]],"-",liste_groupe[[#This Row],[Concentration]],liste_groupe[[#This Row],[Unité]],liste_groupe[[#This Row],[Dopage (+Testostérone / + EE2, ….)]]))) -> EE2-76ng/L | B11: Témoin | C11: 76 | D11: ng/L | E11: EE2
A12: =IF(ISBLANK(liste_groupe[[#This Row],[Code WF]])," ",IF(ISBLANK(liste_groupe[[#This Row],[Unité]]),CONCATENATE(liste_groupe[[#This Row],[Nom de l''échantillon donné par le client]],liste_groupe[[#This Row],[Dopage (+Testostérone / + EE2, ….)]]),CONCATENATE(liste_groupe[[#This Row],[Nom de l''échantillon donné par le client]],"-",liste_groupe[[#This Row],[Concentration]],liste_groupe[[#This Row],[Unité]],liste_groupe[[#This Row],[Dopage (+Testostérone / + EE2, ….)]]))) -> EE2-114ng/L | B12: Témoin | C12: 114 | D12: ng/L | E12: EE2
A13: =IF(ISBLANK(liste_groupe[[#This Row],[Code WF]])," ",IF(ISBLANK(liste_groupe[[#This Row],[Unité]]),CONCATENATE(liste_groupe[[#This Row],[Nom de l''échantillon donné par le client]],liste_groupe[[#This Row],[Dopage (+Testostérone / + EE2, ….)]]),CONCATENATE(liste_groupe[[#This Row],[Nom de l''échantillon donné par le client]],"-",liste_groupe[[#This Row],[Concentration]],liste_groupe[[#This Row],[Unité]],liste_groupe[[#This Row],[Dopage (+Testostérone / + EE2, ….)]]))) -> EE2-170,9ng/L | B13: Témoin | C13: 170.9 | D13: ng/L | E13: EE2
A14: =IF(ISBLANK(liste_groupe[[#This Row],[Code WF]])," ",IF(ISBLANK(liste_groupe[[#This Row],[Unité]]),CONCATENATE(liste_groupe[[#This Row],[Nom de l''échantillon donné par le client]],liste_groupe[[#This Row],[Dopage (+Testostérone / + EE2, ….)]]),CONCATENATE(liste_groupe[[#This Row],[Nom de l''échantillon donné par le client]],"-",liste_groupe[[#This Row],[Concentration]],liste_groupe[[#This Row],[Unité]],liste_groupe[[#This Row],[Dopage (+Testostérone / + EE2, ….)]]))) -> EE2-488ng/L | B14: Témoin | C14: 488 | D14: ng/L | E14: EE2
A15: Triphénylphosphate-0,18mg/L | C15: 0.18 | D15: mg/L | E15: Triphénylphosphate
A16: Triphénylphosphate-0,26mg/L | C16: 0.26 | D16: mg/L | E16: Triphénylphosphate
A17: Triphénylphosphate-0,4mg/L | C17: 0.4 | D17: mg/L | E17: Triphénylphosphate
A18: Triphénylphosphate-0,59mg/L | C18: 0.59 | D18: mg/L | E18: Triphénylphosphate
A19: Triphénylphosphate-0,89mg/L | C19: 0.89 | D19: mg/L | E19: Triphénylphosphate
A20: =IF(ISBLANK(liste_groupe[[#This Row],[Code WF]])," ",IF(ISBLANK(liste_groupe[[#This Row],[Unité]]),CONCATENATE(liste_groupe[[#This Row],[Nom de l''échantillon donné par le client]],liste_groupe[[#This Row],[Dopage (+Testostérone / + EE2, ….)]]),CONCATENATE(liste_groupe[[#This Row],[Nom de l''échantillon donné par le client]],"-",liste_groupe[[#This Row],[Concentration]],liste_groupe[[#This Row],[Unité]],liste_groupe[[#This Row],[Dopage (+Testostérone / + EE2, ….)]])))
A21: =IF(ISBLANK(liste_groupe[[#This Row],[Code WF]])," ",IF(ISBLANK(liste_groupe[[#This Row],[Unité]]),CONCATENATE(liste_groupe[[#This Row],[Nom de l''échantillon donné par le client]],liste_groupe[[#This Row],[Dopage (+Testostérone / + EE2, ….)]]),CONCATENATE(liste_groupe[[#This Row],[Nom de l''échantillon donné par le client]],"-",liste_groupe[[#This Row],[Concentration]],liste_groupe[[#This Row],[Unité]],liste_groupe[[#This Row],[Dopage (+Testostérone / + EE2, ….)]])))
A22: =IF(ISBLANK(liste_groupe[[#This Row],[Code WF]])," ",IF(ISBLANK(liste_groupe[[#This Row],[Unité]]),CONCATENATE(liste_groupe[[#This Row],[Nom de l''échantillon donné par le client]],liste_groupe[[#This Row],[Dopage (+Testostérone / + EE2, ….)]]),CONCATENATE(liste_groupe[[#This Row],[Nom de l''échantillon donné par le client]],"-",liste_groupe[[#This Row],[Concentration]],liste_groupe[[#This Row],[Unité]],liste_groupe[[#This Row],[Dopage (+Testostérone / + EE2, ….)]])))
A23: =IF(ISBLANK(liste_groupe[[#This Row],[Code WF]])," ",IF(ISBLANK(liste_groupe[[#This Row],[Unité]]),CONCATENATE(liste_groupe[[#This Row],[Nom de l''échantillon donné par le client]],liste_groupe[[#This Row],[Dopage (+Testostérone / + EE2, ….)]]),CONCATENATE(liste_groupe[[#This Row],[Nom de l''échantillon donné par le client]],"-",liste_groupe[[#This Row],[Concentration]],liste_groupe[[#This Row],[Unité]],liste_groupe[[#This Row],[Dopage (+Testostérone / + EE2, ….)]])))
A24: =IF(ISBLANK(liste_groupe[[#This Row],[Code WF]])," ",IF(ISBLANK(liste_groupe[[#This Row],[Unité]]),CONCATENATE(liste_groupe[[#This Row],[Nom de l''échantillon donné par le client]],liste_groupe[[#This Row],[Dopage (+Testostérone / + EE2, ….)]]),CONCATENATE(liste_groupe[[#This Row],[Nom de l''échantillon donné par le client]],"-",liste_groupe[[#This Row],[Concentration]],liste_groupe[[#This Row],[Unité]],liste_groupe[[#This Row],[Dopage (+Testostérone / + EE2, ….)]])))
A25: =IF(ISBLANK(liste_groupe[[#This Row],[Code WF]])," ",IF(ISBLANK(liste_groupe[[#This Row],[Unité]]),CONCATENATE(liste_groupe[[#This Row],[Nom de l''échantillon donné par le client]],liste_groupe[[#This Row],[Dopage (+Testostérone / + EE2, ….)]]),CONCATENATE(liste_groupe[[#This Row],[Nom de l''échantillon donné par le client]],"-",liste_groupe[[#This Row],[Concentration]],liste_groupe[[#This Row],[Unité]],liste_groupe[[#This Row],[Dopage (+Testostérone / + EE2, ….)]])))
A26: =IF(ISBLANK(liste_groupe[[#This Row],[Code WF]])," ",IF(ISBLANK(liste_groupe[[#This Row],[Unité]]),CONCATENATE(liste_groupe[[#This Row],[Nom de l''échantillon donné par le client]],liste_groupe[[#This Row],[Dopage (+Testostérone / + EE2, ….)]]),CONCATENATE(liste_groupe[[#This Row],[Nom de l''échantillon donné par le client]],"-",liste_groupe[[#This Row],[Concentration]],liste_groupe[[#This Row],[Unité]],liste_groupe[[#This Row],[Dopage (+Testostérone / + EE2, ….)]])))
A27: =IF(ISBLANK(liste_groupe[[#This Row],[Code WF]])," ",IF(ISBLANK(liste_groupe[[#This Row],[Unité]]),CONCATENATE(liste_groupe[[#This Row],[Nom de l''échantillon donné par le client]],liste_groupe[[#This Row],[Dopage (+Testostérone / + EE2, ….)]]),CONCATENATE(liste_groupe[[#This Row],[Nom de l''échantillon donné par le client]],"-",liste_groupe[[#This Row],[Concentration]],liste_groupe[[#This Row],[Unité]],liste_groupe[[#This Row],[Dopage (+Testostérone / + EE2, ….)]])))
A28: =IF(ISBLANK(liste_groupe[[#This Row],[Code WF]])," ",IF(ISBLANK(liste_groupe[[#This Row],[Unité]]),CONCATENATE(liste_groupe[[#This Row],[Nom de l''échantillon donné par le client]],liste_groupe[[#This Row],[Dopage (+Testostérone / + EE2, ….)]]),CONCATENATE(liste_groupe[[#This Row],[Nom de l''échantillon donné par le client]],"-",liste_groupe[[#This Row],[Concentration]],liste_groupe[[#This Row],[Unité]],liste_groupe[[#This Row],[Dopage (+Testostérone / + EE2, ….)]])))
A29: =IF(ISBLANK(liste_groupe[[#This Row],[Code WF]])," ",IF(ISBLANK(liste_groupe[[#This Row],[Unité]]),CONCATENATE(liste_groupe[[#This Row],[Nom de l''échantillon donné par le client]],liste_groupe[[#This Row],[Dopage (+Testostérone / + EE2, ….)]]),CONCATENATE(liste_groupe[[#This Row],[Nom de l''échantillon donné par le client]],"-",liste_groupe[[#This Row],[Concentration]],liste_groupe[[#This Row],[Unité]],liste_groupe[[#This Row],[Dopage (+Testostérone / + EE2, ….)]])))
A30: =IF(ISBLANK(liste_groupe[[#This Row],[Code WF]])," ",IF(ISBLANK(liste_groupe[[#This Row],[Unité]]),CONCATENATE(liste_groupe[[#This Row],[Nom de l''échantillon donné par le client]],liste_groupe[[#This Row],[Dopage (+Testostérone / + EE2, ….)]]),CONCATENATE(liste_groupe[[#This Row],[Nom de l''échantillon donné par le client]],"-",liste_groupe[[#This Row],[Concentration]],liste_groupe[[#This Row],[Unité]],liste_groupe[[#This Row],[Dopage (+Testostérone / + EE2, ….)]])))
A31: =IF(ISBLANK(liste_groupe[[#This Row],[Code WF]])," ",IF(ISBLANK(liste_groupe[[#This Row],[Unité]]),CONCATENATE(liste_groupe[[#This Row],[Nom de l''échantillon donné par le client]],liste_groupe[[#This Row],[Dopage (+Testostérone / + EE2, ….)]]),CONCATENATE(liste_groupe[[#This Row],[Nom de l''échantillon donné par le client]],"-",liste_groupe[[#This Row],[Concentration]],liste_groupe[[#This Row],[Unité]],liste_groupe[[#This Row],[Dopage (+Testostérone / + EE2, ….)]])))
... A35: =IF(ISBLANK(liste_groupe[[#This Row],[Code WF]])," ",IF(ISBLANK(liste_groupe[[#This Row],[Unité]]),CONCATENATE(liste_groupe[[#This Row],[Nom de l''échantillon donné par le client]],liste_groupe[[#This Row],[Dopage (+Testostérone / + EE2, ….)]]),CONCATENATE(liste_groupe[[#This Row],[Nom de l''échantillon donné par le client]],"-",liste_groupe[[#This Row],[Concentration]],liste_groupe[[#This Row],[Unité]],liste_groupe[[#This Row],[Dopage (+Testostérone / + EE2, ….)]])))
A36: =IF(ISBLANK(liste_groupe[[#This Row],[Code WF]])," ",IF(ISBLANK(liste_groupe[[#This Row],[Unité]]),CONCATENATE(liste_groupe[[#This Row],[Nom de l''échantillon donné par le client]],liste_groupe[[#This Row],[Dopage (+Testostérone / + EE2, ….)]]),CONCATENATE(liste_groupe[[#This Row],[Nom de l''échantillon donné par le client]],"-",liste_groupe[[#This Row],[Concentration]],liste_groupe[[#This Row],[Unité]],liste_groupe[[#This Row],[Dopage (+Testostérone / + EE2, ….)]]))) -> Testo -30µg/L | B36: Témoin | C36: 30 | D36: µg/L | E36: Testo
A37: =IF(ISBLANK(liste_groupe[[#This Row],[Code WF]])," ",IF(ISBLANK(liste_groupe[[#This Row],[Unité]]),CONCATENATE(liste_groupe[[#This Row],[Nom de l''échantillon donné par le client]],liste_groupe[[#This Row],[Dopage (+Testostérone / + EE2, ….)]]),CONCATENATE(liste_groupe[[#This Row],[Nom de l''échantillon donné par le client]],"-",liste_groupe[[#This Row],[Concentration]],liste_groupe[[#This Row],[Unité]],liste_groupe[[#This Row],[Dopage (+Testostérone / + EE2, ….)]]))) -> Testo 30µg/L + EE2 -64ng/L | B37: Témoin | C37: 64 | D37: ng/L | E37: Testo 30µg/L + EE2
A38: =IF(ISBLANK(liste_groupe[[#This Row],[Code WF]])," ",IF(ISBLANK(liste_groupe[[#This Row],[Unité]]),CONCATENATE(liste_groupe[[#This Row],[Nom de l''échantillon donné par le client]],liste_groupe[[#This Row],[Dopage (+Testostérone / + EE2, ….)]]),CONCATENATE(liste_groupe[[#This Row],[Nom de l''échantillon donné par le client]],"-",liste_groupe[[#This Row],[Concentration]],liste_groupe[[#This Row],[Unité]],liste_groupe[[#This Row],[Dopage (+Testostérone / + EE2, ….)]]))) -> Testo 30µg/L + FAD-10mg/L | B38: Témoin | C38: 10 | D38: mg/L | E38: Testo 30µg/L + FAD
A39: =IF(ISBLANK(liste_groupe[[#This Row],[Code WF]])," ",IF(ISBLANK(liste_groupe[[#This Row],[Unité]]),CONCATENATE(liste_groupe[[#This Row],[Nom de l''échantillon donné par le client]],liste_groupe[[#This Row],[Dopage (+Testostérone / + EE2, ….)]]),CONCATENATE(liste_groupe[[#This Row],[Nom de l''échantillon donné par le client]],"-",liste_groupe[[#This Row],[Concentration]],liste_groupe[[#This Row],[Unité]],liste_groupe[[#This Row],[Dopage (+Testostérone / + EE2, ….)]]))) -> Triphénylphosphate-0,18mg/L + Testostérone | B39: =B15 -> 0 | C39: =C15 -> 0.18 | D39: =D15 -> mg/L | E39: =E15 -> Triphénylphosphate | F39: + Testostérone
A40: =IF(ISBLANK(liste_groupe[[#This Row],[Code WF]])," ",IF(ISBLANK(liste_groupe[[#This Row],[Unité]]),CONCATENATE(liste_groupe[[#This Row],[Nom de l''échantillon donné par le client]],liste_groupe[[#This Row],[Dopage (+Testostérone / + EE2, ….)]]),CONCATENATE(liste_groupe[[#This Row],[Nom de l''échantillon donné par le client]],"-",liste_groupe[[#This Row],[Concentration]],liste_groupe[[#This Row],[Unité]],liste_groupe[[#This Row],[Dopage (+Testostérone / + EE2, ….)]]))) -> Triphénylphosphate-0,26mg/L + Testostérone | B40: =B16 -> 0 | C40: =C16 -> 0.26 | D40: =D16 -> mg/L | E40: =E16 -> Triphénylphosphate | F40: + Testostérone
A41: =IF(ISBLANK(liste_groupe[[#This Row],[Code WF]])," ",IF(ISBLANK(liste_groupe[[#This Row],[Unité]]),CONCATENATE(liste_groupe[[#This Row],[Nom de l''échantillon donné par le client]],liste_groupe[[#This Row],[Dopage (+Testostérone / + EE2, ….)]]),CONCATENATE(liste_groupe[[#This Row],[Nom de l''échantillon donné par le client]],"-",liste_groupe[[#This Row],[Concentration]],liste_groupe[[#This Row],[Unité]],liste_groupe[[#This Row],[Dopage (+Testostérone / + EE2, ….)]]))) -> Triphénylphosphate-0,4mg/L + Testostérone | B41: =B17 -> 0 | C41: =C17 -> 0.4 | D41: =D17 -> mg/L | E41: =E17 -> Triphénylphosphate | F41: + Testostérone
A42: =IF(ISBLANK(liste_groupe[[#This Row],[Code WF]])," ",IF(ISBLANK(liste_groupe[[#This Row],[Unité]]),CONCATENATE(liste_groupe[[#This Row],[Nom de l''échantillon donné par le client]],liste_groupe[[#This Row],[Dopage (+Testostérone / + EE2, ….)]]),CONCATENATE(liste_groupe[[#This Row],[Nom de l''échantillon donné par le client]],"-",liste_groupe[[#This Row],[Concentration]],liste_groupe[[#This Row],[Unité]],liste_groupe[[#This Row],[Dopage (+Testostérone / + EE2, ….)]]))) -> Triphénylphosphate-0,59mg/L + Testostérone | B42: =B18 -> 0 | C42: =C18 -> 0.59 | D42: =D18 -> mg/L | E42: =E18 -> Triphénylphosphate | F42: + Testostérone
A43: =IF(ISBLANK(liste_groupe[[#This Row],[Code WF]])," ",IF(ISBLANK(liste_groupe[[#This Row],[Unité]]),CONCATENATE(liste_groupe[[#This Row],[Nom de l''échantillon donné par le client]],liste_groupe[[#This Row],[Dopage (+Testostérone / + EE2, ….)]]),CONCATENATE(liste_groupe[[#This Row],[Nom de l''échantillon donné par le client]],"-",liste_groupe[[#This Row],[Concentration]],liste_groupe[[#This Row],[Unité]],liste_groupe[[#This Row],[Dopage (+Testostérone / + EE2, ….)]]))) -> Triphénylphosphate-0,89mg/L + Testostérone | B43: =B19 -> 0 | C43: =C19 -> 0.89 | D43: =D19 -> mg/L | E43: =E19 -> Triphénylphosphate | F43: + Testostérone
...

Sheet Feuil1
A1: Nom groupe | B1: N° de valeur | C1: file name | D1: total area | E1: mean intensity | G1: total fluorescence | I1: nbre de larves
A2: 01 EE2 0 | B2: A | C2: C:\Users\Olympus\Desktop\20190122\plaque1/@01 EE2 0/A1_1.tif | D2: 4931.616 | E2: 73.0526 | G2: 360268
A3: 01 EE2 0 | B3: A | C3: C:\Users\Olympus\Desktop\20190122\plaque1/@01 EE2 0/A1_2.tif | D3: 5234.4345 | E3: 71.1281 | G3: 372315
A4: 01 EE2 0 | B4: A | C4: C:\Users\Olympus\Desktop\20190122\plaque1/@01 EE2 0/A1_3.tif | D4: 3547.3027 | E4: 66.9878 | G4: 237626
A5: 01 EE2 0 | B5: A | C5: C:\Users\Olympus\Desktop\20190122\plaque3/@01 EE2 0/A1_3.tif | D5: 21456.8555 | E5: 67.0655 | G5: 1439015
A6: 01 EE2 0 | B6: A | C6: C:\Users\Olympus\Desktop\20190122\plaque3/@01 EE2 0/A1_2.tif | D6: 21586.6348 | E6: 66.4108 | G6: 1433586
A7: 01 EE2 0 | B7: A | C7: C:\Users\Olympus\Desktop\20190122\plaque3/@01 EE2 0/A1_1.tif | D7: 15984.4921 | E7: 69.7767 | G7: 1115346

Sheet Raw data R1
A1: Nom groupe | B1: N° de valeur | C1: file name | D1: total area | E1: mean intensity | G1: total fluorescence | I1: nbre de larves | J1: Colonne1 | L1: (Tous)
A2: =IFERROR(LEFT(RIGHT(C2,LEN(C2)-SEARCH("@",C2)),SEARCH("/",RIGHT(C2,LEN(C2)-SEARCH("@",C2)-1))),"") -> 01 TS | B2: =LEFT(RIGHT(RIGHT(Tableau4[[#This Row],[file name]],LEN(Tableau4[[#This Row],[file name]])-SEARCH("@",Tableau4[[#This Row],[file name]])),LEN(RIGHT(Tableau4[[#This Row],[file name]],LEN(Tableau4[[#This Row],[file name]])-SEARCH("@",Tableau4[[#This Row],[file name]])))-SEARCH("/",RIGHT(Tableau4[[#This Row],[file name]],LEN(Tableau4[[#This Row],[file name]])-SEARCH("@",Tableau4[[#This Row],[file name]])))),1) -> A | C2: \\192.168.24.208\images\R&D\Coralie\Triphenylphosphate\2021-CHG-CBA-TRIPHENYLP\plaque 1/@01 TS/A1_01- exclu.tif | K2: Filtre lignes : Enlever (vide) et Néant | L2: Filtre colonnes : Enlever (vide) et " "
A3: =IFERROR(LEFT(RIGHT(C3,LEN(C3)-SEARCH("@",C3)),SEARCH("/",RIGHT(C3,LEN(C3)-SEARCH("@",C3)-1))),"") -> 01 TS | B3: =LEFT(RIGHT(RIGHT(Tableau4[[#This Row],[file name]],LEN(Tableau4[[#This Row],[file name]])-SEARCH("@",Tableau4[[#This Row],[file name]])),LEN(RIGHT(Tableau4[[#This Row],[file name]],LEN(Tableau4[[#This Row],[file name]])-SEARCH("@",Tableau4[[#This Row],[file name]])))-SEARCH("/",RIGHT(Tableau4[[#This Row],[file name]],LEN(Tableau4[[#This Row],[file name]])-SEARCH("@",Tableau4[[#This Row],[file name]])))),1) -> A | C3: \\192.168.24.208\images\R&D\Coralie\Triphenylphosphate\2021-CHG-CBA-TRIPHENYLP\plaque 1/@01 TS/A1_02.tif | D3: 9062.9258 | E3: 76.9189 | G3: 697110 | K3: Moyenne de total fluorescence | L3: Étiquettes de colonnes
A4: =IFERROR(LEFT(RIGHT(C4,LEN(C4)-SEARCH("@",C4)),SEARCH("/",RIGHT(C4,LEN(C4)-SEARCH("@",C4)-1))),"") -> 01 TS | B4: =LEFT(RIGHT(RIGHT(Tableau4[[#This Row],[file name]],LEN(Tableau4[[#This Row],[file name]])-SEARCH("@",Tableau4[[#This Row],[file name]])),LEN(RIGHT(Tableau4[[#This Row],[file name]],LEN(Tableau4[[#This Row],[file name]])-SEARCH("@",Tableau4[[#This Row],[file name]])))-SEARCH("/",RIGHT(Tableau4[[#This Row],[file name]],LEN(Tableau4[[#This Row],[file name]])-SEARCH("@",Tableau4[[#This Row],[file name]])))),1) -> A | C4: \\192.168.24.208\images\R&D\Coralie\Triphenylphosphate\2021-CHG-CBA-TRIPHENYLP\plaque 1/@01 TS/A1_03.tif | D4: 9560.4134 | E4: 79.6335 | G4: 761329 | K4: Étiquettes de lignes | L4: 01 TS | M4: 02 EE2 34 | N4: 03 EE2 51 | O4: 04 EE2 76 | P4: 05 EE2 114 | Q4: 06 EE2 171 | R4: 07 EE2 488 | S4: 08 TRIPHENYLP 0.18 | T4: 09 TRIPHENYLP 0.26 | U4: 10 TRIPHENYLP 0.4 | V4: 11 TRIPHENYLP 0.59 | W4: 12 TRIPHENYLP 0.89 | X4: 01 TESTO | Y4: 02 TESTO | Z4: 03 TESTO + EE2 | AA4: 04 TESTO + FAD | AB4: 05 TRIPHENYLP 0.18 + TESTO | AC4: 06 TRIPHENYLP 0.26 + TESTO | AD4: 07 TRIPHENYLP 0.4 + TESTO | AE4: 08 TRIPHENYLP 0.59 + TESTO | AF4: 09 TRIPHENYLP 0.89 + TESTO
A5: =IFERROR(LEFT(RIGHT(C5,LEN(C5)-SEARCH("@",C5)),SEARCH("/",RIGHT(C5,LEN(C5)-SEARCH("@",C5)-1))),"") -> 01 TS | B5: =LEFT(RIGHT(RIGHT(Tableau4[[#This Row],[file name]],LEN(Tableau4[[#This Row],[file name]])-SEARCH("@",Tableau4[[#This Row],[file name]])),LEN(RIGHT(Tableau4[[#This Row],[file name]],LEN(Tableau4[[#This Row],[file name]])-SEARCH("@",Tableau4[[#This Row],[file name]])))-SEARCH("/",RIGHT(Tableau4[[#This Row],[file name]],LEN(Tableau4[[#This Row],[file name]])-SEARCH("@",Tableau4[[#This Row],[file name]])))),1) -> B | C5: \\192.168.24.208\images\R&D\Coralie\Triphenylphosphate\2021-CHG-CBA-TRIPHENYLP\plaque 1/@01 TS/B1_01.tif | D5: 3828.4913 | E5: 69.1695 | G5: 264815 | K5: A | L5: 729219.5 | M5: 413015.67 | N5: 908635.67 | O5: 475216 | P5: 1070932 | Q5: 2366973.7 | R5: 8194968.7 | S5: 292068.33 | T5: 896321 | U5: 593315.33 | V5: 420326.33 | W5: 5132716.3 | X5: 5700422 | Y5: 3447653.7 | Z5: 4565198.7 | AA5: 316575 | AB5: 3953894 | AC5: 3514468.7 | AD5: 5397495 | AE5: 3812146.3 | AF5: 5842440
A6: =IFERROR(LEFT(RIGHT(C6,LEN(C6)-SEARCH("@",C6)),SEARCH("/",RIGHT(C6,LEN(C6)-SEARCH("@",C6)-1))),"") -> 01 TS | B6: =LEFT(RIGHT(RIGHT(Tableau4[[#This Row],[file name]],LEN(Tableau4[[#This Row],[file name]])-SEARCH("@",Tableau4[[#This Row],[file name]])),LEN(RIGHT(Tableau4[[#This Row],[file name]],LEN(Tableau4[[#This Row],[file name]])-SEARCH("@",Tableau4[[#This Row],[file name]])))-SEARCH("/",RIGHT(Tableau4[[#This Row],[file name]],LEN(Tableau4[[#This Row],[file name]])-SEARCH("@",Tableau4[[#This Row],[file name]])))),1) -> B | C6: \\192.168.24.208\images\R&D\Coralie\Triphenylphosphate\2021-CHG-CBA-TRIPHENYLP\plaque 1/@01 TS/B1_02- exclu.tif | K6: B | L6: 282713.5 | M6: 660285 | N6: 567244.33 | O6: 450507.33 | P6: 3767459 | Q6: 2932336 | R6: 5952994 | S6: 639646.33 | T6: 185555.67 | U6: 231331.67 | V6: 1426614.3 | X6: 3054033 | Y6: 2711970.3 | Z6: 5159292.3 | AA6: 35084 | AB6: 5074611.3 | AC6: 5260779.7 | AD6: 6270838 | AE6: 6570052 | AF6: 3379541
A7: =IFERROR(LEFT(RIGHT(C7,LEN(C7)-SEARCH("@",C7)),SEARCH("/",RIGHT(C7,LEN(C7)-SEARCH("@",C7)-1))),"") -> 01 TS | B7: =LEFT(RIGHT(RIGHT(Tableau4[[#This Row],[file name]],LEN(Tableau4[[#This Row],[file name]])-SEARCH("@",Tableau4[[#This Row],[file name]])),LEN(RIGHT(Tableau4[[#This Row],[file name]],LEN(Tableau4[[#This Row],[file name]])-SEARCH("@",Tableau4[[#This Row],[file name]])))-SEARCH("/",RIGHT(Tableau4[[#This Row],[file name]],LEN(Tableau4[[#This Row],[file name]])-SEARCH("@",Tableau4[[#This Row],[file name]])))),1) -> B | C7: \\192.168.24.208\images\R&D\Coralie\Triphenylphosphate\2021-CHG-CBA-TRIPHENYLP\plaque 1/@01 TS/B1_03.tif | D7: 4434.1284 | E7: 67.7951 | G7: 300612 | K7: C | L7: 184106.67 | M7: 234886.33 | N7: 458954 | O7: 859478.33 | P7: 673187.33 | Q7: 3818195.7 | R7: 6442889.7 | S7: 35159.5 | T7: 171164.67 | U7: 555290 | V7: 793572 | W7: 3019079 | X7: 2811014 | Y7: 3509818.5 | Z7: 4033622.3 | AA7: 450990.67 | AB7: 5036405.3 | AC7: 5678474.3 | AD7: 5158686.3 | AE7: 4598523 | AF7: 6780049
A8: =IFERROR(LEFT(RIGHT(C8,LEN(C8)-SEARCH("@",C8)),SEARCH("/",RIGHT(C8,LEN(C8)-SEARCH("@",C8)-1))),"") -> 01 TS | B8: =LEFT(RIGHT(RIGHT(Tableau4[[#This Row],[file name]],LEN(Tableau4[[#This Row],[file name]])-SEARCH("@",Tableau4[[#This Row],[file name]])),LEN(RIGHT(Tableau4[[#This Row],[file name]],LEN(Tableau4[[#This Row],[file name]])-SEARCH("@",Tableau4[[#This Row],[file name]])))-SEARCH("/",RIGHT(Tableau4[[#This Row],[file name]],LEN(Tableau4[[#This Row],[file name]])-SEARCH("@",Tableau4[[#This Row],[file name]])))),1) -> C | C8: \\192.168.24.208\images\R&D\Coralie\Triphenylphosphate\2021-CHG-CBA-TRIPHENYLP\plaque 1/@01 TS/C1_01.tif | D8: 2638.8471 | E8: 67.082 | G8: 177019 | K8: D | L8: 537741 | M8: 378660 | N8: 947093.67 | O8: 855534.33 | P8: 1056014.7 | Q8: 4073961.7 | R8: 6987249 | S8: 680671 | T8: 75048.333 | U8: 835880 | V8: 3350946.5 | W8: 1340390 | X8: 2858974.3 | Y8: 3232868.7 | Z8: 3484035.3 | AA8: 423376.33 | AB8: 3682720.3 | AC8: 3979028 | AD8: 3793991.5 | AE8: 3533358.7 | AF8: 6393559
A9: =IFERROR(LEFT(RIGHT(C9,LEN(C9)-SEARCH("@",C9)),SEARCH("/",RIGHT(C9,LEN(C9)-SEARCH("@",C9)-1))),"") -> 01 TS | B9: =LEFT(RIGHT(RIGHT(Tableau4[[#This Row],[file name]],LEN(Tableau4[[#This Row],[file name]])-SEARCH("@",Tableau4[[#This Row],[file name]])),LEN(RIGHT(Tableau4[[#This Row],[file name]],LEN(Tableau4[[#This Row],[file name]])-SEARCH("@",Tableau4[[#This Row],[file name]])))-SEARCH("/",RIGHT(Tableau4[[#This Row],[file name]],LEN(Tableau4[[#This Row],[file name]])-SEARCH("@",Tableau4[[#This Row],[file name]])))),1) -> C | C9: \\192.168.24.208\images\R&D\Coralie\Triphenylphosphate\2021-CHG-CBA-TRIPHENYLP\plaque 1/@01 TS/C1_02.tif | D9: 735.4164 | E9: 63.6765 | G9: 46829 | K9: E | L9: 342650 | M9: 103830.33 | N9: 505836.67 | O9: 219406.33 | P9: 2359100.7 | Q9: 1528620.3 | R9: 4390977 | S9: 310281 | T9: 672437.33 | U9: 783420 | V9: 2390881.7 | W9: 4075836.3 | X9: 3195449 | Y9: 4445570.3 | Z9: 2478576.7 | AA9: 181958 | AB9: 4368892.7 | AC9: 5344628 | AD9: 4611962 | AE9: 3855204.3 | AF9: 3475859
A10: =IFERROR(LEFT(RIGHT(C10,LEN(C10)-SEARCH("@",C10)),SEARCH("/",RIGHT(C10,LEN(C10)-SEARCH("@",C10)-1))),"") -> 01 TS | B10: =LEFT(RIGHT(RIGHT(Tableau4[[#This Row],[file name]],LEN(Tableau4[[#This Row],[file name]])-SEARCH("@",Tableau4[[#This Row],[file name]])),LEN(RIGHT(Tableau4[[#This Row],[file name]],LEN(Tableau4[[#This Row],[file name]])-SEARCH("@",Tableau4[[#This Row],[file name]])))-SEARCH("/",RIGHT(Tableau4[[#This Row],[file name]],LEN(Tableau4[[#This Row],[file name]])-SEARCH("@",Tableau4[[#This Row],[file name]])))),1) -> C | C10: \\192.168.24.208\images\R&D\Coralie\Triphenylphosphate\2021-CHG-CBA-TRIPHENYLP\plaque 1/@01 TS/C1_03.tif | D10: 4866.7263 | E10: 67.4933 | G10: 328472 | K10: F | L10: 893282 | N10: 682279 | P10: 252074.67 | Q10: 2462916.7 | R10: 4346931 | S10: 333417.33 | T10: 1192686.7 | U10: 556616.67 | V10: 721277.67 | W10: 3379455 | X10: 3910728 | Y10: 3696188.7 | Z10: 3579639.3 | AA10: 105539.67 | AB10: 4825305 | AC10: 32802 | AD10: 3965898.7 | AE10: 2793083 | AF10: 5557628.3
A11: =IFERROR(LEFT(RIGHT(C11,LEN(C11)-SEARCH("@",C11)),SEARCH("/",RIGHT(C11,LEN(C11)-SEARCH("@",C11)-1))),"") -> 01 TS | B11: =LEFT(RIGHT(RIGHT(Tableau4[[#This Row],[file name]],LEN(Tableau4[[#This Row],[file name]])-SEARCH("@",Tableau4[[#This Row],[file name]])),LEN(RIGHT(Tableau4[[#This Row],[file name]],LEN(Tableau4[[#This Row],[file name]])-SEARCH("@",Tableau4[[#This Row],[file name]])))-SEARCH("/",RIGHT(Tableau4[[#This Row],[file name]],LEN(Tableau4[[#This Row],[file name]])-SEARCH("@",Tableau4[[#This Row],[file name]])))),1) -> D | C11: \\192.168.24.208\images\R&D\Coralie\Triphenylphosphate\2021-CHG-CBA-TRIPHENYLP\plaque 1/@01 TS/D1_01.tif | D11: 11615.2534 | E11: 74.4115 | G11: 864309 | K11: G | L11: 308961 | M11: 412864.33 | P11: 2308053.7 | Q11: 713058.33 | R11: 5154685 | S11: 201122 | T11: 893758 | U11: 1711963 | V11: 909148 | X11: 1448309 | Y11: 2895096.5 | Z11: 3431546.7 | AA11: 415878 | AB11: 2937739.5 | AC11: 5504902 | AD11: 5336751.3 | AE11: 4948985 | AF11: 4730234.3
A12: =IFERROR(LEFT(RIGHT(C12,LEN(C12)-SEARCH("@",C12)),SEARCH("/",RIGHT(C12,LEN(C12)-SEARCH("@",C12)-1))),"") -> 01 TS | B12: =LEFT(RIGHT(RIGHT(Tableau4[[#This Row],[file name]],LEN(Tableau4[[#This Row],[file name]])-SEARCH("@",Tableau4[[#This Row],[file name]])),LEN(RIGHT(Tableau4[[#This Row],[file name]],LEN(Tableau4[[#This Row],[file name]])-SEARCH("@",Tableau4[[#This Row],[file name]])))-SEARCH("/",RIGHT(Tableau4[[#This Row],[file name]],LEN(Tableau4[[#This Row],[file name]])-SEARCH("@",Tableau4[[#This Row],[file name]])))),1) -> D | C12: \\192.168.24.208\images\R&D\Coralie\Triphenylphosphate\2021-CHG-CBA-TRIPHENYLP\plaque 1/@01 TS/D1_02.tif | D12: 3201.2244 | E12: 65.9662 | G12: 211173 | K12: H | L12: 261159.33 | M12: 864258.67 | N12: 270784.67 | O12: 229633.5 | P12: 1703195.3 | Q12: 3234138 | R12: 5845320.7 | S12: 176817.33 | T12: 412648 | V12: 1172282.7 | X12: 4555724.3 | Y12: 3916799 | Z12: 4351188.5 | AA12: 90809.333 | AB12: 2767516.3 | AC12: 2103125 | AD12: 4050868.3 | AE12: 5272589.7 | AF12: 4674350
A13: =IFERROR(LEFT(RIGHT(C13,LEN(C13)-SEARCH("@",C13)),SEARCH("/",RIGHT(C13,LEN(C13)-SEARCH("@",C13)-1))),"") -> 01 TS | B13: =LEFT(RIGHT(RIGHT(Tableau4[[#This Row],[file name]],LEN(Tableau4[[#This Row],[file name]])-SEARCH("@",Tableau4[[#This Row],[file name]])),LEN(RIGHT(Tableau4[[#This Row],[file name]],LEN(Tableau4[[#This Row],[file name]])-SEARCH("@",Tableau4[[#This Row],[file name]])))-SEARCH("/",RIGHT(Tableau4[[#This Row],[file name]],LEN(Tableau4[[#This Row],[file name]])-SEARCH("@",Tableau4[[#This Row],[file name]])))),1) -> D | C13: \\192.168.24.208\images\R&D\Coralie\Triphenylphosphate\2021-CHG-CBA-TRIPHENYLP\plaque 1/@01 TS/D1_03- exclu.tif
A14: =IFERROR(LEFT(RIGHT(C14,LEN(C14)-SEARCH("@",C14)),SEARCH("/",RIGHT(C14,LEN(C14)-SEARCH("@",C14)-1))),"") -> 01 TS | B14: =LEFT(RIGHT(RIGHT(Tableau4[[#This Row],[file name]],LEN(Tableau4[[#This Row],[file name]])-SEARCH("@",Tableau4[[#This Row],[file name]])),LEN(RIGHT(Tableau4[[#This Row],[file name]],LEN(Tableau4[[#This Row],[file name]])-SEARCH("@",Tableau4[[#This Row],[file name]])))-SEARCH("/",RIGHT(Tableau4[[#This Row],[file name]],LEN(Tableau4[[#This Row],[file name]])-SEARCH("@",Tableau4[[#This Row],[file name]])))),1) -> E | C14: \\192.168.24.208\images\R&D\Coralie\Triphenylphosphate\2021-CHG-CBA-TRIPHENYLP\plaque 1/@01 TS/E1_01.tif | D14: 6597.1179 | E14: 68.3639 | G14: 451005
A15: =IFERROR(LEFT(RIGHT(C15,LEN(C15)-SEARCH("@",C15)),SEARCH("/",RIGHT(C15,LEN(C15)-SEARCH("@",C15)-1))),"") -> 01 TS | B15: =LEFT(RIGHT(RIGHT(Tableau4[[#This Row],[file name]],LEN(Tableau4[[#This Row],[file name]])-SEARCH("@",Tableau4[[#This Row],[file name]])),LEN(RIGHT(Tableau4[[#This Row],[file name]],LEN(Tableau4[[#This Row],[file name]])-SEARCH("@",Tableau4[[#This Row],[file name]])))-SEARCH("/",RIGHT(Tableau4[[#This Row],[file name]],LEN(Tableau4[[#This Row],[file name]])-SEARCH("@",Tableau4[[#This Row],[file name]])))),1) -> E | C15: \\192.168.24.208\images\R&D\Coralie\Triphenylphosphate\2021-CHG-CBA-TRIPHENYLP\plaque 1/@01 TS/E1_02.tif | D15: 3633.8223 | E15: 64.4762 | G15: 234295
A16: =IFERROR(LEFT(RIGHT(C16,LEN(C16)-SEARCH("@",C16)),SEARCH("/",RIGHT(C16,LEN(C16)-SEARCH("@",C16)-1))),"") -> 01 TS | B16: =LEFT(RIGHT(RIGHT(Tableau4[[#This Row],[file name]],LEN(Tableau4[[#This Row],[file name]])-SEARCH("@",Tableau4[[#This Row],[file name]])),LEN(RIGHT(Tableau4[[#This Row],[file name]],LEN(Tableau4[[#This Row],[file name]])-SEARCH("@",Tableau4[[#This Row],[file name]])))-SEARCH("/",RIGHT(Tableau4[[#This Row],[file name]],LEN(Tableau4[[#This Row],[file name]])-SEARCH("@",Tableau4[[#This Row],[file name]])))),1) -> E | C16: \\192.168.24.208\images\R&D\Coralie\Triphenylphosphate\2021-CHG-CBA-TRIPHENYLP\plaque 1/@01 TS/E1_03- exclu.tif
A17: =IFERROR(LEFT(RIGHT(C17,LEN(C17)-SEARCH("@",C17)),SEARCH("/",RIGHT(C17,LEN(C17)-SEARCH("@",C17)-1))),"") -> 01 TS | B17: =LEFT(RIGHT(RIGHT(Tableau4[[#This Row],[file name]],LEN(Tableau4[[#This Row],[file name]])-SEARCH("@",Tableau4[[#This Row],[file name]])),LEN(RIGHT(Tableau4[[#This Row],[file name]],LEN(Tableau4[[#This Row],[file name]])-SEARCH("@",Tableau4[[#This Row],[file name]])))-SEARCH("/",RIGHT(Tableau4[[#This Row],[file name]],LEN(Tableau4[[#This Row],[file name]])-SEARCH("@",Tableau4[[#This Row],[file name]])))),1) -> F | C17: \\192.168.24.208\images\R&D\Coralie\Triphenylphosphate\2021-CHG-CBA-TRIPHENYLP\plaque 1/@01 TS/F1_01.tif | D17: 12329.0399 | E17: 71.5526 | G17: 882175
A18: =IFERROR(LEFT(RIGHT(C18,LEN(C18)-SEARCH("@",C18)),SEARCH("/",RIGHT(C18,LEN(C18)-SEARCH("@",C18)-1))),"") -> 01 TS | B18: =LEFT(RIGHT(RIGHT(Tableau4[[#This Row],[file name]],LEN(Tableau4[[#This Row],[file name]])-SEARCH("@",Tableau4[[#This Row],[file name]])),LEN(RIGHT(Tableau4[[#This Row],[file name]],LEN(Tableau4[[#This Row],[file name]])-SEARCH("@",Tableau4[[#This Row],[file name]])))-SEARCH("/",RIGHT(Tableau4[[#This Row],[file name]],LEN(Tableau4[[#This Row],[file name]])-SEARCH("@",Tableau4[[#This Row],[file name]])))),1) -> F | C18: \\192.168.24.208\images\R&D\Coralie\Triphenylphosphate\2021-CHG-CBA-TRIPHENYLP\plaque 1/@01 TS/F1_02.tif | D18: 12631.8585 | E18: 71.5959 | G18: 904389
A19: =IFERROR(LEFT(RIGHT(C19,LEN(C19)-SEARCH("@",C19)),SEARCH("/",RIGHT(C19,LEN(C19)-SEARCH("@",C19)-1))),"") -> 01 TS | B19: =LEFT(RIGHT(RIGHT(Tableau4[[#This Row],[file name]],LEN(Tableau4[[#This Row],[file name]])-SEARCH("@",Tableau4[[#This Row],[file name]])),LEN(RIGHT(Tableau4[[#This Row],[file name]],LEN(Tableau4[[#This Row],[file name]])-SEARCH("@",Tableau4[[#This Row],[file name]])))-SEARCH("/",RIGHT(Tableau4[[#This Row],[file name]],LEN(Tableau4[[#This Row],[file name]])-SEARCH("@",Tableau4[[#This Row],[file name]])))),1) -> F | C19: \\192.168.24.208\images\R&D\Coralie\Triphenylphosphate\2021-CHG-CBA-TRIPHENYLP\plaque 1/@01 TS/F1_03- exclu.tif
A20: =IFERROR(LEFT(RIGHT(C20,LEN(C20)-SEARCH("@",C20)),SEARCH("/",RIGHT(C20,LEN(C20)-SEARCH("@",C20)-1))),"") -> 01 TS | B20: =LEFT(RIGHT(RIGHT(Tableau4[[#This Row],[file name]],LEN(Tableau4[[#This Row],[file name]])-SEARCH("@",Tableau4[[#This Row],[file name]])),LEN(RIGHT(Tableau4[[#This Row],[file name]],LEN(Tableau4[[#This Row],[file name]])-SEARCH("@",Tableau4[[#This Row],[file name]])))-SEARCH("/",RIGHT(Tableau4[[#This Row],[file name]],LEN(Tableau4[[#This Row],[file name]])-SEARCH("@",Tableau4[[#This Row],[file name]])))),1) -> G | C20: \\192.168.24.208\images\R&D\Coralie\Triphenylphosphate\2021-CHG-CBA-TRIPHENYLP\plaque 1/@01 TS/G1_01.tif | D20: 6056.3705 | E20: 67.525 | G20: 408956
A21: =IFERROR(LEFT(RIGHT(C21,LEN(C21)-SEARCH("@",C21)),SEARCH("/",RIGHT(C21,LEN(C21)-SEARCH("@",C21)-1))),"") -> 01 TS | B21: =LEFT(RIGHT(RIGHT(Tableau4[[#This Row],[file name]],LEN(Tableau4[[#This Row],[file name]])-SEARCH("@",Tableau4[[#This Row],[file name]])),LEN(RIGHT(Tableau4[[#This Row],[file name]],LEN(Tableau4[[#This Row],[file name]])-SEARCH("@",Tableau4[[#This Row],[file name]])))-SEARCH("/",RIGHT(Tableau4[[#This Row],[file name]],LEN(Tableau4[[#This Row],[file name]])-SEARCH("@",Tableau4[[#This Row],[file name]])))),1) -> G | C21: \\192.168.24.208\images\R&D\Coralie\Triphenylphosphate\2021-CHG-CBA-TRIPHENYLP\plaque 1/@01 TS/G1_02.tif | D21: 2768.6265 | E21: 65.0078 | G21: 179982
A22: =IFERROR(LEFT(RIGHT(C22,LEN(C22)-SEARCH("@",C22)),SEARCH("/",RIGHT(C22,LEN(C22)-SEARCH("@",C22)-1))),"") -> 01 TS | B22: =LEFT(RIGHT(RIGHT(Tableau4[[#This Row],[file name]],LEN(Tableau4[[#This Row],[file name]])-SEARCH("@",Tableau4[[#This Row],[file name]])),LEN(RIGHT(Tableau4[[#This Row],[file name]],LEN(Tableau4[[#This Row],[file name]])-SEARCH("@",Tableau4[[#This Row],[file name]])))-SEARCH("/",RIGHT(Tableau4[[#This Row],[file name]],LEN(Tableau4[[#This Row],[file name]])-SEARCH("@",Tableau4[[#This Row],[file name]])))),1) -> G | C22: \\192.168.24.208\images\R&D\Coralie\Triphenylphosphate\2021-CHG-CBA-TRIPHENYLP\plaque 1/@01 TS/G1_03.tif | D22: 4823.4665 | E22: 70.0628 | G22: 337945
A23: =IFERROR(LEFT(RIGHT(C23,LEN(C23)-SEARCH("@",C23)),SEARCH("/",RIGHT(C23,LEN(C23)-SEARCH("@",C23)-1))),"") -> 01 TS | B23: =LEFT(RIGHT(RIGHT(Tableau4[[#This Row],[file name]],LEN(Tableau4[[#This Row],[file name]])-SEARCH("@",Tableau4[[#This Row],[file name]])),LEN(RIGHT(Tableau4[[#This Row],[file name]],LEN(Tableau4[[#This Row],[file name]])-SEARCH("@",Tableau4[[#This Row],[file name]])))-SEARCH("/",RIGHT(Tableau4[[#This Row],[file name]],LEN(Tableau4[[#This Row],[file name]])-SEARCH("@",Tableau4[[#This Row],[file name]])))),1) -> H | C23: \\192.168.24.208\images\R&D\Coralie\Triphenylphosphate\2021-CHG-CBA-TRIPHENYLP\plaque 1/@01 TS/H1_01.tif | D23: 5796.8118 | E23: 70.2836 | G23: 407421
A24: =IFERROR(LEFT(RIGHT(C24,LEN(C24)-SEARCH("@",C24)),SEARCH("/",RIGHT(C24,LEN(C24)-SEARCH("@",C24)-1))),"") -> 01 TS | B24: =LEFT(RIGHT(RIGHT(Tableau4[[#This Row],[file name]],LEN(Tableau4[[#This Row],[file name]])-SEARCH("@",Tableau4[[#This Row],[file name]])),LEN(RIGHT(Tableau4[[#This Row],[file name]],LEN(Tableau4[[#This Row],[file name]])-SEARCH("@",Tableau4[[#This Row],[file name]])))-SEARCH("/",RIGHT(Tableau4[[#This Row],[file name]],LEN(Tableau4[[#This Row],[file name]])-SEARCH("@",Tableau4[[#This Row],[file name]])))),1) -> H | C24: \\192.168.24.208\images\R&D\Coralie\Triphenylphosphate\2021-CHG-CBA-TRIPHENYLP\plaque 1/@01 TS/H1_02.tif | D24: 1925.0606 | E24: 67.6404 | G24: 130212
A25: =IFERROR(LEFT(RIGHT(C25,LEN(C25)-SEARCH("@",C25)),SEARCH("/",RIGHT(C25,LEN(C25)-SEARCH("@",C25)-1))),"") -> 01 TS | B25: =LEFT(RIGHT(RIGHT(Tableau4[[#This Row],[file name]],LEN(Tableau4[[#This Row],[file name]])-SEARCH("@",Tableau4[[#This Row],[file name]])),LEN(RIGHT(Tableau4[[#This Row],[file name]],LEN(Tableau4[[#This Row],[file name]])-SEARCH("@",Tableau4[[#This Row],[file name]])))-SEARCH("/",RIGHT(Tableau4[[#This Row],[file name]],LEN(Tableau4[[#This Row],[file name]])-SEARCH("@",Tableau4[[#This Row],[file name]])))),1) -> H | C25: \\192.168.24.208\images\R&D\Coralie\Triphenylphosphate\2021-CHG-CBA-TRIPHENYLP\plaque 1/@01 TS/H1_03.tif | D25: 3655.4522 | E25: 67.2544 | G25: 245845
A26: =IFERROR(LEFT(RIGHT(C26,LEN(C26)-SEARCH("@",C26)),SEARCH("/",RIGHT(C26,LEN(C26)-SEARCH("@",C26)-1))),"") | B26: =LEFT(RIGHT(RIGHT(Tableau4[[#This Row],[file name]],LEN(Tableau4[[#This Row],[file name]])-SEARCH("@",Tableau4[[#This Row],[file name]])),LEN(RIGHT(Tableau4[[#This Row],[file name]],LEN(Tableau4[[#This Row],[file name]])-SEARCH("@",Tableau4[[#This Row],[file name]])))-SEARCH("/",RIGHT(Tableau4[[#This Row],[file name]],LEN(Tableau4[[#This Row],[file name]])-SEARCH("@",Tableau4[[#This Row],[file name]])))),1) -> #VALUE!
A27: =IFERROR(LEFT(RIGHT(C27,LEN(C27)-SEARCH("@",C27)),SEARCH("/",RIGHT(C27,LEN(C27)-SEARCH("@",C27)-1))),"") | B27: =LEFT(RIGHT(RIGHT(Tableau4[[#This Row],[file name]],LEN(Tableau4[[#This Row],[file name]])-SEARCH("@",Tableau4[[#This Row],[file name]])),LEN(RIGHT(Tableau4[[#This Row],[file name]],LEN(Tableau4[[#This Row],[file name]])-SEARCH("@",Tableau4[[#This Row],[file name]])))-SEARCH("/",RIGHT(Tableau4[[#This Row],[file name]],LEN(Tableau4[[#This Row],[file name]])-SEARCH("@",Tableau4[[#This Row],[file name]])))),1) -> #VALUE! | C27: group | E27: mean of mean fluo | F27: SD mean fluo | G27: mean of total fluo | H27: SD total fluo | I27: n fluorescent | J27: n total
A28: =IFERROR(LEFT(RIGHT(C28,LEN(C28)-SEARCH("@",C28)),SEARCH("/",RIGHT(C28,LEN(C28)-SEARCH("@",C28)-1))),"") -> 01 TS | B28: =LEFT(RIGHT(RIGHT(Tableau4[[#This Row],[file name]],LEN(Tableau4[[#This Row],[file name]])-SEARCH("@",Tableau4[[#This Row],[file name]])),LEN(RIGHT(Tableau4[[#This Row],[file name]],LEN(Tableau4[[#This Row],[file name]])-SEARCH("@",Tableau4[[#This Row],[file name]])))-SEARCH("/",RIGHT(Tableau4[[#This Row],[file name]],LEN(Tableau4[[#This Row],[file name]])-SEARCH("@",Tableau4[[#This Row],[file name]])))),1) | C28: \\192.168.24.208\images\R&D\Coralie\Triphenylphosphate\2021-CHG-CBA-TRIPHENYLP\plaque 1/@01 TS/ | E28: 69.2368 | F28: 5.948 | G28: 388801.792 | H28: 319828.217 | I28: 24 | J28: 24
A29: =IFERROR(LEFT(RIGHT(C29,LEN(C29)-SEARCH("@",C29)),SEARCH("/",RIGHT(C29,LEN(C29)-SEARCH("@",C29)-1))),"") | B29: =LEFT(RIGHT(RIGHT(Tableau4[[#This Row],[file name]],LEN(Tableau4[[#This Row],[file name]])-SEARCH("@",Tableau4[[#This Row],[file name]])),LEN(RIGHT(Tableau4[[#This Row],[file name]],LEN(Tableau4[[#This Row],[file name]])-SEARCH("@",Tableau4[[#This Row],[file name]])))-SEARCH("/",RIGHT(Tableau4[[#This Row],[file name]],LEN(Tableau4[[#This Row],[file name]])-SEARCH("@",Tableau4[[#This Row],[file name]])))),1) -> #VALUE!
A30: =IFERROR(LEFT(RIGHT(C30,LEN(C30)-SEARCH("@",C30)),SEARCH("/",RIGHT(C30,LEN(C30)-SEARCH("@",C30)-1))),"") | B30: =LEFT(RIGHT(RIGHT(Tableau4[[#This Row],[file name]],LEN(Tableau4[[#This Row],[file name]])-SEARCH("@",Tableau4[[#This Row],[file name]])),LEN(RIGHT(Tableau4[[#This Row],[file name]],LEN(Tableau4[[#This Row],[file name]])-SEARCH("@",Tableau4[[#This Row],[file name]])))-SEARCH("/",RIGHT(Tableau4[[#This Row],[file name]],LEN(Tableau4[[#This Row],[file name]])-SEARCH("@",Tableau4[[#This Row],[file name]])))),1) -> #VALUE!
A31: =IFERROR(LEFT(RIGHT(C31,LEN(C31)-SEARCH("@",C31)),SEARCH("/",RIGHT(C31,LEN(C31)-SEARCH("@",C31)-1))),"") | B31: =LEFT(RIGHT(RIGHT(Tableau4[[#This Row],[file name]],LEN(Tableau4[[#This Row],[file name]])-SEARCH("@",Tableau4[[#This Row],[file name]])),LEN(RIGHT(Tableau4[[#This Row],[file name]],LEN(Tableau4[[#This Row],[file name]])-SEARCH("@",Tableau4[[#This Row],[file name]])))-SEARCH("/",RIGHT(Tableau4[[#This Row],[file name]],LEN(Tableau4[[#This Row],[file name]])-SEARCH("@",Tableau4[[#This Row],[file name]])))),1) -> #VALUE!
A32: =IFERROR(LEFT(RIGHT(C32,LEN(C32)-SEARCH("@",C32)),SEARCH("/",RIGHT(C32,LEN(C32)-SEARCH("@",C32)-1))),"") | B32: =LEFT(RIGHT(RIGHT(Tableau4[[#This Row],[file name]],LEN(Tableau4[[#This Row],[file name]])-SEARCH("@",Tableau4[[#This Row],[file name]])),LEN(RIGHT(Tableau4[[#This Row],[file name]],LEN(Tableau4[[#This Row],[file name]])-SEARCH("@",Tableau4[[#This Row],[file name]])))-SEARCH("/",RIGHT(Tableau4[[#This Row],[file name]],LEN(Tableau4[[#This Row],[file name]])-SEARCH("@",Tableau4[[#This Row],[file name]])))),1) -> #VALUE!
A33: =IFERROR(LEFT(RIGHT(C33,LEN(C33)-SEARCH("@",C33)),SEARCH("/",RIGHT(C33,LEN(C33)-SEARCH("@",C33)-1))),"") | B33: =LEFT(RIGHT(RIGHT(Tableau4[[#This Row],[file name]],LEN(Tableau4[[#This Row],[file name]])-SEARCH("@",Tableau4[[#This Row],[file name]])),LEN(RIGHT(Tableau4[[#This Row],[file name]],LEN(Tableau4[[#This Row],[file name]])-SEARCH("@",Tableau4[[#This Row],[file name]])))-SEARCH("/",RIGHT(Tableau4[[#This Row],[file name]],LEN(Tableau4[[#This Row],[file name]])-SEARCH("@",Tableau4[[#This Row],[file name]])))),1) -> #VALUE!
A34: =IFERROR(LEFT(RIGHT(C34,LEN(C34)-SEARCH("@",C34)),SEARCH("/",RIGHT(C34,LEN(C34)-SEARCH("@",C34)-1))),"") | B34: =LEFT(RIGHT(RIGHT(Tableau4[[#This Row],[file name]],LEN(Tableau4[[#This Row],[file name]])-SEARCH("@",Tableau4[[#This Row],[file name]])),LEN(RIGHT(Tableau4[[#This Row],[file name]],LEN(Tableau4[[#This Row],[file name]])-SEARCH("@",Tableau4[[#This Row],[file name]])))-SEARCH("/",RIGHT(Tableau4[[#This Row],[file name]],LEN(Tableau4[[#This Row],[file name]])-SEARCH("@",Tableau4[[#This Row],[file name]])))),1) -> #VALUE! | C34: file name | D34: total area | E34: mean intensity | G34: total fluorescence
A35: =IFERROR(LEFT(RIGHT(C35,LEN(C35)-SEARCH("@",C35)),SEARCH("/",RIGHT(C35,LEN(C35)-SEARCH("@",C35)-1))),"") -> 02 EE2 34 | B35: =LEFT(RIGHT(RIGHT(Tableau4[[#This Row],[file name]],LEN(Tableau4[[#This Row],[file name]])-SEARCH("@",Tableau4[[#This Row],[file name]])),LEN(RIGHT(Tableau4[[#This Row],[file name]],LEN(Tableau4[[#This Row],[file name]])-SEARCH("@",Tableau4[[#This Row],[file name]])))-SEARCH("/",RIGHT(Tableau4[[#This Row],[file name]],LEN(Tableau4[[#This Row],[file name]])-SEARCH("@",Tableau4[[#This Row],[file name]])))),1) -> A | C35: \\192.168.24.208\images\R&D\Coralie\Triphenylphosphate\2021-CHG-CBA-TRIPHENYLP\plaque 1/@02 EE2 34/A2_01.tif | D35: 6186.1499 | E35: 68.9301 | G35: 426412
A36: =IFERROR(LEFT(RIGHT(C36,LEN(C36)-SEARCH("@",C36)),SEARCH("/",RIGHT(C36,LEN(C36)-SEARCH("@",C36)-1))),"") -> 02 EE2 34 | B36: =LEFT(RIGHT(RIGHT(Tableau4[[#This Row],[file name]],LEN(Tableau4[[#This Row],[file name]])-SEARCH("@",Tableau4[[#This Row],[file name]])),LEN(RIGHT(Tableau4[[#This Row],[file name]],LEN(Tableau4[[#This Row],[file name]])-SEARCH("@",Tableau4[[#This Row],[file name]])))-SEARCH("/",RIGHT(Tableau4[[#This Row],[file name]],LEN(Tableau4[[#This Row],[file name]])-SEARCH("@",Tableau4[[#This Row],[file name]])))),1) -> A | C36: \\192.168.24.208\images\R&D\Coralie\Triphenylphosphate\2021-CHG-CBA-TRIPHENYLP\plaque 1/@02 EE2 34/A2_02.tif | D36: 7267.6446 | E36: 71.8125 | G36: 521908
A37: =IFERROR(LEFT(RIGHT(C37,LEN(C37)-SEARCH("@",C37)),SEARCH("/",RIGHT(C37,LEN(C37)-SEARCH("@",C37)-1))),"") -> 02 EE2 34 | B37: =LEFT(RIGHT(RIGHT(Tableau4[[#This Row],[file name]],LEN(Tableau4[[#This Row],[file name]])-SEARCH("@",Tableau4[[#This Row],[file name]])),LEN(RIGHT(Tableau4[[#This Row],[file name]],LEN(Tableau4[[#This Row],[file name]])-SEARCH("@",Tableau4[[#This Row],[file name]])))-SEARCH("/",RIGHT(Tableau4[[#This Row],[file name]],LEN(Tableau4[[#This Row],[file name]])-SEARCH("@",Tableau4[[#This Row],[file name]])))),1) -> A | C37: \\192.168.24.208\images\R&D\Coralie\Triphenylphosphate\2021-CHG-CBA-TRIPHENYLP\plaque 1/@02 EE2 34/A2_03.tif | D37: 4390.8686 | E37: 66.2118 | G37: 290727
A38: =IFERROR(LEFT(RIGHT(C38,LEN(C38)-SEARCH("@",C38)),SEARCH("/",RIGHT(C38,LEN(C38)-SEARCH("@",C38)-1))),"") -> 02 EE2 34 | B38: =LEFT(RIGHT(RIGHT(Tableau4[[#This Row],[file name]],LEN(Tableau4[[#This Row],[file name]])-SEARCH("@",Tableau4[[#This Row],[file name]])),LEN(RIGHT(Tableau4[[#This Row],[file name]],LEN(Tableau4[[#This Row],[file name]])-SEARCH("@",Tableau4[[#This Row],[file name]])))-SEARCH("/",RIGHT(Tableau4[[#This Row],[file name]],LEN(Tableau4[[#This Row],[file name]])-SEARCH("@",Tableau4[[#This Row],[file name]])))),1) -> B | C38: \\192.168.24.208\images\R&D\Coralie\Triphenylphosphate\2021-CHG-CBA-TRIPHENYLP\plaque 1/@02 EE2 34/B2_01.tif | D38: 10490.4989 | E38: 72.6928 | G38: 762584
A39: =IFERROR(LEFT(RIGHT(C39,LEN(C39)-SEARCH("@",C39)),SEARCH("/",RIGHT(C39,LEN(C39)-SEARCH("@",C39)-1))),"") -> 02 EE2 34 | B39: =LEFT(RIGHT(RIGHT(Tableau4[[#This Row],[file name]],LEN(Tableau4[[#This Row],[file name]])-SEARCH("@",Tableau4[[#This Row],[file name]])),LEN(RIGHT(Tableau4[[#This Row],[file name]],LEN(Tableau4[[#This Row],[file name]])-SEARCH("@",Tableau4[[#This Row],[file name]])))-SEARCH("/",RIGHT(Tableau4[[#This Row],[file name]],LEN(Tableau4[[#This Row],[file name]])-SEARCH("@",Tableau4[[#This Row],[file name]])))),1) -> B | C39: \\192.168.24.208\images\R&D\Coralie\Triphenylphosphate\2021-CHG-CBA-TRIPHENYLP\plaque 1/@02 EE2 34/B2_02- exclu.tif
A40: =IFERROR(LEFT(RIGHT(C40,LEN(C40)-SEARCH("@",C40)),SEARCH("/",RIGHT(C40,LEN(C40)-SEARCH("@",C40)-1))),"") -> 02 EE2 34 | B40: =LEFT(RIGHT(RIGHT(Tableau4[[#This Row],[file name]],LEN(Tableau4[[#This Row],[file name]])-SEARCH("@",Tableau4[[#This Row],[file name]])),LEN(RIGHT(Tableau4[[#This Row],[file name]],LEN(Tableau4[[#This Row],[file name]])-SEARCH("@",Tableau4[[#This Row],[file name]])))-SEARCH("/",RIGHT(Tableau4[[#This Row],[file name]],LEN(Tableau4[[#This Row],[file name]])-SEARCH("@",Tableau4[[#This Row],[file name]])))),1) -> B | C40: \\192.168.24.208\images\R&D\Coralie\Triphenylphosphate\2021-CHG-CBA-TRIPHENYLP\plaque 1/@02 EE2 34/B2_03.tif | D40: 8067.9507 | E40: 69.1609 | G40: 557986
...

Sheet R1
A1: 3. Expérimentateur 1 : copier et coller les valeurs des intensités totales de fluorescences obtenues dans le fichier raw data lors du traitement des images.
A3: R1 | B3: Non dopé | AE3: avec testo
A4: Noms des groupes | B4: ='Page de garde'!A7 -> Témoin solvant | C4: ='Page de garde'!A9 -> EE2-33,8ng/L | D4: ='Page de garde'!A10 -> EE2-50,6ng/L | E4: ='Page de garde'!A11 -> EE2-76ng/L | F4: ='Page de garde'!A12 -> EE2-114ng/L | G4: ='Page de garde'!A13 -> EE2-170,9ng/L | H4: ='Page de garde'!A14 -> EE2-488ng/L | I4: ='Page de garde'!A15 -> Triphénylphosphate-0,18mg/L | J4: ='Page de garde'!A16 -> Triphénylphosphate-0,26mg/L | K4: ='Page de garde'!A17 -> Triphénylphosphate-0,4mg/L | L4: ='Page de garde'!A18 -> Triphénylphosphate-0,59mg/L | M4: ='Page de garde'!A19 -> Triphénylphosphate-0,89mg/L | N4: ='Page de garde'!A20 | O4: ='Page de garde'!A36 -> Testo -30µg/L | P4: ='Page de garde'!A37 -> Testo 30µg/L + EE2 -64ng/L | Q4: ='Page de garde'!A38 -> Testo 30µg/L + FAD-10mg/L | R4: ='Page de garde'!A39 -> Triphénylphosphate-0,18mg/L + Testostérone | S4: ='Page de garde'!A40 -> Triphénylphosphate-0,26mg/L + Testostérone | T4: ='Page de garde'!A41 -> Triphénylphosphate-0,4mg/L + Testostérone | U4: ='Page de garde'!A42 -> Triphénylphosphate-0,59mg/L + Testostérone | V4: ='Page de garde'!A43 -> Triphénylphosphate-0,89mg/L + Testostérone | W4: ='Page de garde'!A44 -> 0-00 + Testostérone | X4: ='Page de garde'!A45 -> 0-00 + Testostérone | Y4: ='Page de garde'!A46 -> 0-00 + Testostérone | Z4: ='Page de garde'!A47 -> 0-00 + Testostérone | AA4: ='Page de garde'!A48 -> 0-00 + Testostérone | AB4: ='Page de garde'!A49 -> 0-00 + Testostérone | AC4: ='Page de garde'!A50 -> 0-00 + Testostérone | AD4: ='Page de garde'!A51 -> 0-00 + Testostérone | AE4: ='Page de garde'!A52 -> 0-00 + Testostérone | AF4: ='Page de garde'!A53 -> 0-00 + Testostérone | AG4: ='Page de garde'!A54 -> 0-00 + Testostérone | AH4: ='Page de garde'!A55 -> 0-00 + Testostérone | AI4: ='Page de garde'!A56 -> 0-00 + Testostérone | AJ4: ='Page de garde'!A57 -> 0-00 + Testostérone | AK4: ='Page de garde'!A58 -> 0-00 + Testostérone
A5: Données brutes | B5: 729219.5 | C5: 413015.67 | D5: 908635.67 | E5: 475216 | F5: 1070932 | G5: 2366973.7 | H5: 8194968.7 | I5: 292068.33 | J5: 896321 | K5: 593315.33 | L5: 420326.33 | M5: 5132716.3 | O5: 5700422 | P5: 4565198.7 | Q5: 316575 | R5: 3953894 | S5: 3514468.7 | T5: 5397495 | U5: 3812146.3 | V5: 5842440
B6: 282713.5 | C6: 660285 | D6: 567244.33 | E6: 450507.33 | F6: 3767459 | G6: 2932336 | H6: 5952994 | I6: 639646.33 | J6: 185555.67 | K6: 231331.67 | L6: 1426614.3 | O6: 3054033 | P6: 5159292.3 | Q6: 35084 | R6: 5074611.3 | S6: 5260779.7 | T6: 6270838 | U6: 6570052 | V6: 3379541
B7: 184106.67 | C7: 234886.33 | D7: 458954 | E7: 859478.33 | F7: 673187.33 | G7: 3818195.7 | H7: 6442889.7 | I7: 35159.5 | J7: 171164.67 | K7: 555290 | L7: 793572 | M7: 3019079 | O7: 2811014 | P7: 4033622.3 | Q7: 450990.67 | R7: 5036405.3 | S7: 5678474.3 | T7: 5158686.3 | U7: 4598523 | V7: 6780049
B8: 537741 | C8: 378660 | D8: 947093.67 | E8: 855534.33 | F8: 1056014.7 | G8: 4073961.7 | H8: 6987249 | I8: 680671 | J8: 75048.333 | K8: 835880 | L8: 3350946.5 | M8: 1340390 | O8: 2858974.3 | P8: 3484035.3 | Q8: 423376.33 | R8: 3682720.3 | S8: 3979028 | T8: 3793991.5 | U8: 3533358.7 | V8: 6393559
B9: 342650 | C9: 103830.33 | D9: 505836.67 | E9: 219406.33 | F9: 2359100.7 | G9: 1528620.3 | H9: 4390977 | I9: 310281 | J9: 672437.33 | K9: 783420 | L9: 2390881.7 | M9: 4075836.3 | O9: 3195449 | P9: 2478576.7 | Q9: 181958 | R9: 4368892.7 | S9: 5344628 | T9: 4611962 | U9: 3855204.3 | V9: 3475859
B10: 893282 | D10: 682279 | F10: 252074.67 | G10: 2462916.7 | H10: 4346931 | I10: 333417.33 | J10: 1192686.7 | K10: 556616.67 | L10: 721277.67 | M10: 3379455 | O10: 3910728 | P10: 3579639.3 | Q10: 105539.67 | R10: 4825305 | S10: 32802 | T10: 3965898.7 | U10: 2793083 | V10: 5557628.3
B11: 308961 | C11: 412864.33 | F11: 2308053.7 | G11: 713058.33 | H11: 5154685 | I11: 201122 | J11: 893758 | K11: 1711963 | L11: 909148 | O11: 1448309 | P11: 3431546.7 | Q11: 415878 | R11: 2937739.5 | S11: 5504902 | T11: 5336751.3 | U11: 4948985 | V11: 4730234.3
B12: 261159.33 | C12: 864258.67 | D12: 270784.67 | E12: 229633.5 | F12: 1703195.3 | G12: 3234138 | H12: 5845320.7 | I12: 176817.33 | J12: 412648 | L12: 1172282.7 | O12: 4555724.3 | P12: 4351188.5 | Q12: 90809.333 | R12: 2767516.3 | S12: 2103125 | T12: 4050868.3 | U12: 5272589.7 | V12: 4674350
O13: 3447653.7
O14: 2711970.3
O15: 3509818.5
O16: 3232868.7
O17: 4445570.3
O18: 3696188.7
O19: 2895096.5
O20: 3916799
A22: =A4 -> Noms des groupes | B22: =B4 -> Témoin solvant | C22: =C4 -> EE2-33,8ng/L | D22: =D4 -> EE2-50,6ng/L | E22: =E4 -> EE2-76ng/L | F22: =F4 -> EE2-114ng/L | G22: =G4 -> EE2-170,9ng/L | H22: =H4 -> EE2-488ng/L | ... N22: =N4 | O22: =#REF! -> #REF! | P22: =#REF! -> #REF! | Q22: =#REF! -> #REF! | R22: =#REF! -> #REF! | S22: =#REF! -> #REF! | T22: =#REF! -> #REF! | U22: =#REF! -> #REF! | V22: =#REF! -> #REF! | ... AC22: =#REF! -> #REF! | AD22: Nom des groupes | AE22: =O4 -> Testo -30µg/L | AF22: =P4 -> Testo 30µg/L + EE2 -64ng/L | AG22: =Q4 -> Testo 30µg/L + FAD-10mg/L | AH22: =R4 -> Triphénylphosphate-0,18mg/L + Testostérone | AI22: =S4 -> Triphénylphosphate-0,26mg/L + Testostérone | AJ22: =T4 -> Triphénylphosphate-0,4mg/L + Testostérone | AK22: =U4 -> Triphénylphosphate-0,59mg/L + Testostérone | AL22: =V4 -> Triphénylphosphate-0,89mg/L + Testostérone | ... BA22: =AK4 -> 0-00 + Testostérone
A23: mean | B23: =AVERAGE(B5:B20) -> 442479.13 | C23: =AVERAGE(C5:C20) -> 438257.19 | D23: =AVERAGE(D5:D20) -> 620118.29 | E23: =AVERAGE(E5:E20) -> 514962.64 | F23: =AVERAGE(F5:F20) -> 1648752.2 | G23: =AVERAGE(G5:G20) -> 2641275 | H23: =AVERAGE(H5:H20) -> 5914501.9 | I23: =AVERAGE(I5:I20) -> 333647.85 | ... N23: =AVERAGE(N5:N20) -> #DIV/0! | O23: =AVERAGE(#REF!) -> #REF! | P23: =AVERAGE(#REF!) -> #REF! | Q23: =AVERAGE(#REF!) -> #REF! | R23: =AVERAGE(#REF!) -> #REF! | S23: =AVERAGE(#REF!) -> #REF! | T23: =AVERAGE(#REF!) -> #REF! | U23: =AVERAGE(#REF!) -> #REF! | V23: =AVERAGE(#REF!) -> #REF! | ... AC23: =AVERAGE(#REF!) -> #REF! | AD23: mean | AE23: =AVERAGE(O5:O20) -> 3461913.7 | AF23: =AVERAGE(P5:P20) -> 3885387.5 | AG23: =AVERAGE(Q5:Q20) -> 252526.38 | AH23: =AVERAGE(R5:R20) -> 4080885.6 | AI23: =AVERAGE(S5:S20) -> 3927276 | AJ23: =AVERAGE(T5:T20) -> 4823311.4 | AK23: =AVERAGE(U5:U20) -> 4422992.8 | AL23: =AVERAGE(V5:V20) -> 5104207.6 | ... BA23: =AVERAGE(AK5:AK20) -> #DIV/0!
A24: SD | B24: =STDEV(B5:B20) -> 252832.33 | C24: =STDEV(C5:C20) -> 254561.19 | D24: =STDEV(D5:D20) -> 244227.69 | E24: =STDEV(E5:E20) -> 286070.16 | F24: =STDEV(F5:F20) -> 1135077.4 | G24: =STDEV(G5:G20) -> 1129918.4 | H24: =STDEV(H5:H20) -> 1308898.4 | I24: =STDEV(I5:I20) -> 222835.39 | ... N24: =STDEV(N5:N20) -> #DIV/0! | O24: =STDEV(#REF!) -> #REF! | P24: =STDEV(#REF!) -> #REF! | Q24: =STDEV(#REF!) -> #REF! | R24: =STDEV(#REF!) -> #REF! | S24: =STDEV(#REF!) -> #REF! | T24: =STDEV(#REF!) -> #REF! | U24: =STDEV(#REF!) -> #REF! | V24: =STDEV(#REF!) -> #REF! | ... AC24: =STDEV(#REF!) -> #REF! | AD24: SD | AE24: =STDEV(O5:O20) -> 954148.77 | AF24: =STDEV(P5:P20) -> 824930.7 | AG24: =STDEV(Q5:Q20) -> 168769.64 | AH24: =STDEV(R5:R20) -> 905854.09 | AI24: =STDEV(S5:S20) -> 2000366.4 | AJ24: =STDEV(T5:T20) -> 864961.59 | AK24: =STDEV(U5:U20) -> 1182172.9 | AL24: =STDEV(V5:V20) -> 1263333.3 | ... BA24: =STDEV(AK5:AK20) -> #DIV/0!
B26: Non dopé | AE26: avec testo
A27: Noms des groupes | B27: =B4 -> Témoin solvant | C27: =C4 -> EE2-33,8ng/L | D27: =D4 -> EE2-50,6ng/L | E27: =E4 -> EE2-76ng/L | F27: =F4 -> EE2-114ng/L | G27: =G4 -> EE2-170,9ng/L | H27: =H4 -> EE2-488ng/L | I27: =I4 -> Triphénylphosphate-0,18mg/L | ... N27: =N4 | P27: =O4 -> Testo -30µg/L | Q27: =P4 -> Testo 30µg/L + EE2 -64ng/L | R27: =Q4 -> Testo 30µg/L + FAD-10mg/L | S27: =R4 -> Triphénylphosphate-0,18mg/L + Testostérone | T27: =S4 -> Triphénylphosphate-0,26mg/L + Testostérone | U27: =T4 -> Triphénylphosphate-0,4mg/L + Testostérone | V27: =U4 -> Triphénylphosphate-0,59mg/L + Testostérone | W27: =V4 -> Triphénylphosphate-0,89mg/L + Testostérone | ... AL27: =AK4 -> 0-00 + Testostérone
A28: Données normalisées sur la moyenne du groupe "Testo" | B28: =IF(B5="","",(B5/$AE$23)) -> 0.21064058 | C28: =IF(C5="","",(C5/$AE$23)) -> 0.1193027 | D28: =IF(D5="","",(D5/$AE$23)) -> 0.2624663 | E28: =IF(E5="","",(E5/$AE$23)) -> 0.13726974 | F28: =IF(F5="","",(F5/$AE$23)) -> 0.30934682 | G28: =IF(G5="","",(G5/$AE$23)) -> 0.68371827 | H28: =IF(H5="","",(H5/$AE$23)) -> 2.3671788 | I28: =IF(I5="","",(I5/$AE$23)) -> 0.084366151 | ... N28: =IF(N5="","",(N5/$AE$23)) | P28: =IF(O5="","",(O5/$AE$23)) -> 1.6466101 | Q28: =IF(P5="","",(P5/$AE$23)) -> 1.3186922 | R28: =IF(Q5="","",(Q5/$AE$23)) -> 0.091445087 | S28: =IF(R5="","",(R5/$AE$23)) -> 1.1421122 | T28: =IF(S5="","",(S5/$AE$23)) -> 1.0151809 | U28: =IF(T5="","",(T5/$AE$23)) -> 1.5591073 | V28: =IF(U5="","",(U5/$AE$23)) -> 1.1011673 | W28: =IF(V5="","",(V5/$AE$23)) -> 1.6876331 | ... AL28: =IF(AK5="","",(AK5/$AE$23))
B29: =IF(B6="","",(B6/$AE$23)) -> 0.081663936 | C29: =IF(C6="","",(C6/$AE$23)) -> 0.19072832 | D29: =IF(D6="","",(D6/$AE$23)) -> 0.16385282 | E29: =IF(E6="","",(E6/$AE$23)) -> 0.13013246 | F29: =IF(F6="","",(F6/$AE$23)) -> 1.0882591 | G29: =IF(G6="","",(G6/$AE$23)) -> 0.84702747 | H29: =IF(H6="","",(H6/$AE$23)) -> 1.7195674 | I29: =IF(I6="","",(I6/$AE$23)) -> 0.18476669 | ... N29: =IF(N6="","",(N6/$AE$23)) | P29: =IF(O6="","",(O6/$AE$23)) -> 0.88218057 | Q29: =IF(P6="","",(P6/$AE$23)) -> 1.4903007 | R29: =IF(Q6="","",(Q6/$AE$23)) -> 0.010134279 | S29: =IF(R6="","",(R6/$AE$23)) -> 1.4658399 | T29: =IF(S6="","",(S6/$AE$23)) -> 1.5196161 | U29: =IF(T6="","",(T6/$AE$23)) -> 1.8113791 | V29: =IF(U6="","",(U6/$AE$23)) -> 1.8978093 | W29: =IF(V6="","",(V6/$AE$23)) -> 0.97620602 | ... AL29: =IF(AK6="","",(AK6/$AE$23))
B30: =IF(B7="","",(B7/$AE$23)) -> 0.053180605 | C30: =IF(C7="","",(C7/$AE$23)) -> 0.067848697 | D30: =IF(D7="","",(D7/$AE$23)) -> 0.13257234 | E30: =IF(E7="","",(E7/$AE$23)) -> 0.24826683 | F30: =IF(F7="","",(F7/$AE$23)) -> 0.19445526 | G30: =IF(G7="","",(G7/$AE$23)) -> 1.1029147 | H30: =IF(H7="","",(H7/$AE$23)) -> 1.8610775 | I30: =IF(I7="","",(I7/$AE$23)) -> 0.010156088 | ... N30: =IF(N7="","",(N7/$AE$23)) | P30: =IF(O7="","",(O7/$AE$23)) -> 0.81198269 | Q30: =IF(P7="","",(P7/$AE$23)) -> 1.1651424 | R30: =IF(Q7="","",(Q7/$AE$23)) -> 0.13027207 | S30: =IF(R7="","",(R7/$AE$23)) -> 1.4548038 | T30: =IF(S7="","",(S7/$AE$23)) -> 1.6402703 | U30: =IF(T7="","",(T7/$AE$23)) -> 1.4901256 | V30: =IF(U7="","",(U7/$AE$23)) -> 1.3283182 | W30: =IF(V7="","",(V7/$AE$23)) -> 1.9584685 | ... AL30: =IF(AK7="","",(AK7/$AE$23))
B31: =IF(B8="","",(B8/$AE$23)) -> 0.15533056 | C31: =IF(C8="","",(C8/$AE$23)) -> 0.10937881 | D31: =IF(D8="","",(D8/$AE$23)) -> 0.27357518 | E31: =IF(E8="","",(E8/$AE$23)) -> 0.24712757 | F31: =IF(F8="","",(F8/$AE$23)) -> 0.30503784 | G31: =IF(G8="","",(G8/$AE$23)) -> 1.1767947 | H31: =IF(H8="","",(H8/$AE$23)) -> 2.0183198 | I31: =IF(I8="","",(I8/$AE$23)) -> 0.19661697 | ... N31: =IF(N8="","",(N8/$AE$23)) | P31: =IF(O8="","",(O8/$AE$23)) -> 0.82583639 | Q31: =IF(P8="","",(P8/$AE$23)) -> 1.00639 | R31: =IF(Q8="","",(Q8/$AE$23)) -> 0.12229546 | S31: =IF(R8="","",(R8/$AE$23)) -> 1.0637817 | T31: =IF(S8="","",(S8/$AE$23)) -> 1.1493724 | U31: =IF(T8="","",(T8/$AE$23)) -> 1.0959232 | V31: =IF(U8="","",(U8/$AE$23)) -> 1.0206374 | W31: =IF(V8="","",(V8/$AE$23)) -> 1.846828 | ... AL31: =IF(AK8="","",(AK8/$AE$23))
B32: =IF(B9="","",(B9/$AE$23)) -> 0.098977048 | C32: =IF(C9="","",(C9/$AE$23)) -> 0.029992178 | D32: =IF(D9="","",(D9/$AE$23)) -> 0.14611475 | E32: =IF(E9="","",(E9/$AE$23)) -> 0.063377181 | F32: =IF(F9="","",(F9/$AE$23)) -> 0.6814441 | G32: =IF(G9="","",(G9/$AE$23)) -> 0.44155356 | H32: =IF(H9="","",(H9/$AE$23)) -> 1.268367 | I32: =IF(I9="","",(I9/$AE$23)) -> 0.089627017 | ... N32: =IF(N9="","",(N9/$AE$23)) | P32: =IF(O9="","",(O9/$AE$23)) -> 0.92302965 | Q32: =IF(P9="","",(P9/$AE$23)) -> 0.71595565 | R32: =IF(Q9="","",(Q9/$AE$23)) -> 0.052559947 | S32: =IF(R9="","",(R9/$AE$23)) -> 1.2619877 | T32: =IF(S9="","",(S9/$AE$23)) -> 1.5438363 | U32: =IF(T9="","",(T9/$AE$23)) -> 1.3322002 | V32: =IF(U9="","",(U9/$AE$23)) -> 1.113605 | W32: =IF(V9="","",(V9/$AE$23)) -> 1.0040282 | ... AL32: =IF(AK9="","",(AK9/$AE$23))
