Workbook

Sheet Page de garde
A1: 1. Expérimentateur 1 : copier et coller le n° de prestation et renseigner la date de réalisation de chaque réplica ainsi que le visa de l'expérimentateur.
A2: R1 | B2: Numéro d'expérience : | E2: Date de réalisation :
A3: R2 | B3: Numéro d'expérience : | E3: Date de réalisation :
A4: R3 | B4: Numéro d'expérience : | E4: Date de réalisation :
A5: 2. Expérimentateur 1 : copier et coller la dilution appliquée et le nom donné pour chaque des échantillons par le client. Conserver la mise en forme de l'exemple en italique. Ne pas remplir la colonne "nom sur graphique".
A6: Nom sur le graphique | B6: Code WF | C6: Concentration | D6: Unité | E6: Nom de l'échantillon donné par le client | F6: Dopage (+Testostérone / + EE2, ….)
A7: =IF(ISBLANK(liste_groupe[[#This Row],[Code WF]])," ",IF(ISBLANK(liste_groupe[[#This Row],[Unité]]),CONCATENATE(liste_groupe[[#This Row],[Nom de l''échantillon donné par le client]],liste_groupe[[#This Row],[Dopage (+Testostérone / + EE2, ….)]]),CONCATENATE(liste_groupe[[#This Row],[Nom de l''échantillon donné par le client]],"-",liste_groupe[[#This Row],[Concentration]],liste_groupe[[#This Row],[Unité]],liste_groupe[[#This Row],[Dopage (+Testostérone / + EE2, ….)]]))) -> Témoin solvant | B7: Témoin | E7: Témoin solvant
A8: =IF(ISBLANK(liste_groupe[[#This Row],[Code WF]])," ",IF(ISBLANK(liste_groupe[[#This Row],[Unité]]),CONCATENATE(liste_groupe[[#This Row],[Nom de l''échantillon donné par le client]],liste_groupe[[#This Row],[Dopage (+Testostérone / + EE2, ….)]]),CONCATENATE(liste_groupe[[#This Row],[Nom de l''échantillon donné par le client]],"-",liste_groupe[[#This Row],[Concentration]],liste_groupe[[#This Row],[Unité]],liste_groupe[[#This Row],[Dopage (+Testostérone / + EE2, ….)]]))) -> EE2-22.5ng/L | B8: Témoin | C8: 22.5 | D8: ng/L | E8: EE2
A9: =IF(ISBLANK(liste_groupe[[#This Row],[Code WF]])," ",IF(ISBLANK(liste_groupe[[#This Row],[Unité]]),CONCATENATE(liste_groupe[[#This Row],[Nom de l''échantillon donné par le client]],liste_groupe[[#This Row],[Dopage (+Testostérone / + EE2, ….)]]),CONCATENATE(liste_groupe[[#This Row],[Nom de l''échantillon donné par le client]],"-",liste_groupe[[#This Row],[Concentration]],liste_groupe[[#This Row],[Unité]],liste_groupe[[#This Row],[Dopage (+Testostérone / + EE2, ….)]]))) -> EE2-33.8ng/L | B9: Témoin | C9: 33.8 | D9: ng/L | E9: EE2
A10: =IF(ISBLANK(liste_groupe[[#This Row],[Code WF]])," ",IF(ISBLANK(liste_groupe[[#This Row],[Unité]]),CONCATENATE(liste_groupe[[#This Row],[Nom de l''échantillon donné par le client]],liste_groupe[[#This Row],[Dopage (+Testostérone / + EE2, ….)]]),CONCATENATE(liste_groupe[[#This Row],[Nom de l''échantillon donné par le client]],"-",liste_groupe[[#This Row],[Concentration]],liste_groupe[[#This Row],[Unité]],liste_groupe[[#This Row],[Dopage (+Testostérone / + EE2, ….)]]))) -> EE2-50.6ng/L | B10: Témoin | C10: 50.6 | D10: ng/L | E10: EE2
A11: =IF(ISBLANK(liste_groupe[[#This Row],[Code WF]])," ",IF(ISBLANK(liste_groupe[[#This Row],[Unité]]),CONCATENATE(liste_groupe[[#This Row],[Nom de l''échantillon donné par le client]],liste_groupe[[#This Row],[Dopage (+Testostérone / + EE2, ….)]]),CONCATENATE(liste_groupe[[#This Row],[Nom de l''échantillon donné par le client]],"-",liste_groupe[[#This Row],[Concentration]],liste_groupe[[#This Row],[Unité]],liste_groupe[[#This Row],[Dopage (+Testostérone / + EE2, ….)]]))) -> EE2-76ng/L | B11: Témoin | C11: 76 | D11: ng/L | E11: EE2
A12: =IF(ISBLANK(liste_groupe[[#This Row],[Code WF]])," ",IF(ISBLANK(liste_groupe[[#This Row],[Unité]]),CONCATENATE(liste_groupe[[#This Row],[Nom de l''échantillon donné par le client]],liste_groupe[[#This Row],[Dopage (+Testostérone / + EE2, ….)]]),CONCATENATE(liste_groupe[[#This Row],[Nom de l''échantillon donné par le client]],"-",liste_groupe[[#This Row],[Concentration]],liste_groupe[[#This Row],[Unité]],liste_groupe[[#This Row],[Dopage (+Testostérone / + EE2, ….)]]))) -> EE2-114ng/L | B12: Témoin | C12: 114 | D12: ng/L | E12: EE2
A13: =IF(ISBLANK(liste_groupe[[#This Row],[Code WF]])," ",IF(ISBLANK(liste_groupe[[#This Row],[Unité]]),CONCATENATE(liste_groupe[[#This Row],[Nom de l''échantillon donné par le client]],liste_groupe[[#This Row],[Dopage (+Testostérone / + EE2, ….)]]),CONCATENATE(liste_groupe[[#This Row],[Nom de l''échantillon donné par le client]],"-",liste_groupe[[#This Row],[Concentration]],liste_groupe[[#This Row],[Unité]],liste_groupe[[#This Row],[Dopage (+Testostérone / + EE2, ….)]]))) -> EE2-170.9ng/L | B13: Témoin | C13: 170.9 | D13: ng/L | E13: EE2
A14: =IF(ISBLANK(liste_groupe[[#This Row],[Code WF]])," ",IF(ISBLANK(liste_groupe[[#This Row],[Unité]]),CONCATENATE(liste_groupe[[#This Row],[Nom de l''échantillon donné par le client]],liste_groupe[[#This Row],[Dopage (+Testostérone / + EE2, ….)]]),CONCATENATE(liste_groupe[[#This Row],[Nom de l''échantillon donné par le client]],"-",liste_groupe[[#This Row],[Concentration]],liste_groupe[[#This Row],[Unité]],liste_groupe[[#This Row],[Dopage (+Testostérone / + EE2, ….)]]))) -> EE2-488ng/L | B14: Témoin | C14: 488 | D14: ng/L | E14: EE2
A15: Dutasteride-0,01mg/L | C15: 0.01 | D15: mg/L | E15: Dutasteride
A16: Dutasteride-0,1mg/L | C16: 0.1 | D16: mg/L | E16: Dutasteride
A17: Dutasteride-0,25mg/L | C17: 0.25 | D17: mg/L | E17: Dutasteride
A18: Dutasteride-0,5mg/L | C18: 0.5 | D18: mg/L | E18: Dutasteride
A19: Dutasteride-1mg/L | C19: 1 | D19: mg/L | E19: Dutasteride
A20: =IF(ISBLANK(liste_groupe[[#This Row],[Code WF]])," ",IF(ISBLANK(liste_groupe[[#This Row],[Unité]]),CONCATENATE(liste_groupe[[#This Row],[Nom de l''échantillon donné par le client]],liste_groupe[[#This Row],[Dopage (+Testostérone / + EE2, ….)]]),CONCATENATE(liste_groupe[[#This Row],[Nom de l''échantillon donné par le client]],"-",liste_groupe[[#This Row],[Concentration]],liste_groupe[[#This Row],[Unité]],liste_groupe[[#This Row],[Dopage (+Testostérone / + EE2, ….)]])))
A21: =IF(ISBLANK(liste_groupe[[#This Row],[Code WF]])," ",IF(ISBLANK(liste_groupe[[#This Row],[Unité]]),CONCATENATE(liste_groupe[[#This Row],[Nom de l''échantillon donné par le client]],liste_groupe[[#This Row],[Dopage (+Testostérone / + EE2, ….)]]),CONCATENATE(liste_groupe[[#This Row],[Nom de l''échantillon donné par le client]],"-",liste_groupe[[#This Row],[Concentration]],liste_groupe[[#This Row],[Unité]],liste_groupe[[#This Row],[Dopage (+Testostérone / + EE2, ….)]])))
A22: =IF(ISBLANK(liste_groupe[[#This Row],[Code WF]])," ",IF(ISBLANK(liste_groupe[[#This Row],[Unité]]),CONCATENATE(liste_groupe[[#This Row],[Nom de l''échantillon donné par le client]],liste_groupe[[#This Row],[Dopage (+Testostérone / + EE2, ….)]]),CONCATENATE(liste_groupe[[#This Row],[Nom de l''échantillon donné par le client]],"-",liste_groupe[[#This Row],[Concentration]],liste_groupe[[#This Row],[Unité]],liste_groupe[[#This Row],[Dopage (+Testostérone / + EE2, ….)]])))
A23: =IF(ISBLANK(liste_groupe[[#This Row],[Code WF]])," ",IF(ISBLANK(liste_groupe[[#This Row],[Unité]]),CONCATENATE(liste_groupe[[#This Row],[Nom de l''échantillon donné par le client]],liste_groupe[[#This Row],[Dopage (+Testostérone / + EE2, ….)]]),CONCATENATE(liste_groupe[[#This Row],[Nom de l''échantillon donné par le client]],"-",liste_groupe[[#This Row],[Concentration]],liste_groupe[[#This Row],[Unité]],liste_groupe[[#This Row],[Dopage (+Testostérone / + EE2, ….)]])))
A24: =IF(ISBLANK(liste_groupe[[#This Row],[Code WF]])," ",IF(ISBLANK(liste_groupe[[#This Row],[Unité]]),CONCATENATE(liste_groupe[[#This Row],[Nom de l''échantillon donné par le client]],liste_groupe[[#This Row],[Dopage (+Testostérone / + EE2, ….)]]),CONCATENATE(liste_groupe[[#This Row],[Nom de l''échantillon donné par le client]],"-",liste_groupe[[#This Row],[Concentration]],liste_groupe[[#This Row],[Unité]],liste_groupe[[#This Row],[Dopage (+Testostérone / + EE2, ….)]])))
A25: =IF(ISBLANK(liste_groupe[[#This Row],[Code WF]])," ",IF(ISBLANK(liste_groupe[[#This Row],[Unité]]),CONCATENATE(liste_groupe[[#This Row],[Nom de l''échantillon donné par le client]],liste_groupe[[#This Row],[Dopage (+Testostérone / + EE2, ….)]]),CONCATENATE(liste_groupe[[#This Row],[Nom de l''échantillon donné par le client]],"-",liste_groupe[[#This Row],[Concentration]],liste_groupe[[#This Row],[Unité]],liste_groupe[[#This Row],[Dopage (+Testostérone / + EE2, ….)]])))
A26: =IF(ISBLANK(liste_groupe[[#This Row],[Code WF]])," ",IF(ISBLANK(liste_groupe[[#This Row],[Unité]]),CONCATENATE(liste_groupe[[#This Row],[Nom de l''échantillon donné par le client]],liste_groupe[[#This Row],[Dopage (+Testostérone / + EE2, ….)]]),CONCATENATE(liste_groupe[[#This Row],[Nom de l''échantillon donné par le client]],"-",liste_groupe[[#This Row],[Concentration]],liste_groupe[[#This Row],[Unité]],liste_groupe[[#This Row],[Dopage (+Testostérone / + EE2, ….)]])))
A27: =IF(ISBLANK(liste_groupe[[#This Row],[Code WF]])," ",IF(ISBLANK(liste_groupe[[#This Row],[Unité]]),CONCATENATE(liste_groupe[[#This Row],[Nom de l''échantillon donné par le client]],liste_groupe[[#This Row],[Dopage (+Testostérone / + EE2, ….)]]),CONCATENATE(liste_groupe[[#This Row],[Nom de l''échantillon donné par le client]],"-",liste_groupe[[#This Row],[Concentration]],liste_groupe[[#This Row],[Unité]],liste_groupe[[#This Row],[Dopage (+Testostérone / + EE2, ….)]])))
A28: =IF(ISBLANK(liste_groupe[[#This Row],[Code WF]])," ",IF(ISBLANK(liste_groupe[[#This Row],[Unité]]),CONCATENATE(liste_groupe[[#This Row],[Nom de l''échantillon donné par le client]],liste_groupe[[#This Row],[Dopage (+Testostérone / + EE2, ….)]]),CONCATENATE(liste_groupe[[#This Row],[Nom de l''échantillon donné par le client]],"-",liste_groupe[[#This Row],[Concentration]],liste_groupe[[#This Row],[Unité]],liste_groupe[[#This Row],[Dopage (+Testostérone / + EE2, ….)]])))
A29: =IF(ISBLANK(liste_groupe[[#This Row],[Code WF]])," ",IF(ISBLANK(liste_groupe[[#This Row],[Unité]]),CONCATENATE(liste_groupe[[#This Row],[Nom de l''échantillon donné par le client]],liste_groupe[[#This Row],[Dopage (+Testostérone / + EE2, ….)]]),CONCATENATE(liste_groupe[[#This Row],[Nom de l''échantillon donné par le client]],"-",liste_groupe[[#This Row],[Concentration]],liste_groupe[[#This Row],[Unité]],liste_groupe[[#This Row],[Dopage (+Testostérone / + EE2, ….)]])))
A30: =IF(ISBLANK(liste_groupe[[#This Row],[Code WF]])," ",IF(ISBLANK(liste_groupe[[#This Row],[Unité]]),CONCATENATE(liste_groupe[[#This Row],[Nom de l''échantillon donné par le client]],liste_groupe[[#This Row],[Dopage (+Testostérone / + EE2, ….)]]),CONCATENATE(liste_groupe[[#This Row],[Nom de l''échantillon donné par le client]],"-",liste_groupe[[#This Row],[Concentration]],liste_groupe[[#This Row],[Unité]],liste_groupe[[#This Row],[Dopage (+Testostérone / + EE2, ….)]])))
A31: =IF(ISBLANK(liste_groupe[[#This Row],[Code WF]])," ",IF(ISBLANK(liste_groupe[[#This Row],[Unité]]),CONCATENATE(liste_groupe[[#This Row],[Nom de l''échantillon donné par le client]],liste_groupe[[#This Row],[Dopage (+Testostérone / + EE2, ….)]]),CONCATENATE(liste_groupe[[#This Row],[Nom de l''échantillon donné par le client]],"-",liste_groupe[[#This Row],[Concentration]],liste_groupe[[#This Row],[Unité]],liste_groupe[[#This Row],[Dopage (+Testostérone / + EE2, ….)]])))
... A35: =IF(ISBLANK(liste_groupe[[#This Row],[Code WF]])," ",IF(ISBLANK(liste_groupe[[#This Row],[Unité]]),CONCATENATE(liste_groupe[[#This Row],[Nom de l''échantillon donné par le client]],liste_groupe[[#This Row],[Dopage (+Testostérone / + EE2, ….)]]),CONCATENATE(liste_groupe[[#This Row],[Nom de l''échantillon donné par le client]],"-",liste_groupe[[#This Row],[Concentration]],liste_groupe[[#This Row],[Unité]],liste_groupe[[#This Row],[Dopage (+Testostérone / + EE2, ….)]])))
A36: =IF(ISBLANK(liste_groupe[[#This Row],[Code WF]])," ",IF(ISBLANK(liste_groupe[[#This Row],[Unité]]),CONCATENATE(liste_groupe[[#This Row],[Nom de l''échantillon donné par le client]],liste_groupe[[#This Row],[Dopage (+Testostérone / + EE2, ….)]]),CONCATENATE(liste_groupe[[#This Row],[Nom de l''échantillon donné par le client]],"-",liste_groupe[[#This Row],[Concentration]],liste_groupe[[#This Row],[Unité]],liste_groupe[[#This Row],[Dopage (+Testostérone / + EE2, ….)]]))) -> Testo -30µg/L | B36: Témoin | C36: 30 | D36: µg/L | E36: Testo
A37: =IF(ISBLANK(liste_groupe[[#This Row],[Code WF]])," ",IF(ISBLANK(liste_groupe[[#This Row],[Unité]]),CONCATENATE(liste_groupe[[#This Row],[Nom de l''échantillon donné par le client]],liste_groupe[[#This Row],[Dopage (+Testostérone / + EE2, ….)]]),CONCATENATE(liste_groupe[[#This Row],[Nom de l''échantillon donné par le client]],"-",liste_groupe[[#This Row],[Concentration]],liste_groupe[[#This Row],[Unité]],liste_groupe[[#This Row],[Dopage (+Testostérone / + EE2, ….)]]))) -> Testo 30µg/L + EE2 -64ng/L | B37: Témoin | C37: 64 | D37: ng/L | E37: Testo 30µg/L + EE2
A38: =IF(ISBLANK(liste_groupe[[#This Row],[Code WF]])," ",IF(ISBLANK(liste_groupe[[#This Row],[Unité]]),CONCATENATE(liste_groupe[[#This Row],[Nom de l''échantillon donné par le client]],liste_groupe[[#This Row],[Dopage (+Testostérone / + EE2, ….)]]),CONCATENATE(liste_groupe[[#This Row],[Nom de l''échantillon donné par le client]],"-",liste_groupe[[#This Row],[Concentration]],liste_groupe[[#This Row],[Unité]],liste_groupe[[#This Row],[Dopage (+Testostérone / + EE2, ….)]]))) -> Testo 30µg/L + FAD-10µg/L | B38: Témoin | C38: 10 | D38: µg/L | E38: Testo 30µg/L + FAD
A39: =IF(ISBLANK(liste_groupe[[#This Row],[Code WF]])," ",IF(ISBLANK(liste_groupe[[#This Row],[Unité]]),CONCATENATE(liste_groupe[[#This Row],[Nom de l''échantillon donné par le client]],liste_groupe[[#This Row],[Dopage (+Testostérone / + EE2, ….)]]),CONCATENATE(liste_groupe[[#This Row],[Nom de l''échantillon donné par le client]],"-",liste_groupe[[#This Row],[Concentration]],liste_groupe[[#This Row],[Unité]],liste_groupe[[#This Row],[Dopage (+Testostérone / + EE2, ….)]]))) -> Dutasteride-0.01mg/L + Testostérone | B39: =B15 -> 0 | C39: =C15 -> 0.01 | D39: =D15 -> mg/L | E39: =E15 -> Dutasteride | F39: + Testostérone
A40: =IF(ISBLANK(liste_groupe[[#This Row],[Code WF]])," ",IF(ISBLANK(liste_groupe[[#This Row],[Unité]]),CONCATENATE(liste_groupe[[#This Row],[Nom de l''échantillon donné par le client]],liste_groupe[[#This Row],[Dopage (+Testostérone / + EE2, ….)]]),CONCATENATE(liste_groupe[[#This Row],[Nom de l''échantillon donné par le client]],"-",liste_groupe[[#This Row],[Concentration]],liste_groupe[[#This Row],[Unité]],liste_groupe[[#This Row],[Dopage (+Testostérone / + EE2, ….)]]))) -> Dutasteride-0.1mg/L + Testostérone | B40: =B16 -> 0 | C40: =C16 -> 0.1 | D40: =D16 -> mg/L | E40: =E16 -> Dutasteride | F40: + Testostérone
A41: =IF(ISBLANK(liste_groupe[[#This Row],[Code WF]])," ",IF(ISBLANK(liste_groupe[[#This Row],[Unité]]),CONCATENATE(liste_groupe[[#This Row],[Nom de l''échantillon donné par le client]],liste_groupe[[#This Row],[Dopage (+Testostérone / + EE2, ….)]]),CONCATENATE(liste_groupe[[#This Row],[Nom de l''échantillon donné par le client]],"-",liste_groupe[[#This Row],[Concentration]],liste_groupe[[#This Row],[Unité]],liste_groupe[[#This Row],[Dopage (+Testostérone / + EE2, ….)]]))) -> Dutasteride-0.25mg/L + Testostérone | B41: =B17 -> 0 | C41: =C17 -> 0.25 | D41: =D17 -> mg/L | E41: =E17 -> Dutasteride | F41: + Testostérone
A42: =IF(ISBLANK(liste_groupe[[#This Row],[Code WF]])," ",IF(ISBLANK(liste_groupe[[#This Row],[Unité]]),CONCATENATE(liste_groupe[[#This Row],[Nom de l''échantillon donné par le client]],liste_groupe[[#This Row],[Dopage (+Testostérone / + EE2, ….)]]),CONCATENATE(liste_groupe[[#This Row],[Nom de l''échantillon donné par le client]],"-",liste_groupe[[#This Row],[Concentration]],liste_groupe[[#This Row],[Unité]],liste_groupe[[#This Row],[Dopage (+Testostérone / + EE2, ….)]]))) -> Dutasteride-0.5mg/L + Testostérone | B42: =B18 -> 0 | C42: =C18 -> 0.5 | D42: =D18 -> mg/L | E42: =E18 -> Dutasteride | F42: + Testostérone
A43: =IF(ISBLANK(liste_groupe[[#This Row],[Code WF]])," ",IF(ISBLANK(liste_groupe[[#This Row],[Unité]]),CONCATENATE(liste_groupe[[#This Row],[Nom de l''échantillon donné par le client]],liste_groupe[[#This Row],[Dopage (+Testostérone / + EE2, ….)]]),CONCATENATE(liste_groupe[[#This Row],[Nom de l''échantillon donné par le client]],"-",liste_groupe[[#This Row],[Concentration]],liste_groupe[[#This Row],[Unité]],liste_groupe[[#This Row],[Dopage (+Testostérone / + EE2, ….)]]))) -> Dutasteride-1mg/L + Testostérone | B43: =B19 -> 0 | C43: =C19 -> 1 | D43: =D19 -> mg/L | E43: =E19 -> Dutasteride | F43: + Testostérone
...

Sheet Feuil1
A1: Nom groupe | B1: N° de valeur | C1: file name | D1: total area | E1: mean intensity | G1: total fluorescence | I1: nbre de larves
A2: 01 EE2 0 | B2: A | C2: C:\Users\Olympus\Desktop\20190122\plaque1/@01 EE2 0/A1_1.tif | D2: 4931.616 | E2: 73.0526 | G2: 360268
A3: 01 EE2 0 | B3: A | C3: C:\Users\Olympus\Desktop\20190122\plaque1/@01 EE2 0/A1_2.tif | D3: 5234.4345 | E3: 71.1281 | G3: 372315
A4: 01 EE2 0 | B4: A | C4: C:\Users\Olympus\Desktop\20190122\plaque1/@01 EE2 0/A1_3.tif | D4: 3547.3027 | E4: 66.9878 | G4: 237626
A5: 01 EE2 0 | B5: A | C5: C:\Users\Olympus\Desktop\20190122\plaque3/@01 EE2 0/A1_3.tif | D5: 21456.8555 | E5: 67.0655 | G5: 1439015
A6: 01 EE2 0 | B6: A | C6: C:\Users\Olympus\Desktop\20190122\plaque3/@01 EE2 0/A1_2.tif | D6: 21586.6348 | E6: 66.4108 | G6: 1433586
A7: 01 EE2 0 | B7: A | C7: C:\Users\Olympus\Desktop\20190122\plaque3/@01 EE2 0/A1_1.tif | D7: 15984.4921 | E7: 69.7767 | G7: 1115346

Sheet Feuil2
A1: Nom groupe | B1: N° de valeur | C1: file name | D1: total area | E1: mean intensity | G1: total fluorescence | I1: nbre de larves | J1: Colonne1
A2: 01 TS | B2: A | C2: D:\images\2022-CHG-NLO-dutasteride\plaque 1/@01 TS/A1_03.tif | D2: 8.4893 | E2: 64.2 | G2: 545
A3: 01 TS | B3: A | C3: D:\images\2022-CHG-NLO-dutasteride\plaque 1/@01 TS/A1_02.tif | D3: 11.885 | E3: 63.0714 | G3: 750
A4: 01 TS | B4: A | C4: D:\images\2022-CHG-NLO-dutasteride\plaque 1/@01 TS/A1_01.tif | D4: 22.0721 | E4: 63.4231 | G4: 1400

Sheet Raw data R1
A1: Nom groupe | B1: N° de valeur | C1: file name | D1: total area | E1: mean intensity | G1: total fluorescence | I1: nbre de larves | J1: Colonne1 | L1: (Tous)
A2: =IFERROR(LEFT(RIGHT(C2,LEN(C2)-SEARCH("@",C2)),SEARCH("/",RIGHT(C2,LEN(C2)-SEARCH("@",C2)-1))),"") | B2: =LEFT(RIGHT(RIGHT(Tableau4[[#This Row],[file name]],LEN(Tableau4[[#This Row],[file name]])-SEARCH("@",Tableau4[[#This Row],[file name]])),LEN(RIGHT(Tableau4[[#This Row],[file name]],LEN(Tableau4[[#This Row],[file name]])-SEARCH("@",Tableau4[[#This Row],[file name]])))-SEARCH("/",RIGHT(Tableau4[[#This Row],[file name]],LEN(Tableau4[[#This Row],[file name]])-SEARCH("@",Tableau4[[#This Row],[file name]])))),1) -> #VALUE! | C2: raw data | K2: Filtre lignes : Enlever (vide) et Néant | L2: Filtre colonnes : Enlever (vide) et " "
A3: =IFERROR(LEFT(RIGHT(C3,LEN(C3)-SEARCH("@",C3)),SEARCH("/",RIGHT(C3,LEN(C3)-SEARCH("@",C3)-1))),"") | B3: =LEFT(RIGHT(RIGHT(Tableau4[[#This Row],[file name]],LEN(Tableau4[[#This Row],[file name]])-SEARCH("@",Tableau4[[#This Row],[file name]])),LEN(RIGHT(Tableau4[[#This Row],[file name]],LEN(Tableau4[[#This Row],[file name]])-SEARCH("@",Tableau4[[#This Row],[file name]])))-SEARCH("/",RIGHT(Tableau4[[#This Row],[file name]],LEN(Tableau4[[#This Row],[file name]])-SEARCH("@",Tableau4[[#This Row],[file name]])))),1) -> #VALUE! | K3: Moyenne de total fluorescence | L3: Étiquettes de colonnes
A4: =IFERROR(LEFT(RIGHT(C4,LEN(C4)-SEARCH("@",C4)),SEARCH("/",RIGHT(C4,LEN(C4)-SEARCH("@",C4)-1))),"") | B4: =LEFT(RIGHT(RIGHT(Tableau4[[#This Row],[file name]],LEN(Tableau4[[#This Row],[file name]])-SEARCH("@",Tableau4[[#This Row],[file name]])),LEN(RIGHT(Tableau4[[#This Row],[file name]],LEN(Tableau4[[#This Row],[file name]])-SEARCH("@",Tableau4[[#This Row],[file name]])))-SEARCH("/",RIGHT(Tableau4[[#This Row],[file name]],LEN(Tableau4[[#This Row],[file name]])-SEARCH("@",Tableau4[[#This Row],[file name]])))),1) -> #VALUE! | C4: Version 4.0, Macro for Choriogenin Analysis. 60-255, auto blue selection TIF | K4: Étiquettes de lignes | L4: 04 EE2 76 | M4: 05 EE2 114 | N4: 07 EE2 488 | O4: 01 TS | P4: 02 EE2 34 | Q4: 03 EE2 51 | R4: 06 EE2 171 | S4: 08 duta 0.01 | T4: 09 duta 0.1 | U4: 10 duta 0.25 | V4: 11 duta 0.5 | W4: 12 duta 1 | X4: 13 testo | Y4: 14 testo | Z4: 15 testo + EE2 64 | AA4: 16 testo + fad | AB4: 17 testo + duta 0.01 | AC4: 18 testo + duta 0.1 | AD4: 19 testo + duta 0.25 | AE4: 20 testo + duta 0.5 | AF4: 21 testo + duta 1
A5: =IFERROR(LEFT(RIGHT(C5,LEN(C5)-SEARCH("@",C5)),SEARCH("/",RIGHT(C5,LEN(C5)-SEARCH("@",C5)-1))),"") | B5: =LEFT(RIGHT(RIGHT(Tableau4[[#This Row],[file name]],LEN(Tableau4[[#This Row],[file name]])-SEARCH("@",Tableau4[[#This Row],[file name]])),LEN(RIGHT(Tableau4[[#This Row],[file name]],LEN(Tableau4[[#This Row],[file name]])-SEARCH("@",Tableau4[[#This Row],[file name]])))-SEARCH("/",RIGHT(Tableau4[[#This Row],[file name]],LEN(Tableau4[[#This Row],[file name]])-SEARCH("@",Tableau4[[#This Row],[file name]])))),1) -> #VALUE! | K5: A | L5: 4087 | M5: 23266.667 | N5: 289398.67 | O5: 898.33333 | P5: 1228.6667 | Q5: 841 | R5: 76987 | S5: 25658.333 | T5: 4114.6667 | U5: 7253 | W5: 736 | X5: 664.5 | Y5: 87488 | Z5: 179834 | AA5: 2703 | AB5: 132753.67 | AC5: 99442.667 | AD5: 144318.67 | AE5: 127357.5 | AF5: 113581
A6: =IFERROR(LEFT(RIGHT(C6,LEN(C6)-SEARCH("@",C6)),SEARCH("/",RIGHT(C6,LEN(C6)-SEARCH("@",C6)-1))),"") | B6: =LEFT(RIGHT(RIGHT(Tableau4[[#This Row],[file name]],LEN(Tableau4[[#This Row],[file name]])-SEARCH("@",Tableau4[[#This Row],[file name]])),LEN(RIGHT(Tableau4[[#This Row],[file name]],LEN(Tableau4[[#This Row],[file name]])-SEARCH("@",Tableau4[[#This Row],[file name]])))-SEARCH("/",RIGHT(Tableau4[[#This Row],[file name]],LEN(Tableau4[[#This Row],[file name]])-SEARCH("@",Tableau4[[#This Row],[file name]])))),1) -> #VALUE! | K6: B | L6: 32840.667 | M6: 21138.333 | N6: 220805.33 | O6: 655.33333 | P6: 299 | Q6: 1106.6667 | R6: 160526.67 | S6: 890 | T6: 508.33333 | U6: 1929 | V6: 815.66667 | W6: 544.66667 | X6: 46034 | Y6: 27740 | Z6: 85611.667 | AA6: 1804.6667 | AB6: 2280 | AC6: 71544.667 | AD6: 13125.333 | AE6: 135077 | AF6: 81609.667
A7: =IFERROR(LEFT(RIGHT(C7,LEN(C7)-SEARCH("@",C7)),SEARCH("/",RIGHT(C7,LEN(C7)-SEARCH("@",C7)-1))),"") | B7: =LEFT(RIGHT(RIGHT(Tableau4[[#This Row],[file name]],LEN(Tableau4[[#This Row],[file name]])-SEARCH("@",Tableau4[[#This Row],[file name]])),LEN(RIGHT(Tableau4[[#This Row],[file name]],LEN(Tableau4[[#This Row],[file name]])-SEARCH("@",Tableau4[[#This Row],[file name]])))-SEARCH("/",RIGHT(Tableau4[[#This Row],[file name]],LEN(Tableau4[[#This Row],[file name]])-SEARCH("@",Tableau4[[#This Row],[file name]])))),1) -> #VALUE! | C7: analysed: | K7: C | L7: 1876.5 | M7: 24673.667 | N7: 150270.67 | O7: 7962 | P7: 3989 | Q7: 517.66667 | R7: 101078.33 | S7: 840.66667 | T7: 936 | U7: 4509.6667 | V7: 3784.3333 | W7: 358 | X7: 86265.667 | Y7: 128175.5 | Z7: 134675 | AA7: 925.66667 | AB7: 33958 | AC7: 118920.67 | AD7: 36777.667 | AE7: 80494.667 | AF7: 77971
A8: =IFERROR(LEFT(RIGHT(C8,LEN(C8)-SEARCH("@",C8)),SEARCH("/",RIGHT(C8,LEN(C8)-SEARCH("@",C8)-1))),"") | B8: =LEFT(RIGHT(RIGHT(Tableau4[[#This Row],[file name]],LEN(Tableau4[[#This Row],[file name]])-SEARCH("@",Tableau4[[#This Row],[file name]])),LEN(RIGHT(Tableau4[[#This Row],[file name]],LEN(Tableau4[[#This Row],[file name]])-SEARCH("@",Tableau4[[#This Row],[file name]])))-SEARCH("/",RIGHT(Tableau4[[#This Row],[file name]],LEN(Tableau4[[#This Row],[file name]])-SEARCH("@",Tableau4[[#This Row],[file name]])))),1) -> #VALUE! | C8: Date: Thu 29-Sep-2022 | K8: D | L8: 1802.6667 | M8: 70945.333 | N8: 48490 | O8: 2038.6667 | P8: 622.66667 | Q8: 3250.5 | R8: 4761 | S8: 740.66667 | T8: 582.66667 | U8: 544 | V8: 2303.6667 | W8: 7337 | X8: 70306 | Y8: 113809 | Z8: 119801 | AA8: 3260 | AB8: 68780.333 | AC8: 80031.667 | AD8: 21010 | AE8: 145377.67 | AF8: 70565.333
A9: =IFERROR(LEFT(RIGHT(C9,LEN(C9)-SEARCH("@",C9)),SEARCH("/",RIGHT(C9,LEN(C9)-SEARCH("@",C9)-1))),"") | B9: =LEFT(RIGHT(RIGHT(Tableau4[[#This Row],[file name]],LEN(Tableau4[[#This Row],[file name]])-SEARCH("@",Tableau4[[#This Row],[file name]])),LEN(RIGHT(Tableau4[[#This Row],[file name]],LEN(Tableau4[[#This Row],[file name]])-SEARCH("@",Tableau4[[#This Row],[file name]])))-SEARCH("/",RIGHT(Tableau4[[#This Row],[file name]],LEN(Tableau4[[#This Row],[file name]])-SEARCH("@",Tableau4[[#This Row],[file name]])))),1) -> #VALUE! | C9: Time: 16:04:31 | K9: E | L9: 5211.3333 | M9: 31265 | N9: 184792.67 | O9: 3827.3333 | P9: 886.33333 | Q9: 9380 | R9: 128211.67 | S9: 882.33333 | T9: 10898.5 | U9: 1237 | V9: 473.33333 | W9: 538 | X9: 36335 | Y9: 50367.333 | Z9: 8001 | AA9: 4983.6667 | AB9: 73197.667 | AC9: 30221 | AD9: 35624 | AE9: 84514.333 | AF9: 2584.3333
A10: =IFERROR(LEFT(RIGHT(C10,LEN(C10)-SEARCH("@",C10)),SEARCH("/",RIGHT(C10,LEN(C10)-SEARCH("@",C10)-1))),"") | B10: =LEFT(RIGHT(RIGHT(Tableau4[[#This Row],[file name]],LEN(Tableau4[[#This Row],[file name]])-SEARCH("@",Tableau4[[#This Row],[file name]])),LEN(RIGHT(Tableau4[[#This Row],[file name]],LEN(Tableau4[[#This Row],[file name]])-SEARCH("@",Tableau4[[#This Row],[file name]])))-SEARCH("/",RIGHT(Tableau4[[#This Row],[file name]],LEN(Tableau4[[#This Row],[file name]])-SEARCH("@",Tableau4[[#This Row],[file name]])))),1) -> #VALUE! | K10: F | L10: 1377.6667 | M10: 52712 | N10: 117331.33 | O10: 7548 | P10: 1490 | Q10: 823.66667 | R10: 95670 | S10: 1777.3333 | T10: 3746 | U10: 1305.6667 | V10: 6782 | W10: 28785 | X10: 74464.667 | Y10: 42078 | Z10: 126312.67 | AA10: 1286 | AB10: 18571 | AC10: 102472.67 | AD10: 16015.333 | AE10: 50323 | AF10: 29598
A11: =IFERROR(LEFT(RIGHT(C11,LEN(C11)-SEARCH("@",C11)),SEARCH("/",RIGHT(C11,LEN(C11)-SEARCH("@",C11)-1))),"") | B11: =LEFT(RIGHT(RIGHT(Tableau4[[#This Row],[file name]],LEN(Tableau4[[#This Row],[file name]])-SEARCH("@",Tableau4[[#This Row],[file name]])),LEN(RIGHT(Tableau4[[#This Row],[file name]],LEN(Tableau4[[#This Row],[file name]])-SEARCH("@",Tableau4[[#This Row],[file name]])))-SEARCH("/",RIGHT(Tableau4[[#This Row],[file name]],LEN(Tableau4[[#This Row],[file name]])-SEARCH("@",Tableau4[[#This Row],[file name]])))),1) -> #VALUE! | C11: start date of exposure: | D11: 28/09/2022 | K11: G | L11: 5890.6667 | M11: 62986.333 | N11: 190470.33 | O11: 8112 | P11: 6912.3333 | Q11: 1055.6667 | R11: 143495 | S11: 2602.6667 | T11: 7991.3333 | U11: 564 | V11: 628 | W11: 1659 | X11: 12800 | Y11: 55672.333 | Z11: 118578.33 | AA11: 1832 | AB11: 427 | AC11: 3385 | AD11: 124834.33 | AE11: 121794.67 | AF11: 14828.667
A12: =IFERROR(LEFT(RIGHT(C12,LEN(C12)-SEARCH("@",C12)),SEARCH("/",RIGHT(C12,LEN(C12)-SEARCH("@",C12)-1))),"") | B12: =LEFT(RIGHT(RIGHT(Tableau4[[#This Row],[file name]],LEN(Tableau4[[#This Row],[file name]])-SEARCH("@",Tableau4[[#This Row],[file name]])),LEN(RIGHT(Tableau4[[#This Row],[file name]],LEN(Tableau4[[#This Row],[file name]])-SEARCH("@",Tableau4[[#This Row],[file name]])))-SEARCH("/",RIGHT(Tableau4[[#This Row],[file name]],LEN(Tableau4[[#This Row],[file name]])-SEARCH("@",Tableau4[[#This Row],[file name]])))),1) -> #VALUE! | C12: date of read: | D12: 29/09/2022 | K12: H | L12: 7090.3333 | M12: 64881.333 | N12: 165996.33 | O12: 643.66667 | P12: 1064.3333 | Q12: 12822.333 | R12: 138335 | S12: 2072 | T12: 662 | U12: 3253.6667 | V12: 652 | W12: 588 | X12: 54967.333 | Y12: 31594 | Z12: 115345 | AA12: 1432.3333 | AB12: 76731 | AC12: 24632 | AD12: 87894.333 | AE12: 96709 | AF12: 31206.667
A13: =IFERROR(LEFT(RIGHT(C13,LEN(C13)-SEARCH("@",C13)),SEARCH("/",RIGHT(C13,LEN(C13)-SEARCH("@",C13)-1))),"") | B13: =LEFT(RIGHT(RIGHT(Tableau4[[#This Row],[file name]],LEN(Tableau4[[#This Row],[file name]])-SEARCH("@",Tableau4[[#This Row],[file name]])),LEN(RIGHT(Tableau4[[#This Row],[file name]],LEN(Tableau4[[#This Row],[file name]])-SEARCH("@",Tableau4[[#This Row],[file name]])))-SEARCH("/",RIGHT(Tableau4[[#This Row],[file name]],LEN(Tableau4[[#This Row],[file name]])-SEARCH("@",Tableau4[[#This Row],[file name]])))),1) -> #VALUE! | C13: line: | D13: ChgH homozygous
A14: =IFERROR(LEFT(RIGHT(C14,LEN(C14)-SEARCH("@",C14)),SEARCH("/",RIGHT(C14,LEN(C14)-SEARCH("@",C14)-1))),"") | B14: =LEFT(RIGHT(RIGHT(Tableau4[[#This Row],[file name]],LEN(Tableau4[[#This Row],[file name]])-SEARCH("@",Tableau4[[#This Row],[file name]])),LEN(RIGHT(Tableau4[[#This Row],[file name]],LEN(Tableau4[[#This Row],[file name]])-SEARCH("@",Tableau4[[#This Row],[file name]])))-SEARCH("/",RIGHT(Tableau4[[#This Row],[file name]],LEN(Tableau4[[#This Row],[file name]])-SEARCH("@",Tableau4[[#This Row],[file name]])))),1) -> #VALUE! | C14: crossed with: | D14: ChgH homozygous
A15: =IFERROR(LEFT(RIGHT(C15,LEN(C15)-SEARCH("@",C15)),SEARCH("/",RIGHT(C15,LEN(C15)-SEARCH("@",C15)-1))),"") | B15: =LEFT(RIGHT(RIGHT(Tableau4[[#This Row],[file name]],LEN(Tableau4[[#This Row],[file name]])-SEARCH("@",Tableau4[[#This Row],[file name]])),LEN(RIGHT(Tableau4[[#This Row],[file name]],LEN(Tableau4[[#This Row],[file name]])-SEARCH("@",Tableau4[[#This Row],[file name]])))-SEARCH("/",RIGHT(Tableau4[[#This Row],[file name]],LEN(Tableau4[[#This Row],[file name]])-SEARCH("@",Tableau4[[#This Row],[file name]])))),1) -> #VALUE! | C15: generation of embryos:
A16: =IFERROR(LEFT(RIGHT(C16,LEN(C16)-SEARCH("@",C16)),SEARCH("/",RIGHT(C16,LEN(C16)-SEARCH("@",C16)-1))),"") | B16: =LEFT(RIGHT(RIGHT(Tableau4[[#This Row],[file name]],LEN(Tableau4[[#This Row],[file name]])-SEARCH("@",Tableau4[[#This Row],[file name]])),LEN(RIGHT(Tableau4[[#This Row],[file name]],LEN(Tableau4[[#This Row],[file name]])-SEARCH("@",Tableau4[[#This Row],[file name]])))-SEARCH("/",RIGHT(Tableau4[[#This Row],[file name]],LEN(Tableau4[[#This Row],[file name]])-SEARCH("@",Tableau4[[#This Row],[file name]])))),1) -> #VALUE! | C16: exposure length in hours: | D16: 24h
A17: =IFERROR(LEFT(RIGHT(C17,LEN(C17)-SEARCH("@",C17)),SEARCH("/",RIGHT(C17,LEN(C17)-SEARCH("@",C17)-1))),"") | B17: =LEFT(RIGHT(RIGHT(Tableau4[[#This Row],[file name]],LEN(Tableau4[[#This Row],[file name]])-SEARCH("@",Tableau4[[#This Row],[file name]])),LEN(RIGHT(Tableau4[[#This Row],[file name]],LEN(Tableau4[[#This Row],[file name]])-SEARCH("@",Tableau4[[#This Row],[file name]])))-SEARCH("/",RIGHT(Tableau4[[#This Row],[file name]],LEN(Tableau4[[#This Row],[file name]])-SEARCH("@",Tableau4[[#This Row],[file name]])))),1) -> #VALUE!
A18: =IFERROR(LEFT(RIGHT(C18,LEN(C18)-SEARCH("@",C18)),SEARCH("/",RIGHT(C18,LEN(C18)-SEARCH("@",C18)-1))),"") | B18: =LEFT(RIGHT(RIGHT(Tableau4[[#This Row],[file name]],LEN(Tableau4[[#This Row],[file name]])-SEARCH("@",Tableau4[[#This Row],[file name]])),LEN(RIGHT(Tableau4[[#This Row],[file name]],LEN(Tableau4[[#This Row],[file name]])-SEARCH("@",Tableau4[[#This Row],[file name]])))-SEARCH("/",RIGHT(Tableau4[[#This Row],[file name]],LEN(Tableau4[[#This Row],[file name]])-SEARCH("@",Tableau4[[#This Row],[file name]])))),1) -> #VALUE!
A19: =IFERROR(LEFT(RIGHT(C19,LEN(C19)-SEARCH("@",C19)),SEARCH("/",RIGHT(C19,LEN(C19)-SEARCH("@",C19)-1))),"") | B19: =LEFT(RIGHT(RIGHT(Tableau4[[#This Row],[file name]],LEN(Tableau4[[#This Row],[file name]])-SEARCH("@",Tableau4[[#This Row],[file name]])),LEN(RIGHT(Tableau4[[#This Row],[file name]],LEN(Tableau4[[#This Row],[file name]])-SEARCH("@",Tableau4[[#This Row],[file name]])))-SEARCH("/",RIGHT(Tableau4[[#This Row],[file name]],LEN(Tableau4[[#This Row],[file name]])-SEARCH("@",Tableau4[[#This Row],[file name]])))),1) -> #VALUE! | C19: file name | D19: total area | E19: mean intensity | G19: total fluorescence
A20: =IFERROR(LEFT(RIGHT(C20,LEN(C20)-SEARCH("@",C20)),SEARCH("/",RIGHT(C20,LEN(C20)-SEARCH("@",C20)-1))),"") -> 01 TS | B20: =LEFT(RIGHT(RIGHT(Tableau4[[#This Row],[file name]],LEN(Tableau4[[#This Row],[file name]])-SEARCH("@",Tableau4[[#This Row],[file name]])),LEN(RIGHT(Tableau4[[#This Row],[file name]],LEN(Tableau4[[#This Row],[file name]])-SEARCH("@",Tableau4[[#This Row],[file name]])))-SEARCH("/",RIGHT(Tableau4[[#This Row],[file name]],LEN(Tableau4[[#This Row],[file name]])-SEARCH("@",Tableau4[[#This Row],[file name]])))),1) -> A | C20: D:\images\2022-CHG-NLO-dutasteride\plaque 1/@01 TS/A1_01.tif | D20: 22.0721 | E20: 63.4231 | G20: 1400
A21: =IFERROR(LEFT(RIGHT(C21,LEN(C21)-SEARCH("@",C21)),SEARCH("/",RIGHT(C21,LEN(C21)-SEARCH("@",C21)-1))),"") -> 01 TS | B21: =LEFT(RIGHT(RIGHT(Tableau4[[#This Row],[file name]],LEN(Tableau4[[#This Row],[file name]])-SEARCH("@",Tableau4[[#This Row],[file name]])),LEN(RIGHT(Tableau4[[#This Row],[file name]],LEN(Tableau4[[#This Row],[file name]])-SEARCH("@",Tableau4[[#This Row],[file name]])))-SEARCH("/",RIGHT(Tableau4[[#This Row],[file name]],LEN(Tableau4[[#This Row],[file name]])-SEARCH("@",Tableau4[[#This Row],[file name]])))),1) -> A | C21: D:\images\2022-CHG-NLO-dutasteride\plaque 1/@01 TS/A1_02.tif | D21: 11.885 | E21: 63.0714 | G21: 750
A22: =IFERROR(LEFT(RIGHT(C22,LEN(C22)-SEARCH("@",C22)),SEARCH("/",RIGHT(C22,LEN(C22)-SEARCH("@",C22)-1))),"") -> 01 TS | B22: =LEFT(RIGHT(RIGHT(Tableau4[[#This Row],[file name]],LEN(Tableau4[[#This Row],[file name]])-SEARCH("@",Tableau4[[#This Row],[file name]])),LEN(RIGHT(Tableau4[[#This Row],[file name]],LEN(Tableau4[[#This Row],[file name]])-SEARCH("@",Tableau4[[#This Row],[file name]])))-SEARCH("/",RIGHT(Tableau4[[#This Row],[file name]],LEN(Tableau4[[#This Row],[file name]])-SEARCH("@",Tableau4[[#This Row],[file name]])))),1) -> A | C22: D:\images\2022-CHG-NLO-dutasteride\plaque 1/@01 TS/A1_03.tif | D22: 8.4893 | E22: 64.2 | G22: 545
A23: =IFERROR(LEFT(RIGHT(C23,LEN(C23)-SEARCH("@",C23)),SEARCH("/",RIGHT(C23,LEN(C23)-SEARCH("@",C23)-1))),"") -> 01 TS | B23: =LEFT(RIGHT(RIGHT(Tableau4[[#This Row],[file name]],LEN(Tableau4[[#This Row],[file name]])-SEARCH("@",Tableau4[[#This Row],[file name]])),LEN(RIGHT(Tableau4[[#This Row],[file name]],LEN(Tableau4[[#This Row],[file name]])-SEARCH("@",Tableau4[[#This Row],[file name]])))-SEARCH("/",RIGHT(Tableau4[[#This Row],[file name]],LEN(Tableau4[[#This Row],[file name]])-SEARCH("@",Tableau4[[#This Row],[file name]])))),1) -> B | C23: D:\images\2022-CHG-NLO-dutasteride\plaque 1/@01 TS/B1_01.tif | D23: 6.7914 | E23: 64.5 | G23: 438
A24: =IFERROR(LEFT(RIGHT(C24,LEN(C24)-SEARCH("@",C24)),SEARCH("/",RIGHT(C24,LEN(C24)-SEARCH("@",C24)-1))),"") -> 01 TS | B24: =LEFT(RIGHT(RIGHT(Tableau4[[#This Row],[file name]],LEN(Tableau4[[#This Row],[file name]])-SEARCH("@",Tableau4[[#This Row],[file name]])),LEN(RIGHT(Tableau4[[#This Row],[file name]],LEN(Tableau4[[#This Row],[file name]])-SEARCH("@",Tableau4[[#This Row],[file name]])))-SEARCH("/",RIGHT(Tableau4[[#This Row],[file name]],LEN(Tableau4[[#This Row],[file name]])-SEARCH("@",Tableau4[[#This Row],[file name]])))),1) -> B | C24: D:\images\2022-CHG-NLO-dutasteride\plaque 1/@01 TS/B1_02.tif | D24: 11.885 | E24: 63.3571 | G24: 753
A25: =IFERROR(LEFT(RIGHT(C25,LEN(C25)-SEARCH("@",C25)),SEARCH("/",RIGHT(C25,LEN(C25)-SEARCH("@",C25)-1))),"") -> 01 TS | B25: =LEFT(RIGHT(RIGHT(Tableau4[[#This Row],[file name]],LEN(Tableau4[[#This Row],[file name]])-SEARCH("@",Tableau4[[#This Row],[file name]])),LEN(RIGHT(Tableau4[[#This Row],[file name]],LEN(Tableau4[[#This Row],[file name]])-SEARCH("@",Tableau4[[#This Row],[file name]])))-SEARCH("/",RIGHT(Tableau4[[#This Row],[file name]],LEN(Tableau4[[#This Row],[file name]])-SEARCH("@",Tableau4[[#This Row],[file name]])))),1) -> B | C25: D:\images\2022-CHG-NLO-dutasteride\plaque 1/@01 TS/B1_03.tif | D25: 11.885 | E25: 65.2143 | G25: 775
A26: =IFERROR(LEFT(RIGHT(C26,LEN(C26)-SEARCH("@",C26)),SEARCH("/",RIGHT(C26,LEN(C26)-SEARCH("@",C26)-1))),"") -> 01 TS | B26: =LEFT(RIGHT(RIGHT(Tableau4[[#This Row],[file name]],LEN(Tableau4[[#This Row],[file name]])-SEARCH("@",Tableau4[[#This Row],[file name]])),LEN(RIGHT(Tableau4[[#This Row],[file name]],LEN(Tableau4[[#This Row],[file name]])-SEARCH("@",Tableau4[[#This Row],[file name]])))-SEARCH("/",RIGHT(Tableau4[[#This Row],[file name]],LEN(Tableau4[[#This Row],[file name]])-SEARCH("@",Tableau4[[#This Row],[file name]])))),1) -> C | C26: D:\images\2022-CHG-NLO-dutasteride\plaque 1/@01 TS/C1_01.tif | D26: 16.9786 | E26: 65.55 | G26: 1113
A27: =IFERROR(LEFT(RIGHT(C27,LEN(C27)-SEARCH("@",C27)),SEARCH("/",RIGHT(C27,LEN(C27)-SEARCH("@",C27)-1))),"") -> 01 TS | B27: =LEFT(RIGHT(RIGHT(Tableau4[[#This Row],[file name]],LEN(Tableau4[[#This Row],[file name]])-SEARCH("@",Tableau4[[#This Row],[file name]])),LEN(RIGHT(Tableau4[[#This Row],[file name]],LEN(Tableau4[[#This Row],[file name]])-SEARCH("@",Tableau4[[#This Row],[file name]])))-SEARCH("/",RIGHT(Tableau4[[#This Row],[file name]],LEN(Tableau4[[#This Row],[file name]])-SEARCH("@",Tableau4[[#This Row],[file name]])))),1) -> C | C27: D:\images\2022-CHG-NLO-dutasteride\plaque 1/@01 TS/C1_02.tif | D27: 290.3333 | E27: 68.6784 | G27: 19940
A28: =IFERROR(LEFT(RIGHT(C28,LEN(C28)-SEARCH("@",C28)),SEARCH("/",RIGHT(C28,LEN(C28)-SEARCH("@",C28)-1))),"") -> 01 TS | B28: =LEFT(RIGHT(RIGHT(Tableau4[[#This Row],[file name]],LEN(Tableau4[[#This Row],[file name]])-SEARCH("@",Tableau4[[#This Row],[file name]])),LEN(RIGHT(Tableau4[[#This Row],[file name]],LEN(Tableau4[[#This Row],[file name]])-SEARCH("@",Tableau4[[#This Row],[file name]])))-SEARCH("/",RIGHT(Tableau4[[#This Row],[file name]],LEN(Tableau4[[#This Row],[file name]])-SEARCH("@",Tableau4[[#This Row],[file name]])))),1) -> C | C28: D:\images\2022-CHG-NLO-dutasteride\plaque 1/@01 TS/C1_03.tif | D28: 44.1442 | E28: 64.1731 | G28: 2833
A29: =IFERROR(LEFT(RIGHT(C29,LEN(C29)-SEARCH("@",C29)),SEARCH("/",RIGHT(C29,LEN(C29)-SEARCH("@",C29)-1))),"") -> 01 TS | B29: =LEFT(RIGHT(RIGHT(Tableau4[[#This Row],[file name]],LEN(Tableau4[[#This Row],[file name]])-SEARCH("@",Tableau4[[#This Row],[file name]])),LEN(RIGHT(Tableau4[[#This Row],[file name]],LEN(Tableau4[[#This Row],[file name]])-SEARCH("@",Tableau4[[#This Row],[file name]])))-SEARCH("/",RIGHT(Tableau4[[#This Row],[file name]],LEN(Tableau4[[#This Row],[file name]])-SEARCH("@",Tableau4[[#This Row],[file name]])))),1) -> D | C29: D:\images\2022-CHG-NLO-dutasteride\plaque 1/@01 TS/D1_01.tif | D29: 67.0653 | E29: 65.3797 | G29: 4385
A30: =IFERROR(LEFT(RIGHT(C30,LEN(C30)-SEARCH("@",C30)),SEARCH("/",RIGHT(C30,LEN(C30)-SEARCH("@",C30)-1))),"") -> 01 TS | B30: =LEFT(RIGHT(RIGHT(Tableau4[[#This Row],[file name]],LEN(Tableau4[[#This Row],[file name]])-SEARCH("@",Tableau4[[#This Row],[file name]])),LEN(RIGHT(Tableau4[[#This Row],[file name]],LEN(Tableau4[[#This Row],[file name]])-SEARCH("@",Tableau4[[#This Row],[file name]])))-SEARCH("/",RIGHT(Tableau4[[#This Row],[file name]],LEN(Tableau4[[#This Row],[file name]])-SEARCH("@",Tableau4[[#This Row],[file name]])))),1) -> D | C30: D:\images\2022-CHG-NLO-dutasteride\plaque 1/@01 TS/D1_02.tif | D30: 17.8275 | E30: 63.7143 | G30: 1136
A31: =IFERROR(LEFT(RIGHT(C31,LEN(C31)-SEARCH("@",C31)),SEARCH("/",RIGHT(C31,LEN(C31)-SEARCH("@",C31)-1))),"") -> 01 TS | B31: =LEFT(RIGHT(RIGHT(Tableau4[[#This Row],[file name]],LEN(Tableau4[[#This Row],[file name]])-SEARCH("@",Tableau4[[#This Row],[file name]])),LEN(RIGHT(Tableau4[[#This Row],[file name]],LEN(Tableau4[[#This Row],[file name]])-SEARCH("@",Tableau4[[#This Row],[file name]])))-SEARCH("/",RIGHT(Tableau4[[#This Row],[file name]],LEN(Tableau4[[#This Row],[file name]])-SEARCH("@",Tableau4[[#This Row],[file name]])))),1) -> D | C31: D:\images\2022-CHG-NLO-dutasteride\plaque 1/@01 TS/D1_03.tif | D31: 9.3382 | E31: 63.7273 | G31: 595
... A38: =IFERROR(LEFT(RIGHT(C38,LEN(C38)-SEARCH("@",C38)),SEARCH("/",RIGHT(C38,LEN(C38)-SEARCH("@",C38)-1))),"") -> 01 TS | B38: =LEFT(RIGHT(RIGHT(Tableau4[[#This Row],[file name]],LEN(Tableau4[[#This Row],[file name]])-SEARCH("@",Tableau4[[#This Row],[file name]])),LEN(RIGHT(Tableau4[[#This Row],[file name]],LEN(Tableau4[[#This Row],[file name]])-SEARCH("@",Tableau4[[#This Row],[file name]])))-SEARCH("/",RIGHT(Tableau4[[#This Row],[file name]],LEN(Tableau4[[#This Row],[file name]])-SEARCH("@",Tableau4[[#This Row],[file name]])))),1) -> G | C38: D:\images\2022-CHG-NLO-dutasteride\plaque 1/@01 TS/G1_01.tif | D38: 185.0663 | E38: 66.3028 | G38: 12270
A39: =IFERROR(LEFT(RIGHT(C39,LEN(C39)-SEARCH("@",C39)),SEARCH("/",RIGHT(C39,LEN(C39)-SEARCH("@",C39)-1))),"") -> 01 TS | B39: =LEFT(RIGHT(RIGHT(Tableau4[[#This Row],[file name]],LEN(Tableau4[[#This Row],[file name]])-SEARCH("@",Tableau4[[#This Row],[file name]])),LEN(RIGHT(Tableau4[[#This Row],[file name]],LEN(Tableau4[[#This Row],[file name]])-SEARCH("@",Tableau4[[#This Row],[file name]])))-SEARCH("/",RIGHT(Tableau4[[#This Row],[file name]],LEN(Tableau4[[#This Row],[file name]])-SEARCH("@",Tableau4[[#This Row],[file name]])))),1) -> G | C39: D:\images\2022-CHG-NLO-dutasteride\plaque 1/@01 TS/G1_02.tif | D39: 100.1735 | E39: 65 | G39: 6511
A40: =IFERROR(LEFT(RIGHT(C40,LEN(C40)-SEARCH("@",C40)),SEARCH("/",RIGHT(C40,LEN(C40)-SEARCH("@",C40)-1))),"") -> 01 TS | B40: =LEFT(RIGHT(RIGHT(Tableau4[[#This Row],[file name]],LEN(Tableau4[[#This Row],[file name]])-SEARCH("@",Tableau4[[#This Row],[file name]])),LEN(RIGHT(Tableau4[[#This Row],[file name]],LEN(Tableau4[[#This Row],[file name]])-SEARCH("@",Tableau4[[#This Row],[file name]])))-SEARCH("/",RIGHT(Tableau4[[#This Row],[file name]],LEN(Tableau4[[#This Row],[file name]])-SEARCH("@",Tableau4[[#This Row],[file name]])))),1) -> G | C40: D:\images\2022-CHG-NLO-dutasteride\plaque 1/@01 TS/G1_03.tif | D40: 86.5906 | E40: 64.1471 | G40: 5555
A41: =IFERROR(LEFT(RIGHT(C41,LEN(C41)-SEARCH("@",C41)),SEARCH("/",RIGHT(C41,LEN(C41)-SEARCH("@",C41)-1))),"") -> 01 TS | B41: =LEFT(RIGHT(RIGHT(Tableau4[[#This Row],[file name]],LEN(Tableau4[[#This Row],[file name]])-SEARCH("@",Tableau4[[#This Row],[file name]])),LEN(RIGHT(Tableau4[[#This Row],[file name]],LEN(Tableau4[[#This Row],[file name]])-SEARCH("@",Tableau4[[#This Row],[file name]])))-SEARCH("/",RIGHT(Tableau4[[#This Row],[file name]],LEN(Tableau4[[#This Row],[file name]])-SEARCH("@",Tableau4[[#This Row],[file name]])))),1) -> H | C41: D:\images\2022-CHG-NLO-dutasteride\plaque 1/@01 TS/H1_01.tif | D41: 5.0936 | E41: 66.3333 | G41: 338
A42: =IFERROR(LEFT(RIGHT(C42,LEN(C42)-SEARCH("@",C42)),SEARCH("/",RIGHT(C42,LEN(C42)-SEARCH("@",C42)-1))),"") -> 01 TS | B42: =LEFT(RIGHT(RIGHT(Tableau4[[#This Row],[file name]],LEN(Tableau4[[#This Row],[file name]])-SEARCH("@",Tableau4[[#This Row],[file name]])),LEN(RIGHT(Tableau4[[#This Row],[file name]],LEN(Tableau4[[#This Row],[file name]])-SEARCH("@",Tableau4[[#This Row],[file name]])))-SEARCH("/",RIGHT(Tableau4[[#This Row],[file name]],LEN(Tableau4[[#This Row],[file name]])-SEARCH("@",Tableau4[[#This Row],[file name]])))),1) -> H | C42: D:\images\2022-CHG-NLO-dutasteride\plaque 1/@01 TS/H1_02.tif | D42: 10.1871 | E42: 64.1667 | G42: 654
A43: =IFERROR(LEFT(RIGHT(C43,LEN(C43)-SEARCH("@",C43)),SEARCH("/",RIGHT(C43,LEN(C43)-SEARCH("@",C43)-1))),"") -> 01 TS | B43: =LEFT(RIGHT(RIGHT(Tableau4[[#This Row],[file name]],LEN(Tableau4[[#This Row],[file name]])-SEARCH("@",Tableau4[[#This Row],[file name]])),LEN(RIGHT(Tableau4[[#This Row],[file name]],LEN(Tableau4[[#This Row],[file name]])-SEARCH("@",Tableau4[[#This Row],[file name]])))-SEARCH("/",RIGHT(Tableau4[[#This Row],[file name]],LEN(Tableau4[[#This Row],[file name]])-SEARCH("@",Tableau4[[#This Row],[file name]])))),1) -> H | C43: D:\images\2022-CHG-NLO-dutasteride\plaque 1/@01 TS/H1_03.tif | D43: 14.4318 | E43: 65.0588 | G43: 939
A44: =IFERROR(LEFT(RIGHT(C44,LEN(C44)-SEARCH("@",C44)),SEARCH("/",RIGHT(C44,LEN(C44)-SEARCH("@",C44)-1))),"") | B44: =LEFT(RIGHT(RIGHT(Tableau4[[#This Row],[file name]],LEN(Tableau4[[#This Row],[file name]])-SEARCH("@",Tableau4[[#This Row],[file name]])),LEN(RIGHT(Tableau4[[#This Row],[file name]],LEN(Tableau4[[#This Row],[file name]])-SEARCH("@",Tableau4[[#This Row],[file name]])))-SEARCH("/",RIGHT(Tableau4[[#This Row],[file name]],LEN(Tableau4[[#This Row],[file name]])-SEARCH("@",Tableau4[[#This Row],[file name]])))),1) -> #VALUE!
A45: =IFERROR(LEFT(RIGHT(C45,LEN(C45)-SEARCH("@",C45)),SEARCH("/",RIGHT(C45,LEN(C45)-SEARCH("@",C45)-1))),"") | B45: =LEFT(RIGHT(RIGHT(Tableau4[[#This Row],[file name]],LEN(Tableau4[[#This Row],[file name]])-SEARCH("@",Tableau4[[#This Row],[file name]])),LEN(RIGHT(Tableau4[[#This Row],[file name]],LEN(Tableau4[[#This Row],[file name]])-SEARCH("@",Tableau4[[#This Row],[file name]])))-SEARCH("/",RIGHT(Tableau4[[#This Row],[file name]],LEN(Tableau4[[#This Row],[file name]])-SEARCH("@",Tableau4[[#This Row],[file name]])))),1) -> #VALUE! | C45: group | E45: mean of mean fluo | F45: SD mean fluo | G45: mean of total fluo | H45: SD total fluo | I45: n fluorescent | J45: n total
A46: =IFERROR(LEFT(RIGHT(C46,LEN(C46)-SEARCH("@",C46)),SEARCH("/",RIGHT(C46,LEN(C46)-SEARCH("@",C46)-1))),"") -> 01 TS | B46: =LEFT(RIGHT(RIGHT(Tableau4[[#This Row],[file name]],LEN(Tableau4[[#This Row],[file name]])-SEARCH("@",Tableau4[[#This Row],[file name]])),LEN(RIGHT(Tableau4[[#This Row],[file name]],LEN(Tableau4[[#This Row],[file name]])-SEARCH("@",Tableau4[[#This Row],[file name]])))-SEARCH("/",RIGHT(Tableau4[[#This Row],[file name]],LEN(Tableau4[[#This Row],[file name]])-SEARCH("@",Tableau4[[#This Row],[file name]])))),1) | C46: D:\images\2022-CHG-NLO-dutasteride\plaque 1/@01 TS/ | E46: 64.8259 | F46: 1.3243 | G46: 3960.6667 | H46: 5055.9931 | I46: 24 | J46: 24
...

Sheet R1
A1: 3. Expérimentateur 1 : copier et coller les valeurs des intensités totales de fluorescences obtenues dans le fichier raw data lors du traitement des images.
A3: R1 | B3: Non dopé | O3: avec testo
A4: Noms des groupes | B4: ='Page de garde'!A7 -> Témoin solvant | C4: ='Page de garde'!A9 -> EE2-33.8ng/L | D4: ='Page de garde'!A10 -> EE2-50.6ng/L | E4: ='Page de garde'!A11 -> EE2-76ng/L | F4: ='Page de garde'!A12 -> EE2-114ng/L | G4: ='Page de garde'!A13 -> EE2-170.9ng/L | H4: ='Page de garde'!A14 -> EE2-488ng/L | I4: ='Page de garde'!A15 -> Dutasteride-0,01mg/L | J4: ='Page de garde'!A16 -> Dutasteride-0,1mg/L | K4: ='Page de garde'!A17 -> Dutasteride-0,25mg/L | L4: ='Page de garde'!A18 -> Dutasteride-0,5mg/L | M4: ='Page de garde'!A19 -> Dutasteride-1mg/L | O4: ='Page de garde'!A36 -> Testo -30µg/L | P4: ='Page de garde'!A37 -> Testo 30µg/L + EE2 -64ng/L | Q4: ='Page de garde'!A38 -> Testo 30µg/L + FAD-10µg/L | R4: ='Page de garde'!A39 -> Dutasteride-0.01mg/L + Testostérone | S4: ='Page de garde'!A40 -> Dutasteride-0.1mg/L + Testostérone | T4: ='Page de garde'!A41 -> Dutasteride-0.25mg/L + Testostérone | U4: ='Page de garde'!A42 -> Dutasteride-0.5mg/L + Testostérone | V4: ='Page de garde'!A43 -> Dutasteride-1mg/L + Testostérone
A5: Données brutes | B5: 898.33333 | C5: 1228.6667 | D5: 841 | E5: 4087 | F5: 23266.667 | G5: 76987 | H5: 289398.67 | I5: 25658.333 | J5: 4114.6667 | K5: 7253 | M5: 736 | O5: 87488 | P5: 179834 | Q5: 2703 | R5: 132753.67 | S5: 99442.667 | T5: 144318.67 | U5: 127357.5 | V5: 113581
B6: 655.33333 | C6: 299 | D6: 1106.6667 | E6: 32840.667 | F6: 21138.333 | G6: 160526.67 | H6: 220805.33 | I6: 890 | J6: 508.33333 | K6: 1929 | L6: 815.66667 | M6: 544.66667 | O6: 27740 | P6: 85611.667 | Q6: 1804.6667 | R6: 2280 | S6: 71544.667 | T6: 13125.333 | U6: 135077 | V6: 81609.667
B7: 7962 | C7: 3989 | D7: 517.66667 | E7: 1876.5 | F7: 24673.667 | G7: 101078.33 | H7: 150270.67 | I7: 840.66667 | J7: 936 | K7: 4509.6667 | L7: 3784.3333 | M7: 358 | O7: 128175.5 | P7: 134675 | Q7: 925.66667 | R7: 33958 | S7: 118920.67 | T7: 36777.667 | U7: 80494.667 | V7: 77971
B8: 2038.6667 | C8: 622.66667 | D8: 3250.5 | E8: 1802.6667 | F8: 70945.333 | G8: 4761 | H8: 48490 | I8: 740.66667 | J8: 582.66667 | K8: 544 | L8: 2303.6667 | M8: 7337 | O8: 113809 | P8: 119801 | Q8: 3260 | R8: 68780.333 | S8: 80031.667 | T8: 21010 | U8: 145377.67 | V8: 70565.333
B9: 3827.3333 | C9: 886.33333 | D9: 9380 | E9: 5211.3333 | F9: 31265 | G9: 128211.67 | H9: 184792.67 | I9: 882.33333 | J9: 10898.5 | K9: 1237 | L9: 473.33333 | M9: 538 | O9: 50367.333 | P9: 8001 | Q9: 4983.6667 | R9: 73197.667 | S9: 30221 | T9: 35624 | U9: 84514.333 | V9: 2584.3333
B10: 7548 | C10: 1490 | D10: 823.66667 | E10: 1377.6667 | F10: 52712 | G10: 95670 | H10: 117331.33 | I10: 1777.3333 | J10: 3746 | K10: 1305.6667 | L10: 6782 | M10: 28785 | O10: 42078 | P10: 126312.67 | Q10: 1286 | R10: 18571 | S10: 102472.67 | T10: 16015.333 | U10: 50323 | V10: 29598
B11: 8112 | C11: 6912.3333 | D11: 1055.6667 | E11: 5890.6667 | F11: 62986.333 | G11: 143495 | H11: 190470.33 | I11: 2602.6667 | J11: 7991.3333 | K11: 564 | L11: 628 | M11: 1659 | O11: 55672.333 | P11: 118578.33 | Q11: 1832 | R11: 427 | S11: 3385 | T11: 124834.33 | U11: 121794.67 | V11: 14828.667
B12: 643.66667 | C12: 1064.3333 | D12: 12822.333 | E12: 7090.3333 | F12: 64881.333 | G12: 138335 | H12: 165996.33 | I12: 2072 | J12: 662 | K12: 3253.6667 | L12: 652 | M12: 588 | O12: 31594 | P12: 115345 | Q12: 1432.3333 | R12: 76731 | S12: 24632 | T12: 87894.333 | U12: 96709 | V12: 31206.667
O13: 664.5
O14: 46034
O15: 86265.667
O16: 70306
O17: 36335
O18: 74464.667
O19: 12800
O20: 54967.333
A22: =A4 -> Noms des groupes | B22: =B4 -> Témoin solvant | C22: =C4 -> EE2-33.8ng/L | D22: =D4 -> EE2-50.6ng/L | E22: =E4 -> EE2-76ng/L | F22: =F4 -> EE2-114ng/L | G22: =G4 -> EE2-170.9ng/L | H22: =H4 -> EE2-488ng/L | ... M22: =M4 -> Dutasteride-1mg/L | N22: Nom des groupes | O22: =O4 -> Testo -30µg/L | P22: =P4 -> Testo 30µg/L + EE2 -64ng/L | Q22: =Q4 -> Testo 30µg/L + FAD-10µg/L | R22: =R4 -> Dutasteride-0.01mg/L + Testostérone | S22: =S4 -> Dutasteride-0.1mg/L + Testostérone | T22: =T4 -> Dutasteride-0.25mg/L + Testostérone | U22: =U4 -> Dutasteride-0.5mg/L + Testostérone | V22: =V4 -> Dutasteride-1mg/L + Testostérone
A23: mean | B23: =AVERAGE(B5:B20) -> 3960.6667 | C23: =AVERAGE(C5:C20) -> 2061.5417 | D23: =AVERAGE(D5:D20) -> 3724.6875 | E23: =AVERAGE(E5:E20) -> 7522.1042 | F23: =AVERAGE(F5:F20) -> 43983.583 | G23: =AVERAGE(G5:G20) -> 106133.08 | H23: =AVERAGE(H5:H20) -> 170944.42 | I23: =AVERAGE(I5:I20) -> 4433 | ... M23: =AVERAGE(M5:M20) -> 5068.2083 | N23: mean | O23: =AVERAGE(O5:O20) -> 57422.583 | P23: =AVERAGE(P5:P20) -> 111019.83 | Q23: =AVERAGE(Q5:Q20) -> 2278.4167 | R23: =AVERAGE(R5:R20) -> 50837.333 | S23: =AVERAGE(S5:S20) -> 66331.292 | T23: =AVERAGE(T5:T20) -> 59949.958 | U23: =AVERAGE(U5:U20) -> 105205.98 | V23: =AVERAGE(V5:V20) -> 52743.083
A24: SD | B24: =STDEV(B5:B20) -> 3404.4228 | C24: =STDEV(C5:C20) -> 2262.0493 | D24: =STDEV(D5:D20) -> 4720.3032 | E24: =STDEV(E5:E20) -> 10442.743 | F24: =STDEV(F5:F20) -> 20998.888 | G24: =STDEV(G5:G20) -> 49482.785 | H24: =STDEV(H5:H20) -> 71125.533 | I24: =STDEV(I5:I20) -> 8603.9032 | ... M24: =STDEV(M5:M20) -> 9865.292 | N24: SD | O24: =STDEV(O5:O20) -> 34647.951 | P24: =STDEV(P5:P20) -> 49193.828 | Q24: =STDEV(Q5:Q20) -> 1331.8388 | R24: =STDEV(R5:R20) -> 45399.415 | S24: =STDEV(S5:S20) -> 42068.148 | T24: =STDEV(T5:T20) -> 51929.586 | U24: =STDEV(U5:U20) -> 32502.857 | V24: =STDEV(V5:V20) -> 38621.843
B26: Non dopé | O26: avec testo
A27: Noms des groupes | B27: =B4 -> Témoin solvant | C27: =C4 -> EE2-33.8ng/L | D27: =D4 -> EE2-50.6ng/L | E27: =E4 -> EE2-76ng/L | F27: =F4 -> EE2-114ng/L | G27: =G4 -> EE2-170.9ng/L | H27: =H4 -> EE2-488ng/L | I27: =I4 -> Dutasteride-0,01mg/L | ... M27: =M4 -> Dutasteride-1mg/L | O27: =O4 -> Testo -30µg/L | P27: =P4 -> Testo 30µg/L + EE2 -64ng/L | Q27: =Q4 -> Testo 30µg/L + FAD-10µg/L | R27: =R4 -> Dutasteride-0.01mg/L + Testostérone | S27: =S4 -> Dutasteride-0.1mg/L + Testostérone | T27: =T4 -> Dutasteride-0.25mg/L + Testostérone | U27: =U4 -> Dutasteride-0.5mg/L + Testostérone | V27: =V4 -> Dutasteride-1mg/L + Testostérone
A28: Données normalisées sur la moyenne du groupe "Testo" | B28: =IF(B5="","",(B5/$O$23)) -> 0.015644251 | C28: =IF(C5="","",(C5/$O$23)) -> 0.021396924 | D28: =IF(D5="","",(D5/$O$23)) -> 0.014645806 | E28: =IF(E5="","",(E5/$O$23)) -> 0.071174088 | F28: =IF(F5="","",(F5/$O$23)) -> 0.40518321 | G28: =IF(G5="","",(G5/$O$23)) -> 1.3407094 | H28: =IF(H5="","",(H5/$O$23)) -> 5.0398058 | I28: =IF(I5="","",(I5/$O$23)) -> 0.44683349 | ... M28: =IF(M5="","",(M5/$O$23)) -> 0.012817257 | O28: =IF(O5="","",(O5/$O$23)) -> 1.5235817 | P28: =IF(P5="","",(P5/$O$23)) -> 3.1317644 | Q28: =IF(Q5="","",(Q5/$O$23)) -> 0.047072072 | R28: =IF(R5="","",(R5/$O$23)) -> 2.3118721 | S28: =IF(S5="","",(S5/$O$23)) -> 1.7317693 | T28: =IF(T5="","",(T5/$O$23)) -> 2.5132737 | U28: =IF(U5="","",(U5/$O$23)) -> 2.2178992 | V28: =IF(V5="","",(V5/$O$23)) -> 1.9779849
B29: =IF(B6="","",(B6/$O$23)) -> 0.011412467 | C29: =IF(C6="","",(C6/$O$23)) -> 0.0052070106 | D29: =IF(D6="","",(D6/$O$23)) -> 0.019272325 | E29: =IF(E6="","",(E6/$O$23)) -> 0.57191204 | F29: =IF(F6="","",(F6/$O$23)) -> 0.36811882 | G29: =IF(G6="","",(G6/$O$23)) -> 2.795532 | H29: =IF(H6="","",(H6/$O$23)) -> 3.8452699 | I29: =IF(I6="","",(I6/$O$23)) -> 0.015499129 | ... M29: =IF(M6="","",(M6/$O$23)) -> 0.0094852345 | O29: =IF(O6="","",(O6/$O$23)) -> 0.4830852 | P29: =IF(P6="","",(P6/$O$23)) -> 1.4909059 | Q29: =IF(Q6="","",(Q6/$O$23)) -> 0.031427821 | R29: =IF(R6="","",(R6/$O$23)) -> 0.039705633 | S29: =IF(S6="","",(S6/$O$23)) -> 1.2459326 | T29: =IF(T6="","",(T6/$O$23)) -> 0.22857441 | U29: =IF(U6="","",(U6/$O$23)) -> 2.3523323 | V29: =IF(V6="","",(V6/$O$23)) -> 1.421212
B30: =IF(B7="","",(B7/$O$23)) -> 0.13865625 | C30: =IF(C7="","",(C7/$O$23)) -> 0.069467442 | D30: =IF(D7="","",(D7/$O$23)) -> 0.0090150362 | E30: =IF(E7="","",(E7/$O$23)) -> 0.032678781 | F30: =IF(F7="","",(F7/$O$23)) -> 0.42968577 | G30: =IF(G7="","",(G7/$O$23)) -> 1.760254 | H30: =IF(H7="","",(H7/$O$23)) -> 2.6169263 | I30: =IF(I7="","",(I7/$O$23)) -> 0.014640001 | ... M30: =IF(M7="","",(M7/$O$23)) -> 0.0062344809 | O30: =IF(O7="","",(O7/$O$23)) -> 2.2321444 | P30: =IF(P7="","",(P7/$O$23)) -> 2.3453316 | Q30: =IF(Q7="","",(Q7/$O$23)) -> 0.016120255 | R30: =IF(R7="","",(R7/$O$23)) -> 0.59137012 | S30: =IF(S7="","",(S7/$O$23)) -> 2.0709738 | T30: =IF(T7="","",(T7/$O$23)) -> 0.64047391 | U30: =IF(U7="","",(U7/$O$23)) -> 1.4017946 | V30: =IF(V7="","",(V7/$O$23)) -> 1.3578456
B31: =IF(B8="","",(B8/$O$23)) -> 0.035502873 | C31: =IF(C8="","",(C8/$O$23)) -> 0.010843585 | D31: =IF(D8="","",(D8/$O$23)) -> 0.056606649 | E31: =IF(E8="","",(E8/$O$23)) -> 0.031392991 | F31: =IF(F8="","",(F8/$O$23)) -> 1.2354953 | G31: =IF(G8="","",(G8/$O$23)) -> 0.08291163 | H31: =IF(H8="","",(H8/$O$23)) -> 0.84444128 | I31: =IF(I8="","",(I8/$O$23)) -> 0.012898526 | ... M31: =IF(M8="","",(M8/$O$23)) -> 0.12777203 | O31: =IF(O8="","",(O8/$O$23)) -> 1.9819554 | P31: =IF(P8="","",(P8/$O$23)) -> 2.0863046 | Q31: =IF(Q8="","",(Q8/$O$23)) -> 0.056772089 | R31: =IF(R8="","",(R8/$O$23)) -> 1.1977924 | S31: =IF(S8="","",(S8/$O$23)) -> 1.3937316 | T31: =IF(T8="","",(T8/$O$23)) -> 0.36588392 | U31: =IF(U8="","",(U8/$O$23)) -> 2.5317159 | V31: =IF(V8="","",(V8/$O$23)) -> 1.2288777
B32: =IF(B9="","",(B9/$O$23)) -> 0.066652058 | C32: =IF(C9="","",(C9/$O$23)) -> 0.015435274 | D32: =IF(D9="","",(D9/$O$23)) -> 0.16335037 | E32: =IF(E9="","",(E9/$O$23)) -> 0.090754073 | F32: =IF(F9="","",(F9/$O$23)) -> 0.5444722 | G32: =IF(G9="","",(G9/$O$23)) -> 2.2327743 | H32: =IF(H9="","",(H9/$O$23)) -> 3.2181183 | I32: =IF(I9="","",(I9/$O$23)) -> 0.015365615 | ... M32: =IF(M9="","",(M9/$O$23)) -> 0.0093691361 | O32: =IF(O9="","",(O9/$O$23)) -> 0.87713458 | P32: =IF(P9="","",(P9/$O$23)) -> 0.13933542 | Q32: =IF(Q9="","",(Q9/$O$23)) -> 0.086789315 | R32: =IF(R9="","",(R9/$O$23)) -> 1.2747192 | S32: =IF(S9="","",(S9/$O$23)) -> 0.52629119 | T32: =IF(T9="","",(T9/$O$23)) -> 0.6203831 | U32: =IF(U9="","",(U9/$O$23)) -> 1.4717961 | V32: =IF(V9="","",(V9/$O$23)) -> 0.045005522
B33: =IF(B10="","",(B10/$O$23)) -> 0.13144654 | C33: =IF(C10="","",(C10/$O$23)) -> 0.025947979 | D33: =IF(D10="","",(D10/$O$23)) -> 0.01434395 | E33: =IF(E10="","",(E10/$O$23)) -> 0.023991722 | F33: =IF(F10="","",(F10/$O$23)) -> 0.91796636 | G33: =IF(G10="","",(G10/$O$23)) -> 1.6660692 | H33: =IF(H10="","",(H10/$O$23)) -> 2.043296 | I33: =IF(I10="","",(I10/$O$23)) -> 0.030951818 | ... M33: =IF(M10="","",(M10/$O$23)) -> 0.50128361 | O33: =IF(O10="","",(O10/$O$23)) -> 0.7327779 | P33: =IF(P10="","",(P10/$O$23)) -> 2.1997037 | Q33: =IF(Q10="","",(Q10/$O$23)) -> 0.02239537 | R33: =IF(R10="","",(R10/$O$23)) -> 0.32340934 | S33: =IF(S10="","",(S10/$O$23)) -> 1.784536 | T33: =IF(T10="","",(T10/$O$23)) -> 0.27890304 | U33: =IF(U10="","",(U10/$O$23)) -> 0.87636252 | V33: =IF(V10="","",(V10/$O$23)) -> 0.5154418
B34: =IF(B11="","",(B11/$O$23)) -> 0.14126846 | C34: =IF(C11="","",(C11/$O$23)) -> 0.12037656 | D34: =IF(D11="","",(D11/$O$23)) -> 0.018384172 | E34: =IF(E11="","",(E11/$O$23)) -> 0.10258449 | F34: =IF(F11="","",(F11/$O$23)) -> 1.0968913 | G34: =IF(G11="","",(G11/$O$23)) -> 2.4989297 | H34: =IF(H11="","",(H11/$O$23)) -> 3.3169935 | I34: =IF(I11="","",(I11/$O$23)) -> 0.045324792 | ... M34: =IF(M11="","",(M11/$O$23)) -> 0.028891072 | O34: =IF(O11="","",(O11/$O$23)) -> 0.96951983 | P34: =IF(P11="","",(P11/$O$23)) -> 2.0650122 | Q34: =IF(Q11="","",(Q11/$O$23)) -> 0.031903824 | R34: =IF(R11="","",(R11/$O$23)) -> 0.0074360987 | S34: =IF(S11="","",(S11/$O$23)) -> 0.058948933 | T34: =IF(T11="","",(T11/$O$23)) -> 2.1739589 | U34: =IF(U11="","",(U11/$O$23)) -> 2.1210238 | V34: =IF(V11="","",(V11/$O$23)) -> 0.25823754
B35: =IF(B12="","",(B12/$O$23)) -> 0.011209295 | C35: =IF(C12="","",(C12/$O$23)) -> 0.0185351 | D35: =IF(D12="","",(D12/$O$23)) -> 0.22329774 | E35: =IF(E12="","",(E12/$O$23)) -> 0.12347639 | F35: =IF(F12="","",(F12/$O$23)) -> 1.1298923 | G35: =IF(G12="","",(G12/$O$23)) -> 2.4090696 | H35: =IF(H12="","",(H12/$O$23)) -> 2.8907848 | I35: =IF(I12="","",(I12/$O$23)) -> 0.036083364 | ... M35: =IF(M12="","",(M12/$O$23)) -> 0.010239874 | O35: =IF(O12="","",(O12/$O$23)) -> 0.55020165 | P35: =IF(P12="","",(P12/$O$23)) -> 2.0087045 | Q35: =IF(Q12="","",(Q12/$O$23)) -> 0.024943729 | R35: =IF(R12="","",(R12/$O$23)) -> 1.3362513 | S35: =IF(S12="","",(S12/$O$23)) -> 0.42896015 | T35: =IF(T12="","",(T12/$O$23)) -> 1.5306579 | U35: =IF(U12="","",(U12/$O$23)) -> 1.6841632 | V35: =IF(V12="","",(V12/$O$23)) -> 0.54345633
B36: =IF(B13="","",(B13/$O$23)) | C36: =IF(C13="","",(C13/$O$23)) | D36: =IF(D13="","",(D13/$O$23)) | E36: =IF(E13="","",(E13/$O$23)) | F36: =IF(F13="","",(F13/$O$23)) | G36: =IF(G13="","",(G13/$O$23)) | H36: =IF(H13="","",(H13/$O$23)) | I36: =IF(I13="","",(I13/$O$23)) | ... M36: =IF(M13="","",(M13/$O$23)) | O36: =IF(O13="","",(O13/$O$23)) -> 0.011572102 | P36: =IF(P13="","",(P13/$O$23)) | Q36: =IF(Q13="","",(Q13/$O$23)) | R36: =IF(R13="","",(R13/$O$23)) | S36: =IF(S13="","",(S13/$O$23)) | T36: =IF(T13="","",(T13/$O$23)) | U36: =IF(U13="","",(U13/$O$23)) | V36: =IF(V13="","",(V13/$O$23))
B37: =IF(B14="","",(B14/$O$23)) | C37: =IF(C14="","",(C14/$O$23)) | D37: =IF(D14="","",(D14/$O$23)) | E37: =IF(E14="","",(E14/$O$23)) | F37: =IF(F14="","",(F14/$O$23)) | G37: =IF(G14="","",(G14/$O$23)) | H37: =IF(H14="","",(H14/$O$23)) | I37: =IF(I14="","",(I14/$O$23)) | ... M37: =IF(M14="","",(M14/$O$23)) | O37: =IF(O14="","",(O14/$O$23)) -> 0.80167066 | P37: =IF(P14="","",(P14/$O$23)) | Q37: =IF(Q14="","",(Q14/$O$23)) | R37: =IF(R14="","",(R14/$O$23)) | S37: =IF(S14="","",(S14/$O$23)) | T37: =IF(T14="","",(T14/$O$23)) | U37: =IF(U14="","",(U14/$O$23)) | V37: =IF(V14="","",(V14/$O$23))
B38: =IF(B15="","",(B15/$O$23)) | C38: =IF(C15="","",(C15/$O$23)) | D38: =IF(D15="","",(D15/$O$23)) | E38: =IF(E15="","",(E15/$O$23)) | F38: =IF(F15="","",(F15/$O$23)) | G38: =IF(G15="","",(G15/$O$23)) | H38: =IF(H15="","",(H15/$O$23)) | I38: =IF(I15="","",(I15/$O$23)) | ... M38: =IF(M15="","",(M15/$O$23)) | O38: =IF(O15="","",(O15/$O$23)) -> 1.5022951 | P38: =IF(P15="","",(P15/$O$23)) | Q38: =IF(Q15="","",(Q15/$O$23)) | R38: =IF(R15="","",(R15/$O$23)) | S38: =IF(S15="","",(S15/$O$23)) | T38: =IF(T15="","",(T15/$O$23)) | U38: =IF(U15="","",(U15/$O$23)) | V38: =IF(V15="","",(V15/$O$23))
B39: =IF(B16="","",(B16/$O$23)) | C39: =IF(C16="","",(C16/$O$23)) | D39: =IF(D16="","",(D16/$O$23)) | E39: =IF(E16="","",(E16/$O$23)) | F39: =IF(F16="","",(F16/$O$23)) | G39: =IF(G16="","",(G16/$O$23)) | H39: =IF(H16="","",(H16/$O$23)) | I39: =IF(I16="","",(I16/$O$23)) | ... M39: =IF(M16="","",(M16/$O$23)) | O39: =IF(O16="","",(O16/$O$23)) -> 1.2243615 | P39: =IF(P16="","",(P16/$O$23)) | Q39: =IF(Q16="","",(Q16/$O$23)) | R39: =IF(R16="","",(R16/$O$23)) | S39: =IF(S16="","",(S16/$O$23)) | T39: =IF(T16="","",(T16/$O$23)) | U39: =IF(U16="","",(U16/$O$23)) | V39: =IF(V16="","",(V16/$O$23))
