Workbook

Sheet Page de garde
A1: 1. Expérimentateur 1 : copier et coller le n° de prestation et renseigner la date de réalisation de chaque réplica ainsi que le visa de l'expérimentateur.
A2: R1 | B2: Numéro d'expérience : | E2: Date de réalisation :
A3: R2 | B3: Numéro d'expérience : | E3: Date de réalisation :
A4: R3 | B4: Numéro d'expérience : | E4: Date de réalisation :
A5: 2. Expérimentateur 1 : copier et coller la dilution appliquée et le nom donné pour chaque des échantillons par le client. Conserver la mise en forme de l'exemple en italique. Ne pas remplir la colonne "nom sur graphique".
A6: Nom sur le graphique | B6: Code WF | C6: Concentration | D6: Unité | E6: Nom de l'échantillon donné par le client | F6: Dopage (+Testostérone / + EE2, ….)
A7: =IF(ISBLANK(liste_groupe[[#This Row],[Code WF]])," ",IF(ISBLANK(liste_groupe[[#This Row],[Unité]]),CONCATENATE(liste_groupe[[#This Row],[Nom de l''échantillon donné par le client]],liste_groupe[[#This Row],[Dopage (+Testostérone / + EE2, ….)]]),CONCATENATE(liste_groupe[[#This Row],[Nom de l''échantillon donné par le client]],"-",liste_groupe[[#This Row],[Concentration]],liste_groupe[[#This Row],[Unité]],liste_groupe[[#This Row],[Dopage (+Testostérone / + EE2, ….)]]))) -> Témoin solvant | B7: Témoin | E7: Témoin solvant
A8: =IF(ISBLANK(liste_groupe[[#This Row],[Code WF]])," ",IF(ISBLANK(liste_groupe[[#This Row],[Unité]]),CONCATENATE(liste_groupe[[#This Row],[Nom de l''échantillon donné par le client]],liste_groupe[[#This Row],[Dopage (+Testostérone / + EE2, ….)]]),CONCATENATE(liste_groupe[[#This Row],[Nom de l''échantillon donné par le client]],"-",liste_groupe[[#This Row],[Concentration]],liste_groupe[[#This Row],[Unité]],liste_groupe[[#This Row],[Dopage (+Testostérone / + EE2, ….)]]))) -> EE2-22,5ng/L | B8: Témoin | C8: 22.5 | D8: ng/L | E8: EE2
A9: =IF(ISBLANK(liste_groupe[[#This Row],[Code WF]])," ",IF(ISBLANK(liste_groupe[[#This Row],[Unité]]),CONCATENATE(liste_groupe[[#This Row],[Nom de l''échantillon donné par le client]],liste_groupe[[#This Row],[Dopage (+Testostérone / + EE2, ….)]]),CONCATENATE(liste_groupe[[#This Row],[Nom de l''échantillon donné par le client]],"-",liste_groupe[[#This Row],[Concentration]],liste_groupe[[#This Row],[Unité]],liste_groupe[[#This Row],[Dopage (+Testostérone / + EE2, ….)]]))) -> EE2-33,8ng/L | B9: Témoin | C9: 33.8 | D9: ng/L | E9: EE2
A10: =IF(ISBLANK(liste_groupe[[#This Row],[Code WF]])," ",IF(ISBLANK(liste_groupe[[#This Row],[Unité]]),CONCATENATE(liste_groupe[[#This Row],[Nom de l''échantillon donné par le client]],liste_groupe[[#This Row],[Dopage (+Testostérone / + EE2, ….)]]),CONCATENATE(liste_groupe[[#This Row],[Nom de l''échantillon donné par le client]],"-",liste_groupe[[#This Row],[Concentration]],liste_groupe[[#This Row],[Unité]],liste_groupe[[#This Row],[Dopage (+Testostérone / + EE2, ….)]]))) -> EE2-50,6ng/L | B10: Témoin | C10: 50.6 | D10: ng/L | E10: EE2
A11: =IF(ISBLANK(liste_groupe[[#This Row],[Code WF]])," ",IF(ISBLANK(liste_groupe[[#This Row],[Unité]]),CONCATENATE(liste_groupe[[#This Row],[Nom de l''échantillon donné par le client]],liste_groupe[[#This Row],[Dopage (+Testostérone / + EE2, ….)]]),CONCATENATE(liste_groupe[[#This Row],[Nom de l''échantillon donné par le client]],"-",liste_groupe[[#This Row],[Concentration]],liste_groupe[[#This Row],[Unité]],liste_groupe[[#This Row],[Dopage (+Testostérone / + EE2, ….)]]))) -> EE2-76ng/L | B11: Témoin | C11: 76 | D11: ng/L | E11: EE2
A12: =IF(ISBLANK(liste_groupe[[#This Row],[Code WF]])," ",IF(ISBLANK(liste_groupe[[#This Row],[Unité]]),CONCATENATE(liste_groupe[[#This Row],[Nom de l''échantillon donné par le client]],liste_groupe[[#This Row],[Dopage (+Testostérone / + EE2, ….)]]),CONCATENATE(liste_groupe[[#This Row],[Nom de l''échantillon donné par le client]],"-",liste_groupe[[#This Row],[Concentration]],liste_groupe[[#This Row],[Unité]],liste_groupe[[#This Row],[Dopage (+Testostérone / + EE2, ….)]]))) -> EE2-114ng/L | B12: Témoin | C12: 114 | D12: ng/L | E12: EE2
A13: =IF(ISBLANK(liste_groupe[[#This Row],[Code WF]])," ",IF(ISBLANK(liste_groupe[[#This Row],[Unité]]),CONCATENATE(liste_groupe[[#This Row],[Nom de l''échantillon donné par le client]],liste_groupe[[#This Row],[Dopage (+Testostérone / + EE2, ….)]]),CONCATENATE(liste_groupe[[#This Row],[Nom de l''échantillon donné par le client]],"-",liste_groupe[[#This Row],[Concentration]],liste_groupe[[#This Row],[Unité]],liste_groupe[[#This Row],[Dopage (+Testostérone / + EE2, ….)]]))) -> EE2-170,9ng/L | B13: Témoin | C13: 170.9 | D13: ng/L | E13: EE2
A14: =IF(ISBLANK(liste_groupe[[#This Row],[Code WF]])," ",IF(ISBLANK(liste_groupe[[#This Row],[Unité]]),CONCATENATE(liste_groupe[[#This Row],[Nom de l''échantillon donné par le client]],liste_groupe[[#This Row],[Dopage (+Testostérone / + EE2, ….)]]),CONCATENATE(liste_groupe[[#This Row],[Nom de l''échantillon donné par le client]],"-",liste_groupe[[#This Row],[Concentration]],liste_groupe[[#This Row],[Unité]],liste_groupe[[#This Row],[Dopage (+Testostérone / + EE2, ….)]]))) -> EE2-488ng/L | B14: Témoin | C14: 488 | D14: ng/L | E14: EE2
A15: =IF(ISBLANK(liste_groupe[[#This Row],[Code WF]])," ",IF(ISBLANK(liste_groupe[[#This Row],[Unité]]),CONCATENATE(liste_groupe[[#This Row],[Nom de l''échantillon donné par le client]],liste_groupe[[#This Row],[Dopage (+Testostérone / + EE2, ….)]]),CONCATENATE(liste_groupe[[#This Row],[Nom de l''échantillon donné par le client]],"-",liste_groupe[[#This Row],[Concentration]],liste_groupe[[#This Row],[Unité]],liste_groupe[[#This Row],[Dopage (+Testostérone / + EE2, ….)]])))
A16: =IF(ISBLANK(liste_groupe[[#This Row],[Code WF]])," ",IF(ISBLANK(liste_groupe[[#This Row],[Unité]]),CONCATENATE(liste_groupe[[#This Row],[Nom de l''échantillon donné par le client]],liste_groupe[[#This Row],[Dopage (+Testostérone / + EE2, ….)]]),CONCATENATE(liste_groupe[[#This Row],[Nom de l''échantillon donné par le client]],"-",liste_groupe[[#This Row],[Concentration]],liste_groupe[[#This Row],[Unité]],liste_groupe[[#This Row],[Dopage (+Testostérone / + EE2, ….)]])))
A17: =IF(ISBLANK(liste_groupe[[#This Row],[Code WF]])," ",IF(ISBLANK(liste_groupe[[#This Row],[Unité]]),CONCATENATE(liste_groupe[[#This Row],[Nom de l''échantillon donné par le client]],liste_groupe[[#This Row],[Dopage (+Testostérone / + EE2, ….)]]),CONCATENATE(liste_groupe[[#This Row],[Nom de l''échantillon donné par le client]],"-",liste_groupe[[#This Row],[Concentration]],liste_groupe[[#This Row],[Unité]],liste_groupe[[#This Row],[Dopage (+Testostérone / + EE2, ….)]])))
A18: =IF(ISBLANK(liste_groupe[[#This Row],[Code WF]])," ",IF(ISBLANK(liste_groupe[[#This Row],[Unité]]),CONCATENATE(liste_groupe[[#This Row],[Nom de l''échantillon donné par le client]],liste_groupe[[#This Row],[Dopage (+Testostérone / + EE2, ….)]]),CONCATENATE(liste_groupe[[#This Row],[Nom de l''échantillon donné par le client]],"-",liste_groupe[[#This Row],[Concentration]],liste_groupe[[#This Row],[Unité]],liste_groupe[[#This Row],[Dopage (+Testostérone / + EE2, ….)]])))
A19: =IF(ISBLANK(liste_groupe[[#This Row],[Code WF]])," ",IF(ISBLANK(liste_groupe[[#This Row],[Unité]]),CONCATENATE(liste_groupe[[#This Row],[Nom de l''échantillon donné par le client]],liste_groupe[[#This Row],[Dopage (+Testostérone / + EE2, ….)]]),CONCATENATE(liste_groupe[[#This Row],[Nom de l''échantillon donné par le client]],"-",liste_groupe[[#This Row],[Concentration]],liste_groupe[[#This Row],[Unité]],liste_groupe[[#This Row],[Dopage (+Testostérone / + EE2, ….)]])))
A20: =IF(ISBLANK(liste_groupe[[#This Row],[Code WF]])," ",IF(ISBLANK(liste_groupe[[#This Row],[Unité]]),CONCATENATE(liste_groupe[[#This Row],[Nom de l''échantillon donné par le client]],liste_groupe[[#This Row],[Dopage (+Testostérone / + EE2, ….)]]),CONCATENATE(liste_groupe[[#This Row],[Nom de l''échantillon donné par le client]],"-",liste_groupe[[#This Row],[Concentration]],liste_groupe[[#This Row],[Unité]],liste_groupe[[#This Row],[Dopage (+Testostérone / + EE2, ….)]])))
A21: =IF(ISBLANK(liste_groupe[[#This Row],[Code WF]])," ",IF(ISBLANK(liste_groupe[[#This Row],[Unité]]),CONCATENATE(liste_groupe[[#This Row],[Nom de l''échantillon donné par le client]],liste_groupe[[#This Row],[Dopage (+Testostérone / + EE2, ….)]]),CONCATENATE(liste_groupe[[#This Row],[Nom de l''échantillon donné par le client]],"-",liste_groupe[[#This Row],[Concentration]],liste_groupe[[#This Row],[Unité]],liste_groupe[[#This Row],[Dopage (+Testostérone / + EE2, ….)]])))
A22: =IF(ISBLANK(liste_groupe[[#This Row],[Code WF]])," ",IF(ISBLANK(liste_groupe[[#This Row],[Unité]]),CONCATENATE(liste_groupe[[#This Row],[Nom de l''échantillon donné par le client]],liste_groupe[[#This Row],[Dopage (+Testostérone / + EE2, ….)]]),CONCATENATE(liste_groupe[[#This Row],[Nom de l''échantillon donné par le client]],"-",liste_groupe[[#This Row],[Concentration]],liste_groupe[[#This Row],[Unité]],liste_groupe[[#This Row],[Dopage (+Testostérone / + EE2, ….)]])))
A23: =IF(ISBLANK(liste_groupe[[#This Row],[Code WF]])," ",IF(ISBLANK(liste_groupe[[#This Row],[Unité]]),CONCATENATE(liste_groupe[[#This Row],[Nom de l''échantillon donné par le client]],liste_groupe[[#This Row],[Dopage (+Testostérone / + EE2, ….)]]),CONCATENATE(liste_groupe[[#This Row],[Nom de l''échantillon donné par le client]],"-",liste_groupe[[#This Row],[Concentration]],liste_groupe[[#This Row],[Unité]],liste_groupe[[#This Row],[Dopage (+Testostérone / + EE2, ….)]])))
A24: =IF(ISBLANK(liste_groupe[[#This Row],[Code WF]])," ",IF(ISBLANK(liste_groupe[[#This Row],[Unité]]),CONCATENATE(liste_groupe[[#This Row],[Nom de l''échantillon donné par le client]],liste_groupe[[#This Row],[Dopage (+Testostérone / + EE2, ….)]]),CONCATENATE(liste_groupe[[#This Row],[Nom de l''échantillon donné par le client]],"-",liste_groupe[[#This Row],[Concentration]],liste_groupe[[#This Row],[Unité]],liste_groupe[[#This Row],[Dopage (+Testostérone / + EE2, ….)]])))
A25: =IF(ISBLANK(liste_groupe[[#This Row],[Code WF]])," ",IF(ISBLANK(liste_groupe[[#This Row],[Unité]]),CONCATENATE(liste_groupe[[#This Row],[Nom de l''échantillon donné par le client]],liste_groupe[[#This Row],[Dopage (+Testostérone / + EE2, ….)]]),CONCATENATE(liste_groupe[[#This Row],[Nom de l''échantillon donné par le client]],"-",liste_groupe[[#This Row],[Concentration]],liste_groupe[[#This Row],[Unité]],liste_groupe[[#This Row],[Dopage (+Testostérone / + EE2, ….)]])))
A26: =IF(ISBLANK(liste_groupe[[#This Row],[Code WF]])," ",IF(ISBLANK(liste_groupe[[#This Row],[Unité]]),CONCATENATE(liste_groupe[[#This Row],[Nom de l''échantillon donné par le client]],liste_groupe[[#This Row],[Dopage (+Testostérone / + EE2, ….)]]),CONCATENATE(liste_groupe[[#This Row],[Nom de l''échantillon donné par le client]],"-",liste_groupe[[#This Row],[Concentration]],liste_groupe[[#This Row],[Unité]],liste_groupe[[#This Row],[Dopage (+Testostérone / + EE2, ….)]])))
... A35: =IF(ISBLANK(liste_groupe[[#This Row],[Code WF]])," ",IF(ISBLANK(liste_groupe[[#This Row],[Unité]]),CONCATENATE(liste_groupe[[#This Row],[Nom de l''échantillon donné par le client]],liste_groupe[[#This Row],[Dopage (+Testostérone / + EE2, ….)]]),CONCATENATE(liste_groupe[[#This Row],[Nom de l''échantillon donné par le client]],"-",liste_groupe[[#This Row],[Concentration]],liste_groupe[[#This Row],[Unité]],liste_groupe[[#This Row],[Dopage (+Testostérone / + EE2, ….)]])))
A36: =IF(ISBLANK(liste_groupe[[#This Row],[Code WF]])," ",IF(ISBLANK(liste_groupe[[#This Row],[Unité]]),CONCATENATE(liste_groupe[[#This Row],[Nom de l''échantillon donné par le client]],liste_groupe[[#This Row],[Dopage (+Testostérone / + EE2, ….)]]),CONCATENATE(liste_groupe[[#This Row],[Nom de l''échantillon donné par le client]],"-",liste_groupe[[#This Row],[Concentration]],liste_groupe[[#This Row],[Unité]],liste_groupe[[#This Row],[Dopage (+Testostérone / + EE2, ….)]]))) -> Testo -30µg/L | B36: Témoin | C36: 30 | D36: µg/L | E36: Testo
A37: =IF(ISBLANK(liste_groupe[[#This Row],[Code WF]])," ",IF(ISBLANK(liste_groupe[[#This Row],[Unité]]),CONCATENATE(liste_groupe[[#This Row],[Nom de l''échantillon donné par le client]],liste_groupe[[#This Row],[Dopage (+Testostérone / + EE2, ….)]]),CONCATENATE(liste_groupe[[#This Row],[Nom de l''échantillon donné par le client]],"-",liste_groupe[[#This Row],[Concentration]],liste_groupe[[#This Row],[Unité]],liste_groupe[[#This Row],[Dopage (+Testostérone / + EE2, ….)]]))) -> Testo 30µg/L + EE2 -64ng/L | B37: Témoin | C37: 64 | D37: ng/L | E37: Testo 30µg/L + EE2
A38: =IF(ISBLANK(liste_groupe[[#This Row],[Code WF]])," ",IF(ISBLANK(liste_groupe[[#This Row],[Unité]]),CONCATENATE(liste_groupe[[#This Row],[Nom de l''échantillon donné par le client]],liste_groupe[[#This Row],[Dopage (+Testostérone / + EE2, ….)]]),CONCATENATE(liste_groupe[[#This Row],[Nom de l''échantillon donné par le client]],"-",liste_groupe[[#This Row],[Concentration]],liste_groupe[[#This Row],[Unité]],liste_groupe[[#This Row],[Dopage (+Testostérone / + EE2, ….)]]))) -> Testo 30µg/L + FAD-10mg/L | B38: Témoin | C38: 10 | D38: mg/L | E38: Testo 30µg/L + FAD
A39: =IF(ISBLANK(liste_groupe[[#This Row],[Code WF]])," ",IF(ISBLANK(liste_groupe[[#This Row],[Unité]]),CONCATENATE(liste_groupe[[#This Row],[Nom de l''échantillon donné par le client]],liste_groupe[[#This Row],[Dopage (+Testostérone / + EE2, ….)]]),CONCATENATE(liste_groupe[[#This Row],[Nom de l''échantillon donné par le client]],"-",liste_groupe[[#This Row],[Concentration]],liste_groupe[[#This Row],[Unité]],liste_groupe[[#This Row],[Dopage (+Testostérone / + EE2, ….)]]))) -> 0-00 + Testostérone | B39: =B15 -> 0 | C39: =C15 -> 0 | D39: =D15 -> 0 | E39: =E15 -> 0 | F39: + Testostérone
A40: =IF(ISBLANK(liste_groupe[[#This Row],[Code WF]])," ",IF(ISBLANK(liste_groupe[[#This Row],[Unité]]),CONCATENATE(liste_groupe[[#This Row],[Nom de l''échantillon donné par le client]],liste_groupe[[#This Row],[Dopage (+Testostérone / + EE2, ….)]]),CONCATENATE(liste_groupe[[#This Row],[Nom de l''échantillon donné par le client]],"-",liste_groupe[[#This Row],[Concentration]],liste_groupe[[#This Row],[Unité]],liste_groupe[[#This Row],[Dopage (+Testostérone / + EE2, ….)]]))) -> 0-00 + Testostérone | B40: =B16 -> 0 | C40: =C16 -> 0 | D40: =D16 -> 0 | E40: =E16 -> 0 | F40: + Testostérone
A41: =IF(ISBLANK(liste_groupe[[#This Row],[Code WF]])," ",IF(ISBLANK(liste_groupe[[#This Row],[Unité]]),CONCATENATE(liste_groupe[[#This Row],[Nom de l''échantillon donné par le client]],liste_groupe[[#This Row],[Dopage (+Testostérone / + EE2, ….)]]),CONCATENATE(liste_groupe[[#This Row],[Nom de l''échantillon donné par le client]],"-",liste_groupe[[#This Row],[Concentration]],liste_groupe[[#This Row],[Unité]],liste_groupe[[#This Row],[Dopage (+Testostérone / + EE2, ….)]]))) -> 0-00 + Testostérone | B41: =B17 -> 0 | C41: =C17 -> 0 | D41: =D17 -> 0 | E41: =E17 -> 0 | F41: + Testostérone
A42: =IF(ISBLANK(liste_groupe[[#This Row],[Code WF]])," ",IF(ISBLANK(liste_groupe[[#This Row],[Unité]]),CONCATENATE(liste_groupe[[#This Row],[Nom de l''échantillon donné par le client]],liste_groupe[[#This Row],[Dopage (+Testostérone / + EE2, ….)]]),CONCATENATE(liste_groupe[[#This Row],[Nom de l''échantillon donné par le client]],"-",liste_groupe[[#This Row],[Concentration]],liste_groupe[[#This Row],[Unité]],liste_groupe[[#This Row],[Dopage (+Testostérone / + EE2, ….)]]))) -> 0-00 + Testostérone | B42: =B18 -> 0 | C42: =C18 -> 0 | D42: =D18 -> 0 | E42: =E18 -> 0 | F42: + Testostérone
A43: =IF(ISBLANK(liste_groupe[[#This Row],[Code WF]])," ",IF(ISBLANK(liste_groupe[[#This Row],[Unité]]),CONCATENATE(liste_groupe[[#This Row],[Nom de l''échantillon donné par le client]],liste_groupe[[#This Row],[Dopage (+Testostérone / + EE2, ….)]]),CONCATENATE(liste_groupe[[#This Row],[Nom de l''échantillon donné par le client]],"-",liste_groupe[[#This Row],[Concentration]],liste_groupe[[#This Row],[Unité]],liste_groupe[[#This Row],[Dopage (+Testostérone / + EE2, ….)]]))) -> 0-00 + Testostérone | B43: =B19 -> 0 | C43: =C19 -> 0 | D43: =D19 -> 0 | E43: =E19 -> 0 | F43: + Testostérone
A44: =IF(ISBLANK(liste_groupe[[#This Row],[Code WF]])," ",IF(ISBLANK(liste_groupe[[#This Row],[Unité]]),CONCATENATE(liste_groupe[[#This Row],[Nom de l''échantillon donné par le client]],liste_groupe[[#This Row],[Dopage (+Testostérone / + EE2, ….)]]),CONCATENATE(liste_groupe[[#This Row],[Nom de l''échantillon donné par le client]],"-",liste_groupe[[#This Row],[Concentration]],liste_groupe[[#This Row],[Unité]],liste_groupe[[#This Row],[Dopage (+Testostérone / + EE2, ….)]]))) -> 0-00 + Testostérone | B44: =B20 -> 0 | C44: =C20 -> 0 | D44: =D20 -> 0 | E44: =E20 -> 0 | F44: + Testostérone
A45: =IF(ISBLANK(liste_groupe[[#This Row],[Code WF]])," ",IF(ISBLANK(liste_groupe[[#This Row],[Unité]]),CONCATENATE(liste_groupe[[#This Row],[Nom de l''échantillon donné par le client]],liste_groupe[[#This Row],[Dopage (+Testostérone / + EE2, ….)]]),CONCATENATE(liste_groupe[[#This Row],[Nom de l''échantillon donné par le client]],"-",liste_groupe[[#This Row],[Concentration]],liste_groupe[[#This Row],[Unité]],liste_groupe[[#This Row],[Dopage (+Testostérone / + EE2, ….)]]))) -> 0-00 + Testostérone | B45: =B21 -> 0 | C45: =C21 -> 0 | D45: =D21 -> 0 | E45: =E21 -> 0 | F45: + Testostérone
A46: =IF(ISBLANK(liste_groupe[[#This Row],[Code WF]])," ",IF(ISBLANK(liste_groupe[[#This Row],[Unité]]),CONCATENATE(liste_groupe[[#This Row],[Nom de l''échantillon donné par le client]],liste_groupe[[#This Row],[Dopage (+Testostérone / + EE2, ….)]]),CONCATENATE(liste_groupe[[#This Row],[Nom de l''échantillon donné par le client]],"-",liste_groupe[[#This Row],[Concentration]],liste_groupe[[#This Row],[Unité]],liste_groupe[[#This Row],[Dopage (+Testostérone / + EE2, ….)]]))) -> 0-00 + Testostérone | B46: =B22 -> 0 | C46: =C22 -> 0 | D46: =D22 -> 0 | E46: =E22 -> 0 | F46: + Testostérone
A47: =IF(ISBLANK(liste_groupe[[#This Row],[Code WF]])," ",IF(ISBLANK(liste_groupe[[#This Row],[Unité]]),CONCATENATE(liste_groupe[[#This Row],[Nom de l''échantillon donné par le client]],liste_groupe[[#This Row],[Dopage (+Testostérone / + EE2, ….)]]),CONCATENATE(liste_groupe[[#This Row],[Nom de l''échantillon donné par le client]],"-",liste_groupe[[#This Row],[Concentration]],liste_groupe[[#This Row],[Unité]],liste_groupe[[#This Row],[Dopage (+Testostérone / + EE2, ….)]]))) -> 0-00 + Testostérone | B47: =B23 -> 0 | C47: =C23 -> 0 | D47: =D23 -> 0 | E47: =E23 -> 0 | F47: + Testostérone
A48: =IF(ISBLANK(liste_groupe[[#This Row],[Code WF]])," ",IF(ISBLANK(liste_groupe[[#This Row],[Unité]]),CONCATENATE(liste_groupe[[#This Row],[Nom de l''échantillon donné par le client]],liste_groupe[[#This Row],[Dopage (+Testostérone / + EE2, ….)]]),CONCATENATE(liste_groupe[[#This Row],[Nom de l''échantillon donné par le client]],"-",liste_groupe[[#This Row],[Concentration]],liste_groupe[[#This Row],[Unité]],liste_groupe[[#This Row],[Dopage (+Testostérone / + EE2, ….)]]))) -> 0-00 + Testostérone | B48: =B24 -> 0 | C48: =C24 -> 0 | D48: =D24 -> 0 | E48: =E24 -> 0 | F48: + Testostérone
...

Sheet Feuil1
A1: Nom groupe | B1: N° de valeur | C1: file name | D1: total area | E1: mean intensity | G1: total fluorescence | I1: nbre de larves
A2: 01 EE2 0 | B2: A | C2: C:\Users\Olympus\Desktop\20190122\plaque1/@01 EE2 0/A1_1.tif | D2: 4931.616 | E2: 73.0526 | G2: 360268
A3: 01 EE2 0 | B3: A | C3: C:\Users\Olympus\Desktop\20190122\plaque1/@01 EE2 0/A1_2.tif | D3: 5234.4345 | E3: 71.1281 | G3: 372315
A4: 01 EE2 0 | B4: A | C4: C:\Users\Olympus\Desktop\20190122\plaque1/@01 EE2 0/A1_3.tif | D4: 3547.3027 | E4: 66.9878 | G4: 237626
A5: 01 EE2 0 | B5: A | C5: C:\Users\Olympus\Desktop\20190122\plaque3/@01 EE2 0/A1_3.tif | D5: 21456.8555 | E5: 67.0655 | G5: 1439015
A6: 01 EE2 0 | B6: A | C6: C:\Users\Olympus\Desktop\20190122\plaque3/@01 EE2 0/A1_2.tif | D6: 21586.6348 | E6: 66.4108 | G6: 1433586
A7: 01 EE2 0 | B7: A | C7: C:\Users\Olympus\Desktop\20190122\plaque3/@01 EE2 0/A1_1.tif | D7: 15984.4921 | E7: 69.7767 | G7: 1115346

Sheet Raw data R1
A1: Nom groupe | B1: N° de valeur | C1: file name | D1: total area | E1: mean intensity | G1: total fluorescence | I1: nbre de larves | L1: (Tous)
A2: =IFERROR(LEFT(RIGHT(C2,LEN(C2)-SEARCH("@",C2)),SEARCH("/",RIGHT(C2,LEN(C2)-SEARCH("@",C2)-1))),"") | B2: =LEFT(RIGHT(RIGHT(Tableau4[[#This Row],[file name]],LEN(Tableau4[[#This Row],[file name]])-SEARCH("@",Tableau4[[#This Row],[file name]])),LEN(RIGHT(Tableau4[[#This Row],[file name]],LEN(Tableau4[[#This Row],[file name]])-SEARCH("@",Tableau4[[#This Row],[file name]])))-SEARCH("/",RIGHT(Tableau4[[#This Row],[file name]],LEN(Tableau4[[#This Row],[file name]])-SEARCH("@",Tableau4[[#This Row],[file name]])))),1) -> #VALUE! | K2: Filtre lignes : Enlever (vide) et Néant | L2: Filtre colonnes : Enlever (vide) et " "
A3: =IFERROR(LEFT(RIGHT(C3,LEN(C3)-SEARCH("@",C3)),SEARCH("/",RIGHT(C3,LEN(C3)-SEARCH("@",C3)-1))),"") | B3: =LEFT(RIGHT(RIGHT(Tableau4[[#This Row],[file name]],LEN(Tableau4[[#This Row],[file name]])-SEARCH("@",Tableau4[[#This Row],[file name]])),LEN(RIGHT(Tableau4[[#This Row],[file name]],LEN(Tableau4[[#This Row],[file name]])-SEARCH("@",Tableau4[[#This Row],[file name]])))-SEARCH("/",RIGHT(Tableau4[[#This Row],[file name]],LEN(Tableau4[[#This Row],[file name]])-SEARCH("@",Tableau4[[#This Row],[file name]])))),1) -> #VALUE! | K3: Moyenne de total fluorescence | L3: Étiquettes de colonnes
A4: =IFERROR(LEFT(RIGHT(C4,LEN(C4)-SEARCH("@",C4)),SEARCH("/",RIGHT(C4,LEN(C4)-SEARCH("@",C4)-1))),"") | B4: =LEFT(RIGHT(RIGHT(Tableau4[[#This Row],[file name]],LEN(Tableau4[[#This Row],[file name]])-SEARCH("@",Tableau4[[#This Row],[file name]])),LEN(RIGHT(Tableau4[[#This Row],[file name]],LEN(Tableau4[[#This Row],[file name]])-SEARCH("@",Tableau4[[#This Row],[file name]])))-SEARCH("/",RIGHT(Tableau4[[#This Row],[file name]],LEN(Tableau4[[#This Row],[file name]])-SEARCH("@",Tableau4[[#This Row],[file name]])))),1) -> #VALUE! | K4: Étiquettes de lignes
A5: =IFERROR(LEFT(RIGHT(C5,LEN(C5)-SEARCH("@",C5)),SEARCH("/",RIGHT(C5,LEN(C5)-SEARCH("@",C5)-1))),"") | B5: =LEFT(RIGHT(RIGHT(Tableau4[[#This Row],[file name]],LEN(Tableau4[[#This Row],[file name]])-SEARCH("@",Tableau4[[#This Row],[file name]])),LEN(RIGHT(Tableau4[[#This Row],[file name]],LEN(Tableau4[[#This Row],[file name]])-SEARCH("@",Tableau4[[#This Row],[file name]])))-SEARCH("/",RIGHT(Tableau4[[#This Row],[file name]],LEN(Tableau4[[#This Row],[file name]])-SEARCH("@",Tableau4[[#This Row],[file name]])))),1) -> #VALUE! | K5: #VALEUR!
A6: =IFERROR(LEFT(RIGHT(C6,LEN(C6)-SEARCH("@",C6)),SEARCH("/",RIGHT(C6,LEN(C6)-SEARCH("@",C6)-1))),"") | B6: =LEFT(RIGHT(RIGHT(Tableau4[[#This Row],[file name]],LEN(Tableau4[[#This Row],[file name]])-SEARCH("@",Tableau4[[#This Row],[file name]])),LEN(RIGHT(Tableau4[[#This Row],[file name]],LEN(Tableau4[[#This Row],[file name]])-SEARCH("@",Tableau4[[#This Row],[file name]])))-SEARCH("/",RIGHT(Tableau4[[#This Row],[file name]],LEN(Tableau4[[#This Row],[file name]])-SEARCH("@",Tableau4[[#This Row],[file name]])))),1) -> #VALUE!
A7: =IFERROR(LEFT(RIGHT(C7,LEN(C7)-SEARCH("@",C7)),SEARCH("/",RIGHT(C7,LEN(C7)-SEARCH("@",C7)-1))),"") | B7: =LEFT(RIGHT(RIGHT(Tableau4[[#This Row],[file name]],LEN(Tableau4[[#This Row],[file name]])-SEARCH("@",Tableau4[[#This Row],[file name]])),LEN(RIGHT(Tableau4[[#This Row],[file name]],LEN(Tableau4[[#This Row],[file name]])-SEARCH("@",Tableau4[[#This Row],[file name]])))-SEARCH("/",RIGHT(Tableau4[[#This Row],[file name]],LEN(Tableau4[[#This Row],[file name]])-SEARCH("@",Tableau4[[#This Row],[file name]])))),1) -> #VALUE!
A8: =IFERROR(LEFT(RIGHT(C8,LEN(C8)-SEARCH("@",C8)),SEARCH("/",RIGHT(C8,LEN(C8)-SEARCH("@",C8)-1))),"") | B8: =LEFT(RIGHT(RIGHT(Tableau4[[#This Row],[file name]],LEN(Tableau4[[#This Row],[file name]])-SEARCH("@",Tableau4[[#This Row],[file name]])),LEN(RIGHT(Tableau4[[#This Row],[file name]],LEN(Tableau4[[#This Row],[file name]])-SEARCH("@",Tableau4[[#This Row],[file name]])))-SEARCH("/",RIGHT(Tableau4[[#This Row],[file name]],LEN(Tableau4[[#This Row],[file name]])-SEARCH("@",Tableau4[[#This Row],[file name]])))),1) -> #VALUE!
A9: =IFERROR(LEFT(RIGHT(C9,LEN(C9)-SEARCH("@",C9)),SEARCH("/",RIGHT(C9,LEN(C9)-SEARCH("@",C9)-1))),"") | B9: =LEFT(RIGHT(RIGHT(Tableau4[[#This Row],[file name]],LEN(Tableau4[[#This Row],[file name]])-SEARCH("@",Tableau4[[#This Row],[file name]])),LEN(RIGHT(Tableau4[[#This Row],[file name]],LEN(Tableau4[[#This Row],[file name]])-SEARCH("@",Tableau4[[#This Row],[file name]])))-SEARCH("/",RIGHT(Tableau4[[#This Row],[file name]],LEN(Tableau4[[#This Row],[file name]])-SEARCH("@",Tableau4[[#This Row],[file name]])))),1) -> #VALUE!
A10: =IFERROR(LEFT(RIGHT(C10,LEN(C10)-SEARCH("@",C10)),SEARCH("/",RIGHT(C10,LEN(C10)-SEARCH("@",C10)-1))),"") | B10: =LEFT(RIGHT(RIGHT(Tableau4[[#This Row],[file name]],LEN(Tableau4[[#This Row],[file name]])-SEARCH("@",Tableau4[[#This Row],[file name]])),LEN(RIGHT(Tableau4[[#This Row],[file name]],LEN(Tableau4[[#This Row],[file name]])-SEARCH("@",Tableau4[[#This Row],[file name]])))-SEARCH("/",RIGHT(Tableau4[[#This Row],[file name]],LEN(Tableau4[[#This Row],[file name]])-SEARCH("@",Tableau4[[#This Row],[file name]])))),1) -> #VALUE!
A11: =IFERROR(LEFT(RIGHT(C11,LEN(C11)-SEARCH("@",C11)),SEARCH("/",RIGHT(C11,LEN(C11)-SEARCH("@",C11)-1))),"") | B11: =LEFT(RIGHT(RIGHT(Tableau4[[#This Row],[file name]],LEN(Tableau4[[#This Row],[file name]])-SEARCH("@",Tableau4[[#This Row],[file name]])),LEN(RIGHT(Tableau4[[#This Row],[file name]],LEN(Tableau4[[#This Row],[file name]])-SEARCH("@",Tableau4[[#This Row],[file name]])))-SEARCH("/",RIGHT(Tableau4[[#This Row],[file name]],LEN(Tableau4[[#This Row],[file name]])-SEARCH("@",Tableau4[[#This Row],[file name]])))),1) -> #VALUE!
A12: =IFERROR(LEFT(RIGHT(C12,LEN(C12)-SEARCH("@",C12)),SEARCH("/",RIGHT(C12,LEN(C12)-SEARCH("@",C12)-1))),"") | B12: =LEFT(RIGHT(RIGHT(Tableau4[[#This Row],[file name]],LEN(Tableau4[[#This Row],[file name]])-SEARCH("@",Tableau4[[#This Row],[file name]])),LEN(RIGHT(Tableau4[[#This Row],[file name]],LEN(Tableau4[[#This Row],[file name]])-SEARCH("@",Tableau4[[#This Row],[file name]])))-SEARCH("/",RIGHT(Tableau4[[#This Row],[file name]],LEN(Tableau4[[#This Row],[file name]])-SEARCH("@",Tableau4[[#This Row],[file name]])))),1) -> #VALUE!
A13: =IFERROR(LEFT(RIGHT(C13,LEN(C13)-SEARCH("@",C13)),SEARCH("/",RIGHT(C13,LEN(C13)-SEARCH("@",C13)-1))),"") | B13: =LEFT(RIGHT(RIGHT(Tableau4[[#This Row],[file name]],LEN(Tableau4[[#This Row],[file name]])-SEARCH("@",Tableau4[[#This Row],[file name]])),LEN(RIGHT(Tableau4[[#This Row],[file name]],LEN(Tableau4[[#This Row],[file name]])-SEARCH("@",Tableau4[[#This Row],[file name]])))-SEARCH("/",RIGHT(Tableau4[[#This Row],[file name]],LEN(Tableau4[[#This Row],[file name]])-SEARCH("@",Tableau4[[#This Row],[file name]])))),1) -> #VALUE!
A14: =IFERROR(LEFT(RIGHT(C14,LEN(C14)-SEARCH("@",C14)),SEARCH("/",RIGHT(C14,LEN(C14)-SEARCH("@",C14)-1))),"") | B14: =LEFT(RIGHT(RIGHT(Tableau4[[#This Row],[file name]],LEN(Tableau4[[#This Row],[file name]])-SEARCH("@",Tableau4[[#This Row],[file name]])),LEN(RIGHT(Tableau4[[#This Row],[file name]],LEN(Tableau4[[#This Row],[file name]])-SEARCH("@",Tableau4[[#This Row],[file name]])))-SEARCH("/",RIGHT(Tableau4[[#This Row],[file name]],LEN(Tableau4[[#This Row],[file name]])-SEARCH("@",Tableau4[[#This Row],[file name]])))),1) -> #VALUE!
A15: =IFERROR(LEFT(RIGHT(C15,LEN(C15)-SEARCH("@",C15)),SEARCH("/",RIGHT(C15,LEN(C15)-SEARCH("@",C15)-1))),"") | B15: =LEFT(RIGHT(RIGHT(Tableau4[[#This Row],[file name]],LEN(Tableau4[[#This Row],[file name]])-SEARCH("@",Tableau4[[#This Row],[file name]])),LEN(RIGHT(Tableau4[[#This Row],[file name]],LEN(Tableau4[[#This Row],[file name]])-SEARCH("@",Tableau4[[#This Row],[file name]])))-SEARCH("/",RIGHT(Tableau4[[#This Row],[file name]],LEN(Tableau4[[#This Row],[file name]])-SEARCH("@",Tableau4[[#This Row],[file name]])))),1) -> #VALUE!
A16: =IFERROR(LEFT(RIGHT(C16,LEN(C16)-SEARCH("@",C16)),SEARCH("/",RIGHT(C16,LEN(C16)-SEARCH("@",C16)-1))),"") | B16: =LEFT(RIGHT(RIGHT(Tableau4[[#This Row],[file name]],LEN(Tableau4[[#This Row],[file name]])-SEARCH("@",Tableau4[[#This Row],[file name]])),LEN(RIGHT(Tableau4[[#This Row],[file name]],LEN(Tableau4[[#This Row],[file name]])-SEARCH("@",Tableau4[[#This Row],[file name]])))-SEARCH("/",RIGHT(Tableau4[[#This Row],[file name]],LEN(Tableau4[[#This Row],[file name]])-SEARCH("@",Tableau4[[#This Row],[file name]])))),1) -> #VALUE!
A17: =IFERROR(LEFT(RIGHT(C17,LEN(C17)-SEARCH("@",C17)),SEARCH("/",RIGHT(C17,LEN(C17)-SEARCH("@",C17)-1))),"") | B17: =LEFT(RIGHT(RIGHT(Tableau4[[#This Row],[file name]],LEN(Tableau4[[#This Row],[file name]])-SEARCH("@",Tableau4[[#This Row],[file name]])),LEN(RIGHT(Tableau4[[#This Row],[file name]],LEN(Tableau4[[#This Row],[file name]])-SEARCH("@",Tableau4[[#This Row],[file name]])))-SEARCH("/",RIGHT(Tableau4[[#This Row],[file name]],LEN(Tableau4[[#This Row],[file name]])-SEARCH("@",Tableau4[[#This Row],[file name]])))),1) -> #VALUE!
... A1557: =IFERROR(LEFT(RIGHT(C1557,LEN(C1557)-SEARCH("@",C1557)),SEARCH("/",RIGHT(C1557,LEN(C1557)-SEARCH("@",C1557)-1))),"") | B1557: =LEFT(RIGHT(RIGHT(Tableau4[[#This Row],[file name]],LEN(Tableau4[[#This Row],[file name]])-SEARCH("@",Tableau4[[#This Row],[file name]])),LEN(RIGHT(Tableau4[[#This Row],[file name]],LEN(Tableau4[[#This Row],[file name]])-SEARCH("@",Tableau4[[#This Row],[file name]])))-SEARCH("/",RIGHT(Tableau4[[#This Row],[file name]],LEN(Tableau4[[#This Row],[file name]])-SEARCH("@",Tableau4[[#This Row],[file name]])))),1) -> #VALUE!

Sheet Feuil2
A1: raw data
A3: Version 4.0, Macro for Choriogenin Analysis. 80-255, green - red jpg
A6: analysed:
A7: Date: Wed 30-Jun-2021
A8: Time: 09:38:00
A10: start date of exposure:
A11: date of read:
A12: line: | B12: ChgH homozygous
A13: crossed with: | B13: ChgH homozygous
A14: generation of embryos:
A15: exposure length in hours: | B15: 24
A18: file name | B18: total area | C18: mean intensity | E18: total fluorescence
A19: C:\Users\achikhaoui\Desktop\Calibration exp danemark\80-255\R1 Danemark/@01 Solvent control/Solvent_control__20210617_001- exclu.jpg
A20: C:\Users\achikhaoui\Desktop\Calibration exp danemark\80-255\R1 Danemark/@01 Solvent control/Solvent_control__20210617_003- exclu.jpg
A21: C:\Users\achikhaoui\Desktop\Calibration exp danemark\80-255\R1 Danemark/@01 Solvent control/Solvent_control__20210617_004- exclu.jpg
A22: C:\Users\achikhaoui\Desktop\Calibration exp danemark\80-255\R1 Danemark/@01 Solvent control/Solvent_control__20210617_005- exclu.jpg
A23: C:\Users\achikhaoui\Desktop\Calibration exp danemark\80-255\R1 Danemark/@01 Solvent control/Solvent_control__20210617_007.jpg | B23: 97 | C23: 85.6082 | E23: 8304
A24: C:\Users\achikhaoui\Desktop\Calibration exp danemark\80-255\R1 Danemark/@01 Solvent control/Solvent_control__20210617_008- exclu.jpg
A25: C:\Users\achikhaoui\Desktop\Calibration exp danemark\80-255\R1 Danemark/@01 Solvent control/Solvent_control__20210617_011.jpg | B25: 1 | C25: 81 | E25: 81
A26: C:\Users\achikhaoui\Desktop\Calibration exp danemark\80-255\R1 Danemark/@01 Solvent control/Solvent_control__20210617_012.jpg | B26: 0 | C26: 0 | E26: 0
A28: group | C28: mean of mean fluo | D28: SD mean fluo | E28: mean of total fluo | F28: SD total fluo | G28: n fluorescent | H28: n total
A29: C:\Users\achikhaoui\Desktop\Calibration exp danemark\80-255\R1 Danemark/@01 Solvent control/ | C29: 41.1698 | D29: 44.0381 | E29: 1109.375 | F29: 2909.3798 | G29: 4 | H29: 8
A35: file name | B35: total area | C35: mean intensity | E35: total fluorescence
A36: C:\Users\achikhaoui\Desktop\Calibration exp danemark\80-255\R1 Danemark/@02 EE2 34ngL/EE2_34ngL__20210617_002.jpg | B36: 0 | C36: 0 | E36: 0
A37: C:\Users\achikhaoui\Desktop\Calibration exp danemark\80-255\R1 Danemark/@02 EE2 34ngL/EE2_34ngL__20210617_003.jpg | B37: 31 | C37: 84.4194 | E37: 2617
A38: C:\Users\achikhaoui\Desktop\Calibration exp danemark\80-255\R1 Danemark/@02 EE2 34ngL/EE2_34ngL__20210617_005.jpg | B38: 18 | C38: 83.3333 | E38: 1500
A39: C:\Users\achikhaoui\Desktop\Calibration exp danemark\80-255\R1 Danemark/@02 EE2 34ngL/EE2_34ngL__20210617_006- exclu.jpg
A40: C:\Users\achikhaoui\Desktop\Calibration exp danemark\80-255\R1 Danemark/@02 EE2 34ngL/EE2_34ngL__20210617_007- exclu.jpg
A41: C:\Users\achikhaoui\Desktop\Calibration exp danemark\80-255\R1 Danemark/@02 EE2 34ngL/EE2_34ngL__20210617_008.jpg | B41: 132 | C41: 90.6212 | E41: 11962
A42: C:\Users\achikhaoui\Desktop\Calibration exp danemark\80-255\R1 Danemark/@02 EE2 34ngL/EE2_34ngL__20210617_009.jpg | B42: 0 | C42: 0 | E42: 0
A43: C:\Users\achikhaoui\Desktop\Calibration exp danemark\80-255\R1 Danemark/@02 EE2 34ngL/EE2_34ngL__20210617_013.jpg | B43: 29 | C43: 89.1379 | E43: 2585
A45: group | C45: mean of mean fluo | D45: SD mean fluo | E45: mean of total fluo | F45: SD total fluo | G45: n fluorescent | H45: n total
A46: C:\Users\achikhaoui\Desktop\Calibration exp danemark\80-255\R1 Danemark/@02 EE2 34ngL/ | C46: 64.2723 | D46: 39.7681 | E46: 2458 | F46: 3982.7531 | G46: 6 | H46: 8
A52: file name | B52: total area | C52: mean intensity | E52: total fluorescence
A53: C:\Users\achikhaoui\Desktop\Calibration exp danemark\80-255\R1 Danemark/@03 EE2 51ngL/EE2_51ngL__20210617_001.jpg | B53: 28 | C53: 82.4643 | E53: 2309
A54: C:\Users\achikhaoui\Desktop\Calibration exp danemark\80-255\R1 Danemark/@03 EE2 51ngL/EE2_51ngL__20210617_004.jpg | B54: 0 | C54: 0 | E54: 0
A55: C:\Users\achikhaoui\Desktop\Calibration exp danemark\80-255\R1 Danemark/@03 EE2 51ngL/EE2_51ngL__20210617_010.jpg | B55: 166 | C55: 84.7651 | E55: 14071
A56: C:\Users\achikhaoui\Desktop\Calibration exp danemark\80-255\R1 Danemark/@03 EE2 51ngL/EE2_51ngL__20210617_011.jpg | B56: 207 | C56: 94.6763 | E56: 19598
A57: C:\Users\achikhaoui\Desktop\Calibration exp danemark\80-255\R1 Danemark/@03 EE2 51ngL/EE2_51ngL__20210617_012.jpg | B57: 1593 | C57: 93.2825 | E57: 148599
A58: C:\Users\achikhaoui\Desktop\Calibration exp danemark\80-255\R1 Danemark/@03 EE2 51ngL/EE2_51ngL__20210617_013.jpg | B58: 82 | C58: 83.7927 | E58: 6871
...

Sheet R1
A1: 3. Expérimentateur 1 : copier et coller les valeurs des intensités totales de fluorescences obtenues dans le fichier raw data lors du traitement des images.
A3: R1 | B3: Non dopé | J3: avec testo
A4: Noms des groupes | B4: ='Page de garde'!A7 -> Témoin solvant | C4: ='Page de garde'!A9 -> EE2-33,8ng/L | D4: ='Page de garde'!A10 -> EE2-50,6ng/L | E4: ='Page de garde'!A11 -> EE2-76ng/L | F4: ='Page de garde'!A12 -> EE2-114ng/L | G4: ='Page de garde'!A13 -> EE2-170,9ng/L | H4: ='Page de garde'!A14 -> EE2-488ng/L | J4: ='Page de garde'!A36 -> Testo -30µg/L | K4: ='Page de garde'!A37 -> Testo 30µg/L + EE2 -64ng/L | L4: ='Page de garde'!A38 -> Testo 30µg/L + FAD-10mg/L
A5: Données brutes | B5: =Feuil2!E23 -> 8304 | C5: =Feuil2!E36 -> 0 | D5: =Feuil2!E53 -> 2309 | E5: =Feuil2!E70 -> 0 | F5: =Feuil2!E87 -> 67935 | G5: =Feuil2!E104 -> 356147 | H5: =Feuil2!E121 -> 287243 | J5: =Feuil2!E138 -> 54082 | L5: =Feuil2!E155 -> 3263
C6: =Feuil2!E37 -> 2617 | D6: =Feuil2!E54 -> 0 | E6: =Feuil2!E71 -> 72588 | F6: =Feuil2!E88 -> 109282 | G6: =Feuil2!E105 -> 366161 | H6: =Feuil2!E122 -> 278778 | J6: =Feuil2!E139 -> 264211 | L6: =Feuil2!E156 -> 81
B7: =Feuil2!E25 -> 81 | C7: =Feuil2!E38 -> 1500 | D7: =Feuil2!E55 -> 14071 | E7: =Feuil2!E72 -> 32748 | F7: =Feuil2!E89 -> 241206 | G7: =Feuil2!E106 -> 275197 | H7: =Feuil2!E123 -> 429004 | J7: =Feuil2!E140 -> 288949 | L7: =Feuil2!E157 -> 52926
B8: =Feuil2!E26 -> 0 | D8: =Feuil2!E56 -> 19598 | E8: =Feuil2!E73 -> 2988 | F8: =Feuil2!E90 -> 259441 | G8: =Feuil2!E107 -> 331176 | H8: =Feuil2!E124 -> 537583 | J8: =Feuil2!E141 -> 205637 | L8: =Feuil2!E158 -> 2557
D9: =Feuil2!E57 -> 148599 | E9: =Feuil2!E74 -> 14001 | F9: =Feuil2!E91 -> 158732 | H9: =Feuil2!E125 -> 337731 | J9: =Feuil2!E142 -> 341545 | L9: =Feuil2!E159 -> 17861
C10: =Feuil2!E41 -> 11962 | D10: =Feuil2!E58 -> 6871 | E10: =Feuil2!E75 -> 302504 | F10: =Feuil2!E92 -> 92333 | G10: =Feuil2!E109 -> 244067 | H10: =Feuil2!E126 -> 379425 | J10: =Feuil2!E143 -> 76649 | L10: =Feuil2!E160 -> 32128
C11: =Feuil2!E42 -> 0 | D11: =Feuil2!E59 -> 23082 | E11: =Feuil2!E76 -> 38182 | F11: =Feuil2!E93 -> 229497 | G11: =Feuil2!E110 -> 306562 | H11: =Feuil2!E127 -> 364890 | J11: =Feuil2!E144 -> 358372 | L11: =Feuil2!E161 -> 14960
C12: =Feuil2!E43 -> 2585 | D12: =Feuil2!E60 -> 0 | E12: =Feuil2!E77 -> 252629 | F12: =Feuil2!E94 -> 33990 | G12: =Feuil2!E111 -> 215357 | H12: =Feuil2!E128 -> 347858 | J12: =Feuil2!E145 -> 294098 | L12: =Feuil2!E162 -> 580
A22: =A4 -> Noms des groupes | B22: =B4 -> Témoin solvant | C22: =C4 -> EE2-33,8ng/L | D22: =D4 -> EE2-50,6ng/L | E22: =E4 -> EE2-76ng/L | F22: =F4 -> EE2-114ng/L | G22: =G4 -> EE2-170,9ng/L | H22: =H4 -> EE2-488ng/L | I22: Nom des groupes | J22: =J4 -> Testo -30µg/L | K22: =K4 -> Testo 30µg/L + EE2 -64ng/L | L22: =L4 -> Testo 30µg/L + FAD-10mg/L
A23: mean | B23: =AVERAGE(B5:B20) -> 2795 | C23: =AVERAGE(C5:C20) -> 3110.6667 | D23: =AVERAGE(D5:D20) -> 26816.25 | E23: =AVERAGE(E5:E20) -> 89455 | F23: =AVERAGE(F5:F20) -> 149052 | G23: =AVERAGE(G5:G20) -> 299238.14 | H23: =AVERAGE(H5:H20) -> 370314 | I23: mean | J23: =AVERAGE(J5:J20) -> 235442.88 | K23: =AVERAGE(K5:K20) -> #DIV/0! | L23: =AVERAGE(L5:L20) -> 15544.5
A24: SD | B24: =STDEV(B5:B20) -> 4771.1058 | C24: =STDEV(C5:C20) -> 4490.2756 | D24: =STDEV(D5:D20) -> 49994.526 | E24: =STDEV(E5:E20) -> 119113.86 | F24: =STDEV(F5:F20) -> 86073.989 | G24: =STDEV(G5:G20) -> 56933.924 | H24: =STDEV(H5:H20) -> 83136.221 | I24: SD | J24: =STDEV(J5:J20) -> 114950.81 | K24: =STDEV(K5:K20) -> #DIV/0! | L24: =STDEV(L5:L20) -> 18748.955
B26: Non dopé | J26: avec testo
A27: Noms des groupes | B27: =B4 -> Témoin solvant | C27: =C4 -> EE2-33,8ng/L | D27: =D4 -> EE2-50,6ng/L | E27: =E4 -> EE2-76ng/L | F27: =F4 -> EE2-114ng/L | G27: =G4 -> EE2-170,9ng/L | H27: =H4 -> EE2-488ng/L | J27: =J4 -> Testo -30µg/L | K27: =K4 -> Testo 30µg/L + EE2 -64ng/L | L27: =L4 -> Testo 30µg/L + FAD-10mg/L
A28: Données normalisées sur la moyenne du groupe "Testo" | B28: =IF(B5="","",(B5/$J$23)) -> 0.035269702 | C28: =IF(C5="","",(C5/$J$23)) -> 0 | D28: =IF(D5="","",(D5/$J$23)) -> 0.0098070498 | E28: =IF(E5="","",(E5/$J$23)) -> 0 | F28: =IF(F5="","",(F5/$J$23)) -> 0.28854133 | G28: =IF(G5="","",(G5/$J$23)) -> 1.5126684 | H28: =IF(H5="","",(H5/$J$23)) -> 1.2200114 | J28: =IF(J5="","",(J5/$J$23)) -> 0.22970328 | K28: =IF(K5="","",(K5/$J$23)) | L28: =IF(L5="","",(L5/$J$23)) -> 0.013858988
C29: =IF(C6="","",(C6/$J$23)) -> 0.011115223 | D29: =IF(D6="","",(D6/$J$23)) -> 0 | E29: =IF(E6="","",(E6/$J$23)) -> 0.30830408 | F29: =IF(F6="","",(F6/$J$23)) -> 0.46415505 | G29: =IF(G6="","",(G6/$J$23)) -> 1.555201 | H29: =IF(H6="","",(H6/$J$23)) -> 1.1840579 | J29: =IF(J6="","",(J6/$J$23)) -> 1.1221873 | K29: =IF(K6="","",(K6/$J$23)) | L29: =IF(L6="","",(L6/$J$23)) -> 0.0003440325
B30: =IF(B7="","",(B7/$J$23)) -> 0.0003440325 | C30: =IF(C7="","",(C7/$J$23)) -> 0.0063709722 | D30: =IF(D7="","",(D7/$J$23)) -> 0.059763966 | E30: =IF(E7="","",(E7/$J$23)) -> 0.13909106 | F30: =IF(F7="","",(F7/$J$23)) -> 1.0244778 | G30: =IF(G7="","",(G7/$J$23)) -> 1.1688483 | H30: =IF(H7="","",(H7/$J$23)) -> 1.822115 | J30: =IF(J7="","",(J7/$J$23)) -> 1.2272574 | K30: =IF(K7="","",(K7/$J$23)) | L30: =IF(L7="","",(L7/$J$23)) -> 0.22479338
B31: =IF(B8="","",(B8/$J$23)) -> 0 | D31: =IF(D8="","",(D8/$J$23)) -> 0.083238875 | E31: =IF(E8="","",(E8/$J$23)) -> 0.012690977 | F31: =IF(F8="","",(F8/$J$23)) -> 1.1019276 | G31: =IF(G8="","",(G8/$J$23)) -> 1.4066087 | H31: =IF(H8="","",(H8/$J$23)) -> 2.2832842 | J31: =IF(J8="","",(J8/$J$23)) -> 0.87340507 | K31: =IF(K8="","",(K8/$J$23)) | L31: =IF(L8="","",(L8/$J$23)) -> 0.010860384
D32: =IF(D9="","",(D9/$J$23)) -> 0.63114673 | E32: =IF(E9="","",(E9/$J$23)) -> 0.059466654 | F32: =IF(F9="","",(F9/$J$23)) -> 0.67418477 | H32: =IF(H9="","",(H9/$J$23)) -> 1.4344499 | J32: =IF(J9="","",(J9/$J$23)) -> 1.4506491 | K32: =IF(K9="","",(K9/$J$23)) | L32: =IF(L9="","",(L9/$J$23)) -> 0.075861289
C33: =IF(C10="","",(C10/$J$23)) -> 0.050806379 | D33: =IF(D10="","",(D10/$J$23)) -> 0.0291833 | E33: =IF(E10="","",(E10/$J$23)) -> 1.2848297 | F33: =IF(F10="","",(F10/$J$23)) -> 0.39216731 | G33: =IF(G10="","",(G10/$J$23)) -> 1.0366294 | H33: =IF(H10="","",(H10/$J$23)) -> 1.6115374 | J33: =IF(J10="","",(J10/$J$23)) -> 0.32555243 | K33: =IF(K10="","",(K10/$J$23)) | L33: =IF(L10="","",(L10/$J$23)) -> 0.13645773
C34: =IF(C11="","",(C11/$J$23)) -> 0 | D34: =IF(D11="","",(D11/$J$23)) -> 0.098036519 | E34: =IF(E11="","",(E11/$J$23)) -> 0.16217097 | F34: =IF(F11="","",(F11/$J$23)) -> 0.974746 | G34: =IF(G11="","",(G11/$J$23)) -> 1.3020653 | H34: =IF(H11="","",(H11/$J$23)) -> 1.5498027 | J34: =IF(J11="","",(J11/$J$23)) -> 1.5221187 | K34: =IF(K11="","",(K11/$J$23)) | L34: =IF(L11="","",(L11/$J$23)) -> 0.063539829
C35: =IF(C12="","",(C12/$J$23)) -> 0.010979309 | D35: =IF(D12="","",(D12/$J$23)) -> 0 | E35: =IF(E12="","",(E12/$J$23)) -> 1.0729949 | F35: =IF(F12="","",(F12/$J$23)) -> 0.14436623 | G35: =IF(G12="","",(G12/$J$23)) -> 0.91468897 | H35: =IF(H12="","",(H12/$J$23)) -> 1.4774624 | J35: =IF(J12="","",(J12/$J$23)) -> 1.2491268 | K35: =IF(K12="","",(K12/$J$23)) | L35: =IF(L12="","",(L12/$J$23)) -> 0.0024634426
G36: =IF(G13="","",(G13/$J$23)) | H36: =IF(H13="","",(H13/$J$23)) | J36: =IF(J13="","",(J13/$J$23)) | K36: =IF(K13="","",(K13/$J$23))
E37: =IF(E14="","",(E14/$J$23)) | F37: =IF(F14="","",(F14/$J$23)) | G37: =IF(G14="","",(G14/$J$23)) | H37: =IF(H14="","",(H14/$J$23)) | J37: =IF(J14="","",(J14/$J$23)) | K37: =IF(K14="","",(K14/$J$23)) | L37: =IF(L14="","",(L14/$J$23))
C38: =IF(C15="","",(C15/$J$23)) | E38: =IF(E15="","",(E15/$J$23)) | F38: =IF(F15="","",(F15/$J$23)) | G38: =IF(G15="","",(G15/$J$23)) | H38: =IF(H15="","",(H15/$J$23)) | J38: =IF(J15="","",(J15/$J$23)) | K38: =IF(K15="","",(K15/$J$23)) | L38: =IF(L15="","",(L15/$J$23))
C39: =IF(C16="","",(C16/$J$23)) | E39: =IF(E16="","",(E16/$J$23)) | F39: =IF(F16="","",(F16/$J$23)) | G39: =IF(G16="","",(G16/$J$23)) | H39: =IF(H16="","",(H16/$J$23)) | J39: =IF(J16="","",(J16/$J$23)) | K39: =IF(K16="","",(K16/$J$23)) | L39: =IF(L16="","",(L16/$J$23))
B40: =IF(B17="","",(B17/$J$23)) | C40: =IF(C17="","",(C17/$J$23)) | E40: =IF(E17="","",(E17/$J$23)) | F40: =IF(F17="","",(F17/$J$23)) | G40: =IF(G17="","",(G17/$J$23)) | H40: =IF(H17="","",(H17/$J$23)) | J40: =IF(J17="","",(J17/$J$23)) | K40: =IF(K17="","",(K17/$J$23)) | L40: =IF(L17="","",(L17/$J$23))
B41: =IF(B18="","",(B18/$J$23)) | C41: =IF(C18="","",(C18/$J$23)) | D41: =IF(D18="","",(D18/$J$23)) | E41: =IF(E18="","",(E18/$J$23)) | F41: =IF(F18="","",(F18/$J$23)) | G41: =IF(G18="","",(G18/$J$23)) | H41: =IF(H18="","",(H18/$J$23)) | J41: =IF(J18="","",(J18/$J$23)) | K41: =IF(K18="","",(K18/$J$23)) | L41: =IF(L18="","",(L18/$J$23))
B42: =IF(B19="","",(B19/$J$23)) | C42: =IF(C19="","",(C19/$J$23)) | D42: =IF(D19="","",(D19/$J$23)) | E42: =IF(E19="","",(E19/$J$23)) | F42: =IF(F19="","",(F19/$J$23)) | G42: =IF(G19="","",(G19/$J$23)) | H42: =IF(H19="","",(H19/$J$23)) | J42: =IF(J19="","",(J19/$J$23)) | K42: =IF(K19="","",(K19/$J$23)) | L42: =IF(L19="","",(L19/$J$23))
B43: =IF(B20="","",(B20/$J$23)) | C43: =IF(C20="","",(C20/$J$23)) | D43: =IF(D20="","",(D20/$J$23)) | E43: =IF(E20="","",(E20/$J$23)) | F43: =IF(F20="","",(F20/$J$23)) | G43: =IF(G20="","",(G20/$J$23)) | H43: =IF(H20="","",(H20/$J$23)) | J43: =IF(J20="","",(J20/$J$23)) | K43: =IF(K20="","",(K20/$J$23)) | L43: =IF(L20="","",(L20/$J$23))
A45: =A4 -> Noms des groupes | B45: =B4 -> Témoin solvant | C45: =C4 -> EE2-33,8ng/L | D45: =D4 -> EE2-50,6ng/L | E45: =E4 -> EE2-76ng/L | F45: =F4 -> EE2-114ng/L | G45: =G4 -> EE2-170,9ng/L | H45: =H4 -> EE2-488ng/L | I45: =I22 -> Nom des groupes | J45: =J4 -> Testo -30µg/L | K45: =K4 -> Testo 30µg/L + EE2 -64ng/L | L45: =L4 -> Testo 30µg/L + FAD-10mg/L
A46: mean | B46: =AVERAGE(B28:B43) -> 0.011871245 | C46: =AVERAGE(C28:C43) -> 0.01321198 | D46: =AVERAGE(D28:D43) -> 0.11389705 | E46: =AVERAGE(E28:E43) -> 0.37994354 | F46: =AVERAGE(F28:F43) -> 0.63307076 | G46: =AVERAGE(G28:G43) -> 1.2709586 | H46: =AVERAGE(H28:H43) -> 1.5728401 | I46: mean | J46: =AVERAGE(J28:J43) -> 1 | K46: =AVERAGE(K28:K43) -> #DIV/0! | L46: =AVERAGE(L28:L43) -> 0.066022384
A47: SD | B47: =STDEV(B28:B43) -> 0.020264388 | C47: =STDEV(C28:C43) -> 0.019071614 | D47: =STDEV(D28:D43) -> 0.21234249 | E47: =STDEV(E28:E43) -> 0.50591404 | F47: =STDEV(F28:F43) -> 0.36558332 | G47: =STDEV(G28:G43) -> 0.2418163 | H47: =STDEV(H28:H43) -> 0.3531057 | I47: SD | J47: =STDEV(J28:J43) -> 0.48823226 | K47: =STDEV(K28:K43) -> #DIV/0! | L47: =STDEV(L28:L43) -> 0.079632715
A48: SEM | B48: =B47/SQRT(COUNT(B28:B43)) -> 0.01169965 | C48: =C47/SQRT(COUNT(C28:C43)) -> 0.0077859538 | D48: =D47/SQRT(COUNT(D28:D43)) -> 0.075074406 | E48: =E47/SQRT(COUNT(E28:E43)) -> 0.17886763 | F48: =F47/SQRT(COUNT(F28:F43)) -> 0.12925322 | G48: =G47/SQRT(COUNT(G28:G43)) -> 0.091397969 | H48: =H47/SQRT(COUNT(H28:H43)) -> 0.12484172 | I48: SEM | J48: =J47/SQRT(COUNT(J28:J43)) -> 0.17261617 | K48: =K47/SQRT(COUNT(K28:K43)) -> #DIV/0! | L48: =L47/SQRT(COUNT(L28:L43)) -> 0.028154417
A50: 4. Expérimentateur 1 : réaliser les tests statistiques avec les données normalisées et renseigner les résultats ainsi que le test statistique utilisé dans le tableau violet.
A52: =A27 -> Noms des groupes | B52: =B27 -> Témoin solvant | C52: =C27 -> EE2-33,8ng/L | D52: =D27 -> EE2-50,6ng/L | E52: =E27 -> EE2-76ng/L | F52: =F27 -> EE2-114ng/L | G52: =G27 -> EE2-170,9ng/L | H52: =H27 -> EE2-488ng/L | J52: =J27 -> Testo -30µg/L | K52: =K27 -> Testo 30µg/L + EE2 -64ng/L | L52: =L27 -> Testo 30µg/L + FAD-10mg/L
A53: Mean | B53: =B46 -> 0.011871245 | C53: =C46 -> 0.01321198 | D53: =D46 -> 0.11389705 | E53: =E46 -> 0.37994354 | F53: =F46 -> 0.63307076 | G53: =G46 -> 1.2709586 | H53: =H46 -> 1.5728401 | J53: =J46 -> 1 | K53: =K46 -> #DIV/0! | L53: =L46 -> 0.066022384
A54: SEM | B54: =B48 -> 0.01169965 | C54: =C48 -> 0.0077859538 | D54: =D48 -> 0.075074406 | E54: =E48 -> 0.17886763 | F54: =F48 -> 0.12925322 | G54: =G48 -> 0.091397969 | H54: =H48 -> 0.12484172 | J54: =J48 -> 0.17261617 | K54: =K48 -> #DIV/0! | L54: =L48 -> 0.028154417
...

Sheet Raw data R2
A1: Nom groupe | B1: N° de valeur | C1: file name | D1: total area | E1: mean intensity | G1: total fluorescence | I1: nbre de larves | L1: (Tous)
A2: =IFERROR(LEFT(RIGHT(C2,LEN(C2)-SEARCH("@",C2)),SEARCH("/",RIGHT(C2,LEN(C2)-SEARCH("@",C2)-1))),"") | B2: =LEFT(RIGHT(RIGHT(Tableau46[[#This Row],[file name]],LEN(Tableau46[[#This Row],[file name]])-SEARCH("@",Tableau46[[#This Row],[file name]])),LEN(RIGHT(Tableau46[[#This Row],[file name]],LEN(Tableau46[[#This Row],[file name]])-SEARCH("@",Tableau46[[#This Row],[file name]])))-SEARCH("/",RIGHT(Tableau46[[#This Row],[file name]],LEN(Tableau46[[#This Row],[file name]])-SEARCH("@",Tableau46[[#This Row],[file name]])))),1) -> #VALUE! | K2: Filtre lignes : Enlever (vide) et Néant | L2: Filtre colonnes : Enlever (vide) et " "
A3: =IFERROR(LEFT(RIGHT(C3,LEN(C3)-SEARCH("@",C3)),SEARCH("/",RIGHT(C3,LEN(C3)-SEARCH("@",C3)-1))),"") | B3: =LEFT(RIGHT(RIGHT(Tableau46[[#This Row],[file name]],LEN(Tableau46[[#This Row],[file name]])-SEARCH("@",Tableau46[[#This Row],[file name]])),LEN(RIGHT(Tableau46[[#This Row],[file name]],LEN(Tableau46[[#This Row],[file name]])-SEARCH("@",Tableau46[[#This Row],[file name]])))-SEARCH("/",RIGHT(Tableau46[[#This Row],[file name]],LEN(Tableau46[[#This Row],[file name]])-SEARCH("@",Tableau46[[#This Row],[file name]])))),1) -> #VALUE! | K3: Moyenne de total fluorescence | L3: Étiquettes de colonnes
A4: =IFERROR(LEFT(RIGHT(C4,LEN(C4)-SEARCH("@",C4)),SEARCH("/",RIGHT(C4,LEN(C4)-SEARCH("@",C4)-1))),"") | B4: =LEFT(RIGHT(RIGHT(Tableau46[[#This Row],[file name]],LEN(Tableau46[[#This Row],[file name]])-SEARCH("@",Tableau46[[#This Row],[file name]])),LEN(RIGHT(Tableau46[[#This Row],[file name]],LEN(Tableau46[[#This Row],[file name]])-SEARCH("@",Tableau46[[#This Row],[file name]])))-SEARCH("/",RIGHT(Tableau46[[#This Row],[file name]],LEN(Tableau46[[#This Row],[file name]])-SEARCH("@",Tableau46[[#This Row],[file name]])))),1) -> #VALUE! | K4: Étiquettes de lignes
A5: =IFERROR(LEFT(RIGHT(C5,LEN(C5)-SEARCH("@",C5)),SEARCH("/",RIGHT(C5,LEN(C5)-SEARCH("@",C5)-1))),"") | B5: =LEFT(RIGHT(RIGHT(Tableau46[[#This Row],[file name]],LEN(Tableau46[[#This Row],[file name]])-SEARCH("@",Tableau46[[#This Row],[file name]])),LEN(RIGHT(Tableau46[[#This Row],[file name]],LEN(Tableau46[[#This Row],[file name]])-SEARCH("@",Tableau46[[#This Row],[file name]])))-SEARCH("/",RIGHT(Tableau46[[#This Row],[file name]],LEN(Tableau46[[#This Row],[file name]])-SEARCH("@",Tableau46[[#This Row],[file name]])))),1) -> #VALUE! | K5: #VALEUR!
A6: =IFERROR(LEFT(RIGHT(C6,LEN(C6)-SEARCH("@",C6)),SEARCH("/",RIGHT(C6,LEN(C6)-SEARCH("@",C6)-1))),"") | B6: =LEFT(RIGHT(RIGHT(Tableau46[[#This Row],[file name]],LEN(Tableau46[[#This Row],[file name]])-SEARCH("@",Tableau46[[#This Row],[file name]])),LEN(RIGHT(Tableau46[[#This Row],[file name]],LEN(Tableau46[[#This Row],[file name]])-SEARCH("@",Tableau46[[#This Row],[file name]])))-SEARCH("/",RIGHT(Tableau46[[#This Row],[file name]],LEN(Tableau46[[#This Row],[file name]])-SEARCH("@",Tableau46[[#This Row],[file name]])))),1) -> #VALUE!
A7: =IFERROR(LEFT(RIGHT(C7,LEN(C7)-SEARCH("@",C7)),SEARCH("/",RIGHT(C7,LEN(C7)-SEARCH("@",C7)-1))),"") | B7: =LEFT(RIGHT(RIGHT(Tableau46[[#This Row],[file name]],LEN(Tableau46[[#This Row],[file name]])-SEARCH("@",Tableau46[[#This Row],[file name]])),LEN(RIGHT(Tableau46[[#This Row],[file name]],LEN(Tableau46[[#This Row],[file name]])-SEARCH("@",Tableau46[[#This Row],[file name]])))-SEARCH("/",RIGHT(Tableau46[[#This Row],[file name]],LEN(Tableau46[[#This Row],[file name]])-SEARCH("@",Tableau46[[#This Row],[file name]])))),1) -> #VALUE!
A8: =IFERROR(LEFT(RIGHT(C8,LEN(C8)-SEARCH("@",C8)),SEARCH("/",RIGHT(C8,LEN(C8)-SEARCH("@",C8)-1))),"") | B8: =LEFT(RIGHT(RIGHT(Tableau46[[#This Row],[file name]],LEN(Tableau46[[#This Row],[file name]])-SEARCH("@",Tableau46[[#This Row],[file name]])),LEN(RIGHT(Tableau46[[#This Row],[file name]],LEN(Tableau46[[#This Row],[file name]])-SEARCH("@",Tableau46[[#This Row],[file name]])))-SEARCH("/",RIGHT(Tableau46[[#This Row],[file name]],LEN(Tableau46[[#This Row],[file name]])-SEARCH("@",Tableau46[[#This Row],[file name]])))),1) -> #VALUE!
A9: =IFERROR(LEFT(RIGHT(C9,LEN(C9)-SEARCH("@",C9)),SEARCH("/",RIGHT(C9,LEN(C9)-SEARCH("@",C9)-1))),"") | B9: =LEFT(RIGHT(RIGHT(Tableau46[[#This Row],[file name]],LEN(Tableau46[[#This Row],[file name]])-SEARCH("@",Tableau46[[#This Row],[file name]])),LEN(RIGHT(Tableau46[[#This Row],[file name]],LEN(Tableau46[[#This Row],[file name]])-SEARCH("@",Tableau46[[#This Row],[file name]])))-SEARCH("/",RIGHT(Tableau46[[#This Row],[file name]],LEN(Tableau46[[#This Row],[file name]])-SEARCH("@",Tableau46[[#This Row],[file name]])))),1) -> #VALUE!
A10: =IFERROR(LEFT(RIGHT(C10,LEN(C10)-SEARCH("@",C10)),SEARCH("/",RIGHT(C10,LEN(C10)-SEARCH("@",C10)-1))),"") | B10: =LEFT(RIGHT(RIGHT(Tableau46[[#This Row],[file name]],LEN(Tableau46[[#This Row],[file name]])-SEARCH("@",Tableau46[[#This Row],[file name]])),LEN(RIGHT(Tableau46[[#This Row],[file name]],LEN(Tableau46[[#This Row],[file name]])-SEARCH("@",Tableau46[[#This Row],[file name]])))-SEARCH("/",RIGHT(Tableau46[[#This Row],[file name]],LEN(Tableau46[[#This Row],[file name]])-SEARCH("@",Tableau46[[#This Row],[file name]])))),1) -> #VALUE!
A11: =IFERROR(LEFT(RIGHT(C11,LEN(C11)-SEARCH("@",C11)),SEARCH("/",RIGHT(C11,LEN(C11)-SEARCH("@",C11)-1))),"") | B11: =LEFT(RIGHT(RIGHT(Tableau46[[#This Row],[file name]],LEN(Tableau46[[#This Row],[file name]])-SEARCH("@",Tableau46[[#This Row],[file name]])),LEN(RIGHT(Tableau46[[#This Row],[file name]],LEN(Tableau46[[#This Row],[file name]])-SEARCH("@",Tableau46[[#This Row],[file name]])))-SEARCH("/",RIGHT(Tableau46[[#This Row],[file name]],LEN(Tableau46[[#This Row],[file name]])-SEARCH("@",Tableau46[[#This Row],[file name]])))),1) -> #VALUE!
A12: =IFERROR(LEFT(RIGHT(C12,LEN(C12)-SEARCH("@",C12)),SEARCH("/",RIGHT(C12,LEN(C12)-SEARCH("@",C12)-1))),"") | B12: =LEFT(RIGHT(RIGHT(Tableau46[[#This Row],[file name]],LEN(Tableau46[[#This Row],[file name]])-SEARCH("@",Tableau46[[#This Row],[file name]])),LEN(RIGHT(Tableau46[[#This Row],[file name]],LEN(Tableau46[[#This Row],[file name]])-SEARCH("@",Tableau46[[#This Row],[file name]])))-SEARCH("/",RIGHT(Tableau46[[#This Row],[file name]],LEN(Tableau46[[#This Row],[file name]])-SEARCH("@",Tableau46[[#This Row],[file name]])))),1) -> #VALUE!
A13: =IFERROR(LEFT(RIGHT(C13,LEN(C13)-SEARCH("@",C13)),SEARCH("/",RIGHT(C13,LEN(C13)-SEARCH("@",C13)-1))),"") | B13: =LEFT(RIGHT(RIGHT(Tableau46[[#This Row],[file name]],LEN(Tableau46[[#This Row],[file name]])-SEARCH("@",Tableau46[[#This Row],[file name]])),LEN(RIGHT(Tableau46[[#This Row],[file name]],LEN(Tableau46[[#This Row],[file name]])-SEARCH("@",Tableau46[[#This Row],[file name]])))-SEARCH("/",RIGHT(Tableau46[[#This Row],[file name]],LEN(Tableau46[[#This Row],[file name]])-SEARCH("@",Tableau46[[#This Row],[file name]])))),1) -> #VALUE!
A14: =IFERROR(LEFT(RIGHT(C14,LEN(C14)-SEARCH("@",C14)),SEARCH("/",RIGHT(C14,LEN(C14)-SEARCH("@",C14)-1))),"") | B14: =LEFT(RIGHT(RIGHT(Tableau46[[#This Row],[file name]],LEN(Tableau46[[#This Row],[file name]])-SEARCH("@",Tableau46[[#This Row],[file name]])),LEN(RIGHT(Tableau46[[#This Row],[file name]],LEN(Tableau46[[#This Row],[file name]])-SEARCH("@",Tableau46[[#This Row],[file name]])))-SEARCH("/",RIGHT(Tableau46[[#This Row],[file name]],LEN(Tableau46[[#This Row],[file name]])-SEARCH("@",Tableau46[[#This Row],[file name]])))),1) -> #VALUE!
A15: =IFERROR(LEFT(RIGHT(C15,LEN(C15)-SEARCH("@",C15)),SEARCH("/",RIGHT(C15,LEN(C15)-SEARCH("@",C15)-1))),"") | B15: =LEFT(RIGHT(RIGHT(Tableau46[[#This Row],[file name]],LEN(Tableau46[[#This Row],[file name]])-SEARCH("@",Tableau46[[#This Row],[file name]])),LEN(RIGHT(Tableau46[[#This Row],[file name]],LEN(Tableau46[[#This Row],[file name]])-SEARCH("@",Tableau46[[#This Row],[file name]])))-SEARCH("/",RIGHT(Tableau46[[#This Row],[file name]],LEN(Tableau46[[#This Row],[file name]])-SEARCH("@",Tableau46[[#This Row],[file name]])))),1) -> #VALUE!
A16: =IFERROR(LEFT(RIGHT(C16,LEN(C16)-SEARCH("@",C16)),SEARCH("/",RIGHT(C16,LEN(C16)-SEARCH("@",C16)-1))),"") | B16: =LEFT(RIGHT(RIGHT(Tableau46[[#This Row],[file name]],LEN(Tableau46[[#This Row],[file name]])-SEARCH("@",Tableau46[[#This Row],[file name]])),LEN(RIGHT(Tableau46[[#This Row],[file name]],LEN(Tableau46[[#This Row],[file name]])-SEARCH("@",Tableau46[[#This Row],[file name]])))-SEARCH("/",RIGHT(Tableau46[[#This Row],[file name]],LEN(Tableau46[[#This Row],[file name]])-SEARCH("@",Tableau46[[#This Row],[file name]])))),1) -> #VALUE!
A17: =IFERROR(LEFT(RIGHT(C17,LEN(C17)-SEARCH("@",C17)),SEARCH("/",RIGHT(C17,LEN(C17)-SEARCH("@",C17)-1))),"") | B17: =LEFT(RIGHT(RIGHT(Tableau46[[#This Row],[file name]],LEN(Tableau46[[#This Row],[file name]])-SEARCH("@",Tableau46[[#This Row],[file name]])),LEN(RIGHT(Tableau46[[#This Row],[file name]],LEN(Tableau46[[#This Row],[file name]])-SEARCH("@",Tableau46[[#This Row],[file name]])))-SEARCH("/",RIGHT(Tableau46[[#This Row],[file name]],LEN(Tableau46[[#This Row],[file name]])-SEARCH("@",Tableau46[[#This Row],[file name]])))),1) -> #VALUE!
... A1531: =IFERROR(LEFT(RIGHT(C1531,LEN(C1531)-SEARCH("@",C1531)),SEARCH("/",RIGHT(C1531,LEN(C1531)-SEARCH("@",C1531)-1))),"") | B1531: =LEFT(RIGHT(RIGHT(Tableau46[[#This Row],[file name]],LEN(Tableau46[[#This Row],[file name]])-SEARCH("@",Tableau46[[#This Row],[file name]])),LEN(RIGHT(Tableau46[[#This Row],[file name]],LEN(Tableau46[[#This Row],[file name]])-SEARCH("@",Tableau46[[#This Row],[file name]])))-SEARCH("/",RIGHT(Tableau46[[#This Row],[file name]],LEN(Tableau46[[#This Row],[file name]])-SEARCH("@",Tableau46[[#This Row],[file name]])))),1) -> #VALUE!

Sheet R2
A1: 6. Expérimentateur 2 : copier et coller les valeurs des intensités totales de fluorescences obtenues dans le fichier raw data lors du traitement des images. Ne pas supprimer les colonnes correspondant aux concentrations non lues.
A3: R2 | B3: Non dopé | J3: avec testo
A4: Noms des groupes | B4: ='Page de garde'!A7 -> Témoin solvant | C4: ='Page de garde'!A9 -> EE2-33,8ng/L | D4: ='Page de garde'!A10 -> EE2-50,6ng/L | E4: ='Page de garde'!A11 -> EE2-76ng/L | F4: ='Page de garde'!A12 -> EE2-114ng/L | G4: ='Page de garde'!A13 -> EE2-170,9ng/L | H4: ='Page de garde'!A14 -> EE2-488ng/L | J4: ='Page de garde'!A36 -> Testo -30µg/L | K4: ='Page de garde'!A37 -> Testo 30µg/L + EE2 -64ng/L | L4: ='Page de garde'!A38 -> Testo 30µg/L + FAD-10mg/L
A5: Données brutes | B5: =Feuil2!E172 -> 18279 | C5: =Feuil2!E189 -> 34120 | D5: =Feuil2!E206 -> 21055 | E5: =Feuil2!E223 -> 20226 | F5: =Feuil2!E240 -> 39644 | G5: =Feuil2!E257 -> 390106 | H5: =Feuil2!E274 -> 379509 | J5: =Feuil2!E291 -> 245685 | K5: =Feuil2!E308 -> 257383 | L5: =Feuil2!E325 -> 4116
B6: =Feuil2!E173 -> 4789 | C6: =Feuil2!E190 -> 2778 | D6: =Feuil2!E207 -> 945 | E6: =Feuil2!E224 -> 117649 | F6: =Feuil2!E241 -> 31315 | G6: =Feuil2!E258 -> 169612 | H6: =Feuil2!E275 -> 23854 | J6: =Feuil2!E292 -> 343473 | K6: =Feuil2!E309 -> 336785 | L6: =Feuil2!E326 -> 7471
B7: =Feuil2!E174 -> 22740 | C7: =Feuil2!E191 -> 63199 | D7: =Feuil2!E208 -> 407 | E7: =Feuil2!E225 -> 16076 | F7: =Feuil2!E242 -> 33897 | G7: =Feuil2!E259 -> 241561 | H7: =Feuil2!E276 -> 360485 | J7: =Feuil2!E293 -> 339347 | K7: =Feuil2!E310 -> 316392 | L7: =Feuil2!E327 -> 6817
B8: =Feuil2!E175 -> 1336 | C8: =Feuil2!E192 -> 3347 | D8: =Feuil2!E209 -> 35100 | E8: =Feuil2!E226 -> 181441 | F8: =Feuil2!E243 -> 982 | G8: =Feuil2!E260 -> 331859 | H8: =Feuil2!E277 -> 499210 | J8: =Feuil2!E294 -> 190876 | K8: =Feuil2!E311 -> 273694 | L8: =Feuil2!E328 -> 24333
B9: =Feuil2!E176 -> 3881 | C9: =Feuil2!E193 -> 7554 | D9: =Feuil2!E210 -> 27172 | E9: =Feuil2!E227 -> 9132 | G9: =Feuil2!E261 -> 259330 | H9: =Feuil2!E278 -> 422387 | J9: =Feuil2!E295 -> 106258 | K9: =Feuil2!E312 -> 187466 | L9: =Feuil2!E329 -> 12430
B10: =Feuil2!E177 -> 3044 | C10: =Feuil2!E194 -> 27173 | D10: =Feuil2!E211 -> 15093 | E10: =Feuil2!E228 -> 9328 | F10: =Feuil2!E245 -> 13909 | G10: =Feuil2!E262 -> 306542 | H10: =Feuil2!E279 -> 373117 | J10: =Feuil2!E296 -> 341669 | K10: =Feuil2!E313 -> 182551 | L10: =Feuil2!E330 -> 25435
B11: =Feuil2!E178 -> 6920 | C11: =Feuil2!E195 -> 31183 | D11: =Feuil2!E212 -> 0 | E11: =Feuil2!E229 -> 9323 | F11: =Feuil2!E246 -> 20026 | G11: =Feuil2!E263 -> 270435 | H11: =Feuil2!E280 -> 275670 | J11: =Feuil2!E297 -> 285593 | K11: =Feuil2!E314 -> 325646 | L11: =Feuil2!E331 -> 42160
B12: =Feuil2!E179 -> 28071 | C12: =Feuil2!E196 -> 15452 | D12: =Feuil2!E213 -> 8043 | E12: =Feuil2!E230 -> 60405 | F12: =Feuil2!E247 -> 0 | G12: =Feuil2!E264 -> 175240 | H12: =Feuil2!E281 -> 440977 | J12: =Feuil2!E298 -> 239371 | K12: =Feuil2!E315 -> 326877 | L12: =Feuil2!E332 -> 54700
A22: =A4 -> Noms des groupes | B22: =B4 -> Témoin solvant | C22: =C4 -> EE2-33,8ng/L | D22: =D4 -> EE2-50,6ng/L | E22: =E4 -> EE2-76ng/L | F22: =F4 -> EE2-114ng/L | G22: =G4 -> EE2-170,9ng/L | H22: =H4 -> EE2-488ng/L | I22: Noms des groupes | J22: =J4 -> Testo -30µg/L | K22: =K4 -> Testo 30µg/L + EE2 -64ng/L | L22: =L4 -> Testo 30µg/L + FAD-10mg/L
A23: mean | B23: =AVERAGE(B5:B20) -> 11132.5 | C23: =AVERAGE(C5:C20) -> 23100.75 | D23: =AVERAGE(D5:D20) -> 13476.875 | E23: =AVERAGE(E5:E20) -> 52947.5 | F23: =AVERAGE(F5:F20) -> 19967.571 | G23: =AVERAGE(G5:G20) -> 268085.62 | H23: =AVERAGE(H5:H20) -> 346901.12 | I23: mean | J23: =AVERAGE(J5:J20) -> 261534 | K23: =AVERAGE(K5:K20) -> 275849.25 | L23: =AVERAGE(L5:L20) -> 22182.75
A24: SD | B24: =STDEV(B5:B20) -> 10314.234 | C24: =STDEV(C5:C20) -> 20405.283 | D24: =STDEV(D5:D20) -> 13385.378 | E24: =STDEV(E5:E20) -> 64263.117 | F24: =STDEV(F5:F20) -> 15842.035 | G24: =STDEV(G5:G20) -> 75155.087 | H24: =STDEV(H5:H20) -> 145952.42 | I24: SD | J24: =STDEV(J5:J20) -> 84189.323 | K24: =STDEV(K5:K20) -> 62452.539 | L24: =STDEV(L5:L20) -> 18305.847
B26: Non dopé | J26: avec testo
A27: Noms des groupes | B27: =B4 -> Témoin solvant | C27: =C4 -> EE2-33,8ng/L | D27: =D4 -> EE2-50,6ng/L | E27: =E4 -> EE2-76ng/L | F27: =F4 -> EE2-114ng/L | G27: =G4 -> EE2-170,9ng/L | H27: =H4 -> EE2-488ng/L | J27: =J4 -> Testo -30µg/L | K27: =K4 -> Testo 30µg/L + EE2 -64ng/L | L27: =L4 -> Testo 30µg/L + FAD-10mg/L
