Workbook

Sheet Front page
A2: R1 | B2: Experiment number : | C2: Prochloraz_01 | E2: Date performed : 01-09-2021
A3: R2 | B3: Experiment number : | C3: Prochloraz_02 | E3: Date performed : 15-09-2021
A4: R3 | B4: Experiment number : | C4: Prochloraz_03 | E4: Date performed : 17-09-2021
A5: 2. Expérimentateur 1 : copier et coller la dilution appliquée et le nom donné pour chaque des échantillons par le client. Conserver la mise en forme de l'exemple en italique. Ne pas remplir la colonne "nom sur graphique".
A6: Do not fill in | B6: Do not fill in2 | C6: Concentration | D6: Units | E6: Chemical name | F6: Do not fill in3
A7: =IF(ISBLANK(liste_groupe[[#This Row],[Do not fill in2]])," ",IF(ISBLANK(liste_groupe[[#This Row],[Units]]),CONCATENATE(liste_groupe[[#This Row],[Chemical name]],liste_groupe[[#This Row],[Do not fill in3]]),CONCATENATE(liste_groupe[[#This Row],[Chemical name]],"-",liste_groupe[[#This Row],[Concentration]],liste_groupe[[#This Row],[Units]],liste_groupe[[#This Row],[Do not fill in3]]))) -> Solvent control | B7: Témoin | E7: Solvent control
A8: =IF(ISBLANK(liste_groupe[[#This Row],[Do not fill in2]])," ",IF(ISBLANK(liste_groupe[[#This Row],[Units]]),CONCATENATE(liste_groupe[[#This Row],[Chemical name]],liste_groupe[[#This Row],[Do not fill in3]]),CONCATENATE(liste_groupe[[#This Row],[Chemical name]],"-",liste_groupe[[#This Row],[Concentration]],liste_groupe[[#This Row],[Units]],liste_groupe[[#This Row],[Do not fill in3]]))) -> EE2-33.8ng/L | B8: Témoin | C8: 33.8 | D8: ng/L | E8: EE2
A9: =IF(ISBLANK(liste_groupe[[#This Row],[Do not fill in2]])," ",IF(ISBLANK(liste_groupe[[#This Row],[Units]]),CONCATENATE(liste_groupe[[#This Row],[Chemical name]],liste_groupe[[#This Row],[Do not fill in3]]),CONCATENATE(liste_groupe[[#This Row],[Chemical name]],"-",liste_groupe[[#This Row],[Concentration]],liste_groupe[[#This Row],[Units]],liste_groupe[[#This Row],[Do not fill in3]]))) -> EE2-50.6ng/L | B9: Témoin | C9: 50.6 | D9: ng/L | E9: EE2
A10: =IF(ISBLANK(liste_groupe[[#This Row],[Do not fill in2]])," ",IF(ISBLANK(liste_groupe[[#This Row],[Units]]),CONCATENATE(liste_groupe[[#This Row],[Chemical name]],liste_groupe[[#This Row],[Do not fill in3]]),CONCATENATE(liste_groupe[[#This Row],[Chemical name]],"-",liste_groupe[[#This Row],[Concentration]],liste_groupe[[#This Row],[Units]],liste_groupe[[#This Row],[Do not fill in3]]))) -> EE2-76ng/L | B10: Témoin | C10: 76 | D10: ng/L | E10: EE2
A11: =IF(ISBLANK(liste_groupe[[#This Row],[Do not fill in2]])," ",IF(ISBLANK(liste_groupe[[#This Row],[Units]]),CONCATENATE(liste_groupe[[#This Row],[Chemical name]],liste_groupe[[#This Row],[Do not fill in3]]),CONCATENATE(liste_groupe[[#This Row],[Chemical name]],"-",liste_groupe[[#This Row],[Concentration]],liste_groupe[[#This Row],[Units]],liste_groupe[[#This Row],[Do not fill in3]]))) -> EE2-114ng/L | B11: Témoin | C11: 114 | D11: ng/L | E11: EE2
A12: =IF(ISBLANK(liste_groupe[[#This Row],[Do not fill in2]])," ",IF(ISBLANK(liste_groupe[[#This Row],[Units]]),CONCATENATE(liste_groupe[[#This Row],[Chemical name]],liste_groupe[[#This Row],[Do not fill in3]]),CONCATENATE(liste_groupe[[#This Row],[Chemical name]],"-",liste_groupe[[#This Row],[Concentration]],liste_groupe[[#This Row],[Units]],liste_groupe[[#This Row],[Do not fill in3]]))) -> EE2-170.9ng/L | B12: Témoin | C12: 170.9 | D12: ng/L | E12: EE2
A13: =IF(ISBLANK(liste_groupe[[#This Row],[Do not fill in2]])," ",IF(ISBLANK(liste_groupe[[#This Row],[Units]]),CONCATENATE(liste_groupe[[#This Row],[Chemical name]],liste_groupe[[#This Row],[Do not fill in3]]),CONCATENATE(liste_groupe[[#This Row],[Chemical name]],"-",liste_groupe[[#This Row],[Concentration]],liste_groupe[[#This Row],[Units]],liste_groupe[[#This Row],[Do not fill in3]]))) -> EE2-488ng/L | B13: Témoin | C13: 488 | D13: ng/L | E13: EE2
A14: =IF(ISBLANK(liste_groupe[[#This Row],[Do not fill in2]])," ",IF(ISBLANK(liste_groupe[[#This Row],[Units]]),CONCATENATE(liste_groupe[[#This Row],[Chemical name]],liste_groupe[[#This Row],[Do not fill in3]]),CONCATENATE(liste_groupe[[#This Row],[Chemical name]],"-",liste_groupe[[#This Row],[Concentration]],liste_groupe[[#This Row],[Units]],liste_groupe[[#This Row],[Do not fill in3]]))) -> Prochloraz-0.063mg/L | B14: test chemical | C14: 0.063 | D14: mg/L | E14: Prochloraz
A15: =IF(ISBLANK(liste_groupe[[#This Row],[Do not fill in2]])," ",IF(ISBLANK(liste_groupe[[#This Row],[Units]]),CONCATENATE(liste_groupe[[#This Row],[Chemical name]],liste_groupe[[#This Row],[Do not fill in3]]),CONCATENATE(liste_groupe[[#This Row],[Chemical name]],"-",liste_groupe[[#This Row],[Concentration]],liste_groupe[[#This Row],[Units]],liste_groupe[[#This Row],[Do not fill in3]]))) -> Prochloraz-0.13mg/L | B15: test chemical | C15: 0.13 | D15: mg/L | E15: Prochloraz
A16: =IF(ISBLANK(liste_groupe[[#This Row],[Do not fill in2]])," ",IF(ISBLANK(liste_groupe[[#This Row],[Units]]),CONCATENATE(liste_groupe[[#This Row],[Chemical name]],liste_groupe[[#This Row],[Do not fill in3]]),CONCATENATE(liste_groupe[[#This Row],[Chemical name]],"-",liste_groupe[[#This Row],[Concentration]],liste_groupe[[#This Row],[Units]],liste_groupe[[#This Row],[Do not fill in3]]))) -> Prochloraz-0.25mg/L | B16: test chemical | C16: 0.25 | D16: mg/L | E16: Prochloraz
A17: =IF(ISBLANK(liste_groupe[[#This Row],[Do not fill in2]])," ",IF(ISBLANK(liste_groupe[[#This Row],[Units]]),CONCATENATE(liste_groupe[[#This Row],[Chemical name]],liste_groupe[[#This Row],[Do not fill in3]]),CONCATENATE(liste_groupe[[#This Row],[Chemical name]],"-",liste_groupe[[#This Row],[Concentration]],liste_groupe[[#This Row],[Units]],liste_groupe[[#This Row],[Do not fill in3]]))) -> Prochloraz-0.5mg/L | B17: test chemical | C17: 0.5 | D17: mg/L | E17: Prochloraz
A18: =IF(ISBLANK(liste_groupe[[#This Row],[Do not fill in2]])," ",IF(ISBLANK(liste_groupe[[#This Row],[Units]]),CONCATENATE(liste_groupe[[#This Row],[Chemical name]],liste_groupe[[#This Row],[Do not fill in3]]),CONCATENATE(liste_groupe[[#This Row],[Chemical name]],"-",liste_groupe[[#This Row],[Concentration]],liste_groupe[[#This Row],[Units]],liste_groupe[[#This Row],[Do not fill in3]]))) -> Prochloraz-1.0mg/L | B18: test chemical | C18: 1.0 | D18: mg/L | E18: Prochloraz
A19: =IF(ISBLANK(liste_groupe[[#This Row],[Do not fill in2]])," ",IF(ISBLANK(liste_groupe[[#This Row],[Units]]),CONCATENATE(liste_groupe[[#This Row],[Chemical name]],liste_groupe[[#This Row],[Do not fill in3]]),CONCATENATE(liste_groupe[[#This Row],[Chemical name]],"-",liste_groupe[[#This Row],[Concentration]],liste_groupe[[#This Row],[Units]],liste_groupe[[#This Row],[Do not fill in3]]))) | B19: test chemical
A20: =IF(ISBLANK(liste_groupe[[#This Row],[Do not fill in2]])," ",IF(ISBLANK(liste_groupe[[#This Row],[Units]]),CONCATENATE(liste_groupe[[#This Row],[Chemical name]],liste_groupe[[#This Row],[Do not fill in3]]),CONCATENATE(liste_groupe[[#This Row],[Chemical name]],"-",liste_groupe[[#This Row],[Concentration]],liste_groupe[[#This Row],[Units]],liste_groupe[[#This Row],[Do not fill in3]]))) | B20: test chemical
A21: =IF(ISBLANK(liste_groupe[[#This Row],[Do not fill in2]])," ",IF(ISBLANK(liste_groupe[[#This Row],[Units]]),CONCATENATE(liste_groupe[[#This Row],[Chemical name]],liste_groupe[[#This Row],[Do not fill in3]]),CONCATENATE(liste_groupe[[#This Row],[Chemical name]],"-",liste_groupe[[#This Row],[Concentration]],liste_groupe[[#This Row],[Units]],liste_groupe[[#This Row],[Do not fill in3]]))) | B21: test chemical
A22: =IF(ISBLANK(liste_groupe[[#This Row],[Do not fill in2]])," ",IF(ISBLANK(liste_groupe[[#This Row],[Units]]),CONCATENATE(liste_groupe[[#This Row],[Chemical name]],liste_groupe[[#This Row],[Do not fill in3]]),CONCATENATE(liste_groupe[[#This Row],[Chemical name]],"-",liste_groupe[[#This Row],[Concentration]],liste_groupe[[#This Row],[Units]],liste_groupe[[#This Row],[Do not fill in3]]))) | B22: test chemical
A23: =IF(ISBLANK(liste_groupe[[#This Row],[Do not fill in2]])," ",IF(ISBLANK(liste_groupe[[#This Row],[Units]]),CONCATENATE(liste_groupe[[#This Row],[Chemical name]],liste_groupe[[#This Row],[Do not fill in3]]),CONCATENATE(liste_groupe[[#This Row],[Chemical name]],"-",liste_groupe[[#This Row],[Concentration]],liste_groupe[[#This Row],[Units]],liste_groupe[[#This Row],[Do not fill in3]]))) | B23: test chemical
A24: =IF(ISBLANK(liste_groupe[[#This Row],[Do not fill in2]])," ",IF(ISBLANK(liste_groupe[[#This Row],[Units]]),CONCATENATE(liste_groupe[[#This Row],[Chemical name]],liste_groupe[[#This Row],[Do not fill in3]]),CONCATENATE(liste_groupe[[#This Row],[Chemical name]],"-",liste_groupe[[#This Row],[Concentration]],liste_groupe[[#This Row],[Units]],liste_groupe[[#This Row],[Do not fill in3]]))) | B24: test chemical
A25: =IF(ISBLANK(liste_groupe[[#This Row],[Do not fill in2]])," ",IF(ISBLANK(liste_groupe[[#This Row],[Units]]),CONCATENATE(liste_groupe[[#This Row],[Chemical name]],liste_groupe[[#This Row],[Do not fill in3]]),CONCATENATE(liste_groupe[[#This Row],[Chemical name]],"-",liste_groupe[[#This Row],[Concentration]],liste_groupe[[#This Row],[Units]],liste_groupe[[#This Row],[Do not fill in3]]))) | B25: test chemical
A26: =IF(ISBLANK(liste_groupe[[#This Row],[Do not fill in2]])," ",IF(ISBLANK(liste_groupe[[#This Row],[Units]]),CONCATENATE(liste_groupe[[#This Row],[Chemical name]],liste_groupe[[#This Row],[Do not fill in3]]),CONCATENATE(liste_groupe[[#This Row],[Chemical name]],"-",liste_groupe[[#This Row],[Concentration]],liste_groupe[[#This Row],[Units]],liste_groupe[[#This Row],[Do not fill in3]]))) | B26: test chemical
A27: =IF(ISBLANK(liste_groupe[[#This Row],[Do not fill in2]])," ",IF(ISBLANK(liste_groupe[[#This Row],[Units]]),CONCATENATE(liste_groupe[[#This Row],[Chemical name]],liste_groupe[[#This Row],[Do not fill in3]]),CONCATENATE(liste_groupe[[#This Row],[Chemical name]],"-",liste_groupe[[#This Row],[Concentration]],liste_groupe[[#This Row],[Units]],liste_groupe[[#This Row],[Do not fill in3]]))) | B27: test chemical
A28: =IF(ISBLANK(liste_groupe[[#This Row],[Do not fill in2]])," ",IF(ISBLANK(liste_groupe[[#This Row],[Units]]),CONCATENATE(liste_groupe[[#This Row],[Chemical name]],liste_groupe[[#This Row],[Do not fill in3]]),CONCATENATE(liste_groupe[[#This Row],[Chemical name]],"-",liste_groupe[[#This Row],[Concentration]],liste_groupe[[#This Row],[Units]],liste_groupe[[#This Row],[Do not fill in3]]))) | B28: test chemical
A29: =IF(ISBLANK(liste_groupe[[#This Row],[Do not fill in2]])," ",IF(ISBLANK(liste_groupe[[#This Row],[Units]]),CONCATENATE(liste_groupe[[#This Row],[Chemical name]],liste_groupe[[#This Row],[Do not fill in3]]),CONCATENATE(liste_groupe[[#This Row],[Chemical name]],"-",liste_groupe[[#This Row],[Concentration]],liste_groupe[[#This Row],[Units]],liste_groupe[[#This Row],[Do not fill in3]]))) | B29: test chemical
A30: =IF(ISBLANK(liste_groupe[[#This Row],[Do not fill in2]])," ",IF(ISBLANK(liste_groupe[[#This Row],[Units]]),CONCATENATE(liste_groupe[[#This Row],[Chemical name]],liste_groupe[[#This Row],[Do not fill in3]]),CONCATENATE(liste_groupe[[#This Row],[Chemical name]],"-",liste_groupe[[#This Row],[Concentration]],liste_groupe[[#This Row],[Units]],liste_groupe[[#This Row],[Do not fill in3]]))) | B30: test chemical
... A34: =IF(ISBLANK(liste_groupe[[#This Row],[Do not fill in2]])," ",IF(ISBLANK(liste_groupe[[#This Row],[Units]]),CONCATENATE(liste_groupe[[#This Row],[Chemical name]],liste_groupe[[#This Row],[Do not fill in3]]),CONCATENATE(liste_groupe[[#This Row],[Chemical name]],"-",liste_groupe[[#This Row],[Concentration]],liste_groupe[[#This Row],[Units]],liste_groupe[[#This Row],[Do not fill in3]]))) | B34: test chemical
A35: =IF(ISBLANK(liste_groupe[[#This Row],[Do not fill in2]])," ",IF(ISBLANK(liste_groupe[[#This Row],[Units]]),CONCATENATE(liste_groupe[[#This Row],[Chemical name]],liste_groupe[[#This Row],[Do not fill in3]]),CONCATENATE(liste_groupe[[#This Row],[Chemical name]],"-",liste_groupe[[#This Row],[Concentration]],liste_groupe[[#This Row],[Units]],liste_groupe[[#This Row],[Do not fill in3]]))) -> Testo -30µg/L | B35: Témoin | C35: 30 | D35: µg/L | E35: Testo
A36: =IF(ISBLANK(liste_groupe[[#This Row],[Do not fill in2]])," ",IF(ISBLANK(liste_groupe[[#This Row],[Units]]),CONCATENATE(liste_groupe[[#This Row],[Chemical name]],liste_groupe[[#This Row],[Do not fill in3]]),CONCATENATE(liste_groupe[[#This Row],[Chemical name]],"-",liste_groupe[[#This Row],[Concentration]],liste_groupe[[#This Row],[Units]],liste_groupe[[#This Row],[Do not fill in3]]))) -> Testo 30µg/L + EE2 -64ng/L | B36: Témoin | C36: 64 | D36: ng/L | E36: Testo 30µg/L + EE2
A37: =IF(ISBLANK(liste_groupe[[#This Row],[Do not fill in2]])," ",IF(ISBLANK(liste_groupe[[#This Row],[Units]]),CONCATENATE(liste_groupe[[#This Row],[Chemical name]],liste_groupe[[#This Row],[Do not fill in3]]),CONCATENATE(liste_groupe[[#This Row],[Chemical name]],"-",liste_groupe[[#This Row],[Concentration]],liste_groupe[[#This Row],[Units]],liste_groupe[[#This Row],[Do not fill in3]]))) -> Testo 30µg/L + FAD-10mg/L | B37: Témoin | C37: 10 | D37: mg/L | E37: Testo 30µg/L + FAD
A38: =IF(ISBLANK(liste_groupe[[#This Row],[Do not fill in2]])," ",IF(ISBLANK(liste_groupe[[#This Row],[Units]]),CONCATENATE(liste_groupe[[#This Row],[Chemical name]],liste_groupe[[#This Row],[Do not fill in3]]),CONCATENATE(liste_groupe[[#This Row],[Chemical name]],"-",liste_groupe[[#This Row],[Concentration]],liste_groupe[[#This Row],[Units]],liste_groupe[[#This Row],[Do not fill in3]]))) -> Prochloraz-0.063mg/L + Testostérone | B38: =B14 -> test chemical | C38: =C14 -> 0.063 | D38: =D14 -> mg/L | E38: =E14 -> Prochloraz | F38: + Testostérone
A39: =IF(ISBLANK(liste_groupe[[#This Row],[Do not fill in2]])," ",IF(ISBLANK(liste_groupe[[#This Row],[Units]]),CONCATENATE(liste_groupe[[#This Row],[Chemical name]],liste_groupe[[#This Row],[Do not fill in3]]),CONCATENATE(liste_groupe[[#This Row],[Chemical name]],"-",liste_groupe[[#This Row],[Concentration]],liste_groupe[[#This Row],[Units]],liste_groupe[[#This Row],[Do not fill in3]]))) -> Prochloraz-0.13mg/L + Testostérone | B39: =B15 -> test chemical | C39: =C15 -> 0.13 | D39: =D15 -> mg/L | E39: =E15 -> Prochloraz | F39: + Testostérone
A40: =IF(ISBLANK(liste_groupe[[#This Row],[Do not fill in2]])," ",IF(ISBLANK(liste_groupe[[#This Row],[Units]]),CONCATENATE(liste_groupe[[#This Row],[Chemical name]],liste_groupe[[#This Row],[Do not fill in3]]),CONCATENATE(liste_groupe[[#This Row],[Chemical name]],"-",liste_groupe[[#This Row],[Concentration]],liste_groupe[[#This Row],[Units]],liste_groupe[[#This Row],[Do not fill in3]]))) -> Prochloraz-0.25mg/L + Testostérone | B40: =B16 -> test chemical | C40: =C16 -> 0.25 | D40: =D16 -> mg/L | E40: =E16 -> Prochloraz | F40: + Testostérone
A41: =IF(ISBLANK(liste_groupe[[#This Row],[Do not fill in2]])," ",IF(ISBLANK(liste_groupe[[#This Row],[Units]]),CONCATENATE(liste_groupe[[#This Row],[Chemical name]],liste_groupe[[#This Row],[Do not fill in3]]),CONCATENATE(liste_groupe[[#This Row],[Chemical name]],"-",liste_groupe[[#This Row],[Concentration]],liste_groupe[[#This Row],[Units]],liste_groupe[[#This Row],[Do not fill in3]]))) -> Prochloraz-0.5mg/L + Testostérone | B41: =B17 -> test chemical | C41: =C17 -> 0.5 | D41: =D17 -> mg/L | E41: =E17 -> Prochloraz | F41: + Testostérone
A42: =IF(ISBLANK(liste_groupe[[#This Row],[Do not fill in2]])," ",IF(ISBLANK(liste_groupe[[#This Row],[Units]]),CONCATENATE(liste_groupe[[#This Row],[Chemical name]],liste_groupe[[#This Row],[Do not fill in3]]),CONCATENATE(liste_groupe[[#This Row],[Chemical name]],"-",liste_groupe[[#This Row],[Concentration]],liste_groupe[[#This Row],[Units]],liste_groupe[[#This Row],[Do not fill in3]]))) -> Prochloraz-1.0mg/L + Testostérone | B42: =B18 -> test chemical | C42: =C18 -> 1.0 | D42: =D18 -> mg/L | E42: =E18 -> Prochloraz | F42: + Testostérone
A43: =IF(ISBLANK(liste_groupe[[#This Row],[Do not fill in2]])," ",IF(ISBLANK(liste_groupe[[#This Row],[Units]]),CONCATENATE(liste_groupe[[#This Row],[Chemical name]],liste_groupe[[#This Row],[Do not fill in3]]),CONCATENATE(liste_groupe[[#This Row],[Chemical name]],"-",liste_groupe[[#This Row],[Concentration]],liste_groupe[[#This Row],[Units]],liste_groupe[[#This Row],[Do not fill in3]]))) -> 0-00 + Testostérone | B43: =B19 -> test chemical | C43: =C19 -> 0 | D43: =D19 -> 0 | E43: =E19 -> 0 | F43: + Testostérone
A44: =IF(ISBLANK(liste_groupe[[#This Row],[Do not fill in2]])," ",IF(ISBLANK(liste_groupe[[#This Row],[Units]]),CONCATENATE(liste_groupe[[#This Row],[Chemical name]],liste_groupe[[#This Row],[Do not fill in3]]),CONCATENATE(liste_groupe[[#This Row],[Chemical name]],"-",liste_groupe[[#This Row],[Concentration]],liste_groupe[[#This Row],[Units]],liste_groupe[[#This Row],[Do not fill in3]]))) -> 0-00 + Testostérone | B44: =B20 -> test chemical | C44: =C20 -> 0 | D44: =D20 -> 0 | E44: =E20 -> 0 | F44: + Testostérone
...

Sheet R1
A1: 3. Expérimentateur 1 : copier et coller les valeurs des intensités totales de fluorescences obtenues dans le fichier raw data lors du traitement des images.
A3: R1 | B3: Non dopé | O3: avec testo
A4: Noms des groupes | B4: ='Front page'!A7 -> Solvent control | C4: ='Front page'!A8 -> EE2-33.8ng/L | D4: ='Front page'!A9 -> EE2-50.6ng/L | E4: ='Front page'!A10 -> EE2-76ng/L | F4: ='Front page'!A11 -> EE2-114ng/L | G4: ='Front page'!A12 -> EE2-170.9ng/L | H4: ='Front page'!A13 -> EE2-488ng/L | I4: ='Front page'!A14 -> Prochloraz-0.063mg/L | J4: ='Front page'!A15 -> Prochloraz-0.13mg/L | K4: ='Front page'!A16 -> Prochloraz-0.25mg/L | L4: ='Front page'!A17 -> Prochloraz-0.5mg/L | M4: ='Front page'!A18 -> Prochloraz-1.0mg/L | O4: ='Front page'!A35 -> Testo -30µg/L | P4: ='Front page'!A36 -> Testo 30µg/L + EE2 -64ng/L | Q4: ='Front page'!A37 -> Testo 30µg/L + FAD-10mg/L | R4: ='Front page'!A38 -> Prochloraz-0.063mg/L + Testostérone | S4: ='Front page'!A39 -> Prochloraz-0.13mg/L + Testostérone | T4: ='Front page'!A40 -> Prochloraz-0.25mg/L + Testostérone | U4: ='Front page'!A41 -> Prochloraz-0.5mg/L + Testostérone | V4: ='Front page'!A42 -> Prochloraz-1.0mg/L + Testostérone | W4: ='Front page'!A43 -> 0-00 + Testostérone | X4: ='Front page'!A44 -> 0-00 + Testostérone | Y4: ='Front page'!A45 -> 0-00 + Testostérone | Z4: ='Front page'!A46 -> 0-00 + Testostérone | AA4: ='Front page'!A47 -> 0-00 + Testostérone | AB4: ='Front page'!A48 -> 0-00 + Testostérone | AC4: ='Front page'!A49 -> 0-00 + Testostérone | AD4: ='Front page'!A50 -> 0-00 + Testostérone | AE4: ='Front page'!A51 -> 0-00 + Testostérone | AF4: ='Front page'!A52 -> 0-00 + Testostérone | AG4: ='Front page'!A53 -> 0-00 + Testostérone | AH4: ='Front page'!A54 -> 0-00 + Testostérone | AI4: ='Front page'!A55 -> 0-00 + Testostérone | AJ4: ='Front page'!A56 -> 0-00 + Testostérone | AK4: ='Front page'!A57 -> 0-00 + Testostérone
A5: Données brutes | B5: 0 | C5: 0 | D5: 0 | E5: 0 | F5: 841 | G5: 165441 | H5: 156931 | I5: 0 | J5: 0 | K5: 0 | L5: 0 | M5: 2041 | O5: 0 | P5: 230263 | Q5: 0 | R5: 10964 | S5: 0 | T5: 160 | U5: 0 | V5: 5472
B6: 413 | C6: 402 | D6: 0 | E6: 0 | F6: 128071 | G6: 266292 | H6: 286760 | I6: 0 | J6: 0 | K6: 0 | L6: 80 | M6: 841 | O6: 110643 | P6: 251514 | Q6: 0 | R6: 43264 | S6: 241 | T6: 1626 | U6: 80 | V6: 0
B7: 0 | C7: 82 | D7: 0 | E7: 322 | F7: 63763 | G7: 240013 | H7: 260200 | I7: 8515 | J7: 7800 | K7: 18063 | L7: 0 | M7: 5404 | O7: 21268 | P7: 255082 | Q7: 0 | R7: 0 | S7: 0 | T7: 0 | U7: 0 | V7: 84
B8: 0 | C8: 0 | D8: 11307 | E8: 0 | F8: 0 | G8: 222169 | H8: 193671 | I8: 570 | J8: 1535 | K8: 0 | L8: 1395 | M8: 0 | O8: 97611 | P8: 172537 | Q8: 4342 | R8: 74374 | S8: 404 | T8: 0 | U8: 0 | V8: 81
B9: 0 | C9: 81 | D9: 0 | E9: 255 | F9: 182835 | G9: 116056 | H9: 340831 | I9: 6889 | J9: 0 | K9: 5812 | L9: 0 | M9: 12527 | O9: 238539 | P9: 194599 | Q9: 0 | R9: 510 | S9: 12378 | T9: 0 | U9: 0 | V9: 0
B10: 4412 | C10: 0 | D10: 0 | E10: 249333 | F10: 71495 | G10: 134293 | H10: 204993 | I10: 0 | J10: 0 | K10: 405 | L10: 0 | M10: 0 | O10: 136199 | P10: 206544 | Q10: 819 | R10: 1463 | S10: 15399 | T10: 0 | U10: 0 | V10: 0
B11: 0 | C11: 0 | D11: 5836 | E11: 80 | F11: 3967 | G11: 218940 | H11: 276626 | I11: 7969 | J11: 0 | K11: 0 | L11: 20529 | M11: 0 | O11: 154618 | P11: 124267 | Q11: 0 | R11: 11152 | S11: 0 | T11: 2053 | U11: 0 | V11: 0
B12: 1237 | C12: 15885 | D12: 0 | E12: 246730 | F12: 0 | G12: 147158 | H12: 306586 | I12: 0 | J12: 0 | K12: 0 | L12: 0 | M12: 723 | O12: 189521 | P12: 186430 | Q12: 0 | R12: 8752 | S12: 0 | T12: 0 | U12: 0 | V12: 325
O13: 93987
O14: 125914
O15: 0
O16: 209100
O17: 68435
O18: 170717
O19: 189227
O20: 152068
A22: =A4 -> Noms des groupes | B22: =B4 -> Solvent control | C22: =C4 -> EE2-33.8ng/L | D22: =D4 -> EE2-50.6ng/L | E22: =E4 -> EE2-76ng/L | F22: =F4 -> EE2-114ng/L | G22: =G4 -> EE2-170.9ng/L | H22: =H4 -> EE2-488ng/L | ... M22: =M4 -> Prochloraz-1.0mg/L | O22: =O4 -> Testo -30µg/L | P22: =P4 -> Testo 30µg/L + EE2 -64ng/L | Q22: =Q4 -> Testo 30µg/L + FAD-10mg/L | R22: =R4 -> Prochloraz-0.063mg/L + Testostérone | S22: =S4 -> Prochloraz-0.13mg/L + Testostérone | T22: =T4 -> Prochloraz-0.25mg/L + Testostérone | U22: =U4 -> Prochloraz-0.5mg/L + Testostérone | V22: =V4 -> Prochloraz-1.0mg/L + Testostérone | ... AK22: =AK4 -> 0-00 + Testostérone
A23: mean | B23: =AVERAGE(B5:B20) -> 757.75 | C23: =AVERAGE(C5:C20) -> 2056.25 | D23: =AVERAGE(D5:D20) -> 2142.875 | E23: =AVERAGE(E5:E20) -> 62090 | F23: =AVERAGE(F5:F20) -> 56371.5 | G23: =AVERAGE(G5:G20) -> 188795.25 | H23: =AVERAGE(H5:H20) -> 253324.75 | I23: =AVERAGE(I5:I20) -> 2992.875 | ... M23: =AVERAGE(M5:M20) -> 2692 | O23: =AVERAGE(O5:O20) -> 122365.44 | P23: =AVERAGE(P5:P20) -> 202654.5 | Q23: =AVERAGE(Q5:Q20) -> 645.125 | R23: =AVERAGE(R5:R20) -> 18809.875 | S23: =AVERAGE(S5:S20) -> 3552.75 | T23: =AVERAGE(T5:T20) -> 479.875 | U23: =AVERAGE(U5:U20) -> 10 | V23: =AVERAGE(V5:V20) -> 745.25 | ... AK23: =AVERAGE(AK5:AK20) -> #DIV/0!
A24: SD | B24: =STDEV(B5:B20) -> 1538.6915 | C24: =STDEV(C5:C20) -> 5589.3112 | D24: =STDEV(D5:D20) -> 4228.6749 | E24: =STDEV(E5:E20) -> 114767.76 | F24: =STDEV(F5:F20) -> 69284.661 | G24: =STDEV(G5:G20) -> 55022.194 | H24: =STDEV(H5:H20) -> 62551.146 | I24: =STDEV(I5:I20) -> 4002.41 | ... M24: =STDEV(M5:M20) -> 4367.8979 | O24: =STDEV(O5:O20) -> 72615.49 | P24: =STDEV(P5:P20) -> 43577.583 | Q24: =STDEV(Q5:Q20) -> 1521.0069 | R24: =STDEV(R5:R20) -> 26447.654 | S24: =STDEV(S5:S20) -> 6431.9417 | T24: =STDEV(T5:T20) -> 848.70026 | U24: =STDEV(U5:U20) -> 28.284271 | V24: =STDEV(V5:V20) -> 1913.0695 | ... AK24: =STDEV(AK5:AK20) -> #DIV/0!
B26: Non dopé | O26: avec testo
A27: Noms des groupes | B27: =B4 -> Solvent control | C27: =C4 -> EE2-33.8ng/L | D27: =D4 -> EE2-50.6ng/L | E27: =E4 -> EE2-76ng/L | F27: =F4 -> EE2-114ng/L | G27: =G4 -> EE2-170.9ng/L | H27: =H4 -> EE2-488ng/L | I27: =I4 -> Prochloraz-0.063mg/L | ... M27: =M4 -> Prochloraz-1.0mg/L | O27: =O4 -> Testo -30µg/L | P27: =P4 -> Testo 30µg/L + EE2 -64ng/L | Q27: =Q4 -> Testo 30µg/L + FAD-10mg/L | R27: =R4 -> Prochloraz-0.063mg/L + Testostérone | S27: =S4 -> Prochloraz-0.13mg/L + Testostérone | T27: =T4 -> Prochloraz-0.25mg/L + Testostérone | U27: =U4 -> Prochloraz-0.5mg/L + Testostérone | V27: =V4 -> Prochloraz-1.0mg/L + Testostérone | ... AK27: =AK4 -> 0-00 + Testostérone
A28: Données normalisées sur la moyenne du groupe "Testo" | B28: =IF(B5="","",(B5/$O$23)) -> 0 | C28: =IF(C5="","",(C5/$O$23)) -> 0 | D28: =IF(D5="","",(D5/$O$23)) -> 0 | E28: =IF(E5="","",(E5/$O$23)) -> 0 | F28: =IF(F5="","",(F5/$O$23)) -> 0.0068728557 | G28: =IF(G5="","",(G5/$O$23)) -> 1.3520239 | H28: =IF(H5="","",(H5/$O$23)) -> 1.2824782 | I28: =IF(I5="","",(I5/$O$23)) -> 0 | ... M28: =IF(M5="","",(M5/$O$23)) -> 0.016679546 | O28: =IF(O5="","",(O5/$O$23)) -> 0 | P28: =IF(P5="","",(P5/$O$23)) -> 1.881765 | Q28: =IF(Q5="","",(Q5/$O$23)) -> 0 | R28: =IF(R5="","",(R5/$O$23)) -> 0.089600464 | S28: =IF(S5="","",(S5/$O$23)) -> 0 | T28: =IF(T5="","",(T5/$O$23)) -> 0.0013075588 | U28: =IF(U5="","",(U5/$O$23)) -> 0 | V28: =IF(V5="","",(V5/$O$23)) -> 0.04471851 | ... AK28: =IF(AK5="","",(AK5/$O$23))
B29: =IF(B6="","",(B6/$O$23)) -> 0.0033751361 | C29: =IF(C6="","",(C6/$O$23)) -> 0.0032852414 | D29: =IF(D6="","",(D6/$O$23)) -> 0 | E29: =IF(E6="","",(E6/$O$23)) -> 0 | F29: =IF(F6="","",(F6/$O$23)) -> 1.0466272 | G29: =IF(G6="","",(G6/$O$23)) -> 2.1762027 | H29: =IF(H6="","",(H6/$O$23)) -> 2.3434722 | I29: =IF(I6="","",(I6/$O$23)) -> 0 | ... M29: =IF(M6="","",(M6/$O$23)) -> 0.0068728557 | O29: =IF(O6="","",(O6/$O$23)) -> 0.9042014 | P29: =IF(P6="","",(P6/$O$23)) -> 2.0554333 | Q29: =IF(Q6="","",(Q6/$O$23)) -> 0 | R29: =IF(R6="","",(R6/$O$23)) -> 0.35356389 | S29: =IF(S6="","",(S6/$O$23)) -> 0.0019695104 | T29: =IF(T6="","",(T6/$O$23)) -> 0.013288066 | U29: =IF(U6="","",(U6/$O$23)) -> 0.00065377938 | V29: =IF(V6="","",(V6/$O$23)) -> 0 | ... AK29: =IF(AK6="","",(AK6/$O$23))
B30: =IF(B7="","",(B7/$O$23)) -> 0 | C30: =IF(C7="","",(C7/$O$23)) -> 0.00067012387 | D30: =IF(D7="","",(D7/$O$23)) -> 0 | E30: =IF(E7="","",(E7/$O$23)) -> 0.002631462 | F30: =IF(F7="","",(F7/$O$23)) -> 0.52108668 | G30: =IF(G7="","",(G7/$O$23)) -> 1.9614444 | H30: =IF(H7="","",(H7/$O$23)) -> 2.1264174 | I30: =IF(I7="","",(I7/$O$23)) -> 0.069586643 | ... M30: =IF(M7="","",(M7/$O$23)) -> 0.044162797 | O30: =IF(O7="","",(O7/$O$23)) -> 0.17380725 | P30: =IF(P7="","",(P7/$O$23)) -> 2.0845919 | Q30: =IF(Q7="","",(Q7/$O$23)) -> 0 | R30: =IF(R7="","",(R7/$O$23)) -> 0 | S30: =IF(S7="","",(S7/$O$23)) -> 0 | T30: =IF(T7="","",(T7/$O$23)) -> 0 | U30: =IF(U7="","",(U7/$O$23)) -> 0 | V30: =IF(V7="","",(V7/$O$23)) -> 0.00068646835 | ... AK30: =IF(AK7="","",(AK7/$O$23))
B31: =IF(B8="","",(B8/$O$23)) -> 0 | C31: =IF(C8="","",(C8/$O$23)) -> 0 | D31: =IF(D8="","",(D8/$O$23)) -> 0.092403543 | E31: =IF(E8="","",(E8/$O$23)) -> 0 | F31: =IF(F8="","",(F8/$O$23)) -> 0 | G31: =IF(G8="","",(G8/$O$23)) -> 1.8156189 | H31: =IF(H8="","",(H8/$O$23)) -> 1.5827263 | I31: =IF(I8="","",(I8/$O$23)) -> 0.0046581781 | ... M31: =IF(M8="","",(M8/$O$23)) -> 0 | O31: =IF(O8="","",(O8/$O$23)) -> 0.79770074 | P31: =IF(P8="","",(P8/$O$23)) -> 1.4100142 | Q31: =IF(Q8="","",(Q8/$O$23)) -> 0.035483876 | R31: =IF(R8="","",(R8/$O$23)) -> 0.60780235 | S31: =IF(S8="","",(S8/$O$23)) -> 0.0033015859 | T31: =IF(T8="","",(T8/$O$23)) -> 0 | U31: =IF(U8="","",(U8/$O$23)) -> 0 | V31: =IF(V8="","",(V8/$O$23)) -> 0.00066195162 | ... AK31: =IF(AK8="","",(AK8/$O$23))
B32: =IF(B9="","",(B9/$O$23)) -> 0 | C32: =IF(C9="","",(C9/$O$23)) -> 0.00066195162 | D32: =IF(D9="","",(D9/$O$23)) -> 0 | E32: =IF(E9="","",(E9/$O$23)) -> 0.0020839218 | F32: =IF(F9="","",(F9/$O$23)) -> 1.4941719 | G32: =IF(G9="","",(G9/$O$23)) -> 0.94843775 | H32: =IF(H9="","",(H9/$O$23)) -> 2.7853535 | I32: =IF(I9="","",(I9/$O$23)) -> 0.056298577 | ... M32: =IF(M9="","",(M9/$O$23)) -> 0.10237368 | O32: =IF(O9="","",(O9/$O$23)) -> 1.9493985 | P32: =IF(P9="","",(P9/$O$23)) -> 1.5903102 | Q32: =IF(Q9="","",(Q9/$O$23)) -> 0 | R32: =IF(R9="","",(R9/$O$23)) -> 0.0041678436 | S32: =IF(S9="","",(S9/$O$23)) -> 0.10115601 | T32: =IF(T9="","",(T9/$O$23)) -> 0 | U32: =IF(U9="","",(U9/$O$23)) -> 0 | V32: =IF(V9="","",(V9/$O$23)) -> 0 | ... AK32: =IF(AK9="","",(AK9/$O$23))
B33: =IF(B10="","",(B10/$O$23)) -> 0.036055933 | C33: =IF(C10="","",(C10/$O$23)) -> 0 | D33: =IF(D10="","",(D10/$O$23)) -> 0 | E33: =IF(E10="","",(E10/$O$23)) -> 2.0376097 | F33: =IF(F10="","",(F10/$O$23)) -> 0.58427446 | G33: =IF(G10="","",(G10/$O$23)) -> 1.0974749 | H33: =IF(H10="","",(H10/$O$23)) -> 1.6752525 | I33: =IF(I10="","",(I10/$O$23)) -> 0 | ... M33: =IF(M10="","",(M10/$O$23)) -> 0 | O33: =IF(O10="","",(O10/$O$23)) -> 1.1130512 | P33: =IF(P10="","",(P10/$O$23)) -> 1.6879276 | Q33: =IF(Q10="","",(Q10/$O$23)) -> 0.0066930664 | R33: =IF(R10="","",(R10/$O$23)) -> 0.01195599 | S33: =IF(S10="","",(S10/$O$23)) -> 0.12584436 | T33: =IF(T10="","",(T10/$O$23)) -> 0 | U33: =IF(U10="","",(U10/$O$23)) -> 0 | V33: =IF(V10="","",(V10/$O$23)) -> 0 | ... AK33: =IF(AK10="","",(AK10/$O$23))
B34: =IF(B11="","",(B11/$O$23)) -> 0 | C34: =IF(C11="","",(C11/$O$23)) -> 0 | D34: =IF(D11="","",(D11/$O$23)) -> 0.047693206 | E34: =IF(E11="","",(E11/$O$23)) -> 0.00065377938 | F34: =IF(F11="","",(F11/$O$23)) -> 0.032419285 | G34: =IF(G11="","",(G11/$O$23)) -> 1.7892307 | H34: =IF(H11="","",(H11/$O$23)) -> 2.2606547 | I34: =IF(I11="","",(I11/$O$23)) -> 0.065124599 | ... M34: =IF(M11="","",(M11/$O$23)) -> 0 | O34: =IF(O11="","",(O11/$O$23)) -> 1.2635758 | P34: =IF(P11="","",(P11/$O$23)) -> 1.01554 | Q34: =IF(Q11="","",(Q11/$O$23)) -> 0 | R34: =IF(R11="","",(R11/$O$23)) -> 0.091136846 | S34: =IF(S11="","",(S11/$O$23)) -> 0 | T34: =IF(T11="","",(T11/$O$23)) -> 0.016777613 | U34: =IF(U11="","",(U11/$O$23)) -> 0 | V34: =IF(V11="","",(V11/$O$23)) -> 0 | ... AK34: =IF(AK11="","",(AK11/$O$23))
B35: =IF(B12="","",(B12/$O$23)) -> 0.010109064 | C35: =IF(C12="","",(C12/$O$23)) -> 0.12981607 | D35: =IF(D12="","",(D12/$O$23)) -> 0 | E35: =IF(E12="","",(E12/$O$23)) -> 2.0163373 | F35: =IF(F12="","",(F12/$O$23)) -> 0 | G35: =IF(G12="","",(G12/$O$23)) -> 1.2026108 | H35: =IF(H12="","",(H12/$O$23)) -> 2.5054951 | I35: =IF(I12="","",(I12/$O$23)) -> 0 | ... M35: =IF(M12="","",(M12/$O$23)) -> 0.0059085312 | O35: =IF(O12="","",(O12/$O$23)) -> 1.5488115 | P35: =IF(P12="","",(P12/$O$23)) -> 1.5235511 | Q35: =IF(Q12="","",(Q12/$O$23)) -> 0 | R35: =IF(R12="","",(R12/$O$23)) -> 0.071523464 | S35: =IF(S12="","",(S12/$O$23)) -> 0 | T35: =IF(T12="","",(T12/$O$23)) -> 0 | U35: =IF(U12="","",(U12/$O$23)) -> 0 | V35: =IF(V12="","",(V12/$O$23)) -> 0.0026559787 | ... AK35: =IF(AK12="","",(AK12/$O$23))
B36: =IF(B13="","",(B13/$O$23)) | C36: =IF(C13="","",(C13/$O$23)) | D36: =IF(D13="","",(D13/$O$23)) | E36: =IF(E13="","",(E13/$O$23)) | F36: =IF(F13="","",(F13/$O$23)) | G36: =IF(G13="","",(G13/$O$23)) | H36: =IF(H13="","",(H13/$O$23)) | I36: =IF(I13="","",(I13/$O$23)) | ... M36: =IF(M13="","",(M13/$O$23)) | O36: =IF(O13="","",(O13/$O$23)) -> 0.76808453 | P36: =IF(P13="","",(P13/$O$23)) | Q36: =IF(Q13="","",(Q13/$O$23)) | R36: =IF(R13="","",(R13/$O$23)) | S36: =IF(S13="","",(S13/$O$23)) | T36: =IF(T13="","",(T13/$O$23)) | U36: =IF(U13="","",(U13/$O$23)) | V36: =IF(V13="","",(V13/$O$23)) | ... AK36: =IF(AK13="","",(AK13/$O$23))
B37: =IF(B14="","",(B14/$O$23)) | C37: =IF(C14="","",(C14/$O$23)) | D37: =IF(D14="","",(D14/$O$23)) | E37: =IF(E14="","",(E14/$O$23)) | F37: =IF(F14="","",(F14/$O$23)) | G37: =IF(G14="","",(G14/$O$23)) | H37: =IF(H14="","",(H14/$O$23)) | I37: =IF(I14="","",(I14/$O$23)) | ... M37: =IF(M14="","",(M14/$O$23)) | O37: =IF(O14="","",(O14/$O$23)) -> 1.0289997 | P37: =IF(P14="","",(P14/$O$23)) | Q37: =IF(Q14="","",(Q14/$O$23)) | R37: =IF(R14="","",(R14/$O$23)) | S37: =IF(S14="","",(S14/$O$23)) | T37: =IF(T14="","",(T14/$O$23)) | U37: =IF(U14="","",(U14/$O$23)) | V37: =IF(V14="","",(V14/$O$23)) | ... AK37: =IF(AK14="","",(AK14/$O$23))
B38: =IF(B15="","",(B15/$O$23)) | C38: =IF(C15="","",(C15/$O$23)) | D38: =IF(D15="","",(D15/$O$23)) | E38: =IF(E15="","",(E15/$O$23)) | F38: =IF(F15="","",(F15/$O$23)) | G38: =IF(G15="","",(G15/$O$23)) | H38: =IF(H15="","",(H15/$O$23)) | I38: =IF(I15="","",(I15/$O$23)) | ... M38: =IF(M15="","",(M15/$O$23)) | O38: =IF(O15="","",(O15/$O$23)) -> 0 | P38: =IF(P15="","",(P15/$O$23)) | Q38: =IF(Q15="","",(Q15/$O$23)) | R38: =IF(R15="","",(R15/$O$23)) | S38: =IF(S15="","",(S15/$O$23)) | T38: =IF(T15="","",(T15/$O$23)) | U38: =IF(U15="","",(U15/$O$23)) | V38: =IF(V15="","",(V15/$O$23)) | ... AK38: =IF(AK15="","",(AK15/$O$23))
B39: =IF(B16="","",(B16/$O$23)) | C39: =IF(C16="","",(C16/$O$23)) | D39: =IF(D16="","",(D16/$O$23)) | E39: =IF(E16="","",(E16/$O$23)) | F39: =IF(F16="","",(F16/$O$23)) | G39: =IF(G16="","",(G16/$O$23)) | H39: =IF(H16="","",(H16/$O$23)) | I39: =IF(I16="","",(I16/$O$23)) | ... M39: =IF(M16="","",(M16/$O$23)) | O39: =IF(O16="","",(O16/$O$23)) -> 1.7088159 | P39: =IF(P16="","",(P16/$O$23)) | Q39: =IF(Q16="","",(Q16/$O$23)) | R39: =IF(R16="","",(R16/$O$23)) | S39: =IF(S16="","",(S16/$O$23)) | T39: =IF(T16="","",(T16/$O$23)) | U39: =IF(U16="","",(U16/$O$23)) | V39: =IF(V16="","",(V16/$O$23)) | ... AK39: =IF(AK16="","",(AK16/$O$23))
B40: =IF(B17="","",(B17/$O$23)) | C40: =IF(C17="","",(C17/$O$23)) | D40: =IF(D17="","",(D17/$O$23)) | E40: =IF(E17="","",(E17/$O$23)) | F40: =IF(F17="","",(F17/$O$23)) | G40: =IF(G17="","",(G17/$O$23)) | H40: =IF(H17="","",(H17/$O$23)) | I40: =IF(I17="","",(I17/$O$23)) | ... M40: =IF(M17="","",(M17/$O$23)) | O40: =IF(O17="","",(O17/$O$23)) -> 0.5592674 | P40: =IF(P17="","",(P17/$O$23)) | Q40: =IF(Q17="","",(Q17/$O$23)) | R40: =IF(R17="","",(R17/$O$23)) | S40: =IF(S17="","",(S17/$O$23)) | T40: =IF(T17="","",(T17/$O$23)) | U40: =IF(U17="","",(U17/$O$23)) | V40: =IF(V17="","",(V17/$O$23)) | ... AK40: =IF(AK17="","",(AK17/$O$23))
... B43: =IF(B20="","",(B20/$O$23)) | C43: =IF(C20="","",(C20/$O$23)) | D43: =IF(D20="","",(D20/$O$23)) | E43: =IF(E20="","",(E20/$O$23)) | F43: =IF(F20="","",(F20/$O$23)) | G43: =IF(G20="","",(G20/$O$23)) | H43: =IF(H20="","",(H20/$O$23)) | I43: =IF(I20="","",(I20/$O$23)) | ... M43: =IF(M20="","",(M20/$O$23)) | O43: =IF(O20="","",(O20/$O$23)) -> 1.2427365 | P43: =IF(P20="","",(P20/$O$23)) | Q43: =IF(Q20="","",(Q20/$O$23)) | R43: =IF(R20="","",(R20/$O$23)) | S43: =IF(S20="","",(S20/$O$23)) | T43: =IF(T20="","",(T20/$O$23)) | U43: =IF(U20="","",(U20/$O$23)) | V43: =IF(V20="","",(V20/$O$23)) | ... AK43: =IF(AK20="","",(AK20/$O$23))
A45: =A4 -> Noms des groupes | B45: =B4 -> Solvent control | C45: =C4 -> EE2-33.8ng/L | D45: =D4 -> EE2-50.6ng/L | E45: =E4 -> EE2-76ng/L | F45: =F4 -> EE2-114ng/L | G45: =G4 -> EE2-170.9ng/L | H45: =H4 -> EE2-488ng/L | ... M45: =M4 -> Prochloraz-1.0mg/L | O45: =O4 -> Testo -30µg/L | P45: =P4 -> Testo 30µg/L + EE2 -64ng/L | Q45: =Q4 -> Testo 30µg/L + FAD-10mg/L | R45: =R4 -> Prochloraz-0.063mg/L + Testostérone | S45: =S4 -> Prochloraz-0.13mg/L + Testostérone | T45: =T4 -> Prochloraz-0.25mg/L + Testostérone | U45: =U4 -> Prochloraz-0.5mg/L + Testostérone | V45: =V4 -> Prochloraz-1.0mg/L + Testostérone | ... AK45: =AK4 -> 0-00 + Testostérone
A46: mean | B46: =AVERAGE(B28:B43) -> 0.0061925166 | C46: =AVERAGE(C28:C43) -> 0.016804173 | D46: =AVERAGE(D28:D43) -> 0.017512094 | E46: =AVERAGE(E28:E43) -> 0.50741452 | F46: =AVERAGE(F28:F43) -> 0.46068155 | G46: =AVERAGE(G28:G43) -> 1.5428805 | H46: =AVERAGE(H28:H43) -> 2.0702312 | I46: =AVERAGE(I28:I43) -> 0.0244585 | ... M46: =AVERAGE(M28:M43) -> 0.021999676 | O46: =AVERAGE(O28:O43) -> 1 | P46: =AVERAGE(P28:P43) -> 1.6561417 | Q46: =AVERAGE(Q28:Q43) -> 0.0052721178 | R46: =AVERAGE(R28:R43) -> 0.15371886 | S46: =AVERAGE(S28:S43) -> 0.029033934 | T46: =AVERAGE(T28:T43) -> 0.0039216548 | U46: =AVERAGE(U28:U43) -> 8.1722423e-05 | V46: =AVERAGE(V28:V43) -> 0.0060903635 | ... AK46: =AVERAGE(AK28:AK43) -> #DIV/0!
...

Sheet R2
A1: 6. Expérimentateur 2 : copier et coller les valeurs des intensités totales de fluorescences obtenues dans le fichier raw data lors du traitement des images. Ne pas supprimer les colonnes correspondant aux concentrations non lues.
A3: R2 | B3: Non dopé | O3: avec testo
A4: Noms des groupes | B4: ='Front page'!A7 -> Solvent control | C4: ='Front page'!A8 -> EE2-33.8ng/L | D4: ='Front page'!A9 -> EE2-50.6ng/L | E4: ='Front page'!A10 -> EE2-76ng/L | F4: ='Front page'!A11 -> EE2-114ng/L | G4: ='Front page'!A12 -> EE2-170.9ng/L | H4: ='Front page'!A13 -> EE2-488ng/L | I4: ='Front page'!A14 -> Prochloraz-0.063mg/L | J4: ='Front page'!A15 -> Prochloraz-0.13mg/L | K4: ='Front page'!A16 -> Prochloraz-0.25mg/L | L4: ='Front page'!A17 -> Prochloraz-0.5mg/L | M4: ='Front page'!A18 -> Prochloraz-1.0mg/L | O4: ='Front page'!A35 -> Testo -30µg/L | P4: ='Front page'!A36 -> Testo 30µg/L + EE2 -64ng/L | Q4: ='Front page'!A37 -> Testo 30µg/L + FAD-10mg/L | R4: ='Front page'!A38 -> Prochloraz-0.063mg/L + Testostérone | S4: ='Front page'!A39 -> Prochloraz-0.13mg/L + Testostérone | T4: ='Front page'!A40 -> Prochloraz-0.25mg/L + Testostérone | U4: ='Front page'!A41 -> Prochloraz-0.5mg/L + Testostérone | V4: ='Front page'!A42 -> Prochloraz-1.0mg/L + Testostérone | W4: ='Front page'!A43 -> 0-00 + Testostérone | X4: ='Front page'!A44 -> 0-00 + Testostérone | Y4: ='Front page'!A45 -> 0-00 + Testostérone | Z4: ='Front page'!A46 -> 0-00 + Testostérone | AA4: ='Front page'!A47 -> 0-00 + Testostérone | AB4: ='Front page'!A48 -> 0-00 + Testostérone | AC4: ='Front page'!A49 -> 0-00 + Testostérone | AD4: ='Front page'!A50 -> 0-00 + Testostérone | AE4: ='Front page'!A51 -> 0-00 + Testostérone | AF4: ='Front page'!A52 -> 0-00 + Testostérone | AG4: ='Front page'!A53 -> 0-00 + Testostérone | AH4: ='Front page'!A54 -> 0-00 + Testostérone | AI4: ='Front page'!A55 -> 0-00 + Testostérone | AJ4: ='Front page'!A56 -> 0-00 + Testostérone | AK4: ='Front page'!A57 -> 0-00 + Testostérone
A5: Données brutes | B5: 26845 | C5: 13590 | D5: 28511 | E5: 277882 | F5: 262927 | G5: 348222 | H5: 285950 | I5: 0 | J5: 2461 | K5: 40408 | L5: 15391 | M5: 1897 | O5: 231768 | P5: 388480 | Q5: 10047 | R5: 116139 | S5: 54908 | T5: 37271 | U5: 23476 | V5: 40700
B6: 12180 | C6: 28850 | D6: 13800 | E6: 263637 | F6: 313319 | G6: 289878 | H6: 343588 | I6: 4263 | J6: 37713 | K6: 1091 | L6: 2337 | M6: 21733 | O6: 338433 | P6: 359984 | Q6: 36014 | R6: 173789 | S6: 4530 | T6: 76636 | U6: 26042 | V6: 3669
B7: 11823 | C7: 200156 | D7: 74335 | E7: 197995 | F7: 189445 | G7: 311846 | H7: 354496 | I7: 11738 | J7: 10207 | K7: 0 | L7: 70624 | M7: 34838 | O7: 181358 | P7: 321057 | Q7: 35801 | R7: 198452 | S7: 142859 | T7: 57786 | U7: 30605 | V7: 196549
B8: 32493 | C8: 5588 | D8: 38928 | E8: 11085 | F8: 330421 | G8: 323298 | H8: 471806 | I8: 34057 | J8: 7804 | K8: 251 | L8: 57924 | M8: 10608 | O8: 251994 | P8: 288305 | Q8: 20954 | R8: 10336 | S8: 39697 | T8: 76784 | U8: 7073 | V8: 729
B9: 9892 | C9: 10998 | D9: 51416 | E9: 180251 | F9: 101761 | G9: 397463 | H9: 465778 | I9: 28401 | J9: 3455 | K9: 13042 | L9: 21144 | M9: 31018 | O9: 290456 | P9: 358008 | Q9: 17500 | R9: 278257 | S9: 121121 | T9: 36031 | U9: 16399 | V9: 126900
B10: 30442 | C10: 8027 | D10: 18895 | E10: 237398 | F10: 306327 | G10: 346056 | H10: 431746 | I10: 13105 | J10: 20290 | K10: 36443 | L10: 7668 | M10: 23922 | O10: 271772 | P10: 302750 | Q10: 53666 | R10: 110035 | S10: 14356 | T10: 34152 | U10: 50141 | V10: 30029
B11: 30282 | C11: 8767 | D11: 39559 | E11: 172279 | F11: 368635 | G11: 292374 | H11: 423648 | I11: 27606 | J11: 22707 | K11: 10238 | L11: 6682 | M11: 22272 | O11: 238751 | P11: 377678 | Q11: 19197 | R11: 187887 | S11: 18506 | T11: 18820 | U11: 35233 | V11: 72340
B12: 21571 | C12: 9519 | D12: 7423 | E12: 280381 | F12: 195040 | G12: 349338 | H12: 359645 | I12: 12727 | K12: 26251 | L12: 18093 | M12: 0 | O12: 275166 | P12: 317767 | Q12: 33133 | R12: 214853 | S12: 24458 | T12: 184119 | U12: 23558 | V12: 26700
O13: 242292
O14: 255389
O15: 338695
O16: 305780
O17: 383153
O18: 207444
O19: 235598
O20: 248680
A22: =A4 -> Noms des groupes | B22: =B4 -> Solvent control | C22: =C4 -> EE2-33.8ng/L | D22: =D4 -> EE2-50.6ng/L | E22: =E4 -> EE2-76ng/L | F22: =F4 -> EE2-114ng/L | G22: =G4 -> EE2-170.9ng/L | H22: =H4 -> EE2-488ng/L | ... M22: =M4 -> Prochloraz-1.0mg/L | N22: Noms des groupes | O22: =O4 -> Testo -30µg/L | P22: =P4 -> Testo 30µg/L + EE2 -64ng/L | Q22: =Q4 -> Testo 30µg/L + FAD-10mg/L | R22: =R4 -> Prochloraz-0.063mg/L + Testostérone | S22: =S4 -> Prochloraz-0.13mg/L + Testostérone | T22: =T4 -> Prochloraz-0.25mg/L + Testostérone | U22: =U4 -> Prochloraz-0.5mg/L + Testostérone | V22: =V4 -> Prochloraz-1.0mg/L + Testostérone | ... AK22: =AK4 -> 0-00 + Testostérone
A23: mean | B23: =AVERAGE(B5:B20) -> 21941 | C23: =AVERAGE(C5:C20) -> 35686.875 | D23: =AVERAGE(D5:D20) -> 34108.375 | E23: =AVERAGE(E5:E20) -> 202613.5 | F23: =AVERAGE(F5:F20) -> 258484.38 | G23: =AVERAGE(G5:G20) -> 332309.38 | H23: =AVERAGE(H5:H20) -> 392082.12 | I23: =AVERAGE(I5:I20) -> 16487.125 | J23: =AVERAGE(J5:J20) -> 14948.143 | L23: =AVERAGE(L5:L20) -> 24982.875 | N23: mean | O23: =AVERAGE(O5:O20) -> 268545.56 | P23: =AVERAGE(P5:P20) -> 339253.62 | Q23: =AVERAGE(Q5:Q20) -> 28289 | R23: =AVERAGE(R5:R20) -> 161218.5 | S23: =AVERAGE(S5:S20) -> 52554.375 | T23: =AVERAGE(T5:T20) -> 65199.875 | U23: =AVERAGE(U5:U20) -> 26565.875 | V23: =AVERAGE(V5:V20) -> 62202 | ... AK23: =AVERAGE(AK5:AK20) -> #DIV/0!
A24: SD | B24: =STDEV(B5:B20) -> 9412.7539 | C24: =STDEV(C5:C20) -> 66842.135 | D24: =STDEV(D5:D20) -> 21902.348 | E24: =STDEV(E5:E20) -> 88456.382 | F24: =STDEV(F5:F20) -> 89424.644 | G24: =STDEV(G5:G20) -> 35601.687 | H24: =STDEV(H5:H20) -> 65940.663 | I24: =STDEV(I5:I20) -> 12210.396 | J24: =STDEV(J5:J20) -> 12705.067 | L24: =STDEV(L5:L20) -> 25269.982 | N24: SD | O24: =STDEV(O5:O20) -> 52314.836 | P24: =STDEV(P5:P20) -> 36649.328 | Q24: =STDEV(Q5:Q20) -> 13985.717 | R24: =STDEV(R5:R20) -> 81282.287 | S24: =STDEV(S5:S20) -> 51742.927 | T24: =STDEV(T5:T20) -> 52382.671 | U24: =STDEV(U5:U20) -> 12814.204 | V24: =STDEV(V5:V20) -> 67929.163 | ... AK24: =STDEV(AK5:AK20) -> #DIV/0!
B26: Non dopé | O26: avec testo
A27: Noms des groupes | B27: =B4 -> Solvent control | C27: =C4 -> EE2-33.8ng/L | D27: =D4 -> EE2-50.6ng/L | E27: =E4 -> EE2-76ng/L | F27: =F4 -> EE2-114ng/L | G27: =G4 -> EE2-170.9ng/L | H27: =H4 -> EE2-488ng/L | I27: =I4 -> Prochloraz-0.063mg/L | ... M27: =M4 -> Prochloraz-1.0mg/L | O27: =O4 -> Testo -30µg/L | P27: =P4 -> Testo 30µg/L + EE2 -64ng/L | Q27: =Q4 -> Testo 30µg/L + FAD-10mg/L | R27: =R4 -> Prochloraz-0.063mg/L + Testostérone | S27: =S4 -> Prochloraz-0.13mg/L + Testostérone | T27: =T4 -> Prochloraz-0.25mg/L + Testostérone | U27: =U4 -> Prochloraz-0.5mg/L + Testostérone | V27: =V4 -> Prochloraz-1.0mg/L + Testostérone | ... AK27: =AK4 -> 0-00 + Testostérone
A28: Données normalisées sur la moyenne du groupe "Testo" | B28: =IF(B5="","",(B5/$O$23)) -> 0.099964415 | C28: =IF(C5="","",(C5/$O$23)) -> 0.050605938 | D28: =IF(D5="","",(D5/$O$23)) -> 0.1061682 | E28: =IF(E5="","",(E5/$O$23)) -> 1.0347667 | F28: =IF(F5="","",(F5/$O$23)) -> 0.97907781 | G28: =IF(G5="","",(G5/$O$23)) -> 1.2966962 | H28: =IF(H5="","",(H5/$O$23)) -> 1.06481 | I28: =IF(I5="","",(I5/$O$23)) -> 0 | ... M28: =IF(M5="","",(M5/$O$23)) -> 0.0070639782 | O28: =IF(O5="","",(O5/$O$23)) -> 0.86304908 | P28: =IF(P5="","",(P5/$O$23)) -> 1.4466074 | Q28: =IF(Q5="","",(Q5/$O$23)) -> 0.037412646 | R28: =IF(R5="","",(R5/$O$23)) -> 0.4324741 | S28: =IF(S5="","",(S5/$O$23)) -> 0.20446437 | T28: =IF(T5="","",(T5/$O$23)) -> 0.13878837 | U28: =IF(U5="","",(U5/$O$23)) -> 0.087419058 | V28: =IF(V5="","",(V5/$O$23)) -> 0.15155715 | ... AK28: =IF(AK5="","",(AK5/$O$23))
B29: =IF(B6="","",(B6/$O$23)) -> 0.045355432 | C29: =IF(C6="","",(C6/$O$23)) -> 0.10743056 | D29: =IF(D6="","",(D6/$O$23)) -> 0.051387928 | E29: =IF(E6="","",(E6/$O$23)) -> 0.98172168 | F29: =IF(F6="","",(F6/$O$23)) -> 1.1667257 | G29: =IF(G6="","",(G6/$O$23)) -> 1.0794369 | H29: =IF(H6="","",(H6/$O$23)) -> 1.2794402 | I29: =IF(I6="","",(I6/$O$23)) -> 0.015874401 | ... M29: =IF(M6="","",(M6/$O$23)) -> 0.080928539 | O29: =IF(O6="","",(O6/$O$23)) -> 1.2602442 | P29: =IF(P6="","",(P6/$O$23)) -> 1.3404951 | Q29: =IF(Q6="","",(Q6/$O$23)) -> 0.1341076 | R29: =IF(R6="","",(R6/$O$23)) -> 0.64714903 | S29: =IF(S6="","",(S6/$O$23)) -> 0.016868646 | T29: =IF(T6="","",(T6/$O$23)) -> 0.28537429 | U29: =IF(U6="","",(U6/$O$23)) -> 0.096974233 | V29: =IF(V6="","",(V6/$O$23)) -> 0.013662486 | ... AK29: =IF(AK6="","",(AK6/$O$23))
B30: =IF(B7="","",(B7/$O$23)) -> 0.044026049 | C30: =IF(C7="","",(C7/$O$23)) -> 0.74533349 | D30: =IF(D7="","",(D7/$O$23)) -> 0.27680591 | E30: =IF(E7="","",(E7/$O$23)) -> 0.73728643 | F30: =IF(F7="","",(F7/$O$23)) -> 0.70544826 | G30: =IF(G7="","",(G7/$O$23)) -> 1.1612406 | H30: =IF(H7="","",(H7/$O$23)) -> 1.320059 | I30: =IF(I7="","",(I7/$O$23)) -> 0.043709529 | ... M30: =IF(M7="","",(M7/$O$23)) -> 0.12972845 | O30: =IF(O7="","",(O7/$O$23)) -> 0.67533419 | P30: =IF(P7="","",(P7/$O$23)) -> 1.1955401 | Q30: =IF(Q7="","",(Q7/$O$23)) -> 0.13331444 | R30: =IF(R7="","",(R7/$O$23)) -> 0.73898819 | S30: =IF(S7="","",(S7/$O$23)) -> 0.53197304 | T30: =IF(T7="","",(T7/$O$23)) -> 0.21518136 | U30: =IF(U7="","",(U7/$O$23)) -> 0.11396576 | V30: =IF(V7="","",(V7/$O$23)) -> 0.73190187 | ... AK30: =IF(AK7="","",(AK7/$O$23))
B31: =IF(B8="","",(B8/$O$23)) -> 0.12099623 | C31: =IF(C8="","",(C8/$O$23)) -> 0.020808387 | D31: =IF(D8="","",(D8/$O$23)) -> 0.14495864 | E31: =IF(E8="","",(E8/$O$23)) -> 0.041277912 | F31: =IF(F8="","",(F8/$O$23)) -> 1.2304095 | G31: =IF(G8="","",(G8/$O$23)) -> 1.2038851 | H31: =IF(H8="","",(H8/$O$23)) -> 1.7568937 | I31: =IF(I8="","",(I8/$O$23)) -> 0.12682019 | ... M31: =IF(M8="","",(M8/$O$23)) -> 0.039501677 | O31: =IF(O8="","",(O8/$O$23)) -> 0.93836591 | P31: =IF(P8="","",(P8/$O$23)) -> 1.0735795 | Q31: =IF(Q8="","",(Q8/$O$23)) -> 0.078027728 | R31: =IF(R8="","",(R8/$O$23)) -> 0.038488813 | S31: =IF(S8="","",(S8/$O$23)) -> 0.14782222 | T31: =IF(T8="","",(T8/$O$23)) -> 0.28592541 | U31: =IF(U8="","",(U8/$O$23)) -> 0.026338175 | V31: =IF(V8="","",(V8/$O$23)) -> 0.0027146231 | ... AK31: =IF(AK8="","",(AK8/$O$23))
B32: =IF(B9="","",(B9/$O$23)) -> 0.036835463 | C32: =IF(C9="","",(C9/$O$23)) -> 0.040953944 | D32: =IF(D9="","",(D9/$O$23)) -> 0.19146099 | E32: =IF(E9="","",(E9/$O$23)) -> 0.67121198 | F32: =IF(F9="","",(F9/$O$23)) -> 0.37893384 | G32: =IF(G9="","",(G9/$O$23)) -> 1.480058 | H32: =IF(H9="","",(H9/$O$23)) -> 1.7344468 | I32: =IF(I9="","",(I9/$O$23)) -> 0.10575859 | ... M32: =IF(M9="","",(M9/$O$23)) -> 0.11550368 | O32: =IF(O9="","",(O9/$O$23)) -> 1.0815893 | P32: =IF(P9="","",(P9/$O$23)) -> 1.3331369 | Q32: =IF(Q9="","",(Q9/$O$23)) -> 0.065165851 | R32: =IF(R9="","",(R9/$O$23)) -> 1.0361631 | S32: =IF(S9="","",(S9/$O$23)) -> 0.45102589 | T32: =IF(T9="","",(T9/$O$23)) -> 0.1341709 | U32: =IF(U9="","",(U9/$O$23)) -> 0.061065988 | V32: =IF(V9="","",(V9/$O$23)) -> 0.47254551 | ... AK32: =IF(AK9="","",(AK9/$O$23))
B33: =IF(B10="","",(B10/$O$23)) -> 0.11335879 | C33: =IF(C10="","",(C10/$O$23)) -> 0.029890645 | D33: =IF(D10="","",(D10/$O$23)) -> 0.0703605 | E33: =IF(E10="","",(E10/$O$23)) -> 0.88401386 | F33: =IF(F10="","",(F10/$O$23)) -> 1.1406891 | G33: =IF(G10="","",(G10/$O$23)) -> 1.2886305 | H33: =IF(H10="","",(H10/$O$23)) -> 1.6077197 | I33: =IF(I10="","",(I10/$O$23)) -> 0.048799913 | ... M33: =IF(M10="","",(M10/$O$23)) -> 0.089079856 | O33: =IF(O10="","",(O10/$O$23)) -> 1.0120145 | P33: =IF(P10="","",(P10/$O$23)) -> 1.1273692 | Q33: =IF(Q10="","",(Q10/$O$23)) -> 0.19983946 | R33: =IF(R10="","",(R10/$O$23)) -> 0.40974425 | S33: =IF(S10="","",(S10/$O$23)) -> 0.05345834 | T33: =IF(T10="","",(T10/$O$23)) -> 0.12717395 | U33: =IF(U10="","",(U10/$O$23)) -> 0.1867132 | V33: =IF(V10="","",(V10/$O$23)) -> 0.11182088 | ... AK33: =IF(AK10="","",(AK10/$O$23))
B34: =IF(B11="","",(B11/$O$23)) -> 0.11276299 | C34: =IF(C11="","",(C11/$O$23)) -> 0.032646229 | D34: =IF(D11="","",(D11/$O$23)) -> 0.14730834 | E34: =IF(E11="","",(E11/$O$23)) -> 0.64152615 | F34: =IF(F11="","",(F11/$O$23)) -> 1.3727093 | G34: =IF(G11="","",(G11/$O$23)) -> 1.0887315 | H34: =IF(H11="","",(H11/$O$23)) -> 1.5775647 | I34: =IF(I11="","",(I11/$O$23)) -> 0.1027982 | ... M34: =IF(M11="","",(M11/$O$23)) -> 0.082935647 | O34: =IF(O11="","",(O11/$O$23)) -> 0.88905211 | P34: =IF(P11="","",(P11/$O$23)) -> 1.4063833 | Q34: =IF(Q11="","",(Q11/$O$23)) -> 0.071485076 | R34: =IF(R11="","",(R11/$O$23)) -> 0.69964664 | S34: =IF(S11="","",(S11/$O$23)) -> 0.068911956 | T34: =IF(T11="","",(T11/$O$23)) -> 0.070081218 | U34: =IF(U11="","",(U11/$O$23)) -> 0.13119934 | V34: =IF(V11="","",(V11/$O$23)) -> 0.26937701 | ... AK34: =IF(AK11="","",(AK11/$O$23))
B35: =IF(B12="","",(B12/$O$23)) -> 0.080325289 | C35: =IF(C12="","",(C12/$O$23)) -> 0.035446499 | D35: =IF(D12="","",(D12/$O$23)) -> 0.027641492 | E35: =IF(E12="","",(E12/$O$23)) -> 1.0440724 | F35: =IF(F12="","",(F12/$O$23)) -> 0.72628271 | G35: =IF(G12="","",(G12/$O$23)) -> 1.3008519 | H35: =IF(H12="","",(H12/$O$23)) -> 1.3392327 | I35: =IF(I12="","",(I12/$O$23)) -> 0.04739233 | ... M35: =IF(M12="","",(M12/$O$23)) -> 0 | O35: =IF(O12="","",(O12/$O$23)) -> 1.0246529 | P35: =IF(P12="","",(P12/$O$23)) -> 1.183289 | Q35: =IF(Q12="","",(Q12/$O$23)) -> 0.12337944 | R35: =IF(R12="","",(R12/$O$23)) -> 0.80006163 | S35: =IF(S12="","",(S12/$O$23)) -> 0.091075793 | T35: =IF(T12="","",(T12/$O$23)) -> 0.6856155 | U35: =IF(U12="","",(U12/$O$23)) -> 0.087724406 | V35: =IF(V12="","",(V12/$O$23)) -> 0.099424469 | ... AK35: =IF(AK12="","",(AK12/$O$23))
B36: =IF(B13="","",(B13/$O$23)) | C36: =IF(C13="","",(C13/$O$23)) | D36: =IF(D13="","",(D13/$O$23)) | E36: =IF(E13="","",(E13/$O$23)) | F36: =IF(F13="","",(F13/$O$23)) | G36: =IF(G13="","",(G13/$O$23)) | H36: =IF(H13="","",(H13/$O$23)) | I36: =IF(I13="","",(I13/$O$23)) | ... M36: =IF(M13="","",(M13/$O$23)) | O36: =IF(O13="","",(O13/$O$23)) -> 0.90223796 | P36: =IF(P13="","",(P13/$O$23)) | Q36: =IF(Q13="","",(Q13/$O$23)) | R36: =IF(R13="","",(R13/$O$23)) | S36: =IF(S13="","",(S13/$O$23)) | T36: =IF(T13="","",(T13/$O$23)) | U36: =IF(U13="","",(U13/$O$23)) | V36: =IF(V13="","",(V13/$O$23)) | ... AK36: =IF(AK13="","",(AK13/$O$23))
B37: =IF(B14="","",(B14/$O$23)) | C37: =IF(C14="","",(C14/$O$23)) | D37: =IF(D14="","",(D14/$O$23)) | E37: =IF(E14="","",(E14/$O$23)) | F37: =IF(F14="","",(F14/$O$23)) | G37: =IF(G14="","",(G14/$O$23)) | H37: =IF(H14="","",(H14/$O$23)) | I37: =IF(I14="","",(I14/$O$23)) | ... M37: =IF(M14="","",(M14/$O$23)) | O37: =IF(O14="","",(O14/$O$23)) -> 0.95100808 | P37: =IF(P14="","",(P14/$O$23)) | Q37: =IF(Q14="","",(Q14/$O$23)) | R37: =IF(R14="","",(R14/$O$23)) | S37: =IF(S14="","",(S14/$O$23)) | T37: =IF(T14="","",(T14/$O$23)) | U37: =IF(U14="","",(U14/$O$23)) | V37: =IF(V14="","",(V14/$O$23)) | ... AK37: =IF(AK14="","",(AK14/$O$23))
B38: =IF(B15="","",(B15/$O$23)) | C38: =IF(C15="","",(C15/$O$23)) | D38: =IF(D15="","",(D15/$O$23)) | E38: =IF(E15="","",(E15/$O$23)) | F38: =IF(F15="","",(F15/$O$23)) | G38: =IF(G15="","",(G15/$O$23)) | H38: =IF(H15="","",(H15/$O$23)) | I38: =IF(I15="","",(I15/$O$23)) | ... M38: =IF(M15="","",(M15/$O$23)) | O38: =IF(O15="","",(O15/$O$23)) -> 1.2612199 | P38: =IF(P15="","",(P15/$O$23)) | Q38: =IF(Q15="","",(Q15/$O$23)) | R38: =IF(R15="","",(R15/$O$23)) | S38: =IF(S15="","",(S15/$O$23)) | T38: =IF(T15="","",(T15/$O$23)) | U38: =IF(U15="","",(U15/$O$23)) | V38: =IF(V15="","",(V15/$O$23)) | ... AK38: =IF(AK15="","",(AK15/$O$23))
B39: =IF(B16="","",(B16/$O$23)) | C39: =IF(C16="","",(C16/$O$23)) | D39: =IF(D16="","",(D16/$O$23)) | E39: =IF(E16="","",(E16/$O$23)) | F39: =IF(F16="","",(F16/$O$23)) | G39: =IF(G16="","",(G16/$O$23)) | H39: =IF(H16="","",(H16/$O$23)) | I39: =IF(I16="","",(I16/$O$23)) | ... M39: =IF(M16="","",(M16/$O$23)) | O39: =IF(O16="","",(O16/$O$23)) -> 1.1386522 | P39: =IF(P16="","",(P16/$O$23)) | Q39: =IF(Q16="","",(Q16/$O$23)) | R39: =IF(R16="","",(R16/$O$23)) | S39: =IF(S16="","",(S16/$O$23)) | T39: =IF(T16="","",(T16/$O$23)) | U39: =IF(U16="","",(U16/$O$23)) | V39: =IF(V16="","",(V16/$O$23)) | ... AK39: =IF(AK16="","",(AK16/$O$23))
B40: =IF(B17="","",(B17/$O$23)) | C40: =IF(C17="","",(C17/$O$23)) | D40: =IF(D17="","",(D17/$O$23)) | E40: =IF(E17="","",(E17/$O$23)) | F40: =IF(F17="","",(F17/$O$23)) | G40: =IF(G17="","",(G17/$O$23)) | H40: =IF(H17="","",(H17/$O$23)) | I40: =IF(I17="","",(I17/$O$23)) | ... M40: =IF(M17="","",(M17/$O$23)) | O40: =IF(O17="","",(O17/$O$23)) -> 1.4267709 | P40: =IF(P17="","",(P17/$O$23)) | Q40: =IF(Q17="","",(Q17/$O$23)) | R40: =IF(R17="","",(R17/$O$23)) | S40: =IF(S17="","",(S17/$O$23)) | T40: =IF(T17="","",(T17/$O$23)) | U40: =IF(U17="","",(U17/$O$23)) | V40: =IF(V17="","",(V17/$O$23)) | ... AK40: =IF(AK17="","",(AK17/$O$23))
... B43: =IF(B20="","",(B20/$O$23)) | C43: =IF(C20="","",(C20/$O$23)) | D43: =IF(D20="","",(D20/$O$23)) | E43: =IF(E20="","",(E20/$O$23)) | F43: =IF(F20="","",(F20/$O$23)) | G43: =IF(G20="","",(G20/$O$23)) | H43: =IF(H20="","",(H20/$O$23)) | I43: =IF(I20="","",(I20/$O$23)) | ... M43: =IF(M20="","",(M20/$O$23)) | O43: =IF(O20="","",(O20/$O$23)) -> 0.92602536 | P43: =IF(P20="","",(P20/$O$23)) | Q43: =IF(Q20="","",(Q20/$O$23)) | R43: =IF(R20="","",(R20/$O$23)) | S43: =IF(S20="","",(S20/$O$23)) | T43: =IF(T20="","",(T20/$O$23)) | U43: =IF(U20="","",(U20/$O$23)) | V43: =IF(V20="","",(V20/$O$23)) | ... AK43: =IF(AK20="","",(AK20/$O$23))
A45: =A4 -> Noms des groupes | B45: =B4 -> Solvent control | C45: =C4 -> EE2-33.8ng/L | D45: =D4 -> EE2-50.6ng/L | E45: =E4 -> EE2-76ng/L | F45: =F4 -> EE2-114ng/L | G45: =G4 -> EE2-170.9ng/L | H45: =H4 -> EE2-488ng/L | ... M45: =M4 -> Prochloraz-1.0mg/L | O45: =O4 -> Testo -30µg/L | P45: =P4 -> Testo 30µg/L + EE2 -64ng/L | Q45: =Q4 -> Testo 30µg/L + FAD-10mg/L | R45: =R4 -> Prochloraz-0.063mg/L + Testostérone | S45: =S4 -> Prochloraz-0.13mg/L + Testostérone | T45: =T4 -> Prochloraz-0.25mg/L + Testostérone | U45: =U4 -> Prochloraz-0.5mg/L + Testostérone | V45: =V4 -> Prochloraz-1.0mg/L + Testostérone | ... AK45: =AK4 -> 0-00 + Testostérone
A46: mean | B46: =AVERAGE(B28:B43) -> 0.081703082 | C46: =AVERAGE(C28:C43) -> 0.13288946 | D46: =AVERAGE(D28:D43) -> 0.1270115 | E46: =AVERAGE(E28:E43) -> 0.75448463 | F46: =AVERAGE(F28:F43) -> 0.96253452 | G46: =AVERAGE(G28:G43) -> 1.2374413 | H46: =AVERAGE(H28:H43) -> 1.4600209 | I46: =AVERAGE(I28:I43) -> 0.061394144 | ... M46: =AVERAGE(M28:M43) -> 0.068092728 | N46: mean | O46: =AVERAGE(O28:O43) -> 1 | P46: =AVERAGE(P28:P43) -> 1.2633001 | Q46: =AVERAGE(Q28:Q43) -> 0.10534153 | R46: =AVERAGE(R28:R43) -> 0.60033947 | S46: =AVERAGE(S28:S43) -> 0.19570003 | T46: =AVERAGE(T28:T43) -> 0.24278887 | U46: =AVERAGE(U28:U43) -> 0.098925019 | V46: =AVERAGE(V28:V43) -> 0.2316255 | ... AK46: =AVERAGE(AK28:AK43) -> #DIV/0!
...

Sheet R3
A1: 6. Expérimentateur 2 : copier et coller les valeurs des intensités totales de fluorescences obtenues dans le fichier raw data lors du traitement des images. Ne pas supprimer les colonnes correspondant aux concentrations non lues.
A3: R3 | B3: Non dopé | O3: avec testo
A4: Noms des groupes | B4: ='Front page'!A7 -> Solvent control | C4: ='Front page'!A8 -> EE2-33.8ng/L | D4: ='Front page'!A9 -> EE2-50.6ng/L | E4: ='Front page'!A10 -> EE2-76ng/L | F4: ='Front page'!A11 -> EE2-114ng/L | G4: ='Front page'!A12 -> EE2-170.9ng/L | H4: ='Front page'!A13 -> EE2-488ng/L | I4: ='Front page'!A14 -> Prochloraz-0.063mg/L | J4: ='Front page'!A15 -> Prochloraz-0.13mg/L | K4: ='Front page'!A16 -> Prochloraz-0.25mg/L | L4: ='Front page'!A17 -> Prochloraz-0.5mg/L | M4: ='Front page'!A18 -> Prochloraz-1.0mg/L | O4: ='Front page'!A35 -> Testo -30µg/L | P4: ='Front page'!A36 -> Testo 30µg/L + EE2 -64ng/L | Q4: ='Front page'!A37 -> Testo 30µg/L + FAD-10mg/L | R4: ='Front page'!A38 -> Prochloraz-0.063mg/L + Testostérone | S4: ='Front page'!A39 -> Prochloraz-0.13mg/L + Testostérone | T4: ='Front page'!A40 -> Prochloraz-0.25mg/L + Testostérone | U4: ='Front page'!A41 -> Prochloraz-0.5mg/L + Testostérone | V4: ='Front page'!A42 -> Prochloraz-1.0mg/L + Testostérone | W4: ='Front page'!A43 -> 0-00 + Testostérone | X4: ='Front page'!A44 -> 0-00 + Testostérone | Y4: ='Front page'!A45 -> 0-00 + Testostérone | Z4: ='Front page'!A46 -> 0-00 + Testostérone | AA4: ='Front page'!A47 -> 0-00 + Testostérone | AB4: ='Front page'!A48 -> 0-00 + Testostérone | AC4: ='Front page'!A49 -> 0-00 + Testostérone | AD4: ='Front page'!A50 -> 0-00 + Testostérone | AE4: ='Front page'!A51 -> 0-00 + Testostérone | AF4: ='Front page'!A52 -> 0-00 + Testostérone | AG4: ='Front page'!A53 -> 0-00 + Testostérone | AH4: ='Front page'!A54 -> 0-00 + Testostérone | AI4: ='Front page'!A55 -> 0-00 + Testostérone | AJ4: ='Front page'!A56 -> 0-00 + Testostérone | AK4: ='Front page'!A57 -> 0-00 + Testostérone
A5: Données brutes | B5: 8996 | D5: 1902 | E5: 12968 | F5: 173295 | G5: 2906 | H5: 253804 | I5: 2426 | J5: 1840 | K5: 82 | L5: 1816 | M5: 0 | O5: 203055 | P5: 111683 | Q5: 0 | R5: 14801 | S5: 11802 | T5: 578 | U5: 0 | V5: 40136
B6: 5484 | D6: 1338 | E6: 0 | F6: 1508 | G6: 384499 | H6: 282945 | I6: 0 | J6: 1739 | K6: 335 | L6: 2764 | M6: 3553 | O6: 144189 | P6: 256201 | Q6: 99735 | R6: 40980 | S6: 245 | T6: 21662 | U6: 1833 | V6: 490
B7: 422 | D7: 242 | E7: 30668 | F7: 169276 | G7: 243198 | H7: 223912 | I7: 4381 | J7: 1171 | K7: 9141 | L7: 0 | M7: 0 | O7: 221053 | P7: 276536 | Q7: 839 | R7: 56078 | S7: 30588 | T7: 566 | U7: 562 | V7: 4909
B8: 734 | D8: 8791 | E8: 1473 | F8: 273980 | G8: 251816 | H8: 402101 | I8: 920 | J8: 253 | K8: 5814 | L8: 0 | M8: 4543 | O8: 162948 | P8: 249176 | Q8: 322 | R8: 27783 | S8: 6571 | T8: 19775 | U8: 12710 | V8: 0
B9: 9934 | D9: 814 | E9: 0 | F9: 143728 | G9: 60661 | H9: 319761 | I9: 8673 | J9: 2328 | K9: 487 | L9: 1645 | M9: 3758 | O9: 178232 | P9: 240916 | Q9: 0 | R9: 131607 | S9: 168322 | T9: 72554 | U9: 3176 | V9: 18033
B10: 2025 | D10: 164 | E10: 15240 | F10: 31364 | G10: 182330 | H10: 168932 | I10: 1429 | J10: 4418 | K10: 335 | L10: 9212 | M10: 0 | O10: 78581 | P10: 197655 | Q10: 18038 | R10: 24251 | S10: 56968 | T10: 0 | U10: 326 | V10: 12515
B11: 5565 | D11: 11287 | E11: 247232 | F11: 150063 | G11: 139396 | H11: 400259 | I11: 3298 | J11: 80 | K11: 569 | L11: 81 | M11: 15097 | O11: 69173 | P11: 214172 | Q11: 0 | R11: 54914 | S11: 13540 | T11: 59761 | U11: 9194 | V11: 4851
B12: 247 | D12: 15995 | E12: 73568 | F12: 206765 | G12: 176759 | H12: 202632 | I12: 832 | K12: 5207 | L12: 0 | M12: 7191 | O12: 119524 | P12: 233263 | Q12: 2618 | R12: 150692 | S12: 22153 | T12: 26771 | U12: 1660 | V12: 0
O13: 239567
O14: 249233
O15: 108959
O16: 176288
O17: 238737
O18: 176305
O19: 157188
O20: 220295
A22: =A4 -> Noms des groupes | B22: =B4 -> Solvent control | C22: =C4 -> EE2-33.8ng/L | D22: =D4 -> EE2-50.6ng/L | E22: =E4 -> EE2-76ng/L | F22: =F4 -> EE2-114ng/L | G22: =G4 -> EE2-170.9ng/L | H22: =H4 -> EE2-488ng/L | ... M22: =M4 -> Prochloraz-1.0mg/L | N22: Noms des groupes | O22: =O4 -> Testo -30µg/L | P22: =P4 -> Testo 30µg/L + EE2 -64ng/L | Q22: =Q4 -> Testo 30µg/L + FAD-10mg/L | R22: =R4 -> Prochloraz-0.063mg/L + Testostérone | S22: =S4 -> Prochloraz-0.13mg/L + Testostérone | T22: =T4 -> Prochloraz-0.25mg/L + Testostérone | U22: =U4 -> Prochloraz-0.5mg/L + Testostérone | V22: =V4 -> Prochloraz-1.0mg/L + Testostérone | ... AK22: =AK4 -> 0-00 + Testostérone
A23: mean | B23: =AVERAGE(B5:B20) -> 4175.875 | C23: =AVERAGE(C5:C20) -> #DIV/0! | D23: =AVERAGE(D5:D20) -> 5066.625 | E23: =AVERAGE(E5:E20) -> 47643.625 | F23: =AVERAGE(F5:F20) -> 143747.38 | G23: =AVERAGE(G5:G20) -> 180195.62 | H23: =AVERAGE(H5:H20) -> 281793.25 | I23: =AVERAGE(I5:I20) -> 2744.875 | ... M23: =AVERAGE(M5:M20) -> 4267.75 | N23: mean | O23: =AVERAGE(O5:O20) -> 171457.94 | P23: =AVERAGE(P5:P20) -> 222450.25 | Q23: =AVERAGE(Q5:Q20) -> 15194 | R23: =AVERAGE(R5:R20) -> 62638.25 | S23: =AVERAGE(S5:S20) -> 38773.625 | T23: =AVERAGE(T5:T20) -> 25208.375 | U23: =AVERAGE(U5:U20) -> 3682.625 | V23: =AVERAGE(V5:V20) -> 10116.75 | ... AK23: =AVERAGE(AK5:AK20) -> #DIV/0!
A24: SD | B24: =STDEV(B5:B20) -> 3891.949 | C24: =STDEV(C5:C20) -> #DIV/0! | D24: =STDEV(D5:D20) -> 6109.8102 | E24: =STDEV(E5:E20) -> 84278.209 | F24: =STDEV(F5:F20) -> 88928.929 | G24: =STDEV(G5:G20) -> 118466.25 | H24: =STDEV(H5:H20) -> 87086.794 | I24: =STDEV(I5:I20) -> 2789.8368 | ... M24: =STDEV(M5:M20) -> 5089.2827 | N24: SD | O24: =STDEV(O5:O20) -> 56486.766 | P24: =STDEV(P5:P20) -> 50975.154 | Q24: =STDEV(Q5:Q20) -> 34709.488 | R24: =STDEV(R5:R20) -> 50792.018 | S24: =STDEV(S5:S20) -> 55217.408 | T24: =STDEV(T5:T20) -> 27592.433 | U24: =STDEV(U5:U20) -> 4693.5291 | V24: =STDEV(V5:V20) -> 13741.461 | ... AK24: =STDEV(AK5:AK20) -> #DIV/0!
B26: Non dopé | O26: avec testo
A27: Noms des groupes | B27: =B4 -> Solvent control | C27: =C4 -> EE2-33.8ng/L | D27: =D4 -> EE2-50.6ng/L | E27: =E4 -> EE2-76ng/L | F27: =F4 -> EE2-114ng/L | G27: =G4 -> EE2-170.9ng/L | H27: =H4 -> EE2-488ng/L | I27: =I4 -> Prochloraz-0.063mg/L | ... M27: =M4 -> Prochloraz-1.0mg/L | O27: =O4 -> Testo -30µg/L | P27: =P4 -> Testo 30µg/L + EE2 -64ng/L | Q27: =Q4 -> Testo 30µg/L + FAD-10mg/L | R27: =R4 -> Prochloraz-0.063mg/L + Testostérone | S27: =S4 -> Prochloraz-0.13mg/L + Testostérone | T27: =T4 -> Prochloraz-0.25mg/L + Testostérone | U27: =U4 -> Prochloraz-0.5mg/L + Testostérone | V27: =V4 -> Prochloraz-1.0mg/L + Testostérone | ... AK27: =AK4 -> 0-00 + Testostérone
