Workbook

Sheet Front page
A2: R1 | B2: Experiment number : | C2: saccharin_01 | E2: Date performed : 23-09-2021
A3: R2 | B3: Experiment number : | C3: saccharin_02 | E3: Date performed : 30-09-2021
A4: R3 | B4: Experiment number : | C4: saccharin_03 | E4: Date performed : 07-10-2021
A6: Do not fill in | B6: Do not fill in2 | C6: Concentration | D6: Units | E6: Chemical name | F6: Do not fill in3
A7: =IF(ISBLANK(liste_groupe[[#This Row],[Do not fill in2]])," ",IF(ISBLANK(liste_groupe[[#This Row],[Units]]),CONCATENATE(liste_groupe[[#This Row],[Chemical name]],liste_groupe[[#This Row],[Do not fill in3]]),CONCATENATE(liste_groupe[[#This Row],[Chemical name]],"-",liste_groupe[[#This Row],[Concentration]],liste_groupe[[#This Row],[Units]],liste_groupe[[#This Row],[Do not fill in3]]))) -> Solvent control | B7: Control | E7: Solvent control
A8: =IF(ISBLANK(liste_groupe[[#This Row],[Do not fill in2]])," ",IF(ISBLANK(liste_groupe[[#This Row],[Units]]),CONCATENATE(liste_groupe[[#This Row],[Chemical name]],liste_groupe[[#This Row],[Do not fill in3]]),CONCATENATE(liste_groupe[[#This Row],[Chemical name]],"-",liste_groupe[[#This Row],[Concentration]],liste_groupe[[#This Row],[Units]],liste_groupe[[#This Row],[Do not fill in3]]))) -> EE2-33.8ng/L | B8: Control | C8: 33.8 | D8: ng/L | E8: EE2
A9: =IF(ISBLANK(liste_groupe[[#This Row],[Do not fill in2]])," ",IF(ISBLANK(liste_groupe[[#This Row],[Units]]),CONCATENATE(liste_groupe[[#This Row],[Chemical name]],liste_groupe[[#This Row],[Do not fill in3]]),CONCATENATE(liste_groupe[[#This Row],[Chemical name]],"-",liste_groupe[[#This Row],[Concentration]],liste_groupe[[#This Row],[Units]],liste_groupe[[#This Row],[Do not fill in3]]))) -> EE2-50.6ng/L | B9: Control | C9: 50.6 | D9: ng/L | E9: EE2
A10: =IF(ISBLANK(liste_groupe[[#This Row],[Do not fill in2]])," ",IF(ISBLANK(liste_groupe[[#This Row],[Units]]),CONCATENATE(liste_groupe[[#This Row],[Chemical name]],liste_groupe[[#This Row],[Do not fill in3]]),CONCATENATE(liste_groupe[[#This Row],[Chemical name]],"-",liste_groupe[[#This Row],[Concentration]],liste_groupe[[#This Row],[Units]],liste_groupe[[#This Row],[Do not fill in3]]))) -> EE2-76ng/L | B10: Control | C10: 76 | D10: ng/L | E10: EE2
A11: =IF(ISBLANK(liste_groupe[[#This Row],[Do not fill in2]])," ",IF(ISBLANK(liste_groupe[[#This Row],[Units]]),CONCATENATE(liste_groupe[[#This Row],[Chemical name]],liste_groupe[[#This Row],[Do not fill in3]]),CONCATENATE(liste_groupe[[#This Row],[Chemical name]],"-",liste_groupe[[#This Row],[Concentration]],liste_groupe[[#This Row],[Units]],liste_groupe[[#This Row],[Do not fill in3]]))) -> EE2-114ng/L | B11: Control | C11: 114 | D11: ng/L | E11: EE2
A12: =IF(ISBLANK(liste_groupe[[#This Row],[Do not fill in2]])," ",IF(ISBLANK(liste_groupe[[#This Row],[Units]]),CONCATENATE(liste_groupe[[#This Row],[Chemical name]],liste_groupe[[#This Row],[Do not fill in3]]),CONCATENATE(liste_groupe[[#This Row],[Chemical name]],"-",liste_groupe[[#This Row],[Concentration]],liste_groupe[[#This Row],[Units]],liste_groupe[[#This Row],[Do not fill in3]]))) -> EE2-170.9ng/L | B12: Control | C12: 170.9 | D12: ng/L | E12: EE2
A13: =IF(ISBLANK(liste_groupe[[#This Row],[Do not fill in2]])," ",IF(ISBLANK(liste_groupe[[#This Row],[Units]]),CONCATENATE(liste_groupe[[#This Row],[Chemical name]],liste_groupe[[#This Row],[Do not fill in3]]),CONCATENATE(liste_groupe[[#This Row],[Chemical name]],"-",liste_groupe[[#This Row],[Concentration]],liste_groupe[[#This Row],[Units]],liste_groupe[[#This Row],[Do not fill in3]]))) -> EE2-488ng/L | B13: Control | C13: 488 | D13: ng/L | E13: EE2
A14: =IF(ISBLANK(liste_groupe[[#This Row],[Do not fill in2]])," ",IF(ISBLANK(liste_groupe[[#This Row],[Units]]),CONCATENATE(liste_groupe[[#This Row],[Chemical name]],liste_groupe[[#This Row],[Do not fill in3]]),CONCATENATE(liste_groupe[[#This Row],[Chemical name]],"-",liste_groupe[[#This Row],[Concentration]],liste_groupe[[#This Row],[Units]],liste_groupe[[#This Row],[Do not fill in3]]))) -> saccharin-0.01mg/L | B14: test chemical | C14: 0.01 | D14: mg/L | E14: saccharin
A15: =IF(ISBLANK(liste_groupe[[#This Row],[Do not fill in2]])," ",IF(ISBLANK(liste_groupe[[#This Row],[Units]]),CONCATENATE(liste_groupe[[#This Row],[Chemical name]],liste_groupe[[#This Row],[Do not fill in3]]),CONCATENATE(liste_groupe[[#This Row],[Chemical name]],"-",liste_groupe[[#This Row],[Concentration]],liste_groupe[[#This Row],[Units]],liste_groupe[[#This Row],[Do not fill in3]]))) -> saccharin-0.1mg/L | B15: test chemical | C15: 0.1 | D15: mg/L | E15: saccharin
A16: =IF(ISBLANK(liste_groupe[[#This Row],[Do not fill in2]])," ",IF(ISBLANK(liste_groupe[[#This Row],[Units]]),CONCATENATE(liste_groupe[[#This Row],[Chemical name]],liste_groupe[[#This Row],[Do not fill in3]]),CONCATENATE(liste_groupe[[#This Row],[Chemical name]],"-",liste_groupe[[#This Row],[Concentration]],liste_groupe[[#This Row],[Units]],liste_groupe[[#This Row],[Do not fill in3]]))) -> saccharin-1mg/L | B16: test chemical | C16: 1 | D16: mg/L | E16: saccharin
A17: =IF(ISBLANK(liste_groupe[[#This Row],[Do not fill in2]])," ",IF(ISBLANK(liste_groupe[[#This Row],[Units]]),CONCATENATE(liste_groupe[[#This Row],[Chemical name]],liste_groupe[[#This Row],[Do not fill in3]]),CONCATENATE(liste_groupe[[#This Row],[Chemical name]],"-",liste_groupe[[#This Row],[Concentration]],liste_groupe[[#This Row],[Units]],liste_groupe[[#This Row],[Do not fill in3]]))) -> saccharin-10mg/L | B17: test chemical | C17: 10 | D17: mg/L | E17: saccharin
A18: =IF(ISBLANK(liste_groupe[[#This Row],[Do not fill in2]])," ",IF(ISBLANK(liste_groupe[[#This Row],[Units]]),CONCATENATE(liste_groupe[[#This Row],[Chemical name]],liste_groupe[[#This Row],[Do not fill in3]]),CONCATENATE(liste_groupe[[#This Row],[Chemical name]],"-",liste_groupe[[#This Row],[Concentration]],liste_groupe[[#This Row],[Units]],liste_groupe[[#This Row],[Do not fill in3]]))) -> saccharin-100mg/L | B18: test chemical | C18: 100 | D18: mg/L | E18: saccharin
A19: =IF(ISBLANK(liste_groupe[[#This Row],[Do not fill in2]])," ",IF(ISBLANK(liste_groupe[[#This Row],[Units]]),CONCATENATE(liste_groupe[[#This Row],[Chemical name]],liste_groupe[[#This Row],[Do not fill in3]]),CONCATENATE(liste_groupe[[#This Row],[Chemical name]],"-",liste_groupe[[#This Row],[Concentration]],liste_groupe[[#This Row],[Units]],liste_groupe[[#This Row],[Do not fill in3]]))) | B19: test chemical
A20: =IF(ISBLANK(liste_groupe[[#This Row],[Do not fill in2]])," ",IF(ISBLANK(liste_groupe[[#This Row],[Units]]),CONCATENATE(liste_groupe[[#This Row],[Chemical name]],liste_groupe[[#This Row],[Do not fill in3]]),CONCATENATE(liste_groupe[[#This Row],[Chemical name]],"-",liste_groupe[[#This Row],[Concentration]],liste_groupe[[#This Row],[Units]],liste_groupe[[#This Row],[Do not fill in3]]))) | B20: test chemical
A21: =IF(ISBLANK(liste_groupe[[#This Row],[Do not fill in2]])," ",IF(ISBLANK(liste_groupe[[#This Row],[Units]]),CONCATENATE(liste_groupe[[#This Row],[Chemical name]],liste_groupe[[#This Row],[Do not fill in3]]),CONCATENATE(liste_groupe[[#This Row],[Chemical name]],"-",liste_groupe[[#This Row],[Concentration]],liste_groupe[[#This Row],[Units]],liste_groupe[[#This Row],[Do not fill in3]]))) | B21: test chemical
A22: =IF(ISBLANK(liste_groupe[[#This Row],[Do not fill in2]])," ",IF(ISBLANK(liste_groupe[[#This Row],[Units]]),CONCATENATE(liste_groupe[[#This Row],[Chemical name]],liste_groupe[[#This Row],[Do not fill in3]]),CONCATENATE(liste_groupe[[#This Row],[Chemical name]],"-",liste_groupe[[#This Row],[Concentration]],liste_groupe[[#This Row],[Units]],liste_groupe[[#This Row],[Do not fill in3]]))) | B22: test chemical
A23: =IF(ISBLANK(liste_groupe[[#This Row],[Do not fill in2]])," ",IF(ISBLANK(liste_groupe[[#This Row],[Units]]),CONCATENATE(liste_groupe[[#This Row],[Chemical name]],liste_groupe[[#This Row],[Do not fill in3]]),CONCATENATE(liste_groupe[[#This Row],[Chemical name]],"-",liste_groupe[[#This Row],[Concentration]],liste_groupe[[#This Row],[Units]],liste_groupe[[#This Row],[Do not fill in3]]))) | B23: test chemical
A24: =IF(ISBLANK(liste_groupe[[#This Row],[Do not fill in2]])," ",IF(ISBLANK(liste_groupe[[#This Row],[Units]]),CONCATENATE(liste_groupe[[#This Row],[Chemical name]],liste_groupe[[#This Row],[Do not fill in3]]),CONCATENATE(liste_groupe[[#This Row],[Chemical name]],"-",liste_groupe[[#This Row],[Concentration]],liste_groupe[[#This Row],[Units]],liste_groupe[[#This Row],[Do not fill in3]]))) | B24: test chemical
A25: =IF(ISBLANK(liste_groupe[[#This Row],[Do not fill in2]])," ",IF(ISBLANK(liste_groupe[[#This Row],[Units]]),CONCATENATE(liste_groupe[[#This Row],[Chemical name]],liste_groupe[[#This Row],[Do not fill in3]]),CONCATENATE(liste_groupe[[#This Row],[Chemical name]],"-",liste_groupe[[#This Row],[Concentration]],liste_groupe[[#This Row],[Units]],liste_groupe[[#This Row],[Do not fill in3]]))) | B25: test chemical
A26: =IF(ISBLANK(liste_groupe[[#This Row],[Do not fill in2]])," ",IF(ISBLANK(liste_groupe[[#This Row],[Units]]),CONCATENATE(liste_groupe[[#This Row],[Chemical name]],liste_groupe[[#This Row],[Do not fill in3]]),CONCATENATE(liste_groupe[[#This Row],[Chemical name]],"-",liste_groupe[[#This Row],[Concentration]],liste_groupe[[#This Row],[Units]],liste_groupe[[#This Row],[Do not fill in3]]))) | B26: test chemical
A27: =IF(ISBLANK(liste_groupe[[#This Row],[Do not fill in2]])," ",IF(ISBLANK(liste_groupe[[#This Row],[Units]]),CONCATENATE(liste_groupe[[#This Row],[Chemical name]],liste_groupe[[#This Row],[Do not fill in3]]),CONCATENATE(liste_groupe[[#This Row],[Chemical name]],"-",liste_groupe[[#This Row],[Concentration]],liste_groupe[[#This Row],[Units]],liste_groupe[[#This Row],[Do not fill in3]]))) | B27: test chemical
A28: =IF(ISBLANK(liste_groupe[[#This Row],[Do not fill in2]])," ",IF(ISBLANK(liste_groupe[[#This Row],[Units]]),CONCATENATE(liste_groupe[[#This Row],[Chemical name]],liste_groupe[[#This Row],[Do not fill in3]]),CONCATENATE(liste_groupe[[#This Row],[Chemical name]],"-",liste_groupe[[#This Row],[Concentration]],liste_groupe[[#This Row],[Units]],liste_groupe[[#This Row],[Do not fill in3]]))) | B28: test chemical
A29: =IF(ISBLANK(liste_groupe[[#This Row],[Do not fill in2]])," ",IF(ISBLANK(liste_groupe[[#This Row],[Units]]),CONCATENATE(liste_groupe[[#This Row],[Chemical name]],liste_groupe[[#This Row],[Do not fill in3]]),CONCATENATE(liste_groupe[[#This Row],[Chemical name]],"-",liste_groupe[[#This Row],[Concentration]],liste_groupe[[#This Row],[Units]],liste_groupe[[#This Row],[Do not fill in3]]))) | B29: test chemical
A30: =IF(ISBLANK(liste_groupe[[#This Row],[Do not fill in2]])," ",IF(ISBLANK(liste_groupe[[#This Row],[Units]]),CONCATENATE(liste_groupe[[#This Row],[Chemical name]],liste_groupe[[#This Row],[Do not fill in3]]),CONCATENATE(liste_groupe[[#This Row],[Chemical name]],"-",liste_groupe[[#This Row],[Concentration]],liste_groupe[[#This Row],[Units]],liste_groupe[[#This Row],[Do not fill in3]]))) | B30: test chemical
... A34: =IF(ISBLANK(liste_groupe[[#This Row],[Do not fill in2]])," ",IF(ISBLANK(liste_groupe[[#This Row],[Units]]),CONCATENATE(liste_groupe[[#This Row],[Chemical name]],liste_groupe[[#This Row],[Do not fill in3]]),CONCATENATE(liste_groupe[[#This Row],[Chemical name]],"-",liste_groupe[[#This Row],[Concentration]],liste_groupe[[#This Row],[Units]],liste_groupe[[#This Row],[Do not fill in3]]))) | B34: test chemical
A35: =IF(ISBLANK(liste_groupe[[#This Row],[Do not fill in2]])," ",IF(ISBLANK(liste_groupe[[#This Row],[Units]]),CONCATENATE(liste_groupe[[#This Row],[Chemical name]],liste_groupe[[#This Row],[Do not fill in3]]),CONCATENATE(liste_groupe[[#This Row],[Chemical name]],"-",liste_groupe[[#This Row],[Concentration]],liste_groupe[[#This Row],[Units]],liste_groupe[[#This Row],[Do not fill in3]]))) -> Testo -30µg/L | B35: Control | C35: 30 | D35: µg/L | E35: Testo
A36: =IF(ISBLANK(liste_groupe[[#This Row],[Do not fill in2]])," ",IF(ISBLANK(liste_groupe[[#This Row],[Units]]),CONCATENATE(liste_groupe[[#This Row],[Chemical name]],liste_groupe[[#This Row],[Do not fill in3]]),CONCATENATE(liste_groupe[[#This Row],[Chemical name]],"-",liste_groupe[[#This Row],[Concentration]],liste_groupe[[#This Row],[Units]],liste_groupe[[#This Row],[Do not fill in3]]))) -> Testo 30µg/L + EE2 -64ng/L | B36: Control | C36: 64 | D36: ng/L | E36: Testo 30µg/L + EE2
A37: =IF(ISBLANK(liste_groupe[[#This Row],[Do not fill in2]])," ",IF(ISBLANK(liste_groupe[[#This Row],[Units]]),CONCATENATE(liste_groupe[[#This Row],[Chemical name]],liste_groupe[[#This Row],[Do not fill in3]]),CONCATENATE(liste_groupe[[#This Row],[Chemical name]],"-",liste_groupe[[#This Row],[Concentration]],liste_groupe[[#This Row],[Units]],liste_groupe[[#This Row],[Do not fill in3]]))) -> Testo 30µg/L + FAD-10mg/L | B37: Control | C37: 10 | D37: mg/L | E37: Testo 30µg/L + FAD
A38: =IF(ISBLANK(liste_groupe[[#This Row],[Do not fill in2]])," ",IF(ISBLANK(liste_groupe[[#This Row],[Units]]),CONCATENATE(liste_groupe[[#This Row],[Chemical name]],liste_groupe[[#This Row],[Do not fill in3]]),CONCATENATE(liste_groupe[[#This Row],[Chemical name]],"-",liste_groupe[[#This Row],[Concentration]],liste_groupe[[#This Row],[Units]],liste_groupe[[#This Row],[Do not fill in3]]))) -> saccharin-0.01mg/L + Testostérone | B38: =B14 -> test chemical | C38: =C14 -> 0.01 | D38: =D14 -> mg/L | E38: =E14 -> saccharin | F38: + Testostérone
A39: =IF(ISBLANK(liste_groupe[[#This Row],[Do not fill in2]])," ",IF(ISBLANK(liste_groupe[[#This Row],[Units]]),CONCATENATE(liste_groupe[[#This Row],[Chemical name]],liste_groupe[[#This Row],[Do not fill in3]]),CONCATENATE(liste_groupe[[#This Row],[Chemical name]],"-",liste_groupe[[#This Row],[Concentration]],liste_groupe[[#This Row],[Units]],liste_groupe[[#This Row],[Do not fill in3]]))) -> saccharin-0.1mg/L + Testostérone | B39: =B15 -> test chemical | C39: =C15 -> 0.1 | D39: =D15 -> mg/L | E39: =E15 -> saccharin | F39: + Testostérone
A40: =IF(ISBLANK(liste_groupe[[#This Row],[Do not fill in2]])," ",IF(ISBLANK(liste_groupe[[#This Row],[Units]]),CONCATENATE(liste_groupe[[#This Row],[Chemical name]],liste_groupe[[#This Row],[Do not fill in3]]),CONCATENATE(liste_groupe[[#This Row],[Chemical name]],"-",liste_groupe[[#This Row],[Concentration]],liste_groupe[[#This Row],[Units]],liste_groupe[[#This Row],[Do not fill in3]]))) -> saccharin-1mg/L + Testostérone | B40: =B16 -> test chemical | C40: =C16 -> 1 | D40: =D16 -> mg/L | E40: =E16 -> saccharin | F40: + Testostérone
A41: =IF(ISBLANK(liste_groupe[[#This Row],[Do not fill in2]])," ",IF(ISBLANK(liste_groupe[[#This Row],[Units]]),CONCATENATE(liste_groupe[[#This Row],[Chemical name]],liste_groupe[[#This Row],[Do not fill in3]]),CONCATENATE(liste_groupe[[#This Row],[Chemical name]],"-",liste_groupe[[#This Row],[Concentration]],liste_groupe[[#This Row],[Units]],liste_groupe[[#This Row],[Do not fill in3]]))) -> saccharin-10mg/L + Testostérone | B41: =B17 -> test chemical | C41: =C17 -> 10 | D41: =D17 -> mg/L | E41: =E17 -> saccharin | F41: + Testostérone
A42: =IF(ISBLANK(liste_groupe[[#This Row],[Do not fill in2]])," ",IF(ISBLANK(liste_groupe[[#This Row],[Units]]),CONCATENATE(liste_groupe[[#This Row],[Chemical name]],liste_groupe[[#This Row],[Do not fill in3]]),CONCATENATE(liste_groupe[[#This Row],[Chemical name]],"-",liste_groupe[[#This Row],[Concentration]],liste_groupe[[#This Row],[Units]],liste_groupe[[#This Row],[Do not fill in3]]))) -> saccharin-100mg/L + Testostérone | B42: =B18 -> test chemical | C42: =C18 -> 100 | D42: =D18 -> mg/L | E42: =E18 -> saccharin | F42: + Testostérone
A43: =IF(ISBLANK(liste_groupe[[#This Row],[Do not fill in2]])," ",IF(ISBLANK(liste_groupe[[#This Row],[Units]]),CONCATENATE(liste_groupe[[#This Row],[Chemical name]],liste_groupe[[#This Row],[Do not fill in3]]),CONCATENATE(liste_groupe[[#This Row],[Chemical name]],"-",liste_groupe[[#This Row],[Concentration]],liste_groupe[[#This Row],[Units]],liste_groupe[[#This Row],[Do not fill in3]]))) -> 0-00 + Testostérone | B43: =B19 -> test chemical | C43: =C19 -> 0 | D43: =D19 -> 0 | E43: =E19 -> 0 | F43: + Testostérone
A44: =IF(ISBLANK(liste_groupe[[#This Row],[Do not fill in2]])," ",IF(ISBLANK(liste_groupe[[#This Row],[Units]]),CONCATENATE(liste_groupe[[#This Row],[Chemical name]],liste_groupe[[#This Row],[Do not fill in3]]),CONCATENATE(liste_groupe[[#This Row],[Chemical name]],"-",liste_groupe[[#This Row],[Concentration]],liste_groupe[[#This Row],[Units]],liste_groupe[[#This Row],[Do not fill in3]]))) -> 0-00 + Testostérone | B44: =B20 -> test chemical | C44: =C20 -> 0 | D44: =D20 -> 0 | E44: =E20 -> 0 | F44: + Testostérone
A45: =IF(ISBLANK(liste_groupe[[#This Row],[Do not fill in2]])," ",IF(ISBLANK(liste_groupe[[#This Row],[Units]]),CONCATENATE(liste_groupe[[#This Row],[Chemical name]],liste_groupe[[#This Row],[Do not fill in3]]),CONCATENATE(liste_groupe[[#This Row],[Chemical name]],"-",liste_groupe[[#This Row],[Concentration]],liste_groupe[[#This Row],[Units]],liste_groupe[[#This Row],[Do not fill in3]]))) -> 0-00 + Testostérone | B45: =B21 -> test chemical | C45: =C21 -> 0 | D45: =D21 -> 0 | E45: =E21 -> 0 | F45: + Testostérone
...

Sheet R1
A3: R1 | B3: Unspiked | O3: Testosterone spiked
A4: Group names | B4: ='Front page'!A7 -> Solvent control | C4: ='Front page'!A8 -> EE2-33.8ng/L | D4: ='Front page'!A9 -> EE2-50.6ng/L | E4: ='Front page'!A10 -> EE2-76ng/L | F4: ='Front page'!A11 -> EE2-114ng/L | G4: ='Front page'!A12 -> EE2-170.9ng/L | H4: ='Front page'!A13 -> EE2-488ng/L | I4: ='Front page'!A14 -> saccharin-0.01mg/L | J4: ='Front page'!A15 -> saccharin-0.1mg/L | K4: ='Front page'!A16 -> saccharin-1mg/L | L4: ='Front page'!A17 -> saccharin-10mg/L | M4: ='Front page'!A18 -> saccharin-100mg/L | O4: ='Front page'!A35 -> Testo -30µg/L | P4: ='Front page'!A36 -> Testo 30µg/L + EE2 -64ng/L | Q4: ='Front page'!A37 -> Testo 30µg/L + FAD-10mg/L | R4: ='Front page'!A38 -> saccharin-0.01mg/L + Testostérone | S4: ='Front page'!A39 -> saccharin-0.1mg/L + Testostérone | T4: ='Front page'!A40 -> saccharin-1mg/L + Testostérone | U4: ='Front page'!A41 -> saccharin-10mg/L + Testostérone | V4: ='Front page'!A42 -> saccharin-100mg/L + Testostérone
A5: Raw data | B5: 0 | C5: 412 | D5: 0 | E5: 240 | F5: 574 | G5: 49042 | H5: 316725 | I5: 0 | J5: 0 | K5: 0 | L5: 0 | M5: 0 | O5: 47300 | P5: 120135 | Q5: 163 | R5: 81710 | S5: 120089 | T5: 151592 | U5: 43390 | V5: 91251
B6: 0 | C6: 0 | D6: 0 | E6: 0 | F6: 147643 | G6: 187620 | H6: 228388 | I6: 1573 | J6: 0 | K6: 0 | L6: 0 | M6: 0 | O6: 133172 | P6: 201927 | Q6: 0 | R6: 93010 | S6: 7530 | T6: 80259 | U6: 0 | V6: 161516
B7: 0 | C7: 0 | D7: 3251 | E7: 80 | F7: 0 | G7: 234509 | H7: 50593 | I7: 0 | J7: 5636 | K7: 0 | L7: 0 | M7: 0 | O7: 82577 | P7: 184295 | Q7: 5491 | R7: 155151 | S7: 132685 | T7: 6279 | U7: 45731 | V7: 49502
B8: 0 | C8: 163 | D8: 0 | E8: 172872 | F8: 21014 | G8: 208582 | H8: 288909 | I8: 0 | J8: 0 | K8: 0 | L8: 241 | M8: 0 | O8: 147545 | P8: 197921 | Q8: 4190 | R8: 29908 | S8: 71045 | T8: 12517 | U8: 2038 | V8: 98289
B9: 0 | C9: 0 | D9: 0 | E9: 0 | F9: 88180 | G9: 178873 | H9: 251307 | I9: 164 | J9: 0 | K9: 80 | L9: 0 | M9: 0 | O9: 81914 | P9: 107180 | Q9: 0 | R9: 68940 | S9: 23406 | T9: 97129 | U9: 62989 | V9: 7750
B10: 0 | C10: 0 | D10: 162 | E10: 0 | F10: 140995 | G10: 247182 | H10: 309778 | I10: 0 | J10: 0 | K10: 810 | L10: 0 | M10: 82 | O10: 107928 | P10: 192833 | Q10: 0 | R10: 10842 | S10: 166888 | T10: 176498 | U10: 119953 | V10: 56093
B11: 0 | C11: 0 | D11: 80 | E11: 0 | F11: 122114 | G11: 52136 | H11: 287905 | I11: 0 | J11: 0 | K11: 162 | L11: 0 | M11: 6740 | O11: 93964 | P11: 232079 | Q11: 0 | R11: 82336 | S11: 12157 | T11: 188741 | U11: 48843 | V11: 129690
B12: 0 | C12: 0 | D12: 0 | E12: 0 | G12: 262260 | H12: 258863 | I12: 0 | J12: 0 | K12: 0 | L12: 0 | M12: 0 | O12: 66465 | P12: 83977 | Q12: 0 | R12: 147172 | S12: 4387 | T12: 2268 | U12: 50701 | V12: 0
O13: 117910
O14: 140043
O15: 128382
O16: 80736
O17: 130331
O18: 32112
O19: 98243
O20: 7034
A22: =A4 -> Group names | B22: =B4 -> Solvent control | C22: =C4 -> EE2-33.8ng/L | D22: =D4 -> EE2-50.6ng/L | E22: =E4 -> EE2-76ng/L | F22: =F4 -> EE2-114ng/L | G22: =G4 -> EE2-170.9ng/L | H22: =H4 -> EE2-488ng/L | ... M22: =M4 -> saccharin-100mg/L | N22: Nom des groupes | O22: =O4 -> Testo -30µg/L | P22: =P4 -> Testo 30µg/L + EE2 -64ng/L | Q22: =Q4 -> Testo 30µg/L + FAD-10mg/L | R22: =R4 -> saccharin-0.01mg/L + Testostérone | S22: =S4 -> saccharin-0.1mg/L + Testostérone | T22: =T4 -> saccharin-1mg/L + Testostérone | U22: =U4 -> saccharin-10mg/L + Testostérone | V22: =V4 -> saccharin-100mg/L + Testostérone
A23: mean | B23: =AVERAGE(B5:B20) -> 0 | C23: =AVERAGE(C5:C20) -> 71.875 | D23: =AVERAGE(D5:D20) -> 436.625 | E23: =AVERAGE(E5:E20) -> 21649 | F23: =AVERAGE(F5:F20) -> 74360 | G23: =AVERAGE(G5:G20) -> 177525.5 | H23: =AVERAGE(H5:H20) -> 249058.5 | I23: =AVERAGE(I5:I20) -> 217.125 | ... M23: =AVERAGE(M5:M20) -> 852.75 | N23: mean | O23: =AVERAGE(O5:O20) -> 93478.5 | P23: =AVERAGE(P5:P20) -> 165043.38 | Q23: =AVERAGE(Q5:Q20) -> 1230.5 | R23: =AVERAGE(R5:R20) -> 83633.625 | S23: =AVERAGE(S5:S20) -> 67273.375 | T23: =AVERAGE(T5:T20) -> 89410.375 | U23: =AVERAGE(U5:U20) -> 46705.625 | V23: =AVERAGE(V5:V20) -> 74261.375
A24: SD | B24: =STDEV(B5:B20) -> 0 | C24: =STDEV(C5:C20) -> 148.7975 | D24: =STDEV(D5:D20) -> 1138.7031 | E24: =STDEV(E5:E20) -> 61103.377 | F24: =STDEV(F5:F20) -> 65956.599 | G24: =STDEV(G5:G20) -> 83304.81 | H24: =STDEV(H5:H20) -> 85590.165 | I24: =STDEV(I5:I20) -> 550.85374 | ... M24: =STDEV(M5:M20) -> 2378.9813 | N24: SD | O24: =STDEV(O5:O20) -> 40486.73 | P24: =STDEV(P5:P20) -> 53471.879 | Q24: =STDEV(Q5:Q20) -> 2255.8086 | R24: =STDEV(R5:R20) -> 50208.318 | S24: =STDEV(S5:S20) -> 64908.285 | T24: =STDEV(T5:T20) -> 77347.007 | U24: =STDEV(U5:U20) -> 37491.738 | V24: =STDEV(V5:V20) -> 56610.584
B26: Unspiked | O26: Testosterone spiked
A27: =A4 -> Group names | B27: =B4 -> Solvent control | C27: =C4 -> EE2-33.8ng/L | D27: =D4 -> EE2-50.6ng/L | E27: =E4 -> EE2-76ng/L | F27: =F4 -> EE2-114ng/L | G27: =G4 -> EE2-170.9ng/L | H27: =H4 -> EE2-488ng/L | ... M27: =M4 -> saccharin-100mg/L | O27: =O4 -> Testo -30µg/L | P27: =P4 -> Testo 30µg/L + EE2 -64ng/L | Q27: =Q4 -> Testo 30µg/L + FAD-10mg/L | R27: =R4 -> saccharin-0.01mg/L + Testostérone | S27: =S4 -> saccharin-0.1mg/L + Testostérone | T27: =T4 -> saccharin-1mg/L + Testostérone | U27: =U4 -> saccharin-10mg/L + Testostérone | V27: =V4 -> saccharin-100mg/L + Testostérone
A28: Data normalised to the "Testo" group | B28: =IF(B5="","",(B5/$O$23)) -> 0 | C28: =IF(C5="","",(C5/$O$23)) -> 0.0044074306 | D28: =IF(D5="","",(D5/$O$23)) -> 0 | E28: =IF(E5="","",(E5/$O$23)) -> 0.0025674353 | F28: =IF(F5="","",(F5/$O$23)) -> 0.0061404494 | G28: =IF(G5="","",(G5/$O$23)) -> 0.52463401 | H28: =IF(H5="","",(H5/$O$23)) -> 3.3882123 | I28: =IF(I5="","",(I5/$O$23)) -> 0 | ... M28: =IF(M5="","",(M5/$O$23)) -> 0 | O28: =IF(O5="","",(O5/$O$23)) -> 0.50599871 | P28: =IF(P5="","",(P5/$O$23)) -> 1.2851618 | Q28: =IF(Q5="","",(Q5/$O$23)) -> 0.0017437165 | R28: =IF(R5="","",(R5/$O$23)) -> 0.87410474 | S28: =IF(S5="","",(S5/$O$23)) -> 1.2846697 | T28: =IF(T5="","",(T5/$O$23)) -> 1.6216777 | U28: =IF(U5="","",(U5/$O$23)) -> 0.46417091 | V28: =IF(V5="","",(V5/$O$23)) -> 0.97617099
B29: =IF(B6="","",(B6/$O$23)) -> 0 | C29: =IF(C6="","",(C6/$O$23)) -> 0 | D29: =IF(D6="","",(D6/$O$23)) -> 0 | E29: =IF(E6="","",(E6/$O$23)) -> 0 | F29: =IF(F6="","",(F6/$O$23)) -> 1.5794327 | G29: =IF(G6="","",(G6/$O$23)) -> 2.0070925 | H29: =IF(H6="","",(H6/$O$23)) -> 2.4432142 | I29: =IF(I6="","",(I6/$O$23)) -> 0.016827399 | ... M29: =IF(M6="","",(M6/$O$23)) -> 0 | O29: =IF(O6="","",(O6/$O$23)) -> 1.4246271 | P29: =IF(P6="","",(P6/$O$23)) -> 2.1601438 | Q29: =IF(Q6="","",(Q6/$O$23)) -> 0 | R29: =IF(R6="","",(R6/$O$23)) -> 0.99498815 | S29: =IF(S6="","",(S6/$O$23)) -> 0.080553282 | T29: =IF(T6="","",(T6/$O$23)) -> 0.85858245 | U29: =IF(U6="","",(U6/$O$23)) -> 0 | V29: =IF(V6="","",(V6/$O$23)) -> 1.7278412
B30: =IF(B7="","",(B7/$O$23)) -> 0 | C30: =IF(C7="","",(C7/$O$23)) -> 0 | D30: =IF(D7="","",(D7/$O$23)) -> 0.034778051 | E30: =IF(E7="","",(E7/$O$23)) -> 0.00085581176 | F30: =IF(F7="","",(F7/$O$23)) -> 0 | G30: =IF(G7="","",(G7/$O$23)) -> 2.5086945 | H30: =IF(H7="","",(H7/$O$23)) -> 0.54122606 | I30: =IF(I7="","",(I7/$O$23)) -> 0 | ... M30: =IF(M7="","",(M7/$O$23)) -> 0 | O30: =IF(O7="","",(O7/$O$23)) -> 0.8833796 | P30: =IF(P7="","",(P7/$O$23)) -> 1.9715229 | Q30: =IF(Q7="","",(Q7/$O$23)) -> 0.05874078 | R30: =IF(R7="","",(R7/$O$23)) -> 1.6597506 | S30: =IF(S7="","",(S7/$O$23)) -> 1.4194173 | T30: =IF(T7="","",(T7/$O$23)) -> 0.067170526 | U30: =IF(U7="","",(U7/$O$23)) -> 0.4892141 | V30: =IF(V7="","",(V7/$O$23)) -> 0.52955492
B31: =IF(B8="","",(B8/$O$23)) -> 0 | C31: =IF(C8="","",(C8/$O$23)) -> 0.0017437165 | D31: =IF(D8="","",(D8/$O$23)) -> 0 | E31: =IF(E8="","",(E8/$O$23)) -> 1.8493236 | F31: =IF(F8="","",(F8/$O$23)) -> 0.22480036 | G31: =IF(G8="","",(G8/$O$23)) -> 2.2313366 | H31: =IF(H8="","",(H8/$O$23)) -> 3.0906465 | I31: =IF(I8="","",(I8/$O$23)) -> 0 | ... M31: =IF(M8="","",(M8/$O$23)) -> 0 | O31: =IF(O8="","",(O8/$O$23)) -> 1.5783843 | P31: =IF(P8="","",(P8/$O$23)) -> 2.117289 | Q31: =IF(Q8="","",(Q8/$O$23)) -> 0.044823141 | R31: =IF(R8="","",(R8/$O$23)) -> 0.31994523 | S31: =IF(S8="","",(S8/$O$23)) -> 0.76001433 | T31: =IF(T8="","",(T8/$O$23)) -> 0.13390245 | U31: =IF(U8="","",(U8/$O$23)) -> 0.021801805 | V31: =IF(V8="","",(V8/$O$23)) -> 1.051461
B32: =IF(B9="","",(B9/$O$23)) -> 0 | C32: =IF(C9="","",(C9/$O$23)) -> 0 | D32: =IF(D9="","",(D9/$O$23)) -> 0 | E32: =IF(E9="","",(E9/$O$23)) -> 0 | F32: =IF(F9="","",(F9/$O$23)) -> 0.94331852 | G32: =IF(G9="","",(G9/$O$23)) -> 1.9135202 | H32: =IF(H9="","",(H9/$O$23)) -> 2.6883936 | I32: =IF(I9="","",(I9/$O$23)) -> 0.0017544141 | ... M32: =IF(M9="","",(M9/$O$23)) -> 0 | O32: =IF(O9="","",(O9/$O$23)) -> 0.87628706 | P32: =IF(P9="","",(P9/$O$23)) -> 1.1465738 | Q32: =IF(Q9="","",(Q9/$O$23)) -> 0 | R32: =IF(R9="","",(R9/$O$23)) -> 0.73749579 | S32: =IF(S9="","",(S9/$O$23)) -> 0.25038913 | T32: =IF(T9="","",(T9/$O$23)) -> 1.0390518 | U32: =IF(U9="","",(U9/$O$23)) -> 0.67383409 | V32: =IF(V9="","",(V9/$O$23)) -> 0.082906765
B33: =IF(B10="","",(B10/$O$23)) -> 0 | C33: =IF(C10="","",(C10/$O$23)) -> 0 | D33: =IF(D10="","",(D10/$O$23)) -> 0.0017330188 | E33: =IF(E10="","",(E10/$O$23)) -> 0 | F33: =IF(F10="","",(F10/$O$23)) -> 1.5083147 | G33: =IF(G10="","",(G10/$O$23)) -> 2.6442658 | H33: =IF(H10="","",(H10/$O$23)) -> 3.3138957 | I33: =IF(I10="","",(I10/$O$23)) -> 0 | ... M33: =IF(M10="","",(M10/$O$23)) -> 0.00087720706 | O33: =IF(O10="","",(O10/$O$23)) -> 1.1545757 | P33: =IF(P10="","",(P10/$O$23)) -> 2.0628594 | Q33: =IF(Q10="","",(Q10/$O$23)) -> 0 | R33: =IF(R10="","",(R10/$O$23)) -> 0.11598389 | S33: =IF(S10="","",(S10/$O$23)) -> 1.7853089 | T33: =IF(T10="","",(T10/$O$23)) -> 1.8881133 | U33: =IF(U10="","",(U10/$O$23)) -> 1.2832149 | V33: =IF(V10="","",(V10/$O$23)) -> 0.60006312
B34: =IF(B11="","",(B11/$O$23)) -> 0 | C34: =IF(C11="","",(C11/$O$23)) -> 0 | D34: =IF(D11="","",(D11/$O$23)) -> 0.00085581176 | E34: =IF(E11="","",(E11/$O$23)) -> 0 | F34: =IF(F11="","",(F11/$O$23)) -> 1.3063325 | G34: =IF(G11="","",(G11/$O$23)) -> 0.55773253 | H34: =IF(H11="","",(H11/$O$23)) -> 3.0799061 | I34: =IF(I11="","",(I11/$O$23)) -> 0 | ... M34: =IF(M11="","",(M11/$O$23)) -> 0.072102141 | O34: =IF(O11="","",(O11/$O$23)) -> 1.0051937 | P34: =IF(P11="","",(P11/$O$23)) -> 2.4826992 | Q34: =IF(Q11="","",(Q11/$O$23)) -> 0 | R34: =IF(R11="","",(R11/$O$23)) -> 0.88080147 | S34: =IF(S11="","",(S11/$O$23)) -> 0.1300513 | T34: =IF(T11="","",(T11/$O$23)) -> 2.0190846 | U34: =IF(U11="","",(U11/$O$23)) -> 0.52250517 | V34: =IF(V11="","",(V11/$O$23)) -> 1.3873778
B35: =IF(B12="","",(B12/$O$23)) -> 0 | C35: =IF(C12="","",(C12/$O$23)) -> 0 | D35: =IF(D12="","",(D12/$O$23)) -> 0 | E35: =IF(E12="","",(E12/$O$23)) -> 0 | F35: =IF(F12="","",(F12/$O$23)) | G35: =IF(G12="","",(G12/$O$23)) -> 2.8055649 | H35: =IF(H12="","",(H12/$O$23)) -> 2.769225 | I35: =IF(I12="","",(I12/$O$23)) -> 0 | ... M35: =IF(M12="","",(M12/$O$23)) -> 0 | O35: =IF(O12="","",(O12/$O$23)) -> 0.71101911 | P35: =IF(P12="","",(P12/$O$23)) -> 0.89835631 | Q35: =IF(Q12="","",(Q12/$O$23)) -> 0 | R35: =IF(R12="","",(R12/$O$23)) -> 1.5743941 | S35: =IF(S12="","",(S12/$O$23)) -> 0.046930578 | T35: =IF(T12="","",(T12/$O$23)) -> 0.024262264 | U35: =IF(U12="","",(U12/$O$23)) -> 0.5423814 | V35: =IF(V12="","",(V12/$O$23)) -> 0
B36: =IF(B13="","",(B13/$O$23)) | C36: =IF(C13="","",(C13/$O$23)) | D36: =IF(D13="","",(D13/$O$23)) | E36: =IF(E13="","",(E13/$O$23)) | F36: =IF(F13="","",(F13/$O$23)) | G36: =IF(G13="","",(G13/$O$23)) | H36: =IF(H13="","",(H13/$O$23)) | I36: =IF(I13="","",(I13/$O$23)) | ... M36: =IF(M13="","",(M13/$O$23)) | O36: =IF(O13="","",(O13/$O$23)) -> 1.2613596 | P36: =IF(P13="","",(P13/$O$23)) | Q36: =IF(Q13="","",(Q13/$O$23)) | R36: =IF(R13="","",(R13/$O$23)) | S36: =IF(S13="","",(S13/$O$23)) | T36: =IF(T13="","",(T13/$O$23)) | U36: =IF(U13="","",(U13/$O$23)) | V36: =IF(V13="","",(V13/$O$23))
B37: =IF(B14="","",(B14/$O$23)) | C37: =IF(C14="","",(C14/$O$23)) | D37: =IF(D14="","",(D14/$O$23)) | E37: =IF(E14="","",(E14/$O$23)) | F37: =IF(F14="","",(F14/$O$23)) | G37: =IF(G14="","",(G14/$O$23)) | H37: =IF(H14="","",(H14/$O$23)) | I37: =IF(I14="","",(I14/$O$23)) | ... M37: =IF(M14="","",(M14/$O$23)) | O37: =IF(O14="","",(O14/$O$23)) -> 1.4981306 | P37: =IF(P14="","",(P14/$O$23)) | Q37: =IF(Q14="","",(Q14/$O$23)) | R37: =IF(R14="","",(R14/$O$23)) | S37: =IF(S14="","",(S14/$O$23)) | T37: =IF(T14="","",(T14/$O$23)) | U37: =IF(U14="","",(U14/$O$23)) | V37: =IF(V14="","",(V14/$O$23))
B38: =IF(B15="","",(B15/$O$23)) | C38: =IF(C15="","",(C15/$O$23)) | D38: =IF(D15="","",(D15/$O$23)) | E38: =IF(E15="","",(E15/$O$23)) | F38: =IF(F15="","",(F15/$O$23)) | G38: =IF(G15="","",(G15/$O$23)) | H38: =IF(H15="","",(H15/$O$23)) | I38: =IF(I15="","",(I15/$O$23)) | ... M38: =IF(M15="","",(M15/$O$23)) | O38: =IF(O15="","",(O15/$O$23)) -> 1.3733853 | P38: =IF(P15="","",(P15/$O$23)) | Q38: =IF(Q15="","",(Q15/$O$23)) | R38: =IF(R15="","",(R15/$O$23)) | S38: =IF(S15="","",(S15/$O$23)) | T38: =IF(T15="","",(T15/$O$23)) | U38: =IF(U15="","",(U15/$O$23)) | V38: =IF(V15="","",(V15/$O$23))
B39: =IF(B16="","",(B16/$O$23)) | C39: =IF(C16="","",(C16/$O$23)) | D39: =IF(D16="","",(D16/$O$23)) | E39: =IF(E16="","",(E16/$O$23)) | F39: =IF(F16="","",(F16/$O$23)) | G39: =IF(G16="","",(G16/$O$23)) | H39: =IF(H16="","",(H16/$O$23)) | I39: =IF(I16="","",(I16/$O$23)) | ... M39: =IF(M16="","",(M16/$O$23)) | O39: =IF(O16="","",(O16/$O$23)) -> 0.86368523 | P39: =IF(P16="","",(P16/$O$23)) | Q39: =IF(Q16="","",(Q16/$O$23)) | R39: =IF(R16="","",(R16/$O$23)) | S39: =IF(S16="","",(S16/$O$23)) | T39: =IF(T16="","",(T16/$O$23)) | U39: =IF(U16="","",(U16/$O$23)) | V39: =IF(V16="","",(V16/$O$23))
B40: =IF(B17="","",(B17/$O$23)) | C40: =IF(C17="","",(C17/$O$23)) | D40: =IF(D17="","",(D17/$O$23)) | E40: =IF(E17="","",(E17/$O$23)) | F40: =IF(F17="","",(F17/$O$23)) | G40: =IF(G17="","",(G17/$O$23)) | H40: =IF(H17="","",(H17/$O$23)) | I40: =IF(I17="","",(I17/$O$23)) | ... M40: =IF(M17="","",(M17/$O$23)) | O40: =IF(O17="","",(O17/$O$23)) -> 1.394235 | P40: =IF(P17="","",(P17/$O$23)) | Q40: =IF(Q17="","",(Q17/$O$23)) | R40: =IF(R17="","",(R17/$O$23)) | S40: =IF(S17="","",(S17/$O$23)) | T40: =IF(T17="","",(T17/$O$23)) | U40: =IF(U17="","",(U17/$O$23)) | V40: =IF(V17="","",(V17/$O$23))
... B43: =IF(B20="","",(B20/$O$23)) | C43: =IF(C20="","",(C20/$O$23)) | D43: =IF(D20="","",(D20/$O$23)) | E43: =IF(E20="","",(E20/$O$23)) | F43: =IF(F20="","",(F20/$O$23)) | G43: =IF(G20="","",(G20/$O$23)) | H43: =IF(H20="","",(H20/$O$23)) | I43: =IF(I20="","",(I20/$O$23)) | ... M43: =IF(M20="","",(M20/$O$23)) | O43: =IF(O20="","",(O20/$O$23)) -> 0.075247249 | P43: =IF(P20="","",(P20/$O$23)) | Q43: =IF(Q20="","",(Q20/$O$23)) | R43: =IF(R20="","",(R20/$O$23)) | S43: =IF(S20="","",(S20/$O$23)) | T43: =IF(T20="","",(T20/$O$23)) | U43: =IF(U20="","",(U20/$O$23)) | V43: =IF(V20="","",(V20/$O$23))
A45: =A4 -> Group names | B45: =B4 -> Solvent control | C45: =C4 -> EE2-33.8ng/L | D45: =D4 -> EE2-50.6ng/L | E45: =E4 -> EE2-76ng/L | F45: =F4 -> EE2-114ng/L | G45: =G4 -> EE2-170.9ng/L | H45: =H4 -> EE2-488ng/L | ... M45: =M4 -> saccharin-100mg/L | N45: =N22 -> Nom des groupes | O45: =O4 -> Testo -30µg/L | P45: =P4 -> Testo 30µg/L + EE2 -64ng/L | Q45: =Q4 -> Testo 30µg/L + FAD-10mg/L | R45: =R4 -> saccharin-0.01mg/L + Testostérone | S45: =S4 -> saccharin-0.1mg/L + Testostérone | T45: =T4 -> saccharin-1mg/L + Testostérone | U45: =U4 -> saccharin-10mg/L + Testostérone | V45: =V4 -> saccharin-100mg/L + Testostérone
A46: mean | B46: =AVERAGE(B28:B43) -> 0 | C46: =AVERAGE(C28:C43) -> 0.00076889338 | D46: =AVERAGE(D28:D43) -> 0.0046708601 | E46: =AVERAGE(E28:E43) -> 0.23159336 | F46: =AVERAGE(F28:F43) -> 0.79547703 | G46: =AVERAGE(G28:G43) -> 1.8991051 | H46: =AVERAGE(H28:H43) -> 2.6643399 | I46: =AVERAGE(I28:I43) -> 0.0023227266 | ... M46: =AVERAGE(M28:M43) -> 0.0091224185 | N46: mean | O46: =AVERAGE(O28:O43) -> 1 | P46: =AVERAGE(P28:P43) -> 1.7655758 | Q46: =AVERAGE(Q28:Q43) -> 0.013163455 | R46: =AVERAGE(R28:R43) -> 0.894683 | S46: =AVERAGE(S28:S43) -> 0.71966682 | T46: =AVERAGE(T28:T43) -> 0.95648063 | U46: =AVERAGE(U28:U43) -> 0.49964029 | V46: =AVERAGE(V28:V43) -> 0.79442198
A47: SD | B47: =STDEV(B28:B43) -> 0 | C47: =STDEV(C28:C43) -> 0.0015917832 | D47: =STDEV(D28:D43) -> 0.012181444 | E47: =STDEV(E28:E43) -> 0.65366236 | F47: =STDEV(F28:F43) -> 0.70558041 | G47: =STDEV(G28:G43) -> 0.89116546 | H47: =STDEV(H28:H43) -> 0.91561337 | I47: =STDEV(I28:I43) -> 0.0058928389 | ... M47: =STDEV(M28:M43) -> 0.025449502 | N47: SD | O47: =STDEV(O28:O43) -> 0.43311275 | P47: =STDEV(P28:P43) -> 0.57202329 | Q47: =STDEV(Q28:Q43) -> 0.024131845 | R47: =STDEV(R28:R43) -> 0.53711087 | S47: =STDEV(S28:S43) -> 0.69436592 | T47: =STDEV(T28:T43) -> 0.82743099 | U47: =STDEV(U28:U43) -> 0.40107338 | V47: =STDEV(V28:V43) -> 0.60560005
...

Sheet R2
A3: R2 | B3: Unspiked | O3: Testosterone spiked
A4: Group names | B4: ='Front page'!A7 -> Solvent control | C4: ='Front page'!A8 -> EE2-33.8ng/L | D4: ='Front page'!A9 -> EE2-50.6ng/L | E4: ='Front page'!A10 -> EE2-76ng/L | F4: ='Front page'!A11 -> EE2-114ng/L | G4: ='Front page'!A12 -> EE2-170.9ng/L | H4: ='Front page'!A13 -> EE2-488ng/L | I4: ='Front page'!A14 -> saccharin-0.01mg/L | J4: ='Front page'!A15 -> saccharin-0.1mg/L | K4: ='Front page'!A16 -> saccharin-1mg/L | L4: ='Front page'!A17 -> saccharin-10mg/L | M4: ='Front page'!A18 -> saccharin-100mg/L | O4: ='Front page'!A35 -> Testo -30µg/L | P4: ='Front page'!A36 -> Testo 30µg/L + EE2 -64ng/L | Q4: ='Front page'!A37 -> Testo 30µg/L + FAD-10mg/L | R4: ='Front page'!A38 -> saccharin-0.01mg/L + Testostérone | S4: ='Front page'!A39 -> saccharin-0.1mg/L + Testostérone | T4: ='Front page'!A40 -> saccharin-1mg/L + Testostérone | U4: ='Front page'!A41 -> saccharin-10mg/L + Testostérone | V4: ='Front page'!A42 -> saccharin-100mg/L + Testostérone
A5: Raw data | B5: 0 | C5: 0 | D5: 2331 | E5: 258753 | F5: 198059 | G5: 249128 | H5: 237395 | I5: 1765 | J5: 1374 | K5: 401 | L5: 0 | M5: 0 | O5: 83373 | P5: 174007 | Q5: 407 | R5: 126529 | S5: 44940 | T5: 112552 | U5: 19813 | V5: 115995
B6: 0 | C6: 166 | D6: 0 | E6: 158472 | F6: 212090 | G6: 180908 | H6: 223344 | I6: 7346 | J6: 327 | K6: 0 | L6: 1140 | M6: 0 | O6: 0 | P6: 261706 | Q6: 0 | R6: 131617 | S6: 30458 | T6: 59584 | U6: 126696 | V6: 173046
B7: 0 | C7: 0 | D7: 0 | E7: 167178 | F7: 885 | G7: 153207 | H7: 255809 | I7: 163 | J7: 2237 | K7: 0 | L7: 0 | M7: 410 | O7: 40291 | P7: 149587 | Q7: 10333 | R7: 65607 | S7: 61415 | T7: 28899 | U7: 93600 | V7: 154441
B8: 0 | C8: 0 | D8: 0 | E8: 209241 | F8: 114671 | G8: 202187 | H8: 332490 | I8: 1010 | J8: 0 | K8: 6675 | L8: 1298 | M8: 0 | O8: 199795 | P8: 269003 | Q8: 0 | R8: 118303 | S8: 159813 | T8: 69153 | U8: 124016 | V8: 40171
B9: 0 | C9: 1059 | D9: 97478 | E9: 136024 | F9: 5589 | G9: 102537 | H9: 251072 | I9: 0 | J9: 0 | K9: 0 | L9: 0 | M9: 3704 | O9: 136530 | P9: 247474 | Q9: 5399 | R9: 29672 | S9: 168144 | T9: 163241 | U9: 71480 | V9: 167317
B10: 0 | C10: 13490 | D10: 0 | E10: 211579 | F10: 22437 | G10: 214678 | H10: 249573 | I10: 0 | J10: 0 | K10: 0 | L10: 0 | M10: 0 | O10: 187266 | P10: 184463 | Q10: 0 | R10: 115300 | S10: 151795 | T10: 83931 | U10: 131552 | V10: 0
B11: 0 | C11: 0 | D11: 330 | E11: 250327 | F11: 176938 | G11: 282967 | H11: 307494 | I11: 0 | J11: 0 | K11: 0 | L11: 502 | M11: 0 | O11: 0 | P11: 194592 | Q11: 2181 | R11: 107996 | S11: 223632 | T11: 66076 | U11: 16073 | V11: 103213
B12: 87 | C12: 0 | D12: 647 | E12: 96794 | F12: 15818 | G12: 80695 | H12: 284809 | I12: 856 | J12: 0 | K12: 3275 | L12: 0 | M12: 4347 | O12: 133251 | P12: 246845 | Q12: 0 | R12: 110025 | S12: 129518 | T12: 0 | U12: 118186 | V12: 42546
O13: 192609
O14: 216661
O15: 262265
O16: 64732
O17: 173287
O18: 81271
O19: 106225
O20: 26482
A22: =A4 -> Group names | B22: =B4 -> Solvent control | C22: =C4 -> EE2-33.8ng/L | D22: =D4 -> EE2-50.6ng/L | E22: =E4 -> EE2-76ng/L | F22: =F4 -> EE2-114ng/L | G22: =G4 -> EE2-170.9ng/L | H22: =H4 -> EE2-488ng/L | ... M22: =M4 -> saccharin-100mg/L | N22: Noms des groupes | O22: =O4 -> Testo -30µg/L | P22: =P4 -> Testo 30µg/L + EE2 -64ng/L | Q22: =Q4 -> Testo 30µg/L + FAD-10mg/L | R22: =R4 -> saccharin-0.01mg/L + Testostérone | S22: =S4 -> saccharin-0.1mg/L + Testostérone | T22: =T4 -> saccharin-1mg/L + Testostérone | U22: =U4 -> saccharin-10mg/L + Testostérone | V22: =V4 -> saccharin-100mg/L + Testostérone
A23: mean | B23: =AVERAGE(B5:B20) -> 10.875 | C23: =AVERAGE(C5:C20) -> 1839.375 | D23: =AVERAGE(D5:D20) -> 12598.25 | E23: =AVERAGE(E5:E20) -> 186046 | F23: =AVERAGE(F5:F20) -> 93310.875 | G23: =AVERAGE(G5:G20) -> 183288.38 | H23: =AVERAGE(H5:H20) -> 267748.25 | I23: =AVERAGE(I5:I20) -> 1392.5 | J23: =AVERAGE(J5:J20) -> 492.25 | L23: =AVERAGE(L5:L20) -> 367.5 | N23: mean | O23: =AVERAGE(O5:O20) -> 119002.38 | P23: =AVERAGE(P5:P20) -> 215959.62 | Q23: =AVERAGE(Q5:Q20) -> 2290 | R23: =AVERAGE(R5:R20) -> 100631.12 | S23: =AVERAGE(S5:S20) -> 121214.38 | T23: =AVERAGE(T5:T20) -> 72929.5 | U23: =AVERAGE(U5:U20) -> 87677 | V23: =AVERAGE(V5:V20) -> 99591.125
A24: SD | B24: =STDEV(B5:B20) -> 30.759145 | C24: =STDEV(C5:C20) -> 4721.7239 | D24: =STDEV(D5:D20) -> 34305.756 | E24: =STDEV(E5:E20) -> 56306.234 | F24: =STDEV(F5:F20) -> 92424.736 | G24: =STDEV(G5:G20) -> 69250.984 | H24: =STDEV(H5:H20) -> 37237.324 | I24: =STDEV(I5:I20) -> 2488.4274 | J24: =STDEV(J5:J20) -> 850.25152 | L24: =STDEV(L5:L20) -> 554.97207 | N24: SD | O24: =STDEV(O5:O20) -> 81242.037 | P24: =STDEV(P5:P20) -> 45461.685 | Q24: =STDEV(Q5:Q20) -> 3758.6035 | R24: =STDEV(R5:R20) -> 34974.825 | S24: =STDEV(S5:S20) -> 68469.183 | T24: =STDEV(T5:T20) -> 49776.463 | U24: =STDEV(U5:U20) -> 47402.381 | V24: =STDEV(V5:V20) -> 65439.63
B26: Unspiked | O26: Testosterone spiked
A27: =A4 -> Group names | B27: =B4 -> Solvent control | C27: =C4 -> EE2-33.8ng/L | D27: =D4 -> EE2-50.6ng/L | E27: =E4 -> EE2-76ng/L | F27: =F4 -> EE2-114ng/L | G27: =G4 -> EE2-170.9ng/L | H27: =H4 -> EE2-488ng/L | ... M27: =M4 -> saccharin-100mg/L | O27: =O4 -> Testo -30µg/L | P27: =P4 -> Testo 30µg/L + EE2 -64ng/L | Q27: =Q4 -> Testo 30µg/L + FAD-10mg/L | R27: =R4 -> saccharin-0.01mg/L + Testostérone | S27: =S4 -> saccharin-0.1mg/L + Testostérone | T27: =T4 -> saccharin-1mg/L + Testostérone | U27: =U4 -> saccharin-10mg/L + Testostérone | V27: =V4 -> saccharin-100mg/L + Testostérone
A28: Data normalised to the "Testo" group | B28: =IF(B5="","",(B5/$O$23)) -> 0 | C28: =IF(C5="","",(C5/$O$23)) -> 0 | D28: =IF(D5="","",(D5/$O$23)) -> 0.019587844 | E28: =IF(E5="","",(E5/$O$23)) -> 2.1743516 | F28: =IF(F5="","",(F5/$O$23)) -> 1.6643281 | G28: =IF(G5="","",(G5/$O$23)) -> 2.0934708 | H28: =IF(H5="","",(H5/$O$23)) -> 1.9948762 | I28: =IF(I5="","",(I5/$O$23)) -> 0.014831637 | ... M28: =IF(M5="","",(M5/$O$23)) -> 0 | O28: =IF(O5="","",(O5/$O$23)) -> 0.70059946 | P28: =IF(P5="","",(P5/$O$23)) -> 1.4622145 | Q28: =IF(Q5="","",(Q5/$O$23)) -> 0.0034200998 | R28: =IF(R5="","",(R5/$O$23)) -> 1.0632477 | S28: =IF(S5="","",(S5/$O$23)) -> 0.37763952 | T28: =IF(T5="","",(T5/$O$23)) -> 0.94579625 | U28: =IF(U5="","",(U5/$O$23)) -> 0.16649248 | V28: =IF(V5="","",(V5/$O$23)) -> 0.97472845
B29: =IF(B6="","",(B6/$O$23)) -> 0 | C29: =IF(C6="","",(C6/$O$23)) -> 0.0013949301 | D29: =IF(D6="","",(D6/$O$23)) -> 0 | E29: =IF(E6="","",(E6/$O$23)) -> 1.3316709 | F29: =IF(F6="","",(F6/$O$23)) -> 1.7822333 | G29: =IF(G6="","",(G6/$O$23)) -> 1.520205 | H29: =IF(H6="","",(H6/$O$23)) -> 1.8768029 | I29: =IF(I6="","",(I6/$O$23)) -> 0.06172986 | ... M29: =IF(M6="","",(M6/$O$23)) -> 0 | O29: =IF(O6="","",(O6/$O$23)) -> 0 | P29: =IF(P6="","",(P6/$O$23)) -> 2.1991662 | Q29: =IF(Q6="","",(Q6/$O$23)) -> 0 | R29: =IF(R6="","",(R6/$O$23)) -> 1.1060031 | S29: =IF(S6="","",(S6/$O$23)) -> 0.25594447 | T29: =IF(T6="","",(T6/$O$23)) -> 0.50069589 | U29: =IF(U6="","",(U6/$O$23)) -> 1.064651 | V29: =IF(V6="","",(V6/$O$23)) -> 1.454139
B30: =IF(B7="","",(B7/$O$23)) -> 0 | C30: =IF(C7="","",(C7/$O$23)) -> 0 | D30: =IF(D7="","",(D7/$O$23)) -> 0 | E30: =IF(E7="","",(E7/$O$23)) -> 1.4048291 | F30: =IF(F7="","",(F7/$O$23)) -> 0.0074368264 | G30: =IF(G7="","",(G7/$O$23)) -> 1.2874281 | H30: =IF(H7="","",(H7/$O$23)) -> 2.1496126 | I30: =IF(I7="","",(I7/$O$23)) -> 0.0013697206 | ... M30: =IF(M7="","",(M7/$O$23)) -> 0.0034453094 | O30: =IF(O7="","",(O7/$O$23)) -> 0.33857307 | P30: =IF(P7="","",(P7/$O$23)) -> 1.2570085 | Q30: =IF(Q7="","",(Q7/$O$23)) -> 0.0868302 | R30: =IF(R7="","",(R7/$O$23)) -> 0.55130832 | S30: =IF(S7="","",(S7/$O$23)) -> 0.51608214 | T30: =IF(T7="","",(T7/$O$23)) -> 0.24284389 | U30: =IF(U7="","",(U7/$O$23)) -> 0.78653892 | V30: =IF(V7="","",(V7/$O$23)) -> 1.2977976
B31: =IF(B8="","",(B8/$O$23)) -> 0 | C31: =IF(C8="","",(C8/$O$23)) -> 0 | D31: =IF(D8="","",(D8/$O$23)) -> 0 | E31: =IF(E8="","",(E8/$O$23)) -> 1.7582926 | F31: =IF(F8="","",(F8/$O$23)) -> 0.96360262 | G31: =IF(G8="","",(G8/$O$23)) -> 1.6990165 | H31: =IF(H8="","",(H8/$O$23)) -> 2.7939779 | I31: =IF(I8="","",(I8/$O$23)) -> 0.0084872256 | ... M31: =IF(M8="","",(M8/$O$23)) -> 0 | O31: =IF(O8="","",(O8/$O$23)) -> 1.6789161 | P31: =IF(P8="","",(P8/$O$23)) -> 2.2604843 | Q31: =IF(Q8="","",(Q8/$O$23)) -> 0 | R31: =IF(R8="","",(R8/$O$23)) -> 0.99412302 | S31: =IF(S8="","",(S8/$O$23)) -> 1.3429396 | T31: =IF(T8="","",(T8/$O$23)) -> 0.58110605 | U31: =IF(U8="","",(U8/$O$23)) -> 1.0421305 | V31: =IF(V8="","",(V8/$O$23)) -> 0.33756469
B32: =IF(B9="","",(B9/$O$23)) -> 0 | C32: =IF(C9="","",(C9/$O$23)) -> 0.0088989821 | D32: =IF(D9="","",(D9/$O$23)) -> 0.81912651 | E32: =IF(E9="","",(E9/$O$23)) -> 1.143036 | F32: =IF(F9="","",(F9/$O$23)) -> 0.046965449 | G32: =IF(G9="","",(G9/$O$23)) -> 0.86163827 | H32: =IF(H9="","",(H9/$O$23)) -> 2.1098066 | I32: =IF(I9="","",(I9/$O$23)) -> 0 | ... M32: =IF(M9="","",(M9/$O$23)) -> 0.031125429 | O32: =IF(O9="","",(O9/$O$23)) -> 1.147288 | P32: =IF(P9="","",(P9/$O$23)) -> 2.0795719 | Q32: =IF(Q9="","",(Q9/$O$23)) -> 0.045368842 | R32: =IF(R9="","",(R9/$O$23)) -> 0.24933956 | S32: =IF(S9="","",(S9/$O$23)) -> 1.4129466 | T32: =IF(T9="","",(T9/$O$23)) -> 1.3717457 | U32: =IF(U9="","",(U9/$O$23)) -> 0.60066028 | V32: =IF(V9="","",(V9/$O$23)) -> 1.4059971
B33: =IF(B10="","",(B10/$O$23)) -> 0 | C33: =IF(C10="","",(C10/$O$23)) -> 0.11335908 | D33: =IF(D10="","",(D10/$O$23)) -> 0 | E33: =IF(E10="","",(E10/$O$23)) -> 1.7779393 | F33: =IF(F10="","",(F10/$O$23)) -> 0.18854246 | G33: =IF(G10="","",(G10/$O$23)) -> 1.8039808 | H33: =IF(H10="","",(H10/$O$23)) -> 2.0972102 | I33: =IF(I10="","",(I10/$O$23)) -> 0 | ... M33: =IF(M10="","",(M10/$O$23)) -> 0 | O33: =IF(O10="","",(O10/$O$23)) -> 1.5736325 | P33: =IF(P10="","",(P10/$O$23)) -> 1.5500783 | Q33: =IF(Q10="","",(Q10/$O$23)) -> 0 | R33: =IF(R10="","",(R10/$O$23)) -> 0.96888823 | S33: =IF(S10="","",(S10/$O$23)) -> 1.2755628 | T33: =IF(T10="","",(T10/$O$23)) -> 0.70528844 | U33: =IF(U10="","",(U10/$O$23)) -> 1.1054569 | V33: =IF(V10="","",(V10/$O$23)) -> 0
B34: =IF(B11="","",(B11/$O$23)) -> 0 | C34: =IF(C11="","",(C11/$O$23)) -> 0 | D34: =IF(D11="","",(D11/$O$23)) -> 0.0027730539 | E34: =IF(E11="","",(E11/$O$23)) -> 2.1035463 | F34: =IF(F11="","",(F11/$O$23)) -> 1.4868443 | G34: =IF(G11="","",(G11/$O$23)) -> 2.3778265 | H34: =IF(H11="","",(H11/$O$23)) -> 2.5839316 | I34: =IF(I11="","",(I11/$O$23)) -> 0 | ... M34: =IF(M11="","",(M11/$O$23)) -> 0 | O34: =IF(O11="","",(O11/$O$23)) -> 0 | P34: =IF(P11="","",(P11/$O$23)) -> 1.6351943 | Q34: =IF(Q11="","",(Q11/$O$23)) -> 0.018327365 | R34: =IF(R11="","",(R11/$O$23)) -> 0.9075113 | S34: =IF(S11="","",(S11/$O$23)) -> 1.879223 | T34: =IF(T11="","",(T11/$O$23)) -> 0.55524942 | U34: =IF(U11="","",(U11/$O$23)) -> 0.13506453 | V34: =IF(V11="","",(V11/$O$23)) -> 0.86731882
B35: =IF(B12="","",(B12/$O$23)) -> 0.00073107785 | C35: =IF(C12="","",(C12/$O$23)) -> 0 | D35: =IF(D12="","",(D12/$O$23)) -> 0.0054368663 | E35: =IF(E12="","",(E12/$O$23)) -> 0.81337872 | F35: =IF(F12="","",(F12/$O$23)) -> 0.13292172 | G35: =IF(G12="","",(G12/$O$23)) -> 0.67809571 | H35: =IF(H12="","",(H12/$O$23)) -> 2.3933052 | I35: =IF(I12="","",(I12/$O$23)) -> 0.0071931338 | ... M35: =IF(M12="","",(M12/$O$23)) -> 0.036528683 | O35: =IF(O12="","",(O12/$O$23)) -> 1.119734 | P35: =IF(P12="","",(P12/$O$23)) -> 2.0742863 | Q35: =IF(Q12="","",(Q12/$O$23)) -> 0 | R35: =IF(R12="","",(R12/$O$23)) -> 0.92456138 | S35: =IF(S12="","",(S12/$O$23)) -> 1.0883648 | T35: =IF(T12="","",(T12/$O$23)) -> 0 | U35: =IF(U12="","",(U12/$O$23)) -> 0.99313984 | V35: =IF(V12="","",(V12/$O$23)) -> 0.35752228
B36: =IF(B13="","",(B13/$O$23)) | C36: =IF(C13="","",(C13/$O$23)) | D36: =IF(D13="","",(D13/$O$23)) | E36: =IF(E13="","",(E13/$O$23)) | F36: =IF(F13="","",(F13/$O$23)) | G36: =IF(G13="","",(G13/$O$23)) | H36: =IF(H13="","",(H13/$O$23)) | I36: =IF(I13="","",(I13/$O$23)) | ... M36: =IF(M13="","",(M13/$O$23)) | O36: =IF(O13="","",(O13/$O$23)) -> 1.6185307 | P36: =IF(P13="","",(P13/$O$23)) | Q36: =IF(Q13="","",(Q13/$O$23)) | R36: =IF(R13="","",(R13/$O$23)) | S36: =IF(S13="","",(S13/$O$23)) | T36: =IF(T13="","",(T13/$O$23)) | U36: =IF(U13="","",(U13/$O$23)) | V36: =IF(V13="","",(V13/$O$23))
B37: =IF(B14="","",(B14/$O$23)) | C37: =IF(C14="","",(C14/$O$23)) | D37: =IF(D14="","",(D14/$O$23)) | E37: =IF(E14="","",(E14/$O$23)) | F37: =IF(F14="","",(F14/$O$23)) | G37: =IF(G14="","",(G14/$O$23)) | H37: =IF(H14="","",(H14/$O$23)) | I37: =IF(I14="","",(I14/$O$23)) | ... M37: =IF(M14="","",(M14/$O$23)) | O37: =IF(O14="","",(O14/$O$23)) -> 1.8206443 | P37: =IF(P14="","",(P14/$O$23)) | Q37: =IF(Q14="","",(Q14/$O$23)) | R37: =IF(R14="","",(R14/$O$23)) | S37: =IF(S14="","",(S14/$O$23)) | T37: =IF(T14="","",(T14/$O$23)) | U37: =IF(U14="","",(U14/$O$23)) | V37: =IF(V14="","",(V14/$O$23))
B38: =IF(B15="","",(B15/$O$23)) | C38: =IF(C15="","",(C15/$O$23)) | D38: =IF(D15="","",(D15/$O$23)) | E38: =IF(E15="","",(E15/$O$23)) | F38: =IF(F15="","",(F15/$O$23)) | G38: =IF(G15="","",(G15/$O$23)) | H38: =IF(H15="","",(H15/$O$23)) | I38: =IF(I15="","",(I15/$O$23)) | ... M38: =IF(M15="","",(M15/$O$23)) | O38: =IF(O15="","",(O15/$O$23)) -> 2.2038636 | P38: =IF(P15="","",(P15/$O$23)) | Q38: =IF(Q15="","",(Q15/$O$23)) | R38: =IF(R15="","",(R15/$O$23)) | S38: =IF(S15="","",(S15/$O$23)) | T38: =IF(T15="","",(T15/$O$23)) | U38: =IF(U15="","",(U15/$O$23)) | V38: =IF(V15="","",(V15/$O$23))
B39: =IF(B16="","",(B16/$O$23)) | C39: =IF(C16="","",(C16/$O$23)) | D39: =IF(D16="","",(D16/$O$23)) | E39: =IF(E16="","",(E16/$O$23)) | F39: =IF(F16="","",(F16/$O$23)) | G39: =IF(G16="","",(G16/$O$23)) | H39: =IF(H16="","",(H16/$O$23)) | I39: =IF(I16="","",(I16/$O$23)) | ... M39: =IF(M16="","",(M16/$O$23)) | O39: =IF(O16="","",(O16/$O$23)) -> 0.54395553 | P39: =IF(P16="","",(P16/$O$23)) | Q39: =IF(Q16="","",(Q16/$O$23)) | R39: =IF(R16="","",(R16/$O$23)) | S39: =IF(S16="","",(S16/$O$23)) | T39: =IF(T16="","",(T16/$O$23)) | U39: =IF(U16="","",(U16/$O$23)) | V39: =IF(V16="","",(V16/$O$23))
B40: =IF(B17="","",(B17/$O$23)) | C40: =IF(C17="","",(C17/$O$23)) | D40: =IF(D17="","",(D17/$O$23)) | E40: =IF(E17="","",(E17/$O$23)) | F40: =IF(F17="","",(F17/$O$23)) | G40: =IF(G17="","",(G17/$O$23)) | H40: =IF(H17="","",(H17/$O$23)) | I40: =IF(I17="","",(I17/$O$23)) | ... M40: =IF(M17="","",(M17/$O$23)) | O40: =IF(O17="","",(O17/$O$23)) -> 1.4561642 | P40: =IF(P17="","",(P17/$O$23)) | Q40: =IF(Q17="","",(Q17/$O$23)) | R40: =IF(R17="","",(R17/$O$23)) | S40: =IF(S17="","",(S17/$O$23)) | T40: =IF(T17="","",(T17/$O$23)) | U40: =IF(U17="","",(U17/$O$23)) | V40: =IF(V17="","",(V17/$O$23))
... B43: =IF(B20="","",(B20/$O$23)) | C43: =IF(C20="","",(C20/$O$23)) | D43: =IF(D20="","",(D20/$O$23)) | E43: =IF(E20="","",(E20/$O$23)) | F43: =IF(F20="","",(F20/$O$23)) | G43: =IF(G20="","",(G20/$O$23)) | H43: =IF(H20="","",(H20/$O$23)) | I43: =IF(I20="","",(I20/$O$23)) | ... M43: =IF(M20="","",(M20/$O$23)) | O43: =IF(O20="","",(O20/$O$23)) -> 0.22253337 | P43: =IF(P20="","",(P20/$O$23)) | Q43: =IF(Q20="","",(Q20/$O$23)) | R43: =IF(R20="","",(R20/$O$23)) | S43: =IF(S20="","",(S20/$O$23)) | T43: =IF(T20="","",(T20/$O$23)) | U43: =IF(U20="","",(U20/$O$23)) | V43: =IF(V20="","",(V20/$O$23))
A45: =A4 -> Group names | B45: =B4 -> Solvent control | C45: =C4 -> EE2-33.8ng/L | D45: =D4 -> EE2-50.6ng/L | E45: =E4 -> EE2-76ng/L | F45: =F4 -> EE2-114ng/L | G45: =G4 -> EE2-170.9ng/L | H45: =H4 -> EE2-488ng/L | ... M45: =M4 -> saccharin-100mg/L | O45: =O4 -> Testo -30µg/L | P45: =P4 -> Testo 30µg/L + EE2 -64ng/L | Q45: =Q4 -> Testo 30µg/L + FAD-10mg/L | R45: =R4 -> saccharin-0.01mg/L + Testostérone | S45: =S4 -> saccharin-0.1mg/L + Testostérone | T45: =T4 -> saccharin-1mg/L + Testostérone | U45: =U4 -> saccharin-10mg/L + Testostérone | V45: =V4 -> saccharin-100mg/L + Testostérone
A46: mean | B46: =AVERAGE(B28:B43) -> 9.1384731e-05 | C46: =AVERAGE(C28:C43) -> 0.015456624 | D46: =AVERAGE(D28:D43) -> 0.10586553 | E46: =AVERAGE(E28:E43) -> 1.5633806 | F46: =AVERAGE(F28:F43) -> 0.78410935 | G46: =AVERAGE(G28:G43) -> 1.5402077 | H46: =AVERAGE(H28:H43) -> 2.2499404 | I46: =AVERAGE(I28:I43) -> 0.011701447 | ... M46: =AVERAGE(M28:M43) -> 0.0088874277 | N46: mean | O46: =AVERAGE(O28:O43) -> 1 | P46: =AVERAGE(P28:P43) -> 1.8147505 | Q46: =AVERAGE(Q28:Q43) -> 0.019243313 | R46: =AVERAGE(R28:R43) -> 0.84562283 | S46: =AVERAGE(S28:S43) -> 1.0185879 | T46: =AVERAGE(T28:T43) -> 0.61284071 | U46: =AVERAGE(U28:U43) -> 0.73676681 | V46: =AVERAGE(V28:V43) -> 0.83688351
A47: SD | B47: =STDEV(B28:B43) -> 0.00025847505 | C47: =STDEV(C28:C43) -> 0.03967756 | D47: =STDEV(D28:D43) -> 0.28827791 | E47: =STDEV(E28:E43) -> 0.47315219 | F47: =STDEV(F28:F43) -> 0.77666295 | G47: =STDEV(G28:G43) -> 0.58192943 | H47: =STDEV(H28:H43) -> 0.31291244 | I47: =STDEV(I28:I43) -> 0.020910737 | ... M47: =STDEV(M28:M43) -> 0.015506295 | N47: SD | O47: =STDEV(O28:O43) -> 0.68269257 | P47: =STDEV(P28:P43) -> 0.38202334 | Q47: =STDEV(Q28:Q43) -> 0.031584273 | R47: =STDEV(R28:R43) -> 0.29390022 | S47: =STDEV(S28:S43) -> 0.57535981 | T47: =STDEV(T28:T43) -> 0.41828126 | U47: =STDEV(U28:U43) -> 0.39833139 | V47: =STDEV(V28:V43) -> 0.54990188
...

Sheet R3
A3: R3 | B3: Unspiked | O3: Testosterone spiked
A4: Group names | B4: ='Front page'!A7 -> Solvent control | C4: ='Front page'!A8 -> EE2-33.8ng/L | D4: ='Front page'!A9 -> EE2-50.6ng/L | E4: ='Front page'!A10 -> EE2-76ng/L | F4: ='Front page'!A11 -> EE2-114ng/L | G4: ='Front page'!A12 -> EE2-170.9ng/L | H4: ='Front page'!A13 -> EE2-488ng/L | I4: ='Front page'!A14 -> saccharin-0.01mg/L | J4: ='Front page'!A15 -> saccharin-0.1mg/L | K4: ='Front page'!A16 -> saccharin-1mg/L | L4: ='Front page'!A17 -> saccharin-10mg/L | M4: ='Front page'!A18 -> saccharin-100mg/L | O4: ='Front page'!A35 -> Testo -30µg/L | P4: ='Front page'!A36 -> Testo 30µg/L + EE2 -64ng/L | Q4: ='Front page'!A37 -> Testo 30µg/L + FAD-10mg/L | R4: ='Front page'!A38 -> saccharin-0.01mg/L + Testostérone | S4: ='Front page'!A39 -> saccharin-0.1mg/L + Testostérone | T4: ='Front page'!A40 -> saccharin-1mg/L + Testostérone | U4: ='Front page'!A41 -> saccharin-10mg/L + Testostérone | V4: ='Front page'!A42 -> saccharin-100mg/L + Testostérone
A5: Raw data | B5: 0 | C5: 0 | D5: 0 | E5: 0 | F5: 52475 | G5: 54307 | H5: 106122 | I5: 0 | J5: 0 | K5: 0 | L5: 0 | M5: 0 | O5: 47835 | P5: 5883 | Q5: 0 | R5: 96860 | S5: 66062 | T5: 42480 | U5: 0 | V5: 163
B6: 0 | C6: 0 | D6: 0 | E6: 0 | F6: 211081 | G6: 92689 | H6: 192967 | I6: 0 | J6: 0 | K6: 0 | L6: 0 | M6: 0 | O6: 10534 | P6: 1529 | Q6: 0 | R6: 7005 | S6: 8986 | T6: 18706 | U6: 114151 | V6: 48290
B7: 0 | C7: 0 | D7: 0 | E7: 0 | F7: 0 | G7: 136990 | H7: 172745 | I7: 0 | J7: 0 | K7: 0 | L7: 0 | M7: 0 | O7: 44609 | P7: 126357 | Q7: 0 | R7: 2011 | S7: 45794 | T7: 90455 | U7: 11776 | V7: 40156
B8: 0 | C8: 0 | D8: 0 | E8: 0 | F8: 0 | G8: 70243 | H8: 209811 | I8: 0 | J8: 0 | K8: 0 | L8: 0 | M8: 0 | O8: 57787 | P8: 90174 | Q8: 0 | R8: 1702 | S8: 0 | T8: 0 | U8: 18398 | V8: 0
B9: 0 | C9: 81 | D9: 0 | E9: 0 | F9: 106698 | G9: 69626 | H9: 172250 | I9: 0 | J9: 0 | K9: 0 | L9: 0 | M9: 0 | O9: 0 | P9: 153928 | Q9: 0 | R9: 0 | S9: 0 | T9: 320 | U9: 651 | V9: 88565
B10: 0 | C10: 0 | D10: 83 | E10: 82 | F10: 123728 | G10: 157763 | H10: 259945 | I10: 0 | J10: 0 | K10: 0 | L10: 0 | M10: 0 | O10: 60007 | P10: 129585 | Q10: 0 | R10: 3134 | S10: 35224 | T10: 0 | U10: 2285 | V10: 17754
B11: 0 | C11: 0 | D11: 0 | E11: 0 | F11: 3823 | G11: 149843 | H11: 103603 | I11: 0 | J11: 0 | K11: 0 | L11: 0 | M11: 0 | O11: 2507 | P11: 145089 | Q11: 0 | R11: 0 | S11: 0 | T11: 0 | U11: 15190 | V11: 4885
B12: 0 | C12: 0 | D12: 0 | E12: 0 | F12: 0 | G12: 159596 | H12: 208410 | I12: 0 | K12: 0 | L12: 0 | M12: 0 | O12: 40737 | P12: 90735 | Q12: 4885 | R12: 0 | S12: 11039 | T12: 0 | U12: 9549 | V12: 484
O13: 322
O14: 44157
O15: 15081
O16: 94613
O17: 100512
O18: 405
O19: 77951
O20: 97388
A22: =A4 -> Group names | B22: =B4 -> Solvent control | C22: =C4 -> EE2-33.8ng/L | D22: =D4 -> EE2-50.6ng/L | E22: =E4 -> EE2-76ng/L | F22: =F4 -> EE2-114ng/L | G22: =G4 -> EE2-170.9ng/L | H22: =H4 -> EE2-488ng/L | ... M22: =M4 -> saccharin-100mg/L | N22: Noms des groupes | O22: =O4 -> Testo -30µg/L | P22: =P4 -> Testo 30µg/L + EE2 -64ng/L | Q22: =Q4 -> Testo 30µg/L + FAD-10mg/L | R22: =R4 -> saccharin-0.01mg/L + Testostérone | S22: =S4 -> saccharin-0.1mg/L + Testostérone | T22: =T4 -> saccharin-1mg/L + Testostérone | U22: =U4 -> saccharin-10mg/L + Testostérone | V22: =V4 -> saccharin-100mg/L + Testostérone
A23: mean | B23: =AVERAGE(B5:B20) -> 0 | C23: =AVERAGE(C5:C20) -> 10.125 | D23: =AVERAGE(D5:D20) -> 10.375 | E23: =AVERAGE(E5:E20) -> 10.25 | F23: =AVERAGE(F5:F20) -> 62225.625 | G23: =AVERAGE(G5:G20) -> 111382.12 | H23: =AVERAGE(H5:H20) -> 178231.62 | I23: =AVERAGE(I5:I20) -> 0 | J23: =AVERAGE(J5:J20) -> 0 | L23: =AVERAGE(L5:L20) -> 0 | N23: mean | O23: =AVERAGE(O5:O20) -> 43402.812 | P23: =AVERAGE(P5:P20) -> 92910 | Q23: =AVERAGE(Q5:Q20) -> 610.625 | R23: =AVERAGE(R5:R20) -> 13839 | S23: =AVERAGE(S5:S20) -> 20888.125 | T23: =AVERAGE(T5:T20) -> 18995.125 | U23: =AVERAGE(U5:U20) -> 21500 | V23: =AVERAGE(V5:V20) -> 25037.125
A24: SD | B24: =STDEV(B5:B20) -> 0 | C24: =STDEV(C5:C20) -> 28.637825 | D24: =STDEV(D5:D20) -> 29.344931 | E24: =STDEV(E5:E20) -> 28.991378 | F24: =STDEV(F5:F20) -> 78413.085 | G24: =STDEV(G5:G20) -> 44164.902 | H24: =STDEV(H5:H20) -> 52965.367 | I24: =STDEV(I5:I20) -> 0 | J24: =STDEV(J5:J20) -> 0 | L24: =STDEV(L5:L20) -> 0 | N24: SD | O24: =STDEV(O5:O20) -> 36190.996 | P24: =STDEV(P5:P20) -> 59577.086 | Q24: =STDEV(Q5:Q20) -> 1727.1083 | R24: =STDEV(R5:R20) -> 33627.262 | S24: =STDEV(S5:S20) -> 25111.483 | T24: =STDEV(T5:T20) -> 32623.734 | U24: =STDEV(U5:U20) -> 38054.802 | V24: =STDEV(V5:V20) -> 31876.223
B26: Unspiked | O26: Testosterone spiked
A27: =A4 -> Group names | B27: =B4 -> Solvent control | C27: =C4 -> EE2-33.8ng/L | D27: =D4 -> EE2-50.6ng/L | E27: =E4 -> EE2-76ng/L | F27: =F4 -> EE2-114ng/L | G27: =G4 -> EE2-170.9ng/L | H27: =H4 -> EE2-488ng/L | ... M27: =M4 -> saccharin-100mg/L | O27: =O4 -> Testo -30µg/L | P27: =P4 -> Testo 30µg/L + EE2 -64ng/L | Q27: =Q4 -> Testo 30µg/L + FAD-10mg/L | R27: =R4 -> saccharin-0.01mg/L + Testostérone | S27: =S4 -> saccharin-0.1mg/L + Testostérone | T27: =T4 -> saccharin-1mg/L + Testostérone | U27: =U4 -> saccharin-10mg/L + Testostérone | V27: =V4 -> saccharin-100mg/L + Testostérone
A28: Data normalised to the "Testo" group | B28: =IF(B5="","",(B5/$O$23)) -> 0 | C28: =IF(C5="","",(C5/$O$23)) -> 0 | D28: =IF(D5="","",(D5/$O$23)) -> 0 | E28: =IF(E5="","",(E5/$O$23)) -> 0 | F28: =IF(F5="","",(F5/$O$23)) -> 1.209023 | G28: =IF(G5="","",(G5/$O$23)) -> 1.2512323 | H28: =IF(H5="","",(H5/$O$23)) -> 2.4450489 | I28: =IF(I5="","",(I5/$O$23)) -> 0 | ... M28: =IF(M5="","",(M5/$O$23)) -> 0 | O28: =IF(O5="","",(O5/$O$23)) -> 1.1021175 | P28: =IF(P5="","",(P5/$O$23)) -> 0.13554421 | Q28: =IF(Q5="","",(Q5/$O$23)) -> 0 | R28: =IF(R5="","",(R5/$O$23)) -> 2.2316526 | S28: =IF(S5="","",(S5/$O$23)) -> 1.5220673 | T28: =IF(T5="","",(T5/$O$23)) -> 0.97873842 | U28: =IF(U5="","",(U5/$O$23)) -> 0 | V28: =IF(V5="","",(V5/$O$23)) -> 0.003755517
B29: =IF(B6="","",(B6/$O$23)) -> 0 | C29: =IF(C6="","",(C6/$O$23)) -> 0 | D29: =IF(D6="","",(D6/$O$23)) -> 0 | E29: =IF(E6="","",(E6/$O$23)) -> 0 | F29: =IF(F6="","",(F6/$O$23)) -> 4.8633023 | G29: =IF(G6="","",(G6/$O$23)) -> 2.1355529 | H29: =IF(H6="","",(H6/$O$23)) -> 4.4459561 | I29: =IF(I6="","",(I6/$O$23)) -> 0 | ... M29: =IF(M6="","",(M6/$O$23)) -> 0 | O29: =IF(O6="","",(O6/$O$23)) -> 0.24270317 | P29: =IF(P6="","",(P6/$O$23)) -> 0.035228132 | Q29: =IF(Q6="","",(Q6/$O$23)) -> 0 | R29: =IF(R6="","",(R6/$O$23)) -> 0.16139507 | S29: =IF(S6="","",(S6/$O$23)) -> 0.20703727 | T29: =IF(T6="","",(T6/$O$23)) -> 0.4309859 | U29: =IF(U6="","",(U6/$O$23)) -> 2.6300369 | V29: =IF(V6="","",(V6/$O$23)) -> 1.1126007
B30: =IF(B7="","",(B7/$O$23)) -> 0 | C30: =IF(C7="","",(C7/$O$23)) -> 0 | D30: =IF(D7="","",(D7/$O$23)) -> 0 | E30: =IF(E7="","",(E7/$O$23)) -> 0 | F30: =IF(F7="","",(F7/$O$23)) -> 0 | G30: =IF(G7="","",(G7/$O$23)) -> 3.1562471 | H30: =IF(H7="","",(H7/$O$23)) -> 3.9800416 | I30: =IF(I7="","",(I7/$O$23)) -> 0 | ... M30: =IF(M7="","",(M7/$O$23)) -> 0 | O30: =IF(O7="","",(O7/$O$23)) -> 1.0277905 | P30: =IF(P7="","",(P7/$O$23)) -> 2.911263 | Q30: =IF(Q7="","",(Q7/$O$23)) -> 0 | R30: =IF(R7="","",(R7/$O$23)) -> 0.046333403 | S30: =IF(S7="","",(S7/$O$23)) -> 1.0550929 | T30: =IF(T7="","",(T7/$O$23)) -> 2.0840815 | U30: =IF(U7="","",(U7/$O$23)) -> 0.27131882 | V30: =IF(V7="","",(V7/$O$23)) -> 0.9251935
B31: =IF(B8="","",(B8/$O$23)) -> 0 | C31: =IF(C8="","",(C8/$O$23)) -> 0 | D31: =IF(D8="","",(D8/$O$23)) -> 0 | E31: =IF(E8="","",(E8/$O$23)) -> 0 | F31: =IF(F8="","",(F8/$O$23)) -> 0 | G31: =IF(G8="","",(G8/$O$23)) -> 1.6183974 | H31: =IF(H8="","",(H8/$O$23)) -> 4.8340416 | I31: =IF(I8="","",(I8/$O$23)) -> 0 | ... M31: =IF(M8="","",(M8/$O$23)) -> 0 | O31: =IF(O8="","",(O8/$O$23)) -> 1.3314114 | P31: =IF(P8="","",(P8/$O$23)) -> 2.0776073 | Q31: =IF(Q8="","",(Q8/$O$23)) -> 0 | R31: =IF(R8="","",(R8/$O$23)) -> 0.039214049 | S31: =IF(S8="","",(S8/$O$23)) -> 0 | T31: =IF(T8="","",(T8/$O$23)) -> 0 | U31: =IF(U8="","",(U8/$O$23)) -> 0.42388958 | V31: =IF(V8="","",(V8/$O$23)) -> 0
B32: =IF(B9="","",(B9/$O$23)) -> 0 | C32: =IF(C9="","",(C9/$O$23)) -> 0.0018662385 | D32: =IF(D9="","",(D9/$O$23)) -> 0 | E32: =IF(E9="","",(E9/$O$23)) -> 0 | F32: =IF(F9="","",(F9/$O$23)) -> 2.45832 | G32: =IF(G9="","",(G9/$O$23)) -> 1.6041818 | H32: =IF(H9="","",(H9/$O$23)) -> 3.9686368 | I32: =IF(I9="","",(I9/$O$23)) -> 0 | ... M32: =IF(M9="","",(M9/$O$23)) -> 0 | O32: =IF(O9="","",(O9/$O$23)) -> 0 | P32: =IF(P9="","",(P9/$O$23)) -> 3.5464983 | Q32: =IF(Q9="","",(Q9/$O$23)) -> 0 | R32: =IF(R9="","",(R9/$O$23)) -> 0 | S32: =IF(S9="","",(S9/$O$23)) -> 0 | T32: =IF(T9="","",(T9/$O$23)) -> 0.0073727941 | U32: =IF(U9="","",(U9/$O$23)) -> 0.014999028 | V32: =IF(V9="","",(V9/$O$23)) -> 2.040536
