Workbook

Sheet Front page
A2: R1 | B2: Experiment number : | E2: Date performed :20210602
A3: R2 | B3: Experiment number : | E3: Date performed :20210603
A4: R3 | B4: Experiment number : | E4: Date performed :20210609
A5: 2. Expérimentateur 1 : copier et coller la dilution appliquée et le nom donné pour chaque des échantillons par le client. Conserver la mise en forme de l'exemple en italique. Ne pas remplir la colonne "nom sur graphique".
A6: Do not fill in | B6: Do not fill in2 | C6: Concentration | D6: Units | E6: Chemical name | F6: Do not fill in3
A7: =IF(ISBLANK(liste_groupe[[#This Row],[Do not fill in2]])," ",IF(ISBLANK(liste_groupe[[#This Row],[Units]]),CONCATENATE(liste_groupe[[#This Row],[Chemical name]],liste_groupe[[#This Row],[Do not fill in3]]),CONCATENATE(liste_groupe[[#This Row],[Chemical name]],"-",liste_groupe[[#This Row],[Concentration]],liste_groupe[[#This Row],[Units]],liste_groupe[[#This Row],[Do not fill in3]]))) -> Solvent control | B7: Témoin | C7: 0 | E7: Solvent control
A8: =IF(ISBLANK(liste_groupe[[#This Row],[Do not fill in2]])," ",IF(ISBLANK(liste_groupe[[#This Row],[Units]]),CONCATENATE(liste_groupe[[#This Row],[Chemical name]],liste_groupe[[#This Row],[Do not fill in3]]),CONCATENATE(liste_groupe[[#This Row],[Chemical name]],"-",liste_groupe[[#This Row],[Concentration]],liste_groupe[[#This Row],[Units]],liste_groupe[[#This Row],[Do not fill in3]]))) -> EE2-33.8ng/L | B8: Témoin | C8: 33.8 | D8: ng/L | E8: EE2
A9: =IF(ISBLANK(liste_groupe[[#This Row],[Do not fill in2]])," ",IF(ISBLANK(liste_groupe[[#This Row],[Units]]),CONCATENATE(liste_groupe[[#This Row],[Chemical name]],liste_groupe[[#This Row],[Do not fill in3]]),CONCATENATE(liste_groupe[[#This Row],[Chemical name]],"-",liste_groupe[[#This Row],[Concentration]],liste_groupe[[#This Row],[Units]],liste_groupe[[#This Row],[Do not fill in3]]))) -> EE2-50.6ng/L | B9: Témoin | C9: 50.6 | D9: ng/L | E9: EE2
A10: =IF(ISBLANK(liste_groupe[[#This Row],[Do not fill in2]])," ",IF(ISBLANK(liste_groupe[[#This Row],[Units]]),CONCATENATE(liste_groupe[[#This Row],[Chemical name]],liste_groupe[[#This Row],[Do not fill in3]]),CONCATENATE(liste_groupe[[#This Row],[Chemical name]],"-",liste_groupe[[#This Row],[Concentration]],liste_groupe[[#This Row],[Units]],liste_groupe[[#This Row],[Do not fill in3]]))) -> EE2-76ng/L | B10: Témoin | C10: 76 | D10: ng/L | E10: EE2
A11: =IF(ISBLANK(liste_groupe[[#This Row],[Do not fill in2]])," ",IF(ISBLANK(liste_groupe[[#This Row],[Units]]),CONCATENATE(liste_groupe[[#This Row],[Chemical name]],liste_groupe[[#This Row],[Do not fill in3]]),CONCATENATE(liste_groupe[[#This Row],[Chemical name]],"-",liste_groupe[[#This Row],[Concentration]],liste_groupe[[#This Row],[Units]],liste_groupe[[#This Row],[Do not fill in3]]))) -> EE2-114ng/L | B11: Témoin | C11: 114 | D11: ng/L | E11: EE2
A12: =IF(ISBLANK(liste_groupe[[#This Row],[Do not fill in2]])," ",IF(ISBLANK(liste_groupe[[#This Row],[Units]]),CONCATENATE(liste_groupe[[#This Row],[Chemical name]],liste_groupe[[#This Row],[Do not fill in3]]),CONCATENATE(liste_groupe[[#This Row],[Chemical name]],"-",liste_groupe[[#This Row],[Concentration]],liste_groupe[[#This Row],[Units]],liste_groupe[[#This Row],[Do not fill in3]]))) -> EE2-170.9ng/L | B12: Témoin | C12: 170.9 | D12: ng/L | E12: EE2
A13: =IF(ISBLANK(liste_groupe[[#This Row],[Do not fill in2]])," ",IF(ISBLANK(liste_groupe[[#This Row],[Units]]),CONCATENATE(liste_groupe[[#This Row],[Chemical name]],liste_groupe[[#This Row],[Do not fill in3]]),CONCATENATE(liste_groupe[[#This Row],[Chemical name]],"-",liste_groupe[[#This Row],[Concentration]],liste_groupe[[#This Row],[Units]],liste_groupe[[#This Row],[Do not fill in3]]))) -> EE2-488ng/L | B13: Témoin | C13: 488 | D13: ng/L | E13: EE2
A14: =IF(ISBLANK(liste_groupe[[#This Row],[Do not fill in2]])," ",IF(ISBLANK(liste_groupe[[#This Row],[Units]]),CONCATENATE(liste_groupe[[#This Row],[Chemical name]],liste_groupe[[#This Row],[Do not fill in3]]),CONCATENATE(liste_groupe[[#This Row],[Chemical name]],"-",liste_groupe[[#This Row],[Concentration]],liste_groupe[[#This Row],[Units]],liste_groupe[[#This Row],[Do not fill in3]]))) -> Dutasteride-1mg/L | B14: test chemical | C14: 1 | D14: mg/L | E14: Dutasteride
A15: =IF(ISBLANK(liste_groupe[[#This Row],[Do not fill in2]])," ",IF(ISBLANK(liste_groupe[[#This Row],[Units]]),CONCATENATE(liste_groupe[[#This Row],[Chemical name]],liste_groupe[[#This Row],[Do not fill in3]]),CONCATENATE(liste_groupe[[#This Row],[Chemical name]],"-",liste_groupe[[#This Row],[Concentration]],liste_groupe[[#This Row],[Units]],liste_groupe[[#This Row],[Do not fill in3]]))) -> Dutasteride-0.5mg/L | B15: test chemical | C15: 0.5 | D15: mg/L | E15: Dutasteride
A16: =IF(ISBLANK(liste_groupe[[#This Row],[Do not fill in2]])," ",IF(ISBLANK(liste_groupe[[#This Row],[Units]]),CONCATENATE(liste_groupe[[#This Row],[Chemical name]],liste_groupe[[#This Row],[Do not fill in3]]),CONCATENATE(liste_groupe[[#This Row],[Chemical name]],"-",liste_groupe[[#This Row],[Concentration]],liste_groupe[[#This Row],[Units]],liste_groupe[[#This Row],[Do not fill in3]]))) -> Dutasteride-0.25mg/L | B16: test chemical | C16: 0.25 | D16: mg/L | E16: Dutasteride
A17: =IF(ISBLANK(liste_groupe[[#This Row],[Do not fill in2]])," ",IF(ISBLANK(liste_groupe[[#This Row],[Units]]),CONCATENATE(liste_groupe[[#This Row],[Chemical name]],liste_groupe[[#This Row],[Do not fill in3]]),CONCATENATE(liste_groupe[[#This Row],[Chemical name]],"-",liste_groupe[[#This Row],[Concentration]],liste_groupe[[#This Row],[Units]],liste_groupe[[#This Row],[Do not fill in3]]))) -> Dutasteride-0.1mg/L | B17: test chemical | C17: 0.1 | D17: mg/L | E17: Dutasteride
A18: =IF(ISBLANK(liste_groupe[[#This Row],[Do not fill in2]])," ",IF(ISBLANK(liste_groupe[[#This Row],[Units]]),CONCATENATE(liste_groupe[[#This Row],[Chemical name]],liste_groupe[[#This Row],[Do not fill in3]]),CONCATENATE(liste_groupe[[#This Row],[Chemical name]],"-",liste_groupe[[#This Row],[Concentration]],liste_groupe[[#This Row],[Units]],liste_groupe[[#This Row],[Do not fill in3]]))) -> Dutasteride-0.01mg/L | B18: test chemical | C18: 0.01 | D18: mg/L | E18: Dutasteride
A19: =IF(ISBLANK(liste_groupe[[#This Row],[Do not fill in2]])," ",IF(ISBLANK(liste_groupe[[#This Row],[Units]]),CONCATENATE(liste_groupe[[#This Row],[Chemical name]],liste_groupe[[#This Row],[Do not fill in3]]),CONCATENATE(liste_groupe[[#This Row],[Chemical name]],"-",liste_groupe[[#This Row],[Concentration]],liste_groupe[[#This Row],[Units]],liste_groupe[[#This Row],[Do not fill in3]]))) | B19: test chemical
A20: =IF(ISBLANK(liste_groupe[[#This Row],[Do not fill in2]])," ",IF(ISBLANK(liste_groupe[[#This Row],[Units]]),CONCATENATE(liste_groupe[[#This Row],[Chemical name]],liste_groupe[[#This Row],[Do not fill in3]]),CONCATENATE(liste_groupe[[#This Row],[Chemical name]],"-",liste_groupe[[#This Row],[Concentration]],liste_groupe[[#This Row],[Units]],liste_groupe[[#This Row],[Do not fill in3]]))) | B20: test chemical
A21: =IF(ISBLANK(liste_groupe[[#This Row],[Do not fill in2]])," ",IF(ISBLANK(liste_groupe[[#This Row],[Units]]),CONCATENATE(liste_groupe[[#This Row],[Chemical name]],liste_groupe[[#This Row],[Do not fill in3]]),CONCATENATE(liste_groupe[[#This Row],[Chemical name]],"-",liste_groupe[[#This Row],[Concentration]],liste_groupe[[#This Row],[Units]],liste_groupe[[#This Row],[Do not fill in3]]))) | B21: test chemical
A22: =IF(ISBLANK(liste_groupe[[#This Row],[Do not fill in2]])," ",IF(ISBLANK(liste_groupe[[#This Row],[Units]]),CONCATENATE(liste_groupe[[#This Row],[Chemical name]],liste_groupe[[#This Row],[Do not fill in3]]),CONCATENATE(liste_groupe[[#This Row],[Chemical name]],"-",liste_groupe[[#This Row],[Concentration]],liste_groupe[[#This Row],[Units]],liste_groupe[[#This Row],[Do not fill in3]]))) | B22: test chemical
A23: =IF(ISBLANK(liste_groupe[[#This Row],[Do not fill in2]])," ",IF(ISBLANK(liste_groupe[[#This Row],[Units]]),CONCATENATE(liste_groupe[[#This Row],[Chemical name]],liste_groupe[[#This Row],[Do not fill in3]]),CONCATENATE(liste_groupe[[#This Row],[Chemical name]],"-",liste_groupe[[#This Row],[Concentration]],liste_groupe[[#This Row],[Units]],liste_groupe[[#This Row],[Do not fill in3]]))) | B23: test chemical
A24: =IF(ISBLANK(liste_groupe[[#This Row],[Do not fill in2]])," ",IF(ISBLANK(liste_groupe[[#This Row],[Units]]),CONCATENATE(liste_groupe[[#This Row],[Chemical name]],liste_groupe[[#This Row],[Do not fill in3]]),CONCATENATE(liste_groupe[[#This Row],[Chemical name]],"-",liste_groupe[[#This Row],[Concentration]],liste_groupe[[#This Row],[Units]],liste_groupe[[#This Row],[Do not fill in3]]))) | B24: test chemical
A25: =IF(ISBLANK(liste_groupe[[#This Row],[Do not fill in2]])," ",IF(ISBLANK(liste_groupe[[#This Row],[Units]]),CONCATENATE(liste_groupe[[#This Row],[Chemical name]],liste_groupe[[#This Row],[Do not fill in3]]),CONCATENATE(liste_groupe[[#This Row],[Chemical name]],"-",liste_groupe[[#This Row],[Concentration]],liste_groupe[[#This Row],[Units]],liste_groupe[[#This Row],[Do not fill in3]]))) | B25: test chemical
A26: =IF(ISBLANK(liste_groupe[[#This Row],[Do not fill in2]])," ",IF(ISBLANK(liste_groupe[[#This Row],[Units]]),CONCATENATE(liste_groupe[[#This Row],[Chemical name]],liste_groupe[[#This Row],[Do not fill in3]]),CONCATENATE(liste_groupe[[#This Row],[Chemical name]],"-",liste_groupe[[#This Row],[Concentration]],liste_groupe[[#This Row],[Units]],liste_groupe[[#This Row],[Do not fill in3]]))) | B26: test chemical
A27: =IF(ISBLANK(liste_groupe[[#This Row],[Do not fill in2]])," ",IF(ISBLANK(liste_groupe[[#This Row],[Units]]),CONCATENATE(liste_groupe[[#This Row],[Chemical name]],liste_groupe[[#This Row],[Do not fill in3]]),CONCATENATE(liste_groupe[[#This Row],[Chemical name]],"-",liste_groupe[[#This Row],[Concentration]],liste_groupe[[#This Row],[Units]],liste_groupe[[#This Row],[Do not fill in3]]))) | B27: test chemical
A28: =IF(ISBLANK(liste_groupe[[#This Row],[Do not fill in2]])," ",IF(ISBLANK(liste_groupe[[#This Row],[Units]]),CONCATENATE(liste_groupe[[#This Row],[Chemical name]],liste_groupe[[#This Row],[Do not fill in3]]),CONCATENATE(liste_groupe[[#This Row],[Chemical name]],"-",liste_groupe[[#This Row],[Concentration]],liste_groupe[[#This Row],[Units]],liste_groupe[[#This Row],[Do not fill in3]]))) | B28: test chemical
A29: =IF(ISBLANK(liste_groupe[[#This Row],[Do not fill in2]])," ",IF(ISBLANK(liste_groupe[[#This Row],[Units]]),CONCATENATE(liste_groupe[[#This Row],[Chemical name]],liste_groupe[[#This Row],[Do not fill in3]]),CONCATENATE(liste_groupe[[#This Row],[Chemical name]],"-",liste_groupe[[#This Row],[Concentration]],liste_groupe[[#This Row],[Units]],liste_groupe[[#This Row],[Do not fill in3]]))) | B29: test chemical
A30: =IF(ISBLANK(liste_groupe[[#This Row],[Do not fill in2]])," ",IF(ISBLANK(liste_groupe[[#This Row],[Units]]),CONCATENATE(liste_groupe[[#This Row],[Chemical name]],liste_groupe[[#This Row],[Do not fill in3]]),CONCATENATE(liste_groupe[[#This Row],[Chemical name]],"-",liste_groupe[[#This Row],[Concentration]],liste_groupe[[#This Row],[Units]],liste_groupe[[#This Row],[Do not fill in3]]))) | B30: test chemical
... A34: =IF(ISBLANK(liste_groupe[[#This Row],[Do not fill in2]])," ",IF(ISBLANK(liste_groupe[[#This Row],[Units]]),CONCATENATE(liste_groupe[[#This Row],[Chemical name]],liste_groupe[[#This Row],[Do not fill in3]]),CONCATENATE(liste_groupe[[#This Row],[Chemical name]],"-",liste_groupe[[#This Row],[Concentration]],liste_groupe[[#This Row],[Units]],liste_groupe[[#This Row],[Do not fill in3]]))) | B34: test chemical
A35: =IF(ISBLANK(liste_groupe[[#This Row],[Do not fill in2]])," ",IF(ISBLANK(liste_groupe[[#This Row],[Units]]),CONCATENATE(liste_groupe[[#This Row],[Chemical name]],liste_groupe[[#This Row],[Do not fill in3]]),CONCATENATE(liste_groupe[[#This Row],[Chemical name]],"-",liste_groupe[[#This Row],[Concentration]],liste_groupe[[#This Row],[Units]],liste_groupe[[#This Row],[Do not fill in3]]))) -> Testo -30µg/L | B35: Témoin | C35: 30 | D35: µg/L | E35: Testo
A36: =IF(ISBLANK(liste_groupe[[#This Row],[Do not fill in2]])," ",IF(ISBLANK(liste_groupe[[#This Row],[Units]]),CONCATENATE(liste_groupe[[#This Row],[Chemical name]],liste_groupe[[#This Row],[Do not fill in3]]),CONCATENATE(liste_groupe[[#This Row],[Chemical name]],"-",liste_groupe[[#This Row],[Concentration]],liste_groupe[[#This Row],[Units]],liste_groupe[[#This Row],[Do not fill in3]]))) -> Testo 30µg/L + EE2 -64ng/L | B36: Témoin | C36: 64 | D36: ng/L | E36: Testo 30µg/L + EE2
A37: =IF(ISBLANK(liste_groupe[[#This Row],[Do not fill in2]])," ",IF(ISBLANK(liste_groupe[[#This Row],[Units]]),CONCATENATE(liste_groupe[[#This Row],[Chemical name]],liste_groupe[[#This Row],[Do not fill in3]]),CONCATENATE(liste_groupe[[#This Row],[Chemical name]],"-",liste_groupe[[#This Row],[Concentration]],liste_groupe[[#This Row],[Units]],liste_groupe[[#This Row],[Do not fill in3]]))) -> Testo 30µg/L + FAD-10mg/L | B37: Témoin | C37: 10 | D37: mg/L | E37: Testo 30µg/L + FAD
A38: =IF(ISBLANK(liste_groupe[[#This Row],[Do not fill in2]])," ",IF(ISBLANK(liste_groupe[[#This Row],[Units]]),CONCATENATE(liste_groupe[[#This Row],[Chemical name]],liste_groupe[[#This Row],[Do not fill in3]]),CONCATENATE(liste_groupe[[#This Row],[Chemical name]],"-",liste_groupe[[#This Row],[Concentration]],liste_groupe[[#This Row],[Units]],liste_groupe[[#This Row],[Do not fill in3]]))) -> Dutasteride-1mg/L + Testostérone | B38: =B14 -> test chemical | C38: =C14 -> 1 | D38: =D14 -> mg/L | E38: =E14 -> Dutasteride | F38: + Testostérone
A39: =IF(ISBLANK(liste_groupe[[#This Row],[Do not fill in2]])," ",IF(ISBLANK(liste_groupe[[#This Row],[Units]]),CONCATENATE(liste_groupe[[#This Row],[Chemical name]],liste_groupe[[#This Row],[Do not fill in3]]),CONCATENATE(liste_groupe[[#This Row],[Chemical name]],"-",liste_groupe[[#This Row],[Concentration]],liste_groupe[[#This Row],[Units]],liste_groupe[[#This Row],[Do not fill in3]]))) -> Dutasteride-0.5mg/L + Testostérone | B39: =B15 -> test chemical | C39: =C15 -> 0.5 | D39: =D15 -> mg/L | E39: =E15 -> Dutasteride | F39: + Testostérone
A40: =IF(ISBLANK(liste_groupe[[#This Row],[Do not fill in2]])," ",IF(ISBLANK(liste_groupe[[#This Row],[Units]]),CONCATENATE(liste_groupe[[#This Row],[Chemical name]],liste_groupe[[#This Row],[Do not fill in3]]),CONCATENATE(liste_groupe[[#This Row],[Chemical name]],"-",liste_groupe[[#This Row],[Concentration]],liste_groupe[[#This Row],[Units]],liste_groupe[[#This Row],[Do not fill in3]]))) -> Dutasteride-0.25mg/L + Testostérone | B40: =B16 -> test chemical | C40: =C16 -> 0.25 | D40: =D16 -> mg/L | E40: =E16 -> Dutasteride | F40: + Testostérone
A41: =IF(ISBLANK(liste_groupe[[#This Row],[Do not fill in2]])," ",IF(ISBLANK(liste_groupe[[#This Row],[Units]]),CONCATENATE(liste_groupe[[#This Row],[Chemical name]],liste_groupe[[#This Row],[Do not fill in3]]),CONCATENATE(liste_groupe[[#This Row],[Chemical name]],"-",liste_groupe[[#This Row],[Concentration]],liste_groupe[[#This Row],[Units]],liste_groupe[[#This Row],[Do not fill in3]]))) -> Dutasteride-0.1mg/L + Testostérone | B41: =B17 -> test chemical | C41: =C17 -> 0.1 | D41: =D17 -> mg/L | E41: =E17 -> Dutasteride | F41: + Testostérone
A42: =IF(ISBLANK(liste_groupe[[#This Row],[Do not fill in2]])," ",IF(ISBLANK(liste_groupe[[#This Row],[Units]]),CONCATENATE(liste_groupe[[#This Row],[Chemical name]],liste_groupe[[#This Row],[Do not fill in3]]),CONCATENATE(liste_groupe[[#This Row],[Chemical name]],"-",liste_groupe[[#This Row],[Concentration]],liste_groupe[[#This Row],[Units]],liste_groupe[[#This Row],[Do not fill in3]]))) -> Dutasteride-0.01mg/L + Testostérone | B42: =B18 -> test chemical | C42: =C18 -> 0.01 | D42: =D18 -> mg/L | E42: =E18 -> Dutasteride | F42: + Testostérone
A43: =IF(ISBLANK(liste_groupe[[#This Row],[Do not fill in2]])," ",IF(ISBLANK(liste_groupe[[#This Row],[Units]]),CONCATENATE(liste_groupe[[#This Row],[Chemical name]],liste_groupe[[#This Row],[Do not fill in3]]),CONCATENATE(liste_groupe[[#This Row],[Chemical name]],"-",liste_groupe[[#This Row],[Concentration]],liste_groupe[[#This Row],[Units]],liste_groupe[[#This Row],[Do not fill in3]]))) -> 0-00 + Testostérone | B43: =B19 -> test chemical | C43: =C19 -> 0 | D43: =D19 -> 0 | E43: =E19 -> 0 | F43: + Testostérone
A44: =IF(ISBLANK(liste_groupe[[#This Row],[Do not fill in2]])," ",IF(ISBLANK(liste_groupe[[#This Row],[Units]]),CONCATENATE(liste_groupe[[#This Row],[Chemical name]],liste_groupe[[#This Row],[Do not fill in3]]),CONCATENATE(liste_groupe[[#This Row],[Chemical name]],"-",liste_groupe[[#This Row],[Concentration]],liste_groupe[[#This Row],[Units]],liste_groupe[[#This Row],[Do not fill in3]]))) -> 0-00 + Testostérone | B44: =B20 -> test chemical | C44: =C20 -> 0 | D44: =D20 -> 0 | E44: =E20 -> 0 | F44: + Testostérone
...

Sheet R1
A1: 3. Expérimentateur 1 : copier et coller les valeurs des intensités totales de fluorescences obtenues dans le fichier raw data lors du traitement des images.
A3: R1 | B3: Non dopé | O3: avec testo
A4: Noms des groupes | B4: ='Front page'!A7 -> Solvent control | C4: ='Front page'!A8 -> EE2-33.8ng/L | D4: ='Front page'!A9 -> EE2-50.6ng/L | E4: ='Front page'!A10 -> EE2-76ng/L | F4: ='Front page'!A11 -> EE2-114ng/L | G4: ='Front page'!A12 -> EE2-170.9ng/L | H4: ='Front page'!A13 -> EE2-488ng/L | I4: ='Front page'!A14 -> Dutasteride-1mg/L | J4: ='Front page'!A15 -> Dutasteride-0.5mg/L | K4: ='Front page'!A16 -> Dutasteride-0.25mg/L | L4: ='Front page'!A17 -> Dutasteride-0.1mg/L | M4: ='Front page'!A18 -> Dutasteride-0.01mg/L | N4: ='Front page'!A19 | O4: ='Front page'!A35 -> Testo -30µg/L | P4: ='Front page'!A36 -> Testo 30µg/L + EE2 -64ng/L | Q4: ='Front page'!A37 -> Testo 30µg/L + FAD-10mg/L | R4: ='Front page'!A38 -> Dutasteride-1mg/L + Testostérone | S4: ='Front page'!A39 -> Dutasteride-0.5mg/L + Testostérone | T4: ='Front page'!A40 -> Dutasteride-0.25mg/L + Testostérone | U4: ='Front page'!A41 -> Dutasteride-0.1mg/L + Testostérone | V4: ='Front page'!A42 -> Dutasteride-0.01mg/L + Testostérone
A5: Données brutes ローデータ | B5: 1032709 | C5: 2299530 | D5: 2122657 | E5: 11206942 | F5: 5788179 | G5: 14380382 | H5: 16381498 | I5: 1318807 | J5: 715082 | K5: 1004469 | L5: 38503 | M5: 712400 | O5: 7360714 | P5: 9927719 | Q5: 828988 | R5: 13208384 | S5: 5199250 | T5: 3668191 | U5: 12043901 | V5: 7976935
B6: 854313 | C6: 3057768 | D6: 4189516 | E6: 1297234 | F6: 8493152 | G6: 15053382 | H6: 19395577 | I6: 2174167 | J6: 0 | K6: 1457165 | L6: 89486 | M6: 1540029 | O6: 4066439 | P6: 8617235 | Q6: 31531 | R6: 10000869 | S6: 11001233 | T6: 10310712 | U6: 6305054 | V6: 4138448
B7: 55338 | C7: 3052599 | D7: 1424665 | E7: 6924664 | F7: 11243952 | G7: 9793547 | H7: 7099700 | I7: 1979505 | J7: 1960 | K7: 422747 | L7: 100909 | M7: 1902563 | O7: 5504108 | P7: 6740602 | Q7: 806489 | R7: 17053295 | S7: 12048802 | T7: 4276122 | U7: 14728978 | V7: 7182411
B8: 153624 | C8: 237510 | D8: 3764141 | E8: 4781817 | F8: 6618431 | G8: 16338893 | H8: 23090918 | I8: 290467 | J8: 304386 | K8: 3780 | L8: 790825 | M8: 971156 | O8: 11180636 | P8: 5480243 | Q8: 0 | R8: 8840097 | S8: 7370904 | T8: 6609412 | U8: 5109705 | V8: 6852352
B9: 23561 | C9: 1431170 | D9: 3430568 | E9: 4621523 | F9: 11454021 | G9: 11804479 | H9: 25544428 | I9: 1014901 | J9: 2446662 | K9: 432871 | L9: 524865 | M9: 1888392 | O9: 4429486 | P9: 10114823 | Q9: 0 | R9: 5186632 | S9: 11776380 | T9: 5935940 | U9: 13131661 | V9: 11509464
B10: 597453 | C10: 1968641 | D10: 4600272 | E10: 6675720 | F10: 7454765 | G10: 19779371 | H10: 21768963 | I10: 320098 | J10: 70569 | K10: 1151030 | L10: 3200904 | M10: 103646 | O10: 8975382 | P10: 7395563 | Q10: 108489 | R10: 7448516 | S10: 10368355 | T10: 11190868 | U10: 7973721 | V10: 4733848
B11: 372895 | C11: 877763 | D11: 4014608 | E11: 7618648 | F11: 9396807 | G11: 16420711 | H11: 18734589 | I11: 28415 | J11: 40564 | K11: 851365 | L11: 358315 | M11: 1437644 | O11: 3905752 | P11: 14208479 | Q11: 445482 | R11: 7829128 | S11: 6608385 | T11: 12213002 | U11: 11282880 | V11: 6205260
B12: 174862 | D12: 2654784 | E12: 4157396 | F12: 8932439 | G12: 16065467 | H12: 21527534 | I12: 1285414 | J12: 338256 | K12: 0 | L12: 61465 | M12: 0 | O12: 5340183 | P12: 5271590 | Q12: 113953 | R12: 14515394 | S12: 13472784 | T12: 8242548 | U12: 2842878 | V12: 5003194
O13: 4933720
O14: 8227349
O15: 6443247
O16: 2675558
O17: 5709691
O18: 7501272
O19: 7628636
A22: =A4 -> Noms des groupes | B22: =B4 -> Solvent control | C22: =C4 -> EE2-33.8ng/L | D22: =D4 -> EE2-50.6ng/L | E22: =E4 -> EE2-76ng/L | F22: =F4 -> EE2-114ng/L | G22: =G4 -> EE2-170.9ng/L | H22: =H4 -> EE2-488ng/L | ... V22: =V4 -> Dutasteride-0.01mg/L + Testostérone
A23: mean | B23: =AVERAGE(B5:B20) -> 408094.38 | C23: =AVERAGE(C5:C20) -> 1846425.9 | D23: =AVERAGE(D5:D20) -> 3275151.4 | E23: =AVERAGE(E5:E20) -> 5910493 | F23: =AVERAGE(F5:F20) -> 8672718.2 | G23: =AVERAGE(G5:G20) -> 14954529 | H23: =AVERAGE(H5:H20) -> 19192901 | I23: =AVERAGE(I5:I20) -> 1051471.8 | ... V23: =AVERAGE(V5:V20) -> 6700239
A24: SD | B24: =STDEV(B5:B20) -> 381314.58 | C24: =STDEV(C5:C20) -> 1067848.2 | D24: =STDEV(D5:D20) -> 1104501.7 | E24: =STDEV(E5:E20) -> 2924652.4 | F24: =STDEV(F5:F20) -> 2035224.3 | G24: =STDEV(G5:G20) -> 3058417 | H24: =STDEV(H5:H20) -> 5631843.9 | I24: =STDEV(I5:I20) -> 793716.91 | ... V24: =STDEV(V5:V20) -> 2347298.1
B26: Non dopé | O26: avec testo
A27: Noms des groupes | B27: =B4 -> Solvent control | C27: =C4 -> EE2-33.8ng/L | D27: =D4 -> EE2-50.6ng/L | E27: =E4 -> EE2-76ng/L | F27: =F4 -> EE2-114ng/L | G27: =G4 -> EE2-170.9ng/L | H27: =H4 -> EE2-488ng/L | I27: =I4 -> Dutasteride-1mg/L | ... V27: =V4 -> Dutasteride-0.01mg/L + Testostérone
A28: Données normalisées sur la moyenne du groupe "Testo" 「Testo」群の平均に関する標準化データ | B28: =IF(B5="","",(B5/$O$23)) -> 0.16500081 | C28: =IF(C5="","",(C5/$O$23)) -> 0.36740681 | D28: =IF(D5="","",(D5/$O$23)) -> 0.33914698 | E28: =IF(E5="","",(E5/$O$23)) -> 1.7905863 | F28: =IF(F5="","",(F5/$O$23)) -> 0.92480481 | G28: =IF(G5="","",(G5/$O$23)) -> 2.2976218 | H28: =IF(H5="","",(H5/$O$23)) -> 2.6173496 | I28: =IF(I5="","",(I5/$O$23)) -> 0.21071205 | ... V28: =IF(V5="","",(V5/$O$23)) -> 1.2745127
B29: =IF(B6="","",(B6/$O$23)) -> 0.13649764 | C29: =IF(C6="","",(C6/$O$23)) -> 0.48855409 | D29: =IF(D6="","",(D6/$O$23)) -> 0.66937884 | E29: =IF(E6="","",(E6/$O$23)) -> 0.20726523 | F29: =IF(F6="","",(F6/$O$23)) -> 1.3569912 | G29: =IF(G6="","",(G6/$O$23)) -> 2.4051502 | H29: =IF(H6="","",(H6/$O$23)) -> 3.0989233 | I29: =IF(I6="","",(I6/$O$23)) -> 0.34737697 | ... V29: =IF(V6="","",(V6/$O$23)) -> 0.66121946
B30: =IF(B7="","",(B7/$O$23)) -> 0.0088416147 | C30: =IF(C7="","",(C7/$O$23)) -> 0.48772822 | D30: =IF(D7="","",(D7/$O$23)) -> 0.22762548 | E30: =IF(E7="","",(E7/$O$23)) -> 1.1063864 | F30: =IF(F7="","",(F7/$O$23)) -> 1.7964995 | G30: =IF(G7="","",(G7/$O$23)) -> 1.5647614 | H30: =IF(H7="","",(H7/$O$23)) -> 1.1343527 | I30: =IF(I7="","",(I7/$O$23)) -> 0.3162749 | ... V30: =IF(V7="","",(V7/$O$23)) -> 1.1475679
B31: =IF(B8="","",(B8/$O$23)) -> 0.024545235 | C31: =IF(C8="","",(C8/$O$23)) -> 0.037948099 | D31: =IF(D8="","",(D8/$O$23)) -> 0.60141466 | E31: =IF(E8="","",(E8/$O$23)) -> 0.76401358 | F31: =IF(F8="","",(F8/$O$23)) -> 1.0574581 | G31: =IF(G8="","",(G8/$O$23)) -> 2.6105424 | H31: =IF(H8="","",(H8/$O$23)) -> 3.6893455 | I31: =IF(I8="","",(I8/$O$23)) -> 0.04640929 | ... V31: =IF(V8="","",(V8/$O$23)) -> 1.0948328
B32: =IF(B9="","",(B9/$O$23)) -> 0.0037644527 | C32: =IF(C9="","",(C9/$O$23)) -> 0.22866482 | D32: =IF(D9="","",(D9/$O$23)) -> 0.54811812 | E32: =IF(E9="","",(E9/$O$23)) -> 0.73840265 | F32: =IF(F9="","",(F9/$O$23)) -> 1.8300633 | G32: =IF(G9="","",(G9/$O$23)) -> 1.8860576 | H32: =IF(H9="","",(H9/$O$23)) -> 4.0813544 | I32: =IF(I9="","",(I9/$O$23)) -> 0.16215555 | ... V32: =IF(V9="","",(V9/$O$23)) -> 1.8389216
B33: =IF(B10="","",(B10/$O$23)) -> 0.095457899 | C33: =IF(C10="","",(C10/$O$23)) -> 0.31453911 | D33: =IF(D10="","",(D10/$O$23)) -> 0.73500727 | E33: =IF(E10="","",(E10/$O$23)) -> 1.0666114 | F33: =IF(F10="","",(F10/$O$23)) -> 1.1910832 | G33: =IF(G10="","",(G10/$O$23)) -> 3.1602439 | H33: =IF(H10="","",(H10/$O$23)) -> 3.4781305 | I33: =IF(I10="","",(I10/$O$23)) -> 0.051143575 | ... V33: =IF(V10="","",(V10/$O$23)) -> 0.75634934
B34: =IF(B11="","",(B11/$O$23)) -> 0.059579203 | C34: =IF(C11="","",(C11/$O$23)) -> 0.14024436 | D34: =IF(D11="","",(D11/$O$23)) -> 0.64143296 | E34: =IF(E11="","",(E11/$O$23)) -> 1.2172675 | F34: =IF(F11="","",(F11/$O$23)) -> 1.5013724 | G34: =IF(G11="","",(G11/$O$23)) -> 2.6236149 | H34: =IF(H11="","",(H11/$O$23)) -> 2.9933141 | I34: =IF(I11="","",(I11/$O$23)) -> 0.0045399993 | ... V34: =IF(V11="","",(V11/$O$23)) -> 0.99144382
B35: =IF(B12="","",(B12/$O$23)) -> 0.027938531 | C35: =IF(C12="","",(C12/$O$23)) | D35: =IF(D12="","",(D12/$O$23)) -> 0.42416743 | E35: =IF(E12="","",(E12/$O$23)) -> 0.66424687 | F35: =IF(F12="","",(F12/$O$23)) -> 1.4271781 | G35: =IF(G12="","",(G12/$O$23)) -> 2.5668559 | H35: =IF(H12="","",(H12/$O$23)) -> 3.4395562 | I35: =IF(I12="","",(I12/$O$23)) -> 0.20537669 | ... V35: =IF(V12="","",(V12/$O$23)) -> 0.79938403
B36: =IF(B13="","",(B13/$O$23)) | C36: =IF(C13="","",(C13/$O$23)) | D36: =IF(D13="","",(D13/$O$23)) | E36: =IF(E13="","",(E13/$O$23)) | F36: =IF(F13="","",(F13/$O$23)) | G36: =IF(G13="","",(G13/$O$23)) | H36: =IF(H13="","",(H13/$O$23)) | I36: =IF(I13="","",(I13/$O$23)) | ... V36: =IF(V13="","",(V13/$O$23))
B37: =IF(B14="","",(B14/$O$23)) | C37: =IF(C14="","",(C14/$O$23)) | D37: =IF(D14="","",(D14/$O$23)) | E37: =IF(E14="","",(E14/$O$23)) | F37: =IF(F14="","",(F14/$O$23)) | G37: =IF(G14="","",(G14/$O$23)) | H37: =IF(H14="","",(H14/$O$23)) | I37: =IF(I14="","",(I14/$O$23)) | ... V37: =IF(V14="","",(V14/$O$23))
B38: =IF(B15="","",(B15/$O$23)) | C38: =IF(C15="","",(C15/$O$23)) | D38: =IF(D15="","",(D15/$O$23)) | E38: =IF(E15="","",(E15/$O$23)) | F38: =IF(F15="","",(F15/$O$23)) | G38: =IF(G15="","",(G15/$O$23)) | H38: =IF(H15="","",(H15/$O$23)) | I38: =IF(I15="","",(I15/$O$23)) | ... V38: =IF(V15="","",(V15/$O$23))
B39: =IF(B16="","",(B16/$O$23)) | C39: =IF(C16="","",(C16/$O$23)) | D39: =IF(D16="","",(D16/$O$23)) | E39: =IF(E16="","",(E16/$O$23)) | F39: =IF(F16="","",(F16/$O$23)) | G39: =IF(G16="","",(G16/$O$23)) | H39: =IF(H16="","",(H16/$O$23)) | I39: =IF(I16="","",(I16/$O$23)) | ... V39: =IF(V16="","",(V16/$O$23))
B40: =IF(B17="","",(B17/$O$23)) | C40: =IF(C17="","",(C17/$O$23)) | D40: =IF(D17="","",(D17/$O$23)) | E40: =IF(E17="","",(E17/$O$23)) | F40: =IF(F17="","",(F17/$O$23)) | G40: =IF(G17="","",(G17/$O$23)) | H40: =IF(H17="","",(H17/$O$23)) | I40: =IF(I17="","",(I17/$O$23)) | ... V40: =IF(V17="","",(V17/$O$23))
... B43: =IF(B20="","",(B20/$O$23)) | C43: =IF(C20="","",(C20/$O$23)) | D43: =IF(D20="","",(D20/$O$23)) | E43: =IF(E20="","",(E20/$O$23)) | F43: =IF(F20="","",(F20/$O$23)) | G43: =IF(G20="","",(G20/$O$23)) | H43: =IF(H20="","",(H20/$O$23)) | I43: =IF(I20="","",(I20/$O$23)) | ... V43: =IF(V20="","",(V20/$O$23))
A45: =A4 -> Noms des groupes | B45: =B4 -> Solvent control | C45: =C4 -> EE2-33.8ng/L | D45: =D4 -> EE2-50.6ng/L | E45: =E4 -> EE2-76ng/L | F45: =F4 -> EE2-114ng/L | G45: =G4 -> EE2-170.9ng/L | H45: =H4 -> EE2-488ng/L | ... V45: =V4 -> Dutasteride-0.01mg/L + Testostérone
A46: mean | B46: =AVERAGE(B28:B43) -> 0.065203174 | C46: =AVERAGE(C28:C43) -> 0.29501222 | D46: =AVERAGE(D28:D43) -> 0.52328647 | E46: =AVERAGE(E28:E43) -> 0.9443475 | F46: =AVERAGE(F28:F43) -> 1.3856813 | G46: =AVERAGE(G28:G43) -> 2.389356 | H46: =AVERAGE(H28:H43) -> 3.0665408 | I46: =AVERAGE(I28:I43) -> 0.16799863 | ... V46: =AVERAGE(V28:V43) -> 1.070529
A47: SD | B47: =STDEV(B28:B43) -> 0.060924439 | C47: =STDEV(C28:C43) -> 0.17061517 | D47: =STDEV(D28:D43) -> 0.17647147 | E47: =STDEV(E28:E43) -> 0.46728558 | F47: =STDEV(F28:F43) -> 0.32517743 | G47: =STDEV(G28:G43) -> 0.4886578 | H47: =STDEV(H28:H43) -> 0.89982641 | I47: =STDEV(I28:I43) -> 0.12681592 | ... V47: =STDEV(V28:V43) -> 0.37503895
...

Sheet R2
A1: 6. Expérimentateur 2 : copier et coller les valeurs des intensités totales de fluorescences obtenues dans le fichier raw data lors du traitement des images. Ne pas supprimer les colonnes correspondant aux concentrations non lues.
A3: R2 | B3: Non dopé | O3: avec testo
A4: Noms des groupes | B4: ='Front page'!A7 -> Solvent control | C4: ='Front page'!A8 -> EE2-33.8ng/L | D4: ='Front page'!A9 -> EE2-50.6ng/L | E4: ='Front page'!A10 -> EE2-76ng/L | F4: ='Front page'!A11 -> EE2-114ng/L | G4: ='Front page'!A12 -> EE2-170.9ng/L | H4: ='Front page'!A13 -> EE2-488ng/L | I4: ='Front page'!A14 -> Dutasteride-1mg/L | J4: ='Front page'!A15 -> Dutasteride-0.5mg/L | K4: ='Front page'!A16 -> Dutasteride-0.25mg/L | L4: ='Front page'!A17 -> Dutasteride-0.1mg/L | M4: ='Front page'!A18 -> Dutasteride-0.01mg/L | N4: ='Front page'!A19 | O4: ='Front page'!A35 -> Testo -30µg/L | P4: ='Front page'!A36 -> Testo 30µg/L + EE2 -64ng/L | Q4: ='Front page'!A37 -> Testo 30µg/L + FAD-10mg/L | R4: ='Front page'!A38 -> Dutasteride-1mg/L + Testostérone | S4: ='Front page'!A39 -> Dutasteride-0.5mg/L + Testostérone | T4: ='Front page'!A40 -> Dutasteride-0.25mg/L + Testostérone | U4: ='Front page'!A41 -> Dutasteride-0.1mg/L + Testostérone | V4: ='Front page'!A42 -> Dutasteride-0.01mg/L + Testostérone
A5: Données brutes | B5: 2176826 | C5: 2512384 | D5: 5930300 | E5: 5536794 | F5: 9367053 | G5: 13051974 | H5: 17656948 | I5: 90104 | J5: 554105 | K5: 3164969 | L5: 1711796 | M5: 2040133 | O5: 12145370 | P5: 13440348 | Q5: 2622814 | R5: 165713 | S5: 14905792 | T5: 5851261 | U5: 4954281 | V5: 3776584
B6: 1186359 | C6: 1648932 | D6: 2173974 | E6: 5511764 | F6: 7643020 | G6: 8587876 | H6: 9610626 | I6: 126107 | J6: 1677545 | K6: 1719918 | L6: 3252376 | M6: 5436334 | O6: 10111023 | P6: 6432439 | Q6: 1086765 | R6: 5495953 | S6: 14681693 | T6: 3521689 | U6: 6255838 | V6: 9040971
B7: 438618 | C7: 5292 | D7: 0 | E7: 4527084 | F7: 6079702 | G7: 15119472 | H7: 22081109 | I7: 2446174 | J7: 1035135 | K7: 3060512 | L7: 1772011 | M7: 2947822 | O7: 2822701 | P7: 10448709 | Q7: 444538 | R7: 6255693 | S7: 4836169 | T7: 4393620 | U7: 8345826 | V7: 3520472
B8: 250513 | C8: 161676 | D8: 787147 | E8: 16487421 | F8: 10714273 | G8: 17914892 | H8: 24206065 | I8: 3042601 | J8: 1945341 | K8: 560 | L8: 305306 | M8: 4095718 | O8: 5996817 | P8: 12614815 | Q8: 120069 | R8: 6720741 | S8: 5812962 | T8: 5208940 | U8: 11050683 | V8: 2257482
B9: 316905 | C9: 2080776 | D9: 2500083 | E9: 3871358 | F9: 10815369 | G9: 20616214 | H9: 27035264 | I9: 201424 | J9: 2047136 | K9: 2948078 | L9: 1321141 | M9: 314310 | O9: 6738526 | P9: 9798293 | Q9: 14915 | R9: 6212995 | S9: 10713000 | T9: 3430786 | U9: 14760395 | V9: 10657329
B10: 0 | C10: 198388 | D10: 4942825 | E10: 7925963 | F10: 7503785 | G10: 15138368 | H10: 11653840 | I10: 85163 | J10: 823393 | K10: 291718 | L10: 1281421 | M10: 1646544 | O10: 2595968 | P10: 8004509 | Q10: 22557 | R10: 11403469 | S10: 1775015 | T10: 7416128 | U10: 3632066 | V10: 3242733
B11: 478407 | C11: 1595909 | D11: 6116961 | E11: 9220418 | F11: 10481745 | G11: 11948377 | H11: 19193317 | I11: 1168208 | J11: 1181618 | K11: 848557 | L11: 1320778 | M11: 2567875 | O11: 6837351 | P11: 13663378 | Q11: 432815 | R11: 12278275 | S11: 5476213 | T11: 16839800 | U11: 13581815 | V11: 12820260
B12: 748000 | C12: 2584350 | D12: 3202823 | E12: 1007091 | F12: 8112698 | G12: 13620596 | H12: 13190377 | I12: 1373761 | J12: 2903445 | K12: 728278 | L12: 1852265 | M12: 984827 | O12: 11239687 | P12: 14569606 | Q12: 1774111 | R12: 13744850 | S12: 14608495 | T12: 6953634 | U12: 5874049 | V12: 5870977
O13: 9546984
O14: 5424039
O15: 2399058
O16: 4950715
O17: 11264517
O18: 5999725
O19: 9264099
O20: 5243366
A22: =A4 -> Noms des groupes | B22: =B4 -> Solvent control | C22: =C4 -> EE2-33.8ng/L | D22: =D4 -> EE2-50.6ng/L | E22: =E4 -> EE2-76ng/L | F22: =F4 -> EE2-114ng/L | G22: =G4 -> EE2-170.9ng/L | H22: =H4 -> EE2-488ng/L | ... V22: =V4 -> Dutasteride-0.01mg/L + Testostérone
A23: mean | B23: =AVERAGE(B5:B20) -> 699453.5 | C23: =AVERAGE(C5:C20) -> 1348463.4 | D23: =AVERAGE(D5:D20) -> 3206764.1 | E23: =AVERAGE(E5:E20) -> 6760986.6 | F23: =AVERAGE(F5:F20) -> 8839705.6 | G23: =AVERAGE(G5:G20) -> 14499721 | H23: =AVERAGE(H5:H20) -> 18078443 | I23: =AVERAGE(I5:I20) -> 1066692.8 | J23: =AVERAGE(J5:J20) -> 1520964.8 | L23: =AVERAGE(L5:L20) -> 1602136.8 | N23: =AVERAGE(N5:N20) -> #DIV/0! | O23: =AVERAGE(O5:O20) -> 7036246.6 | P23: =AVERAGE(P5:P20) -> 11121512 | Q23: =AVERAGE(Q5:Q20) -> 814823 | R23: =AVERAGE(R5:R20) -> 7784711.1 | S23: =AVERAGE(S5:S20) -> 9101167.4 | T23: =AVERAGE(T5:T20) -> 6701982.2 | U23: =AVERAGE(U5:U20) -> 8556869.1 | V23: =AVERAGE(V5:V20) -> 6398351
A24: SD | B24: =STDEV(B5:B20) -> 694476.79 | C24: =STDEV(C5:C20) -> 1076048.8 | D24: =STDEV(D5:D20) -> 2286755.4 | E24: =STDEV(E5:E20) -> 4652438.6 | F24: =STDEV(F5:F20) -> 1762892.8 | G24: =STDEV(G5:G20) -> 3668299.3 | H24: =STDEV(H5:H20) -> 6234546.3 | I24: =STDEV(I5:I20) -> 1162650.7 | J24: =STDEV(J5:J20) -> 771393.11 | L24: =STDEV(L5:L20) -> 825442.4 | N24: =STDEV(N5:N20) -> #DIV/0! | O24: =STDEV(O5:O20) -> 3201992.3 | P24: =STDEV(P5:P20) -> 2924382.1 | Q24: =STDEV(Q5:Q20) -> 948403.16 | R24: =STDEV(R5:R20) -> 4440697.3 | S24: =STDEV(S5:S20) -> 5258732.9 | T24: =STDEV(T5:T20) -> 4349796.5 | U24: =STDEV(U5:U20) -> 4135595.6 | V24: =STDEV(V5:V20) -> 3944289.6
B26: Non dopé | O26: avec testo
A27: Noms des groupes | B27: =B4 -> Solvent control | C27: =C4 -> EE2-33.8ng/L | D27: =D4 -> EE2-50.6ng/L | E27: =E4 -> EE2-76ng/L | F27: =F4 -> EE2-114ng/L | G27: =G4 -> EE2-170.9ng/L | H27: =H4 -> EE2-488ng/L | I27: =I4 -> Dutasteride-1mg/L | ... V27: =V4 -> Dutasteride-0.01mg/L + Testostérone
A28: Données normalisées sur la moyenne du groupe "Testo" | B28: =IF(B5="","",(B5/$O$23)) -> 0.30937318 | C28: =IF(C5="","",(C5/$O$23)) -> 0.3570631 | D28: =IF(D5="","",(D5/$O$23)) -> 0.84282151 | E28: =IF(E5="","",(E5/$O$23)) -> 0.78689595 | F28: =IF(F5="","",(F5/$O$23)) -> 1.3312571 | G28: =IF(G5="","",(G5/$O$23)) -> 1.8549626 | H28: =IF(H5="","",(H5/$O$23)) -> 2.5094271 | I28: =IF(I5="","",(I5/$O$23)) -> 0.012805691 | ... V28: =IF(V5="","",(V5/$O$23)) -> 0.53673275
B29: =IF(B6="","",(B6/$O$23)) -> 0.1686068 | C29: =IF(C6="","",(C6/$O$23)) -> 0.23434824 | D29: =IF(D6="","",(D6/$O$23)) -> 0.30896785 | E29: =IF(E6="","",(E6/$O$23)) -> 0.78333866 | F29: =IF(F6="","",(F6/$O$23)) -> 1.0862354 | G29: =IF(G6="","",(G6/$O$23)) -> 1.2205195 | H29: =IF(H6="","",(H6/$O$23)) -> 1.365874 | I29: =IF(I6="","",(I6/$O$23)) -> 0.017922482 | ... V29: =IF(V6="","",(V6/$O$23)) -> 1.2849139
B30: =IF(B7="","",(B7/$O$23)) -> 0.062336928 | C30: =IF(C7="","",(C7/$O$23)) -> 0.00075210553 | D30: =IF(D7="","",(D7/$O$23)) -> 0 | E30: =IF(E7="","",(E7/$O$23)) -> 0.64339473 | F30: =IF(F7="","",(F7/$O$23)) -> 0.8640547 | G30: =IF(G7="","",(G7/$O$23)) -> 2.1487979 | H30: =IF(H7="","",(H7/$O$23)) -> 3.1381943 | I30: =IF(I7="","",(I7/$O$23)) -> 0.34765325 | ... V30: =IF(V7="","",(V7/$O$23)) -> 0.5003338
B31: =IF(B8="","",(B8/$O$23)) -> 0.035603215 | C31: =IF(C8="","",(C8/$O$23)) -> 0.022977591 | D31: =IF(D8="","",(D8/$O$23)) -> 0.1118703 | E31: =IF(E8="","",(E8/$O$23)) -> 2.3432125 | F31: =IF(F8="","",(F8/$O$23)) -> 1.5227256 | G31: =IF(G8="","",(G8/$O$23)) -> 2.5460864 | H31: =IF(H8="","",(H8/$O$23)) -> 3.4401956 | I31: =IF(I8="","",(I8/$O$23)) -> 0.43241819 | ... V31: =IF(V8="","",(V8/$O$23)) -> 0.32083611
B32: =IF(B9="","",(B9/$O$23)) -> 0.045038927 | C32: =IF(C9="","",(C9/$O$23)) -> 0.29572244 | D32: =IF(D9="","",(D9/$O$23)) -> 0.35531486 | E32: =IF(E9="","",(E9/$O$23)) -> 0.55020215 | F32: =IF(F9="","",(F9/$O$23)) -> 1.5370935 | G32: =IF(G9="","",(G9/$O$23)) -> 2.9300016 | H32: =IF(H9="","",(H9/$O$23)) -> 3.8422849 | I32: =IF(I9="","",(I9/$O$23)) -> 0.028626626 | ... V32: =IF(V9="","",(V9/$O$23)) -> 1.5146327
B33: =IF(B10="","",(B10/$O$23)) -> 0 | C33: =IF(C10="","",(C10/$O$23)) -> 0.028195146 | D33: =IF(D10="","",(D10/$O$23)) -> 0.70248035 | E33: =IF(E10="","",(E10/$O$23)) -> 1.1264476 | F33: =IF(F10="","",(F10/$O$23)) -> 1.0664471 | G33: =IF(G10="","",(G10/$O$23)) -> 2.1514834 | H33: =IF(H10="","",(H10/$O$23)) -> 1.656258 | I33: =IF(I10="","",(I10/$O$23)) -> 0.01210347 | ... V33: =IF(V10="","",(V10/$O$23)) -> 0.46086119
B34: =IF(B11="","",(B11/$O$23)) -> 0.06799179 | C34: =IF(C11="","",(C11/$O$23)) -> 0.22681254 | D34: =IF(D11="","",(D11/$O$23)) -> 0.86935 | E34: =IF(E11="","",(E11/$O$23)) -> 1.3104171 | F34: =IF(F11="","",(F11/$O$23)) -> 1.4896785 | G34: =IF(G11="","",(G11/$O$23)) -> 1.698118 | H34: =IF(H11="","",(H11/$O$23)) -> 2.7277778 | I34: =IF(I11="","",(I11/$O$23)) -> 0.16602715 | ... V34: =IF(V11="","",(V11/$O$23)) -> 1.8220311
B35: =IF(B12="","",(B12/$O$23)) -> 0.10630668 | C35: =IF(C12="","",(C12/$O$23)) -> 0.36729099 | D35: =IF(D12="","",(D12/$O$23)) -> 0.45518913 | E35: =IF(E12="","",(E12/$O$23)) -> 0.14312901 | F35: =IF(F12="","",(F12/$O$23)) -> 1.1529866 | G35: =IF(G12="","",(G12/$O$23)) -> 1.9357758 | H35: =IF(H12="","",(H12/$O$23)) -> 1.8746326 | I35: =IF(I12="","",(I12/$O$23)) -> 0.1952406 | ... V35: =IF(V12="","",(V12/$O$23)) -> 0.83439045
B36: =IF(B13="","",(B13/$O$23)) | C36: =IF(C13="","",(C13/$O$23)) | D36: =IF(D13="","",(D13/$O$23)) | E36: =IF(E13="","",(E13/$O$23)) | F36: =IF(F13="","",(F13/$O$23)) | G36: =IF(G13="","",(G13/$O$23)) | H36: =IF(H13="","",(H13/$O$23)) | I36: =IF(I13="","",(I13/$O$23)) | ... V36: =IF(V13="","",(V13/$O$23))
B37: =IF(B14="","",(B14/$O$23)) | C37: =IF(C14="","",(C14/$O$23)) | D37: =IF(D14="","",(D14/$O$23)) | E37: =IF(E14="","",(E14/$O$23)) | F37: =IF(F14="","",(F14/$O$23)) | G37: =IF(G14="","",(G14/$O$23)) | H37: =IF(H14="","",(H14/$O$23)) | I37: =IF(I14="","",(I14/$O$23)) | ... V37: =IF(V14="","",(V14/$O$23))
B38: =IF(B15="","",(B15/$O$23)) | C38: =IF(C15="","",(C15/$O$23)) | D38: =IF(D15="","",(D15/$O$23)) | E38: =IF(E15="","",(E15/$O$23)) | F38: =IF(F15="","",(F15/$O$23)) | G38: =IF(G15="","",(G15/$O$23)) | H38: =IF(H15="","",(H15/$O$23)) | I38: =IF(I15="","",(I15/$O$23)) | ... V38: =IF(V15="","",(V15/$O$23))
B39: =IF(B16="","",(B16/$O$23)) | C39: =IF(C16="","",(C16/$O$23)) | D39: =IF(D16="","",(D16/$O$23)) | E39: =IF(E16="","",(E16/$O$23)) | F39: =IF(F16="","",(F16/$O$23)) | G39: =IF(G16="","",(G16/$O$23)) | H39: =IF(H16="","",(H16/$O$23)) | I39: =IF(I16="","",(I16/$O$23)) | ... V39: =IF(V16="","",(V16/$O$23))
B40: =IF(B17="","",(B17/$O$23)) | C40: =IF(C17="","",(C17/$O$23)) | D40: =IF(D17="","",(D17/$O$23)) | E40: =IF(E17="","",(E17/$O$23)) | F40: =IF(F17="","",(F17/$O$23)) | G40: =IF(G17="","",(G17/$O$23)) | H40: =IF(H17="","",(H17/$O$23)) | I40: =IF(I17="","",(I17/$O$23)) | ... V40: =IF(V17="","",(V17/$O$23))
... B43: =IF(B20="","",(B20/$O$23)) | C43: =IF(C20="","",(C20/$O$23)) | D43: =IF(D20="","",(D20/$O$23)) | E43: =IF(E20="","",(E20/$O$23)) | F43: =IF(F20="","",(F20/$O$23)) | G43: =IF(G20="","",(G20/$O$23)) | H43: =IF(H20="","",(H20/$O$23)) | I43: =IF(I20="","",(I20/$O$23)) | ... V43: =IF(V20="","",(V20/$O$23))
A45: =A4 -> Noms des groupes | B45: =B4 -> Solvent control | C45: =C4 -> EE2-33.8ng/L | D45: =D4 -> EE2-50.6ng/L | E45: =E4 -> EE2-76ng/L | F45: =F4 -> EE2-114ng/L | G45: =G4 -> EE2-170.9ng/L | H45: =H4 -> EE2-488ng/L | ... V45: =V4 -> Dutasteride-0.01mg/L + Testostérone
A46: mean | B46: =AVERAGE(B28:B43) -> 0.099407189 | C46: =AVERAGE(C28:C43) -> 0.19164527 | D46: =AVERAGE(D28:D43) -> 0.45574925 | E46: =AVERAGE(E28:E43) -> 0.96087971 | F46: =AVERAGE(F28:F43) -> 1.2563098 | G46: =AVERAGE(G28:G43) -> 2.0607181 | H46: =AVERAGE(H28:H43) -> 2.5693305 | I46: =AVERAGE(I28:I43) -> 0.15159968 | ... V46: =AVERAGE(V28:V43) -> 0.90934149
...

Sheet R3
A1: 6. Expérimentateur 2 : copier et coller les valeurs des intensités totales de fluorescences obtenues dans le fichier raw data lors du traitement des images. Ne pas supprimer les colonnes correspondant aux concentrations non lues. 画像処理時に取得した蛍光強度全体の値をコピーして、生データファイルに貼り付けます。未読濃度に対応する列は削除しないでください。
A3: R3 | B3: Non dopé | O3: avec testo
A4: Noms des groupes | B4: ='Front page'!A7 -> Solvent control | C4: ='Front page'!A8 -> EE2-33.8ng/L | D4: ='Front page'!A9 -> EE2-50.6ng/L | E4: ='Front page'!A10 -> EE2-76ng/L | F4: ='Front page'!A11 -> EE2-114ng/L | G4: ='Front page'!A12 -> EE2-170.9ng/L | H4: ='Front page'!A13 -> EE2-488ng/L | I4: ='Front page'!A14 -> Dutasteride-1mg/L | J4: ='Front page'!A15 -> Dutasteride-0.5mg/L | K4: ='Front page'!A16 -> Dutasteride-0.25mg/L | L4: ='Front page'!A17 -> Dutasteride-0.1mg/L | M4: ='Front page'!A18 -> Dutasteride-0.01mg/L | N4: ='Front page'!A19 | O4: ='Front page'!A35 -> Testo -30µg/L | P4: ='Front page'!A36 -> Testo 30µg/L + EE2 -64ng/L | Q4: ='Front page'!A37 -> Testo 30µg/L + FAD-10mg/L | R4: ='Front page'!A38 -> Dutasteride-1mg/L + Testostérone | S4: ='Front page'!A39 -> Dutasteride-0.5mg/L + Testostérone | T4: ='Front page'!A40 -> Dutasteride-0.25mg/L + Testostérone | U4: ='Front page'!A41 -> Dutasteride-0.1mg/L + Testostérone | V4: ='Front page'!A42 -> Dutasteride-0.01mg/L + Testostérone
A5: Données brutes ローデータ | B5: 161555 | C5: 1808878 | D5: 1222649 | E5: 12625973 | F5: 5389903 | G5: 14388648 | H5: 19725716 | I5: 2219666 | J5: 286111 | K5: 1436517 | L5: 1168700 | M5: 244540 | O5: 4992054 | P5: 3692007 | Q5: 659844 | R5: 110515 | S5: 6912101 | T5: 6137481 | U5: 3480057 | V5: 5228411
B6: 552391 | C6: 3423588 | D6: 2754214 | E6: 3509199 | F6: 4838504 | G6: 14058314 | H6: 10285753 | I6: 942340 | J6: 131223 | K6: 726943 | L6: 127080 | M6: 742156 | O6: 3063841 | P6: 6317995 | Q6: 407372 | R6: 3307770 | S6: 5557031 | T6: 2431091 | U6: 4525597 | V6: 2569550
B7: 3827 | C7: 887139 | D7: 1307463 | E7: 5781023 | F7: 6060483 | G7: 15285315 | H7: 11965295 | I7: 1738043 | J7: 65897 | K7: 679995 | L7: 1026943 | M7: 592866 | O7: 9749890 | P7: 4674458 | Q7: 561225 | R7: 2912029 | S7: 956054 | T7: 8091363 | U7: 2373014 | V7: 2309661
B8: 805 | C8: 2776207 | D8: 1673176 | E8: 1992248 | F8: 10231497 | G8: 9474984 | H8: 15579661 | I8: 92646 | J8: 154417 | K8: 1506824 | L8: 889944 | M8: 22835 | O8: 10013445 | P8: 7706593 | Q8: 1149378 | R8: 5630262 | S8: 1767377 | T8: 1336457 | U8: 1417944 | V8: 5388007
B9: 72221 | C9: 1328074 | D9: 3321536 | E9: 6742762 | F9: 6399284 | G9: 12441139 | H9: 13809188 | I9: 391902 | J9: 316006 | K9: 1769753 | L9: 743239 | M9: 570885 | O9: 5806715 | P9: 10047411 | Q9: 463689 | R9: 3856837 | S9: 2906848 | T9: 851382 | U9: 286714 | V9: 1294893
B10: 24257 | C10: 3246378 | D10: 1830635 | E10: 9422521 | F10: 7609001 | G10: 11475418 | H10: 11856270 | I10: 48939 | J10: 177044 | K10: 183623 | L10: 164996 | M10: 645212 | O10: 2235181 | P10: 8567868 | Q10: 4004742 | R10: 3798397 | S10: 3049651 | T10: 1489576 | U10: 10716636 | V10: 8304467
B11: 68798 | C11: 204985 | D11: 934436 | E11: 8616875 | F11: 8351368 | G11: 14766402 | H11: 10027557 | I11: 909717 | J11: 634815 | K11: 1302620 | L11: 350711 | M11: 468058 | O11: 4625322 | P11: 9773616 | Q11: 1914239 | R11: 2189958 | S11: 3021454 | T11: 4236279 | U11: 2957363 | V11: 2012726
B12: 563333 | C12: 449551 | D12: 2744777 | E12: 8540834 | F12: 8607269 | G12: 12007508 | H12: 13782294 | I12: 1819130 | J12: 588927 | K12: 671508 | L12: 1832612 | M12: 123436 | O12: 4457088 | P12: 2295727 | Q12: 394251 | R12: 4837272 | S12: 3088847 | T12: 2609024 | U12: 2954319 | V12: 3042327
O13: 3565987
O14: 3211524
O15: 7759606
O16: 793483
O17: 38309
O18: 9374173
O19: 9031111
O20: 7097620
A22: =A4 -> Noms des groupes | B22: =B4 -> Solvent control | C22: =C4 -> EE2-33.8ng/L | D22: =D4 -> EE2-50.6ng/L | E22: =E4 -> EE2-76ng/L | F22: =F4 -> EE2-114ng/L | G22: =G4 -> EE2-170.9ng/L | H22: =H4 -> EE2-488ng/L | ... V22: =V4 -> Dutasteride-0.01mg/L + Testostérone
A23: mean | B23: =AVERAGE(B5:B20) -> 180898.38 | C23: =AVERAGE(C5:C20) -> 1765600 | D23: =AVERAGE(D5:D20) -> 1973610.8 | E23: =AVERAGE(E5:E20) -> 7153929.4 | F23: =AVERAGE(F5:F20) -> 7185913.6 | G23: =AVERAGE(G5:G20) -> 12987216 | H23: =AVERAGE(H5:H20) -> 13378967 | I23: =AVERAGE(I5:I20) -> 1020297.9 | J23: =AVERAGE(J5:J20) -> 294305 | L23: =AVERAGE(L5:L20) -> 788028.12 | N23: =AVERAGE(N5:N20) -> #DIV/0! | O23: =AVERAGE(O5:O20) -> 5363459.3 | P23: =AVERAGE(P5:P20) -> 6634459.4 | Q23: =AVERAGE(Q5:Q20) -> 1194342.5 | R23: =AVERAGE(R5:R20) -> 3330380 | S23: =AVERAGE(S5:S20) -> 3407420.4 | T23: =AVERAGE(T5:T20) -> 3397831.6 | U23: =AVERAGE(U5:U20) -> 3588955.5 | V23: =AVERAGE(V5:V20) -> 3768755.2
A24: SD | B24: =STDEV(B5:B20) -> 238249.23 | C24: =STDEV(C5:C20) -> 1258993.6 | D24: =STDEV(D5:D20) -> 863483.39 | E24: =STDEV(E5:E20) -> 3404501.8 | F24: =STDEV(F5:F20) -> 1830475.4 | G24: =STDEV(G5:G20) -> 1979803.7 | H24: =STDEV(H5:H20) -> 3175554.8 | I24: =STDEV(I5:I20) -> 828857.88 | J24: =STDEV(J5:J20) -> 212257.26 | L24: =STDEV(L5:L20) -> 575922.55 | N24: =STDEV(N5:N20) -> #DIV/0! | O24: =STDEV(O5:O20) -> 3194038.7 | P24: =STDEV(P5:P20) -> 2873883.9 | Q24: =STDEV(Q5:Q20) -> 1247767.6 | R24: =STDEV(R5:R20) -> 1686077.4 | S24: =STDEV(S5:S20) -> 1935812.2 | T24: =STDEV(T5:T20) -> 2568207.4 | U24: =STDEV(U5:U20) -> 3153031.7 | V24: =STDEV(V5:V20) -> 2348970.4
B26: Non dopé | O26: avec testo
A27: Noms des groupes | B27: =B4 -> Solvent control | C27: =C4 -> EE2-33.8ng/L | D27: =D4 -> EE2-50.6ng/L | E27: =E4 -> EE2-76ng/L | F27: =F4 -> EE2-114ng/L | G27: =G4 -> EE2-170.9ng/L | H27: =H4 -> EE2-488ng/L | I27: =I4 -> Dutasteride-1mg/L | ... V27: =V4 -> Dutasteride-0.01mg/L + Testostérone
A28: Données normalisées sur la moyenne du groupe "Testo" 「Testo」群の平均に関する標準化データ | B28: =IF(B5="","",(B5/$O$23)) -> 0.030121418 | C28: =IF(C5="","",(C5/$O$23)) -> 0.33725957 | D28: =IF(D5="","",(D5/$O$23)) -> 0.22795903 | E28: =IF(E5="","",(E5/$O$23)) -> 2.3540727 | F28: =IF(F5="","",(F5/$O$23)) -> 1.0049303 | G28: =IF(G5="","",(G5/$O$23)) -> 2.6827178 | H28: =IF(H5="","",(H5/$O$23)) -> 3.6777973 | I28: =IF(I5="","",(I5/$O$23)) -> 0.41384969 | ... V28: =IF(V5="","",(V5/$O$23)) -> 0.97482067
B29: =IF(B6="","",(B6/$O$23)) -> 0.10299155 | C29: =IF(C6="","",(C6/$O$23)) -> 0.63831714 | D29: =IF(D6="","",(D6/$O$23)) -> 0.51351448 | E29: =IF(E6="","",(E6/$O$23)) -> 0.65427904 | F29: =IF(F6="","",(F6/$O$23)) -> 0.90212374 | G29: =IF(G6="","",(G6/$O$23)) -> 2.6211281 | H29: =IF(H6="","",(H6/$O$23)) -> 1.9177461 | I29: =IF(I6="","",(I6/$O$23)) -> 0.17569631 | ... V29: =IF(V6="","",(V6/$O$23)) -> 0.47908446
B30: =IF(B7="","",(B7/$O$23)) -> 0.00071353203 | C30: =IF(C7="","",(C7/$O$23)) -> 0.16540426 | D30: =IF(D7="","",(D7/$O$23)) -> 0.24377233 | E30: =IF(E7="","",(E7/$O$23)) -> 1.0778534 | F30: =IF(F7="","",(F7/$O$23)) -> 1.1299579 | G30: =IF(G7="","",(G7/$O$23)) -> 2.8498986 | H30: =IF(H7="","",(H7/$O$23)) -> 2.2308914 | I30: =IF(I7="","",(I7/$O$23)) -> 0.32405261 | ... V30: =IF(V7="","",(V7/$O$23)) -> 0.43062898
B31: =IF(B8="","",(B8/$O$23)) -> 0.0001500897 | C31: =IF(C8="","",(C8/$O$23)) -> 0.517615 | D31: =IF(D8="","",(D8/$O$23)) -> 0.31195837 | E31: =IF(E8="","",(E8/$O$23)) -> 0.37144833 | F31: =IF(F8="","",(F8/$O$23)) -> 1.9076302 | G31: =IF(G8="","",(G8/$O$23)) -> 1.7665808 | H31: =IF(H8="","",(H8/$O$23)) -> 2.9047784 | I31: =IF(I8="","",(I8/$O$23)) -> 0.017273553 | ... V31: =IF(V8="","",(V8/$O$23)) -> 1.0045768
B32: =IF(B9="","",(B9/$O$23)) -> 0.013465377 | C32: =IF(C9="","",(C9/$O$23)) -> 0.24761519 | D32: =IF(D9="","",(D9/$O$23)) -> 0.61928987 | E32: =IF(E9="","",(E9/$O$23)) -> 1.2571666 | F32: =IF(F9="","",(F9/$O$23)) -> 1.1931262 | G32: =IF(G9="","",(G9/$O$23)) -> 2.319611 | H32: =IF(H9="","",(H9/$O$23)) -> 2.5746794 | I32: =IF(I9="","",(I9/$O$23)) -> 0.073068887 | ... V32: =IF(V9="","",(V9/$O$23)) -> 0.2414287
B33: =IF(B10="","",(B10/$O$23)) -> 0.0045226408 | C33: =IF(C10="","",(C10/$O$23)) -> 0.6052769 | D33: =IF(D10="","",(D10/$O$23)) -> 0.3413161 | E33: =IF(E10="","",(E10/$O$23)) -> 1.7567992 | F33: =IF(F10="","",(F10/$O$23)) -> 1.4186741 | G33: =IF(G10="","",(G10/$O$23)) -> 2.1395553 | H33: =IF(H10="","",(H10/$O$23)) -> 2.210564 | I33: =IF(I10="","",(I10/$O$23)) -> 0.0091245215 | ... V33: =IF(V10="","",(V10/$O$23)) -> 1.5483416
B34: =IF(B11="","",(B11/$O$23)) -> 0.012827169 | C34: =IF(C11="","",(C11/$O$23)) -> 0.038218804 | D34: =IF(D11="","",(D11/$O$23)) -> 0.17422263 | E34: =IF(E11="","",(E11/$O$23)) -> 1.606589 | F34: =IF(F11="","",(F11/$O$23)) -> 1.5570861 | G34: =IF(G11="","",(G11/$O$23)) -> 2.7531489 | H34: =IF(H11="","",(H11/$O$23)) -> 1.8696062 | I34: =IF(I11="","",(I11/$O$23)) -> 0.16961385 | ... V34: =IF(V11="","",(V11/$O$23)) -> 0.37526639
B35: =IF(B12="","",(B12/$O$23)) -> 0.10503165 | C35: =IF(C12="","",(C12/$O$23)) -> 0.08381736 | D35: =IF(D12="","",(D12/$O$23)) -> 0.51175498 | E35: =IF(E12="","",(E12/$O$23)) -> 1.5924114 | F35: =IF(F12="","",(F12/$O$23)) -> 1.604798 | G35: =IF(G12="","",(G12/$O$23)) -> 2.2387618 | H35: =IF(H12="","",(H12/$O$23)) -> 2.5696651 | I35: =IF(I12="","",(I12/$O$23)) -> 0.33917103 | ... V35: =IF(V12="","",(V12/$O$23)) -> 0.56723223
B36: =IF(B13="","",(B13/$O$23)) | C36: =IF(C13="","",(C13/$O$23)) | D36: =IF(D13="","",(D13/$O$23)) | E36: =IF(E13="","",(E13/$O$23)) | F36: =IF(F13="","",(F13/$O$23)) | G36: =IF(G13="","",(G13/$O$23)) | H36: =IF(H13="","",(H13/$O$23)) | I36: =IF(I13="","",(I13/$O$23)) | ... V36: =IF(V13="","",(V13/$O$23))
B37: =IF(B14="","",(B14/$O$23)) | C37: =IF(C14="","",(C14/$O$23)) | D37: =IF(D14="","",(D14/$O$23)) | E37: =IF(E14="","",(E14/$O$23)) | F37: =IF(F14="","",(F14/$O$23)) | G37: =IF(G14="","",(G14/$O$23)) | H37: =IF(H14="","",(H14/$O$23)) | I37: =IF(I14="","",(I14/$O$23)) | ... V37: =IF(V14="","",(V14/$O$23))
B38: =IF(B15="","",(B15/$O$23)) | C38: =IF(C15="","",(C15/$O$23)) | D38: =IF(D15="","",(D15/$O$23)) | E38: =IF(E15="","",(E15/$O$23)) | F38: =IF(F15="","",(F15/$O$23)) | G38: =IF(G15="","",(G15/$O$23)) | H38: =IF(H15="","",(H15/$O$23)) | I38: =IF(I15="","",(I15/$O$23)) | ... V38: =IF(V15="","",(V15/$O$23))
B39: =IF(B16="","",(B16/$O$23)) | C39: =IF(C16="","",(C16/$O$23)) | D39: =IF(D16="","",(D16/$O$23)) | E39: =IF(E16="","",(E16/$O$23)) | F39: =IF(F16="","",(F16/$O$23)) | G39: =IF(G16="","",(G16/$O$23)) | H39: =IF(H16="","",(H16/$O$23)) | I39: =IF(I16="","",(I16/$O$23)) | ... V39: =IF(V16="","",(V16/$O$23))
B40: =IF(B17="","",(B17/$O$23)) | C40: =IF(C17="","",(C17/$O$23)) | D40: =IF(D17="","",(D17/$O$23)) | E40: =IF(E17="","",(E17/$O$23)) | F40: =IF(F17="","",(F17/$O$23)) | G40: =IF(G17="","",(G17/$O$23)) | H40: =IF(H17="","",(H17/$O$23)) | I40: =IF(I17="","",(I17/$O$23)) | ... V40: =IF(V17="","",(V17/$O$23))
... B43: =IF(B20="","",(B20/$O$23)) | C43: =IF(C20="","",(C20/$O$23)) | D43: =IF(D20="","",(D20/$O$23)) | E43: =IF(E20="","",(E20/$O$23)) | F43: =IF(F20="","",(F20/$O$23)) | G43: =IF(G20="","",(G20/$O$23)) | H43: =IF(H20="","",(H20/$O$23)) | I43: =IF(I20="","",(I20/$O$23)) | ... V43: =IF(V20="","",(V20/$O$23))
A45: =A4 -> Noms des groupes | B45: =B4 -> Solvent control | C45: =C4 -> EE2-33.8ng/L | D45: =D4 -> EE2-50.6ng/L | E45: =E4 -> EE2-76ng/L | F45: =F4 -> EE2-114ng/L | G45: =G4 -> EE2-170.9ng/L | H45: =H4 -> EE2-488ng/L | ... V45: =V4 -> Dutasteride-0.01mg/L + Testostérone
A46: mean | B46: =AVERAGE(B28:B43) -> 0.033727929 | C46: =AVERAGE(C28:C43) -> 0.32919053 | D46: =AVERAGE(D28:D43) -> 0.36797347 | E46: =AVERAGE(E28:E43) -> 1.3338275 | F46: =AVERAGE(F28:F43) -> 1.3397908 | G46: =AVERAGE(G28:G43) -> 2.4214253 | H46: =AVERAGE(H28:H43) -> 2.494466 | I46: =AVERAGE(I28:I43) -> 0.19023131 | ... V46: =AVERAGE(V28:V43) -> 0.70267248
...

Sheet pooled normalised values
A1: N°BDC : | B1: ='Front page'!#REF! -> #REF!
B3: Non dopé | P3: avec testo
A4: Noms des groupes | B4: ='R1'!B4 -> Solvent control | C4: ='R1'!C4 -> EE2-33.8ng/L | D4: ='R1'!D4 -> EE2-50.6ng/L | E4: ='R1'!E4 -> EE2-76ng/L | F4: ='R1'!F4 -> EE2-114ng/L | G4: ='R1'!G4 -> EE2-170.9ng/L | H4: ='R1'!H4 -> EE2-488ng/L | I4: ='R1'!I4 -> Dutasteride-1mg/L | ... N4: ='R1'!N4 | P4: ='R1'!O4 -> Testo -30µg/L | Q4: ='R1'!P4 -> Testo 30µg/L + EE2 -64ng/L | R4: ='R1'!Q4 -> Testo 30µg/L + FAD-10mg/L | S4: ='R1'!R4 -> Dutasteride-1mg/L + Testostérone | T4: ='R1'!S4 -> Dutasteride-0.5mg/L + Testostérone | U4: ='R1'!T4 -> Dutasteride-0.25mg/L + Testostérone | V4: ='R1'!U4 -> Dutasteride-0.1mg/L + Testostérone | W4: ='R1'!V4 -> Dutasteride-0.01mg/L + Testostérone
A6: Rep1 | B6: ='R1'!B28 -> 0.16500081 | C6: ='R1'!C28 -> 0.36740681 | D6: ='R1'!D28 -> 0.33914698 | E6: ='R1'!E28 -> 1.7905863 | F6: ='R1'!F28 -> 0.92480481 | G6: ='R1'!G28 -> 2.2976218 | H6: ='R1'!H28 -> 2.6173496 | I6: ='R1'!I28 -> 0.21071205 | ... N6: ='R1'!N28 | P6: ='R1'!O28 -> 1.1760562 | Q6: ='R1'!P28 -> 1.5861987 | R6: ='R1'!Q28 -> 0.13245134 | S6: ='R1'!R28 -> 2.1103662 | T6: ='R1'!S28 -> 0.83070883 | U6: ='R1'!T28 -> 0.58608427 | V6: ='R1'!U28 -> 1.9243112 | W6: ='R1'!V28 -> 1.2745127
A7: Données normalisées sur la moyenne du groupe "Testo" | B7: ='R1'!B29 -> 0.13649764 | C7: ='R1'!C29 -> 0.48855409 | D7: ='R1'!D29 -> 0.66937884 | E7: ='R1'!E29 -> 0.20726523 | F7: ='R1'!F29 -> 1.3569912 | G7: ='R1'!G29 -> 2.4051502 | H7: ='R1'!H29 -> 3.0989233 | I7: ='R1'!I29 -> 0.34737697 | ... N7: ='R1'!N29 | P7: ='R1'!O29 -> 0.64971424 | Q7: ='R1'!P29 -> 1.3768165 | R7: ='R1'!Q29 -> 0.0050378574 | S7: ='R1'!R29 -> 1.5978863 | T7: ='R1'!S29 -> 1.7577192 | U7: ='R1'!T29 -> 1.6473914 | V7: ='R1'!U29 -> 1.0073884 | W7: ='R1'!V29 -> 0.66121946
B8: ='R1'!B30 -> 0.0088416147 | C8: ='R1'!C30 -> 0.48772822 | D8: ='R1'!D30 -> 0.22762548 | E8: ='R1'!E30 -> 1.1063864 | F8: ='R1'!F30 -> 1.7964995 | G8: ='R1'!G30 -> 1.5647614 | H8: ='R1'!H30 -> 1.1343527 | I8: ='R1'!I30 -> 0.3162749 | ... N8: ='R1'!N30 | P8: ='R1'!O30 -> 0.87941744 | Q8: ='R1'!P30 -> 1.0769779 | R8: ='R1'!Q30 -> 0.12885657 | S8: ='R1'!R30 -> 2.7246858 | T8: ='R1'!S30 -> 1.9250942 | U8: ='R1'!T30 -> 0.68321629 | V8: ='R1'!U30 -> 2.3533187 | W8: ='R1'!V30 -> 1.1475679
B9: ='R1'!B31 -> 0.024545235 | C9: ='R1'!C31 -> 0.037948099 | D9: ='R1'!D31 -> 0.60141466 | E9: ='R1'!E31 -> 0.76401358 | F9: ='R1'!F31 -> 1.0574581 | G9: ='R1'!G31 -> 2.6105424 | H9: ='R1'!H31 -> 3.6893455 | I9: ='R1'!I31 -> 0.04640929 | ... N9: ='R1'!N31 | P9: ='R1'!O31 -> 1.7863832 | Q9: ='R1'!P31 -> 0.87560441 | R9: ='R1'!Q31 -> 0 | S9: ='R1'!R31 -> 1.4124242 | T9: ='R1'!S31 -> 1.1776843 | U9: ='R1'!T31 -> 1.0560171 | V9: ='R1'!U31 -> 0.8164018 | W9: ='R1'!V31 -> 1.0948328
B10: ='R1'!B32 -> 0.0037644527 | C10: ='R1'!C32 -> 0.22866482 | D10: ='R1'!D32 -> 0.54811812 | E10: ='R1'!E32 -> 0.73840265 | F10: ='R1'!F32 -> 1.8300633 | G10: ='R1'!G32 -> 1.8860576 | H10: ='R1'!H32 -> 4.0813544 | I10: ='R1'!I32 -> 0.16215555 | ... N10: ='R1'!N32 | P10: ='R1'!O32 -> 0.70771998 | Q10: ='R1'!P32 -> 1.6160932 | R10: ='R1'!Q32 -> 0 | S10: ='R1'!R32 -> 0.82869279 | T10: ='R1'!S32 -> 1.8815681 | U10: ='R1'!T32 -> 0.94841328 | V10: ='R1'!U32 -> 2.0981078 | W10: ='R1'!V32 -> 1.8389216
B11: ='R1'!B33 -> 0.095457899 | C11: ='R1'!C33 -> 0.31453911 | D11: ='R1'!D33 -> 0.73500727 | E11: ='R1'!E33 -> 1.0666114 | F11: ='R1'!F33 -> 1.1910832 | G11: ='R1'!G33 -> 3.1602439 | H11: ='R1'!H33 -> 3.4781305 | I11: ='R1'!I33 -> 0.051143575 | ... N11: ='R1'!N33 | P11: ='R1'!O33 -> 1.4340393 | Q11: ='R1'!P33 -> 1.1816242 | R11: ='R1'!Q33 -> 0.017333802 | S11: ='R1'!R33 -> 1.1900847 | T11: ='R1'!S33 -> 1.6566012 | U11: ='R1'!T33 -> 1.7880181 | V11: ='R1'!U33 -> 1.2739992 | W11: ='R1'!V33 -> 0.75634934
B12: ='R1'!B34 -> 0.059579203 | C12: ='R1'!C34 -> 0.14024436 | D12: ='R1'!D34 -> 0.64143296 | E12: ='R1'!E34 -> 1.2172675 | F12: ='R1'!F34 -> 1.5013724 | G12: ='R1'!G34 -> 2.6236149 | H12: ='R1'!H34 -> 2.9933141 | I12: ='R1'!I34 -> 0.0045399993 | ... N12: ='R1'!N34 | P12: ='R1'!O34 -> 0.62404052 | Q12: ='R1'!P34 -> 2.2701561 | R12: ='R1'!Q34 -> 0.071176772 | S12: ='R1'!R34 -> 1.2508969 | T12: ='R1'!S34 -> 1.055853 | U12: ='R1'!T34 -> 1.9513292 | V12: ='R1'!U34 -> 1.8027192 | W12: ='R1'!V34 -> 0.99144382
B13: ='R1'!B35 -> 0.027938531 | C13: ='R1'!C35 | D13: ='R1'!D35 -> 0.42416743 | E13: ='R1'!E35 -> 0.66424687 | F13: ='R1'!F35 -> 1.4271781 | G13: ='R1'!G35 -> 2.5668559 | H13: ='R1'!H35 -> 3.4395562 | I13: ='R1'!I35 -> 0.20537669 | ... N13: ='R1'!N35 | P13: ='R1'!O35 -> 0.85322636 | Q13: ='R1'!P35 -> 0.84226693 | R13: ='R1'!Q35 -> 0.018206811 | S13: ='R1'!R35 -> 2.3191933 | T13: ='R1'!S35 -> 2.1526106 | U13: ='R1'!T35 -> 1.316951 | V13: ='R1'!U35 -> 0.4542201 | W13: ='R1'!V35 -> 0.79938403
B14: ='R1'!B36 | C14: ='R1'!C36 | D14: ='R1'!D36 | E14: ='R1'!E36 | F14: ='R1'!F36 | G14: ='R1'!G36 | H14: ='R1'!H36 | I14: ='R1'!I36 | ... N14: ='R1'!N36 | P14: ='R1'!O36 -> 0.78828384 | Q14: ='R1'!P36 | R14: ='R1'!Q36 | S14: ='R1'!R36 | T14: ='R1'!S36 | U14: ='R1'!T36 | V14: ='R1'!U36 | W14: ='R1'!V36
B15: ='R1'!B37 | C15: ='R1'!C37 | D15: ='R1'!D37 | E15: ='R1'!E37 | F15: ='R1'!F37 | G15: ='R1'!G37 | H15: ='R1'!H37 | I15: ='R1'!I37 | ... N15: ='R1'!N37 | P15: ='R1'!O37 -> 1.3145226 | Q15: ='R1'!P37 | R15: ='R1'!Q37 | S15: ='R1'!R37 | T15: ='R1'!S37 | U15: ='R1'!T37 | V15: ='R1'!U37 | W15: ='R1'!V37
B16: ='R1'!B38 | C16: ='R1'!C38 | D16: ='R1'!D38 | E16: ='R1'!E38 | F16: ='R1'!F38 | G16: ='R1'!G38 | H16: ='R1'!H38 | I16: ='R1'!I38 | ... N16: ='R1'!N38 | P16: ='R1'!O38 -> 1.0294681 | Q16: ='R1'!P38 | R16: ='R1'!Q38 | S16: ='R1'!R38 | T16: ='R1'!S38 | U16: ='R1'!T38 | V16: ='R1'!U38 | W16: ='R1'!V38
B17: ='R1'!B39 | C17: ='R1'!C39 | D17: ='R1'!D39 | E17: ='R1'!E39 | F17: ='R1'!F39 | G17: ='R1'!G39 | H17: ='R1'!H39 | I17: ='R1'!I39 | ... N17: ='R1'!N39 | P17: ='R1'!O39 -> 0.42748659 | Q17: ='R1'!P39 | R17: ='R1'!Q39 | S17: ='R1'!R39 | T17: ='R1'!S39 | U17: ='R1'!T39 | V17: ='R1'!U39 | W17: ='R1'!V39
B18: ='R1'!B40 | C18: ='R1'!C40 | D18: ='R1'!D40 | E18: ='R1'!E40 | F18: ='R1'!F40 | G18: ='R1'!G40 | H18: ='R1'!H40 | I18: ='R1'!I40 | ... N18: ='R1'!N40 | P18: ='R1'!O40 -> 0.91226441 | Q18: ='R1'!P40 | R18: ='R1'!Q40 | S18: ='R1'!R40 | T18: ='R1'!S40 | U18: ='R1'!T40 | V18: ='R1'!U40 | W18: ='R1'!V40
B19: ='R1'!B41 | C19: ='R1'!C41 | D19: ='R1'!D41 | E19: ='R1'!E41 | F19: ='R1'!F41 | G19: ='R1'!G41 | H19: ='R1'!H41 | I19: ='R1'!I41 | ... N19: ='R1'!N41 | P19: ='R1'!O41 -> 1.1985138 | Q19: ='R1'!P41 | R19: ='R1'!Q41 | S19: ='R1'!R41 | T19: ='R1'!S41 | U19: ='R1'!T41 | V19: ='R1'!U41 | W19: ='R1'!V41
... B21: ='R1'!B43 | C21: ='R1'!C43 | D21: ='R1'!D43 | E21: ='R1'!E43 | F21: ='R1'!F43 | G21: ='R1'!G43 | H21: ='R1'!H43 | I21: ='R1'!I43 | ... N21: ='R1'!N43 | P21: ='R1'!O43 | Q21: ='R1'!P43 | R21: ='R1'!Q43 | S21: ='R1'!R43 | T21: ='R1'!S43 | U21: ='R1'!T43 | V21: ='R1'!U43 | W21: ='R1'!V43
A22: Rep2 | B22: ='R2'!B28 -> 0.30937318 | C22: ='R2'!C28 -> 0.3570631 | D22: ='R2'!D28 -> 0.84282151 | E22: ='R2'!E28 -> 0.78689595 | F22: ='R2'!F28 -> 1.3312571 | G22: ='R2'!G28 -> 1.8549626 | H22: ='R2'!H28 -> 2.5094271 | I22: ='R2'!I28 -> 0.012805691 | ... N22: ='R2'!N28 | P22: ='R2'!O28 -> 1.7261149 | Q22: ='R2'!P28 -> 1.9101587 | R22: ='R2'!Q28 -> 0.37275754 | S22: ='R2'!R28 -> 0.023551335 | T22: ='R2'!S28 -> 2.1184294 | U22: ='R2'!T28 -> 0.83158839 | V22: ='R2'!U28 -> 0.70410849 | W22: ='R2'!V28 -> 0.53673275
A23: Données normalisées sur la moyenne du groupe "Testo" | B23: ='R2'!B29 -> 0.1686068 | C23: ='R2'!C29 -> 0.23434824 | D23: ='R2'!D29 -> 0.30896785 | E23: ='R2'!E29 -> 0.78333866 | F23: ='R2'!F29 -> 1.0862354 | G23: ='R2'!G29 -> 1.2205195 | H23: ='R2'!H29 -> 1.365874 | I23: ='R2'!I29 -> 0.017922482 | ... N23: ='R2'!N29 | P23: ='R2'!O29 -> 1.436991 | Q23: ='R2'!P29 -> 0.91418612 | R23: ='R2'!Q29 -> 0.15445237 | S23: ='R2'!R29 -> 0.78109158 | T23: ='R2'!S29 -> 2.0865802 | U23: ='R2'!T29 -> 0.50050676 | V23: ='R2'!U29 -> 0.88908737 | W23: ='R2'!V29 -> 1.2849139
B24: ='R2'!B30 -> 0.062336928 | C24: ='R2'!C30 -> 0.00075210553 | D24: ='R2'!D30 -> 0 | E24: ='R2'!E30 -> 0.64339473 | F24: ='R2'!F30 -> 0.8640547 | G24: ='R2'!G30 -> 2.1487979 | H24: ='R2'!H30 -> 3.1381943 | I24: ='R2'!I30 -> 0.34765325 | ... N24: ='R2'!N30 | P24: ='R2'!O30 -> 0.40116573 | Q24: ='R2'!P30 -> 1.4849833 | R24: ='R2'!Q30 -> 0.063178286 | S24: ='R2'!R30 -> 0.88906676 | T24: ='R2'!S30 -> 0.68732227 | U24: ='R2'!T30 -> 0.62442666 | V24: ='R2'!U30 -> 1.186119 | W24: ='R2'!V30 -> 0.5003338
